File: Coupon Test Data/Tensile Test_Neebajan_Alan_11.csv
Time,Displacement,Force,Strain 1
(s),(mm),(kN),(mm/mm)
"0.0000","0.0000","0.17639","-0.00018"
"0.3000","0.0044","0.21904","-0.00016"
"0.6000","0.0102","0.28382","-0.00012"
"0.9000","0.0163","0.34914","-0.00009"
"1.2000","0.0224","0.41422","-0.00005"
"1.5000","0.0284","0.47764","-0.00002"
"1.8000","0.0345","0.53848","0.00001"
"2.1000","0.0405","0.59867","0.00005"
"2.4000","0.0464","0.65984","0.00008"
"2.7000","0.0524","0.71831","0.00011"
"3.0000","0.0584","0.77908","0.00014"
"3.3000","0.0645","0.83698","0.00018"
"3.6000","0.0704","0.89448","0.00021"
"3.9000","0.0763","0.95227","0.00024"
"4.2000","0.0825","1.00635","0.00027"
"4.5000","0.0884","1.06016","0.00030"
"4.8000","0.0945","1.11814","0.00033"
"5.1000","0.1003","1.17353","0.00036"
"5.4000","0.1066","1.23269","0.00039"
"5.7000","0.1124","1.28332","0.00042"
"6.0000","0.1185","1.33768","0.00045"
"6.3000","0.1245","1.39283","0.00048"
"6.6000","0.1305","1.44700","0.00051"
"6.9000","0.1365","1.50125","0.00054"
"7.2000","0.1424","1.54877","0.00056"
"7.5000","0.1487","1.60507","0.00060"
"7.8000","0.1544","1.65540","0.00062"
"8.1000","0.1604","1.70842","0.00065"
"8.4000","0.1664","1.75484","0.00068"
"8.7000","0.1725","1.80757","0.00071"
"9.0000","0.1784","1.85757","0.00074"
"9.3000","0.1844","1.90764","0.00077"
"9.6000","0.1905","1.95498","0.00079"
"9.9000","0.1965","2.00443","0.00082"
"10.2000","0.2024","2.05320","0.00084"
"10.5000","0.2085","2.10234","0.00087"
"10.8000","0.2144","2.14707","0.00090"
"11.1000","0.2205","2.19486","0.00092"
"11.4000","0.2264","2.24301","0.00095"
"11.7000","0.2325","2.29147","0.00098"
"12.0000","0.2385","2.33460","0.00100"
"12.3000","0.2443","2.37948","0.00103"
"12.6000","0.2505","2.42797","0.00105"
"12.9000","0.2564","2.47274","0.00108"
"13.2000","0.2626","2.51586","0.00110"
"13.5000","0.2683","2.55863","0.00112"
"13.8000","0.2746","2.60680","0.00115"
"14.1000","0.2805","2.64950","0.00118"
"14.4000","0.2865","2.69039","0.00120"
"14.7000","0.2925","2.73438","0.00122"
"15.0000","0.2985","2.77772","0.00125"
"15.3000","0.3046","2.81810","0.00127"
"15.6000","0.3104","2.85908","0.00129"
"15.9000","0.3166","2.90477","0.00132"
"16.2000","0.3224","2.94485","0.00134"
"16.5000","0.3284","2.98360","0.00136"
"16.8000","0.3344","3.02425","0.00139"
"17.1000","0.3405","3.06702","0.00141"
"17.4000","0.3465","3.10387","0.00143"
"17.7000","0.3524","3.14399","0.00146"
"18.0000","0.3584","3.18463","0.00148"
"18.3000","0.3646","3.22640","0.00150"
"18.6000","0.3703","3.26100","0.00152"
"18.9000","0.3765","3.30181","0.00155"
"19.2000","0.3824","3.34043","0.00157"
"19.5000","0.3886","3.37727","0.00159"
"19.8000","0.3944","3.41467","0.00161"
"20.1000","0.4005","3.45347","0.00163"
"20.4000","0.4065","3.49119","0.00165"
"20.7000","0.4123","3.52383","0.00167"
"21.0000","0.4185","3.56334","0.00169"
"21.3000","0.4244","3.59933","0.00172"
"21.6000","0.4307","3.63645","0.00174"
"21.9000","0.4363","3.67090","0.00176"
"22.2000","0.4426","3.71108","0.00178"
"22.5000","0.4484","3.74451","0.00180"
"22.8000","0.4545","3.78149","0.00183"
"23.1000","0.4604","3.81748","0.00185"
"23.4000","0.4664","3.85250","0.00187"
"23.7000","0.4726","3.88933","0.00189"
"24.0000","0.4785","3.92487","0.00191"
"24.3000","0.4845","3.95975","0.00193"
"24.6000","0.4905","3.99485","0.00195"
"24.9000","0.4964","4.03087","0.00198"
"25.2000","0.5024","4.06453","0.00200"
"25.5000","0.5084","4.10119","0.00202"
"25.8000","0.5146","4.13798","0.00204"
"26.1000","0.5205","4.17197","0.00206"
"26.4000","0.5264","4.20710","0.00208"
"26.7000","0.5325","4.24231","0.00210"
"27.0000","0.5383","4.27658","0.00213"
"27.3000","0.5446","4.31308","0.00215"
"27.6000","0.5503","4.34567","0.00217"
"27.9000","0.5567","4.38430","0.00219"
"28.2000","0.5625","4.41686","0.00221"
"28.5000","0.5685","4.45253","0.00223"
"28.8000","0.5744","4.48591","0.00226"
"29.1000","0.5804","4.52020","0.00228"
"29.4000","0.5865","4.55512","0.00230"
"29.7000","0.5924","4.58773","0.00232"
"30.0000","0.5987","4.62490","0.00234"
"30.3000","0.6045","4.65683","0.00236"
"30.6000","0.6105","4.69148","0.00239"
"30.9000","0.6164","4.72384","0.00241"
"31.2000","0.6225","4.75859","0.00243"
"31.5000","0.6285","4.79191","0.00245"
"31.8000","0.6344","4.82472","0.00247"
"32.1000","0.6405","4.86020","0.00250"
"32.4000","0.6466","4.89339","0.00252"
"32.7000","0.6524","4.92609","0.00254"
"33.0000","0.6585","4.95841","0.00256"
"33.3000","0.6643","4.99133","0.00259"
"33.6000","0.6705","5.02418","0.00261"
"33.9000","0.6764","5.05586","0.00263"
"34.2000","0.6826","5.08913","0.00265"
"34.5000","0.6886","5.12087","0.00267"
"34.8000","0.6944","5.15067","0.00269"
"35.1000","0.7004","5.18203","0.00272"
"35.4000","0.7063","5.21257","0.00274"
"35.7000","0.7126","5.24419","0.00276"
"36.0000","0.7183","5.27259","0.00278"
"36.3000","0.7246","5.30531","0.00281"
"36.6000","0.7305","5.33527","0.00283"
"36.9000","0.7365","5.36358","0.00285"
"37.2000","0.7424","5.39240","0.00288"
"37.5000","0.7483","5.42062","0.00290"
"37.8000","0.7545","5.45115","0.00292"
"38.1000","0.7604","5.47692","0.00295"
"38.4000","0.7666","5.50833","0.00297"
"38.7000","0.7725","5.53389","0.00300"
"39.0000","0.7784","5.56183","0.00302"
"39.3000","0.7844","5.58596","0.00305"
"39.6000","0.7904","5.61376","0.00308"
"39.9000","0.7966","5.63875","0.00310"
"40.2000","0.8024","5.66282","0.00313"
"40.5000","0.8085","5.68826","0.00316"
"40.8000","0.8146","5.71135","0.00319"
"41.1000","0.8205","5.73347","0.00322"
"41.4000","0.8264","5.75309","0.00325"
"41.7000","0.8323","5.77401","0.00328"
"42.0000","0.8385","5.79484","0.00331"
"42.3000","0.8445","5.81264","0.00334"
"42.6000","0.8505","5.82894","0.00337"
"42.9000","0.8566","5.84749","0.00341"
"43.2000","0.8623","5.86070","0.00344"
"43.5000","0.8685","5.87612","0.00348"
"43.8000","0.8743","5.88702","0.00351"
"44.1000","0.8807","5.90269","0.00355"
"44.4000","0.8864","5.90980","0.00358"
"44.7000","0.8926","5.92368","0.00362"
"45.0000","0.8985","5.93114","0.00365"
"45.3000","0.9045","5.94067","0.00369"
"45.6000","0.9104","5.94709","0.00372"
"45.9000","0.9163","5.95460","0.00376"
"46.2000","0.9226","5.96411","0.00380"
"46.5000","0.9285","5.96810","0.00384"
"46.8000","0.9346","5.97621","0.00388"
"47.1000","0.9405","5.97994","0.00391"
"47.4000","0.9464","5.98646","0.00395"
"47.7000","0.9524","5.98945","0.00399"
"48.0000","0.9584","5.99494","0.00402"
"48.3000","0.9646","6.00030","0.00406"
"48.6000","0.9705","6.00368","0.00410"
"48.9000","0.9764","6.00787","0.00414"
"49.2000","0.9826","6.01236","0.00418"
"49.5000","0.9884","6.01476","0.00421"
"49.8000","0.9945","6.01782","0.00425"
"50.1000","1.0002","6.01921","0.00429"
"50.4000","1.0066","6.02669","0.00433"
"50.7000","1.0125","6.02883","0.00437"
"51.0000","1.0186","6.03232","0.00441"
"51.3000","1.0245","6.03483","0.00445"
"51.6000","1.0304","6.03730","0.00449"
"51.9000","1.0365","6.04101","0.00453"
"52.2000","1.0423","6.04206","0.00457"
"52.5000","1.0487","6.04848","0.00462"
"52.8000","1.0545","6.04819","0.00466"
"53.1000","1.0606","6.05258","0.00470"
"53.4000","1.0665","6.05341","0.00475"
"53.7000","1.0725","6.05691","0.00479"
"54.0000","1.0785","6.05834","0.00483"
"54.3000","1.0843","6.05994","0.00488"
"54.6000","1.0905","6.06509","0.00493"
"54.9000","1.0966","6.06642","0.00497"
"55.2000","1.1025","6.06879","0.00502"
"55.5000","1.1085","6.06958","0.00507"
"55.8000","1.1144","6.07278","0.00511"
"56.1000","1.1205","6.07447","0.00516"
"56.4000","1.1263","6.07633","0.00521"
"56.7000","1.1326","6.08011","0.00526"
"57.0000","1.1386","6.08240","0.00531"
"57.3000","1.1444","6.08307","0.00536"
"57.6000","1.1505","6.08572","0.00542"
"57.9000","1.1564","6.08697","0.00546"
"58.2000","1.1626","6.09008","0.00552"
"58.5000","1.1683","6.08979","0.00557"
"58.8000","1.1746","6.09508","0.00562"
"59.1000","1.1806","6.09125","0.00567"
"59.4000","1.1865","6.09391","0.00572"
"59.7000","1.1925","6.09888","0.00577"
"60.0000","1.1984","6.10055","0.00582"
"60.3000","1.2046","6.10385","0.00588"
"60.6000","1.2103","6.10265","0.00593"
"60.9000","1.2166","6.10833","0.00599"
"61.2000","1.2226","6.10752","0.00604"
"61.5000","1.2285","6.11038","0.00610"
"61.8000","1.2344","6.10964","0.00616"
"62.1000","1.2405","6.11307","0.00621"
"62.4000","1.2465","6.11411","0.00627"
"62.7000","1.2524","6.11498","0.00633"
"63.0000","1.2584","6.11806","0.00639"
"63.3000","1.2647","6.12046","0.00645"
"63.6000","1.2704","6.12039","0.00650"
"63.9000","1.2765","6.12158","0.00657"
"64.2000","1.2823","6.12252","0.00662"
"64.5000","1.2886","6.12605","0.00668"
"64.8000","1.2944","6.12623","0.00675"
"65.1000","1.3005","6.12927","0.00680"
"65.4000","1.3067","6.13112","0.00687"
"65.7000","1.3124","6.13070","0.00693"
"66.0000","1.3186","6.13314","0.00699"
"66.3000","1.3243","6.13265","0.00705"
"66.6000","1.3307","6.13736","0.00711"
"66.9000","1.3363","6.13526","0.00717"
"67.2000","1.3426","6.14046","0.00724"
"67.5000","1.3485","6.14016","0.00730"
"67.8000","1.3546","6.14207","0.00736"
"68.1000","1.3605","6.14165","0.00742"
"68.4000","1.3664","6.14293","0.00749"
"68.7000","1.3726","6.14632","0.00755"
"69.0000","1.3784","6.14598","0.00762"
"69.3000","1.3845","6.14907","0.00768"
"69.6000","1.3906","6.14930","0.00774"
"69.9000","1.3965","6.15075","0.00781"
"70.2000","1.4024","6.15053","0.00787"
"70.5000","1.4084","6.15189","0.00794"
"70.8000","1.4146","6.15456","0.00800"
"71.1000","1.4205","6.15488","0.00807"
"71.4000","1.4264","6.15665","0.00813"
"71.7000","1.4326","6.15856","0.00820"
"72.0000","1.4384","6.15875","0.00826"
"72.3000","1.4446","6.15977","0.00833"
"72.6000","1.4502","6.15922","0.00839"
"72.9000","1.4566","6.16370","0.00846"
"73.2000","1.4624","6.16361","0.00852"
"73.5000","1.4685","6.16551","0.00859"
"73.8000","1.4746","6.16662","0.00866"
"74.1000","1.4805","6.16694","0.00872"
"74.4000","1.4866","6.16851","0.00879"
"74.7000","1.4924","6.16780","0.00885"
"75.0000","1.4987","6.17226","0.00892"
"75.3000","1.5044","6.17079","0.00898"
"75.6000","1.5105","6.17391","0.00905"
"75.9000","1.5164","6.17331","0.00912"
"76.2000","1.5225","6.17536","0.00918"
"76.5000","1.5285","6.14013","0.00922"
"76.8000","1.5344","6.16051","0.00927"
"77.1000","1.5405","6.17613","0.00933"
"77.4000","1.5465","6.18050","0.00939"
"77.7000","1.5524","6.18237","0.00946"
"78.0000","1.5585","6.18159","0.00953"
"78.3000","1.5644","6.18272","0.00960"
"78.6000","1.5705","6.18246","0.00967"
"78.9000","1.5764","6.18334","0.00973"
"79.2000","1.5825","6.18505","0.00980"
"79.5000","1.5885","6.18635","0.00987"
"79.8000","1.5943","6.18630","0.00994"
"80.1000","1.6006","6.18843","0.01000"
"80.4000","1.6064","6.18799","0.01007"
"80.7000","1.6127","6.19004","0.01014"
"81.0000","1.6183","6.18834","0.01021"
"81.3000","1.6246","6.19258","0.01028"
"81.6000","1.6305","6.19290","0.01034"
"81.9000","1.6365","6.19382","0.01041"
"82.2000","1.6425","6.19439","0.01048"
"82.5000","1.6484","6.19452","0.01055"
"82.8000","1.6546","6.19719","0.01062"
"83.1000","1.6604","6.19533","0.01068"
"83.4000","1.6667","6.19989","0.01075"
"83.7000","1.6725","6.19845","0.01082"
"84.0000","1.6785","6.20081","0.01088"
"84.3000","1.6844","6.19975","0.01095"
"84.6000","1.6905","6.20226","0.01102"
"84.9000","1.6965","6.20250","0.01109"
"85.2000","1.7024","6.20259","0.01116"
"85.5000","1.7084","6.20431","0.01123"
"85.8000","1.7146","6.20615","0.01130"
"86.1000","1.7203","6.19640","0.01134"
"86.4000","1.7265","6.20493","0.01141"
"86.7000","1.7324","6.20751","0.01147"
"87.0000","1.7386","6.20999","0.01154"
"87.3000","1.7445","6.20966","0.01161"
"87.6000","1.7505","6.21117","0.01167"
"87.9000","1.7566","6.21264","0.01174"
"88.2000","1.7623","6.21203","0.01181"
"88.5000","1.7685","6.21412","0.01188"
"88.8000","1.7743","6.21304","0.01194"
"89.1000","1.7807","6.21700","0.01201"
"89.4000","1.7863","6.21424","0.01208"
"89.7000","1.7926","6.21832","0.01215"
"90.0000","1.7984","6.21726","0.01222"
"90.3000","1.8045","6.21912","0.01228"
"90.6000","1.8104","6.21890","0.01235"
"90.9000","1.8164","6.21965","0.01242"
"91.2000","1.8226","6.22229","0.01249"
"91.5000","1.8285","6.22150","0.01256"
"91.8000","1.8345","6.22358","0.01262"
"92.1000","1.8405","6.22323","0.01269"
"92.4000","1.8464","6.22487","0.01276"
"92.7000","1.8524","6.22492","0.01283"
"93.0000","1.8584","6.22588","0.01289"
"93.3000","1.8646","6.22765","0.01296"
"93.6000","1.8705","6.22752","0.01303"
"93.9000","1.8764","6.22834","0.01310"
"94.2000","1.8825","6.23000","0.01317"
"94.5000","1.8883","6.23014","0.01323"
"94.8000","1.8946","6.23177","0.01330"
"95.1000","1.9003","6.23054","0.01337"
"95.4000","1.9067","6.23431","0.01344"
"95.7000","1.9125","6.23406","0.01351"
"96.0000","1.9186","6.23537","0.01357"
"96.3000","1.9245","6.23578","0.01364"
"96.6000","1.9304","6.23601","0.01371"
"96.9000","1.9365","6.23800","0.01377"
"97.2000","1.9424","6.23695","0.01384"
"97.5000","1.9487","6.24126","0.01391"
"97.8000","1.9545","6.23952","0.01398"
"98.1000","1.9605","6.24178","0.01404"
"98.4000","1.9664","6.24099","0.01411"
"98.7000","1.9725","6.24309","0.01418"
"99.0000","1.9785","6.24343","0.01425"
"99.3000","1.9844","6.24300","0.01431"
"99.6000","1.9906","6.24608","0.01438"
"99.9000","1.9966","6.24591","0.01445"
"100.2000","2.0024","6.24694","0.01451"
"100.5000","2.0085","6.24667","0.01458"
"100.8000","2.0143","6.24818","0.01465"
"101.1000","2.0205","6.24896","0.01472"
"101.4000","2.0264","6.24938","0.01478"
"101.7000","2.0326","6.25143","0.01485"
"102.0000","2.0386","6.25263","0.01492"
"102.3000","2.0444","6.25198","0.01498"
"102.6000","2.0505","6.25359","0.01505"
"102.9000","2.0563","6.25332","0.01512"
"103.2000","2.0626","6.25605","0.01519"
"103.5000","2.0684","6.25434","0.01525"
"103.8000","2.0747","6.25822","0.01532"
"104.1000","2.0806","6.25827","0.01539"
"104.4000","2.0865","6.25848","0.01545"
"104.7000","2.0924","6.25891","0.01552"
"105.0000","2.0983","6.25942","0.01558"
"105.3000","2.1046","6.26235","0.01565"
"105.6000","2.1104","6.26048","0.01572"
"105.9000","2.1167","6.26468","0.01579"
"106.2000","2.1225","6.26310","0.01585"
"106.5000","2.1285","6.26486","0.01592"
"106.8000","2.1343","6.26370","0.01598"
"107.1000","2.1404","6.26613","0.01605"
"107.4000","2.1465","6.26678","0.01611"
"107.7000","2.1524","6.26686","0.01618"
"108.0000","2.1585","6.26852","0.01625"
"108.3000","2.1646","6.27035","0.01632"
"108.6000","2.1704","6.26969","0.01638"
"108.9000","2.1765","6.27021","0.01645"
"109.2000","2.1823","6.27042","0.01651"
"109.5000","2.1886","6.27330","0.01658"
"109.8000","2.1945","6.27295","0.01665"
"110.1000","2.2006","6.27458","0.01671"
"110.4000","2.2066","6.27586","0.01678"
"110.7000","2.2123","6.27506","0.01685"
"111.0000","2.2185","6.27699","0.01692"
"111.3000","2.2243","6.27600","0.01698"
"111.6000","2.2308","6.28082","0.01705"
"111.9000","2.2364","6.27767","0.01711"
"112.2000","2.2427","6.28162","0.01718"
"112.5000","2.2485","6.28066","0.01724"
"112.8000","2.2546","6.28248","0.01731"
"113.1000","2.2604","6.28154","0.01737"
"113.4000","2.2663","6.28225","0.01744"
"113.7000","2.2726","6.28550","0.01750"
"114.0000","2.2785","6.28453","0.01757"
"114.3000","2.2846","6.28666","0.01764"
"114.6000","2.2905","6.28637","0.01770"
"114.9000","2.2964","6.28732","0.01776"
"115.2000","2.3024","6.28730","0.01783"
"115.5000","2.3084","6.28820","0.01790"
"115.8000","2.3146","6.29062","0.01796"
"116.1000","2.3205","6.29022","0.01803"
"116.4000","2.3264","6.29125","0.01809"
"116.7000","2.3326","6.29275","0.01816"
"117.0000","2.3384","6.29226","0.01822"
"117.3000","2.3445","6.29345","0.01829"
"117.6000","2.3502","6.29251","0.01835"
"117.9000","2.3566","6.29698","0.01842"
"118.2000","2.3625","6.29633","0.01848"
"118.5000","2.3686","6.29757","0.01855"
"118.8000","2.3745","6.29808","0.01861"
"119.1000","2.3804","6.29833","0.01868"
"119.4000","2.3865","6.29988","0.01874"
"119.7000","2.3923","6.29874","0.01880"
"120.0000","2.3987","6.30368","0.01887"
"120.3000","2.4045","6.30168","0.01893"
"120.6000","2.4106","6.30378","0.01900"
"120.9000","2.4165","6.30288","0.01906"
"121.2000","2.4225","6.30440","0.01913"
"121.5000","2.4285","6.30454","0.01919"
"121.8000","2.4343","6.30439","0.01926"
"122.1000","2.4405","6.30798","0.01932"
"122.4000","2.4466","6.30800","0.01939"
"122.7000","2.4525","6.30860","0.01945"
"123.0000","2.4585","6.30830","0.01951"
"123.3000","2.4644","6.30944","0.01958"
"123.6000","2.4705","6.31013","0.01964"
"123.9000","2.4763","6.31064","0.01971"
"124.2000","2.4826","6.31299","0.01977"
"124.5000","2.4886","6.31397","0.01983"
"124.8000","2.4944","6.31336","0.01990"
"125.1000","2.5006","6.31493","0.01996"
"125.4000","2.5064","6.31448","0.02002"
"125.7000","2.5126","6.31681","0.02009"
"126.0000","2.5182","6.31513","0.02015"
"126.3000","2.5246","6.31963","0.02022"
"126.6000","2.5306","6.31956","0.02028"
"126.9000","2.5365","6.31986","0.02035"
"127.2000","2.5425","6.32005","0.02041"
"127.5000","2.5484","6.32024","0.02047"
"127.8000","2.5546","6.32273","0.02054"
"128.1000","2.5603","6.32090","0.02060"
"128.4000","2.5666","6.32566","0.02066"
"128.7000","2.5726","6.32432","0.02073"
"129.0000","2.5785","6.32599","0.02079"
"129.3000","2.5844","6.32455","0.02086"
"129.6000","2.5905","6.32662","0.02092"
"129.9000","2.5965","6.32691","0.02099"
"130.2000","2.6024","6.32705","0.02105"
"130.5000","2.6084","6.32901","0.02111"
"130.8000","2.6147","6.33084","0.02117"
"131.1000","2.6204","6.31572","0.02122"
"131.4000","2.6265","6.32530","0.02128"
"131.7000","2.6323","6.32937","0.02134"
"132.0000","2.6385","6.33345","0.02140"
"132.3000","2.6444","6.33338","0.02146"
"132.6000","2.6505","6.33564","0.02152"
"132.9000","2.6566","6.33681","0.02159"
"133.2000","2.6624","6.33560","0.02165"
"133.5000","2.6686","6.33733","0.02171"
"133.8000","2.6743","6.33597","0.02178"
"134.1000","2.6807","6.33968","0.02184"
"134.4000","2.6863","6.33729","0.02190"
"134.7000","2.6926","6.34161","0.02197"
"135.0000","2.6985","6.34088","0.02203"
"135.3000","2.7046","6.34205","0.02209"
"135.6000","2.7105","6.34105","0.02215"
"135.9000","2.7164","6.34164","0.02221"
"136.2000","2.7225","6.34421","0.02228"
"136.5000","2.7284","6.34350","0.02234"
"136.8000","2.7345","6.34594","0.02240"
"137.1000","2.7406","6.34589","0.02247"
"137.4000","2.7465","6.34652","0.02253"
"137.7000","2.7525","6.34627","0.02259"
"138.0000","2.7584","6.34711","0.02265"
"138.3000","2.7646","6.34900","0.02272"
"138.6000","2.7705","6.34873","0.02278"
"138.9000","2.7764","6.34975","0.02284"
"139.2000","2.7826","6.35161","0.02290"
"139.5000","2.7884","6.35116","0.02296"
"139.8000","2.7946","6.35235","0.02303"
"140.1000","2.8002","6.35083","0.02309"
"140.4000","2.8067","6.35519","0.02315"
"140.7000","2.8124","6.35420","0.02321"
"141.0000","2.8186","6.35633","0.02327"
"141.3000","2.8245","6.35644","0.02334"
"141.6000","2.8305","6.35671","0.02340"
"141.9000","2.8365","6.35766","0.02346"
"142.2000","2.8423","6.35661","0.02352"
"142.5000","2.8487","6.36075","0.02358"
"142.8000","2.8544","6.35920","0.02364"
"143.1000","2.8605","6.36141","0.02371"
"143.4000","2.8664","6.36105","0.02377"
"143.7000","2.8726","6.36255","0.02383"
"144.0000","2.8785","6.36242","0.02389"
"144.3000","2.8844","6.36204","0.02395"
"144.6000","2.8905","6.36494","0.02402"
"144.9000","2.8966","6.36523","0.02408"
"145.2000","2.9024","6.36588","0.02414"
"145.5000","2.9085","6.36623","0.02420"
"145.8000","2.9144","6.36691","0.02426"
"146.1000","2.9205","6.36754","0.02432"
"146.4000","2.9264","6.36755","0.02438"
"146.7000","2.9326","6.37007","0.02445"
"147.0000","2.9385","6.37052","0.02451"
"147.3000","2.9444","6.37064","0.02457"
"147.6000","2.9505","6.37195","0.02463"
"147.9000","2.9564","6.37195","0.02469"
"148.2000","2.9626","6.37327","0.02476"
"148.5000","2.9683","6.37177","0.02481"
"148.8000","2.9746","6.37531","0.02488"
"149.1000","2.9805","6.37573","0.02494"
"149.4000","2.9865","6.37600","0.02500"
"149.7000","2.9925","6.37669","0.02506"
"150.0000","2.9984","6.37637","0.02512"
"150.3000","3.0046","6.37892","0.02518"
"150.6000","3.0104","6.37694","0.02524"
"150.9000","3.0166","6.38087","0.02531"
"151.2000","3.0225","6.37986","0.02537"
"151.5000","3.0284","6.38143","0.02542"
"151.8000","3.0345","6.38096","0.02549"
"152.1000","3.0405","6.38257","0.02555"
"152.4000","3.0466","6.38311","0.02561"
"152.7000","3.0524","6.38263","0.02567"
"153.0000","3.0585","6.38483","0.02573"
"153.3000","3.0645","6.38573","0.02579"
"153.6000","3.0704","6.38622","0.02585"
"153.9000","3.0765","6.38621","0.02592"
"154.2000","3.0824","6.38697","0.02597"
"154.5000","3.0886","6.38752","0.02604"
"154.8000","3.0945","6.37156","0.02607"
"155.1000","3.1005","6.38324","0.02612"
"155.4000","3.1066","6.38956","0.02618"
"155.7000","3.1123","6.39030","0.02624"
"156.0000","3.1185","6.39329","0.02630"
"156.3000","3.1243","6.39176","0.02636"
"156.6000","3.1307","6.39584","0.02642"
"156.9000","3.1364","6.39264","0.02648"
"157.2000","3.1426","6.39620","0.02654"
"157.5000","3.1484","6.39490","0.02660"
"157.8000","3.1545","6.39640","0.02666"
"158.1000","3.1605","6.39620","0.02672"
"158.4000","3.1664","6.39641","0.02678"
"158.7000","3.1726","6.39923","0.02684"
"159.0000","3.1785","6.39792","0.02690"
"159.3000","3.1845","6.39995","0.02696"
"159.6000","3.1905","6.39917","0.02702"
"159.9000","3.1964","6.40069","0.02708"
"160.2000","3.2024","6.40037","0.02714"
"160.5000","3.2085","6.40151","0.02720"
"160.8000","3.2146","6.40274","0.02726"
"161.1000","3.2205","6.40286","0.02732"
"161.4000","3.2264","6.40319","0.02738"
"161.7000","3.2325","6.40495","0.02744"
"162.0000","3.2383","6.40418","0.02750"
"162.3000","3.2446","6.40597","0.02756"
"162.6000","3.2503","6.40455","0.02762"
"162.9000","3.2567","6.40834","0.02768"
"163.2000","3.2625","6.40745","0.02774"
"163.5000","3.2685","6.40864","0.02780"
"163.8000","3.2745","6.40874","0.02785"
"164.1000","3.2803","6.40907","0.02791"
"164.4000","3.2865","6.41102","0.02797"
"164.7000","3.2924","6.40991","0.02803"
"165.0000","3.2988","6.41377","0.02810"
"165.3000","3.3045","6.41159","0.02815"
"165.6000","3.3105","6.41361","0.02821"
"165.9000","3.3164","6.41278","0.02827"
"166.2000","3.3225","6.41478","0.02833"
"166.5000","3.3285","6.41495","0.02839"
"166.8000","3.3344","6.41419","0.02845"
"167.1000","3.3406","6.41700","0.02851"
"167.4000","3.3466","6.41697","0.02857"
"167.7000","3.3525","6.41754","0.02863"
"168.0000","3.3585","6.41716","0.02869"
"168.3000","3.3643","6.41816","0.02874"
"168.6000","3.3705","6.41910","0.02880"
"168.9000","3.3764","6.41915","0.02886"
"169.2000","3.3826","6.42124","0.02892"
"169.5000","3.3886","6.42197","0.02898"
"169.8000","3.3944","6.42134","0.02904"
"170.1000","3.4005","6.42253","0.02910"
"170.4000","3.4063","6.42263","0.02915"
"170.7000","3.4126","6.42503","0.02921"
"171.0000","3.4184","6.42303","0.02927"
"171.3000","3.4247","6.42642","0.02934"
"171.6000","3.4306","6.42646","0.02939"
"171.9000","3.4365","6.42634","0.02945"
"172.2000","3.4424","6.42657","0.02951"
"172.5000","3.4483","6.42670","0.02957"
"172.8000","3.4546","6.42959","0.02963"
"173.1000","3.4604","6.42756","0.02969"
"173.4000","3.4666","6.43151","0.02974"
"173.7000","3.4725","6.42994","0.02980"
"174.0000","3.4785","6.43142","0.02986"
"174.3000","3.4843","6.42997","0.02992"
"174.6000","3.4904","6.43199","0.02998"
"174.9000","3.4965","6.43301","0.03003"
"175.2000","3.5025","6.43267","0.03009"
"175.5000","3.5085","6.43404","0.03015"
"175.8000","3.5146","6.43560","0.03021"
"176.1000","3.5204","6.43449","0.03026"
"176.4000","3.5265","6.43526","0.03032"
"176.7000","3.5322","6.43479","0.03038"
"177.0000","3.5386","6.43809","0.03044"
"177.3000","3.5445","6.43710","0.03050"
"177.6000","3.5506","6.43869","0.03056"
"177.9000","3.5566","6.43959","0.03061"
"178.2000","3.5624","6.43853","0.03067"
"178.5000","3.5685","6.44037","0.03073"
"178.8000","3.5743","6.43902","0.03078"
"179.1000","3.5807","6.44349","0.03085"
"179.4000","3.5864","6.44027","0.03090"
"179.7000","3.5926","6.44404","0.03096"
"180.0000","3.5985","6.44315","0.03102"
"180.3000","3.6046","6.44438","0.03107"
"180.6000","3.6104","6.44336","0.03113"
"180.9000","3.6164","6.44381","0.03119"
"181.2000","3.6226","6.44683","0.03125"
"181.5000","3.6285","6.44555","0.03130"
"181.8000","3.6346","6.44727","0.03136"
"182.1000","3.6405","6.44695","0.03142"
"182.4000","3.6464","6.44756","0.03147"
"182.7000","3.6524","6.44738","0.03153"
"183.0000","3.6583","6.44811","0.03159"
"183.3000","3.6646","6.45066","0.03165"
"183.6000","3.6705","6.44992","0.03170"
"183.9000","3.6765","6.45037","0.03176"
"184.2000","3.6826","6.45170","0.03182"
"184.5000","3.6884","6.45107","0.03187"
"184.8000","3.6945","6.45213","0.03193"
"185.1000","3.7002","6.45083","0.03198"
"185.4000","3.7066","6.45521","0.03204"
"185.7000","3.7125","6.45422","0.03210"
"186.0000","3.7186","6.45514","0.03215"
"186.3000","3.7245","6.45548","0.03221"
"186.6000","3.7304","6.45534","0.03227"
"186.9000","3.7365","6.45659","0.03232"
"187.2000","3.7423","6.45548","0.03238"
"187.5000","3.7487","6.45971","0.03243"
"187.8000","3.7545","6.45774","0.03249"
"188.1000","3.7606","6.45959","0.03255"
"188.4000","3.7665","6.45861","0.03260"
"188.7000","3.7725","6.45991","0.03266"
"189.0000","3.7785","6.44999","0.03271"
"189.3000","3.7843","6.45025","0.03275"
"189.6000","3.7905","6.45926","0.03280"
"189.9000","3.7966","6.46174","0.03286"
"190.2000","3.8025","6.46295","0.03291"
"190.5000","3.8085","6.46291","0.03297"
"190.8000","3.8144","6.46363","0.03302"
"191.1000","3.8204","6.46405","0.03308"
"191.4000","3.8263","6.46413","0.03313"
"191.7000","3.8326","6.46646","0.03319"
"192.0000","3.8386","6.46729","0.03325"
"192.3000","3.8444","6.46591","0.03330"
"192.6000","3.8506","6.46753","0.03336"
"192.9000","3.8564","6.46662","0.03341"
"193.2000","3.8626","6.46869","0.03347"
"193.5000","3.8683","6.46627","0.03352"
"193.8000","3.8746","6.47053","0.03357"
"194.1000","3.8806","6.47048","0.03363"
"194.4000","3.8865","6.47039","0.03368"
"194.7000","3.8925","6.47043","0.03374"
"195.0000","3.8984","6.46996","0.03379"
"195.3000","3.9046","6.47235","0.03385"
"195.6000","3.9103","6.47046","0.03390"
"195.9000","3.9167","6.47472","0.03396"
"196.2000","3.9226","6.47292","0.03401"
"196.5000","3.9285","6.47413","0.03406"
"196.8000","3.9344","6.47265","0.03412"
"197.1000","3.9405","6.47463","0.03417"
"197.4000","3.9465","6.47461","0.03423"
"197.7000","3.9524","6.47427","0.03428"
"198.0000","3.9584","6.47601","0.03433"
"198.3000","3.9646","6.47754","0.03439"
"198.6000","3.9704","6.47618","0.03444"
"198.9000","3.9765","6.47682","0.03450"
"199.2000","3.9823","6.47637","0.03455"
"199.5000","3.9886","6.47866","0.03460"
"199.8000","3.9944","6.47790","0.03466"
"200.1000","4.0005","6.47996","0.03471"
"200.4000","4.0067","6.48109","0.03476"
"200.7000","4.0124","6.47928","0.03482"
"201.0000","4.0186","6.48111","0.03487"
"201.3000","4.0243","6.47967","0.03492"
"201.6000","4.0307","6.48343","0.03498"
"201.9000","4.0363","6.48011","0.03503"
"202.2000","4.0426","6.48425","0.03508"
"202.5000","4.0485","6.48314","0.03513"
"202.8000","4.0546","6.48417","0.03519"
"203.1000","4.0604","6.48306","0.03524"
"203.4000","4.0664","6.48339","0.03529"
"203.7000","4.0726","6.48570","0.03534"
"204.0000","4.0784","6.48465","0.03539"
"204.3000","4.0845","6.48663","0.03544"
"204.6000","4.0906","6.48628","0.03550"
"204.9000","4.0965","6.48665","0.03555"
"205.2000","4.1024","6.48603","0.03560"
"205.5000","4.1084","6.48653","0.03565"
"205.8000","4.1146","6.48823","0.03570"
"206.1000","4.1205","6.48771","0.03575"
"206.4000","4.1264","6.48847","0.03580"
"206.7000","4.1326","6.49007","0.03585"
"207.0000","4.1384","6.48918","0.03591"
"207.3000","4.1446","6.49020","0.03596"
"207.6000","4.1502","6.48833","0.03601"
"207.9000","4.1566","6.49213","0.03606"
"208.2000","4.1624","6.49112","0.03611"
"208.5000","4.1686","6.49257","0.03616"
"208.8000","4.1746","6.49277","0.03621"
"209.1000","4.1805","6.49227","0.03626"
"209.4000","4.1865","6.49337","0.03631"
"209.7000","4.1923","6.49188","0.03636"
"210.0000","4.1987","6.49569","0.03641"
"210.3000","4.2044","6.49357","0.03646"
"210.6000","4.2105","6.49564","0.03651"
"210.9000","4.2164","6.49474","0.03656"
"211.2000","4.2225","6.49605","0.03661"
"211.5000","4.2285","6.49558","0.03666"
"211.8000","4.2344","6.49467","0.03671"
"212.1000","4.2405","6.49719","0.03676"
"212.4000","4.2465","6.49711","0.03680"
"212.7000","4.2524","6.49774","0.03685"
"213.0000","4.2585","6.49732","0.03690"
"213.3000","4.2644","6.49796","0.03695"
"213.6000","4.2705","6.49797","0.03700"
"213.9000","4.2764","6.49770","0.03705"
"214.2000","4.2826","6.49940","0.03710"
"214.5000","4.2885","6.50008","0.03714"
"214.8000","4.2944","6.49941","0.03719"
"215.1000","4.3006","6.50092","0.03724"
"215.4000","4.3064","6.49992","0.03729"
"215.7000","4.3126","6.50162","0.03733"
"216.0000","4.3183","6.49939","0.03738"
"216.3000","4.3246","6.50287","0.03743"
"216.6000","4.3305","6.50254","0.03747"
"216.9000","4.3365","6.50281","0.03752"
"217.2000","4.3425","6.50298","0.03757"
"217.5000","4.3484","6.50246","0.03761"
"217.8000","4.3546","6.50447","0.03766"
"218.1000","4.3604","6.50220","0.03771"
"218.4000","4.3667","6.50580","0.03775"
"218.7000","4.3725","6.50376","0.03780"
"219.0000","4.3785","6.50532","0.03784"
"219.3000","4.3844","6.50397","0.03789"
"219.6000","4.3905","6.50563","0.03793"
"219.9000","4.3965","6.50537","0.03798"
"220.2000","4.4024","6.50471","0.03802"
"220.5000","4.4084","6.50582","0.03807"
"220.8000","4.4145","6.50731","0.03811"
"221.1000","4.4204","6.50641","0.03816"
"221.4000","4.4265","6.50700","0.03820"
"221.7000","4.4324","6.50633","0.03824"
"222.0000","4.4386","6.50800","0.03829"
"222.3000","4.4445","6.50716","0.03833"
"222.6000","4.4505","6.50825","0.03837"
"222.9000","4.4566","6.50883","0.03842"
"223.2000","4.4623","6.50752","0.03846"
"223.5000","4.4686","6.50941","0.03850"
"223.8000","4.4743","6.50759","0.03855"
"224.1000","4.4808","6.51144","0.03859"
"224.4000","4.4864","6.50780","0.03863"
"224.7000","4.4926","6.51098","0.03867"
"225.0000","4.4984","6.50931","0.03871"
"225.3000","4.5045","6.51083","0.03876"
"225.6000","4.5104","6.50989","0.03879"
"225.9000","4.5164","6.50986","0.03884"
"226.2000","4.5226","6.51163","0.03888"
"226.5000","4.5285","6.51059","0.03892"
"226.8000","4.5345","6.51172","0.03896"
"227.1000","4.5405","6.51101","0.03900"
"227.4000","4.5464","6.51132","0.03904"
"227.7000","4.5524","6.51122","0.03907"
"228.0000","4.5584","6.51115","0.03911"
"228.3000","4.5646","6.51248","0.03915"
"228.6000","4.5705","6.51167","0.03919"
"228.9000","4.5764","6.51175","0.03923"
"229.2000","4.5825","6.51281","0.03927"
"229.5000","4.5883","6.51182","0.03930"
"229.8000","4.5946","6.51294","0.03934"
"230.1000","4.6003","6.51091","0.03938"
"230.4000","4.6067","6.51422","0.03942"
"230.7000","4.6125","6.51268","0.03945"
"231.0000","4.6186","6.51332","0.03949"
"231.3000","4.6245","6.51288","0.03952"
"231.6000","4.6304","6.51272","0.03956"
"231.9000","4.6365","6.51390","0.03960"
"232.2000","4.6424","6.51194","0.03963"
"232.5000","4.6488","6.51554","0.03967"
"232.8000","4.6545","6.51275","0.03970"
"233.1000","4.6605","6.51428","0.03974"
"233.4000","4.6664","6.51275","0.03977"
"233.7000","4.6725","6.51369","0.03980"
"234.0000","4.6785","6.51347","0.03983"
"234.3000","4.6844","6.51201","0.03987"
"234.6000","4.6906","6.51436","0.03990"
"234.9000","4.6966","6.51348","0.03993"
"235.2000","4.7025","6.51327","0.03996"
"235.5000","4.7084","6.51216","0.03999"
"235.8000","4.7143","6.51263","0.04003"
"236.1000","4.7205","6.51288","0.04006"
"236.4000","4.7264","6.51221","0.04009"
"236.7000","4.7326","6.51333","0.04012"
"237.0000","4.7386","6.51327","0.04015"
"237.3000","4.7444","6.51169","0.04017"
"237.6000","4.7505","6.51239","0.04020"
"237.9000","4.7563","6.51103","0.04023"
"238.2000","4.7626","6.51313","0.04026"
"238.5000","4.7683","6.50999","0.04029"
"238.8000","4.7747","6.51302","0.04031"
"239.1000","4.7806","6.51160","0.04034"
"239.4000","4.7865","6.51107","0.04037"
"239.7000","4.7925","6.51020","0.04039"
"240.0000","4.7984","6.50913","0.04042"
"240.3000","4.8046","6.51121","0.04044"
"240.6000","4.8104","6.50807","0.04046"
"240.9000","4.8167","6.51112","0.04049"
"241.2000","4.8225","6.50840","0.04052"
"241.5000","4.8285","6.50888","0.04054"
"241.8000","4.8343","6.50651","0.04056"
"242.1000","4.8404","6.50734","0.04058"
"242.4000","4.8465","6.50705","0.04061"
"242.7000","4.8525","6.50573","0.04063"
"243.0000","4.8585","6.50571","0.04065"
"243.3000","4.8647","6.50608","0.04067"
"243.6000","4.8704","6.50368","0.04069"
"243.9000","4.8765","6.50315","0.04071"
"244.2000","4.8822","6.50160","0.04073"
"244.5000","4.8886","6.50344","0.04074"
"244.8000","4.8944","6.50122","0.04076"
"245.1000","4.9006","6.50142","0.04078"
"245.4000","4.9066","6.50075","0.04080"
"245.7000","4.9124","6.49822","0.04081"
"246.0000","4.9185","6.49848","0.04083"
"246.3000","4.9243","6.49546","0.04084"
"246.6000","4.9307","6.49833","0.04086"
"246.9000","4.9364","6.49342","0.04088"
"247.2000","4.9427","6.49568","0.04089"
"247.5000","4.9485","6.49266","0.04090"
"247.8000","4.9546","6.49228","0.04092"
"248.1000","4.9604","6.48931","0.04093"
"248.4000","4.9663","6.48785","0.04094"
"248.7000","4.9726","6.48918","0.04096"
"249.0000","4.9785","6.48572","0.04097"
"249.3000","4.9846","6.48522","0.04098"
"249.6000","4.9905","6.48254","0.04099"
"249.9000","4.9964","6.48116","0.04100"
"250.2000","5.0024","6.47860","0.04101"
"250.5000","5.0083","6.47696","0.04102"
"250.8000","5.0146","6.47701","0.04103"
"251.1000","5.0206","6.47367","0.04103"
"251.4000","5.0264","6.47145","0.04104"
"251.7000","5.0326","6.47023","0.04105"
"252.0000","5.0384","6.46666","0.04106"
"252.3000","5.0446","6.46500","0.04106"
"252.6000","5.0502","6.46054","0.04107"
"252.9000","5.0567","6.46226","0.04108"
"253.2000","5.0625","6.45762","0.04108"
"253.5000","5.0686","6.45594","0.04109"
"253.8000","5.0745","6.45199","0.04109"
"254.1000","5.0804","6.44905","0.04110"
"254.4000","5.0865","6.44650","0.04110"
"254.7000","5.0923","6.44164","0.04110"
"255.0000","5.0987","6.44227","0.04111"
"255.3000","5.1045","6.43620","0.04111"
"255.6000","5.1106","6.43399","0.04111"
"255.9000","5.1165","6.42873","0.04111"
"256.2000","5.1225","6.42587","0.04112"
"256.5000","5.1284","6.42154","0.04112"
"256.8000","5.1343","6.41642","0.04112"
"257.1000","5.1405","6.41539","0.04112"
"257.4000","5.1466","6.41031","0.04112"
"257.7000","5.1524","6.40546","0.04112"
"258.0000","5.1585","6.39994","0.04112"
"258.3000","5.1643","6.39564","0.04112"
"258.6000","5.1705","6.39102","0.04112"
"258.9000","5.1763","6.38540","0.04112"
"259.2000","5.1826","6.38262","0.04112"
"259.5000","5.1886","6.37684","0.04112"
"259.8000","5.1945","6.37058","0.04112"
"260.1000","5.2005","6.36511","0.04111"
"260.4000","5.2064","6.35902","0.04111"
"260.7000","5.2126","6.35408","0.04111"
"261.0000","5.2182","6.34595","0.04111"
"261.3000","5.2246","6.34351","0.04111"
"261.6000","5.2306","6.33652","0.04110"
"261.9000","5.2365","6.32914","0.04110"
"262.2000","5.2425","6.32241","0.04110"
"262.5000","5.2484","6.31497","0.04109"
"262.8000","5.2545","6.31075","0.04109"
"263.1000","5.2603","6.30087","0.04109"
"263.4000","5.2666","6.29807","0.04108"
"263.7000","5.2726","6.28798","0.04108"
"264.0000","5.2785","6.28194","0.04108"
"264.3000","5.2845","6.27232","0.04107"
"264.6000","5.2905","6.26633","0.04107"
"264.9000","5.2966","6.25842","0.04107"
"265.2000","5.3024","6.24960","0.04106"
"265.5000","5.3085","6.24394","0.04105"
"265.8000","5.3146","6.23546","0.04105"
"266.1000","5.3205","6.22682","0.04105"
"266.4000","5.3265","6.21687","0.04104"
"266.7000","5.3324","6.20935","0.04104"
"267.0000","5.3385","6.20130","0.04103"
"267.3000","5.3444","6.19214","0.04103"
"267.6000","5.3505","6.18391","0.04102"
"267.9000","5.3567","6.17601","0.04102"
"268.2000","5.3624","6.16431","0.04101"
"268.5000","5.3686","6.15656","0.04100"
"268.8000","5.3743","6.14496","0.04100"
"269.1000","5.3807","6.13916","0.04099"
"269.4000","5.3863","6.12575","0.04098"
"269.7000","5.3926","6.12025","0.04098"
"270.0000","5.3985","6.10787","0.04098"
"270.3000","5.4045","6.09895","0.04097"
"270.6000","5.4105","6.08692","0.04096"
"270.9000","5.4164","6.07667","0.04095"
"271.2000","5.4226","6.06884","0.04095"
"271.5000","5.4284","6.05594","0.04094"
"271.8000","5.4346","6.04800","0.04094"
"272.1000","5.4405","6.03493","0.04093"
"272.4000","5.4465","6.02556","0.04092"
"272.7000","5.4524","6.01202","0.04091"
"273.0000","5.4584","6.00212","0.04091"
"273.3000","5.4645","5.99137","0.04090"
"273.6000","5.4705","5.97960","0.04089"
"273.9000","5.4764","5.96851","0.04089"
"274.2000","5.4827","5.95708","0.04088"
"274.5000","5.4884","5.94405","0.04087"
"274.8000","5.4946","5.93171","0.04086"
"275.1000","5.5003","5.91857","0.04085"
"275.4000","5.5066","5.90934","0.04085"
"275.7000","5.5124","5.89600","0.04084"
"276.0000","5.5185","5.88431","0.04083"
"276.3000","5.5245","5.87090","0.04082"
"276.6000","5.5305","5.85780","0.04082"
"276.9000","5.5365","5.84523","0.04081"
"277.2000","5.5424","5.83017","0.04080"
"277.5000","5.5487","5.82052","0.04079"
"277.8000","5.5544","5.80456","0.04078"
"278.1000","5.5605","5.79400","0.04077"
"278.4000","5.5664","5.77777","0.04076"
"278.7000","5.5726","5.76538","0.04075"
"279.0000","5.5785","5.74993","0.04074"
"279.3000","5.5844","5.73523","0.04073"
"279.6000","5.5905","5.72349","0.04073"
"279.9000","5.5965","5.70768","0.04071"
"280.2000","5.6024","5.69469","0.04071"
"280.5000","5.6085","5.67711","0.04069"
"280.8000","5.6144","5.66434","0.04069"
"281.1000","5.6205","5.64689","0.04067"
"281.4000","5.6264","5.63263","0.04066"
"281.7000","5.6326","5.61763","0.04065"
"282.0000","5.6386","5.60261","0.04064"
"282.3000","5.6444","5.58605","0.04063"
"282.6000","5.6505","5.56981","0.04062"
"282.9000","5.6564","5.55300","0.04061"
"283.2000","5.6626","5.53671","0.04060"
"283.5000","5.6683","5.51886","0.04058"
"283.8000","5.6746","5.50491","0.04057"
"284.1000","5.6805","5.48772","0.04056"
"284.4000","5.6865","5.47025","0.04055"
"284.7000","5.6925","5.45232","0.04054"
"285.0000","5.6985","5.43418","0.04053"
"285.3000","5.7046","5.41736","0.04052"
"285.6000","5.7104","5.39637","0.04050"
"285.9000","5.7166","5.38188","0.04049"
"286.2000","5.7225","5.36051","0.04047"
"286.5000","5.7284","5.34391","0.04046"
"286.8000","5.7344","5.32078","0.04045"
"287.1000","5.7405","5.30277","0.04043"
"287.4000","5.7465","5.28006","0.04042"
"287.7000","5.7524","5.25789","0.04040"
"288.0000","5.7584","5.23754","0.04039"
"288.3000","5.7646","5.21465","0.04037"
"288.6000","5.7704","5.19129","0.04035"
"288.9000","5.7765","5.16514","0.04033"
"289.2000","5.7824","5.14261","0.04032"
"289.5000","5.7886","5.11721","0.04030"
"289.8000","5.7945","5.09124","0.04028"
"290.1000","5.8006","5.06488","0.04026"
"290.4000","5.8066","5.03668","0.04024"
"290.7000","5.8123","5.00607","0.04021"
"291.0000","5.8186","4.97431","0.04019"
"291.3000","5.8244","4.94039","0.04017"
"291.6000","5.8307","4.90410","0.04014"
"291.9000","5.8364","4.86316","0.04011"
"292.2000","5.8426","4.82568","0.04008"
"292.5000","5.8484","4.78453","0.04004"
"292.8000","5.8545","4.73608","0.04001"
"293.1000","5.8605","4.65059","0.03994"
"293.3650","5.8658","4.44211","0.03979"
"293.3820","5.8662","4.12912","0.03977"
"293.3860","5.8663","3.88693","0.03950"