File: Coupon Test Data/Tensile Test_Neebajan_Alan_13.csv
Time,Displacement,Force,Strain 1
(s),(mm),(kN),(mm/mm)
"0.0000","0.0000","0.19702","-0.00022"
"0.4000","0.0063","0.28198","-0.00019"
"0.8000","0.0145","0.39718","-0.00014"
"1.2000","0.0226","0.50830","-0.00010"
"1.6000","0.0304","0.61063","-0.00006"
"2.0000","0.0385","0.71594","-0.00002"
"2.4000","0.0465","0.81794","0.00002"
"2.8000","0.0545","0.91583","0.00006"
"3.2000","0.0624","1.01203","0.00010"
"3.6000","0.0705","1.10163","0.00014"
"4.0000","0.0786","1.19643","0.00018"
"4.4000","0.0865","1.28923","0.00021"
"4.8000","0.0946","1.38019","0.00025"
"5.2000","0.1025","1.46159","0.00028"
"5.6000","0.1105","1.55055","0.00032"
"6.0000","0.1184","1.63455","0.00035"
"6.4000","0.1266","1.71400","0.00039"
"6.8000","0.1347","1.79903","0.00042"
"7.2000","0.1425","1.87783","0.00045"
"7.6000","0.1506","1.95195","0.00048"
"8.0000","0.1584","2.02903","0.00051"
"8.4000","0.1666","2.10738","0.00054"
"8.8000","0.1745","2.17706","0.00057"
"9.2000","0.1825","2.25269","0.00061"
"9.6000","0.1906","2.32469","0.00063"
"10.0000","0.1986","2.39439","0.00066"
"10.4000","0.2066","2.46610","0.00069"
"10.8000","0.2145","2.52888","0.00072"
"11.2000","0.2226","2.60169","0.00075"
"11.6000","0.2304","2.66814","0.00077"
"12.0000","0.2385","2.73083","0.00080"
"12.4000","0.2465","2.80071","0.00083"
"12.8000","0.2546","2.86672","0.00086"
"13.2000","0.2627","2.92784","0.00088"
"13.6000","0.2704","2.99000","0.00091"
"14.0000","0.2785","3.05417","0.00094"
"14.4000","0.2864","3.11303","0.00096"
"14.8000","0.2945","3.17667","0.00099"
"15.2000","0.3026","3.23309","0.00101"
"15.6000","0.3106","3.29419","0.00104"
"16.0000","0.3186","3.35319","0.00106"
"16.4000","0.3265","3.40634","0.00108"
"16.8000","0.3346","3.46955","0.00111"
"17.2000","0.3424","3.52705","0.00113"
"17.6000","0.3506","3.58422","0.00116"
"18.0000","0.3585","3.64461","0.00118"
"18.4000","0.3665","3.69935","0.00120"
"18.8000","0.3747","3.76098","0.00123"
"19.2000","0.3825","3.81849","0.00125"
"19.6000","0.3906","3.87509","0.00128"
"20.0000","0.3984","3.93334","0.00130"
"20.4000","0.4065","3.98752","0.00132"
"20.8000","0.4145","4.04993","0.00135"
"21.2000","0.4226","4.10710","0.00137"
"21.6000","0.4306","4.16521","0.00140"
"22.0000","0.4386","4.22362","0.00142"
"22.4000","0.4466","4.28019","0.00145"
"22.8000","0.4544","4.33471","0.00146"
"23.2000","0.4626","4.39338","0.00149"
"23.6000","0.4706","4.45018","0.00151"
"24.0000","0.4786","4.50641","0.00154"
"24.4000","0.4866","4.56212","0.00156"
"24.8000","0.4945","4.61826","0.00158"
"25.2000","0.5026","4.67476","0.00161"
"25.6000","0.5104","4.72865","0.00163"
"26.0000","0.5186","4.78495","0.00165"
"26.4000","0.5265","4.84108","0.00168"
"26.8000","0.5345","4.89427","0.00170"
"27.2000","0.5426","4.94828","0.00172"
"27.6000","0.5506","5.00155","0.00174"
"28.0000","0.5587","5.05646","0.00177"
"28.4000","0.5664","5.10633","0.00179"
"28.8000","0.5746","5.15959","0.00181"
"29.2000","0.5825","5.21425","0.00183"
"29.6000","0.5905","5.26495","0.00186"
"30.0000","0.5986","5.32026","0.00188"
"30.4000","0.6066","5.37024","0.00190"
"30.8000","0.6145","5.42409","0.00192"
"31.2000","0.6224","5.47354","0.00194"
"31.6000","0.6306","5.52545","0.00196"
"32.0000","0.6385","5.57848","0.00199"
"32.4000","0.6465","5.62938","0.00201"
"32.8000","0.6546","5.68132","0.00203"
"33.2000","0.6626","5.73332","0.00206"
"33.6000","0.6706","5.78566","0.00208"
"34.0000","0.6784","5.83496","0.00210"
"34.4000","0.6867","5.88910","0.00212"
"34.8000","0.6944","5.94058","0.00215"
"35.2000","0.7024","5.99094","0.00217"
"35.6000","0.7106","6.04518","0.00219"
"36.0000","0.7187","6.09872","0.00222"
"36.4000","0.7266","6.14995","0.00224"
"36.8000","0.7344","6.19991","0.00226"
"37.2000","0.7427","6.25422","0.00228"
"37.6000","0.7504","6.30529","0.00231"
"38.0000","0.7585","6.35738","0.00233"
"38.4000","0.7666","6.41114","0.00235"
"38.8000","0.7747","6.46520","0.00238"
"39.2000","0.7825","6.51621","0.00240"
"39.6000","0.7904","6.56601","0.00242"
"40.0000","0.7987","6.62223","0.00245"
"40.4000","0.8064","6.67307","0.00247"
"40.8000","0.8145","6.72402","0.00249"
"41.2000","0.8226","6.77854","0.00252"
"41.6000","0.8306","6.83157","0.00255"
"42.0000","0.8385","6.88261","0.00257"
"42.4000","0.8465","6.93327","0.00260"
"42.8000","0.8548","6.98811","0.00262"
"43.2000","0.8623","7.03709","0.00265"
"43.6000","0.8704","7.08832","0.00267"
"44.0000","0.8786","7.14228","0.00270"
"44.4000","0.8867","7.19533","0.00273"
"44.8000","0.8945","7.24450","0.00275"
"45.2000","0.9025","7.29392","0.00278"
"45.6000","0.9108","7.34792","0.00281"
"46.0000","0.9183","7.39412","0.00283"
"46.4000","0.9265","7.44386","0.00286"
"46.8000","0.9347","7.49692","0.00289"
"47.2000","0.9426","7.54584","0.00292"
"47.6000","0.9505","7.59237","0.00295"
"48.0000","0.9585","7.64026","0.00298"
"48.4000","0.9668","7.69145","0.00301"
"48.8000","0.9744","7.73490","0.00304"
"49.2000","0.9825","7.78062","0.00307"
"49.6000","0.9906","7.82941","0.00311"
"50.0000","0.9986","7.87271","0.00314"
"50.4000","1.0064","7.91741","0.00318"
"50.8000","1.0146","7.95792","0.00321"
"51.2000","1.0229","8.00632","0.00325"
"51.6000","1.0303","8.03457","0.00328"
"52.0000","1.0385","8.07704","0.00332"
"52.4000","1.0466","8.11973","0.00337"
"52.8000","1.0546","8.15610","0.00342"
"53.2000","1.0625","8.18874","0.00346"
"53.6000","1.0706","8.20980","0.00351"
"54.0000","1.0788","8.24695","0.00356"
"54.4000","1.0863","8.26942","0.00361"
"54.8000","1.0945","8.29708","0.00368"
"55.2000","1.1026","8.32058","0.00374"
"55.6000","1.1106","8.34043","0.00380"
"56.0000","1.1184","8.35754","0.00387"
"56.4000","1.1266","8.37411","0.00394"
"56.8000","1.1348","8.39333","0.00402"
"57.2000","1.1423","8.39945","0.00409"
"57.6000","1.1506","8.41432","0.00417"
"58.0000","1.1586","8.42756","0.00425"
"58.4000","1.1665","8.43583","0.00433"
"58.8000","1.1744","8.44582","0.00441"
"59.2000","1.1827","8.45592","0.00449"
"59.6000","1.1908","8.46347","0.00458"
"60.0000","1.1983","8.46539","0.00465"
"60.4000","1.2066","8.47723","0.00473"
"60.8000","1.2145","8.48433","0.00482"
"61.2000","1.2226","8.49023","0.00491"
"61.6000","1.2305","8.49484","0.00499"
"62.0000","1.2387","8.50207","0.00508"
"62.4000","1.2468","8.50928","0.00517"
"62.8000","1.2543","8.50787","0.00525"
"63.2000","1.2626","8.51686","0.00534"
"63.6000","1.2706","8.52127","0.00543"
"64.0000","1.2786","8.52411","0.00552"
"64.4000","1.2865","8.52822","0.00561"
"64.8000","1.2946","8.53391","0.00570"
"65.2000","1.3027","8.53935","0.00579"
"65.6000","1.3105","8.53841","0.00588"
"66.0000","1.3187","8.54464","0.00598"
"66.4000","1.3265","8.54646","0.00606"
"66.8000","1.3345","8.54950","0.00616"
"67.2000","1.3424","8.55298","0.00625"
"67.6000","1.3507","8.54679","0.00633"
"68.0000","1.3587","8.55970","0.00641"
"68.4000","1.3664","8.56062","0.00650"
"68.8000","1.3747","8.56737","0.00660"
"69.2000","1.3824","8.56773","0.00668"
"69.6000","1.3905","8.57001","0.00678"
"70.0000","1.3985","8.57298","0.00687"
"70.4000","1.4067","8.57718","0.00697"
"70.8000","1.4146","8.57933","0.00706"
"71.2000","1.4224","8.57880","0.00715"
"71.6000","1.4307","8.58519","0.00724"
"72.0000","1.4385","8.58485","0.00734"
"72.4000","1.4466","8.58735","0.00743"
"72.8000","1.4545","8.58920","0.00752"
"73.2000","1.4626","8.59305","0.00762"
"73.6000","1.4706","8.59660","0.00771"
"74.0000","1.4785","8.59531","0.00781"
"74.4000","1.4868","8.60097","0.00790"
"74.8000","1.4945","8.60026","0.00800"
"75.2000","1.5025","8.60250","0.00809"
"75.6000","1.5105","8.60496","0.00819"
"76.0000","1.5187","8.60879","0.00828"
"76.4000","1.5266","8.61033","0.00838"
"76.8000","1.5346","8.61067","0.00847"
"77.2000","1.5427","8.61547","0.00857"
"77.6000","1.5504","8.61417","0.00866"
"78.0000","1.5586","8.61808","0.00876"
"78.4000","1.5665","8.61868","0.00885"
"78.8000","1.5747","8.62234","0.00896"
"79.2000","1.5825","8.62391","0.00905"
"79.6000","1.5905","8.62412","0.00915"
"80.0000","1.5988","8.63012","0.00924"
"80.4000","1.6065","8.62800","0.00934"
"80.8000","1.6146","8.63042","0.00943"
"81.2000","1.6225","8.63225","0.00953"
"81.6000","1.6306","8.63482","0.00963"
"82.0000","1.6385","8.63651","0.00972"
"82.4000","1.6466","8.63872","0.00982"
"82.8000","1.6547","8.64213","0.00991"
"83.2000","1.6625","8.64020","0.01001"
"83.6000","1.6706","8.64346","0.01010"
"84.0000","1.6784","8.64422","0.01020"
"84.4000","1.6866","8.64827","0.01029"
"84.8000","1.6945","8.64928","0.01039"
"85.2000","1.7026","8.65032","0.01049"
"85.6000","1.7107","8.65513","0.01058"
"86.0000","1.7184","8.65281","0.01067"
"86.4000","1.7266","8.65645","0.01077"
"86.8000","1.7345","8.65715","0.01087"
"87.2000","1.7426","8.65965","0.01096"
"87.6000","1.7505","8.66068","0.01106"
"88.0000","1.7586","8.66268","0.01116"
"88.4000","1.7667","8.66690","0.01125"
"88.8000","1.7745","8.66592","0.01135"
"89.2000","1.7827","8.66885","0.01145"
"89.6000","1.7904","8.66801","0.01154"
"90.0000","1.7986","8.67183","0.01164"
"90.4000","1.8064","8.67276","0.01173"
"90.8000","1.8147","8.67494","0.01183"
"91.2000","1.8228","8.67888","0.01192"
"91.6000","1.8305","8.67722","0.01202"
"92.0000","1.8386","8.68000","0.01212"
"92.4000","1.8464","8.68010","0.01221"
"92.8000","1.8546","8.68400","0.01231"
"93.2000","1.8625","8.68438","0.01240"
"93.6000","1.8706","8.68644","0.01250"
"94.0000","1.8786","8.68946","0.01259"
"94.4000","1.8865","8.68932","0.01269"
"94.8000","1.8947","8.69311","0.01278"
"95.2000","1.9025","8.69152","0.01288"
"95.6000","1.9107","8.69557","0.01297"
"96.0000","1.9185","8.69549","0.01307"
"96.4000","1.9266","8.69722","0.01316"
"96.8000","1.9347","8.70224","0.01326"
"97.2000","1.9426","8.70107","0.01335"
"97.6000","1.9507","8.68825","0.01343"
"98.0000","1.9584","8.69891","0.01351"
"98.4000","1.9666","8.70687","0.01361"
"98.8000","1.9744","8.70792","0.01370"
"99.2000","1.9826","8.71041","0.01379"
"99.6000","1.9907","8.71340","0.01389"
"100.0000","1.9986","8.71331","0.01399"
"100.4000","2.0067","8.71491","0.01408"
"100.8000","2.0143","8.71336","0.01417"
"101.2000","2.0227","8.71914","0.01427"
"101.6000","2.0304","8.71833","0.01436"
"102.0000","2.0386","8.71983","0.01445"
"102.4000","2.0466","8.72365","0.01455"
"102.8000","2.0545","8.72372","0.01464"
"103.2000","2.0627","8.72669","0.01474"
"103.6000","2.0705","8.72534","0.01483"
"104.0000","2.0787","8.72938","0.01493"
"104.4000","2.0865","8.72863","0.01502"
"104.8000","2.0945","8.73072","0.01511"
"105.2000","2.1025","8.73425","0.01520"
"105.6000","2.1107","8.73596","0.01530"
"106.0000","2.1187","8.73737","0.01539"
"106.4000","2.1265","8.73494","0.01548"
"106.8000","2.1347","8.69563","0.01552"
"107.2000","2.1423","8.72397","0.01560"
"107.6000","2.1506","8.74135","0.01569"
"108.0000","2.1586","8.74846","0.01578"
"108.4000","2.1666","8.74922","0.01587"
"108.8000","2.1746","8.75042","0.01596"
"109.2000","2.1824","8.74903","0.01605"
"109.6000","2.1907","8.75340","0.01615"
"110.0000","2.1985","8.75148","0.01624"
"110.4000","2.2066","8.75364","0.01634"
"110.8000","2.2145","8.75562","0.01643"
"111.2000","2.2226","8.75719","0.01652"
"111.6000","2.2306","8.75929","0.01661"
"112.0000","2.2385","8.75840","0.01671"
"112.4000","2.2467","8.76303","0.01680"
"112.8000","2.2544","8.76004","0.01689"
"113.2000","2.2625","8.76310","0.01698"
"113.6000","2.2705","8.76637","0.01708"
"114.0000","2.2786","8.76760","0.01717"
"114.4000","2.2867","8.76948","0.01726"
"114.8000","2.2946","8.76915","0.01735"
"115.2000","2.3026","8.77288","0.01745"
"115.6000","2.3104","8.77116","0.01754"
"116.0000","2.3186","8.77499","0.01763"
"116.4000","2.3265","8.77663","0.01772"
"116.8000","2.3346","8.77819","0.01781"
"117.2000","2.3426","8.77965","0.01791"
"117.6000","2.3505","8.78009","0.01800"
"118.0000","2.3587","8.78459","0.01809"
"118.4000","2.3664","8.78182","0.01818"
"118.8000","2.3747","8.78622","0.01828"
"119.2000","2.3825","8.78700","0.01836"
"119.6000","2.3904","8.78731","0.01846"
"120.0000","2.3987","8.79210","0.01855"
"120.4000","2.4066","8.79237","0.01864"
"120.8000","2.4147","8.79459","0.01873"
"121.2000","2.4224","8.79264","0.01882"
"121.6000","2.4306","8.79662","0.01892"
"122.0000","2.4384","8.79793","0.01901"
"122.4000","2.4465","8.79950","0.01910"
"122.8000","2.4546","8.80140","0.01919"
"123.2000","2.4627","8.80377","0.01929"
"123.6000","2.4706","8.80546","0.01937"
"124.0000","2.4783","8.80314","0.01946"
"124.4000","2.4867","8.80924","0.01956"
"124.8000","2.4945","8.80871","0.01965"
"125.2000","2.5025","8.80922","0.01974"
"125.6000","2.5106","8.81318","0.01983"
"126.0000","2.5186","8.81402","0.01992"
"126.4000","2.5266","8.81668","0.02001"
"126.8000","2.5344","8.81512","0.02010"
"127.2000","2.5427","8.81907","0.02020"
"127.6000","2.5505","8.81904","0.02029"
"128.0000","2.5584","8.81973","0.02038"
"128.4000","2.5665","8.82298","0.02047"
"128.8000","2.5748","8.82674","0.02056"
"129.2000","2.5826","8.82676","0.02065"
"129.6000","2.5904","8.82493","0.02074"
"130.0000","2.5988","8.83114","0.02084"
"130.4000","2.6063","8.82846","0.02092"
"130.8000","2.6145","8.83129","0.02101"
"131.2000","2.6227","8.83495","0.02110"
"131.6000","2.6307","8.83587","0.02120"
"132.0000","2.6386","8.83738","0.02129"
"132.4000","2.6464","8.83649","0.02137"
"132.8000","2.6547","8.84188","0.02147"
"133.2000","2.6625","8.84074","0.02155"
"133.6000","2.6705","8.84128","0.02165"
"134.0000","2.6786","8.84463","0.02174"
"134.4000","2.6867","8.84708","0.02183"
"134.8000","2.6945","8.84779","0.02192"
"135.2000","2.7025","8.84813","0.02201"
"135.6000","2.7108","8.85356","0.02210"
"136.0000","2.7183","8.84919","0.02219"
"136.4000","2.7265","8.83199","0.02226"
"136.8000","2.7346","8.84836","0.02234"
"137.2000","2.7427","8.85629","0.02243"
"137.6000","2.7505","8.85867","0.02252"
"138.0000","2.7585","8.85966","0.02261"
"138.4000","2.7668","8.86469","0.02270"
"138.8000","2.7743","8.86080","0.02278"
"139.2000","2.7825","8.86405","0.02288"
"139.6000","2.7907","8.86721","0.02297"
"140.0000","2.7987","8.86808","0.02306"
"140.4000","2.8064","8.86778","0.02315"
"140.8000","2.8145","8.86971","0.02323"
"141.2000","2.8229","8.87582","0.02333"
"141.6000","2.8303","8.87027","0.02341"
"142.0000","2.8385","8.87359","0.02350"
"142.4000","2.8466","8.87706","0.02359"
"142.8000","2.8545","8.87717","0.02368"
"143.2000","2.8624","8.87866","0.02377"
"143.6000","2.8706","8.88130","0.02386"
"144.0000","2.8789","8.88524","0.02395"
"144.4000","2.8863","8.88021","0.02404"
"144.8000","2.8945","8.88403","0.02413"
"145.2000","2.9026","8.88716","0.02422"
"145.6000","2.9107","8.88918","0.02431"
"146.0000","2.9185","8.88883","0.02440"
"146.4000","2.9267","8.89114","0.02449"
"146.8000","2.9348","8.89562","0.02458"
"147.2000","2.9422","8.89007","0.02467"
"147.6000","2.9506","8.89521","0.02476"
"148.0000","2.9586","8.89784","0.02485"
"148.4000","2.9666","8.89805","0.02493"
"148.8000","2.9745","8.89897","0.02502"
"149.2000","2.9826","8.90190","0.02511"
"149.6000","2.9908","8.90579","0.02520"
"150.0000","2.9984","8.90198","0.02529"
"150.4000","3.0066","8.90564","0.02538"
"150.8000","3.0146","8.90703","0.02547"
"151.2000","3.0225","8.90793","0.02556"
"151.6000","3.0304","8.90935","0.02565"
"152.0000","3.0387","8.91300","0.02574"
"152.4000","3.0468","8.91587","0.02583"
"152.8000","3.0543","8.91127","0.02591"
"153.2000","3.0626","8.91617","0.02601"
"153.6000","3.0705","8.91729","0.02610"
"154.0000","3.0786","8.91870","0.02618"
"154.4000","3.0865","8.91979","0.02627"
"154.8000","3.0947","8.92343","0.02636"
"155.2000","3.1027","8.92521","0.02645"
"155.6000","3.1103","8.92196","0.02654"
"156.0000","3.1187","8.92779","0.02663"
"156.4000","3.1265","8.92741","0.02672"
"156.8000","3.1346","8.92856","0.02681"
"157.2000","3.1424","8.92928","0.02689"
"157.6000","3.1506","8.93282","0.02698"
"158.0000","3.1587","8.93572","0.02707"
"158.4000","3.1664","8.93253","0.02716"
"158.8000","3.1747","8.93791","0.02725"
"159.2000","3.1825","8.93756","0.02734"
"159.6000","3.1905","8.93807","0.02743"
"160.0000","3.1985","8.94014","0.02752"
"160.4000","3.2067","8.94384","0.02761"
"160.8000","3.2147","8.94490","0.02769"
"161.2000","3.2225","8.94321","0.02778"
"161.6000","3.2307","8.94778","0.02787"
"162.0000","3.2384","8.94663","0.02796"
"162.4000","3.2466","8.94957","0.02805"
"162.8000","3.2545","8.95006","0.02814"
"163.2000","3.2627","8.95311","0.02823"
"163.6000","3.2706","8.95460","0.02831"
"164.0000","3.2784","8.95306","0.02840"
"164.4000","3.2867","8.95867","0.02849"
"164.8000","3.2945","8.95693","0.02858"
"165.2000","3.3026","8.95865","0.02867"
"165.6000","3.3105","8.96000","0.02876"
"166.0000","3.3186","8.96247","0.02884"
"166.4000","3.3265","8.96415","0.02894"
"166.8000","3.3346","8.96458","0.02903"
"167.2000","3.3428","8.96867","0.02912"
"167.6000","3.3504","8.96604","0.02920"
"168.0000","3.3585","8.96829","0.02929"
"168.4000","3.3664","8.94150","0.02935"
"168.8000","3.3747","8.96277","0.02943"
"169.2000","3.3826","8.97190","0.02951"
"169.6000","3.3906","8.97489","0.02960"
"170.0000","3.3987","8.97972","0.02969"
"170.4000","3.4064","8.97770","0.02977"
"170.8000","3.4146","8.98067","0.02986"
"171.2000","3.4226","8.98138","0.02995"
"171.6000","3.4306","8.98334","0.03004"
"172.0000","3.4385","8.98354","0.03013"
"172.4000","3.4466","8.98464","0.03021"
"172.8000","3.4547","8.98875","0.03030"
"173.2000","3.4625","8.98660","0.03039"
"173.6000","3.4706","8.98918","0.03048"
"174.0000","3.4784","8.98872","0.03056"
"174.4000","3.4866","8.99180","0.03065"
"174.8000","3.4945","8.99289","0.03074"
"175.2000","3.5026","8.99432","0.03083"
"175.6000","3.5108","8.99811","0.03092"
"176.0000","3.5184","8.99534","0.03101"
"176.4000","3.5266","8.99822","0.03109"
"176.8000","3.5344","8.99458","0.03118"
"177.2000","3.5426","8.99002","0.03125"
"177.6000","3.5505","8.99826","0.03133"
"178.0000","3.5586","9.00356","0.03142"
"178.4000","3.5667","9.00748","0.03151"
"178.8000","3.5744","9.00594","0.03159"
"179.2000","3.5826","9.00958","0.03168"
"179.6000","3.5905","9.00815","0.03177"
"180.0000","3.5987","9.01150","0.03185"
"180.4000","3.6065","9.01109","0.03194"
"180.8000","3.6146","9.01258","0.03203"
"181.2000","3.6227","9.01733","0.03212"
"181.6000","3.6305","9.01482","0.03220"
"182.0000","3.6386","9.01729","0.03229"
"182.4000","3.6464","9.01660","0.03238"
"182.8000","3.6545","9.01956","0.03247"
"183.2000","3.6624","9.02007","0.03255"
"183.6000","3.6707","9.02275","0.03264"
"184.0000","3.6787","9.02521","0.03273"
"184.4000","3.6866","9.02413","0.03282"
"184.8000","3.6947","9.02649","0.03290"
"185.2000","3.7023","9.02493","0.03299"
"185.6000","3.7106","9.02979","0.03308"
"186.0000","3.7185","9.02945","0.03317"
"186.4000","3.7266","9.03111","0.03326"
"186.8000","3.7346","9.03399","0.03334"
"187.2000","3.7425","9.03342","0.03343"
"187.6000","3.7507","9.03662","0.03352"
"188.0000","3.7585","9.03494","0.03360"
"188.4000","3.7666","9.03839","0.03369"
"188.8000","3.7744","9.03791","0.03378"
"189.2000","3.7826","9.03983","0.03387"
"189.6000","3.7906","9.04321","0.03396"
"190.0000","3.7986","9.04361","0.03404"
"190.4000","3.8067","9.04558","0.03413"
"190.8000","3.8144","9.04330","0.03422"
"191.2000","3.8226","9.04773","0.03431"
"191.6000","3.8303","9.04659","0.03439"
"192.0000","3.8386","9.04941","0.03448"
"192.4000","3.8467","9.05280","0.03457"
"192.8000","3.8546","9.05212","0.03466"
"193.2000","3.8627","9.05382","0.03475"
"193.6000","3.8704","9.05248","0.03483"
"194.0000","3.8787","9.05723","0.03492"
"194.4000","3.8865","9.05603","0.03501"
"194.8000","3.8946","9.05783","0.03510"
"195.2000","3.9026","9.06042","0.03518"
"195.6000","3.9106","9.06161","0.03527"
"196.0000","3.9186","9.06353","0.03536"
"196.4000","3.9265","9.06177","0.03544"
"196.8000","3.9347","9.06650","0.03553"
"197.2000","3.9424","9.06403","0.03562"
"197.6000","3.9506","9.06633","0.03571"
"198.0000","3.9586","9.06965","0.03579"
"198.4000","3.9666","9.07042","0.03588"
"198.8000","3.9747","9.07221","0.03597"
"199.2000","3.9825","9.07047","0.03606"
"199.6000","3.9906","9.07440","0.03614"
"200.0000","3.9984","9.07317","0.03623"
"200.4000","4.0066","9.07627","0.03632"
"200.8000","4.0146","9.07797","0.03641"
"201.2000","4.0227","9.07953","0.03650"
"201.6000","4.0306","9.08029","0.03659"
"202.0000","4.0384","9.07937","0.03667"
"202.4000","4.0467","9.08435","0.03676"
"202.8000","4.0544","9.08129","0.03685"
"203.2000","4.0626","9.08459","0.03694"
"203.6000","4.0705","9.08647","0.03702"
"204.0000","4.0785","9.08655","0.03711"
"204.4000","4.0866","9.08998","0.03720"
"204.8000","4.0946","9.08928","0.03728"
"205.2000","4.1027","9.09244","0.03737"
"205.6000","4.1104","9.09012","0.03746"
"206.0000","4.1186","9.09321","0.03755"
"206.4000","4.1265","9.09446","0.03763"
"206.8000","4.1346","9.09651","0.03772"
"207.2000","4.1426","9.09766","0.03781"
"207.6000","4.1506","9.09760","0.03790"
"208.0000","4.1586","9.10109","0.03798"
"208.4000","4.1663","9.09790","0.03807"
"208.8000","4.1747","9.10250","0.03816"
"209.2000","4.1826","9.10353","0.03825"
"209.6000","4.1906","9.10354","0.03833"
"210.0000","4.1986","9.10621","0.03842"
"210.4000","4.2066","9.10637","0.03851"
"210.8000","4.2146","9.10921","0.03860"
"211.2000","4.2224","9.10724","0.03869"
"211.6000","4.2307","9.11083","0.03878"
"212.0000","4.2385","9.11051","0.03886"
"212.4000","4.2465","9.11169","0.03895"
"212.8000","4.2546","9.11455","0.03904"
"213.2000","4.2627","9.11579","0.03912"
"213.6000","4.2707","9.11795","0.03921"
"214.0000","4.2784","9.11480","0.03930"
"214.4000","4.2867","9.11906","0.03939"
"214.8000","4.2944","9.11868","0.03947"
"215.2000","4.3025","9.12021","0.03956"
"215.6000","4.3107","9.12336","0.03965"
"216.0000","4.3187","9.12380","0.03974"
"216.4000","4.3266","9.12458","0.03982"
"216.8000","4.3344","9.12346","0.03991"
"217.2000","4.3427","9.12839","0.04000"
"217.6000","4.3505","9.12714","0.04008"
"218.0000","4.3585","9.12803","0.04017"
"218.4000","4.3666","9.13052","0.04026"
"218.8000","4.3747","9.13183","0.04035"
"219.2000","4.3826","9.13312","0.04043"
"219.6000","4.3904","9.13166","0.04052"
"220.0000","4.3988","9.13681","0.04061"
"220.4000","4.4063","9.13389","0.04069"
"220.8000","4.4144","9.13526","0.04078"
"221.2000","4.4226","9.13929","0.04087"
"221.6000","4.4307","9.14104","0.04096"
"222.0000","4.4386","9.14048","0.04105"
"222.4000","4.4465","9.13992","0.04113"
"222.8000","4.4547","9.14433","0.04122"
"223.2000","4.4623","9.14149","0.04130"
"223.6000","4.4705","9.14423","0.04139"
"224.0000","4.4786","9.14665","0.04148"
"224.4000","4.4867","9.14812","0.04157"
"224.8000","4.4945","9.14814","0.04165"
"225.2000","4.5024","9.14772","0.04174"
"225.6000","4.5108","9.15381","0.04183"
"226.0000","4.5184","9.14960","0.04192"
"226.4000","4.5265","9.15125","0.04200"
"226.8000","4.5346","9.15484","0.04209"
"227.2000","4.5426","9.15519","0.04218"
"227.6000","4.5505","9.15585","0.04226"
"228.0000","4.5586","9.15667","0.04235"
"228.4000","4.5668","9.13953","0.04243"
"228.8000","4.5743","9.14699","0.04250"
"229.2000","4.5825","9.15642","0.04259"
"229.6000","4.5905","9.16199","0.04267"
"230.0000","4.5988","9.16537","0.04276"
"230.4000","4.6065","9.16412","0.04285"
"230.8000","4.6146","9.16455","0.04294"
"231.2000","4.6229","9.16994","0.04302"
"231.6000","4.6302","9.16405","0.04311"
"232.0000","4.6385","9.16765","0.04320"
"232.4000","4.6467","9.16932","0.04328"
"232.8000","4.6546","9.15047","0.04334"
"233.2000","4.6625","9.16328","0.04342"
"233.6000","4.6706","9.17050","0.04351"
"234.0000","4.6788","9.17687","0.04359"
"234.4000","4.6864","9.17372","0.04368"
"234.8000","4.6946","9.17645","0.04377"
"235.2000","4.7026","9.17762","0.04385"
"235.6000","4.7106","9.17849","0.04394"
"236.0000","4.7184","9.17839","0.04402"
"236.4000","4.7267","9.18129","0.04411"
"236.8000","4.7348","9.18438","0.04420"
"237.2000","4.7423","9.17803","0.04429"
"237.6000","4.7506","9.18262","0.04437"
"238.0000","4.7585","9.18405","0.04446"
"238.4000","4.7666","9.18446","0.04455"
"238.8000","4.7745","9.18543","0.04463"
"239.2000","4.7827","9.18741","0.04472"
"239.6000","4.7908","9.18962","0.04481"
"240.0000","4.7983","9.18533","0.04489"
"240.4000","4.8066","9.18984","0.04498"
"240.8000","4.8146","9.19092","0.04507"
"241.2000","4.8226","9.19095","0.04516"
"241.6000","4.8304","9.19039","0.04524"
"242.0000","4.8387","9.19428","0.04533"
"242.4000","4.8467","9.19692","0.04542"
"242.8000","4.8543","9.19217","0.04551"
"243.2000","4.8627","9.19747","0.04560"
"243.6000","4.8705","9.19687","0.04568"
"244.0000","4.8785","9.19663","0.04577"
"244.4000","4.8865","9.19883","0.04586"
"244.8000","4.8947","9.20147","0.04594"
"245.2000","4.9027","9.20284","0.04603"
"245.6000","4.9104","9.19944","0.04612"
"246.0000","4.9186","9.20331","0.04621"
"246.4000","4.9265","9.20374","0.04629"
"246.8000","4.9346","9.20478","0.04638"
"247.2000","4.9425","9.20472","0.04647"
"247.6000","4.9508","9.20860","0.04656"
"248.0000","4.9586","9.20912","0.04664"
"248.4000","4.9663","9.20554","0.04673"
"248.8000","4.9747","9.21188","0.04682"
"249.2000","4.9825","9.20978","0.04690"
"249.6000","4.9906","9.21057","0.04699"
"250.0000","4.9985","9.21130","0.04708"
"250.4000","5.0066","9.21416","0.04717"
"250.8000","5.0146","9.21620","0.04725"
"251.2000","5.0225","9.21382","0.04734"
"251.6000","5.0308","9.21792","0.04743"
"252.0000","5.0385","9.21578","0.04752"
"252.4000","5.0465","9.21664","0.04760"
"252.8000","5.0544","9.21778","0.04769"
"253.2000","5.0627","9.22160","0.04778"
"253.6000","5.0706","9.22186","0.04786"
"254.0000","5.0785","9.22003","0.04795"
"254.4000","5.0867","9.22445","0.04804"
"254.8000","5.0944","9.22209","0.04813"
"255.2000","5.1026","9.22454","0.04821"
"255.6000","5.1105","9.22520","0.04830"
"256.0000","5.1187","9.22749","0.04839"
"256.4000","5.1266","9.22795","0.04848"
"256.8000","5.1345","9.22680","0.04856"
"257.2000","5.1427","9.23121","0.04865"
"257.6000","5.1505","9.22889","0.04874"
"258.0000","5.1586","9.23076","0.04883"
"258.4000","5.1664","9.23025","0.04891"
"258.8000","5.1746","9.23307","0.04900"
"259.2000","5.1825","9.23432","0.04909"
"259.6000","5.1906","9.23405","0.04918"
"260.0000","5.1988","9.23789","0.04927"
"260.4000","5.2064","9.23445","0.04935"
"260.8000","5.2145","9.23629","0.04944"
"261.2000","5.2225","9.23751","0.04953"
"261.6000","5.2306","9.23961","0.04961"
"262.0000","5.2385","9.23979","0.04970"
"262.4000","5.2466","9.24071","0.04979"
"262.8000","5.2547","9.24321","0.04988"
"263.2000","5.2624","9.24098","0.04996"
"263.6000","5.2706","9.24421","0.05005"
"264.0000","5.2785","9.24361","0.05014"
"264.4000","5.2867","9.24572","0.05023"
"264.8000","5.2945","9.24526","0.05031"
"265.2000","5.3025","9.24605","0.05040"
"265.6000","5.3107","9.25042","0.05049"
"266.0000","5.3184","9.24707","0.05058"
"266.4000","5.3266","9.24962","0.05066"
"266.8000","5.3344","9.24888","0.05075"
"267.2000","5.3426","9.25104","0.05084"
"267.6000","5.3504","9.25128","0.05093"
"268.0000","5.3587","9.25333","0.05102"
"268.4000","5.3667","9.25552","0.05110"
"268.8000","5.3745","9.25297","0.05119"
"269.2000","5.3826","9.25523","0.05128"
"269.6000","5.3904","9.25423","0.05136"
"270.0000","5.3987","9.25819","0.05145"
"270.4000","5.4065","9.25744","0.05154"
"270.8000","5.4146","9.25820","0.05163"
"271.2000","5.4227","9.26103","0.05171"
"271.6000","5.4304","9.25918","0.05180"
"272.0000","5.4387","9.26210","0.05189"
"272.4000","5.4465","9.26064","0.05198"
"272.8000","5.4546","9.26272","0.05206"
"273.2000","5.4625","9.26234","0.05215"
"273.6000","5.4705","9.26365","0.05224"
"274.0000","5.4787","9.26694","0.05233"
"274.4000","5.4866","9.26557","0.05241"
"274.8000","5.4947","9.26783","0.05250"
"275.2000","5.5024","9.26516","0.05259"
"275.6000","5.5106","9.26851","0.05268"
"276.0000","5.5184","9.26807","0.05276"
"276.4000","5.5266","9.27014","0.05285"
"276.8000","5.5347","9.27279","0.05294"
"277.2000","5.5425","9.27086","0.05303"
"277.6000","5.5506","9.27267","0.05312"
"278.0000","5.5584","9.27110","0.05320"
"278.4000","5.5666","9.27441","0.05330"
"278.8000","5.5745","9.27359","0.05338"
"279.2000","5.5826","9.27507","0.05347"
"279.6000","5.5906","9.27699","0.05355"
"280.0000","5.5985","9.27680","0.05364"
"280.4000","5.6067","9.27906","0.05373"
"280.8000","5.6144","9.27638","0.05382"
"281.2000","5.6227","9.28039","0.05391"
"281.6000","5.6304","9.27840","0.05399"
"282.0000","5.6385","9.27965","0.05408"
"282.4000","5.6466","9.28313","0.05417"
"282.8000","5.6546","9.28271","0.05426"
"283.2000","5.6627","9.28385","0.05435"
"283.6000","5.6704","9.28150","0.05443"
"284.0000","5.6786","9.28483","0.05452"
"284.4000","5.6864","9.28351","0.05461"
"284.8000","5.6946","9.28586","0.05470"
"285.2000","5.7026","9.28749","0.05479"
"285.6000","5.7107","9.28817","0.05487"
"286.0000","5.7187","9.28859","0.05496"
"286.4000","5.7264","9.28603","0.05505"
"286.8000","5.7347","9.29143","0.05514"
"287.2000","5.7424","9.28883","0.05522"
"287.6000","5.7506","9.29059","0.05531"
"288.0000","5.7586","9.29212","0.05540"
"288.4000","5.7665","9.29179","0.05549"
"288.8000","5.7747","9.29462","0.05558"
"289.2000","5.7825","9.29260","0.05566"
"289.6000","5.7907","9.29574","0.05575"
"290.0000","5.7984","9.29347","0.05584"
"290.4000","5.8066","9.29514","0.05593"
"290.8000","5.8145","9.29697","0.05602"
"291.2000","5.8227","9.29846","0.05611"
"291.6000","5.8306","9.29859","0.05619"
"292.0000","5.8385","9.29725","0.05628"
"292.4000","5.8466","9.30082","0.05637"
"292.8000","5.8543","9.29725","0.05646"
"293.2000","5.8626","9.30109","0.05655"
"293.6000","5.8706","9.30228","0.05664"
"294.0000","5.8786","9.30189","0.05673"
"294.4000","5.8866","9.30325","0.05681"
"294.8000","5.8945","9.30214","0.05690"
"295.2000","5.9027","9.30571","0.05699"
"295.6000","5.9104","9.30305","0.05708"
"296.0000","5.9186","9.30538","0.05716"
"296.4000","5.9265","9.30576","0.05725"
"296.8000","5.9345","9.30637","0.05734"
"297.2000","5.9426","9.30825","0.05743"
"297.6000","5.9506","9.30743","0.05752"
"298.0000","5.9587","9.31037","0.05761"
"298.4000","5.9664","9.30645","0.05769"
"298.8000","5.9746","9.31010","0.05778"
"299.2000","5.9825","9.31022","0.05786"
"299.6000","5.9905","9.31084","0.05795"
"300.0000","5.9987","9.31293","0.05804"
"300.4000","6.0066","9.31229","0.05813"
"300.8000","6.0146","9.31365","0.05822"
"301.2000","6.0223","9.31127","0.05830"
"301.6000","6.0307","9.31521","0.05839"
"302.0000","6.0385","9.31457","0.05848"
"302.4000","6.0465","9.31481","0.05857"
"302.8000","6.0546","9.31641","0.05866"
"303.2000","6.0626","9.31664","0.05874"
"303.6000","6.0706","9.31874","0.05883"
"304.0000","6.0784","9.31549","0.05892"
"304.4000","6.0867","9.31992","0.05901"
"304.8000","6.0944","9.31819","0.05909"
"305.2000","6.1024","9.31822","0.05918"
"305.6000","6.1106","9.32171","0.05927"
"306.0000","6.1187","9.32261","0.05936"
"306.4000","6.1266","9.32261","0.05945"
"306.8000","6.1344","9.32013","0.05953"
"307.2000","6.1427","9.32377","0.05962"
"307.6000","6.1504","9.32197","0.05971"
"308.0000","6.1585","9.32331","0.05980"
"308.4000","6.1666","9.32510","0.05989"
"308.8000","6.1747","9.32645","0.05997"
"309.2000","6.1826","9.32630","0.06006"
"309.6000","6.1904","9.32418","0.06015"
"310.0000","6.1988","9.32956","0.06024"
"310.4000","6.2064","9.32626","0.06033"
"310.8000","6.2145","9.32672","0.06041"
"311.2000","6.2227","9.32979","0.06050"
"311.6000","6.2306","9.32958","0.06059"
"312.0000","6.2385","9.33001","0.06068"
"312.4000","6.2465","9.32917","0.06077"
"312.8000","6.2548","9.33294","0.06085"
"313.2000","6.2624","9.32926","0.06094"
"313.6000","6.2705","9.33069","0.06103"
"314.0000","6.2786","9.33308","0.06112"
"314.4000","6.2867","9.33473","0.06121"
"314.8000","6.2945","9.33376","0.06129"
"315.2000","6.3025","9.33275","0.06138"
"315.6000","6.3108","9.33725","0.06147"
"316.0000","6.3183","9.33235","0.06156"
"316.4000","6.3265","9.33464","0.06164"
"316.8000","6.3347","9.33772","0.06173"
"317.2000","6.3427","9.33776","0.06182"
"317.6000","6.3505","9.33665","0.06191"
"318.0000","6.3585","9.33683","0.06200"
"318.4000","6.3668","9.34130","0.06209"
"318.8000","6.3744","9.33662","0.06217"
"319.2000","6.3825","9.33867","0.06226"
"319.6000","6.3906","9.34040","0.06235"
"320.0000","6.3986","9.34073","0.06244"
"320.4000","6.4065","9.34079","0.06252"
"320.8000","6.4146","9.34133","0.06261"
"321.2000","6.4229","9.34514","0.06270"
"321.6000","6.4303","9.33895","0.06279"
"322.0000","6.4385","9.34162","0.06287"
"322.4000","6.4466","9.34433","0.06296"
"322.8000","6.4547","9.34491","0.06305"
"323.2000","6.4625","9.34404","0.06314"
"323.6000","6.4706","9.34517","0.06323"
"324.0000","6.4788","9.34806","0.06332"
"324.4000","6.4863","9.34274","0.06341"
"324.8000","6.4946","9.34639","0.06350"
"325.2000","6.5026","9.34758","0.06358"
"325.6000","6.5106","9.34789","0.06367"
"326.0000","6.5184","9.34684","0.06376"
"326.4000","6.5266","9.34827","0.06385"
"326.8000","6.5348","9.35264","0.06393"
"327.2000","6.5423","9.34641","0.06402"
"327.6000","6.5506","9.34967","0.06411"
"328.0000","6.5586","9.35095","0.06420"
"328.4000","6.5665","9.34978","0.06429"
"328.8000","6.5745","9.35054","0.06437"
"329.2000","6.5827","9.35315","0.06446"
"329.6000","6.5908","9.35477","0.06455"
"330.0000","6.5983","9.34964","0.06464"
"330.4000","6.6066","9.35306","0.06472"
"330.8000","6.6145","9.35320","0.06481"
"331.2000","6.6227","9.35470","0.06490"
"331.6000","6.6305","9.35340","0.06499"
"332.0000","6.6387","9.35558","0.06508"
"332.4000","6.6468","9.35765","0.06516"
"332.8000","6.6543","9.35230","0.06525"
"333.2000","6.6627","9.35708","0.06534"
"333.6000","6.6706","9.35686","0.06543"
"334.0000","6.6785","9.35626","0.06551"
"334.4000","6.6865","9.32783","0.06558"
"334.8000","6.6946","9.34503","0.06566"
"335.2000","6.7027","9.35555","0.06574"
"335.6000","6.7104","9.35576","0.06583"
"336.0000","6.7187","9.36114","0.06592"
"336.4000","6.7265","9.36039","0.06600"
"336.8000","6.7345","9.36099","0.06609"
"337.2000","6.7424","9.36074","0.06618"
"337.6000","6.7507","9.36361","0.06626"
"338.0000","6.7587","9.36420","0.06635"
"338.4000","6.7664","9.36000","0.06644"
"338.8000","6.7747","9.36384","0.06653"
"339.2000","6.7824","9.36233","0.06661"
"339.6000","6.7906","9.36322","0.06670"
"340.0000","6.7985","9.36337","0.06679"
"340.4000","6.8067","9.36537","0.06688"
"340.8000","6.8146","9.36501","0.06696"
"341.2000","6.8224","9.36255","0.06705"
"341.6000","6.8307","9.36673","0.06714"
"342.0000","6.8385","9.36419","0.06722"
"342.4000","6.8466","9.36567","0.06731"
"342.8000","6.8545","9.36476","0.06740"
"343.2000","6.8626","9.36674","0.06749"
"343.6000","6.8706","9.36800","0.06757"
"344.0000","6.8785","9.36541","0.06766"
"344.4000","6.8868","9.36967","0.06775"
"344.8000","6.8944","9.36596","0.06783"
"345.2000","6.9025","9.36662","0.06792"
"345.6000","6.9105","9.36811","0.06801"
"346.0000","6.9187","9.36977","0.06810"
"346.4000","6.9266","9.36946","0.06818"
"346.8000","6.9346","9.36871","0.06827"
"347.2000","6.9427","9.37099","0.06836"
"347.6000","6.9504","9.36833","0.06844"
"348.0000","6.9586","9.37069","0.06853"
"348.4000","6.9665","9.36939","0.06862"
"348.8000","6.9747","9.37239","0.06871"
"349.2000","6.9825","9.37151","0.06879"
"349.6000","6.9905","9.37032","0.06888"
"350.0000","6.9988","9.37495","0.06897"
"350.4000","7.0064","9.37065","0.06905"
"350.8000","7.0146","9.37242","0.06915"
"351.2000","7.0225","9.37205","0.06923"
"351.6000","7.0305","9.37301","0.06932"
"352.0000","7.0385","9.37387","0.06940"
"352.4000","7.0466","9.37379","0.06949"
"352.8000","7.0547","9.37579","0.06958"
"353.2000","7.0625","9.37360","0.06966"
"353.6000","7.0706","9.37442","0.06975"
"354.0000","7.0784","9.37325","0.06984"
"354.4000","7.0867","9.37700","0.06993"
"354.8000","7.0945","9.37519","0.07001"
"355.2000","7.1026","9.37575","0.07010"
"355.6000","7.1107","9.37835","0.07019"
"356.0000","7.1184","9.37461","0.07027"
"356.4000","7.1267","9.37761","0.07036"
"356.8000","7.1345","9.37636","0.07045"
"357.2000","7.1426","9.37737","0.07053"
"357.6000","7.1506","9.37776","0.07062"
"358.0000","7.1585","9.37730","0.07071"
"358.4000","7.1667","9.37998","0.07079"
"358.8000","7.1745","9.37842","0.07088"
"359.2000","7.1826","9.37958","0.07097"
"359.6000","7.1904","9.37746","0.07105"
"360.0000","7.1986","9.38017","0.07114"
"360.4000","7.2064","9.37878","0.07122"
"360.8000","7.2147","9.38082","0.07131"
"361.2000","7.2227","9.38249","0.07140"
"361.6000","7.2305","9.37921","0.07148"
"362.0000","7.2387","9.38135","0.07157"
"362.4000","7.2464","9.37876","0.07165"
"362.8000","7.2546","9.38189","0.07174"
"363.2000","7.2625","9.38146","0.07183"
"363.6000","7.2706","9.38157","0.07191"
"364.0000","7.2787","9.38346","0.07200"
"364.4000","7.2865","9.38146","0.07208"
"364.8000","7.2947","9.38388","0.07217"
"365.2000","7.3025","9.38139","0.07226"
"365.6000","7.3107","9.38385","0.07234"
"366.0000","7.3184","9.38186","0.07243"
"366.4000","7.3266","9.38273","0.07251"
"366.8000","7.3347","9.38567","0.07260"
"367.2000","7.3426","9.38400","0.07269"
"367.6000","7.3507","9.38537","0.07277"
"368.0000","7.3584","9.38211","0.07286"
"368.4000","7.3666","9.38476","0.07294"
"368.8000","7.3744","9.38400","0.07303"
"369.2000","7.3826","9.38524","0.07311"
"369.6000","7.3907","9.38652","0.07320"
"370.0000","7.3986","9.38568","0.07328"
"370.4000","7.4067","9.38639","0.07337"
"370.8000","7.4144","9.38334","0.07345"
"371.2000","7.4227","9.38730","0.07354"
"371.6000","7.4305","9.38503","0.07362"
"372.0000","7.4386","9.38565","0.07371"
"372.4000","7.4466","9.38741","0.07379"
"372.8000","7.4545","9.38629","0.07388"
"373.2000","7.4627","9.38882","0.07396"
"373.6000","7.4705","9.38593","0.07404"
"374.0000","7.4787","9.38824","0.07413"
"374.4000","7.4865","9.38637","0.07421"
"374.8000","7.4946","9.38716","0.07430"
"375.2000","7.5026","9.38874","0.07438"
"375.6000","7.5107","9.38927","0.07447"
"376.0000","7.5186","9.38925","0.07455"
"376.4000","7.5264","9.38670","0.07464"
"376.8000","7.5347","9.38994","0.07472"
"377.2000","7.5423","9.38639","0.07480"
"377.6000","7.5506","9.38883","0.07489"
"378.0000","7.5586","9.39039","0.07497"
"378.4000","7.5666","9.38928","0.07506"
"378.8000","7.5746","9.39030","0.07514"
"379.2000","7.5824","9.38789","0.07522"
"379.6000","7.5907","9.39153","0.07531"
"380.0000","7.5984","9.38859","0.07539"
"380.4000","7.6066","9.38972","0.07547"
"380.8000","7.6145","9.39016","0.07556"
"381.2000","7.6226","9.39049","0.07564"
"381.6000","7.6306","9.39158","0.07572"
"382.0000","7.6385","9.38950","0.07581"
"382.4000","7.6467","9.39280","0.07589"
"382.8000","7.6544","9.38837","0.07597"
"383.2000","7.6626","9.39035","0.07605"
"383.6000","7.6705","9.39117","0.07614"
"384.0000","7.6786","9.39133","0.07622"
"384.4000","7.6867","9.39227","0.07630"
"384.8000","7.6945","9.39044","0.07638"
"385.2000","7.7027","9.39245","0.07646"
"385.6000","7.7104","9.38915","0.07654"
"386.0000","7.7186","9.39187","0.07663"
"386.4000","7.7266","9.39195","0.07671"
"386.8000","7.7346","9.39195","0.07679"
"387.2000","7.7426","9.39216","0.07687"
"387.6000","7.7505","9.39070","0.07695"
"388.0000","7.7587","9.39434","0.07704"
"388.4000","7.7664","9.38989","0.07712"
"388.8000","7.7747","9.39254","0.07720"
"389.2000","7.7825","9.39192","0.07728"
"389.6000","7.7904","9.39112","0.07736"
"390.0000","7.7986","9.39396","0.07744"
"390.4000","7.8066","9.39331","0.07752"
"390.8000","7.8147","9.39395","0.07760"
"391.2000","7.8224","9.39050","0.07768"
"391.6000","7.8306","9.39311","0.07776"
"392.0000","7.8384","9.39202","0.07784"
"392.4000","7.8465","9.39292","0.07792"
"392.8000","7.8546","9.39368","0.07800"
"393.2000","7.8626","9.39337","0.07808"
"393.6000","7.8706","9.39399","0.07816"
"394.0000","7.8783","9.39029","0.07823"
"394.4000","7.8867","9.39467","0.07831"
"394.8000","7.8945","9.39292","0.07839"
"395.2000","7.9025","9.39195","0.07847"
"395.6000","7.9106","9.39421","0.07855"
"396.0000","7.9186","9.39367","0.07863"
"396.4000","7.9266","9.39438","0.07870"
"396.8000","7.9345","9.39164","0.07878"
"397.2000","7.9428","9.39472","0.07886"
"397.6000","7.9504","9.39154","0.07893"
"398.0000","7.9584","9.39197","0.07901"
"398.4000","7.9666","9.39421","0.07909"
"398.8000","7.9747","9.39497","0.07917"
"399.2000","7.9826","9.39411","0.07924"
"399.6000","7.9904","9.39103","0.07932"
"400.0000","7.9988","9.39506","0.07940"
"400.4000","8.0063","9.39101","0.07947"
"400.8000","8.0145","9.39203","0.07954"
"401.2000","8.0227","9.39457","0.07962"
"401.6000","8.0307","9.39413","0.07970"
"402.0000","8.0385","9.39263","0.07977"
"402.4000","8.0464","9.39131","0.07984"
"402.8000","8.0547","9.39518","0.07992"
"403.2000","8.0624","9.39164","0.07999"
"403.6000","8.0705","9.39193","0.08006"
"404.0000","8.0786","9.39302","0.08014"
"404.4000","8.0867","9.39368","0.08021"
"404.8000","8.0945","9.39298","0.08028"
"405.2000","8.1025","9.39137","0.08036"
"405.6000","8.1109","9.39561","0.08043"
"406.0000","8.1183","9.38943","0.08050"
"406.4000","8.1265","9.39074","0.08057"
"406.8000","8.1346","9.39321","0.08064"
"407.2000","8.1427","9.39314","0.08072"
"407.6000","8.1505","9.39179","0.08079"
"408.0000","8.1586","9.39119","0.08086"
"408.4000","8.1668","9.39388","0.08093"
"408.8000","8.1743","9.38845","0.08099"
"409.2000","8.1825","9.39112","0.08106"
"409.6000","8.1907","9.39233","0.08113"
"410.0000","8.1987","9.39212","0.08120"
"410.4000","8.2065","9.39022","0.08127"
"410.8000","8.2145","9.39000","0.08134"
"411.2000","8.2229","9.39476","0.08141"
"411.6000","8.2303","9.38734","0.08147"
"412.0000","8.2385","9.38927","0.08154"
"412.4000","8.2466","9.39124","0.08161"
"412.8000","8.2546","9.38968","0.08167"
"413.2000","8.2625","9.38913","0.08174"
"413.6000","8.2706","9.38983","0.08180"
"414.0000","8.2788","9.39215","0.08187"
"414.4000","8.2863","9.38568","0.08193"
"414.8000","8.2945","9.38781","0.08199"
"415.2000","8.3025","9.38878","0.08206"
"415.6000","8.3107","9.38930","0.08212"
"416.0000","8.3185","9.38734","0.08218"
"416.4000","8.3266","9.38773","0.08225"
"416.8000","8.3348","9.39069","0.08231"
"417.2000","8.3422","9.38352","0.08237"
"417.6000","8.3506","9.38682","0.08243"
"418.0000","8.3586","9.38745","0.08249"
"418.4000","8.3666","9.38582","0.08255"
"418.8000","8.3745","9.38461","0.08261"
"419.2000","8.3826","9.38592","0.08266"
"419.6000","8.3907","9.38762","0.08272"
"420.0000","8.3984","9.38233","0.08278"
"420.4000","8.4066","9.38469","0.08284"
"420.8000","8.4146","9.38360","0.08289"
"421.2000","8.4225","9.38286","0.08295"
"421.6000","8.4304","9.38199","0.08300"
"422.0000","8.4387","9.38372","0.08306"
"422.4000","8.4468","9.38477","0.08311"
"422.8000","8.4543","9.37807","0.08316"
"423.2000","8.4626","9.38154","0.08322"
"423.6000","8.4705","9.38040","0.08327"
"424.0000","8.4785","9.37965","0.08332"
"424.4000","8.4865","9.37911","0.08337"
"424.8000","8.4947","9.38029","0.08342"
"425.2000","8.5027","9.38009","0.08347"
"425.6000","8.5103","9.37498","0.08352"
"426.0000","8.5187","9.37852","0.08357"
"426.4000","8.5265","9.37630","0.08362"
"426.8000","8.5346","9.37553","0.08367"
"427.2000","8.5424","9.37371","0.08371"
"427.6000","8.5506","9.37524","0.08376"
"428.0000","8.5587","9.37614","0.08380"
"428.4000","8.5664","9.37046","0.08385"
"428.8000","8.5747","9.37327","0.08389"
"429.2000","8.5825","9.37040","0.08393"
"429.6000","8.5905","9.36916","0.08397"
"430.0000","8.5984","9.36873","0.08402"
"430.4000","8.6067","9.37041","0.08406"
"430.8000","8.6147","9.36889","0.08410"
"431.2000","8.6225","9.36491","0.08414"
"431.6000","8.6307","9.36715","0.08417"
"432.0000","8.6384","9.36342","0.08421"
"432.4000","8.6466","9.36384","0.08425"
"432.8000","8.6545","9.36207","0.08429"
"433.2000","8.6627","9.36259","0.08432"
"433.6000","8.6706","9.36142","0.08436"
"434.0000","8.6784","9.35701","0.08439"
"434.4000","8.6868","9.36021","0.08442"
"434.8000","8.6945","9.35551","0.08446"
"435.2000","8.7026","9.35469","0.08449"
"435.6000","8.7105","9.35314","0.08452"
"436.0000","8.7186","9.35286","0.08455"
"436.4000","8.7265","9.35141","0.08458"
"436.8000","8.7346","9.34907","0.08461"
"437.2000","8.7428","9.35023","0.08464"
"437.6000","8.7504","9.34450","0.08466"
"438.0000","8.7586","9.34418","0.08469"
"438.4000","8.7664","9.34178","0.08472"
"438.8000","8.7747","9.34247","0.08474"
"439.2000","8.7826","9.34002","0.08477"
"439.6000","8.7906","9.33645","0.08479"
"440.0000","8.7987","9.33775","0.08481"
"440.4000","8.8064","9.33205","0.08483"
"440.8000","8.8146","9.33166","0.08486"
"441.2000","8.8225","9.32895","0.08488"
"441.6000","8.8306","9.32740","0.08490"
"442.0000","8.8385","9.32433","0.08492"
"442.4000","8.8465","9.32178","0.08494"
"442.8000","8.8547","9.32244","0.08495"
"443.2000","8.8624","9.31604","0.08497"
"443.6000","8.8706","9.31505","0.08499"
"444.0000","8.8785","9.31047","0.08500"
"444.4000","8.8866","9.30957","0.08502"
"444.8000","8.8944","9.30646","0.08503"
"445.2000","8.9026","9.30368","0.08505"
"445.6000","8.9108","9.30327","0.08506"
"446.0000","8.9185","9.29561","0.08507"
"446.4000","8.9266","9.29388","0.08509"
"446.8000","8.9344","9.29000","0.08510"
"447.2000","8.9426","9.28844","0.08511"
"447.6000","8.9505","9.28344","0.08512"
"448.0000","8.9586","9.28016","0.08513"
"448.4000","8.9667","9.27810","0.08514"
"448.8000","8.9744","9.27171","0.08515"
"449.2000","8.9827","9.27004","0.08516"
"449.6000","8.9905","9.26315","0.08517"
"450.0000","8.9987","9.26127","0.08518"
"450.4000","9.0065","9.25540","0.08518"
"450.8000","9.0146","9.25101","0.08519"
"451.2000","9.0227","9.25012","0.08520"
"451.6000","9.0305","9.24179","0.08520"
"452.0000","9.0387","9.23816","0.08521"
"452.4000","9.0464","9.23087","0.08521"
"452.8000","9.0546","9.22769","0.08521"
"453.2000","9.0624","9.22154","0.08522"
"453.6000","9.0707","9.21771","0.08522"
"454.0000","9.0787","9.21352","0.08523"
"454.4000","9.0866","9.20549","0.08523"
"454.8000","9.0946","9.20140","0.08524"
"455.2000","9.1024","9.19266","0.08524"
"455.6000","9.1107","9.18988","0.08524"
"456.0000","9.1185","9.18162","0.08524"
"456.4000","9.1266","9.17506","0.08524"
"456.8000","9.1347","9.17169","0.08525"
"457.2000","9.1425","9.16252","0.08525"
"457.6000","9.1507","9.15805","0.08525"
"458.0000","9.1585","9.14791","0.08525"
"458.4000","9.1666","9.14268","0.08525"
"458.8000","9.1745","9.13440","0.08525"
"459.2000","9.1825","9.12719","0.08525"
"459.6000","9.1906","9.12233","0.08525"
"460.0000","9.1987","9.11394","0.08525"
"460.4000","9.2067","9.10578","0.08525"
"460.8000","9.2144","9.09418","0.08524"
"461.2000","9.2226","9.09056","0.08524"
"461.6000","9.2303","9.07943","0.08524"
"462.0000","9.2386","9.07200","0.08524"
"462.4000","9.2467","9.06572","0.08524"
"462.8000","9.2546","9.05442","0.08523"
"463.2000","9.2627","9.04711","0.08523"
"463.6000","9.2704","9.03489","0.08523"
"464.0000","9.2786","9.02923","0.08523"
"464.4000","9.2865","9.01794","0.08522"
"464.8000","9.2946","9.00759","0.08522"
"465.2000","9.3026","8.99973","0.08522"
"465.6000","9.3106","8.99022","0.08521"
"466.0000","9.3186","8.98000","0.08521"
"466.4000","9.3265","8.96666","0.08521"
"466.8000","9.3347","8.95978","0.08520"
"467.2000","9.3424","8.94497","0.08520"
"467.6000","9.3506","8.93630","0.08519"
"468.0000","9.3585","8.92741","0.08519"
"468.4000","9.3666","8.91434","0.08518"
"468.8000","9.3747","8.90442","0.08518"
"469.2000","9.3825","8.88965","0.08517"
"469.6000","9.3906","8.88091","0.08517"
"470.0000","9.3984","8.86654","0.08517"
"470.4000","9.4066","8.85501","0.08516"
"470.8000","9.4146","8.84435","0.08516"
"471.2000","9.4226","8.83086","0.08515"
"471.6000","9.4306","8.81775","0.08514"
"472.0000","9.4385","8.80340","0.08514"
"472.4000","9.4467","8.79348","0.08513"
"472.8000","9.4544","8.77500","0.08512"
"473.2000","9.4627","8.76326","0.08512"
"473.6000","9.4705","8.75046","0.08511"
"474.0000","9.4785","8.73478","0.08510"
"474.4000","9.4866","8.72277","0.08510"
"474.8000","9.4946","8.70495","0.08509"
"475.2000","9.5027","8.69301","0.08509"
"475.6000","9.5104","8.67348","0.08508"
"476.0000","9.5186","8.65885","0.08507"
"476.4000","9.5265","8.64501","0.08506"
"476.8000","9.5346","8.62737","0.08505"
"477.2000","9.5426","8.61104","0.08505"
"477.6000","9.5506","8.59292","0.08504"
"478.0000","9.5587","8.57810","0.08503"
"478.4000","9.5664","8.55551","0.08502"
"478.8000","9.5747","8.53932","0.08501"
"479.2000","9.5826","8.52131","0.08500"
"479.6000","9.5906","8.50068","0.08499"
"480.0000","9.5986","8.48263","0.08498"
"480.4000","9.6065","8.46123","0.08497"
"480.8000","9.6146","8.44327","0.08496"
"481.2000","9.6225","8.41714","0.08495"
"481.6000","9.6307","8.39662","0.08494"
"482.0000","9.6385","8.37463","0.08493"
"482.4000","9.6465","8.34979","0.08491"
"482.8000","9.6546","8.32639","0.08490"
"483.2000","9.6627","8.30033","0.08489"
"483.6000","9.6707","8.27663","0.08488"
"484.0000","9.6784","8.24436","0.08486"
"484.4000","9.6867","8.21803","0.08485"
"484.8000","9.6944","8.18750","0.08483"
"485.2000","9.7025","8.15278","0.08481"
"485.6000","9.7107","8.12167","0.08480"
"486.0000","9.7187","8.08676","0.08478"
"486.4000","9.7266","8.05215","0.08476"
"486.8000","9.7344","8.00935","0.08474"
"487.2000","9.7427","7.96608","0.08472"
"487.6000","9.7505","7.91153","0.08469"
"488.0000","9.7585","7.85119","0.08466"
"488.4000","9.7666","7.79349","0.08463"
"488.8000","9.7747","7.71697","0.08459"
"489.2000","9.7826","7.60670","0.08453"
"489.6000","9.7905","7.43945","0.08444"
"489.6980","9.7925","7.04052","0.08468"
"489.7020","9.7926","6.48914","0.08520"
"489.7060","9.7928","5.75774","0.08555"
"489.7070","9.7929","5.55841","0.08561"