File: Coupon Test Data/Tensile Test_Neebajan_Alan_2.csv
Time,Displacement,Force,Strain 1
(s),(mm),(kN),(mm/mm)
"0.0000","0.0000","0.18212","-0.00013"
"0.4000","0.0063","0.23832","-0.00009"
"0.8000","0.0145","0.31640","-0.00004"
"1.2000","0.0224","0.39062","0.00001"
"1.6000","0.0303","0.46296","0.00006"
"2.0000","0.0385","0.53736","0.00011"
"2.4000","0.0466","0.61111","0.00016"
"2.8000","0.0545","0.68095","0.00021"
"3.2000","0.0624","0.75010","0.00026"
"3.6000","0.0706","0.82122","0.00030"
"4.0000","0.0783","0.88190","0.00034"
"4.4000","0.0864","0.94936","0.00039"
"4.8000","0.0945","1.01878","0.00044"
"5.2000","0.1026","1.07735","0.00047"
"5.6000","0.1104","1.14356","0.00052"
"6.0000","0.1183","1.20710","0.00056"
"6.4000","0.1266","1.27516","0.00061"
"6.8000","0.1345","1.33483","0.00064"
"7.2000","0.1424","1.39727","0.00069"
"7.6000","0.1505","1.46383","0.00073"
"8.0000","0.1585","1.52600","0.00078"
"8.4000","0.1664","1.58491","0.00081"
"8.8000","0.1744","1.64636","0.00085"
"9.2000","0.1827","1.71134","0.00090"
"9.6000","0.1903","1.76532","0.00093"
"10.0000","0.1983","1.82678","0.00097"
"10.4000","0.2065","1.88936","0.00101"
"10.8000","0.2146","1.94663","0.00105"
"11.2000","0.2224","2.00552","0.00109"
"11.6000","0.2305","2.06545","0.00113"
"12.0000","0.2387","2.12317","0.00117"
"12.4000","0.2463","2.17795","0.00121"
"12.8000","0.2544","2.23726","0.00125"
"13.2000","0.2626","2.29421","0.00128"
"13.6000","0.2706","2.35141","0.00132"
"14.0000","0.2784","2.40711","0.00136"
"14.4000","0.2864","2.46114","0.00140"
"14.8000","0.2947","2.52056","0.00144"
"15.2000","0.3024","2.57354","0.00147"
"15.6000","0.3104","2.62572","0.00151"
"16.0000","0.3185","2.68323","0.00155"
"16.4000","0.3265","2.73797","0.00158"
"16.8000","0.3344","2.78833","0.00162"
"17.2000","0.3425","2.84426","0.00166"
"17.6000","0.3507","2.90012","0.00169"
"18.0000","0.3583","2.94691","0.00172"
"18.4000","0.3664","3.00102","0.00176"
"18.8000","0.3745","3.05503","0.00180"
"19.2000","0.3826","3.10509","0.00184"
"19.6000","0.3904","3.15620","0.00187"
"20.0000","0.3985","3.20836","0.00191"
"20.4000","0.4067","3.25829","0.00194"
"20.8000","0.4142","3.30529","0.00198"
"21.2000","0.4224","3.35418","0.00201"
"21.6000","0.4305","3.40551","0.00205"
"22.0000","0.4385","3.45492","0.00209"
"22.4000","0.4463","3.49890","0.00211"
"22.8000","0.4545","3.55009","0.00215"
"23.2000","0.4627","3.60032","0.00219"
"23.6000","0.4703","3.64048","0.00222"
"24.0000","0.4785","3.69036","0.00226"
"24.4000","0.4865","3.73788","0.00229"
"24.8000","0.4945","3.78032","0.00232"
"25.2000","0.5023","3.82686","0.00236"
"25.6000","0.5106","3.87497","0.00239"
"26.0000","0.5187","3.91853","0.00243"
"26.4000","0.5263","3.96088","0.00246"
"26.8000","0.5344","4.00432","0.00249"
"27.2000","0.5425","4.04904","0.00253"
"27.6000","0.5505","4.09357","0.00257"
"28.0000","0.5584","4.13281","0.00259"
"28.4000","0.5667","4.17898","0.00263"
"28.8000","0.5746","4.22271","0.00267"
"29.2000","0.5823","4.25801","0.00270"
"29.6000","0.5905","4.30358","0.00274"
"30.0000","0.5985","4.34327","0.00277"
"30.4000","0.6065","4.38279","0.00280"
"30.8000","0.6144","4.42346","0.00284"
"31.2000","0.6226","4.46132","0.00287"
"31.6000","0.6306","4.50274","0.00291"
"32.0000","0.6383","4.53680","0.00294"
"32.4000","0.6466","4.57629","0.00298"
"32.8000","0.6545","4.61501","0.00302"
"33.2000","0.6624","4.64789","0.00305"
"33.6000","0.6704","4.68597","0.00309"
"34.0000","0.6787","4.72463","0.00313"
"34.4000","0.6866","4.75528","0.00317"
"34.8000","0.6944","4.78863","0.00321"
"35.2000","0.7026","4.82392","0.00326"
"35.6000","0.7104","4.84806","0.00329"
"36.0000","0.7185","4.88135","0.00334"
"36.4000","0.7264","4.91043","0.00339"
"36.8000","0.7346","4.93763","0.00344"
"37.2000","0.7426","4.96306","0.00349"
"37.6000","0.7503","4.98360","0.00354"
"38.0000","0.7586","5.00666","0.00360"
"38.4000","0.7665","5.02492","0.00366"
"38.8000","0.7744","5.04100","0.00373"
"39.2000","0.7824","5.05615","0.00380"
"39.6000","0.7905","5.06978","0.00387"
"40.0000","0.7985","5.08136","0.00394"
"40.4000","0.8065","5.08951","0.00402"
"40.8000","0.8147","5.10002","0.00410"
"41.2000","0.8224","5.10604","0.00418"
"41.6000","0.8304","5.11291","0.00426"
"42.0000","0.8383","5.11919","0.00435"
"42.4000","0.8466","5.12545","0.00444"
"42.8000","0.8545","5.13039","0.00452"
"43.2000","0.8625","5.13320","0.00461"
"43.6000","0.8706","5.13911","0.00470"
"44.0000","0.8783","5.14111","0.00478"
"44.4000","0.8865","5.14442","0.00488"
"44.8000","0.8945","5.14800","0.00497"
"45.2000","0.9026","5.15119","0.00506"
"45.6000","0.9104","5.15328","0.00515"
"46.0000","0.9185","5.15094","0.00523"
"46.4000","0.9266","5.15905","0.00532"
"46.8000","0.9344","5.15956","0.00541"
"47.2000","0.9425","5.16183","0.00551"
"47.6000","0.9504","5.16352","0.00560"
"48.0000","0.9585","5.16625","0.00569"
"48.4000","0.9664","5.16830","0.00578"
"48.8000","0.9745","5.16923","0.00588"
"49.2000","0.9828","5.17274","0.00598"
"49.6000","0.9904","5.17192","0.00607"
"50.0000","0.9985","5.17349","0.00617"
"50.4000","1.0064","5.17557","0.00626"
"50.8000","1.0145","5.17749","0.00636"
"51.2000","1.0224","5.17842","0.00645"
"51.6000","1.0305","5.17969","0.00655"
"52.0000","1.0386","5.18235","0.00665"
"52.4000","1.0464","5.18171","0.00674"
"52.8000","1.0546","5.18387","0.00684"
"53.2000","1.0625","5.18440","0.00693"
"53.6000","1.0706","5.18602","0.00703"
"54.0000","1.0784","5.18713","0.00713"
"54.4000","1.0865","5.18798","0.00723"
"54.8000","1.0946","5.19118","0.00732"
"55.2000","1.1024","5.19020","0.00742"
"55.6000","1.1106","5.19160","0.00752"
"56.0000","1.1184","5.19205","0.00761"
"56.4000","1.1265","5.19392","0.00771"
"56.8000","1.1343","5.19457","0.00781"
"57.2000","1.1426","5.19626","0.00791"
"57.6000","1.1507","5.19830","0.00801"
"58.0000","1.1585","5.19750","0.00810"
"58.4000","1.1666","5.19930","0.00820"
"58.8000","1.1744","5.19929","0.00830"
"59.2000","1.1826","5.20151","0.00840"
"59.6000","1.1904","5.20189","0.00850"
"60.0000","1.1985","5.20247","0.00859"
"60.4000","1.2066","5.20540","0.00869"
"60.8000","1.2144","5.20493","0.00879"
"61.2000","1.2226","5.20659","0.00889"
"61.6000","1.2305","5.20648","0.00899"
"62.0000","1.2386","5.20804","0.00908"
"62.4000","1.2464","5.20827","0.00918"
"62.8000","1.2545","5.20944","0.00928"
"63.2000","1.2625","5.21222","0.00938"
"63.6000","1.2705","5.21212","0.00948"
"64.0000","1.2786","5.21319","0.00957"
"64.4000","1.2864","5.21262","0.00967"
"64.8000","1.2945","5.21508","0.00977"
"65.2000","1.3023","5.21517","0.00987"
"65.6000","1.3105","5.21611","0.00997"
"66.0000","1.3186","5.21869","0.01006"
"66.4000","1.3265","5.21837","0.01016"
"66.8000","1.3346","5.21950","0.01026"
"67.2000","1.3423","5.21917","0.01035"
"67.6000","1.3505","5.22166","0.01046"
"68.0000","1.3584","5.22173","0.01055"
"68.4000","1.3665","5.22247","0.01065"
"68.8000","1.3745","5.22473","0.01075"
"69.2000","1.3825","5.22529","0.01084"
"69.6000","1.3906","5.22643","0.01094"
"70.0000","1.3984","5.22545","0.01104"
"70.4000","1.4066","5.22826","0.01114"
"70.8000","1.4144","5.22782","0.01123"
"71.2000","1.4225","5.22855","0.01133"
"71.6000","1.4305","5.23134","0.01143"
"72.0000","1.4386","5.23181","0.01153"
"72.4000","1.4466","5.23250","0.01162"
"72.8000","1.4544","5.23211","0.01172"
"73.2000","1.4625","5.23470","0.01182"
"73.6000","1.4703","5.23422","0.01191"
"74.0000","1.4785","5.23560","0.01201"
"74.4000","1.4865","5.23727","0.01210"
"74.8000","1.4946","5.23839","0.01220"
"75.2000","1.5026","5.21803","0.01227"
"75.6000","1.5104","5.23479","0.01235"
"76.0000","1.5186","5.24187","0.01244"
"76.4000","1.5264","5.24120","0.01254"
"76.8000","1.5345","5.24182","0.01264"
"77.2000","1.5425","5.24389","0.01273"
"77.6000","1.5505","5.24432","0.01282"
"78.0000","1.5586","5.24557","0.01292"
"78.4000","1.5665","5.24543","0.01302"
"78.8000","1.5746","5.24756","0.01311"
"79.2000","1.5824","5.24669","0.01321"
"79.6000","1.5905","5.24796","0.01330"
"80.0000","1.5984","5.24964","0.01340"
"80.4000","1.6065","5.25086","0.01349"
"80.8000","1.6146","5.25165","0.01359"
"81.2000","1.6225","5.25155","0.01368"
"81.6000","1.6306","5.25414","0.01378"
"82.0000","1.6383","5.25271","0.01387"
"82.4000","1.6466","5.25474","0.01397"
"82.8000","1.6545","5.25636","0.01407"
"83.2000","1.6625","5.25653","0.01416"
"83.6000","1.6706","5.25802","0.01426"
"84.0000","1.6785","5.25825","0.01435"
"84.4000","1.6866","5.26059","0.01445"
"84.8000","1.6944","5.25941","0.01454"
"85.2000","1.7025","5.26108","0.01464"
"85.6000","1.7104","5.26210","0.01473"
"86.0000","1.7184","5.26285","0.01482"
"86.4000","1.7265","5.26481","0.01492"
"86.8000","1.7346","5.26500","0.01502"
"87.2000","1.7426","5.26691","0.01511"
"87.6000","1.7504","5.26524","0.01520"
"88.0000","1.7586","5.26748","0.01530"
"88.4000","1.7664","5.26875","0.01539"
"88.8000","1.7744","5.26923","0.01548"
"89.2000","1.7826","5.27096","0.01558"
"89.6000","1.7906","5.27183","0.01567"
"90.0000","1.7985","5.27284","0.01577"
"90.4000","1.8063","5.27189","0.01586"
"90.8000","1.8146","5.27470","0.01595"
"91.2000","1.8224","5.27501","0.01605"
"91.6000","1.8304","5.27542","0.01614"
"92.0000","1.8385","5.27705","0.01623"
"92.4000","1.8465","5.27821","0.01633"
"92.8000","1.8545","5.27969","0.01642"
"93.2000","1.8624","5.27834","0.01651"
"93.6000","1.8706","5.28090","0.01661"
"94.0000","1.8783","5.28116","0.01670"
"94.4000","1.8863","5.28149","0.01679"
"94.8000","1.8945","5.28424","0.01688"
"95.2000","1.9027","5.28546","0.01698"
"95.6000","1.9105","5.28551","0.01707"
"96.0000","1.9184","5.28508","0.01716"
"96.4000","1.9266","5.28690","0.01725"
"96.8000","1.9343","5.28224","0.01732"
"97.2000","1.9424","5.28781","0.01741"
"97.6000","1.9505","5.29050","0.01751"
"98.0000","1.9586","5.29209","0.01760"
"98.4000","1.9664","5.29202","0.01769"
"98.8000","1.9743","5.29157","0.01778"
"99.2000","1.9827","5.29521","0.01787"
"99.6000","1.9904","5.29377","0.01796"
"100.0000","1.9984","5.29389","0.01806"
"100.4000","2.0066","5.29678","0.01815"
"100.8000","2.0146","5.29766","0.01824"
"101.2000","2.0225","5.29818","0.01833"
"101.6000","2.0305","5.29813","0.01842"
"102.0000","2.0387","5.30078","0.01852"
"102.4000","2.0463","5.29971","0.01861"
"102.8000","2.0544","5.30055","0.01870"
"103.2000","2.0625","5.30264","0.01879"
"103.6000","2.0707","5.30496","0.01888"
"104.0000","2.0784","5.30422","0.01897"
"104.4000","2.0865","5.30449","0.01906"
"104.8000","2.0947","5.30776","0.01916"
"105.2000","2.1022","5.30543","0.01925"
"105.6000","2.1104","5.30718","0.01934"
"106.0000","2.1186","5.30959","0.01943"
"106.4000","2.1266","5.30994","0.01952"
"106.8000","2.1344","5.31040","0.01961"
"107.2000","2.1424","5.31118","0.01970"
"107.6000","2.1507","5.31404","0.01980"
"108.0000","2.1584","5.31241","0.01989"
"108.4000","2.1664","5.31328","0.01998"
"108.8000","2.1746","5.31537","0.02007"
"109.2000","2.1825","5.31639","0.02016"
"109.6000","2.1903","5.31650","0.02025"
"110.0000","2.1986","5.31791","0.02034"
"110.4000","2.2067","5.32054","0.02043"
"110.8000","2.2142","5.31756","0.02052"
"111.2000","2.2225","5.32028","0.02061"
"111.6000","2.2305","5.32215","0.02070"
"112.0000","2.2385","5.32238","0.02079"
"112.4000","2.2465","5.32327","0.02089"
"112.8000","2.2546","5.32454","0.02098"
"113.2000","2.2627","5.32629","0.02107"
"113.6000","2.2702","5.32437","0.02115"
"114.0000","2.2785","5.32654","0.02125"
"114.4000","2.2866","5.32860","0.02134"
"114.8000","2.2945","5.32863","0.02143"
"115.2000","2.3023","5.32871","0.02151"
"115.6000","2.3106","5.33120","0.02161"
"116.0000","2.3187","5.33338","0.02170"
"116.4000","2.3263","5.33033","0.02179"
"116.8000","2.3346","5.33311","0.02188"
"117.2000","2.3425","5.33443","0.02197"
"117.6000","2.3504","5.33445","0.02206"
"118.0000","2.3583","5.33543","0.02215"
"118.4000","2.3666","5.33774","0.02224"
"118.8000","2.3747","5.33938","0.02233"
"119.2000","2.3823","5.33682","0.02242"
"119.6000","2.3905","5.33926","0.02251"
"120.0000","2.3985","5.34056","0.02260"
"120.4000","2.4065","5.34108","0.02269"
"120.8000","2.4144","5.34154","0.02278"
"121.2000","2.4227","5.34370","0.02287"
"121.6000","2.4306","5.34511","0.02296"
"122.0000","2.4383","5.34292","0.02305"
"122.4000","2.4466","5.34600","0.02314"
"122.8000","2.4545","5.34691","0.02323"
"123.2000","2.4624","5.34673","0.02332"
"123.6000","2.4703","5.34762","0.02341"
"124.0000","2.4786","5.35010","0.02350"
"124.4000","2.4866","5.35153","0.02359"
"124.8000","2.4944","5.34977","0.02368"
"125.2000","2.5026","5.35218","0.02377"
"125.6000","2.5105","5.35233","0.02386"
"126.0000","2.5184","5.35282","0.02395"
"126.4000","2.5263","5.35357","0.02403"
"126.8000","2.5346","5.35613","0.02413"
"127.2000","2.5426","5.35708","0.02421"
"127.6000","2.5504","5.35571","0.02430"
"128.0000","2.5586","5.35864","0.02439"
"128.4000","2.5664","5.35859","0.02448"
"128.8000","2.5745","5.35926","0.02457"
"129.2000","2.5825","5.36047","0.02466"
"129.6000","2.5906","5.36198","0.02475"
"130.0000","2.5985","5.36255","0.02484"
"130.4000","2.6064","5.36237","0.02493"
"130.8000","2.6146","5.36511","0.02502"
"131.2000","2.6224","5.36435","0.02511"
"131.6000","2.6305","5.36521","0.02520"
"132.0000","2.6384","5.36594","0.02529"
"132.4000","2.6465","5.36784","0.02538"
"132.8000","2.6545","5.36903","0.02546"
"133.2000","2.6625","5.36857","0.02556"
"133.6000","2.6707","5.37125","0.02565"
"134.0000","2.6784","5.37027","0.02573"
"134.4000","2.6864","5.37108","0.02583"
"134.8000","2.6944","5.37225","0.02591"
"135.2000","2.7026","5.37426","0.02600"
"135.6000","2.7105","5.37434","0.02609"
"136.0000","2.7185","5.37467","0.02618"
"136.4000","2.7266","5.37695","0.02627"
"136.8000","2.7343","5.37587","0.02635"
"137.2000","2.7425","5.37748","0.02645"
"137.6000","2.7505","5.37807","0.02653"
"138.0000","2.7586","5.37955","0.02662"
"138.4000","2.7665","5.38000","0.02671"
"138.8000","2.7745","5.38035","0.02680"
"139.2000","2.7826","5.38323","0.02689"
"139.6000","2.7904","5.38212","0.02698"
"140.0000","2.7985","5.38311","0.02707"
"140.4000","2.8064","5.38383","0.02715"
"140.8000","2.8145","5.38516","0.02725"
"141.2000","2.8224","5.38576","0.02733"
"141.6000","2.8306","5.38710","0.02742"
"142.0000","2.8387","5.38874","0.02751"
"142.4000","2.8464","5.38765","0.02760"
"142.8000","2.8545","5.38921","0.02769"
"143.2000","2.8624","5.38934","0.02777"
"143.6000","2.8705","5.39120","0.02786"
"144.0000","2.8784","5.39155","0.02795"
"144.4000","2.8865","5.39223","0.02804"
"144.8000","2.8946","5.39460","0.02813"
"145.2000","2.9024","5.39367","0.02821"
"145.6000","2.9105","5.39522","0.02831"
"146.0000","2.9185","5.39553","0.02839"
"146.4000","2.9266","5.39677","0.02848"
"146.8000","2.9344","5.39677","0.02857"
"147.2000","2.9425","5.39808","0.02866"
"147.6000","2.9506","5.40045","0.02875"
"148.0000","2.9585","5.39955","0.02884"
"148.4000","2.9666","5.40100","0.02893"
"148.8000","2.9744","5.40052","0.02901"
"149.2000","2.9825","5.40260","0.02910"
"149.6000","2.9904","5.40298","0.02919"
"150.0000","2.9985","5.40384","0.02928"
"150.4000","3.0067","5.40606","0.02937"
"150.8000","3.0145","5.40536","0.02946"
"151.2000","3.0225","5.40637","0.02955"
"151.6000","3.0303","5.40630","0.02963"
"152.0000","3.0385","5.40840","0.02972"
"152.4000","3.0464","5.40833","0.02981"
"152.8000","3.0545","5.40928","0.02990"
"153.2000","3.0625","5.41107","0.02999"
"153.6000","3.0705","5.41112","0.03008"
"154.0000","3.0786","5.41263","0.03016"
"154.4000","3.0864","5.41166","0.03025"
"154.8000","3.0946","5.41402","0.03034"
"155.2000","3.1024","5.41368","0.03043"
"155.6000","3.1105","5.41432","0.03052"
"156.0000","3.1185","5.41689","0.03060"
"156.4000","3.1265","5.41687","0.03069"
"156.8000","3.1346","5.41780","0.03078"
"157.2000","3.1424","5.41711","0.03087"
"157.6000","3.1505","5.41909","0.03096"
"158.0000","3.1583","5.41914","0.03104"
"158.4000","3.1665","5.42057","0.03113"
"158.8000","3.1746","5.42187","0.03122"
"159.2000","3.1826","5.42235","0.03131"
"159.6000","3.1906","5.42285","0.03140"
"160.0000","3.1983","5.41563","0.03146"
"160.4000","3.2066","5.42381","0.03155"
"160.8000","3.2144","5.42430","0.03163"
"161.2000","3.2225","5.42553","0.03172"
"161.6000","3.2305","5.42761","0.03181"
"162.0000","3.2385","5.42788","0.03190"
"162.4000","3.2466","5.40998","0.03196"
"162.8000","3.2544","5.42322","0.03204"
"163.2000","3.2626","5.42980","0.03212"
"163.6000","3.2704","5.43006","0.03221"
"164.0000","3.2785","5.43113","0.03230"
"164.4000","3.2864","5.43298","0.03239"
"164.8000","3.2946","5.43386","0.03247"
"165.2000","3.3026","5.43413","0.03256"
"165.6000","3.3104","5.43327","0.03265"
"166.0000","3.3186","5.43575","0.03274"
"166.4000","3.3263","5.43466","0.03282"
"166.8000","3.3345","5.43616","0.03291"
"167.2000","3.3425","5.43760","0.03300"
"167.6000","3.3505","5.43783","0.03309"
"168.0000","3.3586","5.43869","0.03317"
"168.4000","3.3664","5.43831","0.03326"
"168.8000","3.3746","5.44077","0.03335"
"169.2000","3.3824","5.43980","0.03344"
"169.6000","3.3905","5.44089","0.03353"
"170.0000","3.3984","5.44206","0.03361"
"170.4000","3.4065","5.44273","0.03370"
"170.8000","3.4145","5.44408","0.03379"
"171.2000","3.4225","5.44358","0.03388"
"171.6000","3.4307","5.44596","0.03396"
"172.0000","3.4384","5.44410","0.03405"
"172.4000","3.4465","5.44566","0.03414"
"172.8000","3.4544","5.44721","0.03423"
"173.2000","3.4625","5.44778","0.03432"
"173.6000","3.4705","5.44871","0.03441"
"174.0000","3.4785","5.44900","0.03449"
"174.4000","3.4865","5.45052","0.03458"
"174.8000","3.4943","5.44916","0.03467"
"175.2000","3.5026","5.45128","0.03476"
"175.6000","3.5105","5.45186","0.03484"
"176.0000","3.5185","5.45239","0.03493"
"176.4000","3.5265","5.45338","0.03502"
"176.8000","3.5345","5.45385","0.03511"
"177.2000","3.5426","5.45574","0.03519"
"177.6000","3.5504","5.45401","0.03528"
"178.0000","3.5586","5.45615","0.03537"
"178.4000","3.5664","5.45653","0.03546"
"178.8000","3.5744","5.45673","0.03554"
"179.2000","3.5826","5.45901","0.03563"
"179.6000","3.5906","5.45946","0.03572"
"180.0000","3.5985","5.46010","0.03581"
"180.4000","3.6064","5.45905","0.03590"
"180.8000","3.6146","5.46101","0.03599"
"181.2000","3.6223","5.46098","0.03607"
"181.6000","3.6304","5.46191","0.03616"
"182.0000","3.6386","5.46326","0.03625"
"182.4000","3.6466","5.46402","0.03634"
"182.8000","3.6545","5.46460","0.03643"
"183.2000","3.6623","5.46358","0.03651"
"183.6000","3.6707","5.46653","0.03660"
"184.0000","3.6784","5.46615","0.03669"
"184.4000","3.6864","5.46608","0.03678"
"184.8000","3.6946","5.46801","0.03687"
"185.2000","3.7026","5.46891","0.03695"
"185.6000","3.7104","5.46910","0.03704"
"186.0000","3.7184","5.46869","0.03713"
"186.4000","3.7267","5.47118","0.03722"
"186.8000","3.7343","5.47000","0.03731"
"187.2000","3.7424","5.47072","0.03739"
"187.6000","3.7505","5.47273","0.03748"
"188.0000","3.7587","5.47390","0.03757"
"188.4000","3.7665","5.47393","0.03766"
"188.8000","3.7744","5.47301","0.03775"
"189.2000","3.7827","5.47571","0.03784"
"189.6000","3.7903","5.47448","0.03792"
"190.0000","3.7984","5.47518","0.03801"
"190.4000","3.8066","5.47742","0.03810"
"190.8000","3.8146","5.47818","0.03819"
"191.2000","3.8224","5.47774","0.03827"
"191.6000","3.8304","5.47813","0.03836"
"192.0000","3.8387","5.48114","0.03845"
"192.4000","3.8464","5.47904","0.03854"
"192.8000","3.8544","5.47982","0.03863"
"193.2000","3.8625","5.48133","0.03872"
"193.6000","3.8706","5.48245","0.03880"
"194.0000","3.8784","5.48273","0.03889"
"194.4000","3.8865","5.48270","0.03898"
"194.8000","3.8948","5.48558","0.03907"
"195.2000","3.9023","5.48288","0.03915"
"195.6000","3.9104","5.48395","0.03924"
"196.0000","3.9185","5.48648","0.03933"
"196.4000","3.9266","5.48711","0.03942"
"196.8000","3.9345","5.48668","0.03951"
"197.2000","3.9425","5.48750","0.03960"
"197.6000","3.9507","5.48981","0.03969"
"198.0000","3.9582","5.48725","0.03977"
"198.4000","3.9664","5.48913","0.03986"
"198.8000","3.9746","5.49083","0.03995"
"199.2000","3.9826","5.49123","0.04004"
"199.6000","3.9904","5.49079","0.04013"
"200.0000","3.9985","5.49175","0.04021"
"200.4000","4.0068","5.49489","0.04031"
"200.8000","4.0143","5.49179","0.04039"
"201.2000","4.0225","5.49297","0.04048"
"201.6000","4.0306","5.49485","0.04057"
"202.0000","4.0385","5.49481","0.04066"
"202.4000","4.0464","5.49519","0.04075"
"202.8000","4.0546","5.49680","0.04083"
"203.2000","4.0627","5.49855","0.04092"
"203.6000","4.0703","5.49564","0.04101"
"204.0000","4.0785","5.49774","0.04110"
"204.4000","4.0865","5.49892","0.04119"
"204.8000","4.0946","5.49957","0.04127"
"205.2000","4.1024","5.49932","0.04136"
"205.6000","4.1106","5.50073","0.04145"
"206.0000","4.1187","5.50240","0.04154"
"206.4000","4.1262","5.49965","0.04163"
"206.8000","4.1345","5.50201","0.04172"
"207.2000","4.1425","5.50326","0.04180"
"207.6000","4.1505","5.50298","0.04189"
"208.0000","4.1584","5.50293","0.04198"
"208.4000","4.1666","5.50505","0.04207"
"208.8000","4.1747","5.50669","0.04216"
"209.2000","4.1824","5.50411","0.04224"
"209.6000","4.1906","5.50612","0.04234"
"210.0000","4.1985","5.50655","0.04242"
"210.4000","4.2064","5.50668","0.04251"
"210.8000","4.2143","5.50702","0.04260"
"211.2000","4.2226","5.50915","0.04269"
"211.6000","4.2307","5.51043","0.04278"
"212.0000","4.2383","5.50780","0.04286"
"212.4000","4.2466","5.51028","0.04295"
"212.8000","4.2544","5.51055","0.04304"
"213.2000","4.2625","5.51079","0.04313"
"213.6000","4.2705","5.51148","0.04322"
"214.0000","4.2787","5.51301","0.04331"
"214.4000","4.2866","5.51330","0.04339"
"214.8000","4.2943","5.51195","0.04348"
"215.2000","4.3026","5.51458","0.04357"
"215.6000","4.3105","5.51430","0.04366"
"216.0000","4.3184","5.51424","0.04375"
"216.4000","4.3263","5.51433","0.04383"
"216.8000","4.3346","5.51677","0.04392"
"217.2000","4.3425","5.51756","0.04401"
"217.6000","4.3504","5.51582","0.04410"
"218.0000","4.3587","5.51862","0.04419"
"218.4000","4.3664","5.51760","0.04428"
"218.8000","4.3744","5.51775","0.04436"
"219.2000","4.3824","5.51861","0.04445"
"219.6000","4.3906","5.52042","0.04454"
"220.0000","4.3986","5.52095","0.04463"
"220.4000","4.4064","5.51974","0.04472"
"220.8000","4.4146","5.52185","0.04481"
"221.2000","4.4224","5.52142","0.04490"
"221.6000","4.4305","5.52188","0.04499"
"222.0000","4.4384","5.52194","0.04507"
"222.4000","4.4467","5.52424","0.04517"
"222.8000","4.4544","5.52363","0.04525"
"223.2000","4.4624","5.52318","0.04534"
"223.6000","4.4707","5.52632","0.04543"
"224.0000","4.4784","5.52457","0.04552"
"224.4000","4.4865","5.52508","0.04561"
"224.8000","4.4944","5.52567","0.04570"
"225.2000","4.5025","5.52659","0.04578"
"225.6000","4.5105","5.52790","0.04587"
"226.0000","4.5185","5.52750","0.04596"
"226.4000","4.5267","5.52896","0.04605"
"226.8000","4.5345","5.52823","0.04614"
"227.2000","4.5424","5.52833","0.04623"
"227.6000","4.5504","5.52866","0.04631"
"228.0000","4.5586","5.53104","0.04640"
"228.4000","4.5664","5.53047","0.04649"
"228.8000","4.5745","5.53073","0.04658"
"229.2000","4.5826","5.53253","0.04667"
"229.6000","4.5903","5.53090","0.04676"
"230.0000","4.5985","5.53266","0.04685"
"230.4000","4.6065","5.53256","0.04693"
"230.8000","4.6146","5.53355","0.04702"
"231.2000","4.6224","5.53358","0.04711"
"231.6000","4.6305","5.53384","0.04720"
"232.0000","4.6386","5.53625","0.04729"
"232.4000","4.6464","5.53463","0.04738"
"232.8000","4.6545","5.53551","0.04747"
"233.2000","4.6624","5.53542","0.04755"
"233.6000","4.6705","5.53671","0.04765"
"234.0000","4.6784","5.53676","0.04773"
"234.4000","4.6866","5.53782","0.04782"
"234.8000","4.6947","5.53935","0.04792"
"235.2000","4.7024","5.53785","0.04800"
"235.6000","4.7105","5.53881","0.04809"
"236.0000","4.7183","5.53850","0.04818"
"236.4000","4.7265","5.54026","0.04827"
"236.8000","4.7344","5.53995","0.04836"
"237.2000","4.7426","5.54057","0.04845"
"237.6000","4.7506","5.54199","0.04854"
"238.0000","4.7584","5.54093","0.04863"
"238.4000","4.7666","5.54263","0.04872"
"238.8000","4.7745","5.54183","0.04881"
"239.2000","4.7826","5.54344","0.04890"
"239.6000","4.7904","5.54270","0.04898"
"240.0000","4.7985","5.54305","0.04907"
"240.4000","4.8066","5.54553","0.04916"
"240.8000","4.8145","5.54429","0.04925"
"241.2000","4.8226","5.54509","0.04934"
"241.6000","4.8304","5.54452","0.04943"
"242.0000","4.8385","5.54576","0.04952"
"242.4000","4.8464","5.54578","0.04961"
"242.8000","4.8546","5.54688","0.04970"
"243.2000","4.8626","5.54790","0.04979"
"243.6000","4.8705","5.54756","0.04988"
"244.0000","4.8786","5.54808","0.04997"
"244.4000","4.8863","5.54704","0.05005"
"244.8000","4.8946","5.54950","0.05015"
"245.2000","4.9024","5.54851","0.05023"
"245.6000","4.9105","5.54908","0.05032"
"246.0000","4.9185","5.55074","0.05041"
"246.4000","4.9264","5.55009","0.05050"
"246.8000","4.9346","5.55142","0.05059"
"247.2000","4.9424","5.55040","0.05068"
"247.6000","4.9506","5.55180","0.05077"
"248.0000","4.9584","5.55107","0.05086"
"248.4000","4.9665","5.55177","0.05095"
"248.8000","4.9745","5.55350","0.05104"
"249.2000","4.9826","5.55388","0.05113"
"249.6000","4.9906","5.55412","0.05122"
"250.0000","4.9984","5.55277","0.05131"
"250.4000","5.0066","5.55489","0.05140"
"250.8000","5.0143","5.55379","0.05149"
"251.2000","5.0225","5.55477","0.05158"
"251.6000","5.0306","5.55614","0.05167"
"252.0000","5.0386","5.55614","0.05176"
"252.4000","5.0466","5.55633","0.05185"
"252.8000","5.0544","5.55549","0.05194"
"253.2000","5.0626","5.55769","0.05203"
"253.6000","5.0704","5.55660","0.05211"
"254.0000","5.0785","5.55728","0.05221"
"254.4000","5.0865","5.55835","0.05230"
"254.8000","5.0945","5.55873","0.05239"
"255.2000","5.1026","5.55953","0.05248"
"255.6000","5.1105","5.55817","0.05257"
"256.0000","5.1187","5.56029","0.05266"
"256.4000","5.1264","5.55876","0.05274"
"256.8000","5.1345","5.55931","0.05283"
"257.2000","5.1424","5.56089","0.05293"
"257.6000","5.1505","5.56117","0.05302"
"258.0000","5.1586","5.56139","0.05311"
"258.4000","5.1665","5.56106","0.05320"
"258.8000","5.1745","5.56249","0.05329"
"259.2000","5.1823","5.56112","0.05337"
"259.6000","5.1906","5.56262","0.05347"
"260.0000","5.1985","5.56305","0.05356"
"260.4000","5.2065","5.56344","0.05365"
"260.8000","5.2145","5.56365","0.05374"
"261.2000","5.2224","5.56306","0.05383"
"261.6000","5.2306","5.56540","0.05392"
"262.0000","5.2384","5.56340","0.05400"
"262.4000","5.2465","5.56466","0.05410"
"262.8000","5.2544","5.56507","0.05419"
"263.2000","5.2624","5.56487","0.05428"
"263.6000","5.2705","5.56639","0.05437"
"264.0000","5.2786","5.56626","0.05446"
"264.4000","5.2866","5.56731","0.05455"
"264.8000","5.2944","5.56557","0.05464"
"265.2000","5.3025","5.56698","0.05473"
"265.6000","5.3103","5.56701","0.05482"
"266.0000","5.3185","5.56785","0.05491"
"266.4000","5.3266","5.56846","0.05500"
"266.8000","5.3345","5.56838","0.05509"
"267.2000","5.3425","5.56937","0.05518"
"267.6000","5.3503","5.56756","0.05527"
"268.0000","5.3586","5.56985","0.05536"
"268.4000","5.3665","5.56967","0.05545"
"268.8000","5.3744","5.56914","0.05554"
"269.2000","5.3826","5.57073","0.05564"
"269.6000","5.3905","5.57075","0.05573"
"270.0000","5.3985","5.57143","0.05581"
"270.4000","5.4064","5.57009","0.05591"
"270.8000","5.4146","5.57168","0.05600"
"271.2000","5.4224","5.57124","0.05609"
"271.6000","5.4304","5.57126","0.05618"
"272.0000","5.4385","5.57264","0.05627"
"272.4000","5.4467","5.57345","0.05636"
"272.8000","5.4545","5.57345","0.05645"
"273.2000","5.4624","5.57172","0.05654"
"273.6000","5.4706","5.57401","0.05664"
"274.0000","5.4783","5.57302","0.05673"
"274.4000","5.4864","5.57341","0.05682"
"274.8000","5.4946","5.57466","0.05691"
"275.2000","5.5026","5.57517","0.05700"
"275.6000","5.5105","5.57507","0.05709"
"276.0000","5.5183","5.57396","0.05718"
"276.4000","5.5267","5.57656","0.05727"
"276.8000","5.5344","5.57499","0.05736"
"277.2000","5.5424","5.57497","0.05745"
"277.6000","5.5505","5.57626","0.05755"
"278.0000","5.5586","5.57683","0.05764"
"278.4000","5.5664","5.57695","0.05773"
"278.8000","5.5744","5.57604","0.05782"
"279.2000","5.5827","5.57872","0.05791"
"279.6000","5.5903","5.57632","0.05800"
"280.0000","5.5983","5.57644","0.05809"
"280.4000","5.6065","5.57858","0.05818"
"280.8000","5.6147","5.57942","0.05828"
"281.2000","5.6225","5.57811","0.05837"
"281.6000","5.6305","5.57799","0.05846"
"282.0000","5.6387","5.58021","0.05855"
"282.4000","5.6463","5.57782","0.05864"
"282.8000","5.6544","5.57876","0.05873"
"283.2000","5.6626","5.58025","0.05882"
"283.6000","5.6706","5.58069","0.05892"
"284.0000","5.6784","5.57989","0.05901"
"284.4000","5.6864","5.57959","0.05910"
"284.8000","5.6947","5.58261","0.05919"
"285.2000","5.7023","5.57974","0.05928"
"285.6000","5.7104","5.58022","0.05937"
"286.0000","5.7186","5.58196","0.05947"
"286.4000","5.7265","5.58179","0.05956"
"286.8000","5.7344","5.58148","0.05965"
"287.2000","5.7425","5.58191","0.05974"
"287.6000","5.7507","5.58385","0.05983"
"288.0000","5.7583","5.58090","0.05992"
"288.4000","5.7664","5.58195","0.06002"
"288.8000","5.7745","5.58339","0.06011"
"289.2000","5.7826","5.58406","0.06020"
"289.6000","5.7904","5.58308","0.06029"
"290.0000","5.7985","5.58337","0.06039"
"290.4000","5.8068","5.58565","0.06048"
"290.8000","5.8142","5.58202","0.06057"
"291.2000","5.8224","5.58377","0.06066"
"291.6000","5.8306","5.58525","0.06075"
"292.0000","5.8385","5.58448","0.06084"
"292.4000","5.8464","5.58426","0.06094"
"292.8000","5.8545","5.58551","0.06103"
"293.2000","5.8627","5.58722","0.06112"
"293.6000","5.8703","5.58401","0.06121"
"294.0000","5.8785","5.58532","0.06131"
"294.4000","5.8865","5.58607","0.06140"
"294.8000","5.8945","5.58581","0.06149"
"295.2000","5.9023","5.58567","0.06158"
"295.6000","5.9106","5.58736","0.06168"
"296.0000","5.9187","5.58869","0.06177"
"296.4000","5.9263","5.58503","0.06186"
"296.8000","5.9345","5.58672","0.06195"
"297.2000","5.9425","5.58760","0.06204"
"297.6000","5.9505","5.58737","0.06214"
"298.0000","5.9584","5.58696","0.06223"
"298.4000","5.9666","5.58868","0.06232"
"298.8000","5.9746","5.58931","0.06241"
"299.2000","5.9823","5.58642","0.06250"
"299.6000","5.9906","5.58881","0.06260"
"300.0000","5.9985","5.58869","0.06269"
"300.4000","6.0065","5.58848","0.06278"
"300.8000","6.0144","5.58808","0.06287"
"301.2000","6.0225","5.58945","0.06297"
"301.6000","6.0306","5.59095","0.06306"
"302.0000","6.0384","5.58793","0.06315"
"302.4000","6.0466","5.58981","0.06325"
"302.8000","6.0545","5.58964","0.06334"
"303.2000","6.0624","5.58900","0.06343"
"303.6000","6.0704","5.58941","0.06352"
"304.0000","6.0786","5.59128","0.06362"
"304.4000","6.0866","5.59119","0.06371"
"304.8000","6.0944","5.58924","0.06380"
"305.2000","6.1026","5.59129","0.06390"
"305.6000","6.1104","5.59020","0.06399"
"306.0000","6.1185","5.59087","0.06408"
"306.4000","6.1264","5.59051","0.06418"
"306.8000","6.1346","5.59185","0.06427"
"307.2000","6.1426","5.59210","0.06437"
"307.6000","6.1503","5.59013","0.06446"
"308.0000","6.1586","5.59263","0.06455"
"308.4000","6.1665","5.59179","0.06465"
"308.8000","6.1745","5.59124","0.06474"
"309.2000","6.1824","5.59157","0.06483"
"309.6000","6.1905","5.59264","0.06493"
"310.0000","6.1985","5.59293","0.06502"
"310.4000","6.2065","5.59207","0.06511"
"310.8000","6.2147","5.59378","0.06521"
"311.2000","6.2224","5.59176","0.06530"
"311.6000","6.2305","5.59234","0.06539"
"312.0000","6.2384","5.59228","0.06549"
"312.4000","6.2466","5.59382","0.06558"
"312.8000","6.2545","5.59369","0.06568"
"313.2000","6.2625","5.59275","0.06577"
"313.6000","6.2706","5.59485","0.06586"
"314.0000","6.2783","5.59288","0.06595"
"314.4000","6.2865","5.59355","0.06605"
"314.8000","6.2945","5.59388","0.06614"
"315.2000","6.3026","5.59446","0.06624"
"315.6000","6.3104","5.59380","0.06633"
"316.0000","6.3185","5.59379","0.06643"
"316.4000","6.3266","5.59566","0.06652"
"316.8000","6.3344","5.59392","0.06661"
"317.2000","6.3425","5.59432","0.06671"
"317.6000","6.3504","5.59400","0.06680"
"318.0000","6.3585","5.59509","0.06690"
"318.4000","6.3664","5.59498","0.06699"
"318.8000","6.3746","5.59504","0.06709"
"319.2000","6.3827","5.59649","0.06718"
"319.6000","6.3904","5.59454","0.06727"
"320.0000","6.3985","5.59502","0.06737"
"320.4000","6.4064","5.59494","0.06746"
"320.8000","6.4146","5.59619","0.06756"
"321.2000","6.4224","5.59530","0.06765"
"321.6000","6.4306","5.59575","0.06775"
"322.0000","6.4386","5.59667","0.06784"
"322.4000","6.4463","5.59498","0.06794"
"322.8000","6.4545","5.59648","0.06803"
"323.2000","6.4625","5.59573","0.06813"
"323.6000","6.4706","5.59636","0.06822"
"324.0000","6.4784","5.59590","0.06831"
"324.4000","6.4865","5.59602","0.06841"
"324.8000","6.4947","5.59814","0.06851"
"325.2000","6.5024","5.59585","0.06860"
"325.6000","6.5105","5.59655","0.06870"
"326.0000","6.5184","5.59603","0.06879"
"326.4000","6.5265","5.59664","0.06888"
"326.8000","6.5344","5.59643","0.06898"
"327.2000","6.5426","5.59731","0.06908"
"327.6000","6.5506","5.59796","0.06917"
"328.0000","6.5585","5.59691","0.06927"
"328.4000","6.5665","5.59706","0.06936"
"328.8000","6.5743","5.59592","0.06946"
"329.2000","6.5825","5.59811","0.06955"
"329.6000","6.5904","5.59685","0.06965"
"330.0000","6.5985","5.59710","0.06974"
"330.4000","6.6066","5.59836","0.06984"
"330.8000","6.6144","5.59690","0.06993"
"331.2000","6.6226","5.59824","0.07003"
"331.6000","6.6304","5.59670","0.07012"
"332.0000","6.6385","5.59760","0.07022"
"332.4000","6.6464","5.59741","0.07032"
"332.8000","6.6545","5.59718","0.07041"
"333.2000","6.6625","5.59856","0.07051"
"333.6000","6.6705","5.59835","0.07060"
"334.0000","6.6786","5.59815","0.07070"
"334.4000","6.6864","5.59689","0.07080"
"334.8000","6.6945","5.59828","0.07089"
"335.2000","6.7023","5.59705","0.07099"
"335.6000","6.7106","5.59857","0.07109"
"336.0000","6.7186","5.59906","0.07118"
"336.4000","6.7265","5.59807","0.07128"
"336.8000","6.7346","5.59889","0.07137"
"337.2000","6.7423","5.59697","0.07147"
"337.6000","6.7505","5.59875","0.07156"
"338.0000","6.7584","5.59824","0.07166"
"338.4000","6.7665","5.59792","0.07176"
"338.8000","6.7745","5.59904","0.07185"
"339.2000","6.7825","5.59891","0.07195"
"339.6000","6.7906","5.59927","0.07205"
"340.0000","6.7985","5.59800","0.07214"
"340.4000","6.8066","5.59912","0.07224"
"340.8000","6.8144","5.59760","0.07234"
"341.2000","6.8225","5.59851","0.07243"
"341.6000","6.8304","5.59910","0.07253"
"342.0000","6.8385","5.59900","0.07263"
"342.4000","6.8466","5.59953","0.07272"
"342.8000","6.8544","5.59767","0.07282"
"343.2000","6.8626","5.59931","0.07292"
"343.6000","6.8703","5.59801","0.07301"
"344.0000","6.8785","5.59883","0.07311"
"344.4000","6.8865","5.59929","0.07321"
"344.8000","6.8946","5.59919","0.07331"
"345.2000","6.9026","5.59902","0.07340"
"345.6000","6.9104","5.59786","0.07350"
"346.0000","6.9186","5.59987","0.07360"
"346.4000","6.9264","5.59795","0.07370"
"346.8000","6.9345","5.59862","0.07379"
"347.2000","6.9425","5.59905","0.07389"
"347.6000","6.9505","5.59881","0.07399"
"348.0000","6.9586","5.59954","0.07409"
"348.4000","6.9665","5.59837","0.07418"
"348.8000","6.9746","5.59983","0.07428"
"349.2000","6.9824","5.59818","0.07438"
"349.6000","6.9905","5.59851","0.07448"
"350.0000","6.9984","5.59892","0.07457"
"350.4000","7.0065","5.59945","0.07467"
"350.8000","7.0146","5.59931","0.07477"
"351.2000","7.0225","5.59835","0.07487"
"351.6000","7.0305","5.59977","0.07496"
"352.0000","7.0383","5.59764","0.07506"
"352.4000","7.0466","5.59911","0.07517"
"352.8000","7.0545","5.59928","0.07526"
"353.2000","7.0625","5.59858","0.07536"
"353.6000","7.0706","5.59932","0.07546"
"354.0000","7.0785","5.59873","0.07556"
"354.4000","7.0865","5.59973","0.07565"
"354.8000","7.0944","5.59791","0.07575"
"355.2000","7.1025","5.59890","0.07585"
"355.6000","7.1104","5.59871","0.07595"
"356.0000","7.1184","5.59850","0.07605"
"356.4000","7.1265","5.59918","0.07615"
"356.8000","7.1346","5.59923","0.07625"
"357.2000","7.1426","5.59971","0.07635"
"357.6000","7.1503","5.59703","0.07645"
"358.0000","7.1586","5.59865","0.07655"
"358.4000","7.1664","5.59856","0.07664"
"358.8000","7.1744","5.59828","0.07674"
"359.2000","7.1826","5.59906","0.07684"
"359.6000","7.1906","5.59903","0.07694"
"360.0000","7.1985","5.59895","0.07704"
"360.4000","7.2063","5.59736","0.07714"
"360.8000","7.2146","5.59933","0.07724"
"361.2000","7.2224","5.59819","0.07734"
"361.6000","7.2305","5.59793","0.07744"
"362.0000","7.2385","5.59844","0.07754"
"362.4000","7.2466","5.59865","0.07764"
"362.8000","7.2545","5.59901","0.07774"
"363.2000","7.2624","5.59717","0.07784"
"363.6000","7.2706","5.59891","0.07794"
"364.0000","7.2783","5.59740","0.07804"
"364.4000","7.2863","5.59701","0.07813"
"364.8000","7.2946","5.59887","0.07824"
"365.2000","7.3027","5.59918","0.07834"
"365.6000","7.3105","5.59817","0.07844"
"366.0000","7.3184","5.59686","0.07854"
"366.4000","7.3266","5.59858","0.07864"
"366.8000","7.3343","5.59679","0.07874"
"367.2000","7.3424","5.59732","0.07884"
"367.6000","7.3505","5.59811","0.07894"
"368.0000","7.3586","5.59842","0.07904"
"368.4000","7.3665","5.59772","0.07914"
"368.8000","7.3744","5.59640","0.07924"
"369.2000","7.3827","5.59901","0.07934"
"369.6000","7.3904","5.59681","0.07944"
"370.0000","7.3984","5.59642","0.07954"
"370.4000","7.4066","5.59773","0.07965"
"370.8000","7.4146","5.59788","0.07975"
"371.2000","7.4224","5.59713","0.07985"
"371.6000","7.4305","5.59663","0.07995"
"372.0000","7.4387","5.59828","0.08005"
"372.4000","7.4463","5.59549","0.08015"
"372.8000","7.4544","5.59612","0.08025"
"373.2000","7.4625","5.59727","0.08035"
"373.6000","7.4706","5.59795","0.08046"
"374.0000","7.4785","5.59688","0.08056"
"374.4000","7.4865","5.59597","0.08066"
"374.8000","7.4947","5.59807","0.08076"
"375.2000","7.5022","5.59484","0.08086"
"375.6000","7.5104","5.59557","0.08097"
"376.0000","7.5186","5.59716","0.08107"
"376.4000","7.5266","5.59672","0.08117"
"376.8000","7.5344","5.59562","0.08127"
"377.2000","7.5425","5.59588","0.08138"
"377.6000","7.5508","5.59794","0.08148"
"378.0000","7.5583","5.59433","0.08158"
"378.4000","7.5665","5.59519","0.08169"
"378.8000","7.5745","5.59593","0.08179"
"379.2000","7.5825","5.59575","0.08189"
"379.6000","7.5904","5.59514","0.08199"
"380.0000","7.5986","5.59561","0.08210"
"380.4000","7.6068","5.59731","0.08220"
"380.8000","7.6143","5.59335","0.08230"
"381.2000","7.6224","5.59441","0.08241"
"381.6000","7.6305","5.59555","0.08251"
"382.0000","7.6385","5.59501","0.08261"
"382.4000","7.6464","5.59434","0.08272"
"382.8000","7.6546","5.59522","0.08282"
"383.2000","7.6627","5.59609","0.08293"
"383.6000","7.6703","5.59280","0.08303"
"384.0000","7.6785","5.59436","0.08313"
"384.4000","7.6866","5.59463","0.08324"
"384.8000","7.6945","5.59415","0.08334"
"385.2000","7.7023","5.59321","0.08344"
"385.6000","7.7105","5.59437","0.08355"
"386.0000","7.7187","5.59587","0.08365"
"386.4000","7.7263","5.59196","0.08376"
"386.8000","7.7346","5.59345","0.08386"
"387.2000","7.7425","5.59350","0.08397"
"387.6000","7.7504","5.59234","0.08407"
"388.0000","7.7583","5.59258","0.08417"
"388.4000","7.7666","5.59422","0.08428"
"388.8000","7.7747","5.59437","0.08439"
"389.2000","7.7823","5.59121","0.08449"
"389.6000","7.7905","5.59288","0.08459"
"390.0000","7.7985","5.59251","0.08470"
"390.4000","7.8065","5.59238","0.08481"
"390.8000","7.8144","5.59159","0.08491"
"391.2000","7.8226","5.59258","0.08502"
"391.6000","7.8306","5.59315","0.08513"
"392.0000","7.8383","5.58990","0.08523"
"392.4000","7.8466","5.59206","0.08534"
"392.8000","7.8545","5.59176","0.08544"
"393.2000","7.8625","5.59080","0.08555"
"393.6000","7.8704","5.59037","0.08565"
"394.0000","7.8786","5.59165","0.08576"
"394.4000","7.8866","5.59190","0.08587"
"394.8000","7.8944","5.58975","0.08597"
"395.2000","7.9026","5.59122","0.08608"
"395.6000","7.9104","5.58990","0.08618"
"396.0000","7.9184","5.58968","0.08629"
"396.4000","7.9264","5.58945","0.08640"
"396.8000","7.9346","5.59063","0.08651"
"397.2000","7.9426","5.59066","0.08662"
"397.6000","7.9504","5.58845","0.08672"
"398.0000","7.9586","5.59028","0.08683"
"398.4000","7.9664","5.58883","0.08694"
"398.8000","7.9745","5.58865","0.08704"
"399.2000","7.9825","5.58876","0.08715"
"399.6000","7.9906","5.58940","0.08726"
"400.0000","7.9985","5.58859","0.08737"
"400.4000","8.0064","5.58748","0.08747"
"400.8000","8.0146","5.58941","0.08758"
"401.2000","8.0224","5.58751","0.08769"
"401.6000","8.0305","5.58723","0.08780"
"402.0000","8.0384","5.58688","0.08791"
"402.4000","8.0465","5.58768","0.08802"
"402.8000","8.0545","5.58777","0.08813"
"403.2000","8.0625","5.58644","0.08824"
"403.6000","8.0707","5.58796","0.08835"
"404.0000","8.0784","5.58586","0.08845"
"404.4000","8.0864","5.58567","0.08857"
"404.8000","8.0944","5.58567","0.08867"
"405.2000","8.1026","5.58656","0.08879"
"405.6000","8.1105","5.58558","0.08890"
"406.0000","8.1185","5.58510","0.08901"
"406.4000","8.1266","5.58622","0.08912"
"406.8000","8.1344","5.58421","0.08923"
"407.2000","8.1425","5.58473","0.08934"
"407.6000","8.1505","5.58402","0.08945"
"408.0000","8.1586","5.58460","0.08956"
"408.4000","8.1664","5.58377","0.08967"
"408.8000","8.1745","5.58322","0.08978"
"409.2000","8.1827","5.58483","0.08990"
"409.6000","8.1904","5.58259","0.09001"
"410.0000","8.1985","5.58260","0.09012"
"410.4000","8.2064","5.58207","0.09023"
"410.8000","8.2145","5.58262","0.09034"
"411.2000","8.2224","5.58178","0.09045"
"411.6000","8.2306","5.58220","0.09057"
"412.0000","8.2387","5.58271","0.09068"
"412.4000","8.2464","5.58055","0.09079"
"412.8000","8.2545","5.58091","0.09091"
"413.2000","8.2623","5.57982","0.09102"
"413.6000","8.2705","5.58086","0.09113"
"414.0000","8.2784","5.57987","0.09125"
"414.4000","8.2865","5.57944","0.09136"
"414.8000","8.2946","5.58076","0.09148"
"415.2000","8.3024","5.57843","0.09159"
"415.6000","8.3105","5.57873","0.09170"
"416.0000","8.3185","5.57801","0.09182"
"416.4000","8.3265","5.57816","0.09194"
"416.8000","8.3344","5.57693","0.09205"
"417.2000","8.3425","5.57691","0.09217"
"417.6000","8.3506","5.57828","0.09228"
"418.0000","8.3585","5.57626","0.09240"
"418.4000","8.3666","5.57629","0.09252"
"418.8000","8.3744","5.57455","0.09263"
"419.2000","8.3825","5.57537","0.09275"
"419.6000","8.3903","5.57426","0.09286"
"420.0000","8.3985","5.57418","0.09299"
"420.4000","8.4067","5.57531","0.09310"
"420.8000","8.4145","5.57321","0.09322"
"421.2000","8.4226","5.57288","0.09334"
"421.6000","8.4303","5.57135","0.09346"
"422.0000","8.4385","5.57219","0.09358"
"422.4000","8.4464","5.57063","0.09369"
"422.8000","8.4545","5.57060","0.09382"
"423.2000","8.4626","5.57121","0.09394"
"423.6000","8.4704","5.56963","0.09406"
"424.0000","8.4786","5.57008","0.09418"
"424.4000","8.4864","5.56770","0.09430"
"424.8000","8.4946","5.56840","0.09442"
"425.2000","8.5024","5.56639","0.09454"
"425.6000","8.5104","5.56585","0.09466"
"426.0000","8.5186","5.56721","0.09479"
"426.4000","8.5265","5.56554","0.09491"
"426.8000","8.5346","5.56486","0.09503"
"427.2000","8.5424","5.56293","0.09516"
"427.6000","8.5505","5.56337","0.09528"
"428.0000","8.5583","5.56159","0.09540"
"428.4000","8.5665","5.56154","0.09553"
"428.8000","8.5746","5.56146","0.09566"
"429.2000","8.5826","5.56030","0.09579"
"429.6000","8.5906","5.55911","0.09591"
"430.0000","8.5983","5.55664","0.09603"
"430.4000","8.6066","5.55820","0.09617"
"430.8000","8.6144","5.55532","0.09629"
"431.2000","8.6225","5.55438","0.09642"
"431.6000","8.6305","5.55459","0.09655"
"432.0000","8.6385","5.55309","0.09668"
"432.4000","8.6465","5.55240","0.09681"
"432.8000","8.6545","5.54990","0.09694"
"433.2000","8.6626","5.55003","0.09707"
"433.6000","8.6704","5.54701","0.09720"
"434.0000","8.6785","5.54624","0.09734"
"434.4000","8.6864","5.54598","0.09747"
"434.8000","8.6946","5.54484","0.09760"
"435.2000","8.7026","5.54311","0.09774"
"435.6000","8.7104","5.54012","0.09787"
"436.0000","8.7186","5.54035","0.09801"
"436.4000","8.7263","5.53666","0.09815"
"436.8000","8.7346","5.53599","0.09829"
"437.2000","8.7426","5.53499","0.09843"
"437.6000","8.7505","5.53232","0.09856"
"438.0000","8.7586","5.53111","0.09871"
"438.4000","8.7664","5.52797","0.09884"
"438.8000","8.7746","5.52754","0.09899"
"439.2000","8.7824","5.52378","0.09913"
"439.6000","8.7905","5.52199","0.09927"
"440.0000","8.7985","5.51990","0.09942"
"440.4000","8.8065","5.51765","0.09956"
"440.8000","8.8145","5.51532","0.09971"
"441.2000","8.8226","5.51179","0.09986"
"441.6000","8.8306","5.51064","0.10000"
"442.0000","8.8383","5.50493","0.10015"
"442.4000","8.8465","5.50330","0.10030"
"442.8000","8.8544","5.50076","0.10045"
"443.2000","8.8625","5.49700","0.10060"
"443.6000","8.8706","5.49440","0.10075"
"444.0000","8.8785","5.48984","0.10090"
"444.4000","8.8865","5.48743","0.10105"
"444.8000","8.8943","5.48165","0.10120"
"445.2000","8.9025","5.47851","0.10136"
"445.6000","8.9105","5.47487","0.10152"
"446.0000","8.9185","5.46976","0.10167"
"446.4000","8.9265","5.46530","0.10183"
"446.8000","8.9346","5.46110","0.10199"
"447.2000","8.9425","5.45696","0.10214"
"447.6000","8.9503","5.44894","0.10230"
"448.0000","8.9586","5.44584","0.10246"
"448.4000","8.9664","5.43943","0.10262"
"448.8000","8.9744","5.43316","0.10278"
"449.2000","8.9825","5.42887","0.10294"
"449.6000","8.9906","5.42193","0.10311"
"450.0000","8.9986","5.41589","0.10327"
"450.4000","9.0064","5.40669","0.10343"
"450.8000","9.0145","5.40125","0.10359"
"451.2000","9.0224","5.39458","0.10375"
"451.6000","9.0304","5.38581","0.10392"
"452.0000","9.0385","5.37858","0.10409"
"452.4000","9.0467","5.37156","0.10425"
"452.8000","9.0545","5.36278","0.10442"
"453.2000","9.0623","5.35197","0.10459"
"453.6000","9.0707","5.34565","0.10475"
"454.0000","9.0784","5.33520","0.10492"
"454.4000","9.0865","5.32479","0.10509"
"454.8000","9.0945","5.31660","0.10526"
"455.2000","9.1026","5.30652","0.10543"
"455.6000","9.1105","5.29662","0.10560"
"456.0000","9.1184","5.28354","0.10577"
"456.4000","9.1267","5.27457","0.10595"
"456.8000","9.1344","5.26252","0.10611"
"457.2000","9.1423","5.24998","0.10629"
"457.6000","9.1505","5.24006","0.10646"
"458.0000","9.1587","5.22827","0.10664"
"458.4000","9.1665","5.21537","0.10681"
"458.8000","9.1745","5.20067","0.10698"
"459.2000","9.1827","5.19010","0.10716"
"459.6000","9.1903","5.17557","0.10733"
"460.0000","9.1984","5.16123","0.10751"
"460.4000","9.2066","5.14899","0.10769"
"460.8000","9.2146","5.13500","0.10786"
"461.2000","9.2224","5.12049","0.10804"
"461.6000","9.2304","5.10467","0.10822"
"462.0000","9.2387","5.09169","0.10840"
"462.4000","9.2464","5.07475","0.10857"
"462.8000","9.2544","5.05882","0.10875"
"463.2000","9.2625","5.04465","0.10893"
"463.6000","9.2706","5.02885","0.10911"
"464.0000","9.2784","5.01255","0.10929"
"464.4000","9.2865","4.99418","0.10948"
"464.8000","9.2948","4.97979","0.10966"
"465.2000","9.3023","4.96047","0.10983"
"465.6000","9.3104","4.94237","0.11002"
"466.0000","9.3185","4.92712","0.11020"
"466.4000","9.3266","4.90857","0.11039"
"466.8000","9.3345","4.88955","0.11057"
"467.2000","9.3425","4.87032","0.11076"
"467.6000","9.3507","4.85300","0.11095"
"468.0000","9.3583","4.83149","0.11113"
"468.4000","9.3664","4.81119","0.11132"
"468.8000","9.3746","4.79260","0.11151"
"469.2000","9.3826","4.77202","0.11170"
"469.6000","9.3904","4.75054","0.11188"
"470.0000","9.3985","4.72829","0.11208"
"470.4000","9.4067","4.70877","0.11227"
"470.8000","9.4143","4.68320","0.11246"
"471.2000","9.4225","4.65953","0.11266"
"471.6000","9.4306","4.63856","0.11285"
"472.0000","9.4385","4.61381","0.11304"
"472.4000","9.4464","4.58913","0.11324"
"472.8000","9.4546","4.56369","0.11344"
"473.2000","9.4627","4.53964","0.11364"
"473.6000","9.4703","4.51047","0.11383"
"474.0000","9.4785","4.48329","0.11404"
"474.4000","9.4865","4.45723","0.11424"
"474.8000","9.4946","4.42780","0.11444"
"475.2000","9.5024","4.39793","0.11465"
"475.6000","9.5106","4.36743","0.11486"
"476.0000","9.5187","4.33831","0.11507"
"476.4000","9.5262","4.30392","0.11527"
"476.8000","9.5345","4.27031","0.11549"
"477.2000","9.5426","4.23730","0.11571"
"477.6000","9.5505","4.19973","0.11593"
"478.0000","9.5584","4.16112","0.11615"
"478.4000","9.5666","4.11857","0.11639"
"478.8000","9.5747","4.07103","0.11663"
"479.2000","9.5824","4.01714","0.11688"
"479.6000","9.5906","3.95551","0.11715"
"480.0000","9.5985","3.89291","0.11742"
"480.4000","9.6065","3.82315","0.11771"
"480.8000","9.6144","3.74926","0.11800"
"481.2000","9.6227","3.66618","0.11832"
"481.6000","9.6307","3.56290","0.11867"
"481.9680","9.6378","3.35978","0.11919"