File: Coupon Test Data/Tensile Test_Neebajan_Alan_5.csv
Time,Displacement,Force,Strain 1
(s),(mm),(kN),(mm/mm)
"0.0000","-8.6462","0.16688","-0.00021"
"0.3000","-8.6418","0.19595","-0.00018"
"0.6000","-8.6359","0.24223","-0.00015"
"0.9000","-8.6300","0.28670","-0.00010"
"1.2000","-8.6239","0.33250","-0.00007"
"1.5000","-8.6178","0.37863","-0.00003"
"1.8000","-8.6118","0.42299","0.00002"
"2.1000","-8.6056","0.46904","0.00005"
"2.4000","-8.5998","0.51250","0.00009"
"2.7000","-8.5938","0.55620","0.00013"
"3.0000","-8.5879","0.59873","0.00016"
"3.3000","-8.5818","0.64239","0.00020"
"3.6000","-8.5757","0.68592","0.00024"
"3.9000","-8.5698","0.72893","0.00028"
"4.2000","-8.5638","0.77251","0.00032"
"4.5000","-8.5576","0.81670","0.00035"
"4.8000","-8.5518","0.85786","0.00039"
"5.1000","-8.5458","0.90034","0.00043"
"5.4000","-8.5399","0.94170","0.00046"
"5.7000","-8.5337","0.98574","0.00050"
"6.0000","-8.5278","1.02677","0.00054"
"6.3000","-8.5217","1.06944","0.00057"
"6.6000","-8.5157","1.11179","0.00061"
"6.9000","-8.5099","1.15222","0.00065"
"7.2000","-8.5038","1.19455","0.00068"
"7.5000","-8.4979","1.23521","0.00072"
"7.8000","-8.4916","1.27901","0.00076"
"8.1000","-8.4858","1.31839","0.00079"
"8.4000","-8.4796","1.36094","0.00083"
"8.7000","-8.4737","1.40109","0.00086"
"9.0000","-8.4677","1.44221","0.00090"
"9.3000","-8.4619","1.47593","0.00093"
"9.6000","-8.4559","1.51671","0.00097"
"9.9000","-8.4497","1.55888","0.00100"
"10.2000","-8.4438","1.59927","0.00104"
"10.5000","-8.4377","1.64027","0.00108"
"10.8000","-8.4318","1.68023","0.00111"
"11.1000","-8.4258","1.71998","0.00115"
"11.4000","-8.4199","1.75960","0.00118"
"11.7000","-8.4138","1.79524","0.00121"
"12.0000","-8.4077","1.83666","0.00125"
"12.3000","-8.4017","1.87680","0.00128"
"12.6000","-8.3958","1.91604","0.00132"
"12.9000","-8.3897","1.95668","0.00135"
"13.2000","-8.3838","1.99498","0.00139"
"13.5000","-8.3778","2.03346","0.00142"
"13.8000","-8.3720","2.06827","0.00145"
"14.1000","-8.3656","2.10988","0.00149"
"14.4000","-8.3597","2.14885","0.00153"
"14.7000","-8.3537","2.18738","0.00156"
"15.0000","-8.3477","2.22637","0.00160"
"15.3000","-8.3419","2.26354","0.00163"
"15.6000","-8.3357","2.29852","0.00166"
"15.9000","-8.3299","2.33528","0.00169"
"16.2000","-8.3235","2.37666","0.00173"
"16.5000","-8.3177","2.41310","0.00177"
"16.8000","-8.3117","2.45160","0.00180"
"17.1000","-8.3058","2.48812","0.00183"
"17.4000","-8.2997","2.52217","0.00187"
"17.7000","-8.2938","2.55859","0.00190"
"18.0000","-8.2879","2.59489","0.00194"
"18.3000","-8.2817","2.63313","0.00197"
"18.6000","-8.2756","2.67048","0.00201"
"18.9000","-8.2697","2.70373","0.00204"
"19.2000","-8.2638","2.73754","0.00207"
"19.5000","-8.2578","2.77347","0.00211"
"19.8000","-8.2518","2.80940","0.00214"
"20.1000","-8.2458","2.84505","0.00217"
"20.4000","-8.2397","2.88128","0.00221"
"20.7000","-8.2335","2.91316","0.00224"
"21.0000","-8.2278","2.94596","0.00227"
"21.3000","-8.2217","2.98247","0.00231"
"21.6000","-8.2159","3.01538","0.00234"
"21.9000","-8.2096","3.05121","0.00238"
"22.2000","-8.2040","3.07816","0.00240"
"22.5000","-8.1976","3.11443","0.00244"
"22.8000","-8.1917","3.14718","0.00247"
"23.1000","-8.1857","3.18067","0.00251"
"23.4000","-8.1798","3.21250","0.00254"
"23.7000","-8.1738","3.24091","0.00258"
"24.0000","-8.1677","3.27186","0.00261"
"24.3000","-8.1619","3.30190","0.00264"
"24.6000","-8.1556","3.33519","0.00268"
"24.9000","-8.1497","3.36447","0.00272"
"25.2000","-8.1437","3.39469","0.00275"
"25.5000","-8.1379","3.41883","0.00278"
"25.8000","-8.1317","3.44954","0.00282"
"26.1000","-8.1258","3.47749","0.00285"
"26.4000","-8.1198","3.50496","0.00289"
"26.7000","-8.1139","3.53207","0.00293"
"27.0000","-8.1075","3.55671","0.00296"
"27.3000","-8.1018","3.58110","0.00299"
"27.6000","-8.0957","3.60703","0.00304"
"27.9000","-8.0899","3.63008","0.00307"
"28.2000","-8.0836","3.65439","0.00311"
"28.5000","-8.0779","3.67482","0.00315"
"28.8000","-8.0717","3.69326","0.00319"
"29.1000","-8.0656","3.71345","0.00323"
"29.4000","-8.0598","3.73047","0.00327"
"29.7000","-8.0537","3.74790","0.00331"
"30.0000","-8.0479","3.76255","0.00335"
"30.3000","-8.0415","3.77887","0.00339"
"30.6000","-8.0359","3.78996","0.00343"
"30.9000","-8.0296","3.80426","0.00348"
"31.2000","-8.0238","3.81419","0.00352"
"31.5000","-8.0176","3.82448","0.00357"
"31.8000","-8.0118","3.82799","0.00361"
"32.1000","-8.0058","3.83872","0.00365"
"32.4000","-7.9997","3.84802","0.00369"
"32.7000","-7.9938","3.85390","0.00374"
"33.0000","-7.9877","3.86177","0.00378"
"33.3000","-7.9817","3.86639","0.00383"
"33.6000","-7.9757","3.87252","0.00387"
"33.9000","-7.9698","3.87551","0.00391"
"34.2000","-7.9638","3.88112","0.00396"
"34.5000","-7.9577","3.88577","0.00400"
"34.8000","-7.9518","3.88999","0.00405"
"35.1000","-7.9459","3.89360","0.00409"
"35.4000","-7.9396","3.89794","0.00414"
"35.7000","-7.9338","3.90053","0.00418"
"36.0000","-7.9277","3.90315","0.00423"
"36.3000","-7.9219","3.90548","0.00427"
"36.6000","-7.9156","3.91034","0.00432"
"36.9000","-7.9097","3.91240","0.00437"
"37.2000","-7.9037","3.91459","0.00441"
"37.5000","-7.8976","3.91703","0.00446"
"37.8000","-7.8918","3.91819","0.00450"
"38.1000","-7.8856","3.92128","0.00455"
"38.4000","-7.8799","3.92207","0.00459"
"38.7000","-7.8735","3.92696","0.00464"
"39.0000","-7.8678","3.92657","0.00468"
"39.3000","-7.8617","3.92950","0.00473"
"39.6000","-7.8558","3.92925","0.00477"
"39.9000","-7.8497","3.93289","0.00482"
"40.2000","-7.8438","3.93338","0.00486"
"40.5000","-7.8378","3.93507","0.00490"
"40.8000","-7.8318","3.93710","0.00495"
"41.1000","-7.8257","3.93875","0.00499"
"41.4000","-7.8198","3.94035","0.00504"
"41.7000","-7.8137","3.94120","0.00509"
"42.0000","-7.8078","3.94251","0.00513"
"42.3000","-7.8017","3.94314","0.00517"
"42.6000","-7.7958","3.94433","0.00522"
"42.9000","-7.7897","3.94638","0.00526"
"43.2000","-7.7836","3.94819","0.00530"
"43.5000","-7.7779","3.94856","0.00535"
"43.8000","-7.7717","3.95042","0.00540"
"44.1000","-7.7659","3.95078","0.00544"
"44.4000","-7.7596","3.95291","0.00549"
"44.7000","-7.7540","3.95216","0.00553"
"45.0000","-7.7476","3.95570","0.00558"
"45.3000","-7.7418","3.95575","0.00563"
"45.6000","-7.7357","3.95719","0.00567"
"45.9000","-7.7297","3.95730","0.00572"
"46.2000","-7.7237","3.95861","0.00577"
"46.5000","-7.7176","3.96051","0.00581"
"46.8000","-7.7118","3.96010","0.00587"
"47.1000","-7.7056","3.96324","0.00592"
"47.4000","-7.6998","3.96321","0.00596"
"47.7000","-7.6938","3.96484","0.00602"
"48.0000","-7.6878","3.96455","0.00607"
"48.3000","-7.6817","3.96656","0.00612"
"48.6000","-7.6757","3.96701","0.00617"
"48.9000","-7.6698","3.96673","0.00622"
"49.2000","-7.6638","3.96874","0.00627"
"49.5000","-7.6576","3.97026","0.00633"
"49.8000","-7.6519","3.97064","0.00638"
"50.1000","-7.6457","3.97092","0.00643"
"50.4000","-7.6399","3.97150","0.00648"
"50.7000","-7.6336","3.97318","0.00654"
"51.0000","-7.6278","3.97368","0.00659"
"51.3000","-7.6217","3.97496","0.00664"
"51.6000","-7.6157","3.97607","0.00670"
"51.9000","-7.6098","3.97609","0.00675"
"52.2000","-7.6037","3.97766","0.00680"
"52.5000","-7.5978","3.97723","0.00686"
"52.8000","-7.5915","3.97991","0.00691"
"53.1000","-7.5858","3.97877","0.00696"
"53.4000","-7.5797","3.98143","0.00702"
"53.7000","-7.5738","3.98134","0.00707"
"54.0000","-7.5677","3.98234","0.00713"
"54.3000","-7.5617","3.98241","0.00719"
"54.6000","-7.5558","3.98282","0.00724"
"54.9000","-7.5496","3.98494","0.00730"
"55.2000","-7.5437","3.98424","0.00735"
"55.5000","-7.5377","3.98623","0.00741"
"55.8000","-7.5318","3.98571","0.00746"
"56.1000","-7.5259","3.98745","0.00752"
"56.4000","-7.5198","3.98737","0.00757"
"56.7000","-7.5138","3.98887","0.00763"
"57.0000","-7.5077","3.98959","0.00768"
"57.3000","-7.5017","3.98966","0.00774"
"57.6000","-7.4959","3.98983","0.00780"
"57.9000","-7.4897","3.99139","0.00786"
"58.2000","-7.4839","3.99130","0.00791"
"58.5000","-7.4777","3.99250","0.00797"
"58.8000","-7.4719","3.99210","0.00803"
"59.1000","-7.4655","3.99479","0.00809"
"59.4000","-7.4597","3.99486","0.00815"
"59.7000","-7.4537","3.99539","0.00821"
"60.0000","-7.4477","3.99565","0.00827"
"60.3000","-7.4419","3.99594","0.00833"
"60.6000","-7.4357","3.99722","0.00839"
"60.9000","-7.4299","3.99660","0.00844"
"61.2000","-7.4235","3.99993","0.00851"
"61.5000","-7.4177","3.99876","0.00856"
"61.8000","-7.4117","4.00044","0.00863"
"62.1000","-7.4059","3.99952","0.00868"
"62.4000","-7.3997","4.00107","0.00874"
"62.7000","-7.3938","4.00089","0.00880"
"63.0000","-7.3878","4.00136","0.00887"
"63.3000","-7.3817","4.00270","0.00893"
"63.6000","-7.3756","4.00368","0.00899"
"63.9000","-7.3698","4.00388","0.00905"
"64.2000","-7.3637","4.00419","0.00911"
"64.5000","-7.3579","4.00461","0.00918"
"64.8000","-7.3517","4.00587","0.00924"
"65.1000","-7.3458","4.00601","0.00930"
"65.4000","-7.3396","4.00734","0.00936"
"65.7000","-7.3336","4.00771","0.00943"
"66.0000","-7.3279","4.00719","0.00949"
"66.3000","-7.3217","4.00860","0.00955"
"66.6000","-7.3159","4.00862","0.00962"
"66.9000","-7.3095","4.01068","0.00968"
"67.2000","-7.3039","4.00934","0.00974"
"67.5000","-7.2975","4.01246","0.00981"
"67.8000","-7.2917","4.01214","0.00987"
"68.1000","-7.2857","4.01308","0.00994"
"68.4000","-7.2798","4.01278","0.01000"
"68.7000","-7.2738","4.01320","0.01006"
"69.0000","-7.2677","4.01455","0.01012"
"69.3000","-7.2618","4.01383","0.01019"
"69.6000","-7.2556","4.01559","0.01025"
"69.9000","-7.2497","4.01531","0.01031"
"70.2000","-7.2438","4.01635","0.01037"
"70.5000","-7.2379","4.01590","0.01044"
"70.8000","-7.2318","4.01712","0.01050"
"71.1000","-7.2257","4.01798","0.01056"
"71.4000","-7.2197","4.01783","0.01063"
"71.7000","-7.2138","4.01918","0.01069"
"72.0000","-7.2076","4.02000","0.01076"
"72.3000","-7.2018","4.01936","0.01082"
"72.6000","-7.1958","4.01979","0.01088"
"72.9000","-7.1900","4.02024","0.01094"
"73.2000","-7.1836","4.02215","0.01102"
"73.5000","-7.1777","4.02188","0.01108"
"73.8000","-7.1717","4.02281","0.01114"
"74.1000","-7.1657","4.02364","0.01121"
"74.4000","-7.1599","4.02344","0.01127"
"74.7000","-7.1538","4.02453","0.01133"
"75.0000","-7.1479","4.02420","0.01140"
"75.3000","-7.1415","4.02685","0.01147"
"75.6000","-7.1358","4.02540","0.01153"
"75.9000","-7.1296","4.02746","0.01159"
"76.2000","-7.1237","4.02738","0.01166"
"76.5000","-7.1177","4.02810","0.01172"
"76.8000","-7.1118","4.02756","0.01179"
"77.1000","-7.1059","4.02790","0.01185"
"77.4000","-7.0997","4.03021","0.01192"
"77.7000","-7.0937","4.02978","0.01198"
"78.0000","-7.0877","4.03117","0.01205"
"78.3000","-7.0817","4.03079","0.01211"
"78.6000","-7.0758","4.03161","0.01218"
"78.9000","-7.0699","4.03110","0.01224"
"79.2000","-7.0638","4.03255","0.01231"
"79.5000","-7.0576","4.03382","0.01237"
"79.8000","-7.0516","4.03372","0.01244"
"80.1000","-7.0458","4.03361","0.01250"
"80.4000","-7.0396","4.03502","0.01257"
"80.7000","-7.0339","4.03477","0.01263"
"81.0000","-7.0277","4.03596","0.01270"
"81.3000","-7.0220","4.03514","0.01276"
"81.6000","-7.0156","4.03801","0.01283"
"81.9000","-7.0097","4.03790","0.01290"
"82.2000","-7.0037","4.03831","0.01296"
"82.5000","-6.9977","4.03884","0.01303"
"82.8000","-6.9918","4.03869","0.01309"
"83.1000","-6.9857","4.04012","0.01316"
"83.4000","-6.9799","4.03916","0.01322"
"83.7000","-6.9735","4.04260","0.01329"
"84.0000","-6.9677","4.04073","0.01335"
"84.3000","-6.9616","4.04245","0.01341"
"84.6000","-6.9558","4.04150","0.01347"
"84.9000","-6.9497","4.04320","0.01354"
"85.2000","-6.9438","4.04250","0.01360"
"85.5000","-6.9379","4.04291","0.01367"
"85.8000","-6.9317","4.04486","0.01374"
"86.1000","-6.9256","4.04549","0.01380"
"86.4000","-6.9198","4.04539","0.01386"
"86.7000","-6.9137","4.04561","0.01393"
"87.0000","-6.9079","4.04625","0.01399"
"87.3000","-6.9018","4.04681","0.01406"
"87.6000","-6.8959","4.04701","0.01412"
"87.9000","-6.8897","4.04868","0.01419"
"88.2000","-6.8836","4.04937","0.01426"
"88.5000","-6.8778","4.04864","0.01432"
"88.8000","-6.8717","4.04959","0.01438"
"89.1000","-6.8659","4.04922","0.01445"
"89.4000","-6.8596","4.05088","0.01451"
"89.7000","-6.8540","4.04951","0.01458"
"90.0000","-6.8476","4.05307","0.01464"
"90.3000","-6.8417","4.05267","0.01471"
"90.6000","-6.8356","4.05323","0.01477"
"90.9000","-6.8298","4.05283","0.01484"
"91.2000","-6.8238","4.05351","0.01490"
"91.5000","-6.8177","4.05486","0.01497"
"91.8000","-6.8119","4.05397","0.01503"
"92.1000","-6.8056","4.05670","0.01510"
"92.4000","-6.7996","4.05595","0.01516"
"92.7000","-6.7937","4.05661","0.01523"
"93.0000","-6.7878","4.05602","0.01529"
"93.3000","-6.7817","4.05728","0.01536"
"93.6000","-6.7757","4.05771","0.01542"
"93.9000","-6.7699","4.05728","0.01549"
"94.2000","-6.7638","4.05872","0.01555"
"94.5000","-6.7576","4.05978","0.01562"
"94.8000","-6.7518","4.05939","0.01568"
"95.1000","-6.7457","4.05975","0.01575"
"95.4000","-6.7399","4.06008","0.01581"
"95.7000","-6.7337","4.06158","0.01588"
"96.0000","-6.7278","4.06160","0.01594"
"96.3000","-6.7217","4.06294","0.01601"
"96.6000","-6.7156","4.06382","0.01607"
"96.9000","-6.7098","4.06308","0.01613"
"97.2000","-6.7037","4.06386","0.01620"
"97.5000","-6.6979","4.06339","0.01626"
"97.8000","-6.6915","4.06586","0.01633"
"98.1000","-6.6859","4.06418","0.01639"
"98.4000","-6.6797","4.06106","0.01645"
"98.7000","-6.6737","4.06497","0.01651"
"99.0000","-6.6676","4.06709","0.01657"
"99.3000","-6.6618","4.06698","0.01664"
"99.6000","-6.6558","4.06741","0.01670"
"99.9000","-6.6497","4.06941","0.01676"
"100.2000","-6.6438","4.06872","0.01683"
"100.5000","-6.6377","4.07044","0.01689"
"100.8000","-6.6317","4.06983","0.01696"
"101.1000","-6.6257","4.07089","0.01702"
"101.4000","-6.6198","4.06997","0.01709"
"101.7000","-6.6138","4.07087","0.01715"
"102.0000","-6.6077","4.07155","0.01721"
"102.3000","-6.6017","4.07205","0.01728"
"102.6000","-6.5959","4.07234","0.01734"
"102.9000","-6.5896","4.07402","0.01741"
"103.2000","-6.5838","4.07340","0.01747"
"103.5000","-6.5777","4.07406","0.01754"
"103.8000","-6.5720","4.07328","0.01760"
"104.1000","-6.5656","4.07607","0.01767"
"104.4000","-6.5597","4.07567","0.01773"
"104.7000","-6.5537","4.07640","0.01780"
"105.0000","-6.5476","4.07694","0.01786"
"105.3000","-6.5418","4.07683","0.01792"
"105.6000","-6.5356","4.07810","0.01799"
"105.9000","-6.5299","4.07677","0.01805"
"106.2000","-6.5235","4.07992","0.01812"
"106.5000","-6.5178","4.07835","0.01818"
"106.8000","-6.5117","4.08035","0.01824"
"107.1000","-6.5058","4.07973","0.01831"
"107.4000","-6.4997","4.08107","0.01838"
"107.7000","-6.4938","4.08043","0.01844"
"108.0000","-6.4878","4.08055","0.01851"
"108.3000","-6.4817","4.08210","0.01857"
"108.6000","-6.4757","4.08266","0.01864"
"108.9000","-6.4698","4.08276","0.01870"
"109.2000","-6.4637","4.08316","0.01877"
"109.5000","-6.4578","4.08362","0.01883"
"109.8000","-6.4517","4.08389","0.01890"
"110.1000","-6.4458","4.08379","0.01896"
"110.4000","-6.4397","4.08519","0.01902"
"110.7000","-6.4336","4.08590","0.01909"
"111.0000","-6.4279","4.08559","0.01915"
"111.3000","-6.4217","4.08692","0.01922"
"111.6000","-6.4158","4.08647","0.01928"
"111.9000","-6.4096","4.08815","0.01935"
"112.2000","-6.4039","4.08662","0.01941"
"112.5000","-6.3976","4.08945","0.01948"
"112.8000","-6.3918","4.08916","0.01954"
"113.1000","-6.3857","4.08989","0.01960"
"113.4000","-6.3798","4.08979","0.01967"
"113.7000","-6.3737","4.09039","0.01973"
"114.0000","-6.3676","4.09152","0.01980"
"114.3000","-6.3618","4.09057","0.01986"
"114.6000","-6.3556","4.09274","0.01993"
"114.9000","-6.3498","4.09214","0.01999"
"115.2000","-6.3438","4.09313","0.02005"
"115.5000","-6.3378","4.09282","0.02012"
"115.8000","-6.3317","4.09389","0.02018"
"116.1000","-6.3257","4.09413","0.02025"
"116.4000","-6.3198","4.09384","0.02031"
"116.7000","-6.3138","4.09515","0.02038"
"117.0000","-6.3077","4.09587","0.02044"
"117.3000","-6.3019","4.09566","0.02051"
"117.6000","-6.2957","4.09611","0.02057"
"117.9000","-6.2898","4.09651","0.02063"
"118.2000","-6.2836","4.09765","0.02070"
"118.5000","-6.2778","4.09740","0.02076"
"118.8000","-6.2717","4.09815","0.02083"
"119.1000","-6.2657","4.09895","0.02089"
"119.4000","-6.2599","4.09862","0.02096"
"119.7000","-6.2537","4.10011","0.02102"
"120.0000","-6.2478","4.09948","0.02108"
"120.3000","-6.2415","4.10185","0.02115"
"120.6000","-6.2358","4.10030","0.02121"
"120.9000","-6.2296","4.10245","0.02128"
"121.2000","-6.2238","4.10219","0.02134"
"121.5000","-6.2177","4.10314","0.02141"
"121.8000","-6.2118","4.10322","0.02147"
"122.1000","-6.2058","4.10325","0.02154"
"122.4000","-6.1996","4.10494","0.02160"
"122.7000","-6.1937","4.10418","0.02166"
"123.0000","-6.1877","4.10554","0.02172"
"123.3000","-6.1818","4.10486","0.02179"
"123.6000","-6.1758","4.10605","0.02185"
"123.9000","-6.1698","4.10556","0.02191"
"124.2000","-6.1638","4.10656","0.02198"
"124.5000","-6.1576","4.10748","0.02204"
"124.8000","-6.1517","4.10775","0.02210"
"125.1000","-6.1458","4.10776","0.02217"
"125.4000","-6.1397","4.10888","0.02223"
"125.7000","-6.1339","4.10872","0.02229"
"126.0000","-6.1277","4.10965","0.02236"
"126.3000","-6.1218","4.10929","0.02242"
"126.6000","-6.1156","4.11124","0.02249"
"126.9000","-6.1096","4.11132","0.02255"
"127.2000","-6.1037","4.11117","0.02261"
"127.5000","-6.0977","4.11205","0.02267"
"127.8000","-6.0919","4.11167","0.02273"
"128.1000","-6.0857","4.11344","0.02280"
"128.4000","-6.0799","4.11206","0.02286"
"128.7000","-6.0735","4.11502","0.02293"
"129.0000","-6.0677","4.11369","0.02299"
"129.3000","-6.0617","4.11514","0.02305"
"129.6000","-6.0558","4.11448","0.02312"
"129.9000","-6.0497","4.11598","0.02318"
"130.2000","-6.0437","4.11560","0.02324"
"130.5000","-6.0378","4.11557","0.02331"
"130.8000","-6.0317","4.11723","0.02337"
"131.1000","-6.0256","4.11750","0.02344"
"131.4000","-6.0197","4.11785","0.02350"
"131.7000","-6.0138","4.11755","0.02356"
"132.0000","-6.0079","4.11856","0.02362"
"132.3000","-6.0018","4.11907","0.02369"
"132.6000","-5.9957","4.11960","0.02375"
"132.9000","-5.9897","4.12009","0.02382"
"133.2000","-5.9835","4.12132","0.02388"
"133.5000","-5.9779","4.11996","0.02394"
"133.8000","-5.9717","4.12168","0.02400"
"134.1000","-5.9659","4.12082","0.02406"
"134.4000","-5.9596","4.12332","0.02413"
"134.7000","-5.9539","4.12115","0.02419"
"135.0000","-5.9476","4.12411","0.02426"
"135.3000","-5.9417","4.12356","0.02432"
"135.6000","-5.9357","4.12425","0.02438"
"135.9000","-5.9298","4.12374","0.02444"
"136.2000","-5.9239","4.12442","0.02450"
"136.5000","-5.9177","4.12595","0.02457"
"136.8000","-5.9118","4.12501","0.02463"
"137.1000","-5.9056","4.12744","0.02469"
"137.4000","-5.8997","4.12658","0.02475"
"137.7000","-5.8937","4.12759","0.02482"
"138.0000","-5.8879","4.12670","0.02488"
"138.3000","-5.8817","4.12852","0.02495"
"138.6000","-5.8757","4.12860","0.02501"
"138.9000","-5.8697","4.12881","0.02507"
"139.2000","-5.8638","4.12934","0.02513"
"139.5000","-5.8575","4.13068","0.02520"
"139.8000","-5.8519","4.12959","0.02525"
"140.1000","-5.8457","4.13049","0.02532"
"140.4000","-5.8400","4.13012","0.02538"
"140.7000","-5.8336","4.13244","0.02545"
"141.0000","-5.8278","4.13157","0.02551"
"141.3000","-5.8216","4.13284","0.02557"
"141.6000","-5.8156","4.13314","0.02563"
"141.9000","-5.8099","4.13279","0.02569"
"142.2000","-5.8038","4.13365","0.02575"
"142.5000","-5.7979","4.13326","0.02581"
"142.8000","-5.7915","4.13597","0.02588"
"143.1000","-5.7858","4.13430","0.02594"
"143.4000","-5.7796","4.13645","0.02600"
"143.7000","-5.7737","4.13596","0.02606"
"144.0000","-5.7677","4.13654","0.02613"
"144.3000","-5.7618","4.13590","0.02619"
"144.6000","-5.7559","4.13642","0.02625"
"144.9000","-5.7497","4.13836","0.02631"
"145.2000","-5.7437","4.13781","0.02638"
"145.5000","-5.7377","4.13896","0.02644"
"145.8000","-5.7317","4.13859","0.02650"
"146.1000","-5.7258","4.13925","0.02656"
"146.4000","-5.7198","4.13890","0.02662"
"146.7000","-5.7139","4.13982","0.02669"
"147.0000","-5.7077","4.14093","0.02675"
"147.3000","-5.7017","4.14117","0.02681"
"147.6000","-5.6958","4.14106","0.02687"
"147.9000","-5.6896","4.14237","0.02693"
"148.2000","-5.6838","4.14189","0.02699"
"148.5000","-5.6777","4.14253","0.02706"
"148.8000","-5.6720","4.14171","0.02712"
"149.1000","-5.6656","4.14464","0.02718"
"149.4000","-5.6597","4.14449","0.02724"
"149.7000","-5.6537","4.14467","0.02730"
"150.0000","-5.6477","4.14502","0.02737"
"150.3000","-5.6418","4.14478","0.02743"
"150.6000","-5.6357","4.14611","0.02749"
"150.9000","-5.6299","4.14500","0.02755"
"151.2000","-5.6235","4.14842","0.02761"
"151.5000","-5.6177","4.14672","0.02768"
"151.8000","-5.6116","4.14821","0.02774"
"152.1000","-5.6058","4.14704","0.02780"
"152.4000","-5.5997","4.14850","0.02786"
"152.7000","-5.5938","4.14796","0.02792"
"153.0000","-5.5879","4.14825","0.02798"
"153.3000","-5.5818","4.14997","0.02804"
"153.6000","-5.5756","4.15069","0.02810"
"153.9000","-5.5698","4.15030","0.02817"
"154.2000","-5.5637","4.15042","0.02823"
"154.5000","-5.5578","4.15089","0.02829"
"154.8000","-5.5518","4.15142","0.02835"
"155.1000","-5.5459","4.15144","0.02841"
"155.4000","-5.5397","4.15286","0.02847"
"155.7000","-5.5335","4.15382","0.02854"
"156.0000","-5.5278","4.15291","0.02859"
"156.3000","-5.5216","4.15377","0.02866"
"156.6000","-5.5159","4.15311","0.02872"
"156.9000","-5.5096","4.15497","0.02878"
"157.2000","-5.5040","4.15344","0.02884"
"157.5000","-5.4976","4.15679","0.02890"
"157.8000","-5.4917","4.15621","0.02896"
"158.1000","-5.4857","4.15670","0.02902"
"158.4000","-5.4798","4.15620","0.02908"
"158.7000","-5.4738","4.15653","0.02915"
"159.0000","-5.4677","4.15785","0.02921"
"159.3000","-5.4619","4.15701","0.02927"
"159.6000","-5.4556","4.15961","0.02933"
"159.9000","-5.4496","4.15892","0.02939"
"160.2000","-5.4437","4.15947","0.02945"
"160.5000","-5.4378","4.15852","0.02951"
"160.8000","-5.4317","4.15968","0.02957"
"161.1000","-5.4257","4.16006","0.02963"
"161.4000","-5.4199","4.15981","0.02969"
"161.7000","-5.4138","4.16134","0.02975"
"162.0000","-5.4076","4.16221","0.02982"
"162.3000","-5.4018","4.16161","0.02987"
"162.6000","-5.3957","4.16169","0.02994"
"162.9000","-5.3899","4.16169","0.03000"
"163.2000","-5.3837","4.16331","0.03006"
"163.5000","-5.3778","4.16322","0.03012"
"163.8000","-5.3717","4.16439","0.03018"
"164.1000","-5.3656","4.16489","0.03024"
"164.4000","-5.3598","4.16423","0.03030"
"164.7000","-5.3537","4.16496","0.03036"
"165.0000","-5.3478","4.16445","0.03042"
"165.3000","-5.3416","4.16665","0.03048"
"165.6000","-5.3359","4.16515","0.03054"
"165.9000","-5.3297","4.16747","0.03060"
"166.2000","-5.3237","4.16735","0.03066"
"166.5000","-5.3177","4.16781","0.03072"
"166.8000","-5.3118","4.16736","0.03078"
"167.1000","-5.3058","4.16731","0.03084"
"167.4000","-5.2997","4.16919","0.03091"
"167.7000","-5.2938","4.16848","0.03096"
"168.0000","-5.2877","4.17006","0.03102"
"168.3000","-5.2817","4.16960","0.03108"
"168.6000","-5.2757","4.17035","0.03114"
"168.9000","-5.2698","4.16972","0.03120"
"169.2000","-5.2638","4.17087","0.03126"
"169.5000","-5.2577","4.17142","0.03132"
"169.8000","-5.2517","4.17176","0.03138"
"170.1000","-5.2459","4.17178","0.03144"
"170.4000","-5.2396","4.17340","0.03150"
"170.7000","-5.2338","4.17236","0.03156"
"171.0000","-5.2276","4.17321","0.03162"
"171.3000","-5.2219","4.17225","0.03168"
"171.6000","-5.2156","4.17478","0.03174"
"171.9000","-5.2098","4.17426","0.03180"
"172.2000","-5.2037","4.17513","0.03186"
"172.5000","-5.1977","4.17560","0.03192"
"172.8000","-5.1918","4.17518","0.03198"
"173.1000","-5.1857","4.17604","0.03204"
"173.4000","-5.1799","4.17499","0.03210"
"173.7000","-5.1735","4.17805","0.03216"
"174.0000","-5.1678","4.17639","0.03222"
"174.3000","-5.1617","4.17759","0.03228"
"174.6000","-5.1558","4.17705","0.03233"
"174.9000","-5.1497","4.17857","0.03239"
"175.2000","-5.1438","4.17790","0.03245"
"175.5000","-5.1378","4.17818","0.03251"
"175.8000","-5.1318","4.17949","0.03257"
"176.1000","-5.1257","4.18008","0.03263"
"176.4000","-5.1198","4.17983","0.03269"
"176.7000","-5.1137","4.18015","0.03275"
"177.0000","-5.1078","4.18026","0.03281"
"177.3000","-5.1017","4.18080","0.03287"
"177.6000","-5.0958","4.18086","0.03293"
"177.9000","-5.0897","4.18203","0.03299"
"178.2000","-5.0837","4.18232","0.03305"
"178.5000","-5.0779","4.18187","0.03310"
"178.8000","-5.0717","4.18320","0.03316"
"179.1000","-5.0658","4.18258","0.03322"
"179.4000","-5.0596","4.18410","0.03328"
"179.7000","-5.0539","4.18239","0.03334"
"180.0000","-5.0476","4.18517","0.03340"
"180.3000","-5.0418","4.18456","0.03345"
"180.6000","-5.0357","4.18549","0.03351"
"180.9000","-5.0297","4.18526","0.03357"
"181.2000","-5.0237","4.18562","0.03363"
"181.5000","-5.0177","4.18646","0.03369"
"181.8000","-5.0118","4.18575","0.03375"
"182.1000","-5.0056","4.18751","0.03381"
"182.4000","-4.9997","4.18703","0.03386"
"182.7000","-4.9938","4.18776","0.03392"
"183.0000","-4.9878","4.18736","0.03398"
"183.3000","-4.9817","4.18830","0.03404"
"183.6000","-4.9757","4.18857","0.03410"
"183.9000","-4.9698","4.18819","0.03416"
"184.2000","-4.9638","4.18903","0.03421"
"184.5000","-4.9577","4.19004","0.03427"
"184.8000","-4.9519","4.18953","0.03433"
"185.1000","-4.9457","4.19013","0.03439"
"185.4000","-4.9399","4.19006","0.03445"
"185.7000","-4.9336","4.19143","0.03451"
"186.0000","-4.9277","4.19092","0.03457"
"186.3000","-4.9217","4.19170","0.03462"
"186.6000","-4.9157","4.19224","0.03468"
"186.9000","-4.9099","4.19177","0.03474"
"187.2000","-4.9037","4.19292","0.03480"
"187.5000","-4.8978","4.19234","0.03486"
"187.8000","-4.8915","4.19445","0.03492"
"188.1000","-4.8858","4.19279","0.03497"
"188.4000","-4.8797","4.19467","0.03503"
"188.7000","-4.8738","4.19436","0.03509"
"189.0000","-4.8677","4.19502","0.03515"
"189.3000","-4.8617","4.19474","0.03520"
"189.6000","-4.8558","4.19471","0.03526"
"189.9000","-4.8496","4.19625","0.03532"
"190.2000","-4.8437","4.19552","0.03538"
"190.5000","-4.8377","4.19687","0.03543"
"190.8000","-4.8318","4.19635","0.03549"
"191.1000","-4.8258","4.19710","0.03555"
"191.4000","-4.8198","4.19688","0.03561"
"191.7000","-4.8138","4.19760","0.03567"
"192.0000","-4.8076","4.19824","0.03573"
"192.3000","-4.8017","4.19831","0.03578"
"192.6000","-4.7959","4.19799","0.03584"
"192.9000","-4.7897","4.19943","0.03590"
"193.2000","-4.7839","4.19884","0.03595"
"193.5000","-4.7777","4.19983","0.03601"
"193.8000","-4.7719","4.19893","0.03607"
"194.1000","-4.7656","4.20112","0.03613"
"194.4000","-4.7597","4.20076","0.03619"
"194.7000","-4.7537","4.20124","0.03624"
"195.0000","-4.7477","4.20130","0.03630"
"195.3000","-4.7419","4.20108","0.03636"
"195.6000","-4.7357","4.20255","0.03642"
"195.9000","-4.7298","4.20123","0.03647"
"196.2000","-4.7235","4.20398","0.03653"
"196.5000","-4.7178","4.20240","0.03659"
"196.8000","-4.7117","4.20370","0.03665"
"197.1000","-4.7059","4.20271","0.03670"
"197.4000","-4.6997","4.20435","0.03676"
"197.7000","-4.6938","4.20383","0.03682"
"198.0000","-4.6878","4.20392","0.03687"
"198.3000","-4.6817","4.20521","0.03693"
"198.6000","-4.6756","4.20563","0.03699"
"198.9000","-4.6698","4.20513","0.03704"
"199.2000","-4.6638","4.20525","0.03710"
"199.5000","-4.6579","4.20553","0.03716"
"199.8000","-4.6517","4.20635","0.03721"
"200.1000","-4.6458","4.20609","0.03727"
"200.4000","-4.6397","4.20724","0.03733"
"200.7000","-4.6336","4.20779","0.03739"
"201.0000","-4.6279","4.20683","0.03744"
"201.3000","-4.6217","4.20804","0.03750"
"201.6000","-4.6159","4.20752","0.03756"
"201.9000","-4.6095","4.20935","0.03761"
"202.2000","-4.6039","4.20748","0.03767"
"202.5000","-4.5975","4.21015","0.03773"
"202.8000","-4.5917","4.20956","0.03778"
"203.1000","-4.5857","4.20996","0.03784"
"203.4000","-4.5798","4.20936","0.03790"
"203.7000","-4.5739","4.20991","0.03795"
"204.0000","-4.5677","4.21140","0.03801"
"204.3000","-4.5618","4.21039","0.03807"
"204.6000","-4.5556","4.21235","0.03812"
"204.9000","-4.5497","4.21144","0.03818"
"205.2000","-4.5438","4.21182","0.03823"
"205.5000","-4.5379","4.21124","0.03829"
"205.8000","-4.5318","4.21240","0.03835"
"206.1000","-4.5257","4.21283","0.03840"
"206.4000","-4.5198","4.21234","0.03846"
"206.7000","-4.5138","4.21315","0.03851"
"207.0000","-4.5076","4.21408","0.03857"
"207.3000","-4.5018","4.21350","0.03862"
"207.6000","-4.4958","4.21362","0.03868"
"207.9000","-4.4899","4.21347","0.03874"
"208.2000","-4.4837","4.21519","0.03879"
"208.5000","-4.4778","4.21475","0.03885"
"208.8000","-4.4717","4.21536","0.03891"
"209.1000","-4.4656","4.21598","0.03896"
"209.4000","-4.4599","4.21520","0.03902"
"209.7000","-4.4537","4.21610","0.03907"
"210.0000","-4.4479","4.21555","0.03913"
"210.3000","-4.4415","4.21789","0.03918"
"210.6000","-4.4358","4.21333","0.03923"
"210.9000","-4.4296","4.21697","0.03928"
"211.2000","-4.4237","4.21720","0.03934"
"211.5000","-4.4177","4.21800","0.03939"
"211.8000","-4.4118","4.21740","0.03945"
"212.1000","-4.4059","4.21749","0.03950"
"212.4000","-4.3997","4.21973","0.03956"
"212.7000","-4.3937","4.21882","0.03961"
"213.0000","-4.3877","4.21994","0.03967"
"213.3000","-4.3817","4.21911","0.03972"
"213.6000","-4.3758","4.21983","0.03978"
"213.9000","-4.3698","4.21908","0.03983"
"214.2000","-4.3638","4.21976","0.03989"
"214.5000","-4.3577","4.22071","0.03994"
"214.8000","-4.3516","4.22096","0.04000"
"215.1000","-4.3458","4.22045","0.04005"
"215.4000","-4.3396","4.22171","0.04011"
"215.7000","-4.3339","4.22087","0.04016"
"216.0000","-4.3277","4.22167","0.04022"
"216.3000","-4.3220","4.22066","0.04027"
"216.6000","-4.3156","4.22346","0.04032"
"216.9000","-4.3097","4.22297","0.04038"
"217.2000","-4.3037","4.22312","0.04043"
"217.5000","-4.2977","4.22325","0.04049"
"217.8000","-4.2918","4.22282","0.04054"
"218.1000","-4.2857","4.22396","0.04059"
"218.4000","-4.2799","4.22268","0.04065"
"218.7000","-4.2735","4.22584","0.04070"
"219.0000","-4.2677","4.22401","0.04076"
"219.3000","-4.2616","4.22527","0.04081"
"219.6000","-4.2558","4.22411","0.04086"
"219.9000","-4.2497","4.22544","0.04092"
"220.2000","-4.2438","4.22465","0.04097"
"220.5000","-4.2379","4.22458","0.04103"
"220.8000","-4.2317","4.22611","0.04109"
"221.1000","-4.2256","4.22666","0.04115"
"221.4000","-4.2198","4.22610","0.04120"
"221.7000","-4.2137","4.22621","0.04125"
"222.0000","-4.2079","4.22632","0.04130"
"222.3000","-4.2018","4.22674","0.04136"
"222.6000","-4.1959","4.22580","0.04141"
"222.9000","-4.1897","4.22778","0.04146"
"223.2000","-4.1836","4.22828","0.04152"
"223.5000","-4.1778","4.22745","0.04157"
"223.8000","-4.1716","4.22839","0.04162"
"224.1000","-4.1659","4.22755","0.04167"
"224.4000","-4.1596","4.22913","0.04173"
"224.7000","-4.1540","4.22745","0.04178"
"225.0000","-4.1476","4.23051","0.04184"
"225.3000","-4.1417","4.22976","0.04189"
"225.6000","-4.1357","4.22997","0.04194"
"225.9000","-4.1298","4.22942","0.04200"
"226.2000","-4.1238","4.22973","0.04205"
"226.5000","-4.1177","4.23063","0.04210"
"226.8000","-4.1119","4.22956","0.04215"
"227.1000","-4.1056","4.23174","0.04220"
"227.4000","-4.0997","4.23105","0.04226"
"227.7000","-4.0937","4.23142","0.04231"
"228.0000","-4.0878","4.23061","0.04236"
"228.3000","-4.0817","4.23145","0.04241"
"228.6000","-4.0757","4.23168","0.04247"
"228.9000","-4.0699","4.23121","0.04251"
"229.2000","-4.0638","4.23244","0.04257"
"229.5000","-4.0576","4.23307","0.04262"
"229.8000","-4.0518","4.23224","0.04267"
"230.1000","-4.0457","4.23218","0.04272"
"230.4000","-4.0399","4.23214","0.04277"
"230.7000","-4.0337","4.23338","0.04283"
"231.0000","-4.0278","4.23311","0.04288"
"231.3000","-4.0217","4.23411","0.04293"
"231.6000","-4.0156","4.23473","0.04298"
"231.9000","-4.0098","4.23380","0.04303"
"232.2000","-4.0037","4.23431","0.04309"
"232.5000","-3.9978","4.23359","0.04314"
"232.8000","-3.9915","4.23569","0.04319"
"233.1000","-3.9859","4.23392","0.04324"
"233.4000","-3.9797","4.23610","0.04329"
"233.7000","-3.9737","4.23553","0.04334"
"234.0000","-3.9677","4.23590","0.04339"
"234.3000","-3.9618","4.23543","0.04344"
"234.6000","-3.9558","4.23520","0.04349"
"234.9000","-3.9497","4.23664","0.04354"
"235.2000","-3.9438","4.23584","0.04359"
"235.5000","-3.9377","4.23732","0.04364"
"235.8000","-3.9317","4.23658","0.04369"
"236.1000","-3.9257","4.23710","0.04374"
"236.4000","-3.9198","4.23621","0.04379"
"236.7000","-3.9138","4.23703","0.04384"
"237.0000","-3.9077","4.23758","0.04389"
"237.3000","-3.9017","4.23758","0.04394"
"237.6000","-3.8958","4.23776","0.04399"
"237.9000","-3.8896","4.23867","0.04404"
"238.2000","-3.8838","4.23793","0.04409"
"238.5000","-3.8777","4.23830","0.04414"
"238.8000","-3.8719","4.23755","0.04419"
"239.1000","-3.8656","4.23923","0.04424"
"239.4000","-3.8597","4.23910","0.04429"
"239.7000","-3.8537","4.23915","0.04434"
"240.0000","-3.8476","4.23985","0.04439"
"240.3000","-3.8418","4.23877","0.04443"
"240.6000","-3.8356","4.24016","0.04448"
"240.9000","-3.8299","4.23858","0.04453"
"241.2000","-3.8235","4.24128","0.04458"
"241.5000","-3.8178","4.23949","0.04463"
"241.8000","-3.8117","4.24108","0.04468"
"242.1000","-3.8058","4.23993","0.04472"
"242.4000","-3.7997","4.24115","0.04477"
"242.7000","-3.7937","4.24042","0.04482"
"243.0000","-3.7878","4.24007","0.04487"
"243.3000","-3.7817","4.24145","0.04491"
"243.6000","-3.7757","4.24150","0.04496"
"243.9000","-3.7698","4.24164","0.04501"
"244.2000","-3.7637","4.24133","0.04506"
"244.5000","-3.7577","4.24178","0.04510"
"244.8000","-3.7517","4.24150","0.04515"
"245.1000","-3.7458","4.24171","0.04520"
"245.4000","-3.7397","4.24213","0.04524"
"245.7000","-3.7336","4.24304","0.04529"
"246.0000","-3.7279","4.24182","0.04534"
"246.3000","-3.7216","4.24334","0.04539"
"246.6000","-3.7159","4.24203","0.04543"
"246.9000","-3.7096","4.24374","0.04548"
"247.2000","-3.7039","4.24154","0.04552"
"247.5000","-3.6976","4.24423","0.04557"
"247.8000","-3.6918","4.24334","0.04562"
"248.1000","-3.6857","4.24393","0.04566"
"248.4000","-3.6798","4.24323","0.04571"
"248.7000","-3.6737","4.24360","0.04575"
"249.0000","-3.6676","4.24417","0.04580"
"249.3000","-3.6618","4.24303","0.04584"
"249.6000","-3.6556","4.24498","0.04589"
"249.9000","-3.6498","4.24387","0.04593"
"250.2000","-3.6438","4.24496","0.04598"
"250.5000","-3.6379","4.24397","0.04602"
"250.8000","-3.6316","4.24528","0.04607"
"251.1000","-3.6257","4.24470","0.04611"
"251.4000","-3.6197","4.24467","0.04616"
"251.7000","-3.6138","4.24471","0.04620"
"252.0000","-3.6076","4.24599","0.04625"
"252.3000","-3.6019","4.24491","0.04629"
"252.6000","-3.5957","4.24556","0.04633"
"252.9000","-3.5899","4.24477","0.04637"
"253.2000","-3.5836","4.24620","0.04642"
"253.5000","-3.5778","4.24509","0.04646"
"253.8000","-3.5717","4.24611","0.04651"
"254.1000","-3.5657","4.24607","0.04655"
"254.4000","-3.5599","4.24545","0.04659"
"254.7000","-3.5537","4.24630","0.04663"
"255.0000","-3.5478","4.24546","0.04667"
"255.3000","-3.5415","4.24746","0.04672"
"255.6000","-3.5358","4.24539","0.04676"
"255.9000","-3.5296","4.24728","0.04680"
"256.2000","-3.5238","4.24641","0.04685"
"256.5000","-3.5177","4.24706","0.04689"
"256.8000","-3.5118","4.24627","0.04693"
"257.1000","-3.5058","4.24638","0.04697"
"257.4000","-3.4996","4.24754","0.04701"
"257.7000","-3.4937","4.24660","0.04705"
"258.0000","-3.4877","4.24727","0.04709"
"258.3000","-3.4817","4.24665","0.04713"
"258.6000","-3.4758","4.24709","0.04717"
"258.9000","-3.4698","4.24672","0.04721"
"259.2000","-3.4638","4.24716","0.04725"
"259.5000","-3.4576","4.24756","0.04729"
"259.8000","-3.4517","4.24735","0.04733"
"260.1000","-3.4459","4.24685","0.04737"
"260.4000","-3.4397","4.24778","0.04741"
"260.7000","-3.4338","4.24715","0.04745"
"261.0000","-3.4276","4.24765","0.04749"
"261.3000","-3.4219","4.24635","0.04753"
"261.6000","-3.4156","4.24838","0.04757"
"261.9000","-3.4097","4.24780","0.04760"
"262.2000","-3.4037","4.24771","0.04764"
"262.5000","-3.3977","4.24766","0.04768"
"262.8000","-3.3919","4.24706","0.04772"
"263.1000","-3.3857","4.24820","0.04775"
"263.4000","-3.3799","4.24672","0.04779"
"263.7000","-3.3735","4.24914","0.04783"
"264.0000","-3.3677","4.24712","0.04786"
"264.3000","-3.3617","4.24808","0.04790"
"264.6000","-3.3559","4.24673","0.04793"
"264.9000","-3.3497","4.24802","0.04797"
"265.2000","-3.3438","4.24731","0.04801"
"265.5000","-3.3378","4.24701","0.04804"
"265.8000","-3.3317","4.24774","0.04808"
"266.1000","-3.3256","4.24781","0.04811"
"266.4000","-3.3198","4.24708","0.04815"
"266.7000","-3.3138","4.24689","0.04818"
"267.0000","-3.3079","4.24693","0.04821"
"267.3000","-3.3017","4.24728","0.04825"
"267.6000","-3.2958","4.24664","0.04828"
"267.9000","-3.2897","4.24738","0.04831"
"268.2000","-3.2836","4.24760","0.04835"
"268.5000","-3.2779","4.24620","0.04838"
"268.8000","-3.2717","4.24684","0.04841"
"269.1000","-3.2659","4.24574","0.04844"
"269.4000","-3.2596","4.24740","0.04847"
"269.7000","-3.2539","4.24502","0.04850"
"270.0000","-3.2475","4.24731","0.04853"
"270.3000","-3.2417","4.24598","0.04856"
"270.6000","-3.2357","4.24593","0.04859"
"270.9000","-3.2298","4.24484","0.04862"
"271.2000","-3.2239","4.24470","0.04865"
"271.5000","-3.2177","4.24575","0.04868"
"271.8000","-3.2118","4.24405","0.04870"
"272.1000","-3.2056","4.24545","0.04873"
"272.4000","-3.1997","4.24395","0.04876"
"272.7000","-3.1938","4.24399","0.04878"
"273.0000","-3.1879","4.24259","0.04881"
"273.3000","-3.1818","4.24298","0.04883"
"273.6000","-3.1757","4.24283","0.04886"
"273.9000","-3.1698","4.24157","0.04888"
"274.2000","-3.1637","4.24177","0.04890"
"274.5000","-3.1576","4.24178","0.04893"
"274.8000","-3.1518","4.24014","0.04895"
"275.1000","-3.1458","4.23942","0.04898"
"275.4000","-3.1400","4.23838","0.04900"
"275.7000","-3.1337","4.23916","0.04902"
"276.0000","-3.1278","4.23763","0.04904"
"276.3000","-3.1216","4.23721","0.04906"
"276.6000","-3.1156","4.23643","0.04908"
"276.9000","-3.1098","4.23452","0.04909"
"277.2000","-3.1037","4.23398","0.04911"
"277.5000","-3.0979","4.23175","0.04913"
"277.8000","-3.0915","4.23262","0.04914"
"278.1000","-3.0858","4.22919","0.04916"
"278.4000","-3.0796","4.22917","0.04917"
"278.7000","-3.0737","4.22650","0.04918"
"279.0000","-3.0677","4.22475","0.04920"
"279.3000","-3.0618","4.22190","0.04921"
"279.6000","-3.0559","4.21942","0.04922"
"279.9000","-3.0496","4.21884","0.04923"
"280.2000","-3.0437","4.21454","0.04923"
"280.5000","-3.0377","4.21256","0.04924"
"280.8000","-3.0317","4.20791","0.04925"
"281.1000","-3.0258","4.20538","0.04925"
"281.4000","-3.0199","4.20051","0.04925"
"281.7000","-3.0139","4.19709","0.04926"
"282.0000","-3.0077","4.19308","0.04926"
"282.3000","-3.0016","4.18817","0.04926"
"282.6000","-2.9958","4.18262","0.04926"
"282.9000","-2.9896","4.17791","0.04926"
"283.2000","-2.9838","4.17123","0.04926"
"283.5000","-2.9777","4.16542","0.04926"
"283.8000","-2.9720","4.15810","0.04925"
"284.1000","-2.9656","4.15367","0.04925"
"284.4000","-2.9597","4.14571","0.04925"
"284.7000","-2.9537","4.13817","0.04924"
"285.0000","-2.9477","4.13039","0.04924"
"285.3000","-2.9418","4.12204","0.04923"
"285.6000","-2.9357","4.11421","0.04922"
"285.9000","-2.9299","4.10404","0.04921"
"286.2000","-2.9235","4.09794","0.04921"
"286.5000","-2.9177","4.08611","0.04920"
"286.8000","-2.9116","4.07797","0.04919"
"287.1000","-2.9058","4.06607","0.04918"
"287.4000","-2.8997","4.05701","0.04917"
"287.7000","-2.8938","4.04522","0.04916"
"288.0000","-2.8879","4.03440","0.04915"
"288.3000","-2.8817","4.02471","0.04914"
"288.6000","-2.8756","4.01264","0.04913"
"288.9000","-2.8698","4.00059","0.04912"
"289.2000","-2.8637","3.98736","0.04910"
"289.5000","-2.8579","3.97583","0.04909"
"289.8000","-2.8517","3.96232","0.04908"
"290.1000","-2.8459","3.94911","0.04906"
"290.4000","-2.8396","3.93629","0.04905"
"290.7000","-2.8336","3.92217","0.04904"
"291.0000","-2.8278","3.90729","0.04902"
"291.3000","-2.8217","3.89209","0.04901"
"291.6000","-2.8158","3.87659","0.04899"
"291.9000","-2.8096","3.86081","0.04898"
"292.2000","-2.8040","3.84413","0.04896"
"292.5000","-2.7976","3.82948","0.04894"
"292.8000","-2.7917","3.81180","0.04893"
"293.1000","-2.7856","3.79357","0.04891"
"293.4000","-2.7798","3.77469","0.04889"
"293.7000","-2.7738","3.75589","0.04887"
"294.0000","-2.7677","3.73623","0.04885"
"294.3000","-2.7619","3.71349","0.04883"
"294.6000","-2.7556","3.69313","0.04880"
"294.9000","-2.7496","3.66649","0.04878"
"295.2000","-2.7437","3.64049","0.04875"
"295.5000","-2.7378","3.60785","0.04872"
"295.8000","-2.7317","3.56795","0.04868"
"296.1000","-2.7257","3.49455","0.04860"
"296.3450","-2.7207","3.32875","0.04842"
"296.3570","-2.7205","3.05157","0.04851"
"296.3620","-2.7204","2.68210","0.04842"
"296.3640","-2.7203","2.51321","0.04829"