File: Coupon Test Data/Tensile Test_Neebajan_Alan_15.csv
Time,Displacement,Force,Strain 1
(s),(mm),(kN),(mm/mm)
"0.0000","0.0000","0.19611","-0.00018"
"0.5000","0.0083","0.30755","-0.00014"
"1.0000","0.0185","0.44699","-0.00008"
"1.5000","0.0284","0.57721","-0.00003"
"2.0000","0.0386","0.70771","0.00002"
"2.5000","0.0486","0.82929","0.00007"
"3.0000","0.0585","0.94331","0.00012"
"3.5000","0.0683","1.06253","0.00017"
"4.0000","0.0784","1.17636","0.00021"
"4.5000","0.0885","1.29497","0.00026"
"5.0000","0.0984","1.40062","0.00030"
"5.5000","0.1086","1.51230","0.00035"
"6.0000","0.1186","1.61377","0.00039"
"6.5000","0.1286","1.71315","0.00043"
"7.0000","0.1385","1.81299","0.00047"
"7.5000","0.1484","1.90664","0.00051"
"8.0000","0.1585","2.00510","0.00055"
"8.5000","0.1684","2.09463","0.00059"
"9.0000","0.1785","2.18388","0.00062"
"9.5000","0.1885","2.27588","0.00066"
"10.0000","0.1985","2.36310","0.00070"
"10.5000","0.2085","2.44579","0.00073"
"11.0000","0.2185","2.53463","0.00077"
"11.5000","0.2287","2.61881","0.00080"
"12.0000","0.2383","2.69529","0.00083"
"12.5000","0.2486","2.77899","0.00087"
"13.0000","0.2585","2.86017","0.00090"
"13.5000","0.2684","2.93545","0.00093"
"14.0000","0.2784","3.01124","0.00096"
"14.5000","0.2885","3.09277","0.00100"
"15.0000","0.2987","3.16973","0.00103"
"15.5000","0.3085","3.24067","0.00106"
"16.0000","0.3186","3.31751","0.00109"
"16.5000","0.3286","3.38999","0.00112"
"17.0000","0.3384","3.45638","0.00115"
"17.5000","0.3484","3.52414","0.00118"
"18.0000","0.3584","3.59608","0.00120"
"18.5000","0.3686","3.66581","0.00123"
"19.0000","0.3785","3.73147","0.00126"
"19.5000","0.3886","3.80136","0.00129"
"20.0000","0.3987","3.87195","0.00132"
"20.5000","0.4084","3.93756","0.00135"
"21.0000","0.4185","4.00504","0.00138"
"21.5000","0.4285","4.07035","0.00140"
"22.0000","0.4384","4.13628","0.00143"
"22.5000","0.4483","4.20064","0.00146"
"23.0000","0.4586","4.26777","0.00148"
"23.5000","0.4687","4.33203","0.00151"
"24.0000","0.4786","4.39857","0.00154"
"24.5000","0.4885","4.46217","0.00156"
"25.0000","0.4986","4.52415","0.00159"
"25.5000","0.5085","4.58730","0.00162"
"26.0000","0.5183","4.64841","0.00164"
"26.5000","0.5284","4.71224","0.00167"
"27.0000","0.5386","4.77752","0.00170"
"27.5000","0.5485","4.84058","0.00172"
"28.0000","0.5587","4.90554","0.00175"
"28.5000","0.5686","4.96834","0.00178"
"29.0000","0.5785","5.03253","0.00180"
"29.5000","0.5884","5.09549","0.00183"
"30.0000","0.5985","5.16131","0.00185"
"30.5000","0.6085","5.22584","0.00188"
"31.0000","0.6183","5.28874","0.00191"
"31.5000","0.6286","5.35542","0.00194"
"32.0000","0.6386","5.41910","0.00197"
"32.5000","0.6486","5.48449","0.00199"
"33.0000","0.6584","5.54746","0.00202"
"33.5000","0.6686","5.61401","0.00205"
"34.0000","0.6787","5.68065","0.00208"
"34.5000","0.6883","5.74306","0.00211"
"35.0000","0.6985","5.81042","0.00213"
"35.5000","0.7086","5.87515","0.00216"
"36.0000","0.7185","5.93971","0.00219"
"36.5000","0.7285","6.00455","0.00222"
"37.0000","0.7385","6.06952","0.00225"
"37.5000","0.7486","6.13760","0.00228"
"38.0000","0.7585","6.20146","0.00231"
"38.5000","0.7686","6.26861","0.00234"
"39.0000","0.7786","6.33352","0.00237"
"39.5000","0.7884","6.39736","0.00239"
"40.0000","0.7984","6.46281","0.00242"
"40.5000","0.8085","6.52771","0.00245"
"41.0000","0.8185","6.59433","0.00249"
"41.5000","0.8284","6.65781","0.00252"
"42.0000","0.8386","6.72590","0.00255"
"42.5000","0.8488","6.79286","0.00258"
"43.0000","0.8584","6.85582","0.00261"
"43.5000","0.8684","6.92024","0.00264"
"44.0000","0.8785","6.98396","0.00267"
"44.5000","0.8885","7.04878","0.00271"
"45.0000","0.8984","7.11133","0.00274"
"45.5000","0.9085","7.17617","0.00277"
"46.0000","0.9186","7.24122","0.00281"
"46.5000","0.9286","7.30420","0.00284"
"47.0000","0.9387","7.36823","0.00288"
"47.5000","0.9486","7.42956","0.00291"
"48.0000","0.9585","7.49144","0.00295"
"48.5000","0.9683","7.54849","0.00298"
"49.0000","0.9785","7.60782","0.00302"
"49.5000","0.9886","7.67308","0.00306"
"50.0000","0.9984","7.72813","0.00310"
"50.5000","1.0086","7.78295","0.00314"
"51.0000","1.0186","7.84326","0.00319"
"51.5000","1.0285","7.89269","0.00323"
"52.0000","1.0384","7.94662","0.00328"
"52.5000","1.0486","8.00184","0.00333"
"53.0000","1.0585","8.03923","0.00338"
"53.5000","1.0683","8.08867","0.00343"
"54.0000","1.0785","8.13492","0.00349"
"54.5000","1.0886","8.17613","0.00356"
"55.0000","1.0986","8.20065","0.00362"
"55.5000","1.1084","8.23631","0.00369"
"56.0000","1.1185","8.26751","0.00377"
"56.5000","1.1287","8.29620","0.00385"
"57.0000","1.1385","8.31511","0.00393"
"57.5000","1.1486","8.33611","0.00403"
"58.0000","1.1585","8.35298","0.00412"
"58.5000","1.1684","8.36722","0.00422"
"59.0000","1.1785","8.37876","0.00432"
"59.5000","1.1886","8.39429","0.00442"
"60.0000","1.1986","8.40835","0.00452"
"60.5000","1.2084","8.41584","0.00463"
"61.0000","1.2186","8.42672","0.00473"
"61.5000","1.2287","8.43645","0.00484"
"62.0000","1.2384","8.44231","0.00495"
"62.5000","1.2484","8.44789","0.00506"
"63.0000","1.2585","8.45607","0.00518"
"63.5000","1.2686","8.45357","0.00528"
"64.0000","1.2784","8.46648","0.00538"
"64.5000","1.2886","8.47623","0.00549"
"65.0000","1.2988","8.48401","0.00561"
"65.5000","1.3085","8.48571","0.00572"
"66.0000","1.3185","8.48945","0.00584"
"66.5000","1.3285","8.49340","0.00595"
"67.0000","1.3384","8.49893","0.00607"
"67.5000","1.3484","8.50161","0.00618"
"68.0000","1.3586","8.50653","0.00630"
"68.5000","1.3687","8.51293","0.00642"
"69.0000","1.3785","8.51593","0.00653"
"69.5000","1.3886","8.51883","0.00665"
"70.0000","1.3987","8.52346","0.00677"
"70.5000","1.4085","8.52607","0.00689"
"71.0000","1.4182","8.52536","0.00700"
"71.5000","1.4285","8.53116","0.00712"
"72.0000","1.4386","8.53609","0.00724"
"72.5000","1.4485","8.53783","0.00736"
"73.0000","1.4586","8.54201","0.00748"
"73.5000","1.4687","8.54559","0.00760"
"74.0000","1.4786","8.54811","0.00771"
"74.5000","1.4884","8.54824","0.00783"
"75.0000","1.4985","8.55236","0.00795"
"75.5000","1.5085","8.55666","0.00807"
"76.0000","1.5184","8.55627","0.00819"
"76.5000","1.5285","8.55981","0.00831"
"77.0000","1.5386","8.56321","0.00843"
"77.5000","1.5486","8.56722","0.00855"
"78.0000","1.5585","8.56681","0.00867"
"78.5000","1.5686","8.57090","0.00879"
"79.0000","1.5787","8.57509","0.00891"
"79.5000","1.5883","8.57366","0.00902"
"80.0000","1.5986","8.57912","0.00915"
"80.5000","1.6086","8.58066","0.00927"
"81.0000","1.6184","8.58136","0.00938"
"81.5000","1.6284","8.58311","0.00951"
"82.0000","1.6386","8.58713","0.00963"
"82.5000","1.6487","8.59184","0.00975"
"83.0000","1.6585","8.59143","0.00987"
"83.5000","1.6686","8.59445","0.00999"
"84.0000","1.6787","8.59807","0.01011"
"84.5000","1.6885","8.55496","0.01020"
"85.0000","1.6984","8.58809","0.01029"
"85.5000","1.7084","8.60302","0.01040"
"86.0000","1.7186","8.60834","0.01052"
"86.5000","1.7284","8.59657","0.01061"
"87.0000","1.7387","8.61044","0.01073"
"87.5000","1.7488","8.61527","0.01085"
"88.0000","1.7584","8.61430","0.01096"
"88.5000","1.7685","8.61535","0.01108"
"89.0000","1.7785","8.61628","0.01120"
"89.5000","1.7884","8.61799","0.01132"
"90.0000","1.7983","8.61873","0.01145"
"90.5000","1.8086","8.62304","0.01156"
"91.0000","1.8187","8.62683","0.01168"
"91.5000","1.8286","8.62722","0.01180"
"92.0000","1.8385","8.62879","0.01192"
"92.5000","1.8486","8.63219","0.01204"
"93.0000","1.8585","8.63362","0.01216"
"93.5000","1.8683","8.63150","0.01228"
"94.0000","1.8784","8.63552","0.01240"
"94.5000","1.8886","8.64031","0.01252"
"95.0000","1.8985","8.64076","0.01264"
"95.5000","1.9087","8.64409","0.01276"
"96.0000","1.9187","8.64599","0.01288"
"96.5000","1.9285","8.64831","0.01300"
"97.0000","1.9384","8.64813","0.01312"
"97.5000","1.9486","8.65141","0.01324"
"98.0000","1.9585","8.65375","0.01336"
"98.5000","1.9683","8.65344","0.01347"
"99.0000","1.9786","8.65719","0.01360"
"99.5000","1.9886","8.65949","0.01371"
"100.0000","1.9986","8.66252","0.01383"
"100.5000","2.0084","8.66149","0.01395"
"101.0000","2.0186","8.66585","0.01407"
"101.5000","2.0287","8.66926","0.01420"
"102.0000","2.0384","8.66764","0.01432"
"102.5000","2.0485","8.67170","0.01443"
"103.0000","2.0586","8.67431","0.01455"
"103.5000","2.0684","8.67422","0.01467"
"104.0000","2.0785","8.67512","0.01479"
"104.5000","2.0885","8.67825","0.01491"
"105.0000","2.0987","8.68417","0.01503"
"105.5000","2.1085","8.68314","0.01514"
"106.0000","2.1186","8.68583","0.01526"
"106.5000","2.1286","8.68838","0.01538"
"107.0000","2.1384","8.68830","0.01550"
"107.5000","2.1485","8.68946","0.01561"
"108.0000","2.1585","8.69180","0.01573"
"108.5000","2.1686","8.69516","0.01585"
"109.0000","2.1783","8.69453","0.01597"
"109.5000","2.1886","8.70002","0.01608"
"110.0000","2.1988","8.70413","0.01620"
"110.5000","2.2085","8.70271","0.01632"
"111.0000","2.2184","8.70420","0.01643"
"111.5000","2.2285","8.70633","0.01655"
"112.0000","2.2385","8.70803","0.01667"
"112.5000","2.2484","8.70841","0.01678"
"113.0000","2.2585","8.71208","0.01690"
"113.5000","2.2687","8.71674","0.01702"
"114.0000","2.2786","8.71744","0.01714"
"114.5000","2.2886","8.71857","0.01725"
"115.0000","2.2986","8.72126","0.01737"
"115.5000","2.3085","8.72315","0.01748"
"116.0000","2.3183","8.72135","0.01760"
"116.5000","2.3285","8.72524","0.01772"
"117.0000","2.3386","8.72868","0.01783"
"117.5000","2.3484","8.72961","0.01795"
"118.0000","2.3587","8.73333","0.01807"
"118.5000","2.3687","8.73475","0.01818"
"119.0000","2.3786","8.73683","0.01830"
"119.5000","2.3884","8.73618","0.01841"
"120.0000","2.3986","8.74065","0.01853"
"120.5000","2.4086","8.74257","0.01864"
"121.0000","2.4184","8.74174","0.01876"
"121.5000","2.4285","8.74473","0.01887"
"122.0000","2.4386","8.74838","0.01899"
"122.5000","2.4486","8.75068","0.01911"
"123.0000","2.4584","8.74974","0.01922"
"123.5000","2.4685","8.75315","0.01934"
"124.0000","2.4787","8.75796","0.01945"
"124.5000","2.4884","8.75572","0.01957"
"125.0000","2.4986","8.76005","0.01968"
"125.5000","2.5086","8.76122","0.01980"
"126.0000","2.5184","8.76188","0.01991"
"126.5000","2.5285","8.76355","0.02003"
"127.0000","2.5386","8.74432","0.02013"
"127.5000","2.5487","8.76458","0.02023"
"128.0000","2.5584","8.76994","0.02034"
"128.5000","2.5687","8.77480","0.02045"
"129.0000","2.5787","8.77681","0.02057"
"129.5000","2.5884","8.77595","0.02068"
"130.0000","2.5984","8.77655","0.02079"
"130.5000","2.6085","8.77970","0.02091"
"131.0000","2.6186","8.78262","0.02102"
"131.5000","2.6284","8.78167","0.02113"
"132.0000","2.6386","8.78628","0.02125"
"132.5000","2.6488","8.79143","0.02136"
"133.0000","2.6585","8.79003","0.02148"
"133.5000","2.6685","8.79050","0.02159"
"134.0000","2.6785","8.79187","0.02170"
"134.5000","2.6884","8.79466","0.02182"
"135.0000","2.6984","8.79505","0.02193"
"135.5000","2.7086","8.79848","0.02204"
"136.0000","2.7187","8.80202","0.02216"
"136.5000","2.7285","8.80259","0.02227"
"137.0000","2.7386","8.80471","0.02238"
"137.5000","2.7487","8.80743","0.02250"
"138.0000","2.7585","8.80830","0.02261"
"138.5000","2.7682","8.80629","0.02272"
"139.0000","2.7785","8.81117","0.02284"
"139.5000","2.7887","8.81459","0.02295"
"140.0000","2.7985","8.81472","0.02306"
"140.5000","2.8086","8.81814","0.02318"
"141.0000","2.8187","8.82086","0.02329"
"141.5000","2.8286","8.79333","0.02338"
"142.0000","2.8384","8.81357","0.02348"
"142.5000","2.8485","8.82426","0.02359"
"143.0000","2.8585","8.82879","0.02370"
"143.5000","2.8684","8.82801","0.02381"
"144.0000","2.8786","8.83088","0.02392"
"144.5000","2.8886","8.83310","0.02404"
"145.0000","2.8986","8.83560","0.02415"
"145.5000","2.9085","8.83503","0.02426"
"146.0000","2.9186","8.83794","0.02437"
"146.5000","2.9286","8.84122","0.02449"
"147.0000","2.9383","8.83946","0.02460"
"147.5000","2.9486","8.84438","0.02471"
"148.0000","2.9586","8.84554","0.02483"
"148.5000","2.9684","8.84548","0.02494"
"149.0000","2.9784","8.84653","0.02505"
"149.5000","2.9886","8.85024","0.02516"
"150.0000","2.9987","8.85467","0.02527"
"150.5000","3.0085","8.85360","0.02539"
"151.0000","3.0186","8.85605","0.02550"
"151.5000","3.0286","8.85938","0.02561"
"152.0000","3.0385","8.85849","0.02572"
"152.5000","3.0484","8.85911","0.02583"
"153.0000","3.0584","8.86154","0.02595"
"153.5000","3.0685","8.86536","0.02606"
"154.0000","3.0784","8.86480","0.02617"
"154.5000","3.0887","8.86916","0.02628"
"155.0000","3.0988","8.87331","0.02640"
"155.5000","3.1085","8.87219","0.02650"
"156.0000","3.1185","8.87325","0.02662"
"156.5000","3.1285","8.87452","0.02673"
"157.0000","3.1385","8.87683","0.02684"
"157.5000","3.1483","8.87680","0.02695"
"158.0000","3.1586","8.88121","0.02708"
"158.5000","3.1687","8.88435","0.02719"
"159.0000","3.1786","8.88430","0.02730"
"159.5000","3.1886","8.88649","0.02741"
"160.0000","3.1986","8.88977","0.02752"
"160.5000","3.2085","8.89003","0.02763"
"161.0000","3.2182","8.88768","0.02774"
"161.5000","3.2284","8.89171","0.02785"
"162.0000","3.2387","8.89680","0.02797"
"162.5000","3.2485","8.89629","0.02808"
"163.0000","3.2586","8.89927","0.02819"
"163.5000","3.2686","8.90085","0.02830"
"164.0000","3.2785","8.90332","0.02841"
"164.5000","3.2885","8.90345","0.02852"
"165.0000","3.2986","8.90553","0.02863"
"165.5000","3.3085","8.90743","0.02874"
"166.0000","3.3183","8.90667","0.02885"
"166.5000","3.3286","8.91095","0.02897"
"167.0000","3.3387","8.91359","0.02908"
"167.5000","3.3486","8.91520","0.02919"
"168.0000","3.3584","8.91433","0.02930"
"168.5000","3.3686","8.91821","0.02941"
"169.0000","3.3787","8.92136","0.02952"
"169.5000","3.3884","8.92005","0.02963"
"170.0000","3.3985","8.92328","0.02974"
"170.5000","3.4086","8.92553","0.02985"
"171.0000","3.4185","8.90906","0.02994"
"171.5000","3.4285","8.92271","0.03004"
"172.0000","3.4386","8.92992","0.03016"
"172.5000","3.4486","8.93507","0.03027"
"173.0000","3.4584","8.93372","0.03037"
"173.5000","3.4686","8.93684","0.03048"
"174.0000","3.4786","8.93882","0.03060"
"174.5000","3.4884","8.93848","0.03071"
"175.0000","3.4984","8.93889","0.03082"
"175.5000","3.5085","8.94091","0.03093"
"176.0000","3.5186","8.94387","0.03104"
"176.5000","3.5283","8.94321","0.03115"
"177.0000","3.5387","8.94870","0.03126"
"177.5000","3.5488","8.95170","0.03137"
"178.0000","3.5584","8.94988","0.03148"
"178.5000","3.5684","8.95133","0.03159"
"179.0000","3.5785","8.95354","0.03170"
"179.5000","3.5885","8.95494","0.03181"
"180.0000","3.5984","8.95467","0.03192"
"180.5000","3.6085","8.95754","0.03203"
"181.0000","3.6187","8.96235","0.03214"
"181.5000","3.6286","8.96289","0.03225"
"182.0000","3.6386","8.96367","0.03236"
"182.5000","3.6486","8.96591","0.03247"
"183.0000","3.6585","8.96764","0.03258"
"183.5000","3.6683","8.96528","0.03269"
"184.0000","3.6785","8.96862","0.03280"
"184.5000","3.6886","8.97257","0.03291"
"185.0000","3.6984","8.97292","0.03303"
"185.5000","3.7087","8.97626","0.03314"
"186.0000","3.7187","8.97779","0.03325"
"186.5000","3.7286","8.97884","0.03336"
"187.0000","3.7384","8.97835","0.03347"
"187.5000","3.7486","8.98221","0.03358"
"188.0000","3.7586","8.98405","0.03369"
"188.5000","3.7683","8.98284","0.03380"
"189.0000","3.7785","8.98583","0.03391"
"189.5000","3.7886","8.98890","0.03402"
"190.0000","3.7986","8.99103","0.03413"
"190.5000","3.8084","8.98969","0.03424"
"191.0000","3.8185","8.99285","0.03435"
"191.5000","3.8287","8.99714","0.03446"
"192.0000","3.8384","8.99475","0.03457"
"192.5000","3.8486","8.99892","0.03468"
"193.0000","3.8586","8.99962","0.03479"
"193.5000","3.8684","9.00009","0.03490"
"194.0000","3.8785","9.00136","0.03501"
"194.5000","3.8886","9.00367","0.03512"
"195.0000","3.8986","9.00749","0.03523"
"195.5000","3.9084","9.00678","0.03534"
"196.0000","3.9187","9.01043","0.03545"
"196.5000","3.9287","8.98435","0.03554"
"197.0000","3.9384","9.00219","0.03564"
"197.5000","3.9484","9.01031","0.03575"
"198.0000","3.9585","9.01545","0.03585"
"198.5000","3.9686","9.01880","0.03596"
"199.0000","3.9784","9.01731","0.03607"
"199.5000","3.9886","9.02134","0.03618"
"200.0000","3.9988","9.02601","0.03629"
"200.5000","4.0085","9.02412","0.03640"
"201.0000","4.0185","9.02471","0.03651"
"201.5000","4.0285","9.02555","0.03662"
"202.0000","4.0384","9.02747","0.03673"
"202.5000","4.0484","9.02746","0.03684"
"203.0000","4.0586","9.03058","0.03695"
"203.5000","4.0687","9.03384","0.03706"
"204.0000","4.0785","9.03423","0.03717"
"204.5000","4.0886","9.03566","0.03728"
"205.0000","4.0986","9.03780","0.03739"
"205.5000","4.1085","9.03888","0.03750"
"206.0000","4.1182","9.03627","0.03761"
"206.5000","4.1285","9.04059","0.03772"
"207.0000","4.1386","9.04393","0.03783"
"207.5000","4.1485","9.04357","0.03794"
"208.0000","4.1586","9.04650","0.03805"
"208.5000","4.1687","9.04861","0.03816"
"209.0000","4.1786","9.04965","0.03827"
"209.5000","4.1884","9.04859","0.03838"
"210.0000","4.1985","9.05121","0.03849"
"210.5000","4.2085","9.05398","0.03860"
"211.0000","4.2184","9.05321","0.03871"
"211.5000","4.2286","9.05558","0.03882"
"212.0000","4.2386","9.05760","0.03893"
"212.5000","4.2486","9.06054","0.03904"
"213.0000","4.2585","9.05932","0.03915"
"213.5000","4.2686","9.06213","0.03926"
"214.0000","4.2787","9.06511","0.03937"
"214.5000","4.2883","9.06308","0.03948"
"215.0000","4.2986","9.06738","0.03959"
"215.5000","4.3086","9.06857","0.03970"
"216.0000","4.3184","9.06787","0.03981"
"216.5000","4.3284","9.06887","0.03992"
"217.0000","4.3386","9.07241","0.04003"
"217.5000","4.3488","9.07628","0.04014"
"218.0000","4.3585","9.07426","0.04025"
"218.5000","4.3686","9.07652","0.04036"
"219.0000","4.3786","9.07980","0.04047"
"219.5000","4.3885","9.07879","0.04058"
"220.0000","4.3984","9.07883","0.04069"
"220.5000","4.4084","9.08074","0.04080"
"221.0000","4.4186","9.08450","0.04091"
"221.5000","4.4284","9.08323","0.04102"
"222.0000","4.4387","9.08723","0.04113"
"222.5000","4.4488","9.09087","0.04124"
"223.0000","4.4584","9.08888","0.04135"
"223.5000","4.4685","9.09012","0.04146"
"224.0000","4.4785","9.09102","0.04157"
"224.5000","4.4884","9.09200","0.04167"
"225.0000","4.4983","9.06927","0.04177"
"225.5000","4.5086","9.08894","0.04187"
"226.0000","4.5187","9.09796","0.04197"
"226.5000","4.5286","9.09988","0.04208"
"227.0000","4.5386","9.10110","0.04219"
"227.5000","4.5486","9.10383","0.04230"
"228.0000","4.5585","9.10430","0.04241"
"228.5000","4.5682","9.10152","0.04252"
"229.0000","4.5784","9.10457","0.04263"
"229.5000","4.5886","9.10860","0.04274"
"230.0000","4.5985","9.10822","0.04285"
"230.5000","4.6087","9.11051","0.04296"
"231.0000","4.6186","9.11164","0.04307"
"231.5000","4.6285","9.11345","0.04317"
"232.0000","4.6384","9.11236","0.04329"
"232.5000","4.6486","9.11453","0.04339"
"233.0000","4.6585","9.11623","0.04350"
"233.5000","4.6683","9.11517","0.04361"
"234.0000","4.6786","9.11877","0.04372"
"234.5000","4.6886","9.12039","0.04384"
"235.0000","4.6986","9.12227","0.04395"
"235.5000","4.7084","9.12055","0.04405"
"236.0000","4.7186","9.12442","0.04417"
"236.5000","4.7287","9.12717","0.04428"
"237.0000","4.7383","9.12410","0.04438"
"237.5000","4.7485","9.12789","0.04449"
"238.0000","4.7586","9.12984","0.04461"
"238.5000","4.7684","9.12896","0.04471"
"239.0000","4.7785","9.12957","0.04482"
"239.5000","4.7886","9.13192","0.04493"
"240.0000","4.7987","9.13629","0.04504"
"240.5000","4.8085","9.13487","0.04515"
"241.0000","4.8186","9.13722","0.04526"
"241.5000","4.8286","9.13862","0.04537"
"242.0000","4.8384","9.13799","0.04548"
"242.5000","4.8485","9.13874","0.04559"
"243.0000","4.8585","9.14033","0.04570"
"243.5000","4.8686","9.14258","0.04581"
"244.0000","4.8783","9.14138","0.04592"
"244.5000","4.8887","9.14602","0.04603"
"245.0000","4.8988","9.14929","0.04614"
"245.5000","4.9085","9.14712","0.04625"
"246.0000","4.9185","9.14783","0.04636"
"246.5000","4.9285","9.14938","0.04647"
"247.0000","4.9385","9.15039","0.04658"
"247.5000","4.9484","9.14988","0.04669"
"248.0000","4.9585","9.15261","0.04680"
"248.5000","4.9687","9.15695","0.04691"
"249.0000","4.9786","9.15660","0.04702"
"249.5000","4.9886","9.15706","0.04713"
"250.0000","4.9986","9.15918","0.04724"
"250.5000","5.0085","9.16011","0.04735"
"251.0000","5.0183","9.15754","0.04746"
"251.5000","5.0285","9.16070","0.04757"
"252.0000","5.0386","9.16348","0.04768"
"252.5000","5.0484","9.16329","0.04779"
"253.0000","5.0587","9.16647","0.04790"
"253.5000","5.0687","9.16742","0.04801"
"254.0000","5.0786","9.16815","0.04812"
"254.5000","5.0883","9.16673","0.04823"
"255.0000","5.0986","9.17069","0.04834"
"255.5000","5.1086","9.17172","0.04845"
"256.0000","5.1184","9.17025","0.04856"
"256.5000","5.1285","9.17244","0.04867"
"257.0000","5.1386","9.17505","0.04878"
"257.5000","5.1486","9.17660","0.04889"
"258.0000","5.1584","9.17488","0.04900"
"258.5000","5.1685","9.17772","0.04911"
"259.0000","5.1787","9.18119","0.04922"
"259.5000","5.1884","9.17851","0.04933"
"260.0000","5.1986","9.18213","0.04944"
"260.5000","5.2086","9.18236","0.04955"
"261.0000","5.2184","9.18213","0.04966"
"261.5000","5.2285","9.18302","0.04977"
"262.0000","5.2386","9.18496","0.04988"
"262.5000","5.2487","9.18871","0.04999"
"263.0000","5.2584","9.18679","0.05010"
"263.5000","5.2687","9.19036","0.05021"
"264.0000","5.2787","9.19149","0.05032"
"264.5000","5.2884","9.18962","0.05043"
"265.0000","5.2984","9.19013","0.05054"
"265.5000","5.3085","9.19245","0.05065"
"266.0000","5.3186","9.19465","0.05076"
"266.5000","5.3284","9.19299","0.05087"
"267.0000","5.3386","9.19672","0.05098"
"267.5000","5.3489","9.20140","0.05110"
"268.0000","5.3585","9.19874","0.05121"
"268.5000","5.3685","9.19841","0.05132"
"269.0000","5.3785","9.19888","0.05142"
"269.5000","5.3885","9.20136","0.05153"
"270.0000","5.3984","9.20053","0.05164"
"270.5000","5.4086","9.20315","0.05175"
"271.0000","5.4187","9.20581","0.05187"
"271.5000","5.4285","9.20548","0.05198"
"272.0000","5.4387","9.20757","0.05209"
"272.5000","5.4487","9.20908","0.05220"
"273.0000","5.4585","9.20886","0.05231"
"273.5000","5.4682","9.20594","0.05242"
"274.0000","5.4785","9.20962","0.05253"
"274.5000","5.4887","9.21271","0.05264"
"275.0000","5.4984","9.21112","0.05275"
"275.5000","5.5086","9.18841","0.05284"
"276.0000","5.5187","9.20746","0.05294"
"276.5000","5.5286","9.21471","0.05304"
"277.0000","5.5385","9.21610","0.05315"
"277.5000","5.5485","9.21797","0.05326"
"278.0000","5.5585","9.22029","0.05337"
"278.5000","5.5683","9.21851","0.05348"
"279.0000","5.5786","9.22101","0.05359"
"279.5000","5.5886","9.22282","0.05370"
"280.0000","5.5986","9.22397","0.05381"
"280.5000","5.6084","9.22236","0.05392"
"281.0000","5.6186","9.22449","0.05403"
"281.5000","5.6287","9.22694","0.05414"
"282.0000","5.6383","9.22480","0.05425"
"282.5000","5.6486","9.22772","0.05436"
"283.0000","5.6586","9.22838","0.05447"
"283.5000","5.6684","9.22722","0.05458"
"284.0000","5.6784","9.22818","0.05469"
"284.5000","5.6886","9.23140","0.05480"
"285.0000","5.6987","9.23367","0.05492"
"285.5000","5.7084","9.23137","0.05502"
"286.0000","5.7186","9.23351","0.05514"
"286.5000","5.7287","9.23589","0.05525"
"287.0000","5.7385","9.23467","0.05536"
"287.5000","5.7484","9.23392","0.05547"
"288.0000","5.7584","9.23522","0.05558"
"288.5000","5.7686","9.23820","0.05569"
"289.0000","5.7784","9.23696","0.05580"
"289.5000","5.7887","9.24048","0.05591"
"290.0000","5.7988","9.24282","0.05602"
"290.5000","5.8084","9.24064","0.05613"
"291.0000","5.8185","9.24171","0.05624"
"291.5000","5.8285","9.24207","0.05635"
"292.0000","5.8384","9.24252","0.05646"
"292.5000","5.8483","9.24220","0.05657"
"293.0000","5.8586","9.24536","0.05668"
"293.5000","5.8687","9.24788","0.05680"
"294.0000","5.8786","9.24722","0.05691"
"294.5000","5.8886","9.24740","0.05702"
"295.0000","5.8986","9.24991","0.05713"
"295.5000","5.9086","9.24997","0.05724"
"296.0000","5.9182","9.24631","0.05735"
"296.5000","5.9284","9.24902","0.05746"
"297.0000","5.9386","9.25315","0.05757"
"297.5000","5.9485","9.25214","0.05768"
"298.0000","5.9587","9.25420","0.05779"
"298.5000","5.9686","9.25501","0.05790"
"299.0000","5.9785","9.25579","0.05801"
"299.5000","5.9884","9.25476","0.05812"
"300.0000","5.9986","9.25689","0.05824"
"300.5000","6.0085","9.25799","0.05835"
"301.0000","6.0183","9.25599","0.05846"
"301.5000","6.0286","9.25919","0.05857"
"302.0000","6.0386","9.26040","0.05868"
"302.5000","6.0486","9.26160","0.05879"
"303.0000","6.0584","9.25962","0.05890"
"303.5000","6.0686","9.26308","0.05901"
"304.0000","6.0787","9.26530","0.05913"
"304.5000","6.0883","9.26114","0.05924"
"305.0000","6.0986","9.26479","0.05935"
"305.5000","6.1086","9.26609","0.05946"
"306.0000","6.1185","9.26493","0.05957"
"306.5000","6.1285","9.26507","0.05968"
"307.0000","6.1385","9.26662","0.05979"
"307.5000","6.1487","9.27047","0.05990"
"308.0000","6.1585","9.26873","0.06001"
"308.5000","6.1686","9.27040","0.06012"
"309.0000","6.1786","9.27151","0.06024"
"309.5000","6.1884","9.27011","0.06035"
"310.0000","6.1985","9.27043","0.06046"
"310.5000","6.2085","9.27144","0.06057"
"311.0000","6.2186","9.27328","0.06068"
"311.5000","6.2283","9.27149","0.06079"
"312.0000","6.2387","9.27600","0.06090"
"312.5000","6.2488","9.27846","0.06102"
"313.0000","6.2584","9.27552","0.06112"
"313.5000","6.2684","9.27588","0.06123"
"314.0000","6.2785","9.27712","0.06135"
"314.5000","6.2885","9.27732","0.06146"
"315.0000","6.2984","9.27645","0.06157"
"315.5000","6.3085","9.27877","0.06168"
"316.0000","6.3187","9.28244","0.06179"
"316.5000","6.3286","9.28159","0.06190"
"317.0000","6.3386","9.28149","0.06202"
"317.5000","6.3486","9.28276","0.06213"
"318.0000","6.3585","9.28361","0.06224"
"318.5000","6.3683","9.28026","0.06235"
"319.0000","6.3785","9.28274","0.06246"
"319.5000","6.3886","9.28526","0.06258"
"320.0000","6.3984","9.28439","0.06268"
"320.5000","6.4087","9.28709","0.06280"
"321.0000","6.4187","9.28766","0.06291"
"321.5000","6.4285","9.28765","0.06302"
"322.0000","6.4384","9.28625","0.06313"
"322.5000","6.4486","9.28910","0.06324"
"323.0000","6.4586","9.28968","0.06335"
"323.5000","6.4684","9.28754","0.06346"
"324.0000","6.4785","9.28959","0.06358"
"324.5000","6.4886","9.29154","0.06369"
"325.0000","6.4986","9.29290","0.06380"
"325.5000","6.5084","9.29040","0.06391"
"326.0000","6.5185","9.29234","0.06402"
"326.5000","6.5287","9.29548","0.06414"
"327.0000","6.5384","9.29266","0.06425"
"327.5000","6.5486","9.29495","0.06436"
"328.0000","6.5586","9.29513","0.06447"
"328.5000","6.5684","9.29429","0.06458"
"329.0000","6.5785","9.29481","0.06469"
"329.5000","6.5886","9.29653","0.06481"
"330.0000","6.5987","9.29965","0.06492"
"330.5000","6.6084","9.29690","0.06503"
"331.0000","6.6187","9.29971","0.06514"
"331.5000","6.6287","9.30058","0.06525"
"332.0000","6.6384","9.29846","0.06537"
"332.5000","6.6484","9.29779","0.06547"
"333.0000","6.6585","9.30038","0.06559"
"333.5000","6.6686","9.30197","0.06570"
"334.0000","6.6784","9.29949","0.06581"
"334.5000","6.6886","9.30280","0.06593"
"335.0000","6.6988","9.30687","0.06604"
"335.5000","6.7085","9.30354","0.06615"
"336.0000","6.7185","9.30320","0.06626"
"336.5000","6.7285","9.30333","0.06637"
"337.0000","6.7384","9.30430","0.06648"
"337.5000","6.7484","9.30349","0.06659"
"338.0000","6.7586","9.30573","0.06671"
"338.5000","6.7687","9.30771","0.06682"
"339.0000","6.7785","9.30704","0.06693"
"339.5000","6.7887","9.30794","0.06704"
"340.0000","6.7987","9.28760","0.06712"
"340.5000","6.8085","9.30189","0.06723"
"341.0000","6.8182","9.30453","0.06733"
"341.5000","6.8285","9.30990","0.06745"
"342.0000","6.8386","9.31254","0.06756"
"342.5000","6.8484","9.31107","0.06767"
"343.0000","6.8586","9.31310","0.06778"
"343.5000","6.8687","9.31397","0.06789"
"344.0000","6.8786","9.31401","0.06800"
"344.5000","6.8884","9.31159","0.06812"
"345.0000","6.8985","9.31298","0.06823"
"345.5000","6.9085","9.31472","0.06834"
"346.0000","6.9184","9.31251","0.06845"
"346.5000","6.9286","9.31405","0.06856"
"347.0000","6.9386","9.31510","0.06867"
"347.5000","6.9486","9.31660","0.06879"
"348.0000","6.9585","9.31431","0.06890"
"348.5000","6.9686","9.31620","0.06901"
"349.0000","6.9787","9.31813","0.06912"
"349.5000","6.9883","9.31456","0.06923"
"350.0000","6.9986","9.31808","0.06935"
"350.5000","7.0086","9.31793","0.06946"
"351.0000","7.0184","9.31674","0.06957"
"351.5000","7.0284","9.31692","0.06968"
"352.0000","7.0386","9.31927","0.06979"
"352.5000","7.0487","9.32149","0.06991"
"353.0000","7.0585","9.31893","0.07002"
"353.5000","7.0686","9.32028","0.07013"
"354.0000","7.0786","9.32195","0.07024"
"354.5000","7.0885","9.32008","0.07035"
"355.0000","7.0984","9.31922","0.07047"
"355.5000","7.1084","9.32022","0.07058"
"356.0000","7.1186","9.32245","0.07069"
"356.5000","7.1284","9.32024","0.07080"
"357.0000","7.1387","9.32345","0.07092"
"357.5000","7.1488","9.32597","0.07103"
"358.0000","7.1584","9.32310","0.07114"
"358.5000","7.1685","9.32330","0.07125"
"359.0000","7.1785","9.32329","0.07136"
"359.5000","7.1884","9.32338","0.07147"
"360.0000","7.1983","9.32244","0.07158"
"360.5000","7.2086","9.32559","0.07170"
"361.0000","7.2187","9.32756","0.07181"
"361.5000","7.2286","9.32575","0.07192"
"362.0000","7.2385","9.32573","0.07203"
"362.5000","7.2486","9.32792","0.07215"
"363.0000","7.2585","9.32724","0.07226"
"363.5000","7.2682","9.32342","0.07237"
"364.0000","7.2784","9.32577","0.07248"
"364.5000","7.2886","9.32905","0.07259"
"365.0000","7.2985","9.32775","0.07270"
"365.5000","7.3087","9.32918","0.07282"
"366.0000","7.3186","9.32949","0.07293"
"366.5000","7.3285","9.32978","0.07304"
"367.0000","7.3384","9.32770","0.07315"
"367.5000","7.3486","9.32981","0.07326"
"368.0000","7.3585","9.33040","0.07337"
"368.5000","7.3683","9.32815","0.07348"
"369.0000","7.3786","9.33080","0.07360"
"369.5000","7.3886","9.33133","0.07371"
"370.0000","7.3986","9.33177","0.07382"
"370.5000","7.4084","9.32957","0.07393"
"371.0000","7.4186","9.33225","0.07405"
"371.5000","7.4287","9.33403","0.07416"
"372.0000","7.4383","9.33007","0.07427"
"372.5000","7.4485","9.33311","0.07438"
"373.0000","7.4586","9.33399","0.07449"
"373.5000","7.4684","9.33192","0.07460"
"374.0000","7.4785","9.33170","0.07471"
"374.5000","7.4885","9.33290","0.07483"
"375.0000","7.4987","9.33656","0.07494"
"375.5000","7.5085","9.33406","0.07505"
"376.0000","7.5187","9.33528","0.07516"
"376.5000","7.5286","9.33565","0.07527"
"377.0000","7.5384","9.33365","0.07538"
"377.5000","7.5485","9.33388","0.07550"
"378.0000","7.5585","9.33444","0.07561"
"378.5000","7.5686","9.33572","0.07572"
"379.0000","7.5783","9.33371","0.07583"
"379.5000","7.5887","9.33738","0.07594"
"380.0000","7.5989","9.34007","0.07605"
"380.5000","7.6085","9.33592","0.07616"
"381.0000","7.6184","9.33549","0.07627"
"381.5000","7.6285","9.33657","0.07638"
"382.0000","7.6385","9.33716","0.07650"
"382.5000","7.6484","9.33534","0.07660"
"383.0000","7.6585","9.33700","0.07672"
"383.5000","7.6687","9.33986","0.07683"
"384.0000","7.6786","9.33814","0.07694"
"384.5000","7.6887","9.33894","0.07705"
"385.0000","7.6986","9.33977","0.07716"
"385.5000","7.7085","9.33933","0.07727"
"386.0000","7.7183","9.33561","0.07738"
"386.5000","7.7285","9.33781","0.07749"
"387.0000","7.7387","9.34031","0.07760"
"387.5000","7.7484","9.33854","0.07771"
"388.0000","7.7586","9.34100","0.07783"
"388.5000","7.7687","9.34073","0.07794"
"389.0000","7.7785","9.34035","0.07805"
"389.5000","7.7884","9.33899","0.07815"
"390.0000","7.7986","9.34100","0.07827"
"390.5000","7.8086","9.34108","0.07838"
"391.0000","7.8183","9.33824","0.07849"
"391.5000","7.8285","9.34028","0.07860"
"392.0000","7.8387","9.34238","0.07871"
"392.5000","7.8486","9.34245","0.07881"
"393.0000","7.8584","9.33947","0.07893"
"393.5000","7.8685","9.34083","0.07904"
"394.0000","7.8787","9.34367","0.07914"
"394.5000","7.8884","9.34123","0.07925"
"395.0000","7.8986","9.34232","0.07937"
"395.5000","7.9086","9.34193","0.07948"
"396.0000","7.9184","9.34066","0.07958"
"396.5000","7.9285","9.34108","0.07970"
"397.0000","7.9386","9.34264","0.07981"
"397.5000","7.9486","9.34405","0.07992"
"398.0000","7.9584","9.34144","0.08002"
"398.5000","7.9687","9.34385","0.08013"
"399.0000","7.9787","9.34436","0.08024"
"399.5000","7.9884","9.34200","0.08035"
"400.0000","7.9984","9.34059","0.08046"
"400.5000","8.0085","9.34228","0.08056"
"401.0000","8.0186","9.34372","0.08067"
"401.5000","8.0284","9.34129","0.08078"
"402.0000","8.0386","9.34386","0.08089"
"402.5000","8.0488","9.34688","0.08100"
"403.0000","8.0585","9.34362","0.08111"
"403.5000","8.0685","9.34313","0.08121"
"404.0000","8.0785","9.34284","0.08132"
"404.5000","8.0884","9.34321","0.08143"
"405.0000","8.0984","9.34210","0.08154"
"405.5000","8.1086","9.34371","0.08165"
"406.0000","8.1187","9.34515","0.08175"
"406.5000","8.1285","9.34451","0.08186"
"407.0000","8.1386","9.34463","0.08197"
"407.5000","8.1487","9.34513","0.08207"
"408.0000","8.1585","9.34420","0.08218"
"408.5000","8.1682","9.34037","0.08228"
"409.0000","8.1785","9.34326","0.08239"
"409.5000","8.1887","9.34537","0.08250"
"410.0000","8.1985","9.34347","0.08260"
"410.5000","8.2086","9.34481","0.08271"
"411.0000","8.2187","9.34576","0.08282"
"411.5000","8.2286","9.34517","0.08292"
"412.0000","8.2384","9.34263","0.08303"
"412.5000","8.2485","9.34402","0.08313"
"413.0000","8.2585","9.34519","0.08324"
"413.5000","8.2684","9.34268","0.08334"
"414.0000","8.2786","9.34404","0.08344"
"414.5000","8.2886","9.34461","0.08355"
"415.0000","8.2986","9.34558","0.08365"
"415.5000","8.3085","9.34313","0.08376"
"416.0000","8.3186","9.34462","0.08386"
"416.5000","8.3287","9.34604","0.08396"
"417.0000","8.3383","9.34202","0.08407"
"417.5000","8.3486","9.34521","0.08417"
"418.0000","8.3586","9.34473","0.08427"
"418.5000","8.3684","9.34282","0.08438"
"419.0000","8.3784","9.34261","0.08448"
"419.5000","8.3886","9.34419","0.08458"
"420.0000","8.3987","9.34588","0.08468"
"420.5000","8.4085","9.34350","0.08478"
"421.0000","8.4186","9.34449","0.08489"
"421.5000","8.4287","9.34562","0.08499"
"422.0000","8.4385","9.34305","0.08509"
"422.5000","8.4484","9.34187","0.08519"
"423.0000","8.4584","9.34227","0.08529"
"423.5000","8.4686","9.34432","0.08539"
"424.0000","8.4784","9.34179","0.08549"
"424.5000","8.4887","9.34410","0.08558"
"425.0000","8.4988","9.34605","0.08568"
"425.5000","8.5084","9.34283","0.08578"
"426.0000","8.5185","9.34291","0.08588"
"426.5000","8.5285","9.34223","0.08597"
"427.0000","8.5384","9.34179","0.08607"
"427.5000","8.5483","9.34033","0.08617"
"428.0000","8.5586","9.34292","0.08627"
"428.5000","8.5687","9.34420","0.08636"
"429.0000","8.5785","9.34232","0.08646"
"429.5000","8.5885","9.34181","0.08655"
"430.0000","8.5986","9.34307","0.08665"
"430.5000","8.6086","9.34230","0.08674"
"431.0000","8.6182","9.33779","0.08683"
"431.5000","8.6284","9.33946","0.08692"
"432.0000","8.6386","9.34233","0.08702"
"432.5000","8.6485","9.34062","0.08711"
"433.0000","8.6587","9.34157","0.08720"
"433.5000","8.6687","9.34119","0.08729"
"434.0000","8.6785","9.34081","0.08738"
"434.5000","8.6884","9.33854","0.08747"
"435.0000","8.6986","9.33949","0.08756"
"435.5000","8.7085","9.33950","0.08765"
"436.0000","8.7183","9.33702","0.08774"
"436.5000","8.7286","9.33883","0.08782"
"437.0000","8.7386","9.33872","0.08791"
"437.5000","8.7486","9.33910","0.08800"
"438.0000","8.7584","9.33599","0.08808"
"438.5000","8.7686","9.33789","0.08817"
"439.0000","8.7787","9.33870","0.08825"
"439.5000","8.7884","9.33460","0.08833"
"440.0000","8.7985","9.33638","0.08842"
"440.5000","8.8086","9.33674","0.08850"
"441.0000","8.8184","9.33421","0.08858"
"441.5000","8.8284","9.33319","0.08866"
"442.0000","8.8385","9.33378","0.08874"
"442.5000","8.8487","9.33669","0.08882"
"443.0000","8.8585","9.33318","0.08889"
"443.5000","8.8686","9.33318","0.08897"
"444.0000","8.8786","9.33344","0.08904"
"444.5000","8.8884","9.33088","0.08912"
"445.0000","8.8985","9.32950","0.08919"
"445.5000","8.9085","9.32937","0.08926"
"446.0000","8.9186","9.33001","0.08934"
"446.5000","8.9283","9.32680","0.08941"
"447.0000","8.9387","9.32957","0.08948"
"447.5000","8.9488","9.33116","0.08955"
"448.0000","8.9585","9.32641","0.08961"
"448.5000","8.9684","9.32515","0.08968"
"449.0000","8.9786","9.32493","0.08974"
"449.5000","8.9885","9.32346","0.08981"
"450.0000","8.9984","9.32116","0.08987"
"450.5000","9.0085","9.32186","0.08993"
"451.0000","9.0187","9.32349","0.08999"
"451.5000","9.0286","9.32076","0.09005"
"452.0000","9.0386","9.31951","0.09011"
"452.5000","9.0486","9.31890","0.09016"
"453.0000","9.0585","9.31765","0.09022"
"453.5000","9.0683","9.31242","0.09028"
"454.0000","9.0785","9.31300","0.09033"
"454.5000","9.0886","9.31345","0.09038"
"455.0000","9.0984","9.31083","0.09043"
"455.5000","9.1087","9.31096","0.09048"
"456.0000","9.1187","9.30908","0.09053"
"456.5000","9.1285","9.30719","0.09057"
"457.0000","9.1384","9.30361","0.09062"
"457.5000","9.1486","9.30378","0.09066"
"458.0000","9.1586","9.30181","0.09070"
"458.5000","9.1684","9.29713","0.09074"
"459.0000","9.1785","9.29639","0.09078"
"459.5000","9.1886","9.29587","0.09082"
"460.0000","9.1987","9.29413","0.09086"
"460.5000","9.2084","9.28850","0.09089"
"461.0000","9.2185","9.28785","0.09092"
"461.5000","9.2287","9.28801","0.09096"
"462.0000","9.2384","9.28104","0.09099"
"462.5000","9.2486","9.28039","0.09102"
"463.0000","9.2586","9.27704","0.09104"
"463.5000","9.2684","9.27280","0.09107"
"464.0000","9.2785","9.26932","0.09110"
"464.5000","9.2886","9.26698","0.09112"
"465.0000","9.2987","9.26578","0.09115"
"465.5000","9.3084","9.25940","0.09117"
"466.0000","9.3187","9.25788","0.09119"
"466.5000","9.3287","9.25378","0.09121"
"467.0000","9.3384","9.24733","0.09123"
"467.5000","9.3484","9.24213","0.09124"
"468.0000","9.3585","9.23951","0.09126"
"468.5000","9.3686","9.23557","0.09127"
"469.0000","9.3784","9.22818","0.09129"
"469.5000","9.3886","9.22607","0.09131"
"470.0000","9.3988","9.22423","0.09132"
"470.5000","9.4085","9.21567","0.09133"
"471.0000","9.4185","9.20869","0.09134"
"471.5000","9.4285","9.20280","0.09135"
"472.0000","9.4384","9.19795","0.09136"
"472.5000","9.4484","9.18995","0.09137"
"473.0000","9.4586","9.18503","0.09137"
"473.5000","9.4687","9.18096","0.09138"
"474.0000","9.4785","9.17288","0.09139"
"474.5000","9.4886","9.16575","0.09140"
"475.0000","9.4987","9.15962","0.09140"
"475.5000","9.5085","9.15138","0.09140"
"476.0000","9.5182","9.13996","0.09140"
"476.5000","9.5285","9.13508","0.09141"
"477.0000","9.5387","9.12812","0.09141"
"477.5000","9.5485","9.11852","0.09141"
"478.0000","9.5586","9.11159","0.09142"
"478.5000","9.5687","9.10373","0.09142"
"479.0000","9.5786","9.09436","0.09142"
"479.5000","9.5884","9.08186","0.09142"
"480.0000","9.5985","9.07406","0.09142"
"480.5000","9.6085","9.06637","0.09142"
"481.0000","9.6184","9.05319","0.09142"
"481.5000","9.6286","9.04372","0.09142"
"482.0000","9.6386","9.03445","0.09142"
"482.5000","9.6486","9.02526","0.09141"
"483.0000","9.6585","9.01152","0.09141"
"483.5000","9.6686","9.00181","0.09141"
"484.0000","9.6787","8.99180","0.09141"
"484.5000","9.6883","8.97692","0.09140"
"485.0000","9.6986","8.96736","0.09140"
"485.5000","9.7086","8.95461","0.09140"
"486.0000","9.7184","8.94110","0.09139"
"486.5000","9.7284","8.92745","0.09139"
"487.0000","9.7386","8.91586","0.09138"
"487.5000","9.7487","8.90549","0.09138"
"488.0000","9.7585","8.88900","0.09137"
"488.5000","9.7686","8.87601","0.09137"
"489.0000","9.7786","8.86378","0.09136"
"489.5000","9.7885","8.84622","0.09136"
"490.0000","9.7984","8.83013","0.09135"
"490.5000","9.8084","8.81621","0.09134"
"491.0000","9.8186","8.80321","0.09134"
"491.5000","9.8285","8.78408","0.09133"
"492.0000","9.8387","8.77112","0.09132"
"492.5000","9.8488","8.75757","0.09132"
"493.0000","9.8584","8.73806","0.09131"
"493.5000","9.8685","8.71966","0.09130"
"494.0000","9.8785","8.70136","0.09129"
"494.5000","9.8885","8.68517","0.09128"
"495.0000","9.8983","8.66494","0.09127"
"495.5000","9.9086","8.64857","0.09127"
"496.0000","9.9187","8.63121","0.09126"
"496.5000","9.9286","8.61033","0.09125"
"497.0000","9.9386","8.59110","0.09124"
"497.5000","9.9486","8.57183","0.09123"
"498.0000","9.9585","8.54931","0.09122"
"498.5000","9.9682","8.52358","0.09121"
"499.0000","9.9784","8.50335","0.09120"
"499.5000","9.9887","8.48364","0.09119"
"500.0000","9.9985","8.45815","0.09118"
"500.5000","10.0086","8.43453","0.09116"
"501.0000","10.0186","8.40876","0.09115"
"501.5000","10.0285","8.38462","0.09114"
"502.0000","10.0385","8.35423","0.09112"
"502.5000","10.0486","8.32626","0.09111"
"503.0000","10.0585","8.29721","0.09109"
"503.5000","10.0683","8.26271","0.09108"
"504.0000","10.0786","8.22921","0.09106"
"504.5000","10.0887","8.19477","0.09104"
"505.0000","10.0986","8.15694","0.09102"
"505.5000","10.1084","8.11050","0.09100"
"506.0000","10.1186","8.05990","0.09097"
"506.5000","10.1287","8.00685","0.09094"
"507.0000","10.1384","7.94564","0.09091"
"507.5000","10.1485","7.88351","0.09088"
"508.0000","10.1586","7.80621","0.09084"
"508.5000","10.1685","7.71262","0.09079"
"508.9550","10.1778","7.49488","0.09068"
"509.0030","10.1787","7.09155","0.09045"
"509.0170","10.1790","6.59560","0.09081"
"509.0220","10.1792","5.81445","0.09070"
"509.0240","10.1793","5.44231","0.09028"