File: Coupon Test Data/Tensile Test_Neebajan_Alan_7.csv
Time,Displacement,Force,Strain 1
(s),(mm),(kN),(mm/mm)
"0.0000","0.0000","0.19341","-0.00027"
"0.4000","0.0055","0.24614","-0.00025"
"0.8000","0.0138","0.33596","-0.00020"
"1.2000","0.0220","0.42292","-0.00015"
"1.6000","0.0300","0.50539","-0.00011"
"2.0000","0.0379","0.58494","-0.00007"
"2.4000","0.0460","0.66497","-0.00003"
"2.8000","0.0543","0.74603","0.00002"
"3.2000","0.0619","0.81856","0.00005"
"3.6000","0.0700","0.89363","0.00010"
"4.0000","0.0781","0.97088","0.00014"
"4.4000","0.0860","1.03706","0.00017"
"4.8000","0.0939","1.11048","0.00021"
"5.2000","0.1021","1.18649","0.00025"
"5.6000","0.1102","1.25496","0.00029"
"6.0000","0.1178","1.32191","0.00033"
"6.4000","0.1260","1.39408","0.00037"
"6.8000","0.1341","1.46019","0.00040"
"7.2000","0.1421","1.52934","0.00044"
"7.6000","0.1500","1.59556","0.00048"
"8.0000","0.1581","1.66069","0.00051"
"8.4000","0.1662","1.72836","0.00055"
"8.8000","0.1738","1.78541","0.00058"
"9.2000","0.1820","1.85260","0.00062"
"9.6000","0.1901","1.91379","0.00066"
"10.0000","0.1980","1.97570","0.00069"
"10.4000","0.2059","2.03348","0.00072"
"10.8000","0.2141","2.09750","0.00075"
"11.2000","0.2222","2.15583","0.00079"
"11.6000","0.2299","2.21274","0.00082"
"12.0000","0.2381","2.27091","0.00085"
"12.4000","0.2461","2.32940","0.00088"
"12.8000","0.2540","2.38340","0.00091"
"13.2000","0.2619","2.44038","0.00095"
"13.6000","0.2702","2.49671","0.00098"
"14.0000","0.2782","2.55338","0.00101"
"14.4000","0.2859","2.60293","0.00104"
"14.8000","0.2941","2.65744","0.00107"
"15.2000","0.3020","2.71150","0.00110"
"15.6000","0.3100","2.76229","0.00113"
"16.0000","0.3180","2.81407","0.00116"
"16.4000","0.3262","2.86711","0.00119"
"16.8000","0.3341","2.91652","0.00122"
"17.2000","0.3419","2.96410","0.00124"
"17.6000","0.3501","3.01567","0.00127"
"18.0000","0.3580","3.06344","0.00130"
"18.4000","0.3660","3.11133","0.00133"
"18.8000","0.3739","3.15849","0.00136"
"19.2000","0.3821","3.20731","0.00139"
"19.6000","0.3901","3.25490","0.00141"
"20.0000","0.3980","3.29903","0.00144"
"20.4000","0.4062","3.34683","0.00147"
"20.8000","0.4140","3.39138","0.00150"
"21.2000","0.4219","3.43536","0.00153"
"21.6000","0.4300","3.47997","0.00156"
"22.0000","0.4382","3.52519","0.00158"
"22.4000","0.4461","3.56755","0.00161"
"22.8000","0.4540","3.60876","0.00164"
"23.2000","0.4621","3.65225","0.00167"
"23.6000","0.4699","3.69252","0.00170"
"24.0000","0.4780","3.73415","0.00172"
"24.4000","0.4860","3.77527","0.00175"
"24.8000","0.4942","3.81736","0.00178"
"25.2000","0.5020","3.85769","0.00180"
"25.6000","0.5100","3.89721","0.00183"
"26.0000","0.5182","3.93957","0.00186"
"26.4000","0.5260","3.97895","0.00188"
"26.8000","0.5340","4.01941","0.00191"
"27.2000","0.5420","4.06025","0.00194"
"27.6000","0.5501","4.10184","0.00197"
"28.0000","0.5580","4.14243","0.00199"
"28.4000","0.5661","4.18313","0.00202"
"28.8000","0.5742","4.22473","0.00205"
"29.2000","0.5820","4.26309","0.00208"
"29.6000","0.5900","4.30329","0.00211"
"30.0000","0.5979","4.34247","0.00214"
"30.4000","0.6061","4.38248","0.00217"
"30.8000","0.6140","4.42115","0.00220"
"31.2000","0.6221","4.45970","0.00222"
"31.6000","0.6302","4.49979","0.00225"
"32.0000","0.6379","4.53584","0.00228"
"32.4000","0.6461","4.57481","0.00232"
"32.8000","0.6541","4.61370","0.00235"
"33.2000","0.6621","4.65241","0.00238"
"33.6000","0.6700","4.69008","0.00241"
"34.0000","0.6780","4.72793","0.00245"
"34.4000","0.6861","4.76640","0.00248"
"34.8000","0.6940","4.80150","0.00252"
"35.2000","0.7021","4.83783","0.00256"
"35.6000","0.7099","4.87190","0.00259"
"36.0000","0.7181","4.90752","0.00263"
"36.4000","0.7259","4.94030","0.00267"
"36.8000","0.7341","4.97294","0.00271"
"37.2000","0.7423","5.00601","0.00275"
"37.6000","0.7500","5.03353","0.00279"
"38.0000","0.7581","5.06285","0.00284"
"38.4000","0.7659","5.09004","0.00288"
"38.8000","0.7741","5.11692","0.00293"
"39.2000","0.7820","5.14268","0.00298"
"39.6000","0.7901","5.16613","0.00304"
"40.0000","0.7981","5.18902","0.00309"
"40.4000","0.8060","5.20992","0.00315"
"40.8000","0.8141","5.23040","0.00321"
"41.2000","0.8220","5.24760","0.00327"
"41.6000","0.8301","5.26612","0.00333"
"42.0000","0.8379","5.27367","0.00339"
"42.4000","0.8461","5.29403","0.00346"
"42.8000","0.8541","5.30991","0.00353"
"43.2000","0.8620","5.32005","0.00360"
"43.6000","0.8702","5.33286","0.00368"
"44.0000","0.8779","5.34240","0.00375"
"44.4000","0.8860","5.35301","0.00383"
"44.8000","0.8940","5.36267","0.00391"
"45.2000","0.9021","5.37062","0.00399"
"45.6000","0.9102","5.37991","0.00408"
"46.0000","0.9181","5.38690","0.00416"
"46.4000","0.9261","5.39376","0.00424"
"46.8000","0.9339","5.39909","0.00433"
"47.2000","0.9421","5.40708","0.00442"
"47.6000","0.9500","5.41167","0.00450"
"48.0000","0.9581","5.41743","0.00460"
"48.4000","0.9661","5.42432","0.00468"
"48.8000","0.9740","5.42800","0.00477"
"49.2000","0.9822","5.43377","0.00486"
"49.6000","0.9900","5.43617","0.00495"
"50.0000","0.9981","5.44192","0.00504"
"50.4000","1.0060","5.44537","0.00513"
"50.8000","1.0140","5.44882","0.00523"
"51.2000","1.0221","5.45510","0.00532"
"51.6000","1.0301","5.45790","0.00541"
"52.0000","1.0382","5.46108","0.00550"
"52.4000","1.0460","5.46284","0.00559"
"52.8000","1.0541","5.46809","0.00569"
"53.2000","1.0619","5.46989","0.00577"
"53.6000","1.0701","5.47321","0.00587"
"54.0000","1.0782","5.47798","0.00596"
"54.4000","1.0861","5.48002","0.00605"
"54.8000","1.0941","5.48281","0.00615"
"55.2000","1.1019","5.48418","0.00624"
"55.6000","1.1101","5.48932","0.00633"
"56.0000","1.1180","5.49039","0.00643"
"56.4000","1.1261","5.49256","0.00652"
"56.8000","1.1341","5.49693","0.00661"
"57.2000","1.1421","5.49925","0.00671"
"57.6000","1.1501","5.50177","0.00680"
"58.0000","1.1580","5.50206","0.00689"
"58.4000","1.1662","5.50684","0.00699"
"58.8000","1.1739","5.50712","0.00708"
"59.2000","1.1820","5.50939","0.00718"
"59.6000","1.1900","5.51390","0.00727"
"60.0000","1.1981","5.51541","0.00736"
"60.4000","1.2062","5.51757","0.00746"
"60.8000","1.2140","5.51854","0.00755"
"61.2000","1.2221","5.52235","0.00765"
"61.6000","1.2299","5.52284","0.00774"
"62.0000","1.2381","5.52551","0.00783"
"62.4000","1.2461","5.52836","0.00793"
"62.8000","1.2541","5.53027","0.00802"
"63.2000","1.2621","5.53202","0.00811"
"63.6000","1.2700","5.53302","0.00821"
"64.0000","1.2782","5.53754","0.00830"
"64.4000","1.2859","5.53634","0.00839"
"64.8000","1.2941","5.53923","0.00849"
"65.2000","1.3020","5.54235","0.00858"
"65.6000","1.3100","5.54329","0.00868"
"66.0000","1.3181","5.54648","0.00877"
"66.4000","1.3261","5.54734","0.00886"
"66.8000","1.3342","5.55061","0.00896"
"67.2000","1.3420","5.54982","0.00905"
"67.6000","1.3501","5.55256","0.00914"
"68.0000","1.3579","5.55507","0.00923"
"68.4000","1.3661","5.55695","0.00933"
"68.8000","1.3741","5.55894","0.00942"
"69.2000","1.3821","5.56020","0.00952"
"69.6000","1.3901","5.56328","0.00961"
"70.0000","1.3979","5.54354","0.00966"
"70.4000","1.4062","5.56437","0.00974"
"70.8000","1.4140","5.56961","0.00983"
"71.2000","1.4220","5.56980","0.00992"
"71.6000","1.4301","5.57190","0.01002"
"72.0000","1.4381","5.57304","0.01011"
"72.4000","1.4461","5.57535","0.01020"
"72.8000","1.4540","5.57444","0.01029"
"73.2000","1.4622","5.57743","0.01039"
"73.6000","1.4700","5.57880","0.01048"
"74.0000","1.4780","5.58000","0.01057"
"74.4000","1.4861","5.58297","0.01066"
"74.8000","1.4942","5.58457","0.01076"
"75.2000","1.5022","5.58668","0.01085"
"75.6000","1.5099","5.58545","0.01094"
"76.0000","1.5182","5.58918","0.01104"
"76.4000","1.5259","5.59053","0.01113"
"76.8000","1.5340","5.59167","0.01122"
"77.2000","1.5422","5.59460","0.01131"
"77.6000","1.5502","5.59657","0.01140"
"78.0000","1.5580","5.59738","0.01149"
"78.4000","1.5659","5.59757","0.01158"
"78.8000","1.5742","5.60164","0.01168"
"79.2000","1.5820","5.60176","0.01177"
"79.6000","1.5900","5.60298","0.01186"
"80.0000","1.5981","5.60578","0.01196"
"80.4000","1.6061","5.60777","0.01205"
"80.8000","1.6140","5.60954","0.01213"
"81.2000","1.6220","5.60912","0.01223"
"81.6000","1.6303","5.61336","0.01232"
"82.0000","1.6379","5.61263","0.01241"
"82.4000","1.6459","5.61378","0.01250"
"82.8000","1.6541","5.61780","0.01259"
"83.2000","1.6622","5.61969","0.01269"
"83.6000","1.6700","5.61994","0.01277"
"84.0000","1.6781","5.62077","0.01286"
"84.4000","1.6863","5.62460","0.01296"
"84.8000","1.6938","5.62331","0.01304"
"85.2000","1.7020","5.62578","0.01314"
"85.6000","1.7101","5.62858","0.01323"
"86.0000","1.7182","5.63044","0.01332"
"86.4000","1.7260","5.63101","0.01341"
"86.8000","1.7340","5.63193","0.01350"
"87.2000","1.7423","5.63666","0.01359"
"87.6000","1.7499","5.63454","0.01368"
"88.0000","1.7580","5.63581","0.01378"
"88.4000","1.7661","5.63968","0.01387"
"88.8000","1.7741","5.64072","0.01395"
"89.2000","1.7820","5.64204","0.01404"
"89.6000","1.7901","5.64340","0.01413"
"90.0000","1.7983","5.64707","0.01423"
"90.4000","1.8059","5.64515","0.01431"
"90.8000","1.8140","5.64738","0.01440"
"91.2000","1.8220","5.65053","0.01449"
"91.6000","1.8302","5.65262","0.01458"
"92.0000","1.8380","5.65265","0.01467"
"92.4000","1.8461","5.65417","0.01476"
"92.8000","1.8543","5.65828","0.01485"
"93.2000","1.8618","5.65564","0.01494"
"93.6000","1.8700","5.65863","0.01503"
"94.0000","1.8781","5.66144","0.01513"
"94.4000","1.8861","5.66214","0.01521"
"94.8000","1.8939","5.66321","0.01530"
"95.2000","1.9021","5.66549","0.01539"
"95.6000","1.9103","5.66910","0.01548"
"96.0000","1.9179","5.66657","0.01557"
"96.4000","1.9261","5.66931","0.01566"
"96.8000","1.9341","5.67174","0.01575"
"97.2000","1.9421","5.67269","0.01584"
"97.6000","1.9499","5.67395","0.01593"
"98.0000","1.9582","5.67630","0.01602"
"98.4000","1.9663","5.67963","0.01611"
"98.8000","1.9739","5.67673","0.01620"
"99.2000","1.9820","5.67988","0.01629"
"99.6000","1.9900","5.68263","0.01638"
"100.0000","1.9981","5.68333","0.01647"
"100.4000","2.0060","5.68414","0.01655"
"100.8000","2.0142","5.68718","0.01665"
"101.2000","2.0222","5.68935","0.01673"
"101.6000","2.0298","5.68742","0.01682"
"102.0000","2.0381","5.69108","0.01691"
"102.4000","2.0461","5.69253","0.01700"
"102.8000","2.0541","5.69284","0.01709"
"103.2000","2.0620","5.69370","0.01717"
"103.6000","2.0701","5.69673","0.01726"
"104.0000","2.0782","5.70024","0.01735"
"104.4000","2.0859","5.69783","0.01744"
"104.8000","2.0942","5.70121","0.01753"
"105.2000","2.1021","5.70279","0.01761"
"105.6000","2.1100","5.70320","0.01770"
"106.0000","2.1180","5.70519","0.01779"
"106.4000","2.1262","5.70827","0.01788"
"106.8000","2.1342","5.70949","0.01797"
"107.2000","2.1419","5.70846","0.01806"
"107.6000","2.1501","5.71189","0.01815"
"108.0000","2.1580","5.71247","0.01824"
"108.4000","2.1661","5.71421","0.01833"
"108.8000","2.1740","5.71501","0.01841"
"109.2000","2.1822","5.71775","0.01851"
"109.6000","2.1901","5.71960","0.01859"
"110.0000","2.1979","5.71812","0.01868"
"110.4000","2.2062","5.72258","0.01877"
"110.8000","2.2140","5.72286","0.01886"
"111.2000","2.2220","5.72337","0.01895"
"111.6000","2.2300","5.72534","0.01904"
"112.0000","2.2381","5.71045","0.01910"
"112.4000","2.2461","5.72614","0.01918"
"112.8000","2.2540","5.72953","0.01926"
"113.2000","2.2622","5.73345","0.01935"
"113.6000","2.2700","5.73298","0.01944"
"114.0000","2.2780","5.73405","0.01953"
"114.4000","2.2859","5.73537","0.01962"
"114.8000","2.2942","5.73800","0.01971"
"115.2000","2.3021","5.73915","0.01979"
"115.6000","2.3100","5.73889","0.01988"
"116.0000","2.3182","5.74224","0.01997"
"116.4000","2.3259","5.74166","0.02005"
"116.8000","2.3340","5.74346","0.02015"
"117.2000","2.3420","5.74493","0.02023"
"117.6000","2.3501","5.74697","0.02032"
"118.0000","2.3580","5.74770","0.02041"
"118.4000","2.3660","5.74819","0.02050"
"118.8000","2.3742","5.75151","0.02058"
"119.2000","2.3820","5.75056","0.02067"
"119.6000","2.3901","5.75275","0.02075"
"120.0000","2.3980","5.75386","0.02084"
"120.4000","2.4061","5.75626","0.02093"
"120.8000","2.4140","5.75801","0.02101"
"121.2000","2.4221","5.75879","0.02110"
"121.6000","2.4303","5.76178","0.02119"
"122.0000","2.4380","5.76053","0.02128"
"122.4000","2.4460","5.76218","0.02137"
"122.8000","2.4540","5.76391","0.02145"
"123.2000","2.4621","5.76637","0.02154"
"123.6000","2.4700","5.76683","0.02163"
"124.0000","2.4781","5.76815","0.02172"
"124.4000","2.4862","5.77100","0.02181"
"124.8000","2.4939","5.77004","0.02189"
"125.2000","2.5021","5.77284","0.02198"
"125.6000","2.5100","5.77327","0.02207"
"126.0000","2.5182","5.77544","0.02216"
"126.4000","2.5260","5.77617","0.02225"
"126.8000","2.5340","5.77726","0.02233"
"127.2000","2.5422","5.78106","0.02242"
"127.6000","2.5500","5.77995","0.02251"
"128.0000","2.5581","5.78158","0.02260"
"128.4000","2.5660","5.78241","0.02268"
"128.8000","2.5740","5.78441","0.02277"
"129.2000","2.5819","5.78526","0.02286"
"129.6000","2.5901","5.78745","0.02295"
"130.0000","2.5982","5.78989","0.02304"
"130.4000","2.6060","5.78897","0.02312"
"130.8000","2.6141","5.79135","0.02321"
"131.2000","2.6219","5.79127","0.02329"
"131.6000","2.6301","5.79426","0.02338"
"132.0000","2.6380","5.79457","0.02347"
"132.4000","2.6461","5.79583","0.02356"
"132.8000","2.6542","5.79913","0.02365"
"133.2000","2.6620","5.79855","0.02373"
"133.6000","2.6701","5.80064","0.02382"
"134.0000","2.6780","5.80092","0.02391"
"134.4000","2.6861","5.80294","0.02399"
"134.8000","2.6940","5.80323","0.02408"
"135.2000","2.7020","5.80433","0.02417"
"135.6000","2.7101","5.80714","0.02425"
"136.0000","2.7181","5.80770","0.02434"
"136.4000","2.7262","5.80954","0.02442"
"136.8000","2.7339","5.80919","0.02451"
"137.2000","2.7421","5.81252","0.02460"
"137.6000","2.7499","5.81259","0.02468"
"138.0000","2.7581","5.81432","0.02477"
"138.4000","2.7662","5.81727","0.02486"
"138.8000","2.7741","5.81720","0.02494"
"139.2000","2.7821","5.81837","0.02503"
"139.6000","2.7899","5.81838","0.02512"
"140.0000","2.7981","5.82161","0.02520"
"140.4000","2.8060","5.82152","0.02529"
"140.8000","2.8141","5.82298","0.02538"
"141.2000","2.8221","5.82524","0.02547"
"141.6000","2.8301","5.82608","0.02555"
"142.0000","2.8381","5.82801","0.02564"
"142.4000","2.8460","5.82710","0.02573"
"142.8000","2.8542","5.83029","0.02581"
"143.2000","2.8619","5.82974","0.02590"
"143.6000","2.8700","5.83120","0.02599"
"144.0000","2.8781","5.83455","0.02608"
"144.4000","2.8861","5.83492","0.02616"
"144.8000","2.8942","5.83643","0.02625"
"145.2000","2.9020","5.83581","0.02634"
"145.6000","2.9101","5.83868","0.02642"
"146.0000","2.9179","5.83885","0.02651"
"146.4000","2.9261","5.84055","0.02660"
"146.8000","2.9341","5.84250","0.02669"
"147.2000","2.9422","5.84399","0.02677"
"147.6000","2.9501","5.84432","0.02686"
"148.0000","2.9580","5.84442","0.02695"
"148.4000","2.9661","5.84813","0.02704"
"148.8000","2.9739","5.84676","0.02712"
"149.2000","2.9821","5.84865","0.02721"
"149.6000","2.9900","5.85085","0.02730"
"150.0000","2.9980","5.85146","0.02739"
"150.4000","3.0062","5.85393","0.02747"
"150.8000","3.0140","5.85325","0.02756"
"151.2000","3.0222","5.85590","0.02765"
"151.6000","3.0299","5.85527","0.02773"
"152.0000","3.0380","5.85667","0.02782"
"152.4000","3.0460","5.85939","0.02791"
"152.8000","3.0541","5.86053","0.02800"
"153.2000","3.0621","5.86121","0.02808"
"153.6000","3.0701","5.86208","0.02817"
"154.0000","3.0781","5.86414","0.02825"
"154.4000","3.0858","5.86167","0.02834"
"154.8000","3.0942","5.86560","0.02842"
"155.2000","3.1020","5.86683","0.02851"
"155.6000","3.1101","5.86747","0.02859"
"156.0000","3.1182","5.86995","0.02868"
"156.4000","3.1260","5.86992","0.02877"
"156.8000","3.1342","5.87308","0.02885"
"157.2000","3.1419","5.87176","0.02894"
"157.6000","3.1501","5.87366","0.02903"
"158.0000","3.1580","5.87561","0.02911"
"158.4000","3.1659","5.87573","0.02920"
"158.8000","3.1741","5.87778","0.02929"
"159.2000","3.1822","5.87914","0.02937"
"159.6000","3.1901","5.88042","0.02946"
"160.0000","3.1979","5.86815","0.02952"
"160.4000","3.2062","5.88032","0.02960"
"160.8000","3.2139","5.88330","0.02968"
"161.2000","3.2220","5.88473","0.02977"
"161.6000","3.2301","5.88685","0.02986"
"162.0000","3.2381","5.88731","0.02994"
"162.4000","3.2461","5.88869","0.03003"
"162.8000","3.2539","5.88730","0.03012"
"163.2000","3.2622","5.89040","0.03020"
"163.6000","3.2700","5.89107","0.03029"
"164.0000","3.2780","5.89113","0.03038"
"164.4000","3.2861","5.89300","0.03046"
"164.8000","3.2941","5.89458","0.03055"
"165.2000","3.3021","5.89586","0.03064"
"165.6000","3.3100","5.89457","0.03072"
"166.0000","3.3182","5.89792","0.03081"
"166.4000","3.3259","5.89762","0.03090"
"166.8000","3.3339","5.89815","0.03098"
"167.2000","3.3421","5.90139","0.03107"
"167.6000","3.3502","5.90265","0.03116"
"168.0000","3.3581","5.90297","0.03124"
"168.4000","3.3660","5.90247","0.03133"
"168.8000","3.3742","5.90529","0.03142"
"169.2000","3.3819","5.90456","0.03150"
"169.6000","3.3900","5.90619","0.03159"
"170.0000","3.3981","5.90822","0.03168"
"170.4000","3.4062","5.90988","0.03176"
"170.8000","3.4140","5.91008","0.03185"
"171.2000","3.4219","5.90976","0.03193"
"171.6000","3.4303","5.91397","0.03202"
"172.0000","3.4380","5.91236","0.03211"
"172.4000","3.4460","5.91276","0.03219"
"172.8000","3.4541","5.91587","0.03228"
"173.2000","3.4621","5.91694","0.03237"
"173.6000","3.4700","5.91742","0.03245"
"174.0000","3.4780","5.91770","0.03254"
"174.4000","3.4863","5.92102","0.03263"
"174.8000","3.4939","5.91901","0.03271"
"175.2000","3.5019","5.92030","0.03280"
"175.6000","3.5100","5.92245","0.03289"
"176.0000","3.5183","5.92389","0.03297"
"176.4000","3.5260","5.92334","0.03305"
"176.8000","3.5340","5.92411","0.03314"
"177.2000","3.5423","5.92844","0.03323"
"177.6000","3.5498","5.92603","0.03331"
"178.0000","3.5580","5.92794","0.03340"
"178.4000","3.5661","5.93081","0.03348"
"178.8000","3.5741","5.93132","0.03357"
"179.2000","3.5819","5.93115","0.03365"
"179.6000","3.5900","5.93252","0.03374"
"180.0000","3.5983","5.93608","0.03383"
"180.4000","3.6059","5.93296","0.03392"
"180.8000","3.6140","5.93501","0.03400"
"181.2000","3.6221","5.93709","0.03409"
"181.6000","3.6301","5.93793","0.03418"
"182.0000","3.6379","5.93846","0.03426"
"182.4000","3.6461","5.93984","0.03435"
"182.8000","3.6543","5.94311","0.03444"
"183.2000","3.6618","5.93937","0.03452"
"183.6000","3.6700","5.94177","0.03461"
"184.0000","3.6781","5.94450","0.03469"
"184.4000","3.6861","5.94485","0.03478"
"184.8000","3.6940","5.94495","0.03487"
"185.2000","3.7022","5.94677","0.03495"
"185.6000","3.7102","5.94898","0.03504"
"186.0000","3.7178","5.94631","0.03513"
"186.4000","3.7261","5.94935","0.03521"
"186.8000","3.7341","5.95100","0.03530"
"187.2000","3.7421","5.95135","0.03539"
"187.6000","3.7499","5.95143","0.03547"
"188.0000","3.7581","5.95341","0.03556"
"188.4000","3.7663","5.95671","0.03565"
"188.8000","3.7739","5.95314","0.03573"
"189.2000","3.7821","5.95563","0.03582"
"189.6000","3.7901","5.95757","0.03591"
"190.0000","3.7980","5.95739","0.03599"
"190.4000","3.8059","5.95814","0.03608"
"190.8000","3.8142","5.96084","0.03617"
"191.2000","3.8223","5.96240","0.03625"
"191.6000","3.8299","5.95952","0.03634"
"192.0000","3.8381","5.96267","0.03643"
"192.4000","3.8460","5.96348","0.03651"
"192.8000","3.8541","5.96446","0.03660"
"193.2000","3.8620","5.96461","0.03669"
"193.6000","3.8702","5.96674","0.03678"
"194.0000","3.8782","5.96869","0.03687"
"194.4000","3.8858","5.96576","0.03695"
"194.8000","3.8941","5.96930","0.03704"
"195.2000","3.9021","5.97038","0.03713"
"195.6000","3.9100","5.96999","0.03721"
"196.0000","3.9180","5.97079","0.03730"
"196.4000","3.9262","5.97345","0.03739"
"196.8000","3.9342","5.97469","0.03747"
"197.2000","3.9420","5.97270","0.03756"
"197.6000","3.9502","5.97583","0.03765"
"198.0000","3.9580","5.97534","0.03773"
"198.4000","3.9660","5.97604","0.03782"
"198.8000","3.9739","5.97696","0.03790"
"199.2000","3.9822","5.97970","0.03799"
"199.6000","3.9902","5.98078","0.03808"
"200.0000","3.9979","5.97864","0.03816"
"200.4000","4.0062","5.98215","0.03825"
"200.8000","4.0139","5.98157","0.03834"
"201.2000","4.0220","5.98246","0.03843"
"201.6000","4.0300","5.98284","0.03851"
"202.0000","4.0382","5.98368","0.03860"
"202.4000","4.0461","5.98460","0.03868"
"202.8000","4.0540","5.98493","0.03876"
"203.2000","4.0622","5.98849","0.03885"
"203.6000","4.0700","5.98744","0.03894"
"204.0000","4.0780","5.98839","0.03902"
"204.4000","4.0859","5.98887","0.03911"
"204.8000","4.0941","5.99102","0.03920"
"205.2000","4.1020","5.99235","0.03929"
"205.6000","4.1100","5.99149","0.03937"
"206.0000","4.1183","5.99475","0.03946"
"206.4000","4.1260","5.99304","0.03955"
"206.8000","4.1340","5.99366","0.03963"
"207.2000","4.1420","5.99509","0.03972"
"207.6000","4.1502","5.99711","0.03981"
"208.0000","4.1580","5.99707","0.03990"
"208.4000","4.1661","5.99717","0.03998"
"208.8000","4.1742","5.99955","0.04007"
"209.2000","4.1819","5.99833","0.04015"
"209.6000","4.1901","6.00023","0.04024"
"210.0000","4.1980","6.00057","0.04033"
"210.4000","4.2061","6.00203","0.04042"
"210.8000","4.2140","6.00240","0.04050"
"211.2000","4.2220","6.00276","0.04059"
"211.6000","4.2302","6.00588","0.04068"
"212.0000","4.2380","6.00420","0.04076"
"212.4000","4.2461","6.00525","0.04085"
"212.8000","4.2540","6.00564","0.04094"
"213.2000","4.2621","6.00733","0.04102"
"213.6000","4.2699","6.00764","0.04111"
"214.0000","4.2782","6.00907","0.04120"
"214.4000","4.2862","6.01082","0.04128"
"214.8000","4.2940","6.00923","0.04137"
"215.2000","4.3021","6.01108","0.04146"
"215.6000","4.3099","6.01081","0.04154"
"216.0000","4.3181","6.01311","0.04163"
"216.4000","4.3260","6.01305","0.04172"
"216.8000","4.3341","6.01368","0.04180"
"217.2000","4.3422","6.01628","0.04189"
"217.6000","4.3499","6.01454","0.04198"
"218.0000","4.3581","6.01640","0.04207"
"218.4000","4.3661","6.01672","0.04215"
"218.8000","4.3741","6.01772","0.04224"
"219.2000","4.3820","6.01742","0.04233"
"219.6000","4.3901","6.01898","0.04241"
"220.0000","4.3982","6.02132","0.04250"
"220.4000","4.4060","6.02031","0.04259"
"220.8000","4.4141","6.02168","0.04268"
"221.2000","4.4219","6.02092","0.04276"
"221.6000","4.4301","6.02316","0.04285"
"222.0000","4.4379","6.02299","0.04293"
"222.4000","4.4461","6.02421","0.04302"
"222.8000","4.4542","6.02650","0.04311"
"223.2000","4.4620","6.02507","0.04320"
"223.6000","4.4701","6.02638","0.04328"
"224.0000","4.4779","6.02595","0.04337"
"224.4000","4.4861","6.02825","0.04346"
"224.8000","4.4940","6.02806","0.04355"
"225.2000","4.5021","6.02876","0.04363"
"225.6000","4.5101","6.03056","0.04372"
"226.0000","4.5180","6.03042","0.04381"
"226.4000","4.5261","6.03203","0.04390"
"226.8000","4.5340","6.03074","0.04398"
"227.2000","4.5421","6.03296","0.04407"
"227.6000","4.5499","6.03234","0.04415"
"228.0000","4.5580","6.03300","0.04424"
"228.4000","4.5661","6.03586","0.04433"
"228.8000","4.5741","6.03549","0.04442"
"229.2000","4.5822","6.03624","0.04451"
"229.6000","4.5899","6.03523","0.04459"
"230.0000","4.5981","6.03753","0.04468"
"230.4000","4.6059","6.03706","0.04476"
"230.8000","4.6141","6.03861","0.04485"
"231.2000","4.6222","6.03991","0.04494"
"231.6000","4.6301","6.04009","0.04503"
"232.0000","4.6381","6.04079","0.04512"
"232.4000","4.6459","6.03922","0.04520"
"232.8000","4.6541","6.04277","0.04529"
"233.2000","4.6620","6.04159","0.04538"
"233.6000","4.6701","6.04207","0.04547"
"234.0000","4.6781","6.04435","0.04555"
"234.4000","4.6861","6.04426","0.04564"
"234.8000","4.6941","6.04551","0.04573"
"235.2000","4.7020","6.04451","0.04581"
"235.6000","4.7102","6.04671","0.04590"
"236.0000","4.7180","6.04560","0.04599"
"236.4000","4.7260","6.04651","0.04607"
"236.8000","4.7340","6.04820","0.04616"
"237.2000","4.7422","6.04927","0.04625"
"237.6000","4.7502","6.04782","0.04633"
"238.0000","4.7580","6.04640","0.04641"
"238.4000","4.7661","6.05058","0.04650"
"238.8000","4.7739","6.04952","0.04659"
"239.2000","4.7821","6.05146","0.04667"
"239.6000","4.7901","6.05296","0.04676"
"240.0000","4.7981","6.05313","0.04685"
"240.4000","4.8061","6.05385","0.04694"
"240.8000","4.8140","6.05292","0.04702"
"241.2000","4.8222","6.05571","0.04711"
"241.6000","4.8300","6.05401","0.04720"
"242.0000","4.8381","6.05524","0.04729"
"242.4000","4.8460","6.05608","0.04737"
"242.8000","4.8540","6.05682","0.04746"
"243.2000","4.8621","6.05806","0.04755"
"243.6000","4.8701","6.05698","0.04764"
"244.0000","4.8782","6.05944","0.04772"
"244.4000","4.8859","6.05580","0.04781"
"244.8000","4.8941","6.04858","0.04787"
"245.2000","4.9020","6.05828","0.04795"
"245.6000","4.9101","6.06111","0.04804"
"246.0000","4.9181","6.06268","0.04812"
"246.4000","4.9261","6.06253","0.04821"
"246.8000","4.9341","6.06396","0.04830"
"247.2000","4.9419","6.06207","0.04838"
"247.6000","4.9501","6.06399","0.04847"
"248.0000","4.9580","6.06431","0.04856"
"248.4000","4.9661","6.06458","0.04865"
"248.8000","4.9741","6.06509","0.04873"
"249.2000","4.9820","6.06515","0.04882"
"249.6000","4.9901","6.06746","0.04891"
"250.0000","4.9979","6.06481","0.04899"
"250.4000","5.0061","6.06672","0.04908"
"250.8000","5.0140","6.06713","0.04918"
"251.2000","5.0219","6.06674","0.04926"
"251.6000","5.0301","6.06901","0.04935"
"252.0000","5.0382","6.06937","0.04944"
"252.4000","5.0461","6.06984","0.04952"
"252.8000","5.0539","6.06816","0.04961"
"253.2000","5.0621","6.07037","0.04970"
"253.6000","5.0699","6.06995","0.04979"
"254.0000","5.0780","6.07079","0.04987"
"254.4000","5.0861","6.07197","0.04996"
"254.8000","5.0942","6.07274","0.05005"
"255.2000","5.1021","6.07308","0.05014"
"255.6000","5.1098","6.07126","0.05022"
"256.0000","5.1183","6.07487","0.05032"
"256.4000","5.1260","6.07368","0.05040"
"256.8000","5.1340","6.07290","0.05049"
"257.2000","5.1421","6.07556","0.05058"
"257.6000","5.1501","6.07596","0.05067"
"258.0000","5.1581","6.07633","0.05076"
"258.4000","5.1660","6.07510","0.05084"
"258.8000","5.1742","6.07746","0.05093"
"259.2000","5.1820","6.07629","0.05102"
"259.6000","5.1899","6.07656","0.05111"
"260.0000","5.1980","6.07809","0.05120"
"260.4000","5.2063","6.08035","0.05129"
"260.8000","5.2140","6.07923","0.05137"
"261.2000","5.2220","6.07790","0.05146"
"261.6000","5.2303","6.08128","0.05155"
"262.0000","5.2378","6.07903","0.05164"
"262.4000","5.2460","6.07972","0.05172"
"262.8000","5.2541","6.08165","0.05181"
"263.2000","5.2622","6.08208","0.05190"
"263.6000","5.2700","6.08195","0.05199"
"264.0000","5.2779","6.08146","0.05207"
"264.4000","5.2863","6.08432","0.05217"
"264.8000","5.2940","6.08250","0.05225"
"265.2000","5.3020","6.08239","0.05234"
"265.6000","5.3101","6.08387","0.05243"
"266.0000","5.3182","6.08526","0.05252"
"266.4000","5.3259","6.08453","0.05260"
"266.8000","5.3341","6.08458","0.05269"
"267.2000","5.3423","6.08770","0.05278"
"267.6000","5.3498","6.08390","0.05287"
"268.0000","5.3580","6.08562","0.05296"
"268.4000","5.3661","6.08746","0.05304"
"268.8000","5.3741","6.08769","0.05314"
"269.2000","5.3821","6.08757","0.05322"
"269.6000","5.3901","6.08739","0.05331"
"270.0000","5.3983","6.08988","0.05340"
"270.4000","5.4058","6.08706","0.05349"
"270.8000","5.4140","6.08841","0.05357"
"271.2000","5.4221","6.09010","0.05367"
"271.6000","5.4301","6.09044","0.05375"
"272.0000","5.4379","6.08947","0.05384"
"272.4000","5.4461","6.09075","0.05393"
"272.8000","5.4543","6.09359","0.05402"
"273.2000","5.4619","6.08938","0.05410"
"273.6000","5.4701","6.09119","0.05419"
"274.0000","5.4781","6.09248","0.05428"
"274.4000","5.4860","6.09205","0.05437"
"274.8000","5.4939","6.09245","0.05446"
"275.2000","5.5022","6.09365","0.05455"
"275.6000","5.5103","6.09578","0.05464"
"276.0000","5.5179","6.09169","0.05472"
"276.4000","5.5260","6.09372","0.05482"
"276.8000","5.5341","6.09497","0.05491"
"277.2000","5.5421","6.09535","0.05499"
"277.6000","5.5500","6.09442","0.05508"
"278.0000","5.5582","6.09591","0.05517"
"278.4000","5.5662","6.09747","0.05526"
"278.8000","5.5738","6.09379","0.05535"
"279.2000","5.5821","6.09660","0.05544"
"279.6000","5.5901","6.09762","0.05553"
"280.0000","5.5981","6.09668","0.05561"
"280.4000","5.6059","6.09659","0.05570"
"280.8000","5.6141","6.09862","0.05579"
"281.2000","5.6223","6.10000","0.05588"
"281.6000","5.6299","6.09651","0.05597"
"282.0000","5.6381","6.09865","0.05606"
"282.4000","5.6461","6.09889","0.05615"
"282.8000","5.6540","6.09861","0.05623"
"283.2000","5.6619","6.09873","0.05632"
"283.6000","5.6702","6.10089","0.05642"
"284.0000","5.6782","6.10175","0.05650"
"284.4000","5.6859","6.09817","0.05659"
"284.8000","5.6941","6.10088","0.05668"
"285.2000","5.7020","6.10090","0.05677"
"285.6000","5.7100","6.10089","0.05686"
"286.0000","5.7180","6.10108","0.05695"
"286.4000","5.7262","6.10254","0.05704"
"286.8000","5.7341","6.10283","0.05712"
"287.2000","5.7419","6.10057","0.05721"
"287.6000","5.7502","6.10331","0.05730"
"288.0000","5.7580","6.10257","0.05739"
"288.4000","5.7660","6.10231","0.05748"
"288.8000","5.7739","6.10234","0.05757"
"289.2000","5.7821","6.10421","0.05766"
"289.6000","5.7901","6.10508","0.05775"
"290.0000","5.7980","6.10255","0.05784"
"290.4000","5.8062","6.10515","0.05793"
"290.8000","5.8140","6.10398","0.05802"
"291.2000","5.8220","6.10369","0.05810"
"291.6000","5.8299","6.10421","0.05819"
"292.0000","5.8382","6.10633","0.05828"
"292.4000","5.8461","6.10608","0.05837"
"292.8000","5.8540","6.10446","0.05846"
"293.2000","5.8622","6.10700","0.05855"
"293.6000","5.8699","6.10523","0.05864"
"294.0000","5.8781","6.10599","0.05873"
"294.4000","5.8860","6.10575","0.05882"
"294.8000","5.8942","6.10746","0.05891"
"295.2000","5.9021","6.10717","0.05900"
"295.6000","5.9100","6.10590","0.05909"
"296.0000","5.9182","6.10904","0.05918"
"296.4000","5.9260","6.10717","0.05927"
"296.8000","5.9341","6.10708","0.05936"
"297.2000","5.9420","6.10747","0.05945"
"297.6000","5.9501","6.10837","0.05953"
"298.0000","5.9580","6.10857","0.05962"
"298.4000","5.9661","6.10842","0.05971"
"298.8000","5.9743","6.11004","0.05981"
"299.2000","5.9820","6.10760","0.05989"
"299.6000","5.9900","6.10867","0.05998"
"300.0000","5.9979","6.10848","0.06007"
"300.4000","6.0062","6.11013","0.06016"
"300.8000","6.0140","6.10948","0.06025"
"301.2000","6.0221","6.10924","0.06034"
"301.6000","6.0302","6.11122","0.06043"
"302.0000","6.0379","6.10918","0.06052"
"302.4000","6.0461","6.11029","0.06061"
"302.8000","6.0541","6.11020","0.06070"
"303.2000","6.0621","6.11093","0.06080"
"303.6000","6.0700","6.11009","0.06088"
"304.0000","6.0781","6.11064","0.06097"
"304.4000","6.0862","6.11268","0.06106"
"304.8000","6.0940","6.11042","0.06115"
"305.2000","6.1021","6.11143","0.06125"
"305.6000","6.1100","6.11064","0.06133"
"306.0000","6.1181","6.11162","0.06143"
"306.4000","6.1260","6.11152","0.06152"
"306.8000","6.1341","6.11186","0.06161"
"307.2000","6.1423","6.11344","0.06170"
"307.6000","6.1500","6.11131","0.06179"
"308.0000","6.1581","6.11192","0.06188"
"308.4000","6.1659","6.11152","0.06197"
"308.8000","6.1741","6.11301","0.06206"
"309.2000","6.1820","6.11213","0.06215"
"309.6000","6.1901","6.11261","0.06224"
"310.0000","6.1981","6.11392","0.06233"
"310.4000","6.2060","6.11220","0.06243"
"310.8000","6.2142","6.11377","0.06252"
"311.2000","6.2220","6.11193","0.06261"
"311.6000","6.2301","6.11344","0.06270"
"312.0000","6.2380","6.11269","0.06279"
"312.4000","6.2461","6.11266","0.06289"
"312.8000","6.2542","6.11509","0.06298"
"313.2000","6.2620","6.11316","0.06307"
"313.6000","6.2702","6.11373","0.06316"
"314.0000","6.2780","6.11241","0.06325"
"314.4000","6.2860","6.11343","0.06334"
"314.8000","6.2939","6.11299","0.06343"
"315.2000","6.3021","6.11414","0.06353"
"315.6000","6.3102","6.11493","0.06362"
"316.0000","6.3181","6.11360","0.06371"
"316.4000","6.3261","6.11426","0.06380"
"316.8000","6.3339","6.11234","0.06389"
"317.2000","6.3421","6.11490","0.06398"
"317.6000","6.3500","6.11328","0.06408"
"318.0000","6.3581","6.11341","0.06417"
"318.4000","6.3661","6.11529","0.06426"
"318.8000","6.3740","6.11392","0.06436"
"319.2000","6.3821","6.11482","0.06445"
"319.6000","6.3900","6.11310","0.06454"
"320.0000","6.3981","6.11444","0.06464"
"320.4000","6.4060","6.11312","0.06473"
"320.8000","6.4140","6.11330","0.06482"
"321.2000","6.4221","6.11498","0.06491"
"321.6000","6.4301","6.11490","0.06501"
"322.0000","6.4382","6.11481","0.06510"
"322.4000","6.4459","6.11247","0.06519"
"322.8000","6.4541","6.11459","0.06529"
"323.2000","6.4619","6.11301","0.06538"
"323.6000","6.4701","6.11379","0.06548"
"324.0000","6.4782","6.11483","0.06557"
"324.4000","6.4861","6.11399","0.06567"
"324.8000","6.4941","6.11408","0.06576"
"325.2000","6.5019","6.11239","0.06586"
"325.6000","6.5101","6.11466","0.06595"
"326.0000","6.5180","6.11276","0.06605"
"326.4000","6.5261","6.11319","0.06614"
"326.8000","6.5341","6.11384","0.06623"
"327.2000","6.5421","6.11373","0.06633"
"327.6000","6.5501","6.11415","0.06643"
"328.0000","6.5580","6.11206","0.06652"
"328.4000","6.5662","6.11424","0.06662"
"328.8000","6.5739","6.11158","0.06671"
"329.2000","6.5820","6.11210","0.06681"
"329.6000","6.5900","6.11361","0.06691"
"330.0000","6.5981","6.11321","0.06700"
"330.4000","6.6061","6.11291","0.06710"
"330.8000","6.6140","6.11170","0.06720"
"331.2000","6.6221","6.11307","0.06730"
"331.6000","6.6299","6.11101","0.06739"
"332.0000","6.6381","6.11201","0.06749"
"332.4000","6.6461","6.11219","0.06759"
"332.8000","6.6541","6.11195","0.06769"
"333.2000","6.6621","6.11148","0.06779"
"333.6000","6.6700","6.11050","0.06789"
"334.0000","6.6782","6.11267","0.06799"
"334.4000","6.6859","6.10932","0.06809"
"334.8000","6.6941","6.11026","0.06819"
"335.2000","6.7020","6.11055","0.06829"
"335.6000","6.7100","6.10974","0.06839"
"336.0000","6.7181","6.11110","0.06849"
"336.4000","6.7261","6.10973","0.06860"
"336.8000","6.7342","6.11040","0.06870"
"337.2000","6.7419","6.10778","0.06880"
"337.6000","6.7501","6.10852","0.06891"
"338.0000","6.7579","6.10830","0.06900"
"338.4000","6.7661","6.10861","0.06911"
"338.8000","6.7741","6.10868","0.06922"
"339.2000","6.7821","6.10768","0.06932"
"339.6000","6.7901","6.10842","0.06943"
"340.0000","6.7978","6.10541","0.06953"
"340.4000","6.8062","6.10727","0.06964"
"340.8000","6.8141","6.10637","0.06975"
"341.2000","6.8220","6.10512","0.06985"
"341.6000","6.8301","6.10600","0.06996"
"342.0000","6.8381","6.10552","0.07007"
"342.4000","6.8461","6.10577","0.07018"
"342.8000","6.8540","6.10298","0.07029"
"343.2000","6.8622","6.10418","0.07040"
"343.6000","6.8699","6.10240","0.07051"
"344.0000","6.8780","6.10208","0.07062"
"344.4000","6.8861","6.10286","0.07073"
"344.8000","6.8942","6.10254","0.07084"
"345.2000","6.9021","6.10202","0.07096"
"345.6000","6.9099","6.09893","0.07107"
"346.0000","6.9182","6.10051","0.07119"
"346.4000","6.9259","6.09894","0.07130"
"346.8000","6.9340","6.09791","0.07142"
"347.2000","6.9422","6.09871","0.07153"
"347.6000","6.9502","6.09817","0.07165"
"348.0000","6.9580","6.09657","0.07177"
"348.4000","6.9659","6.09465","0.07188"
"348.8000","6.9742","6.09646","0.07201"
"349.2000","6.9820","6.09357","0.07213"
"349.6000","6.9900","6.09246","0.07225"
"350.0000","6.9981","6.09272","0.07237"
"350.4000","7.0061","6.09232","0.07249"
"350.8000","7.0140","6.09158","0.07261"
"351.2000","7.0220","6.08846","0.07274"
"351.6000","7.0303","6.09033","0.07287"
"352.0000","7.0379","6.08639","0.07299"
"352.4000","7.0459","6.08536","0.07311"
"352.8000","7.0541","6.08657","0.07324"
"353.2000","7.0622","6.08552","0.07337"
"353.6000","7.0701","6.08308","0.07350"
"354.0000","7.0780","6.08092","0.07363"
"354.4000","7.0862","6.08208","0.07376"
"354.8000","7.0938","6.07775","0.07389"
"355.2000","7.1020","6.07740","0.07403"
"355.6000","7.1101","6.07716","0.07416"
"356.0000","7.1182","6.07595","0.07430"
"356.4000","7.1260","6.07332","0.07443"
"356.8000","7.1340","6.07091","0.07457"
"357.2000","7.1423","6.07302","0.07470"
"357.6000","7.1499","6.06713","0.07484"
"358.0000","7.1580","6.06544","0.07498"
"358.4000","7.1661","6.06567","0.07512"
"358.8000","7.1741","6.06357","0.07526"
"359.2000","7.1820","6.06121","0.07540"
"359.6000","7.1901","6.05896","0.07554"
"360.0000","7.1983","6.05911","0.07569"
"360.4000","7.2059","6.05318","0.07583"
"360.8000","7.2140","6.05212","0.07597"
"361.2000","7.2221","6.05134","0.07612"
"361.6000","7.2302","6.04904","0.07626"
"362.0000","7.2380","6.04545","0.07641"
"362.4000","7.2461","6.04285","0.07656"
"362.8000","7.2543","6.04309","0.07670"
"363.2000","7.2618","6.03618","0.07685"
"363.6000","7.2700","6.03489","0.07700"
"364.0000","7.2781","6.03358","0.07715"
"364.4000","7.2861","6.02978","0.07730"
"364.8000","7.2939","6.02632","0.07745"
"365.2000","7.3021","6.02428","0.07760"
"365.6000","7.3103","6.02328","0.07775"
"366.0000","7.3179","6.01563","0.07790"
"366.4000","7.3261","6.01377","0.07806"
"366.8000","7.3341","6.01147","0.07821"
"367.2000","7.3421","6.00773","0.07836"
"367.6000","7.3499","6.00393","0.07851"
"368.0000","7.3582","6.00096","0.07868"
"368.4000","7.3663","5.99938","0.07883"
"368.8000","7.3738","5.99045","0.07898"
"369.2000","7.3821","5.98889","0.07914"
"369.6000","7.3900","5.98609","0.07930"
"370.0000","7.3980","5.98056","0.07946"
"370.4000","7.4060","5.97669","0.07961"
"370.8000","7.4142","5.97344","0.07977"
"371.2000","7.4222","5.96964","0.07993"
"371.6000","7.4299","5.96215","0.08009"
"372.0000","7.4381","5.95977","0.08025"
"372.4000","7.4461","5.95466","0.08041"
"372.8000","7.4541","5.94947","0.08057"
"373.2000","7.4619","5.94407","0.08073"
"373.6000","7.4702","5.94073","0.08090"
"374.0000","7.4782","5.93722","0.08106"
"374.4000","7.4859","5.92741","0.08122"
"374.8000","7.4942","5.92455","0.08139"
"375.2000","7.5021","5.91923","0.08155"
"375.6000","7.5100","5.91227","0.08172"
"376.0000","7.5180","5.90794","0.08188"
"376.4000","7.5262","5.90327","0.08205"
"376.8000","7.5342","5.89755","0.08221"
"377.2000","7.5419","5.88879","0.08237"
"377.6000","7.5501","5.88497","0.08254"
"378.0000","7.5580","5.87812","0.08271"
"378.4000","7.5660","5.87155","0.08287"
"378.8000","7.5740","5.86452","0.08304"
"379.2000","7.5823","5.85996","0.08321"
"379.6000","7.5901","5.85384","0.08337"
"380.0000","7.5979","5.84363","0.08354"
"380.4000","7.6063","5.84047","0.08371"
"380.8000","7.6140","5.83176","0.08387"
"381.2000","7.6220","5.82341","0.08404"
"381.6000","7.6300","5.81761","0.08421"
"382.0000","7.6381","5.81070","0.08438"
"382.4000","7.6461","5.80433","0.08455"
"382.8000","7.6540","5.79410","0.08472"
"383.2000","7.6622","5.78821","0.08489"
"383.6000","7.6700","5.77965","0.08506"
"384.0000","7.6780","5.77102","0.08522"
"384.4000","7.6859","5.76319","0.08539"
"384.8000","7.6942","5.75674","0.08557"
"385.2000","7.7021","5.74816","0.08574"
"385.6000","7.7100","5.73752","0.08591"
"386.0000","7.7182","5.73211","0.08608"
"386.4000","7.7259","5.72112","0.08625"
"386.8000","7.7341","5.71232","0.08643"
"387.2000","7.7420","5.70359","0.08659"
"387.6000","7.7502","5.69489","0.08677"
"388.0000","7.7581","5.68616","0.08694"
"388.4000","7.7660","5.67538","0.08711"
"388.8000","7.7742","5.66841","0.08729"
"389.2000","7.7820","5.65621","0.08746"
"389.6000","7.7900","5.64629","0.08764"
"390.0000","7.7980","5.63674","0.08781"
"390.4000","7.8061","5.62710","0.08798"
"390.8000","7.8140","5.61746","0.08815"
"391.2000","7.8221","5.60559","0.08833"
"391.6000","7.8303","5.59698","0.08851"
"392.0000","7.8380","5.58415","0.08868"
"392.4000","7.8460","5.57337","0.08886"
"392.8000","7.8539","5.56269","0.08903"
"393.2000","7.8621","5.55197","0.08921"
"393.6000","7.8700","5.53998","0.08939"
"394.0000","7.8781","5.52780","0.08956"
"394.4000","7.8862","5.51782","0.08974"
"394.8000","7.8940","5.50369","0.08992"
"395.2000","7.9021","5.49207","0.09009"
"395.6000","7.9100","5.47912","0.09027"
"396.0000","7.9182","5.46714","0.09045"
"396.4000","7.9260","5.45447","0.09063"
"396.8000","7.9341","5.44020","0.09081"
"397.2000","7.9422","5.42987","0.09099"
"397.6000","7.9500","5.41365","0.09117"
"398.0000","7.9581","5.39988","0.09134"
"398.4000","7.9660","5.38606","0.09152"
"398.8000","7.9740","5.37213","0.09170"
"399.2000","7.9820","5.35796","0.09188"
"399.6000","7.9902","5.34267","0.09207"
"400.0000","7.9982","5.32917","0.09225"
"400.4000","8.0061","5.31254","0.09243"
"400.8000","8.0141","5.29745","0.09261"
"401.2000","8.0219","5.28091","0.09279"
"401.6000","8.0301","5.26601","0.09298"
"402.0000","8.0380","5.24966","0.09316"
"402.4000","8.0461","5.23200","0.09335"
"402.8000","8.0542","5.21757","0.09354"
"403.2000","8.0620","5.19837","0.09372"
"403.6000","8.0701","5.18044","0.09391"
"404.0000","8.0780","5.16103","0.09410"
"404.4000","8.0861","5.14228","0.09429"
"404.8000","8.0940","5.12190","0.09447"
"405.2000","8.1021","5.09973","0.09467"
"405.6000","8.1101","5.08013","0.09486"
"406.0000","8.1181","5.05251","0.09506"
"406.4000","8.1262","5.02864","0.09526"
"406.8000","8.1340","5.00305","0.09546"
"407.2000","8.1421","4.97860","0.09566"
"407.6000","8.1499","4.95040","0.09586"
"408.0000","8.1581","4.91076","0.09608"
"408.4000","8.1662","4.86449","0.09631"
"408.8000","8.1741","4.78687","0.09660"
"409.2000","8.1822","4.67005","0.09694"
"409.6000","8.1900","4.55001","0.09728"
"409.9940","8.1981","4.33303","0.09779"
"410.2620","8.2034","4.04527","0.09834"
"410.3850","8.2059","3.74017","0.09888"
"410.4130","8.2065","3.66789","0.09900"