File: Coupon Test Data/Tensile Test_Neebajan_Alan_16.csv
Time,Displacement,Force,Strain 1
(s),(mm),(kN),(mm/mm)
"0.0000","0.0000","0.18298","-0.00017"
"0.4000","0.0064","0.24504","-0.00013"
"0.8000","0.0145","0.32844","-0.00008"
"1.2000","0.0225","0.40949","-0.00003"
"1.6000","0.0306","0.49019","0.00002"
"2.0000","0.0385","0.56742","0.00006"
"2.4000","0.0466","0.64041","0.00011"
"2.8000","0.0545","0.71064","0.00015"
"3.2000","0.0625","0.78355","0.00020"
"3.6000","0.0706","0.85621","0.00024"
"4.0000","0.0786","0.92489","0.00028"
"4.4000","0.0867","0.99586","0.00032"
"4.8000","0.0945","1.06507","0.00036"
"5.2000","0.1026","1.13162","0.00040"
"5.6000","0.1105","1.20008","0.00045"
"6.0000","0.1186","1.26515","0.00048"
"6.4000","0.1267","1.33319","0.00053"
"6.8000","0.1347","1.39596","0.00056"
"7.2000","0.1427","1.46073","0.00060"
"7.6000","0.1505","1.52040","0.00064"
"8.0000","0.1586","1.58188","0.00067"
"8.4000","0.1665","1.64414","0.00071"
"8.8000","0.1746","1.70271","0.00075"
"9.2000","0.1826","1.76383","0.00079"
"9.6000","0.1906","1.82151","0.00082"
"10.0000","0.1987","1.87871","0.00086"
"10.4000","0.2066","1.93460","0.00089"
"10.8000","0.2147","1.99346","0.00093"
"11.2000","0.2225","2.04669","0.00096"
"11.6000","0.2306","2.10076","0.00099"
"12.0000","0.2385","2.15537","0.00102"
"12.4000","0.2467","2.21129","0.00106"
"12.8000","0.2547","2.26375","0.00109"
"13.2000","0.2626","2.31491","0.00112"
"13.6000","0.2706","2.36775","0.00116"
"14.0000","0.2784","2.41722","0.00119"
"14.4000","0.2866","2.46976","0.00122"
"14.8000","0.2946","2.52061","0.00125"
"15.2000","0.3026","2.57084","0.00128"
"15.6000","0.3106","2.62085","0.00131"
"16.0000","0.3185","2.66966","0.00134"
"16.4000","0.3267","2.71976","0.00138"
"16.8000","0.3345","2.76651","0.00140"
"17.2000","0.3426","2.81467","0.00143"
"17.6000","0.3505","2.86126","0.00146"
"18.0000","0.3586","2.90806","0.00149"
"18.4000","0.3667","2.95460","0.00152"
"18.8000","0.3747","2.99936","0.00155"
"19.2000","0.3827","3.04542","0.00158"
"19.6000","0.3905","3.08828","0.00161"
"20.0000","0.3986","3.13391","0.00163"
"20.4000","0.4065","3.17770","0.00166"
"20.8000","0.4146","3.22240","0.00169"
"21.2000","0.4227","3.26572","0.00172"
"21.6000","0.4307","3.30771","0.00175"
"22.0000","0.4386","3.34999","0.00177"
"22.4000","0.4464","3.39070","0.00180"
"22.8000","0.4547","3.43421","0.00183"
"23.2000","0.4626","3.47599","0.00185"
"23.6000","0.4706","3.51819","0.00188"
"24.0000","0.4786","3.55991","0.00191"
"24.4000","0.4866","3.60130","0.00193"
"24.8000","0.4946","3.64263","0.00196"
"25.2000","0.5025","3.68222","0.00199"
"25.6000","0.5107","3.72448","0.00202"
"26.0000","0.5185","3.76517","0.00204"
"26.4000","0.5265","3.80637","0.00207"
"26.8000","0.5346","3.84736","0.00210"
"27.2000","0.5428","3.88810","0.00212"
"27.6000","0.5507","3.93141","0.00215"
"28.0000","0.5585","3.96714","0.00217"
"28.4000","0.5667","4.01057","0.00221"
"28.8000","0.5744","4.04792","0.00223"
"29.2000","0.5825","4.08265","0.00225"
"29.6000","0.5907","4.12603","0.00228"
"30.0000","0.5987","4.16096","0.00231"
"30.4000","0.6066","4.20292","0.00234"
"30.8000","0.6145","4.23313","0.00236"
"31.2000","0.6228","4.27942","0.00239"
"31.6000","0.6305","4.31437","0.00241"
"32.0000","0.6385","4.35466","0.00244"
"32.4000","0.6467","4.38760","0.00246"
"32.8000","0.6547","4.43055","0.00249"
"33.2000","0.6625","4.46566","0.00252"
"33.6000","0.6706","4.50674","0.00255"
"34.0000","0.6788","4.54881","0.00258"
"34.4000","0.6865","4.57977","0.00260"
"34.8000","0.6945","4.62270","0.00263"
"35.2000","0.7026","4.65677","0.00266"
"35.6000","0.7108","4.70086","0.00269"
"36.0000","0.7186","4.73191","0.00272"
"36.4000","0.7266","4.77193","0.00274"
"36.8000","0.7348","4.81491","0.00278"
"37.2000","0.7424","4.84206","0.00280"
"37.6000","0.7505","4.88505","0.00283"
"38.0000","0.7587","4.92479","0.00287"
"38.4000","0.7667","4.95638","0.00289"
"38.8000","0.7745","4.99517","0.00292"
"39.2000","0.7825","5.03108","0.00296"
"39.6000","0.7908","5.06253","0.00298"
"40.0000","0.7985","5.09829","0.00302"
"40.4000","0.8066","5.13313","0.00305"
"40.8000","0.8147","5.15712","0.00308"
"41.2000","0.8227","5.19526","0.00312"
"41.6000","0.8305","5.22851","0.00316"
"42.0000","0.8386","5.25846","0.00320"
"42.4000","0.8469","5.28998","0.00324"
"42.8000","0.8544","5.30353","0.00327"
"43.2000","0.8625","5.33597","0.00332"
"43.6000","0.8706","5.36416","0.00337"
"44.0000","0.8787","5.38777","0.00341"
"44.4000","0.8865","5.40796","0.00346"
"44.8000","0.8947","5.42812","0.00352"
"45.2000","0.9028","5.44831","0.00357"
"45.6000","0.9103","5.46152","0.00363"
"46.0000","0.9186","5.47770","0.00369"
"46.4000","0.9267","5.49255","0.00375"
"46.8000","0.9347","5.50473","0.00382"
"47.2000","0.9425","5.51558","0.00388"
"47.6000","0.9507","5.52606","0.00395"
"48.0000","0.9589","5.53029","0.00401"
"48.4000","0.9664","5.53740","0.00405"
"48.8000","0.9746","5.54940","0.00412"
"49.2000","0.9827","5.55755","0.00419"
"49.6000","0.9906","5.56253","0.00426"
"50.0000","0.9985","5.56980","0.00433"
"50.4000","1.0068","5.57669","0.00441"
"50.8000","1.0148","5.58346","0.00448"
"51.2000","1.0224","5.58511","0.00455"
"51.6000","1.0306","5.59130","0.00462"
"52.0000","1.0386","5.59663","0.00470"
"52.4000","1.0467","5.60076","0.00477"
"52.8000","1.0546","5.60390","0.00484"
"53.2000","1.0628","5.60841","0.00492"
"53.6000","1.0708","5.61328","0.00499"
"54.0000","1.0784","5.61098","0.00505"
"54.4000","1.0867","5.61825","0.00513"
"54.8000","1.0947","5.62176","0.00520"
"55.2000","1.1026","5.62345","0.00527"
"55.6000","1.1105","5.62644","0.00535"
"56.0000","1.1187","5.63036","0.00542"
"56.4000","1.1267","5.63370","0.00550"
"56.8000","1.1345","5.63311","0.00557"
"57.2000","1.1427","5.63719","0.00564"
"57.6000","1.1506","5.63937","0.00572"
"58.0000","1.1586","5.64092","0.00580"
"58.4000","1.1665","5.64337","0.00587"
"58.8000","1.1748","5.64660","0.00595"
"59.2000","1.1827","5.64927","0.00602"
"59.6000","1.1904","5.64832","0.00610"
"60.0000","1.1987","5.65230","0.00618"
"60.4000","1.2065","5.65395","0.00625"
"60.8000","1.2146","5.65517","0.00633"
"61.2000","1.2226","5.65702","0.00641"
"61.6000","1.2308","5.65997","0.00648"
"62.0000","1.2387","5.66177","0.00656"
"62.4000","1.2465","5.66145","0.00664"
"62.8000","1.2547","5.66552","0.00672"
"63.2000","1.2626","5.66557","0.00680"
"63.6000","1.2706","5.66708","0.00688"
"64.0000","1.2785","5.66843","0.00695"
"64.4000","1.2867","5.67115","0.00704"
"64.8000","1.2947","5.67373","0.00712"
"65.2000","1.3026","5.67247","0.00719"
"65.6000","1.3108","5.67624","0.00728"
"66.0000","1.3185","5.67624","0.00736"
"66.4000","1.3265","5.67714","0.00744"
"66.8000","1.3345","5.67967","0.00752"
"67.2000","1.3427","5.68185","0.00760"
"67.6000","1.3506","5.68272","0.00768"
"68.0000","1.3586","5.68319","0.00777"
"68.4000","1.3667","5.68520","0.00785"
"68.8000","1.3745","5.68020","0.00791"
"69.2000","1.3826","5.68807","0.00799"
"69.6000","1.3905","5.68912","0.00807"
"70.0000","1.3988","5.69164","0.00815"
"70.4000","1.4066","5.69224","0.00824"
"70.8000","1.4146","5.69225","0.00832"
"71.2000","1.4228","5.69621","0.00841"
"71.6000","1.4305","5.69476","0.00849"
"72.0000","1.4386","5.69606","0.00858"
"72.4000","1.4465","5.69745","0.00866"
"72.8000","1.4546","5.69926","0.00875"
"73.2000","1.4626","5.70098","0.00883"
"73.6000","1.4706","5.70140","0.00892"
"74.0000","1.4788","5.70370","0.00901"
"74.4000","1.4866","5.69360","0.00908"
"74.8000","1.4946","5.70337","0.00916"
"75.2000","1.5025","5.70601","0.00924"
"75.6000","1.5107","5.70900","0.00933"
"76.0000","1.5185","5.70887","0.00942"
"76.4000","1.5267","5.70971","0.00951"
"76.8000","1.5347","5.71263","0.00959"
"77.2000","1.5424","5.71133","0.00968"
"77.6000","1.5507","5.71358","0.00977"
"78.0000","1.5586","5.71428","0.00986"
"78.4000","1.5667","5.71567","0.00995"
"78.8000","1.5746","5.71702","0.01003"
"79.2000","1.5826","5.71765","0.01012"
"79.6000","1.5907","5.72044","0.01021"
"80.0000","1.5986","5.72035","0.01030"
"80.4000","1.6066","5.72151","0.01039"
"80.8000","1.6145","5.72170","0.01048"
"81.2000","1.6226","5.72424","0.01057"
"81.6000","1.6305","5.72474","0.01066"
"82.0000","1.6387","5.72620","0.01076"
"82.4000","1.6468","5.72862","0.01084"
"82.8000","1.6546","5.72764","0.01093"
"83.2000","1.6627","5.72969","0.01103"
"83.6000","1.6705","5.72984","0.01111"
"84.0000","1.6787","5.73218","0.01120"
"84.4000","1.6865","5.73262","0.01129"
"84.8000","1.6947","5.73369","0.01138"
"85.2000","1.7027","5.73623","0.01148"
"85.6000","1.7105","5.73576","0.01156"
"86.0000","1.7187","5.73800","0.01166"
"86.4000","1.7266","5.73787","0.01175"
"86.8000","1.7347","5.73989","0.01184"
"87.2000","1.7425","5.74012","0.01193"
"87.6000","1.7506","5.74125","0.01202"
"88.0000","1.7587","5.74447","0.01211"
"88.4000","1.7666","5.74417","0.01220"
"88.8000","1.7747","5.74550","0.01230"
"89.2000","1.7825","5.74519","0.01238"
"89.6000","1.7906","5.74771","0.01248"
"90.0000","1.7985","5.74819","0.01257"
"90.4000","1.8067","5.74952","0.01266"
"90.8000","1.8147","5.75175","0.01275"
"91.2000","1.8227","5.75205","0.01284"
"91.6000","1.8307","5.75333","0.01293"
"92.0000","1.8384","5.75269","0.01302"
"92.4000","1.8467","5.75631","0.01312"
"92.8000","1.8545","5.75580","0.01320"
"93.2000","1.8626","5.75659","0.01330"
"93.6000","1.8707","5.75959","0.01339"
"94.0000","1.8786","5.75964","0.01348"
"94.4000","1.8867","5.76146","0.01357"
"94.8000","1.8946","5.76095","0.01366"
"95.2000","1.9027","5.76314","0.01375"
"95.6000","1.9105","5.76334","0.01385"
"96.0000","1.9186","5.76447","0.01394"
"96.4000","1.9266","5.76700","0.01403"
"96.8000","1.9347","5.76830","0.01412"
"97.2000","1.9427","5.76871","0.01421"
"97.6000","1.9505","5.76817","0.01430"
"98.0000","1.9587","5.77145","0.01440"
"98.4000","1.9664","5.77045","0.01448"
"98.8000","1.9746","5.77234","0.01458"
"99.2000","1.9827","5.77482","0.01467"
"99.6000","1.9907","5.77521","0.01476"
"100.0000","1.9987","5.77618","0.01485"
"100.4000","2.0065","5.77598","0.01494"
"100.8000","2.0147","5.77932","0.01503"
"101.2000","2.0225","5.77847","0.01512"
"101.6000","2.0306","5.77987","0.01521"
"102.0000","2.0386","5.78187","0.01530"
"102.4000","2.0466","5.78296","0.01539"
"102.8000","2.0547","5.78444","0.01548"
"103.2000","2.0626","5.78377","0.01557"
"103.6000","2.0708","5.78684","0.01566"
"104.0000","2.0785","5.78538","0.01575"
"104.4000","2.0866","5.78709","0.01584"
"104.8000","2.0945","5.78949","0.01593"
"105.2000","2.1026","5.79045","0.01602"
"105.6000","2.1107","5.79159","0.01611"
"106.0000","2.1186","5.79168","0.01620"
"106.4000","2.1267","5.79396","0.01629"
"106.8000","2.1344","5.79316","0.01638"
"107.2000","2.1427","5.79529","0.01647"
"107.6000","2.1506","5.79682","0.01656"
"108.0000","2.1586","5.79759","0.01665"
"108.4000","2.1667","5.79894","0.01674"
"108.8000","2.1746","5.79902","0.01683"
"109.2000","2.1827","5.80213","0.01692"
"109.6000","2.1905","5.80050","0.01701"
"110.0000","2.1987","5.80244","0.01710"
"110.4000","2.2065","5.80398","0.01719"
"110.8000","2.2145","5.80433","0.01728"
"111.2000","2.2227","5.80687","0.01737"
"111.6000","2.2307","5.80747","0.01746"
"112.0000","2.2387","5.80887","0.01755"
"112.4000","2.2465","5.80782","0.01763"
"112.8000","2.2547","5.81014","0.01773"
"113.2000","2.2625","5.81112","0.01781"
"113.6000","2.2706","5.81223","0.01790"
"114.0000","2.2787","5.81381","0.01799"
"114.4000","2.2867","5.80893","0.01806"
"114.8000","2.2946","5.81555","0.01815"
"115.2000","2.3024","5.81537","0.01823"
"115.6000","2.3107","5.81856","0.01833"
"116.0000","2.3186","5.81916","0.01841"
"116.4000","2.3265","5.81910","0.01850"
"116.8000","2.3347","5.82137","0.01859"
"117.2000","2.3427","5.82236","0.01868"
"117.6000","2.3506","5.82366","0.01877"
"118.0000","2.3585","5.82275","0.01885"
"118.4000","2.3668","5.82536","0.01894"
"118.8000","2.3745","5.82506","0.01903"
"119.2000","2.3825","5.82611","0.01912"
"119.6000","2.3906","5.82850","0.01921"
"120.0000","2.3988","5.82995","0.01930"
"120.4000","2.4066","5.83049","0.01938"
"120.8000","2.4145","5.82959","0.01947"
"121.2000","2.4228","5.83290","0.01956"
"121.6000","2.4304","5.83236","0.01965"
"122.0000","2.4385","5.83322","0.01973"
"122.4000","2.4467","5.83589","0.01982"
"122.8000","2.4547","5.83706","0.01991"
"123.2000","2.4625","5.83699","0.02000"
"123.6000","2.4705","5.83712","0.02009"
"124.0000","2.4788","5.84049","0.02017"
"124.4000","2.4865","5.83975","0.02026"
"124.8000","2.4946","5.84027","0.02035"
"125.2000","2.5027","5.82570","0.02042"
"125.6000","2.5107","5.84046","0.02050"
"126.0000","2.5185","5.84450","0.02058"
"126.4000","2.5266","5.84486","0.02067"
"126.8000","2.5348","5.84865","0.02076"
"127.2000","2.5424","5.84647","0.02084"
"127.6000","2.5505","5.84760","0.02093"
"128.0000","2.5586","5.85030","0.02102"
"128.4000","2.5667","5.85142","0.02111"
"128.8000","2.5746","5.85127","0.02119"
"129.2000","2.5826","5.85189","0.02128"
"129.6000","2.5908","5.85490","0.02137"
"130.0000","2.5984","5.85283","0.02145"
"130.4000","2.6065","5.85470","0.02154"
"130.8000","2.6147","5.85700","0.02163"
"131.2000","2.6227","5.85796","0.02172"
"131.6000","2.6305","5.85788","0.02180"
"132.0000","2.6386","5.85877","0.02189"
"132.4000","2.6469","5.86269","0.02198"
"132.8000","2.6544","5.85964","0.02206"
"133.2000","2.6626","5.86110","0.02215"
"133.6000","2.6707","5.86379","0.02223"
"134.0000","2.6786","5.86423","0.02232"
"134.4000","2.6865","5.86489","0.02241"
"134.8000","2.6947","5.86652","0.02249"
"135.2000","2.7029","5.86918","0.02258"
"135.6000","2.7104","5.86628","0.02267"
"136.0000","2.7185","5.86840","0.02276"
"136.4000","2.7266","5.87067","0.02284"
"136.8000","2.7347","5.87202","0.02293"
"137.2000","2.7426","5.87168","0.02301"
"137.6000","2.7507","5.87312","0.02310"
"138.0000","2.7589","5.87615","0.02319"
"138.4000","2.7663","5.87299","0.02327"
"138.8000","2.7746","5.87570","0.02336"
"139.2000","2.7827","5.87786","0.02345"
"139.6000","2.7906","5.87777","0.02354"
"140.0000","2.7985","5.87838","0.02362"
"140.4000","2.8067","5.88053","0.02371"
"140.8000","2.8148","5.88284","0.02380"
"141.2000","2.8225","5.88045","0.02388"
"141.6000","2.8307","5.88257","0.02397"
"142.0000","2.8386","5.88398","0.02405"
"142.4000","2.8466","5.88460","0.02414"
"142.8000","2.8545","5.88527","0.02422"
"143.2000","2.8628","5.88753","0.02431"
"143.6000","2.8708","5.88966","0.02440"
"144.0000","2.8784","5.88659","0.02448"
"144.4000","2.8866","5.88976","0.02457"
"144.8000","2.8946","5.89111","0.02465"
"145.2000","2.9026","5.89143","0.02474"
"145.6000","2.9106","5.89211","0.02483"
"146.0000","2.9188","5.89450","0.02492"
"146.4000","2.9267","5.89565","0.02500"
"146.8000","2.9344","5.89378","0.02509"
"147.2000","2.9427","5.89693","0.02517"
"147.6000","2.9506","5.89757","0.02526"
"148.0000","2.9586","5.89784","0.02535"
"148.4000","2.9665","5.89828","0.02543"
"148.8000","2.9747","5.90073","0.02552"
"149.2000","2.9827","5.90275","0.02560"
"149.6000","2.9905","5.90051","0.02569"
"150.0000","2.9987","5.90338","0.02577"
"150.4000","3.0066","5.90384","0.02586"
"150.8000","3.0145","5.90382","0.02594"
"151.2000","3.0225","5.90513","0.02603"
"151.6000","3.0308","5.90813","0.02612"
"152.0000","3.0387","5.90880","0.02620"
"152.4000","3.0465","5.90737","0.02629"
"152.8000","3.0547","5.91020","0.02638"
"153.2000","3.0625","5.90982","0.02646"
"153.6000","3.0706","5.91113","0.02655"
"154.0000","3.0786","5.91183","0.02663"
"154.4000","3.0867","5.91379","0.02672"
"154.8000","3.0947","5.91481","0.02680"
"155.2000","3.1025","5.91370","0.02689"
"155.6000","3.1108","5.91728","0.02697"
"156.0000","3.1186","5.91659","0.02706"
"156.4000","3.1266","5.91714","0.02714"
"156.8000","3.1346","5.91821","0.02723"
"157.2000","3.1427","5.92009","0.02731"
"157.6000","3.1506","5.92090","0.02740"
"158.0000","3.1586","5.92102","0.02748"
"158.4000","3.1668","5.92365","0.02757"
"158.8000","3.1745","5.92217","0.02765"
"159.2000","3.1826","5.91116","0.02773"
"159.6000","3.1905","5.91982","0.02780"
"160.0000","3.1987","5.92604","0.02789"
"160.4000","3.2066","5.92741","0.02797"
"160.8000","3.2146","5.92763","0.02805"
"161.2000","3.2227","5.93028","0.02814"
"161.6000","3.2305","5.92914","0.02822"
"162.0000","3.2386","5.93042","0.02831"
"162.4000","3.2466","5.93121","0.02840"
"162.8000","3.2547","5.93264","0.02848"
"163.2000","3.2625","5.93267","0.02857"
"163.6000","3.2706","5.93375","0.02865"
"164.0000","3.2787","5.93630","0.02874"
"164.4000","3.2865","5.93474","0.02882"
"164.8000","3.2946","5.93635","0.02891"
"165.2000","3.3025","5.93654","0.02899"
"165.6000","3.3106","5.93832","0.02907"
"166.0000","3.3185","5.93912","0.02916"
"166.4000","3.3267","5.93996","0.02925"
"166.8000","3.3349","5.94248","0.02933"
"167.2000","3.3425","5.94058","0.02941"
"167.6000","3.3506","5.94188","0.02950"
"168.0000","3.3585","5.94284","0.02958"
"168.4000","3.3667","5.94460","0.02967"
"168.8000","3.3745","5.94452","0.02975"
"169.2000","3.3827","5.94582","0.02984"
"169.6000","3.3907","5.94768","0.02992"
"170.0000","3.3985","5.94682","0.03000"
"170.4000","3.4067","5.94873","0.03009"
"170.8000","3.4146","5.94859","0.03017"
"171.2000","3.4227","5.95050","0.03026"
"171.6000","3.4305","5.95031","0.03034"
"172.0000","3.4386","5.95125","0.03042"
"172.4000","3.4467","5.95429","0.03051"
"172.8000","3.4546","5.95301","0.03059"
"173.2000","3.4627","5.95445","0.03068"
"173.6000","3.4705","5.95423","0.03076"
"174.0000","3.4786","5.95597","0.03085"
"174.4000","3.4865","5.95604","0.03093"
"174.8000","3.4947","5.95789","0.03102"
"175.2000","3.5027","5.95948","0.03110"
"175.6000","3.5106","5.95894","0.03118"
"176.0000","3.5187","5.96033","0.03127"
"176.4000","3.5265","5.95959","0.03135"
"176.8000","3.5347","5.96222","0.03144"
"177.2000","3.5425","5.96201","0.03152"
"177.6000","3.5506","5.96283","0.03161"
"178.0000","3.5587","5.96517","0.03169"
"178.4000","3.5665","5.96459","0.03177"
"178.8000","3.5747","5.96657","0.03186"
"179.2000","3.5826","5.96596","0.03194"
"179.6000","3.5907","5.96733","0.03202"
"180.0000","3.5985","5.96755","0.03211"
"180.4000","3.6066","5.96848","0.03219"
"180.8000","3.6147","5.97070","0.03228"
"181.2000","3.6227","5.97123","0.03236"
"181.6000","3.6307","5.97188","0.03245"
"182.0000","3.6385","5.97079","0.03253"
"182.4000","3.6466","5.97363","0.03261"
"182.8000","3.6544","5.97283","0.03270"
"183.2000","3.6627","5.97448","0.03278"
"183.6000","3.6707","5.97637","0.03286"
"184.0000","3.6786","5.97617","0.03295"
"184.4000","3.6867","5.97744","0.03303"
"184.8000","3.6944","5.97634","0.03311"
"185.2000","3.7026","5.97904","0.03320"
"185.6000","3.7106","5.97911","0.03328"
"186.0000","3.7186","5.97947","0.03337"
"186.4000","3.7266","5.98115","0.03345"
"186.8000","3.7346","5.98207","0.03353"
"187.2000","3.7427","5.98297","0.03362"
"187.6000","3.7506","5.98234","0.03370"
"188.0000","3.7587","5.98468","0.03378"
"188.4000","3.7665","5.98329","0.03387"
"188.8000","3.7747","5.98518","0.03395"
"189.2000","3.7826","5.98667","0.03404"
"189.6000","3.7907","5.98717","0.03412"
"190.0000","3.7988","5.98859","0.03420"
"190.4000","3.8065","5.98732","0.03428"
"190.8000","3.8147","5.98960","0.03437"
"191.2000","3.8224","5.98902","0.03445"
"191.6000","3.8306","5.99030","0.03453"
"192.0000","3.8387","5.99220","0.03462"
"192.4000","3.8466","5.99233","0.03470"
"192.8000","3.8546","5.99290","0.03478"
"193.2000","3.8626","5.99302","0.03487"
"193.6000","3.8707","5.99549","0.03495"
"194.0000","3.8785","5.99371","0.03503"
"194.4000","3.8867","5.99586","0.03512"
"194.8000","3.8945","5.99646","0.03520"
"195.2000","3.9025","5.99688","0.03528"
"195.6000","3.9107","5.99907","0.03537"
"196.0000","3.9186","5.98974","0.03542"
"196.4000","3.9267","5.99865","0.03550"
"196.8000","3.9345","5.99916","0.03558"
"197.2000","3.9426","6.00119","0.03567"
"197.6000","3.9505","6.00252","0.03575"
"198.0000","3.9586","6.00305","0.03583"
"198.4000","3.9667","6.00378","0.03591"
"198.8000","3.9746","6.00392","0.03600"
"199.2000","3.9827","6.00569","0.03608"
"199.6000","3.9904","6.00383","0.03616"
"200.0000","3.9987","6.00619","0.03624"
"200.4000","4.0066","6.00697","0.03633"
"200.8000","4.0146","6.00707","0.03641"
"201.2000","4.0227","6.00822","0.03649"
"201.6000","4.0306","6.00842","0.03658"
"202.0000","4.0387","6.01048","0.03666"
"202.4000","4.0465","6.00910","0.03674"
"202.8000","4.0547","6.01062","0.03682"
"203.2000","4.0625","6.01076","0.03690"
"203.6000","4.0705","6.01129","0.03699"
"204.0000","4.0786","6.01323","0.03707"
"204.4000","4.0867","6.01375","0.03715"
"204.8000","4.0947","6.01491","0.03724"
"205.2000","4.1025","6.01288","0.03732"
"205.6000","4.1107","6.01568","0.03740"
"206.0000","4.1185","6.01560","0.03748"
"206.4000","4.1266","6.01596","0.03756"
"206.8000","4.1347","6.01800","0.03765"
"207.2000","4.1427","6.01859","0.03773"
"207.6000","4.1506","6.01876","0.03781"
"208.0000","4.1584","6.01800","0.03789"
"208.4000","4.1667","6.02087","0.03798"
"208.8000","4.1746","6.02038","0.03806"
"209.2000","4.1826","6.02037","0.03814"
"209.6000","4.1906","6.02183","0.03822"
"210.0000","4.1987","6.02322","0.03831"
"210.4000","4.2066","6.02372","0.03838"
"210.8000","4.2145","6.02237","0.03847"
"211.2000","4.2228","6.02539","0.03855"
"211.6000","4.2304","6.02430","0.03863"
"212.0000","4.2385","6.02457","0.03871"
"212.4000","4.2466","6.02724","0.03879"
"212.8000","4.2548","6.02830","0.03888"
"213.2000","4.2626","6.02780","0.03896"
"213.6000","4.2706","6.02723","0.03904"
"214.0000","4.2788","6.03007","0.03912"
"214.4000","4.2864","6.02814","0.03920"
"214.8000","4.2945","6.02966","0.03929"
"215.2000","4.3027","6.03132","0.03937"
"215.6000","4.3107","6.03219","0.03945"
"216.0000","4.3185","6.03189","0.03953"
"216.4000","4.3265","6.03163","0.03961"
"216.8000","4.3348","6.03522","0.03970"
"217.2000","4.3425","6.03281","0.03978"
"217.6000","4.3505","6.03341","0.03986"
"218.0000","4.3587","6.03565","0.03994"
"218.4000","4.3667","6.03607","0.04002"
"218.8000","4.3745","6.03597","0.04010"
"219.2000","4.3826","6.03650","0.04019"
"219.6000","4.3908","6.03904","0.04027"
"220.0000","4.3984","6.03636","0.04035"
"220.4000","4.4065","6.03776","0.04043"
"220.8000","4.4146","6.03976","0.04051"
"221.2000","4.4228","6.04100","0.04059"
"221.6000","4.4306","6.04032","0.04067"
"222.0000","4.4386","6.04042","0.04076"
"222.4000","4.4469","6.04355","0.04084"
"222.8000","4.4543","6.04035","0.04092"
"223.2000","4.4625","6.04206","0.04100"
"223.6000","4.4707","6.04425","0.04108"
"224.0000","4.4787","6.04419","0.04116"
"224.4000","4.4865","6.04380","0.04124"
"224.8000","4.4946","6.04513","0.04132"
"225.2000","4.5028","6.04781","0.04141"
"225.6000","4.5104","6.04081","0.04148"
"226.0000","4.5186","6.03946","0.04155"
"226.4000","4.5267","6.04614","0.04162"
"226.8000","4.5346","6.04817","0.04170"
"227.2000","4.5425","6.04874","0.04178"
"227.6000","4.5507","6.05016","0.04187"
"228.0000","4.5589","6.05238","0.04195"
"228.4000","4.5664","6.04865","0.04202"
"228.8000","4.5746","6.05050","0.04211"
"229.2000","4.5826","6.05238","0.04218"
"229.6000","4.5906","6.05235","0.04227"
"230.0000","4.5985","6.05191","0.04235"
"230.4000","4.6068","6.05399","0.04243"
"230.8000","4.6148","6.05513","0.04251"
"231.2000","4.6224","6.05197","0.04259"
"231.6000","4.6306","6.05476","0.04267"
"232.0000","4.6387","6.05578","0.04275"
"232.4000","4.6467","6.05581","0.04283"
"232.8000","4.6545","6.05531","0.04291"
"233.2000","4.6627","6.05714","0.04299"
"233.6000","4.6708","6.05952","0.04307"
"234.0000","4.6785","6.05589","0.04315"
"234.4000","4.6867","6.05810","0.04323"
"234.8000","4.6946","6.05911","0.04331"
"235.2000","4.7026","6.05855","0.04339"
"235.6000","4.7105","6.05902","0.04347"
"236.0000","4.7188","6.06157","0.04355"
"236.4000","4.7268","6.06213","0.04363"
"236.8000","4.7345","6.05987","0.04371"
"237.2000","4.7427","6.06212","0.04379"
"237.6000","4.7505","6.06197","0.04387"
"238.0000","4.7586","6.06287","0.04395"
"238.4000","4.7665","6.06263","0.04403"
"238.8000","4.7748","6.06454","0.04411"
"239.2000","4.7827","6.06528","0.04419"
"239.6000","4.7904","6.06283","0.04427"
"240.0000","4.7987","6.06624","0.04435"
"240.4000","4.8066","6.06586","0.04443"
"240.8000","4.8146","6.06543","0.04451"
"241.2000","4.8225","6.06617","0.04459"
"241.6000","4.8307","6.06776","0.04467"
"242.0000","4.8387","6.06865","0.04475"
"242.4000","4.8465","6.06705","0.04483"
"242.8000","4.8548","6.06947","0.04491"
"243.2000","4.8626","6.06859","0.04499"
"243.6000","4.8706","6.06884","0.04507"
"244.0000","4.8785","6.06922","0.04514"
"244.4000","4.8867","6.07122","0.04522"
"244.8000","4.8947","6.07176","0.04530"
"245.2000","4.9025","6.07022","0.04538"
"245.6000","4.9107","6.07271","0.04546"
"246.0000","4.9185","6.07177","0.04554"
"246.4000","4.9266","6.07250","0.04562"
"246.8000","4.9346","6.07281","0.04570"
"247.2000","4.9427","6.07426","0.04578"
"247.6000","4.9506","6.07418","0.04585"
"248.0000","4.9585","6.07378","0.04593"
"248.4000","4.9667","6.07642","0.04601"
"248.8000","4.9745","6.07485","0.04609"
"249.2000","4.9826","6.07565","0.04617"
"249.6000","4.9905","6.07566","0.04624"
"250.0000","4.9986","6.07696","0.04633"
"250.4000","5.0066","6.07769","0.04640"
"250.8000","5.0146","6.07743","0.04648"
"251.2000","5.0228","6.07965","0.04656"
"251.6000","5.0305","6.07760","0.04664"
"252.0000","5.0386","6.07832","0.04672"
"252.4000","5.0465","6.07899","0.04679"
"252.8000","5.0547","6.08051","0.04687"
"253.2000","5.0626","6.07994","0.04695"
"253.6000","5.0707","6.08040","0.04703"
"254.0000","5.0787","6.08201","0.04711"
"254.4000","5.0865","6.08044","0.04718"
"254.8000","5.0946","6.08196","0.04726"
"255.2000","5.1026","6.08172","0.04734"
"255.6000","5.1107","6.08303","0.04742"
"256.0000","5.1185","6.08283","0.04750"
"256.4000","5.1266","6.08297","0.04757"
"256.8000","5.1348","6.08569","0.04765"
"257.2000","5.1425","6.08368","0.04773"
"257.6000","5.1506","6.08443","0.04780"
"258.0000","5.1585","6.08443","0.04788"
"258.4000","5.1666","6.08538","0.04796"
"258.8000","5.1745","6.08556","0.04804"
"259.2000","5.1827","6.08663","0.04811"
"259.6000","5.1908","6.08774","0.04819"
"260.0000","5.1986","6.08642","0.04827"
"260.4000","5.2066","6.08743","0.04835"
"260.8000","5.2145","6.08664","0.04842"
"261.2000","5.2227","6.08875","0.04850"
"261.6000","5.2305","6.08829","0.04858"
"262.0000","5.2387","6.08869","0.04865"
"262.4000","5.2467","6.09048","0.04873"
"262.8000","5.2545","6.08887","0.04880"
"263.2000","5.2627","6.09028","0.04888"
"263.6000","5.2706","6.08989","0.04896"
"264.0000","5.2787","6.09085","0.04903"
"264.4000","5.2865","6.09032","0.04911"
"264.8000","5.2946","6.09128","0.04919"
"265.2000","5.3027","6.09287","0.04926"
"265.6000","5.3106","6.09208","0.04934"
"266.0000","5.3187","6.09296","0.04941"
"266.4000","5.3265","6.09164","0.04949"
"266.8000","5.3346","6.09346","0.04957"
"267.2000","5.3425","6.09300","0.04964"
"267.6000","5.3507","6.09394","0.04972"
"268.0000","5.3588","6.09571","0.04979"
"268.4000","5.3666","6.09399","0.04987"
"268.8000","5.3747","6.09484","0.04994"
"269.2000","5.3825","6.09404","0.05002"
"269.6000","5.3907","6.09603","0.05009"
"270.0000","5.3985","6.09529","0.05016"
"270.4000","5.4067","6.09580","0.05024"
"270.8000","5.4147","6.09710","0.05032"
"271.2000","5.4226","6.09691","0.05039"
"271.6000","5.4307","6.09798","0.05047"
"272.0000","5.4385","6.09627","0.05054"
"272.4000","5.4467","6.09842","0.05061"
"272.8000","5.4545","6.09734","0.05069"
"273.2000","5.4626","6.09757","0.05076"
"273.6000","5.4707","6.09987","0.05084"
"274.0000","5.4787","6.09955","0.05091"
"274.4000","5.4867","6.09972","0.05099"
"274.8000","5.4945","6.09836","0.05106"
"275.2000","5.5027","6.10016","0.05113"
"275.6000","5.5104","6.09922","0.05121"
"276.0000","5.5186","6.10052","0.05128"
"276.4000","5.5267","6.10140","0.05136"
"276.8000","5.5347","6.10160","0.05144"
"277.2000","5.5427","6.10190","0.05151"
"277.6000","5.5505","6.10017","0.05158"
"278.0000","5.5587","6.10291","0.05166"
"278.4000","5.5665","6.10111","0.05173"
"278.8000","5.5746","6.10173","0.05180"
"279.2000","5.5826","6.10317","0.05188"
"279.6000","5.5906","6.10306","0.05195"
"280.0000","5.5987","6.10399","0.05202"
"280.4000","5.6066","6.10289","0.05209"
"280.8000","5.6147","6.10457","0.05217"
"281.2000","5.6225","6.10287","0.05224"
"281.6000","5.6306","6.10374","0.05231"
"282.0000","5.6385","6.10478","0.05238"
"282.4000","5.6467","6.10574","0.05245"
"282.8000","5.6547","6.10555","0.05253"
"283.2000","5.6626","6.10439","0.05260"
"283.6000","5.6707","6.10673","0.05267"
"284.0000","5.6784","6.10422","0.05274"
"284.4000","5.6867","6.10583","0.05281"
"284.8000","5.6946","6.10680","0.05288"
"285.2000","5.7026","6.10647","0.05295"
"285.6000","5.7107","6.10691","0.05303"
"286.0000","5.7186","6.10647","0.05309"
"286.4000","5.7267","6.10842","0.05317"
"286.8000","5.7345","6.10640","0.05324"
"287.2000","5.7427","6.10734","0.05331"
"287.6000","5.7505","6.10749","0.05338"
"288.0000","5.7586","6.10796","0.05345"
"288.4000","5.7666","6.10894","0.05352"
"288.8000","5.7747","6.10839","0.05359"
"289.2000","5.7827","6.10977","0.05366"
"289.6000","5.7904","6.10716","0.05373"
"290.0000","5.7987","6.10899","0.05380"
"290.4000","5.8065","6.10933","0.05387"
"290.8000","5.8146","6.10908","0.05393"
"291.2000","5.8227","6.11053","0.05400"
"291.6000","5.8307","6.11006","0.05407"
"292.0000","5.8387","6.11070","0.05414"
"292.4000","5.8464","6.10895","0.05421"
"292.8000","5.8547","6.11095","0.05428"
"293.2000","5.8626","6.11089","0.05435"
"293.6000","5.8706","6.11043","0.05442"
"294.0000","5.8786","6.11076","0.05448"
"294.4000","5.8867","6.11183","0.05455"
"294.8000","5.8946","6.11244","0.05462"
"295.2000","5.9025","6.11008","0.05468"
"295.6000","5.9108","6.11242","0.05476"
"296.0000","5.9185","6.11129","0.05482"
"296.4000","5.9265","6.11097","0.05489"
"296.8000","5.9347","6.11307","0.05495"
"297.2000","5.9427","6.11328","0.05502"
"297.6000","5.9507","6.11344","0.05509"
"298.0000","5.9585","6.11136","0.05515"
"298.4000","5.9667","6.11313","0.05522"
"298.8000","5.9745","6.11267","0.05528"
"299.2000","5.9825","6.11267","0.05535"
"299.6000","5.9907","6.11334","0.05542"
"300.0000","5.9988","6.11477","0.05548"
"300.4000","6.0066","6.11354","0.05555"
"300.8000","6.0144","6.11213","0.05561"
"301.2000","6.0228","6.11570","0.05568"
"301.6000","6.0305","6.11325","0.05574"
"302.0000","6.0386","6.11326","0.05581"
"302.4000","6.0467","6.11462","0.05587"
"302.8000","6.0547","6.11466","0.05593"
"303.2000","6.0626","6.11527","0.05600"
"303.6000","6.0705","6.11367","0.05606"
"304.0000","6.0788","6.11559","0.05613"
"304.4000","6.0865","6.11420","0.05619"
"304.8000","6.0945","6.11371","0.05625"
"305.2000","6.1026","6.11547","0.05631"
"305.6000","6.1108","6.11688","0.05638"
"306.0000","6.1186","6.11508","0.05644"
"306.4000","6.1266","6.11422","0.05650"
"306.8000","6.1348","6.11690","0.05656"
"307.2000","6.1423","6.11378","0.05662"
"307.6000","6.1506","6.11508","0.05668"
"308.0000","6.1587","6.11633","0.05675"
"308.4000","6.1667","6.11620","0.05680"
"308.8000","6.1745","6.11550","0.05687"
"309.2000","6.1825","6.11510","0.05693"
"309.6000","6.1909","6.11795","0.05699"
"310.0000","6.1985","6.11494","0.05705"
"310.4000","6.2065","6.11492","0.05711"
"310.8000","6.2147","6.11644","0.05716"
"311.2000","6.2227","6.11669","0.05722"
"311.6000","6.2305","6.11601","0.05728"
"312.0000","6.2387","6.11612","0.05735"
"312.4000","6.2469","6.11823","0.05741"
"312.8000","6.2544","6.11433","0.05746"
"313.2000","6.2625","6.11539","0.05752"
"313.6000","6.2706","6.11708","0.05758"
"314.0000","6.2787","6.11691","0.05763"
"314.4000","6.2865","6.11600","0.05769"
"314.8000","6.2947","6.11673","0.05775"
"315.2000","6.3029","6.11825","0.05781"
"315.6000","6.3104","6.11431","0.05786"
"316.0000","6.3186","6.11616","0.05791"
"316.4000","6.3267","6.11700","0.05797"
"316.8000","6.3347","6.11679","0.05802"
"317.2000","6.3425","6.11562","0.05808"
"317.6000","6.3506","6.11658","0.05813"
"318.0000","6.3589","6.11884","0.05819"
"318.4000","6.3664","6.11441","0.05824"
"318.8000","6.3746","6.11563","0.05830"
"319.2000","6.3827","6.11659","0.05835"
"319.6000","6.3906","6.11558","0.05840"
"320.0000","6.3985","6.11562","0.05845"
"320.4000","6.4067","6.11712","0.05850"
"320.8000","6.4148","6.11773","0.05855"
"321.2000","6.4224","6.11413","0.05860"
"321.6000","6.4306","6.11583","0.05865"
"322.0000","6.4386","6.11581","0.05870"
"322.4000","6.4467","6.11610","0.05875"
"322.8000","6.4545","6.11496","0.05880"
"323.2000","6.4628","6.11597","0.05885"
"323.6000","6.4708","6.11678","0.05890"
"324.0000","6.4783","6.11305","0.05895"
"324.4000","6.4867","6.11540","0.05900"
"324.8000","6.4947","6.11552","0.05905"
"325.2000","6.5026","6.11413","0.05909"
"325.6000","6.5105","6.11370","0.05914"
"326.0000","6.5187","6.11521","0.05918"
"326.4000","6.5267","6.11583","0.05923"
"326.8000","6.5345","6.11246","0.05928"
"327.2000","6.5427","6.11429","0.05932"
"327.6000","6.5506","6.11331","0.05937"
"328.0000","6.5586","6.11263","0.05941"
"328.4000","6.5665","6.11226","0.05945"
"328.8000","6.5748","6.11401","0.05949"
"329.2000","6.5827","6.11382","0.05954"
"329.6000","6.5905","6.11045","0.05958"
"330.0000","6.5987","6.11260","0.05962"
"330.4000","6.6065","6.11158","0.05966"
"330.8000","6.6146","6.11101","0.05970"
"331.2000","6.6226","6.11046","0.05974"
"331.6000","6.6308","6.11154","0.05978"
"332.0000","6.6387","6.11079","0.05982"
"332.4000","6.6465","6.10859","0.05985"
"332.8000","6.6547","6.11068","0.05989"
"333.2000","6.6626","6.10841","0.05993"
"333.6000","6.6706","6.10793","0.05996"
"334.0000","6.6785","6.10714","0.06000"
"334.4000","6.6867","6.10770","0.06003"
"334.8000","6.6947","6.10792","0.06007"
"335.2000","6.7026","6.10509","0.06010"
"335.6000","6.7108","6.10651","0.06013"
"336.0000","6.7186","6.10433","0.06017"
"336.4000","6.7265","6.10332","0.06020"
"336.8000","6.7345","6.10294","0.06023"
"337.2000","6.7428","6.10356","0.06026"
"337.6000","6.7506","6.10173","0.06029"
"338.0000","6.7586","6.10004","0.06031"
"338.4000","6.7667","6.10083","0.06034"
"338.8000","6.7745","6.09784","0.06037"
"339.2000","6.7826","6.09758","0.06039"
"339.6000","6.7906","6.09601","0.06042"
"340.0000","6.7987","6.09564","0.06044"
"340.4000","6.8066","6.09415","0.06047"
"340.8000","6.8146","6.09161","0.06049"
"341.2000","6.8228","6.09253","0.06051"
"341.6000","6.8305","6.08886","0.06053"
"342.0000","6.8386","6.08700","0.06055"
"342.4000","6.8466","6.08554","0.06057"
"342.8000","6.8546","6.08427","0.06059"
"343.2000","6.8625","6.08200","0.06060"
"343.6000","6.8707","6.07968","0.06062"
"344.0000","6.8788","6.07880","0.06064"
"344.4000","6.8865","6.07405","0.06065"
"344.8000","6.8946","6.07214","0.06066"
"345.2000","6.9025","6.06880","0.06068"
"345.6000","6.9107","6.06742","0.06069"
"346.0000","6.9186","6.06376","0.06070"
"346.4000","6.9267","6.05997","0.06071"
"346.8000","6.9348","6.05855","0.06072"
"347.2000","6.9425","6.05269","0.06073"
"347.6000","6.9506","6.04974","0.06073"
"348.0000","6.9586","6.04528","0.06074"
"348.4000","6.9667","6.04153","0.06075"
"348.8000","6.9745","6.03658","0.06075"
"349.2000","6.9826","6.03215","0.06075"
"349.6000","6.9907","6.02918","0.06076"
"350.0000","6.9986","6.02187","0.06076"
"350.4000","7.0067","6.01739","0.06076"
"350.8000","7.0145","6.01084","0.06076"
"351.2000","7.0226","6.00666","0.06077"
"351.6000","7.0305","6.00025","0.06076"
"352.0000","7.0387","5.99387","0.06076"
"352.4000","7.0468","5.98971","0.06076"
"352.8000","7.0546","5.98060","0.06076"
"353.2000","7.0627","5.97425","0.06076"
"353.6000","7.0705","5.96690","0.06076"
"354.0000","7.0787","5.96073","0.06075"
"354.4000","7.0865","5.95237","0.06075"
"354.8000","7.0947","5.94481","0.06075"
"355.2000","7.1027","5.93873","0.06075"
"355.6000","7.1106","5.92918","0.06074"
"356.0000","7.1187","5.92181","0.06074"
"356.4000","7.1266","5.91159","0.06073"
"356.8000","7.1347","5.90459","0.06073"
"357.2000","7.1425","5.89501","0.06072"
"357.6000","7.1506","5.88552","0.06072"
"358.0000","7.1587","5.87905","0.06071"
"358.4000","7.1666","5.86763","0.06070"
"358.8000","7.1747","5.85801","0.06070"
"359.2000","7.1825","5.84690","0.06069"
"359.6000","7.1906","5.83846","0.06069"
"360.0000","7.1985","5.82730","0.06068"
"360.4000","7.2067","5.81692","0.06067"
"360.8000","7.2147","5.80771","0.06066"
"361.2000","7.2227","5.79590","0.06066"
"361.6000","7.2307","5.78502","0.06065"
"362.0000","7.2385","5.77198","0.06064"
"362.4000","7.2467","5.76270","0.06063"
"362.8000","7.2545","5.74965","0.06062"
"363.2000","7.2626","5.73678","0.06062"
"363.6000","7.2706","5.72726","0.06061"
"364.0000","7.2786","5.71374","0.06060"
"364.4000","7.2867","5.70105","0.06059"
"364.8000","7.2946","5.68670","0.06058"
"365.2000","7.3027","5.67489","0.06057"
"365.6000","7.3105","5.66044","0.06056"
"366.0000","7.3186","5.64674","0.06056"
"366.4000","7.3266","5.63508","0.06055"
"366.8000","7.3347","5.62025","0.06054"
"367.2000","7.3427","5.60519","0.06053"
"367.6000","7.3505","5.58880","0.06052"
"368.0000","7.3587","5.57615","0.06051"
"368.4000","7.3664","5.55898","0.06050"
"368.8000","7.3747","5.54280","0.06049"
"369.2000","7.3827","5.52912","0.06048"
"369.6000","7.3907","5.51140","0.06047"
"370.0000","7.3987","5.49425","0.06046"
"370.4000","7.4065","5.47591","0.06044"
"370.8000","7.4147","5.46030","0.06043"
"371.2000","7.4226","5.44063","0.06042"
"371.6000","7.4306","5.42188","0.06041"
"372.0000","7.4386","5.40539","0.06040"
"372.4000","7.4466","5.38567","0.06039"
"372.8000","7.4547","5.36598","0.06037"
"373.2000","7.4626","5.34385","0.06036"
"373.6000","7.4707","5.32446","0.06035"
"374.0000","7.4785","5.29961","0.06033"
"374.4000","7.4866","5.27517","0.06031"
"374.8000","7.4946","5.25496","0.06030"
"375.2000","7.5027","5.22975","0.06028"
"375.6000","7.5107","5.20496","0.06026"
"376.0000","7.5186","5.17949","0.06024"
"376.4000","7.5267","5.15474","0.06023"
"376.8000","7.5345","5.12542","0.06021"
"377.2000","7.5427","5.09584","0.06018"
"377.6000","7.5506","5.06712","0.06016"
"378.0000","7.5587","5.03316","0.06014"
"378.4000","7.5667","5.00026","0.06011"
"378.8000","7.5746","4.96193","0.06008"
"379.2000","7.5827","4.92076","0.06005"
"379.6000","7.5905","4.87827","0.06002"
"380.0000","7.5987","4.82096","0.05998"
"380.4000","7.6066","4.72103","0.05991"
"380.8000","7.6146","4.51263","0.05977"
"380.8380","7.6155","4.12341","0.05949"
"380.8500","7.6159","3.71103","0.05917"
"380.8520","7.6160","3.64982","0.05914"