File: Coupon Test Data/Tensile Test_Neebajan_Alan_22.csv
Time,Displacement,Force,Strain 1
(s),(mm),(kN),(mm/mm)
"0.0000","0.0000","0.16129","0.00007"
"0.2000","0.0025","0.17473","0.00008"
"0.4000","0.0064","0.20347","0.00011"
"0.6000","0.0105","0.23280","0.00013"
"0.8000","0.0143","0.25993","0.00015"
"1.0000","0.0184","0.28852","0.00018"
"1.2000","0.0225","0.31701","0.00021"
"1.4000","0.0264","0.34431","0.00023"
"1.6000","0.0304","0.37233","0.00025"
"1.8000","0.0346","0.40146","0.00028"
"2.0000","0.0385","0.42801","0.00030"
"2.2000","0.0424","0.45486","0.00032"
"2.4000","0.0466","0.48392","0.00035"
"2.6000","0.0503","0.50916","0.00037"
"2.8000","0.0544","0.53703","0.00040"
"3.0000","0.0585","0.56521","0.00042"
"3.2000","0.0625","0.58951","0.00044"
"3.4000","0.0667","0.61754","0.00047"
"3.6000","0.0705","0.64376","0.00049"
"3.8000","0.0745","0.67065","0.00051"
"4.0000","0.0785","0.69814","0.00054"
"4.2000","0.0825","0.72470","0.00056"
"4.4000","0.0864","0.75106","0.00059"
"4.6000","0.0906","0.77969","0.00061"
"4.8000","0.0945","0.80521","0.00063"
"5.0000","0.0983","0.82891","0.00065"
"5.2000","0.1026","0.85738","0.00068"
"5.4000","0.1064","0.88240","0.00070"
"5.6000","0.1105","0.90952","0.00072"
"5.8000","0.1146","0.93656","0.00075"
"6.0000","0.1185","0.96279","0.00077"
"6.2000","0.1226","0.98423","0.00079"
"6.4000","0.1265","1.00681","0.00081"
"6.6000","0.1304","1.03257","0.00083"
"6.8000","0.1345","1.05923","0.00085"
"7.0000","0.1384","1.08513","0.00087"
"7.2000","0.1424","1.11108","0.00090"
"7.4000","0.1467","1.13970","0.00092"
"7.6000","0.1505","1.16378","0.00094"
"7.8000","0.1544","1.18809","0.00097"
"8.0000","0.1587","1.21609","0.00099"
"8.2000","0.1624","1.24012","0.00101"
"8.4000","0.1665","1.26374","0.00103"
"8.6000","0.1706","1.28938","0.00105"
"8.8000","0.1745","1.31425","0.00108"
"9.0000","0.1785","1.33913","0.00110"
"9.2000","0.1824","1.36395","0.00112"
"9.4000","0.1864","1.38980","0.00114"
"9.6000","0.1905","1.41632","0.00117"
"9.8000","0.1945","1.44180","0.00119"
"10.0000","0.1984","1.46590","0.00121"
"10.2000","0.2027","1.49167","0.00123"
"10.4000","0.2065","1.51379","0.00125"
"10.6000","0.2103","1.53771","0.00127"
"10.8000","0.2146","1.56478","0.00130"
"11.0000","0.2184","1.58831","0.00132"
"11.2000","0.2225","1.61349","0.00134"
"11.4000","0.2265","1.63910","0.00136"
"11.6000","0.2306","1.66463","0.00139"
"11.8000","0.2346","1.68915","0.00141"
"12.0000","0.2385","1.71050","0.00143"
"12.2000","0.2425","1.73485","0.00145"
"12.4000","0.2465","1.75996","0.00147"
"12.6000","0.2505","1.78454","0.00149"
"12.8000","0.2544","1.80854","0.00151"
"13.0000","0.2587","1.83538","0.00154"
"13.2000","0.2625","1.85785","0.00156"
"13.4000","0.2663","1.88061","0.00158"
"13.6000","0.2706","1.90460","0.00160"
"13.8000","0.2744","1.92731","0.00162"
"14.0000","0.2785","1.95242","0.00164"
"14.2000","0.2826","1.97712","0.00166"
"14.4000","0.2866","2.00083","0.00168"
"14.6000","0.2906","2.02474","0.00171"
"14.8000","0.2945","2.04769","0.00173"
"15.0000","0.2984","2.07009","0.00175"
"15.2000","0.3025","2.09211","0.00177"
"15.4000","0.3065","2.11603","0.00179"
"15.6000","0.3104","2.13825","0.00181"
"15.8000","0.3147","2.16412","0.00183"
"16.0000","0.3186","2.18637","0.00185"
"16.2000","0.3224","2.20824","0.00187"
"16.4000","0.3266","2.23275","0.00190"
"16.6000","0.3305","2.25228","0.00191"
"16.8000","0.3346","2.27577","0.00194"
"17.0000","0.3386","2.29870","0.00196"
"17.2000","0.3426","2.32142","0.00198"
"17.4000","0.3465","2.34386","0.00200"
"17.6000","0.3504","2.36566","0.00202"
"17.8000","0.3544","2.38765","0.00204"
"18.0000","0.3586","2.40893","0.00206"
"18.2000","0.3626","2.43145","0.00208"
"18.4000","0.3664","2.45290","0.00210"
"18.6000","0.3708","2.47764","0.00212"
"18.8000","0.3745","2.49808","0.00214"
"19.0000","0.3783","2.51887","0.00216"
"19.2000","0.3825","2.54093","0.00218"
"19.4000","0.3864","2.56094","0.00220"
"19.6000","0.3905","2.58309","0.00222"
"19.8000","0.3945","2.60480","0.00224"
"20.0000","0.3986","2.62646","0.00226"
"20.2000","0.4025","2.64706","0.00228"
"20.4000","0.4065","2.66529","0.00230"
"20.6000","0.4105","2.68554","0.00232"
"20.8000","0.4146","2.70733","0.00234"
"21.0000","0.4186","2.72859","0.00236"
"21.2000","0.4224","2.74781","0.00238"
"21.4000","0.4267","2.76906","0.00240"
"21.6000","0.4305","2.78678","0.00242"
"21.8000","0.4343","2.80623","0.00244"
"22.0000","0.4385","2.82745","0.00246"
"22.2000","0.4425","2.84747","0.00248"
"22.4000","0.4466","2.86537","0.00250"
"22.6000","0.4506","2.88483","0.00252"
"22.8000","0.4546","2.90462","0.00254"
"23.0000","0.4585","2.92374","0.00256"
"23.2000","0.4624","2.94058","0.00257"
"23.4000","0.4664","2.95824","0.00259"
"23.6000","0.4705","2.97740","0.00261"
"23.8000","0.4746","2.99253","0.00263"
"24.0000","0.4784","3.00566","0.00264"
"24.2000","0.4827","3.02236","0.00266"
"24.4000","0.4865","3.03513","0.00267"
"24.6000","0.4904","3.04922","0.00268"
"24.8000","0.4946","3.06533","0.00270"
"25.0000","0.4986","3.07960","0.00271"
"25.2000","0.5026","3.09327","0.00273"
"25.4000","0.5066","3.10785","0.00275"
"25.6000","0.5106","3.12169","0.00276"
"25.8000","0.5144","3.13484","0.00278"
"26.0000","0.5184","3.14899","0.00279"
"26.2000","0.5224","3.16281","0.00281"
"26.4000","0.5266","3.17675","0.00282"
"26.6000","0.5307","3.18991","0.00284"
"26.8000","0.5345","3.20179","0.00285"
"27.0000","0.5387","3.21715","0.00287"
"27.2000","0.5425","3.22993","0.00288"
"27.4000","0.5464","3.24325","0.00290"
"27.6000","0.5505","3.25760","0.00292"
"27.8000","0.5545","3.27088","0.00294"
"28.0000","0.5585","3.28284","0.00295"
"28.2000","0.5625","3.29362","0.00297"
"28.4000","0.5666","3.30576","0.00298"
"28.6000","0.5705","3.31698","0.00300"
"28.8000","0.5745","3.32820","0.00301"
"29.0000","0.5785","3.33911","0.00303"
"29.2000","0.5826","3.35032","0.00304"
"29.4000","0.5866","3.36027","0.00306"
"29.6000","0.5904","3.36917","0.00308"
"29.8000","0.5946","3.38037","0.00309"
"30.0000","0.5985","3.38714","0.00310"
"30.2000","0.6024","3.39479","0.00312"
"30.4000","0.6065","3.40470","0.00314"
"30.6000","0.6106","3.41256","0.00315"
"30.8000","0.6146","3.41917","0.00316"
"31.0000","0.6185","3.42652","0.00318"
"31.2000","0.6226","3.43258","0.00319"
"31.4000","0.6265","3.43754","0.00320"
"31.6000","0.6305","3.44187","0.00321"
"31.8000","0.6344","3.44719","0.00322"
"32.0000","0.6386","3.45436","0.00324"
"32.2000","0.6426","3.45869","0.00325"
"32.4000","0.6464","3.46228","0.00326"
"32.6000","0.6506","3.46770","0.00327"
"32.8000","0.6546","3.47116","0.00328"
"33.0000","0.6585","3.47436","0.00329"
"33.2000","0.6625","3.47919","0.00330"
"33.4000","0.6667","3.48301","0.00331"
"33.6000","0.6706","3.48548","0.00332"
"33.8000","0.6745","3.48842","0.00333"
"34.0000","0.6786","3.49178","0.00334"
"34.2000","0.6825","3.49025","0.00335"
"34.4000","0.6865","3.49407","0.00335"
"34.6000","0.6904","3.49756","0.00337"
"34.8000","0.6946","3.50190","0.00337"
"35.0000","0.6986","3.50395","0.00338"
"35.2000","0.7024","3.50466","0.00339"
"35.4000","0.7066","3.50835","0.00339"
"35.6000","0.7106","3.50946","0.00340"
"35.8000","0.7144","3.51076","0.00341"
"36.0000","0.7185","3.51384","0.00342"
"36.2000","0.7226","3.51597","0.00342"
"36.4000","0.7264","3.51702","0.00343"
"36.6000","0.7304","3.51901","0.00344"
"36.8000","0.7346","3.52114","0.00344"
"37.0000","0.7385","3.52187","0.00345"
"37.2000","0.7426","3.52437","0.00346"
"37.4000","0.7465","3.52562","0.00346"
"37.6000","0.7506","3.52754","0.00347"
"37.8000","0.7546","3.52898","0.00348"
"38.0000","0.7584","3.52960","0.00349"
"38.2000","0.7625","3.53238","0.00349"
"38.4000","0.7666","3.53331","0.00350"
"38.6000","0.7705","3.53473","0.00351"
"38.8000","0.7744","3.53698","0.00352"
"39.0000","0.7787","3.53891","0.00352"
"39.2000","0.7825","3.53881","0.00353"
"39.4000","0.7865","3.53986","0.00353"
"39.6000","0.7906","3.54179","0.00354"
"39.8000","0.7945","3.54248","0.00354"
"40.0000","0.7986","3.54455","0.00355"
"40.2000","0.8025","3.54568","0.00356"
"40.4000","0.8065","3.54775","0.00356"
"40.6000","0.8106","3.54864","0.00357"
"40.8000","0.8143","3.54870","0.00358"
"41.0000","0.8185","3.55188","0.00358"
"41.2000","0.8226","3.55296","0.00359"
"41.4000","0.8265","3.55387","0.00360"
"41.6000","0.8305","3.55589","0.00360"
"41.8000","0.8347","3.55796","0.00361"
"42.0000","0.8385","3.55740","0.00362"
"42.2000","0.8425","3.55901","0.00362"
"42.4000","0.8466","3.56084","0.00363"
"42.6000","0.8505","3.56121","0.00364"
"42.8000","0.8546","3.56358","0.00365"
"43.0000","0.8584","3.56425","0.00365"
"43.2000","0.8625","3.56625","0.00366"
"43.4000","0.8666","3.56728","0.00367"
"43.6000","0.8705","3.56722","0.00367"
"43.8000","0.8745","3.56910","0.00368"
"44.0000","0.8786","3.57048","0.00369"
"44.2000","0.8825","3.57121","0.00370"
"44.4000","0.8864","3.57208","0.00370"
"44.6000","0.8907","3.57456","0.00371"
"44.8000","0.8944","3.57425","0.00371"
"45.0000","0.8984","3.57547","0.00372"
"45.2000","0.9025","3.57720","0.00373"
"45.4000","0.9065","3.57797","0.00374"
"45.6000","0.9107","3.57996","0.00374"
"45.8000","0.9145","3.58012","0.00375"
"46.0000","0.9186","3.58190","0.00376"
"46.2000","0.9226","3.58287","0.00376"
"46.4000","0.9264","3.57660","0.00377"
"46.6000","0.9305","3.58175","0.00377"
"46.8000","0.9347","3.58551","0.00378"
"47.0000","0.9385","3.58681","0.00379"
"47.2000","0.9424","3.58786","0.00380"
"47.4000","0.9467","3.59049","0.00381"
"47.6000","0.9504","3.58916","0.00382"
"47.8000","0.9545","3.59022","0.00383"
"48.0000","0.9586","3.59210","0.00384"
"48.2000","0.9625","3.59281","0.00385"
"48.4000","0.9666","3.59495","0.00385"
"48.6000","0.9705","3.59501","0.00386"
"48.8000","0.9745","3.59628","0.00387"
"49.0000","0.9785","3.59727","0.00388"
"49.2000","0.9824","3.59731","0.00389"
"49.4000","0.9864","3.59900","0.00390"
"49.6000","0.9907","3.60107","0.00391"
"49.8000","0.9946","3.60140","0.00392"
"50.0000","0.9984","3.60191","0.00392"
"50.2000","1.0027","3.60406","0.00393"
"50.4000","1.0064","3.60342","0.00394"
"50.6000","1.0105","3.60486","0.00395"
"50.8000","1.0146","3.60636","0.00396"
"51.0000","1.0185","3.60700","0.00397"
"51.2000","1.0226","3.60837","0.00398"
"51.4000","1.0264","3.60854","0.00399"
"51.6000","1.0305","3.61058","0.00400"
"51.8000","1.0346","3.61157","0.00400"
"52.0000","1.0385","3.61128","0.00401"
"52.2000","1.0425","3.61249","0.00403"
"52.4000","1.0467","3.61422","0.00403"
"52.6000","1.0505","3.61423","0.00404"
"52.8000","1.0544","3.61507","0.00405"
"53.0000","1.0586","3.61778","0.00406"
"53.2000","1.0624","3.61670","0.00407"
"53.4000","1.0664","3.61843","0.00408"
"53.6000","1.0705","3.62009","0.00409"
"53.8000","1.0745","3.62040","0.00410"
"54.0000","1.0786","3.62070","0.00411"
"54.2000","1.0825","3.62143","0.00412"
"54.4000","1.0865","3.62274","0.00413"
"54.6000","1.0906","3.62402","0.00415"
"54.8000","1.0945","3.62449","0.00416"
"55.0000","1.0984","3.62529","0.00417"
"55.2000","1.1027","3.62776","0.00418"
"55.4000","1.1065","3.62753","0.00419"
"55.6000","1.1103","3.62774","0.00420"
"55.8000","1.1146","3.63055","0.00421"
"56.0000","1.1184","3.62982","0.00423"
"56.2000","1.1225","3.63133","0.00424"
"56.4000","1.1266","3.63259","0.00425"
"56.6000","1.1306","3.63323","0.00426"
"56.8000","1.1346","3.63449","0.00427"
"57.0000","1.1385","3.63416","0.00429"
"57.2000","1.1424","3.63552","0.00430"
"57.4000","1.1465","3.63674","0.00431"
"57.6000","1.1505","3.63733","0.00432"
"57.8000","1.1544","3.63826","0.00433"
"58.0000","1.1588","3.64110","0.00435"
"58.2000","1.1626","3.63995","0.00436"
"58.4000","1.1664","3.63990","0.00437"
"58.6000","1.1707","3.64270","0.00439"
"58.8000","1.1745","3.64150","0.00440"
"59.0000","1.1785","3.64305","0.00441"
"59.2000","1.1826","3.64465","0.00443"
"59.4000","1.1866","3.64517","0.00444"
"59.6000","1.1905","3.64583","0.00445"
"59.8000","1.1944","3.64600","0.00447"
"60.0000","1.1984","3.64739","0.00448"
"60.2000","1.2025","3.64861","0.00450"
"60.4000","1.2066","3.64934","0.00451"
"60.6000","1.2105","3.64979","0.00453"
"60.8000","1.2147","3.65194","0.00454"
"61.0000","1.2185","3.65130","0.00456"
"61.2000","1.2224","3.65148","0.00457"
"61.4000","1.2266","3.65362","0.00459"
"61.6000","1.2304","3.65348","0.00460"
"61.8000","1.2346","3.65526","0.00462"
"62.0000","1.2385","3.65580","0.00463"
"62.2000","1.2426","3.65690","0.00464"
"62.4000","1.2466","3.65788","0.00466"
"62.6000","1.2505","3.65726","0.00468"
"62.8000","1.2544","3.65841","0.00469"
"63.0000","1.2586","3.66005","0.00471"
"63.2000","1.2626","3.66046","0.00472"
"63.4000","1.2664","3.66027","0.00474"
"63.6000","1.2707","3.66302","0.00476"
"63.8000","1.2745","3.66208","0.00477"
"64.0000","1.2783","3.66215","0.00479"
"64.2000","1.2825","3.66514","0.00481"
"64.4000","1.2865","3.66471","0.00482"
"64.6000","1.2906","3.66603","0.00484"
"64.8000","1.2946","3.66689","0.00486"
"65.0000","1.2987","3.66714","0.00487"
"65.2000","1.3025","3.66717","0.00488"
"65.4000","1.3064","3.66765","0.00490"
"65.6000","1.3104","3.66901","0.00492"
"65.8000","1.3145","3.67029","0.00493"
"66.0000","1.3186","3.67127","0.00495"
"66.2000","1.3224","3.67160","0.00497"
"66.4000","1.3267","3.67389","0.00498"
"66.6000","1.3305","3.67288","0.00500"
"66.8000","1.3344","3.67296","0.00501"
"67.0000","1.3386","3.67497","0.00503"
"67.2000","1.3425","3.67488","0.00505"
"67.4000","1.3466","3.67651","0.00506"
"67.6000","1.3506","3.67706","0.00508"
"67.8000","1.3546","3.67751","0.00510"
"68.0000","1.3585","3.67783","0.00512"
"68.2000","1.3625","3.67815","0.00513"
"68.4000","1.3664","3.67897","0.00515"
"68.6000","1.3706","3.68089","0.00517"
"68.8000","1.3747","3.68167","0.00519"
"69.0000","1.3784","3.68086","0.00520"
"69.2000","1.3827","3.68341","0.00522"
"69.4000","1.3866","3.68298","0.00524"
"69.6000","1.3903","3.68223","0.00525"
"69.8000","1.3945","3.68474","0.00527"
"70.0000","1.3986","3.68543","0.00529"
"70.2000","1.4025","3.68585","0.00531"
"70.4000","1.4065","3.68675","0.00532"
"70.6000","1.4106","3.68810","0.00534"
"70.8000","1.4145","3.68740","0.00536"
"71.0000","1.4185","3.68805","0.00538"
"71.2000","1.4225","3.68899","0.00540"
"71.4000","1.4266","3.69034","0.00541"
"71.6000","1.4307","3.69127","0.00543"
"71.8000","1.4344","3.69092","0.00545"
"72.0000","1.4387","3.68228","0.00545"
"72.2000","1.4425","3.68473","0.00547"
"72.4000","1.4463","3.68851","0.00548"
"72.6000","1.4505","3.69307","0.00550"
"72.8000","1.4545","3.69470","0.00552"
"73.0000","1.4585","3.69606","0.00554"
"73.2000","1.4626","3.69684","0.00556"
"73.4000","1.4666","3.69694","0.00558"
"73.6000","1.4704","3.69703","0.00559"
"73.8000","1.4745","3.69776","0.00561"
"74.0000","1.4784","3.69784","0.00563"
"74.2000","1.4825","3.69973","0.00565"
"74.4000","1.4866","3.70063","0.00567"
"74.6000","1.4903","3.69952","0.00568"
"74.8000","1.4946","3.70215","0.00570"
"75.0000","1.4986","3.70156","0.00572"
"75.2000","1.5024","3.70083","0.00574"
"75.4000","1.5065","3.70299","0.00576"
"75.6000","1.5107","3.70361","0.00578"
"75.8000","1.5145","3.70377","0.00579"
"76.0000","1.5185","3.70449","0.00581"
"76.2000","1.5226","3.70543","0.00583"
"76.4000","1.5265","3.70499","0.00585"
"76.6000","1.5305","3.70595","0.00587"
"76.8000","1.5344","3.70648","0.00589"
"77.0000","1.5386","3.70844","0.00591"
"77.2000","1.5427","3.70892","0.00592"
"77.4000","1.5464","3.70803","0.00594"
"77.6000","1.5506","3.71013","0.00596"
"77.8000","1.5546","3.70957","0.00598"
"78.0000","1.5584","3.70947","0.00600"
"78.2000","1.5625","3.71115","0.00602"
"78.4000","1.5666","3.71215","0.00604"
"78.6000","1.5705","3.71222","0.00605"
"78.8000","1.5744","3.71296","0.00607"
"79.0000","1.5786","3.71404","0.00609"
"79.2000","1.5825","3.71388","0.00611"
"79.4000","1.5866","3.71465","0.00613"
"79.6000","1.5905","3.71486","0.00615"
"79.8000","1.5946","3.71656","0.00617"
"80.0000","1.5987","3.71692","0.00619"
"80.2000","1.6024","3.71602","0.00620"
"80.4000","1.6066","3.71799","0.00623"
"80.6000","1.6105","3.71754","0.00624"
"80.8000","1.6144","3.71782","0.00626"
"81.0000","1.6184","3.71937","0.00628"
"81.2000","1.6226","3.72058","0.00630"
"81.4000","1.6265","3.72026","0.00632"
"81.6000","1.6305","3.72073","0.00634"
"81.8000","1.6346","3.72162","0.00636"
"82.0000","1.6385","3.72138","0.00638"
"82.2000","1.6426","3.72249","0.00639"
"82.4000","1.6464","3.72254","0.00641"
"82.6000","1.6505","3.72399","0.00643"
"82.8000","1.6546","3.72413","0.00645"
"83.0000","1.6584","3.72222","0.00647"
"83.2000","1.6625","3.72462","0.00649"
"83.4000","1.6666","3.72528","0.00650"
"83.6000","1.6705","3.72575","0.00652"
"83.8000","1.6745","3.72679","0.00654"
"84.0000","1.6787","3.72810","0.00656"
"84.2000","1.6825","3.72767","0.00658"
"84.4000","1.6865","3.72798","0.00659"
"84.6000","1.6906","3.72912","0.00661"
"84.8000","1.6945","3.72907","0.00663"
"85.0000","1.6986","3.73024","0.00665"
"85.2000","1.7024","3.73005","0.00667"
"85.4000","1.7065","3.73164","0.00668"
"85.6000","1.7106","3.73198","0.00671"
"85.8000","1.7144","3.73097","0.00672"
"86.0000","1.7185","3.73270","0.00674"
"86.2000","1.7226","3.73295","0.00676"
"86.4000","1.7265","3.73295","0.00678"
"86.6000","1.7304","3.73386","0.00680"
"86.8000","1.7347","3.73540","0.00681"
"87.0000","1.7384","3.73416","0.00683"
"87.2000","1.7424","3.73490","0.00685"
"87.4000","1.7466","3.73648","0.00687"
"87.6000","1.7505","3.73617","0.00689"
"87.8000","1.7547","3.73758","0.00691"
"88.0000","1.7585","3.73731","0.00692"
"88.2000","1.7626","3.73797","0.00694"
"88.4000","1.7666","3.73840","0.00696"
"88.6000","1.7704","3.73781","0.00697"
"88.8000","1.7744","3.73898","0.00699"
"89.0000","1.7786","3.73990","0.00701"
"89.2000","1.7825","3.74004","0.00703"
"89.4000","1.7864","3.74036","0.00705"
"89.6000","1.7907","3.74211","0.00707"
"89.8000","1.7945","3.74106","0.00709"
"90.0000","1.7985","3.74160","0.00710"
"90.2000","1.8026","3.74249","0.00712"
"90.4000","1.8065","3.74260","0.00714"
"90.6000","1.8107","3.74392","0.00716"
"90.8000","1.8145","3.74323","0.00717"
"91.0000","1.8185","3.74435","0.00719"
"91.2000","1.8225","3.74475","0.00721"
"91.4000","1.8264","3.74399","0.00722"
"91.6000","1.8304","3.74549","0.00724"
"91.8000","1.8347","3.74678","0.00726"
"92.0000","1.8386","3.74637","0.00728"
"92.2000","1.8425","3.74673","0.00729"
"92.4000","1.8467","3.74830","0.00731"
"92.6000","1.8504","3.74681","0.00733"
"92.8000","1.8545","3.74764","0.00735"
"93.0000","1.8586","3.74887","0.00737"
"93.2000","1.8625","3.74868","0.00738"
"93.4000","1.8666","3.74994","0.00740"
"93.6000","1.8704","3.74946","0.00742"
"93.8000","1.8745","3.75048","0.00743"
"94.0000","1.8786","3.75085","0.00745"
"94.2000","1.8825","3.75018","0.00747"
"94.4000","1.8864","3.75091","0.00749"
"94.6000","1.8907","3.75246","0.00750"
"94.8000","1.8946","3.75205","0.00752"
"95.0000","1.8984","3.75182","0.00753"
"95.2000","1.9026","3.75382","0.00755"
"95.4000","1.9064","3.75262","0.00757"
"95.6000","1.9104","3.75335","0.00759"
"95.8000","1.9145","3.75449","0.00760"
"96.0000","1.9186","3.75476","0.00762"
"96.2000","1.9227","3.75569","0.00764"
"96.4000","1.9265","3.75505","0.00765"
"96.6000","1.9305","3.75573","0.00767"
"96.8000","1.9346","3.75622","0.00769"
"97.0000","1.9385","3.75555","0.00770"
"97.2000","1.9424","3.75620","0.00772"
"97.4000","1.9467","3.75766","0.00774"
"97.6000","1.9505","3.75675","0.00775"
"97.8000","1.9543","3.75660","0.00777"
"98.0000","1.9586","3.75888","0.00779"
"98.2000","1.9624","3.75741","0.00780"
"98.4000","1.9665","3.75814","0.00781"
"98.6000","1.9706","3.75773","0.00783"
"98.8000","1.9746","3.75800","0.00785"
"99.0000","1.9786","3.75952","0.00786"
"99.2000","1.9825","3.75913","0.00788"
"99.4000","1.9864","3.75978","0.00789"
"99.6000","1.9905","3.76054","0.00791"
"99.8000","1.9945","3.76049","0.00793"
"100.0000","1.9984","3.76074","0.00794"
"100.2000","2.0027","3.76284","0.00796"
"100.4000","2.0066","3.76194","0.00797"
"100.6000","2.0104","3.76143","0.00799"
"100.8000","2.0147","3.76326","0.00801"
"101.0000","2.0185","3.76162","0.00802"
"101.2000","2.0225","3.76246","0.00803"
"101.4000","2.0266","3.76318","0.00805"
"101.6000","2.0306","3.76355","0.00806"
"101.8000","2.0346","3.76384","0.00808"
"102.0000","2.0384","3.76314","0.00810"
"102.2000","2.0424","3.76414","0.00811"
"102.4000","2.0466","3.76489","0.00813"
"102.6000","2.0506","3.76451","0.00814"
"102.8000","2.0545","3.76483","0.00816"
"103.0000","2.0588","3.76658","0.00817"
"103.2000","2.0625","3.76506","0.00819"
"103.4000","2.0663","3.76472","0.00820"
"103.6000","2.0706","3.76682","0.00822"
"103.8000","2.0744","3.76541","0.00823"
"104.0000","2.0785","3.76654","0.00825"
"104.2000","2.0825","3.76723","0.00826"
"104.4000","2.0866","3.76722","0.00827"
"104.6000","2.0906","3.76767","0.00829"
"104.8000","2.0945","3.76701","0.00830"
"105.0000","2.0985","3.76716","0.00832"
"105.2000","2.1026","3.76782","0.00833"
"105.4000","2.1066","3.76803","0.00834"
"105.6000","2.1104","3.76767","0.00836"
"105.8000","2.1147","3.76955","0.00837"
"106.0000","2.1185","3.76820","0.00838"
"106.2000","2.1223","3.76739","0.00840"
"106.4000","2.1266","3.76967","0.00841"
"106.6000","2.1305","3.76872","0.00842"
"106.8000","2.1346","3.76960","0.00844"
"107.0000","2.1386","3.76993","0.00845"
"107.2000","2.1426","3.76997","0.00846"
"107.4000","2.1466","3.76998","0.00848"
"107.6000","2.1504","3.76920","0.00849"
"107.8000","2.1544","3.76968","0.00850"
"108.0000","2.1585","3.77058","0.00851"
"108.2000","2.1625","3.77062","0.00852"
"108.4000","2.1664","3.77016","0.00854"
"108.6000","2.1708","3.77253","0.00855"
"108.8000","2.1745","3.77048","0.00856"
"109.0000","2.1784","3.76975","0.00857"
"109.2000","2.1826","3.77178","0.00859"
"109.4000","2.1865","3.77045","0.00860"
"109.6000","2.1906","3.77155","0.00861"
"109.8000","2.1946","3.77179","0.00862"
"110.0000","2.1986","3.77133","0.00863"
"110.2000","2.2025","3.77091","0.00864"
"110.4000","2.2064","3.77067","0.00865"
"110.6000","2.2104","3.77102","0.00866"
"110.8000","2.2146","3.77203","0.00867"
"111.0000","2.2187","3.77223","0.00869"
"111.2000","2.2225","3.77129","0.00870"
"111.4000","2.2267","3.77286","0.00871"
"111.6000","2.2306","3.77121","0.00872"
"111.8000","2.2343","3.77018","0.00873"
"112.0000","2.2385","3.77183","0.00874"
"112.2000","2.2425","3.77137","0.00875"
"112.4000","2.2466","3.77202","0.00876"
"112.6000","2.2505","3.77176","0.00877"
"112.8000","2.2546","3.77194","0.00877"
"113.0000","2.2586","3.77147","0.00878"
"113.2000","2.2625","3.77048","0.00879"
"113.4000","2.2664","3.77060","0.00880"
"113.6000","2.2706","3.77165","0.00881"
"113.8000","2.2747","3.77125","0.00882"
"114.0000","2.2784","3.77010","0.00883"
"114.2000","2.2827","3.77187","0.00884"
"114.4000","2.2865","3.76968","0.00884"
"114.6000","2.2903","3.76878","0.00885"
"114.8000","2.2945","3.77064","0.00886"
"115.0000","2.2986","3.76972","0.00887"
"115.2000","2.3026","3.76983","0.00887"
"115.4000","2.3066","3.76974","0.00888"
"115.6000","2.3106","3.76910","0.00889"
"115.8000","2.3145","3.76790","0.00889"
"116.0000","2.3185","3.76747","0.00890"
"116.2000","2.3224","3.76717","0.00891"
"116.4000","2.3265","3.76779","0.00891"
"116.6000","2.3306","3.76749","0.00892"
"116.8000","2.3344","3.76587","0.00892"
"117.0000","2.3386","3.76714","0.00893"
"117.2000","2.3426","3.76515","0.00893"
"117.4000","2.3464","3.76385","0.00893"
"117.6000","2.3506","3.76431","0.00894"
"117.8000","2.3546","3.76334","0.00894"
"118.0000","2.3586","3.76276","0.00895"
"118.2000","2.3625","3.76158","0.00895"
"118.4000","2.3666","3.76103","0.00896"
"118.6000","2.3705","3.75940","0.00896"
"118.8000","2.3744","3.75840","0.00896"
"119.0000","2.3784","3.75756","0.00897"
"119.2000","2.3826","3.75779","0.00897"
"119.4000","2.3867","3.75626","0.00897"
"119.6000","2.3904","3.75345","0.00897"
"119.8000","2.3946","3.75391","0.00898"
"120.0000","2.3985","3.75082","0.00897"
"120.2000","2.4024","3.74878","0.00898"
"120.4000","2.4065","3.74865","0.00898"
"120.6000","2.4106","3.74674","0.00898"
"120.8000","2.4145","3.74452","0.00898"
"121.0000","2.4185","3.74256","0.00898"
"121.2000","2.4226","3.74077","0.00898"
"121.4000","2.4265","3.73760","0.00898"
"121.6000","2.4306","3.73539","0.00898"
"121.8000","2.4345","3.73288","0.00898"
"122.0000","2.4386","3.73114","0.00898"
"122.2000","2.4427","3.72820","0.00898"
"122.4000","2.4464","3.72391","0.00897"
"122.6000","2.4506","3.72219","0.00897"
"122.8000","2.4545","3.71763","0.00897"
"123.0000","2.4584","3.71413","0.00897"
"123.2000","2.4624","3.71193","0.00896"
"123.4000","2.4666","3.70852","0.00896"
"123.6000","2.4706","3.70419","0.00896"
"123.8000","2.4745","3.69986","0.00895"
"124.0000","2.4786","3.69589","0.00895"
"124.2000","2.4825","3.69082","0.00895"
"124.4000","2.4865","3.68671","0.00894"
"124.6000","2.4904","3.68232","0.00894"
"124.8000","2.4946","3.67865","0.00894"
"125.0000","2.4986","3.67313","0.00893"
"125.2000","2.5023","3.66706","0.00893"
"125.4000","2.5066","3.66413","0.00892"
"125.6000","2.5106","3.65691","0.00891"
"125.8000","2.5145","3.65127","0.00891"
"126.0000","2.5185","3.64715","0.00891"
"126.2000","2.5227","3.64100","0.00890"
"126.4000","2.5265","3.63467","0.00889"
"126.6000","2.5305","3.62885","0.00889"
"126.8000","2.5346","3.62281","0.00888"
"127.0000","2.5385","3.61583","0.00888"
"127.2000","2.5426","3.61008","0.00887"
"127.4000","2.5464","3.60338","0.00887"
"127.6000","2.5506","3.59784","0.00886"
"127.8000","2.5547","3.59041","0.00885"
"128.0000","2.5585","3.58186","0.00884"
"128.2000","2.5626","3.57604","0.00884"
"128.4000","2.5666","3.56735","0.00883"
"128.6000","2.5705","3.56003","0.00882"
"128.8000","2.5744","3.55336","0.00882"
"129.0000","2.5786","3.54595","0.00881"
"129.2000","2.5824","3.53736","0.00880"
"129.4000","2.5864","3.52893","0.00880"
"129.6000","2.5906","3.52121","0.00879"
"129.8000","2.5945","3.51204","0.00878"
"130.0000","2.5986","3.50389","0.00877"
"130.2000","2.6025","3.49509","0.00876"
"130.4000","2.6066","3.48680","0.00876"
"130.6000","2.6106","3.47635","0.00875"
"130.8000","2.6144","3.46615","0.00873"
"131.0000","2.6185","3.45815","0.00873"
"131.2000","2.6226","3.44667","0.00872"
"131.4000","2.6265","3.43684","0.00871"
"131.6000","2.6304","3.42730","0.00870"
"131.8000","2.6347","3.41546","0.00869"
"132.0000","2.6385","3.40318","0.00868"
"132.2000","2.6425","3.39156","0.00867"
"132.4000","2.6466","3.37913","0.00866"
"132.6000","2.6505","3.36482","0.00864"
"132.8000","2.6546","3.35066","0.00863"
"133.0000","2.6585","3.33374","0.00861"
"133.2000","2.6625","3.31513","0.00859"
"133.4000","2.6666","3.29189","0.00857"
"133.6000","2.6704","3.26524","0.00855"
"133.8000","2.6744","3.23354","0.00852"
"134.0000","2.6787","3.17121","0.00847"
"134.2000","2.6826","3.11199","0.00841"
"134.4000","2.6865","3.01823","0.00833"
"134.4980","2.6887","2.86808","0.00819"
"134.5840","2.6905","2.71702","0.00806"
"134.6500","2.6918","2.56549","0.00791"
"134.6700","2.6922","2.41071","0.00778"
"134.6750","2.6923","2.25090","0.00763"