File: Coupon Test Data/Tensile Test_Neebajan_Alan_9.csv
Time,Displacement,Force,Strain 1
(s),(mm),(kN),(mm/mm)
"0.0000","0.0000","0.26391","-0.00016"
"0.4000","0.0063","0.34464","-0.00013"
"0.8000","0.0144","0.45499","-0.00008"
"1.2000","0.0224","0.56328","-0.00003"
"1.6000","0.0305","0.67065","0.00001"
"2.0000","0.0384","0.77399","0.00005"
"2.4000","0.0465","0.87900","0.00010"
"2.8000","0.0544","0.97767","0.00014"
"3.2000","0.0624","1.07515","0.00018"
"3.6000","0.0704","1.17425","0.00022"
"4.0000","0.0785","1.27226","0.00027"
"4.4000","0.0865","1.36705","0.00030"
"4.8000","0.0944","1.46000","0.00034"
"5.2000","0.1025","1.55429","0.00038"
"5.6000","0.1103","1.64360","0.00042"
"6.0000","0.1185","1.73661","0.00046"
"6.4000","0.1264","1.82616","0.00050"
"6.8000","0.1345","1.91515","0.00054"
"7.2000","0.1425","2.00262","0.00057"
"7.6000","0.1504","2.08248","0.00061"
"8.0000","0.1585","2.17130","0.00065"
"8.4000","0.1663","2.25385","0.00068"
"8.8000","0.1745","2.33925","0.00072"
"9.2000","0.1824","2.42187","0.00075"
"9.6000","0.1903","2.49767","0.00079"
"10.0000","0.1985","2.58226","0.00082"
"10.4000","0.2065","2.66375","0.00086"
"10.8000","0.2145","2.74370","0.00089"
"11.2000","0.2224","2.81988","0.00093"
"11.6000","0.2305","2.89747","0.00096"
"12.0000","0.2383","2.97000","0.00099"
"12.4000","0.2464","3.04762","0.00102"
"12.8000","0.2545","3.12251","0.00106"
"13.2000","0.2625","3.19544","0.00109"
"13.6000","0.2705","3.26669","0.00112"
"14.0000","0.2782","3.32650","0.00114"
"14.4000","0.2865","3.39746","0.00117"
"14.8000","0.2944","3.46192","0.00120"
"15.2000","0.3024","3.52430","0.00123"
"15.6000","0.3105","3.58900","0.00126"
"16.0000","0.3185","3.64940","0.00129"
"16.4000","0.3265","3.70548","0.00131"
"16.8000","0.3344","3.76334","0.00134"
"17.2000","0.3426","3.82440","0.00136"
"17.6000","0.3504","3.87478","0.00139"
"18.0000","0.3583","3.91957","0.00141"
"18.4000","0.3665","3.97054","0.00143"
"18.8000","0.3746","4.01661","0.00145"
"19.2000","0.3825","4.06859","0.00148"
"19.6000","0.3903","4.12023","0.00150"
"20.0000","0.3986","4.17631","0.00153"
"20.4000","0.4063","4.22578","0.00155"
"20.8000","0.4144","4.27319","0.00157"
"21.2000","0.4225","4.32328","0.00159"
"21.6000","0.4306","4.36927","0.00161"
"22.0000","0.4384","4.42244","0.00164"
"22.4000","0.4463","4.46916","0.00166"
"22.8000","0.4546","4.52598","0.00168"
"23.2000","0.4623","4.57823","0.00171"
"23.6000","0.4704","4.63229","0.00173"
"24.0000","0.4785","4.68489","0.00176"
"24.4000","0.4865","4.74005","0.00178"
"24.8000","0.4944","4.79077","0.00181"
"25.2000","0.5024","4.84264","0.00183"
"25.6000","0.5107","4.89977","0.00186"
"26.0000","0.5183","4.94288","0.00188"
"26.4000","0.5263","5.00000","0.00190"
"26.8000","0.5345","5.05819","0.00193"
"27.2000","0.5426","5.11336","0.00196"
"27.6000","0.5504","5.16484","0.00198"
"28.0000","0.5584","5.21782","0.00201"
"28.4000","0.5666","5.27413","0.00204"
"28.8000","0.5742","5.32290","0.00206"
"29.2000","0.5824","5.37793","0.00208"
"29.6000","0.5905","5.43142","0.00211"
"30.0000","0.5986","5.48115","0.00213"
"30.4000","0.6064","5.52828","0.00215"
"30.8000","0.6144","5.57895","0.00218"
"31.2000","0.6227","5.63429","0.00221"
"31.6000","0.6303","5.67948","0.00223"
"32.0000","0.6384","5.73043","0.00225"
"32.4000","0.6465","5.78284","0.00228"
"32.8000","0.6545","5.83186","0.00231"
"33.2000","0.6624","5.87986","0.00233"
"33.6000","0.6705","5.93082","0.00235"
"34.0000","0.6787","5.98519","0.00238"
"34.4000","0.6862","6.03171","0.00240"
"34.8000","0.6944","6.08469","0.00243"
"35.2000","0.7025","6.13771","0.00246"
"35.6000","0.7106","6.18916","0.00249"
"36.0000","0.7184","6.23649","0.00251"
"36.4000","0.7265","6.28636","0.00254"
"36.8000","0.7347","6.33830","0.00256"
"37.2000","0.7422","6.38131","0.00259"
"37.6000","0.7504","6.43399","0.00261"
"38.0000","0.7585","6.48553","0.00264"
"38.4000","0.7665","6.53380","0.00267"
"38.8000","0.7743","6.58292","0.00270"
"39.2000","0.7825","6.63372","0.00273"
"39.6000","0.7907","6.68494","0.00275"
"40.0000","0.7983","6.72812","0.00278"
"40.4000","0.8065","6.78043","0.00281"
"40.8000","0.8145","6.82862","0.00284"
"41.2000","0.8224","6.87413","0.00287"
"41.6000","0.8303","6.92001","0.00290"
"42.0000","0.8386","6.96850","0.00293"
"42.4000","0.8467","7.01527","0.00296"
"42.8000","0.8542","7.05444","0.00299"
"43.2000","0.8625","7.10069","0.00303"
"43.6000","0.8704","7.14427","0.00306"
"44.0000","0.8784","7.18688","0.00310"
"44.4000","0.8864","7.22813","0.00313"
"44.8000","0.8946","7.27176","0.00317"
"45.2000","0.9026","7.31210","0.00322"
"45.6000","0.9102","7.34523","0.00326"
"46.0000","0.9185","7.38350","0.00331"
"46.4000","0.9265","7.41600","0.00335"
"46.8000","0.9344","7.44660","0.00340"
"47.2000","0.9423","7.47558","0.00345"
"47.6000","0.9505","7.50304","0.00351"
"48.0000","0.9586","7.52867","0.00357"
"48.4000","0.9663","7.54564","0.00363"
"48.8000","0.9746","7.56799","0.00369"
"49.2000","0.9824","7.58559","0.00376"
"49.6000","0.9904","7.59908","0.00383"
"50.0000","0.9983","7.61556","0.00389"
"50.4000","1.0066","7.63111","0.00397"
"50.8000","1.0146","7.64452","0.00405"
"51.2000","1.0223","7.65234","0.00412"
"51.6000","1.0306","7.66558","0.00420"
"52.0000","1.0383","7.67291","0.00428"
"52.4000","1.0465","7.68163","0.00436"
"52.8000","1.0544","7.68979","0.00444"
"53.2000","1.0626","7.69862","0.00452"
"53.6000","1.0706","7.70676","0.00460"
"54.0000","1.0783","7.70952","0.00469"
"54.4000","1.0866","7.71977","0.00477"
"54.8000","1.0944","7.72371","0.00486"
"55.2000","1.1025","7.72831","0.00494"
"55.6000","1.1104","7.73427","0.00503"
"56.0000","1.1185","7.74048","0.00511"
"56.4000","1.1265","7.74594","0.00520"
"56.8000","1.1344","7.74806","0.00529"
"57.2000","1.1427","7.75489","0.00538"
"57.6000","1.1503","7.75564","0.00546"
"58.0000","1.1584","7.76011","0.00555"
"58.4000","1.1663","7.76421","0.00564"
"58.8000","1.1746","7.76911","0.00573"
"59.2000","1.1825","7.77277","0.00582"
"59.6000","1.1904","7.77394","0.00592"
"60.0000","1.1987","7.78073","0.00601"
"60.4000","1.2063","7.78063","0.00609"
"60.8000","1.2145","7.78471","0.00619"
"61.2000","1.2225","7.78836","0.00628"
"61.6000","1.2306","7.79139","0.00637"
"62.0000","1.2384","7.79394","0.00646"
"62.4000","1.2464","7.79633","0.00655"
"62.8000","1.2546","7.80167","0.00664"
"63.2000","1.2624","7.80065","0.00673"
"63.6000","1.2705","7.80388","0.00682"
"64.0000","1.2783","7.79969","0.00691"
"64.4000","1.2865","7.80858","0.00699"
"64.8000","1.2944","7.81247","0.00708"
"65.2000","1.3025","7.81372","0.00717"
"65.6000","1.3107","7.81844","0.00727"
"66.0000","1.3184","7.81723","0.00736"
"66.4000","1.3265","7.82017","0.00745"
"66.8000","1.3343","7.82210","0.00754"
"67.2000","1.3425","7.82592","0.00764"
"67.6000","1.3504","7.82675","0.00773"
"68.0000","1.3585","7.82915","0.00782"
"68.4000","1.3666","7.83331","0.00792"
"68.8000","1.3743","7.83217","0.00801"
"69.2000","1.3825","7.83629","0.00810"
"69.6000","1.3904","7.83667","0.00820"
"70.0000","1.3985","7.83998","0.00829"
"70.4000","1.4064","7.84166","0.00838"
"70.8000","1.4145","7.84296","0.00848"
"71.2000","1.4227","7.84860","0.00857"
"71.6000","1.4304","7.84635","0.00867"
"72.0000","1.4386","7.84952","0.00876"
"72.4000","1.4464","7.85030","0.00885"
"72.8000","1.4544","7.84063","0.00894"
"73.2000","1.4623","7.84818","0.00901"
"73.6000","1.4706","7.85794","0.00910"
"74.0000","1.4786","7.86081","0.00919"
"74.4000","1.4865","7.86053","0.00928"
"74.8000","1.4945","7.86293","0.00938"
"75.2000","1.5023","7.86189","0.00947"
"75.6000","1.5106","7.86693","0.00957"
"76.0000","1.5184","7.86700","0.00966"
"76.4000","1.5265","7.86844","0.00976"
"76.8000","1.5346","7.87271","0.00985"
"77.2000","1.5424","7.87135","0.00994"
"77.6000","1.5506","7.87525","0.01004"
"78.0000","1.5584","7.87450","0.01013"
"78.4000","1.5665","7.87757","0.01023"
"78.8000","1.5744","7.87920","0.01032"
"79.2000","1.5824","7.88028","0.01041"
"79.6000","1.5905","7.88431","0.01051"
"80.0000","1.5985","7.88499","0.01060"
"80.4000","1.6066","7.88659","0.01070"
"80.8000","1.6144","7.88558","0.01079"
"81.2000","1.6225","7.89009","0.01089"
"81.6000","1.6302","7.89013","0.01098"
"82.0000","1.6386","7.89336","0.01107"
"82.4000","1.6466","7.89617","0.01117"
"82.8000","1.6545","7.89580","0.01126"
"83.2000","1.6626","7.89908","0.01135"
"83.6000","1.6703","7.89766","0.01144"
"84.0000","1.6785","7.90189","0.01154"
"84.4000","1.6864","7.90295","0.01163"
"84.8000","1.6945","7.90377","0.01173"
"85.2000","1.7025","7.90710","0.01182"
"85.6000","1.7105","7.90837","0.01191"
"86.0000","1.7185","7.91044","0.01201"
"86.4000","1.7264","7.90979","0.01210"
"86.8000","1.7346","7.91373","0.01219"
"87.2000","1.7423","7.91275","0.01229"
"87.6000","1.7505","7.91502","0.01238"
"88.0000","1.7584","7.90831","0.01246"
"88.4000","1.7665","7.91693","0.01255"
"88.8000","1.7746","7.92193","0.01264"
"89.2000","1.7823","7.92111","0.01273"
"89.6000","1.7905","7.92536","0.01283"
"90.0000","1.7983","7.92447","0.01292"
"90.4000","1.8065","7.92652","0.01303"
"90.8000","1.8145","7.92962","0.01312"
"91.2000","1.8225","7.93055","0.01321"
"91.6000","1.8305","7.93174","0.01330"
"92.0000","1.8384","7.93188","0.01340"
"92.4000","1.8466","7.93667","0.01349"
"92.8000","1.8544","7.93481","0.01358"
"93.2000","1.8625","7.93702","0.01368"
"93.6000","1.8704","7.93998","0.01377"
"94.0000","1.8784","7.94093","0.01386"
"94.4000","1.8865","7.94369","0.01395"
"94.8000","1.8944","7.94309","0.01405"
"95.2000","1.9026","7.94724","0.01414"
"95.6000","1.9103","7.94559","0.01423"
"96.0000","1.9185","7.94795","0.01433"
"96.4000","1.9264","7.95075","0.01442"
"96.8000","1.9345","7.95266","0.01451"
"97.2000","1.9425","7.95380","0.01460"
"97.6000","1.9505","7.95387","0.01470"
"98.0000","1.9585","7.95779","0.01479"
"98.4000","1.9662","7.95556","0.01488"
"98.8000","1.9746","7.95955","0.01498"
"99.2000","1.9825","7.96180","0.01507"
"99.6000","1.9905","7.96213","0.01516"
"100.0000","1.9986","7.96491","0.01525"
"100.4000","2.0064","7.96522","0.01534"
"100.8000","2.0145","7.96898","0.01544"
"101.2000","2.0223","7.96730","0.01553"
"101.6000","2.0306","7.97000","0.01562"
"102.0000","2.0384","7.97170","0.01571"
"102.4000","2.0464","7.97278","0.01581"
"102.8000","2.0545","7.97578","0.01590"
"103.2000","2.0626","7.97634","0.01599"
"103.6000","2.0706","7.97928","0.01609"
"104.0000","2.0783","7.97649","0.01618"
"104.4000","2.0865","7.98057","0.01627"
"104.8000","2.0943","7.98195","0.01636"
"105.2000","2.1024","7.98306","0.01645"
"105.6000","2.1106","7.98622","0.01654"
"106.0000","2.1186","7.98714","0.01664"
"106.4000","2.1265","7.98907","0.01673"
"106.8000","2.1343","7.98760","0.01682"
"107.2000","2.1426","7.99187","0.01691"
"107.6000","2.1504","7.99225","0.01700"
"108.0000","2.1584","7.99314","0.01709"
"108.4000","2.1665","7.99566","0.01719"
"108.8000","2.1745","7.99752","0.01728"
"109.2000","2.1825","7.99977","0.01737"
"109.6000","2.1903","7.99790","0.01746"
"110.0000","2.1987","8.00268","0.01755"
"110.4000","2.2063","8.00182","0.01764"
"110.8000","2.2143","8.00277","0.01773"
"111.2000","2.2225","8.00722","0.01782"
"111.6000","2.2306","8.00881","0.01791"
"112.0000","2.2385","8.00912","0.01801"
"112.4000","2.2464","8.00826","0.01809"
"112.8000","2.2546","8.01295","0.01819"
"113.2000","2.2622","8.01174","0.01828"
"113.6000","2.2704","8.01391","0.01837"
"114.0000","2.2785","8.01686","0.01846"
"114.4000","2.2866","8.01852","0.01855"
"114.8000","2.2944","8.01950","0.01864"
"115.2000","2.3023","8.01851","0.01873"
"115.6000","2.3107","8.02424","0.01882"
"116.0000","2.3183","8.02209","0.01891"
"116.4000","2.3264","8.02326","0.01900"
"116.8000","2.3345","8.02699","0.01909"
"117.2000","2.3425","8.02844","0.01918"
"117.6000","2.3504","8.02936","0.01927"
"118.0000","2.3585","8.02936","0.01936"
"118.4000","2.3667","8.03388","0.01945"
"118.8000","2.3742","8.03093","0.01954"
"119.2000","2.3823","8.03323","0.01963"
"119.6000","2.3905","8.03685","0.01972"
"120.0000","2.3986","8.03891","0.01981"
"120.4000","2.4064","8.03895","0.01990"
"120.8000","2.4145","8.03906","0.01999"
"121.2000","2.4227","8.04432","0.02009"
"121.6000","2.4302","8.04070","0.02017"
"122.0000","2.4384","8.04362","0.02026"
"122.4000","2.4466","8.04684","0.02036"
"122.8000","2.4545","8.03996","0.02043"
"123.2000","2.4623","8.04656","0.02051"
"123.6000","2.4704","8.05019","0.02060"
"124.0000","2.4787","8.05497","0.02070"
"124.4000","2.4863","8.05099","0.02078"
"124.8000","2.4945","8.05391","0.02087"
"125.2000","2.5025","8.05633","0.02096"
"125.6000","2.5105","8.05739","0.02105"
"126.0000","2.5183","8.05813","0.02114"
"126.4000","2.5265","8.06010","0.02123"
"126.8000","2.5348","8.06450","0.02132"
"127.2000","2.5422","8.05964","0.02141"
"127.6000","2.5504","8.06295","0.02150"
"128.0000","2.5585","8.06644","0.02159"
"128.4000","2.5665","8.06676","0.02168"
"128.8000","2.5744","8.06739","0.02177"
"129.2000","2.5826","8.07001","0.02186"
"129.6000","2.5907","8.07322","0.02195"
"130.0000","2.5982","8.06950","0.02204"
"130.4000","2.6065","8.07346","0.02213"
"130.8000","2.6145","8.07550","0.02222"
"131.2000","2.6225","8.07644","0.02231"
"131.6000","2.6303","8.07661","0.02240"
"132.0000","2.6385","8.07932","0.02249"
"132.4000","2.6467","8.08362","0.02257"
"132.8000","2.6542","8.07897","0.02266"
"133.2000","2.6626","8.08294","0.02275"
"133.6000","2.6705","8.08460","0.02284"
"134.0000","2.6784","8.08492","0.02293"
"134.4000","2.6864","8.08685","0.02302"
"134.8000","2.6946","8.08824","0.02311"
"135.2000","2.7027","8.07985","0.02317"
"135.6000","2.7103","8.08665","0.02325"
"136.0000","2.7185","8.09347","0.02334"
"136.4000","2.7264","8.09469","0.02342"
"136.8000","2.7345","8.09600","0.02352"
"137.2000","2.7424","8.09614","0.02360"
"137.6000","2.7506","8.09897","0.02369"
"138.0000","2.7586","8.10155","0.02378"
"138.4000","2.7662","8.09789","0.02387"
"138.8000","2.7746","8.10293","0.02396"
"139.2000","2.7825","8.10368","0.02405"
"139.6000","2.7905","8.10376","0.02414"
"140.0000","2.7984","8.10477","0.02423"
"140.4000","2.8065","8.10785","0.02432"
"140.8000","2.8145","8.11023","0.02440"
"141.2000","2.8224","8.10829","0.02449"
"141.6000","2.8306","8.11216","0.02458"
"142.0000","2.8384","8.11118","0.02467"
"142.4000","2.8464","8.11267","0.02476"
"142.8000","2.8543","8.11388","0.02485"
"143.2000","2.8626","8.11724","0.02494"
"143.6000","2.8705","8.11861","0.02502"
"144.0000","2.8784","8.11684","0.02511"
"144.4000","2.8866","8.12119","0.02520"
"144.8000","2.8943","8.12041","0.02529"
"145.2000","2.9024","8.12233","0.02538"
"145.6000","2.9105","8.12370","0.02547"
"146.0000","2.9186","8.12594","0.02556"
"146.4000","2.9265","8.12663","0.02565"
"146.8000","2.9344","8.12653","0.02574"
"147.2000","2.9426","8.13096","0.02583"
"147.6000","2.9504","8.12949","0.02592"
"148.0000","2.9585","8.13124","0.02601"
"148.4000","2.9664","8.13195","0.02609"
"148.8000","2.9745","8.13474","0.02618"
"149.2000","2.9825","8.13654","0.02627"
"149.6000","2.9905","8.13601","0.02636"
"150.0000","2.9987","8.14029","0.02645"
"150.4000","3.0063","8.13783","0.02654"
"150.8000","3.0144","8.13959","0.02662"
"151.2000","3.0224","8.14140","0.02671"
"151.6000","3.0306","8.14390","0.02680"
"152.0000","3.0385","8.14462","0.02689"
"152.4000","3.0465","8.14503","0.02698"
"152.8000","3.0546","8.14841","0.02707"
"153.2000","3.0623","8.14676","0.02715"
"153.6000","3.0705","8.14967","0.02724"
"154.0000","3.0784","8.15006","0.02733"
"154.4000","3.0866","8.15268","0.02742"
"154.8000","3.0944","8.15318","0.02751"
"155.2000","3.1025","8.15368","0.02759"
"155.6000","3.1107","8.15843","0.02768"
"156.0000","3.1184","8.15599","0.02777"
"156.4000","3.1265","8.15804","0.02786"
"156.8000","3.1344","8.15881","0.02794"
"157.2000","3.1425","8.16071","0.02803"
"157.6000","3.1504","8.16199","0.02812"
"158.0000","3.1586","8.16374","0.02821"
"158.4000","3.1666","8.16630","0.02830"
"158.8000","3.1744","8.16472","0.02839"
"159.2000","3.1825","8.16696","0.02847"
"159.6000","3.1903","8.16672","0.02856"
"160.0000","3.1985","8.17040","0.02865"
"160.4000","3.2064","8.17048","0.02874"
"160.8000","3.2145","8.17144","0.02882"
"161.2000","3.2226","8.17503","0.02891"
"161.6000","3.2303","8.17318","0.02900"
"162.0000","3.2385","8.17613","0.02909"
"162.4000","3.2464","8.16425","0.02916"
"162.8000","3.2545","8.17498","0.02924"
"163.2000","3.2624","8.17810","0.02933"
"163.6000","3.2705","8.18035","0.02942"
"164.0000","3.2786","8.18424","0.02950"
"164.4000","3.2865","8.18271","0.02959"
"164.8000","3.2946","8.18516","0.02968"
"165.2000","3.3023","8.18377","0.02977"
"165.6000","3.3105","8.18708","0.02985"
"166.0000","3.3183","8.18718","0.02994"
"166.4000","3.3265","8.18889","0.03003"
"166.8000","3.3346","8.19212","0.03012"
"167.2000","3.3424","8.19075","0.03020"
"167.6000","3.3506","8.19288","0.03029"
"168.0000","3.3583","8.19194","0.03038"
"168.4000","3.3665","8.19533","0.03047"
"168.8000","3.3744","8.19529","0.03055"
"169.2000","3.3825","8.19672","0.03065"
"169.6000","3.3905","8.19965","0.03073"
"170.0000","3.3984","8.19919","0.03082"
"170.4000","3.4066","8.20191","0.03091"
"170.8000","3.4144","8.20002","0.03099"
"171.2000","3.4226","8.20376","0.03109"
"171.6000","3.4303","8.20282","0.03117"
"172.0000","3.4384","8.20406","0.03126"
"172.4000","3.4465","8.20814","0.03135"
"172.8000","3.4545","8.20784","0.03143"
"173.2000","3.4626","8.20916","0.03152"
"173.6000","3.4704","8.20808","0.03161"
"174.0000","3.4785","8.21130","0.03170"
"174.4000","3.4863","8.21091","0.03178"
"174.8000","3.4945","8.21317","0.03187"
"175.2000","3.5025","8.21537","0.03196"
"175.6000","3.5106","8.21609","0.03205"
"176.0000","3.5186","8.21715","0.03214"
"176.4000","3.5263","8.21560","0.03222"
"176.8000","3.5346","8.22041","0.03231"
"177.2000","3.5424","8.21896","0.03240"
"177.6000","3.5505","8.21997","0.03249"
"178.0000","3.5585","8.22299","0.03257"
"178.4000","3.5664","8.22347","0.03266"
"178.8000","3.5745","8.22555","0.03275"
"179.2000","3.5824","8.22439","0.03284"
"179.6000","3.5906","8.22795","0.03292"
"180.0000","3.5983","8.22639","0.03301"
"180.4000","3.6065","8.22812","0.03310"
"180.8000","3.6144","8.23081","0.03319"
"181.2000","3.6226","8.23233","0.03328"
"181.6000","3.6306","8.23298","0.03336"
"182.0000","3.6384","8.23162","0.03345"
"182.4000","3.6466","8.23555","0.03354"
"182.8000","3.6542","8.23346","0.03362"
"183.2000","3.6625","8.23633","0.03371"
"183.6000","3.6705","8.23847","0.03380"
"184.0000","3.6785","8.23836","0.03389"
"184.4000","3.6866","8.24085","0.03397"
"184.8000","3.6944","8.23982","0.03406"
"185.2000","3.7026","8.24352","0.03415"
"185.6000","3.7104","8.24200","0.03423"
"186.0000","3.7185","8.24380","0.03432"
"186.4000","3.7264","8.24540","0.03441"
"186.8000","3.7345","8.24654","0.03450"
"187.2000","3.7425","8.24798","0.03459"
"187.6000","3.7505","8.24815","0.03467"
"188.0000","3.7586","8.25151","0.03476"
"188.4000","3.7663","8.24810","0.03485"
"188.8000","3.7745","8.25128","0.03494"
"189.2000","3.7824","8.25307","0.03502"
"189.6000","3.7905","8.25374","0.03511"
"190.0000","3.7986","8.25603","0.03520"
"190.4000","3.8065","8.25527","0.03528"
"190.8000","3.8146","8.25810","0.03537"
"191.2000","3.8222","8.25600","0.03546"
"191.6000","3.8305","8.25917","0.03555"
"192.0000","3.8385","8.26074","0.03564"
"192.4000","3.8464","8.26083","0.03572"
"192.8000","3.8545","8.26194","0.03581"
"193.2000","3.8625","8.26360","0.03590"
"193.6000","3.8705","8.26562","0.03599"
"194.0000","3.8783","8.26283","0.03607"
"194.4000","3.8867","8.26757","0.03616"
"194.8000","3.8943","8.26652","0.03625"
"195.2000","3.9024","8.26690","0.03633"
"195.6000","3.9105","8.27074","0.03642"
"196.0000","3.9185","8.27083","0.03651"
"196.4000","3.9266","8.27282","0.03660"
"196.8000","3.9343","8.27020","0.03669"
"197.2000","3.9426","8.27359","0.03677"
"197.6000","3.9504","8.27421","0.03686"
"198.0000","3.9584","8.27444","0.03695"
"198.4000","3.9665","8.27672","0.03704"
"198.8000","3.9746","8.27877","0.03713"
"199.2000","3.9824","8.27890","0.03721"
"199.6000","3.9903","8.27714","0.03730"
"200.0000","3.9987","8.28249","0.03739"
"200.4000","4.0063","8.28040","0.03747"
"200.8000","4.0144","8.28120","0.03756"
"201.2000","4.0225","8.28410","0.03765"
"201.6000","4.0305","8.28501","0.03773"
"202.0000","4.0385","8.28637","0.03782"
"202.4000","4.0464","8.28483","0.03791"
"202.8000","4.0547","8.28869","0.03800"
"203.2000","4.0623","8.28683","0.03808"
"203.6000","4.0703","8.28757","0.03817"
"204.0000","4.0785","8.29088","0.03826"
"204.4000","4.0866","8.29263","0.03835"
"204.8000","4.0945","8.29263","0.03843"
"205.2000","4.1024","8.29152","0.03852"
"205.6000","4.1107","8.29570","0.03861"
"206.0000","4.1182","8.29288","0.03870"
"206.4000","4.1264","8.29506","0.03879"
"206.8000","4.1346","8.29785","0.03887"
"207.2000","4.1426","8.29842","0.03896"
"207.6000","4.1504","8.28620","0.03904"
"208.0000","4.1584","8.29306","0.03912"
"208.4000","4.1667","8.30192","0.03920"
"208.8000","4.1743","8.29992","0.03929"
"209.2000","4.1824","8.30184","0.03938"
"209.6000","4.1905","8.30442","0.03946"
"210.0000","4.1986","8.30553","0.03955"
"210.4000","4.2064","8.30560","0.03964"
"210.8000","4.2145","8.30559","0.03972"
"211.2000","4.2228","8.31037","0.03981"
"211.6000","4.2302","8.30526","0.03990"
"212.0000","4.2384","8.30730","0.03999"
"212.4000","4.2465","8.31086","0.04007"
"212.8000","4.2545","8.29505","0.04013"
"213.2000","4.2624","8.30690","0.04021"
"213.6000","4.2705","8.31185","0.04030"
"214.0000","4.2787","8.31669","0.04038"
"214.4000","4.2862","8.31297","0.04047"
"214.8000","4.2944","8.31552","0.04056"
"215.2000","4.3025","8.31750","0.04064"
"215.6000","4.3106","8.31835","0.04073"
"216.0000","4.3183","8.31733","0.04082"
"216.4000","4.3265","8.31861","0.04090"
"216.8000","4.3347","8.32345","0.04099"
"217.2000","4.3422","8.31791","0.04108"
"217.6000","4.3505","8.32075","0.04117"
"218.0000","4.3585","8.32311","0.04126"
"218.4000","4.3664","8.32238","0.04134"
"218.8000","4.3743","8.32317","0.04143"
"219.2000","4.3826","8.32554","0.04152"
"219.6000","4.3907","8.32802","0.04161"
"220.0000","4.3982","8.32302","0.04169"
"220.4000","4.4065","8.32650","0.04178"
"220.8000","4.4144","8.32791","0.04187"
"221.2000","4.4225","8.32928","0.04196"
"221.6000","4.4304","8.32877","0.04204"
"222.0000","4.4386","8.33087","0.04213"
"222.4000","4.4467","8.33367","0.04222"
"222.8000","4.4542","8.32843","0.04231"
"223.2000","4.4625","8.33289","0.04239"
"223.6000","4.4705","8.33453","0.04248"
"224.0000","4.4785","8.33387","0.04257"
"224.4000","4.4864","8.33423","0.04266"
"224.8000","4.4946","8.33664","0.04275"
"225.2000","4.5026","8.33914","0.04284"
"225.6000","4.5103","8.33541","0.04292"
"226.0000","4.5186","8.33869","0.04301"
"226.4000","4.5264","8.33867","0.04310"
"226.8000","4.5344","8.33904","0.04318"
"227.2000","4.5423","8.33995","0.04327"
"227.6000","4.5506","8.34276","0.04336"
"228.0000","4.5587","8.34457","0.04345"
"228.4000","4.5663","8.34031","0.04353"
"228.8000","4.5745","8.34448","0.04363"
"229.2000","4.5824","8.34440","0.04371"
"229.6000","4.5904","8.34498","0.04380"
"230.0000","4.5984","8.34564","0.04389"
"230.4000","4.6066","8.34837","0.04398"
"230.8000","4.6145","8.34884","0.04406"
"231.2000","4.6223","8.34661","0.04415"
"231.6000","4.6306","8.35095","0.04424"
"232.0000","4.6384","8.34966","0.04433"
"232.4000","4.6465","8.35036","0.04442"
"232.8000","4.6544","8.35069","0.04451"
"233.2000","4.6625","8.35305","0.04459"
"233.6000","4.6705","8.35466","0.04468"
"234.0000","4.6784","8.35190","0.04477"
"234.4000","4.6866","8.35579","0.04486"
"234.8000","4.6944","8.35453","0.04495"
"235.2000","4.7024","8.35494","0.04503"
"235.6000","4.7104","8.35645","0.04512"
"236.0000","4.7186","8.35911","0.04521"
"236.4000","4.7265","8.35909","0.04530"
"236.8000","4.7344","8.35761","0.04539"
"237.2000","4.7426","8.36118","0.04548"
"237.6000","4.7503","8.35913","0.04556"
"238.0000","4.7585","8.36113","0.04565"
"238.4000","4.7664","8.36123","0.04574"
"238.8000","4.7746","8.36355","0.04583"
"239.2000","4.7825","8.36393","0.04592"
"239.6000","4.7904","8.36273","0.04601"
"240.0000","4.7987","8.36711","0.04610"
"240.4000","4.8064","8.36453","0.04618"
"240.8000","4.8145","8.36576","0.04627"
"241.2000","4.8224","8.36613","0.04636"
"241.6000","4.8305","8.36766","0.04645"
"242.0000","4.8384","8.36857","0.04654"
"242.4000","4.8465","8.36906","0.04663"
"242.8000","4.8547","8.37153","0.04671"
"243.2000","4.8624","8.36879","0.04680"
"243.6000","4.8705","8.37080","0.04689"
"244.0000","4.8783","8.37058","0.04698"
"244.4000","4.8866","8.37351","0.04707"
"244.8000","4.8944","8.37337","0.04715"
"245.2000","4.9025","8.37345","0.04724"
"245.6000","4.9107","8.37686","0.04733"
"246.0000","4.9183","8.37374","0.04741"
"246.4000","4.9265","8.37605","0.04751"
"246.8000","4.9344","8.37604","0.04760"
"247.2000","4.9425","8.37770","0.04768"
"247.6000","4.9504","8.37736","0.04777"
"248.0000","4.9585","8.37837","0.04786"
"248.4000","4.9666","8.38147","0.04795"
"248.8000","4.9744","8.37892","0.04804"
"249.2000","4.9825","8.38076","0.04813"
"249.6000","4.9903","8.37958","0.04821"
"250.0000","4.9985","8.38189","0.04830"
"250.4000","5.0063","8.38204","0.04839"
"250.8000","5.0146","8.38313","0.04848"
"251.2000","5.0227","8.38574","0.04857"
"251.6000","5.0304","8.38340","0.04865"
"252.0000","5.0385","8.38530","0.04874"
"252.4000","5.0463","8.38433","0.04883"
"252.8000","5.0545","8.38669","0.04892"
"253.2000","5.0624","8.38642","0.04901"
"253.6000","5.0706","8.38744","0.04910"
"254.0000","5.0786","8.38927","0.04919"
"254.4000","5.0863","8.38763","0.04927"
"254.8000","5.0946","8.39057","0.04936"
"255.2000","5.1024","8.38861","0.04945"
"255.6000","5.1106","8.39115","0.04954"
"256.0000","5.1184","8.39027","0.04963"
"256.4000","5.1265","8.39108","0.04972"
"256.8000","5.1346","8.39471","0.04981"
"257.2000","5.1424","8.39250","0.04989"
"257.6000","5.1506","8.39431","0.04998"
"258.0000","5.1583","8.39264","0.05007"
"258.4000","5.1665","8.39472","0.05016"
"258.8000","5.1743","8.39420","0.05025"
"259.2000","5.1825","8.39627","0.05034"
"259.6000","5.1906","8.39807","0.05043"
"260.0000","5.1985","8.39690","0.05052"
"260.4000","5.2066","8.39823","0.05061"
"260.8000","5.2143","8.39599","0.05069"
"261.2000","5.2226","8.39984","0.05078"
"261.6000","5.2304","8.39832","0.05087"
"262.0000","5.2385","8.39921","0.05096"
"262.4000","5.2465","8.40154","0.05105"
"262.8000","5.2544","8.40064","0.05114"
"263.2000","5.2626","8.40280","0.05123"
"263.6000","5.2704","8.40054","0.05132"
"264.0000","5.2785","8.40300","0.05140"
"264.4000","5.2864","8.40204","0.05149"
"264.8000","5.2944","8.40273","0.05158"
"265.2000","5.3025","8.40522","0.05167"
"265.6000","5.3106","8.40584","0.05176"
"266.0000","5.3186","8.40624","0.05185"
"266.4000","5.3263","8.40339","0.05194"
"266.8000","5.3345","8.39696","0.05201"
"267.2000","5.3423","8.40192","0.05209"
"267.6000","5.3505","8.40648","0.05218"
"268.0000","5.3586","8.40959","0.05227"
"268.4000","5.3665","8.40934","0.05236"
"268.8000","5.3746","8.41010","0.05245"
"269.2000","5.3823","8.40844","0.05254"
"269.6000","5.3906","8.41183","0.05263"
"270.0000","5.3984","8.41009","0.05272"
"270.4000","5.4065","8.41093","0.05281"
"270.8000","5.4145","8.41193","0.05290"
"271.2000","5.4225","8.41269","0.05299"
"271.6000","5.4305","8.41352","0.05308"
"272.0000","5.4384","8.41166","0.05316"
"272.4000","5.4466","8.41534","0.05326"
"272.8000","5.4543","8.41220","0.05334"
"273.2000","5.4625","8.41352","0.05343"
"273.6000","5.4704","8.41567","0.05352"
"274.0000","5.4785","8.41593","0.05361"
"274.4000","5.4866","8.41647","0.05370"
"274.8000","5.4944","8.41514","0.05379"
"275.2000","5.5025","8.41799","0.05388"
"275.6000","5.5103","8.41547","0.05397"
"276.0000","5.5185","8.41775","0.05406"
"276.4000","5.5264","8.41829","0.05415"
"276.8000","5.5345","8.41904","0.05424"
"277.2000","5.5425","8.41933","0.05433"
"277.6000","5.5504","8.41822","0.05441"
"278.0000","5.5586","8.42194","0.05450"
"278.4000","5.5663","8.41851","0.05459"
"278.8000","5.5746","8.42051","0.05468"
"279.2000","5.5824","8.42108","0.05477"
"279.6000","5.5904","8.42084","0.05486"
"280.0000","5.5985","8.42318","0.05495"
"280.4000","5.6065","8.42234","0.05504"
"280.8000","5.6146","8.42407","0.05513"
"281.2000","5.6223","8.42122","0.05522"
"281.6000","5.6305","8.42361","0.05531"
"282.0000","5.6383","8.42373","0.05539"
"282.4000","5.6465","8.42449","0.05548"
"282.8000","5.6545","8.42570","0.05557"
"283.2000","5.6625","8.42534","0.05566"
"283.6000","5.6705","8.42700","0.05575"
"284.0000","5.6782","8.42366","0.05584"
"284.4000","5.6866","8.42750","0.05593"
"284.8000","5.6944","8.42690","0.05602"
"285.2000","5.7024","8.42659","0.05611"
"285.6000","5.7105","8.42855","0.05619"
"286.0000","5.7185","8.42864","0.05629"
"286.4000","5.7265","8.42996","0.05637"
"286.8000","5.7344","8.42746","0.05646"
"287.2000","5.7426","8.43024","0.05655"
"287.6000","5.7503","8.42889","0.05664"
"288.0000","5.7584","8.42920","0.05673"
"288.4000","5.7665","8.43126","0.05682"
"288.8000","5.7746","8.43210","0.05691"
"289.2000","5.7826","8.43253","0.05700"
"289.6000","5.7903","8.42945","0.05709"
"290.0000","5.7986","8.43278","0.05718"
"290.4000","5.8063","8.43136","0.05726"
"290.8000","5.8144","8.43192","0.05735"
"291.2000","5.8226","8.43396","0.05745"
"291.6000","5.8306","8.43434","0.05754"
"292.0000","5.8384","8.43369","0.05762"
"292.4000","5.8463","8.43232","0.05771"
"292.8000","5.8547","8.43649","0.05780"
"293.2000","5.8623","8.43356","0.05789"
"293.6000","5.8704","8.43424","0.05798"
"294.0000","5.8785","8.43579","0.05807"
"294.4000","5.8866","8.43694","0.05816"
"294.8000","5.8945","8.43672","0.05824"
"295.2000","5.9024","8.43492","0.05833"
"295.6000","5.9108","8.43934","0.05843"
"296.0000","5.9182","8.43494","0.05851"
"296.4000","5.9263","8.43564","0.05860"
"296.8000","5.9345","8.43895","0.05869"
"297.2000","5.9426","8.43941","0.05878"
"297.6000","5.9505","8.43845","0.05887"
"298.0000","5.9584","8.43742","0.05896"
"298.4000","5.9666","8.44071","0.05905"
"298.8000","5.9742","8.43741","0.05913"
"299.2000","5.9824","8.43898","0.05922"
"299.6000","5.9905","8.44053","0.05931"
"300.0000","5.9986","8.44176","0.05940"
"300.4000","6.0063","8.44007","0.05949"
"300.8000","6.0144","8.43991","0.05958"
"301.2000","6.0228","8.44457","0.05967"
"301.6000","6.0302","8.43915","0.05975"
"302.0000","6.0385","8.44080","0.05984"
"302.4000","6.0465","8.44288","0.05993"
"302.8000","6.0545","8.44228","0.06002"
"303.2000","6.0624","8.44309","0.06011"
"303.6000","6.0705","8.44306","0.06020"
"304.0000","6.0787","8.44575","0.06029"
"304.4000","6.0863","8.44128","0.06038"
"304.8000","6.0944","8.44250","0.06047"
"305.2000","6.1025","8.44425","0.06055"
"305.6000","6.1106","8.44553","0.06064"
"306.0000","6.1184","8.44362","0.06073"
"306.4000","6.1266","8.44474","0.06082"
"306.8000","6.1347","8.44762","0.06091"
"307.2000","6.1421","8.44172","0.06099"
"307.6000","6.1505","8.44582","0.06109"
"308.0000","6.1585","8.44686","0.06118"
"308.4000","6.1665","8.44553","0.06127"
"308.8000","6.1744","8.44591","0.06136"
"309.2000","6.1825","8.44682","0.06145"
"309.6000","6.1907","8.44957","0.06154"
"310.0000","6.1983","8.44471","0.06162"
"310.4000","6.2065","8.44680","0.06171"
"310.8000","6.2145","8.44801","0.06180"
"311.2000","6.2224","8.44716","0.06189"
"311.6000","6.2303","8.44707","0.06198"
"312.0000","6.2387","8.44970","0.06207"
"312.4000","6.2467","8.45083","0.06216"
"312.8000","6.2542","8.44527","0.06224"
"313.2000","6.2625","8.44903","0.06233"
"313.6000","6.2704","8.44882","0.06242"
"314.0000","6.2785","8.44896","0.06251"
"314.4000","6.2864","8.44881","0.06259"
"314.8000","6.2946","8.45073","0.06269"
"315.2000","6.3026","8.45175","0.06277"
"315.6000","6.3102","8.44743","0.06286"
"316.0000","6.3185","8.45117","0.06295"
"316.4000","6.3265","8.45092","0.06304"
"316.8000","6.3345","8.45015","0.06313"
"317.2000","6.3423","8.44975","0.06321"
"317.6000","6.3506","8.45208","0.06331"
"318.0000","6.3586","8.45334","0.06339"
"318.4000","6.3663","8.44911","0.06348"
"318.8000","6.3746","8.45231","0.06357"
"319.2000","6.3824","8.45127","0.06366"
"319.6000","6.3904","8.45065","0.06375"
"320.0000","6.3983","8.45118","0.06383"
"320.4000","6.4066","8.45404","0.06392"
"320.8000","6.4146","8.45406","0.06401"
"321.2000","6.4223","8.45060","0.06410"
"321.6000","6.4306","8.45366","0.06419"
"322.0000","6.4383","8.45214","0.06428"
"322.4000","6.4465","8.45301","0.06437"
"322.8000","6.4544","8.45244","0.06445"
"323.2000","6.4626","8.45458","0.06454"
"323.6000","6.4705","8.45465","0.06463"
"324.0000","6.4783","8.45123","0.06472"
"324.4000","6.4866","8.45554","0.06481"
"324.8000","6.4944","8.45325","0.06489"
"325.2000","6.5024","8.45321","0.06498"
"325.6000","6.5104","8.45383","0.06507"
"326.0000","6.5185","8.45492","0.06516"
"326.4000","6.5265","8.45545","0.06525"
"326.8000","6.5345","8.45370","0.06534"
"327.2000","6.5427","8.45612","0.06543"
"327.6000","6.5504","8.45336","0.06551"
"328.0000","6.5584","8.45424","0.06560"
"328.4000","6.5663","8.45426","0.06569"
"328.8000","6.5746","8.45633","0.06578"
"329.2000","6.5825","8.45591","0.06587"
"329.6000","6.5904","8.45413","0.06596"
"330.0000","6.5986","8.45749","0.06605"
"330.4000","6.6063","8.45413","0.06613"
"330.8000","6.6145","8.45583","0.06622"
"331.2000","6.6224","8.45550","0.06631"
"331.6000","6.6305","8.45646","0.06640"
"332.0000","6.6384","8.45584","0.06648"
"332.4000","6.6464","8.45547","0.06657"
"332.8000","6.6546","8.45859","0.06666"
"333.2000","6.6624","8.45512","0.06675"
"333.6000","6.6705","8.45625","0.06684"
"334.0000","6.6784","8.45518","0.06692"
"334.4000","6.6865","8.45688","0.06701"
"334.8000","6.6944","8.45662","0.06710"
"335.2000","6.7025","8.45636","0.06718"
"335.6000","6.7107","8.45849","0.06727"
"336.0000","6.7184","8.45554","0.06736"
"336.4000","6.7265","8.45644","0.06745"
"336.8000","6.7344","8.45607","0.06753"
"337.2000","6.7425","8.45744","0.06762"
"337.6000","6.7504","8.45643","0.06771"
"338.0000","6.7585","8.45699","0.06779"
"338.4000","6.7666","8.45865","0.06788"
"338.8000","6.7743","8.45574","0.06797"
"339.2000","6.7826","8.45810","0.06806"
"339.6000","6.7904","8.45616","0.06814"
"340.0000","6.7986","8.45763","0.06823"
"340.4000","6.8064","8.45672","0.06832"
"340.8000","6.8145","8.45667","0.06840"
"341.2000","6.8226","8.45964","0.06849"
"341.6000","6.8304","8.45648","0.06857"
"342.0000","6.8385","8.45772","0.06866"
"342.4000","6.8464","8.45612","0.06875"
"342.8000","6.8545","8.45730","0.06884"
"343.2000","6.8623","8.45668","0.06892"
"343.6000","6.8706","8.45784","0.06901"
"344.0000","6.8786","8.45913","0.06909"
"344.4000","6.8864","8.45651","0.06918"
"344.8000","6.8946","8.45807","0.06927"
"345.2000","6.9023","8.45553","0.06935"
"345.6000","6.9105","8.45827","0.06944"
"346.0000","6.9184","8.45692","0.06952"
"346.4000","6.9265","8.45720","0.06961"
"346.8000","6.9346","8.45907","0.06969"
"347.2000","6.9424","8.45684","0.06978"
"347.6000","6.9506","8.45850","0.06986"
"348.0000","6.9584","8.45613","0.06995"
"348.4000","6.9665","8.45759","0.07003"
"348.8000","6.9744","8.45629","0.07012"
"349.2000","6.9825","8.45673","0.07020"
"349.6000","6.9905","8.45869","0.07029"
"350.0000","6.9985","8.45763","0.07038"
"350.4000","7.0066","8.45824","0.07046"
"350.8000","7.0143","8.45498","0.07054"
"351.2000","7.0225","8.45763","0.07063"
"351.6000","7.0303","8.45593","0.07071"
"352.0000","7.0385","8.45670","0.07080"
"352.4000","7.0466","8.45830","0.07088"
"352.8000","7.0545","8.45658","0.07097"
"353.2000","7.0626","8.45766","0.07105"
"353.6000","7.0703","8.45477","0.07113"
"354.0000","7.0785","8.45754","0.07122"
"354.4000","7.0864","8.45565","0.07130"
"354.8000","7.0945","8.45607","0.07139"
"355.2000","7.1025","8.45710","0.07147"
"355.6000","7.1105","8.45658","0.07155"
"356.0000","7.1186","8.45747","0.07164"
"356.4000","7.1264","8.45447","0.07172"
"356.8000","7.1346","8.45709","0.07181"
"357.2000","7.1423","8.45401","0.07189"
"357.6000","7.1504","8.45471","0.07197"
"358.0000","7.1585","8.45698","0.07205"
"358.4000","7.1666","8.45619","0.07213"
"358.8000","7.1746","8.45609","0.07222"
"359.2000","7.1824","8.45354","0.07230"
"359.6000","7.1905","8.45602","0.07238"
"360.0000","7.1983","8.45378","0.07246"
"360.4000","7.2065","8.45491","0.07255"
"360.8000","7.2145","8.45545","0.07263"
"361.2000","7.2226","8.45544","0.07271"
"361.6000","7.2306","8.45500","0.07279"
"362.0000","7.2383","8.45248","0.07287"
"362.4000","7.2466","8.45601","0.07295"
"362.8000","7.2543","8.45241","0.07303"
"363.2000","7.2625","8.45351","0.07311"
"363.6000","7.2704","8.45389","0.07319"
"364.0000","7.2784","8.45310","0.07327"
"364.4000","7.2866","8.45467","0.07335"
"364.8000","7.2945","8.45217","0.07343"
"365.2000","7.3026","8.45396","0.07351"
"365.6000","7.3103","8.45079","0.07359"
"366.0000","7.3185","8.45201","0.07367"
"366.4000","7.3264","8.45230","0.07375"
"366.8000","7.3345","8.45268","0.07383"
"367.2000","7.3425","8.45251","0.07391"
"367.6000","7.3505","8.45075","0.07399"
"368.0000","7.3586","8.45283","0.07406"
"368.4000","7.3662","8.44879","0.07414"
"368.8000","7.3746","8.45133","0.07422"
"369.2000","7.3825","8.45130","0.07430"
"369.6000","7.3905","8.45000","0.07438"
"370.0000","7.3985","8.45072","0.07445"
"370.4000","7.4064","8.44943","0.07453"
"370.8000","7.4146","8.45138","0.07461"
"371.2000","7.4224","8.44776","0.07468"
"371.6000","7.4306","8.44932","0.07476"
"372.0000","7.4384","8.44848","0.07483"
"372.4000","7.4464","8.44791","0.07491"
"372.8000","7.4545","8.44897","0.07498"
"373.2000","7.4626","8.44826","0.07506"
"373.6000","7.4706","8.44921","0.07513"
"374.0000","7.4783","8.44486","0.07520"
"374.4000","7.4866","8.44745","0.07528"
"374.8000","7.4943","8.44630","0.07536"
"375.2000","7.5024","8.44585","0.07543"
"375.6000","7.5106","8.44703","0.07550"
"376.0000","7.5185","8.44591","0.07558"
"376.4000","7.5265","8.44606","0.07565"
"376.8000","7.5343","8.44304","0.07572"
"377.2000","7.5426","8.44603","0.07579"
"377.6000","7.5504","8.44386","0.07587"
"378.0000","7.5584","8.44340","0.07594"
"378.4000","7.5665","8.44384","0.07601"
"378.8000","7.5745","8.44363","0.07608"
"379.2000","7.5825","8.44383","0.07615"
"379.6000","7.5903","8.44057","0.07622"
"380.0000","7.5987","8.44362","0.07629"
"380.4000","7.6063","8.44005","0.07636"
"380.8000","7.6143","8.43938","0.07643"
"381.2000","7.6225","8.44190","0.07650"
"381.6000","7.6306","8.44166","0.07657"
"382.0000","7.6385","8.43996","0.07664"
"382.4000","7.6464","8.43772","0.07671"
"382.8000","7.6546","8.44030","0.07677"
"383.2000","7.6622","8.43671","0.07684"
"383.6000","7.6704","8.43740","0.07691"
"384.0000","7.6785","8.43785","0.07697"
"384.4000","7.6866","8.43769","0.07704"
"384.8000","7.6944","8.43662","0.07711"
"385.2000","7.7023","8.43411","0.07717"
"385.6000","7.7107","8.43804","0.07724"
"386.0000","7.7183","8.43323","0.07730"
"386.4000","7.7264","8.43259","0.07736"
"386.8000","7.7346","8.43432","0.07743"
"387.2000","7.7425","8.43333","0.07749"
"387.6000","7.7504","8.43254","0.07755"
"388.0000","7.7584","8.43107","0.07762"
"388.4000","7.7667","8.43355","0.07768"
"388.8000","7.7742","8.42801","0.07774"
"389.2000","7.7824","8.42881","0.07780"
"389.6000","7.7905","8.42980","0.07786"
"390.0000","7.7986","8.42990","0.07792"
"390.4000","7.8064","8.42805","0.07798"
"390.8000","7.8145","8.42630","0.07804"
"391.2000","7.8228","8.42928","0.07810"
"391.6000","7.8302","8.42297","0.07816"
"392.0000","7.8384","8.42429","0.07821"
"392.4000","7.8466","8.42567","0.07827"
"392.8000","7.8546","8.42392","0.07832"
"393.2000","7.8624","8.42213","0.07838"
"393.6000","7.8704","8.42168","0.07843"
"394.0000","7.8787","8.42432","0.07849"
"394.4000","7.8863","8.41799","0.07854"
"394.8000","7.8945","8.41894","0.07859"
"395.2000","7.9025","8.41915","0.07865"
"395.6000","7.9105","8.41821","0.07870"
"396.0000","7.9184","8.41660","0.07875"
"396.4000","7.9265","8.41605","0.07880"
"396.8000","7.9348","8.41841","0.07885"
"397.2000","7.9422","8.41088","0.07890"
"397.6000","7.9504","8.41244","0.07895"
"398.0000","7.9585","8.41302","0.07900"
"398.4000","7.9665","8.41148","0.07904"
"398.8000","7.9744","8.40971","0.07909"
"399.2000","7.9826","8.40964","0.07913"
"399.6000","7.9907","8.41038","0.07918"
"400.0000","7.9982","8.40408","0.07922"
"400.4000","8.0065","8.40643","0.07927"
"400.8000","8.0145","8.40579","0.07931"
"401.2000","8.0225","8.40385","0.07936"
"401.6000","8.0304","8.40170","0.07940"
"402.0000","8.0386","8.40185","0.07944"
"402.4000","8.0467","8.40315","0.07948"
"402.8000","8.0542","8.39606","0.07952"
"403.2000","8.0625","8.39753","0.07955"
"403.6000","8.0705","8.39665","0.07959"
"404.0000","8.0784","8.39394","0.07963"
"404.4000","8.0863","8.39311","0.07967"
"404.8000","8.0946","8.39406","0.07971"
"405.2000","8.1027","8.39320","0.07974"
"405.6000","8.1103","8.38681","0.07978"
"406.0000","8.1185","8.38832","0.07981"
"406.4000","8.1264","8.38602","0.07984"
"406.8000","8.1345","8.38527","0.07988"
"407.2000","8.1424","8.38221","0.07991"
"407.6000","8.1506","8.38252","0.07994"
"408.0000","8.1586","8.38196","0.07997"
"408.4000","8.1662","8.37520","0.08000"
"408.8000","8.1746","8.37775","0.08003"
"409.2000","8.1825","8.37489","0.08005"
"409.6000","8.1904","8.37168","0.08008"
"410.0000","8.1984","8.37061","0.08011"
"410.4000","8.2065","8.36988","0.08014"
"410.8000","8.2145","8.36853","0.08016"
"411.2000","8.2224","8.36339","0.08019"
"411.6000","8.2306","8.36398","0.08021"
"412.0000","8.2384","8.35988","0.08023"
"412.4000","8.2464","8.35774","0.08025"
"412.8000","8.2543","8.35492","0.08027"
"413.2000","8.2627","8.35569","0.08030"
"413.6000","8.2705","8.35259","0.08032"
"414.0000","8.2783","8.34664","0.08033"
"414.4000","8.2866","8.34836","0.08035"
"414.8000","8.2943","8.34278","0.08037"
"415.2000","8.3025","8.34067","0.08039"
"415.6000","8.3104","8.33813","0.08040"
"416.0000","8.3186","8.33631","0.08042"
"416.4000","8.3265","8.33345","0.08043"
"416.8000","8.3343","8.32792","0.08045"
"417.2000","8.3426","8.32822","0.08046"
"417.6000","8.3505","8.32281","0.08047"
"418.0000","8.3585","8.31892","0.08048"
"418.4000","8.3663","8.31453","0.08049"
"418.8000","8.3746","8.31337","0.08051"
"419.2000","8.3824","8.30927","0.08052"
"419.6000","8.3905","8.30346","0.08052"
"420.0000","8.3987","8.30288","0.08053"
"420.4000","8.4064","8.29451","0.08054"
"420.8000","8.4145","8.29059","0.08054"
"421.2000","8.4223","8.28661","0.08055"
"421.6000","8.4305","8.28331","0.08056"
"422.0000","8.4385","8.27859","0.08056"
"422.4000","8.4464","8.27184","0.08057"
"422.8000","8.4546","8.26930","0.08057"
"423.2000","8.4623","8.26221","0.08057"
"423.6000","8.4705","8.25780","0.08058"
"424.0000","8.4784","8.25097","0.08058"
"424.4000","8.4866","8.24741","0.08058"
"424.8000","8.4944","8.24089","0.08058"
"425.2000","8.5025","8.23434","0.08058"
"425.6000","8.5106","8.23199","0.08058"
"426.0000","8.5184","8.22154","0.08058"
"426.4000","8.5266","8.21676","0.08058"
"426.8000","8.5343","8.20908","0.08058"
"427.2000","8.5425","8.20384","0.08058"
"427.6000","8.5504","8.19734","0.08058"
"428.0000","8.5585","8.18972","0.08058"
"428.4000","8.5667","8.18482","0.08058"
"428.8000","8.5744","8.17460","0.08057"
"429.2000","8.5825","8.16847","0.08057"
"429.6000","8.5903","8.15993","0.08057"
"430.0000","8.5986","8.15474","0.08057"
"430.4000","8.6064","8.14564","0.08057"
"430.8000","8.6145","8.13766","0.08056"
"431.2000","8.6226","8.13284","0.08056"
"431.6000","8.6303","8.12170","0.08055"
"432.0000","8.6386","8.11516","0.08055"
"432.4000","8.6464","8.10512","0.08055"
"432.8000","8.6545","8.09814","0.08054"
"433.2000","8.6624","8.08875","0.08054"
"433.6000","8.6705","8.07974","0.08053"
"434.0000","8.6786","8.07407","0.08053"
"434.4000","8.6865","8.06232","0.08053"
"434.8000","8.6946","8.05448","0.08052"
"435.2000","8.7023","8.04312","0.08052"
"435.6000","8.7105","8.03602","0.08051"
"436.0000","8.7183","8.02581","0.08050"
"436.4000","8.7266","8.01568","0.08050"
"436.8000","8.7346","8.00902","0.08050"
"437.2000","8.7424","7.99608","0.08049"
"437.6000","8.7506","7.98747","0.08048"
"438.0000","8.7583","7.97588","0.08048"
"438.4000","8.7665","7.96740","0.08047"
"438.8000","8.7744","7.95618","0.08047"
"439.2000","8.7825","7.94547","0.08046"
"439.6000","8.7905","7.93715","0.08045"
"440.0000","8.7984","7.92478","0.08045"
"440.4000","8.8065","7.91524","0.08044"
"440.8000","8.8144","7.90136","0.08043"
"441.2000","8.8226","7.89253","0.08043"
"441.6000","8.8303","7.87930","0.08042"
"442.0000","8.8385","7.86802","0.08041"
"442.4000","8.8465","7.85995","0.08041"
"442.8000","8.8545","7.84598","0.08040"
"443.2000","8.8626","7.83459","0.08039"
"443.6000","8.8704","7.82032","0.08039"
"444.0000","8.8785","7.81059","0.08038"
"444.4000","8.8863","7.79671","0.08037"
"444.8000","8.8945","7.78425","0.08036"
"445.2000","8.9025","7.77418","0.08036"
"445.6000","8.9106","7.76025","0.08035"
"446.0000","8.9186","7.74719","0.08034"
"446.4000","8.9263","7.73171","0.08033"
"446.8000","8.9346","7.72199","0.08032"
"447.2000","8.9424","7.70568","0.08031"
"447.6000","8.9505","7.69147","0.08030"
"448.0000","8.9585","7.68129","0.08030"
"448.4000","8.9664","7.66588","0.08029"
"448.8000","8.9746","7.65217","0.08028"
"449.2000","8.9824","7.63547","0.08027"
"449.6000","8.9906","7.62363","0.08026"
"450.0000","8.9984","7.60638","0.08025"
"450.4000","9.0064","7.59162","0.08024"
"450.8000","9.0144","7.57933","0.08024"
"451.2000","9.0226","7.56318","0.08023"
"451.6000","9.0306","7.54731","0.08021"
"452.0000","9.0384","7.52915","0.08020"
"452.4000","9.0466","7.51669","0.08019"
"452.8000","9.0543","7.49716","0.08018"
"453.2000","9.0625","7.48086","0.08017"
"453.6000","9.0705","7.46737","0.08016"
"454.0000","9.0785","7.44903","0.08015"
"454.4000","9.0865","7.43201","0.08014"
"454.8000","9.0944","7.41348","0.08013"
"455.2000","9.1026","7.39889","0.08012"
"455.6000","9.1104","7.37783","0.08010"
"456.0000","9.1185","7.36068","0.08009"
"456.4000","9.1264","7.34488","0.08008"
"456.8000","9.1344","7.32538","0.08007"
"457.2000","9.1425","7.30793","0.08006"
"457.6000","9.1505","7.28683","0.08005"
"458.0000","9.1586","7.27088","0.08004"
"458.4000","9.1663","7.24755","0.08002"
"458.8000","9.1745","7.22831","0.08001"
"459.2000","9.1824","7.21120","0.08000"
"459.6000","9.1905","7.18874","0.07998"
"460.0000","9.1986","7.16829","0.07997"
"460.4000","9.2065","7.14652","0.07996"
"460.8000","9.2145","7.12657","0.07994"
"461.2000","9.2223","7.10071","0.07993"
"461.6000","9.2306","7.07867","0.07992"
"462.0000","9.2384","7.05577","0.07990"
"462.4000","9.2465","7.02983","0.07989"
"462.8000","9.2545","7.00577","0.07987"
"463.2000","9.2625","6.97925","0.07985"
"463.6000","9.2705","6.95556","0.07984"
"464.0000","9.2783","6.92479","0.07982"
"464.4000","9.2866","6.89866","0.07980"
"464.8000","9.2944","6.87255","0.07978"
"465.2000","9.3024","6.84042","0.07977"
"465.6000","9.3105","6.80738","0.07975"
"466.0000","9.3186","6.76567","0.07972"
"466.4000","9.3265","6.71614","0.07970"
"466.8000","9.3344","6.61180","0.07965"
"467.2000","9.3426","6.46269","0.07959"
"467.5480","9.3493","6.16273","0.07947"
"467.6200","9.3510","5.85157","0.07933"
"467.6310","9.3513","5.38514","0.07909"
"467.6350","9.3514","5.05854","0.07891"