File: Coupon Test Data/Tensile Test_Neebajan_Alan_10.csv
Time,Displacement,Force,Strain 1
(s),(mm),(kN),(mm/mm)
"0.0000","0.0000","0.18295","-0.00034"
"0.4000","0.0063","0.25775","-0.00031"
"0.8000","0.0145","0.35978","-0.00026"
"1.2000","0.0224","0.45727","-0.00021"
"1.6000","0.0306","0.55552","-0.00017"
"2.0000","0.0387","0.64731","-0.00012"
"2.4000","0.0463","0.73358","-0.00008"
"2.8000","0.0545","0.82191","-0.00004"
"3.2000","0.0626","0.90476","0.00000"
"3.6000","0.0706","0.98985","0.00004"
"4.0000","0.0784","1.07182","0.00008"
"4.4000","0.0866","1.15479","0.00012"
"4.8000","0.0948","1.23334","0.00016"
"5.2000","0.1024","1.30750","0.00019"
"5.6000","0.1105","1.38562","0.00023"
"6.0000","0.1186","1.45867","0.00026"
"6.4000","0.1265","1.53107","0.00030"
"6.8000","0.1344","1.60301","0.00033"
"7.2000","0.1427","1.67365","0.00037"
"7.6000","0.1508","1.74429","0.00040"
"8.0000","0.1584","1.80813","0.00043"
"8.4000","0.1665","1.87473","0.00046"
"8.8000","0.1746","1.93955","0.00049"
"9.2000","0.1826","2.00410","0.00052"
"9.6000","0.1905","2.06513","0.00055"
"10.0000","0.1987","2.12718","0.00058"
"10.4000","0.2068","2.19006","0.00061"
"10.8000","0.2143","2.24349","0.00064"
"11.2000","0.2225","2.30279","0.00067"
"11.6000","0.2306","2.36228","0.00069"
"12.0000","0.2386","2.41608","0.00072"
"12.4000","0.2464","2.47071","0.00075"
"12.8000","0.2547","2.52924","0.00077"
"13.2000","0.2627","2.58260","0.00080"
"13.6000","0.2705","2.63282","0.00082"
"14.0000","0.2786","2.68707","0.00085"
"14.4000","0.2866","2.73753","0.00088"
"14.8000","0.2945","2.78942","0.00090"
"15.2000","0.3024","2.84176","0.00092"
"15.6000","0.3107","2.89438","0.00095"
"16.0000","0.3187","2.94775","0.00098"
"16.4000","0.3264","2.99804","0.00100"
"16.8000","0.3346","3.05032","0.00102"
"17.2000","0.3425","3.10229","0.00105"
"17.6000","0.3505","3.15266","0.00108"
"18.0000","0.3585","3.20571","0.00110"
"18.4000","0.3667","3.26034","0.00113"
"18.8000","0.3746","3.31086","0.00115"
"19.2000","0.3824","3.36141","0.00118"
"19.6000","0.3907","3.41501","0.00120"
"20.0000","0.3985","3.46716","0.00123"
"20.4000","0.4065","3.51841","0.00126"
"20.8000","0.4145","3.57120","0.00128"
"21.2000","0.4226","3.62476","0.00131"
"21.6000","0.4306","3.67800","0.00133"
"22.0000","0.4385","3.72806","0.00136"
"22.4000","0.4467","3.78296","0.00139"
"22.8000","0.4545","3.83380","0.00141"
"23.2000","0.4625","3.88512","0.00144"
"23.6000","0.4705","3.93840","0.00146"
"24.0000","0.4787","3.99258","0.00149"
"24.4000","0.4866","4.04450","0.00151"
"24.8000","0.4945","4.09528","0.00154"
"25.2000","0.5027","4.14890","0.00157"
"25.6000","0.5104","4.19866","0.00159"
"26.0000","0.5185","4.25134","0.00162"
"26.4000","0.5265","4.30338","0.00165"
"26.8000","0.5347","4.35655","0.00167"
"27.2000","0.5426","4.40805","0.00170"
"27.6000","0.5505","4.45876","0.00173"
"28.0000","0.5587","4.51288","0.00175"
"28.4000","0.5665","4.56209","0.00178"
"28.8000","0.5746","4.61364","0.00180"
"29.2000","0.5825","4.66513","0.00183"
"29.6000","0.5906","4.71672","0.00186"
"30.0000","0.5985","4.76716","0.00188"
"30.4000","0.6066","4.81852","0.00191"
"30.8000","0.6148","4.87058","0.00194"
"31.2000","0.6225","4.91833","0.00196"
"31.6000","0.6305","4.96890","0.00199"
"32.0000","0.6384","5.01850","0.00201"
"32.4000","0.6466","5.06984","0.00204"
"32.8000","0.6545","5.11831","0.00207"
"33.2000","0.6626","5.16724","0.00209"
"33.6000","0.6707","5.21774","0.00212"
"34.0000","0.6784","5.26369","0.00215"
"34.4000","0.6866","5.31342","0.00217"
"34.8000","0.6946","5.36195","0.00220"
"35.2000","0.7026","5.41069","0.00222"
"35.6000","0.7105","5.45785","0.00225"
"36.0000","0.7186","5.50658","0.00227"
"36.4000","0.7267","5.55646","0.00230"
"36.8000","0.7345","5.60224","0.00233"
"37.2000","0.7426","5.65128","0.00235"
"37.6000","0.7505","5.69781","0.00238"
"38.0000","0.7586","5.74669","0.00241"
"38.4000","0.7664","5.79372","0.00243"
"38.8000","0.7746","5.84219","0.00246"
"39.2000","0.7828","5.89146","0.00249"
"39.6000","0.7905","5.93674","0.00252"
"40.0000","0.7986","5.98459","0.00254"
"40.4000","0.8064","6.03099","0.00257"
"40.8000","0.8146","6.07965","0.00260"
"41.2000","0.8225","6.12613","0.00263"
"41.6000","0.8306","6.17382","0.00266"
"42.0000","0.8387","6.22198","0.00269"
"42.4000","0.8465","6.26639","0.00272"
"42.8000","0.8547","6.31438","0.00275"
"43.2000","0.8625","6.35910","0.00278"
"43.6000","0.8707","6.40661","0.00281"
"44.0000","0.8785","6.45123","0.00284"
"44.4000","0.8866","6.49684","0.00287"
"44.8000","0.8947","6.54430","0.00291"
"45.2000","0.9026","6.58711","0.00294"
"45.6000","0.9107","6.63192","0.00297"
"46.0000","0.9185","6.67401","0.00301"
"46.4000","0.9266","6.71840","0.00304"
"46.8000","0.9344","6.76017","0.00308"
"47.2000","0.9426","6.80294","0.00312"
"47.6000","0.9507","6.84526","0.00315"
"48.0000","0.9586","6.88419","0.00319"
"48.4000","0.9667","6.92337","0.00323"
"48.8000","0.9744","6.95847","0.00328"
"49.2000","0.9827","6.99735","0.00332"
"49.6000","0.9905","7.03063","0.00337"
"50.0000","0.9986","7.06313","0.00341"
"50.4000","1.0066","7.09700","0.00347"
"50.8000","1.0145","7.12409","0.00352"
"51.2000","1.0227","7.15220","0.00358"
"51.6000","1.0305","7.17461","0.00364"
"52.0000","1.0387","7.19887","0.00371"
"52.4000","1.0465","7.21766","0.00377"
"52.8000","1.0546","7.23694","0.00384"
"53.2000","1.0626","7.25600","0.00392"
"53.6000","1.0707","7.27073","0.00400"
"54.0000","1.0787","7.28467","0.00408"
"54.4000","1.0865","7.29452","0.00416"
"54.8000","1.0946","7.30908","0.00424"
"55.2000","1.1024","7.31730","0.00433"
"55.6000","1.1106","7.32728","0.00442"
"56.0000","1.1187","7.33804","0.00450"
"56.4000","1.1266","7.34447","0.00459"
"56.8000","1.1347","7.35330","0.00468"
"57.2000","1.1424","7.35855","0.00477"
"57.6000","1.1507","7.36789","0.00486"
"58.0000","1.1585","7.37203","0.00496"
"58.4000","1.1666","7.37792","0.00505"
"58.8000","1.1746","7.38491","0.00515"
"59.2000","1.1826","7.39018","0.00524"
"59.6000","1.1906","7.39498","0.00534"
"60.0000","1.1986","7.39765","0.00543"
"60.4000","1.2067","7.40508","0.00553"
"60.8000","1.2144","7.40525","0.00563"
"61.2000","1.2226","7.40427","0.00572"
"61.6000","1.2305","7.41401","0.00580"
"62.0000","1.2386","7.41938","0.00590"
"62.4000","1.2467","7.42362","0.00600"
"62.8000","1.2545","7.42454","0.00610"
"63.2000","1.2627","7.43007","0.00620"
"63.6000","1.2704","7.43063","0.00630"
"64.0000","1.2786","7.43454","0.00640"
"64.4000","1.2866","7.43866","0.00649"
"64.8000","1.2946","7.44131","0.00659"
"65.2000","1.3026","7.44372","0.00670"
"65.6000","1.3106","7.44616","0.00680"
"66.0000","1.3187","7.45096","0.00689"
"66.4000","1.3264","7.44945","0.00699"
"66.8000","1.3347","7.45477","0.00710"
"67.2000","1.3425","7.45661","0.00720"
"67.6000","1.3505","7.45829","0.00730"
"68.0000","1.3587","7.46333","0.00740"
"68.4000","1.3666","7.46367","0.00750"
"68.8000","1.3747","7.46768","0.00760"
"69.2000","1.3824","7.46636","0.00770"
"69.6000","1.3906","7.46997","0.00781"
"70.0000","1.3985","7.47322","0.00791"
"70.4000","1.4065","7.47466","0.00801"
"70.8000","1.4146","7.47729","0.00811"
"71.2000","1.4227","7.47974","0.00821"
"71.6000","1.4306","7.48251","0.00832"
"72.0000","1.4384","7.48091","0.00842"
"72.4000","1.4467","7.48632","0.00852"
"72.8000","1.4545","7.48720","0.00862"
"73.2000","1.4626","7.48826","0.00872"
"73.6000","1.4706","7.49197","0.00883"
"74.0000","1.4786","7.49325","0.00893"
"74.4000","1.4866","7.49667","0.00903"
"74.8000","1.4944","7.49494","0.00913"
"75.2000","1.5027","7.49898","0.00924"
"75.6000","1.5105","7.49999","0.00934"
"76.0000","1.5185","7.50116","0.00944"
"76.4000","1.5266","7.50499","0.00954"
"76.8000","1.5347","7.50702","0.00964"
"77.2000","1.5426","7.50863","0.00975"
"77.6000","1.5505","7.50730","0.00985"
"78.0000","1.5587","7.51211","0.00995"
"78.4000","1.5664","7.51195","0.01005"
"78.8000","1.5745","7.51390","0.01015"
"79.2000","1.5827","7.51724","0.01025"
"79.6000","1.5907","7.51872","0.01035"
"80.0000","1.5985","7.52021","0.01045"
"80.4000","1.6064","7.51998","0.01055"
"80.8000","1.6148","7.52481","0.01066"
"81.2000","1.6225","7.52387","0.01075"
"81.6000","1.6305","7.52545","0.01085"
"82.0000","1.6386","7.52851","0.01095"
"82.4000","1.6467","7.53082","0.01106"
"82.8000","1.6545","7.53210","0.01115"
"83.2000","1.6625","7.53169","0.01125"
"83.6000","1.6708","7.53682","0.01136"
"84.0000","1.6784","7.53457","0.01145"
"84.4000","1.6864","7.53627","0.01155"
"84.8000","1.6946","7.54108","0.01165"
"85.2000","1.7027","7.54278","0.01175"
"85.6000","1.7106","7.54254","0.01185"
"86.0000","1.7185","7.53545","0.01193"
"86.4000","1.7268","7.54720","0.01202"
"86.8000","1.7344","7.54660","0.01212"
"87.2000","1.7425","7.54928","0.01222"
"87.6000","1.7506","7.55199","0.01232"
"88.0000","1.7587","7.55406","0.01241"
"88.4000","1.7665","7.55420","0.01251"
"88.8000","1.7745","7.55473","0.01261"
"89.2000","1.7829","7.56050","0.01271"
"89.6000","1.7904","7.55677","0.01280"
"90.0000","1.7985","7.55897","0.01290"
"90.4000","1.8066","7.56274","0.01300"
"90.8000","1.8146","7.56356","0.01310"
"91.2000","1.8225","7.56471","0.01320"
"91.6000","1.8306","7.56635","0.01330"
"92.0000","1.8389","7.57059","0.01340"
"92.4000","1.8463","7.56687","0.01350"
"92.8000","1.8545","7.56997","0.01359"
"93.2000","1.8626","7.57335","0.01369"
"93.6000","1.8707","7.57539","0.01379"
"94.0000","1.8785","7.57522","0.01388"
"94.4000","1.8867","7.57697","0.01398"
"94.8000","1.8948","7.58147","0.01408"
"95.2000","1.9023","7.57733","0.01417"
"95.6000","1.9106","7.58168","0.01427"
"96.0000","1.9187","7.58475","0.01437"
"96.4000","1.9266","7.58481","0.01446"
"96.8000","1.9345","7.58581","0.01456"
"97.2000","1.9426","7.58845","0.01465"
"97.6000","1.9508","7.59239","0.01475"
"98.0000","1.9584","7.58906","0.01484"
"98.4000","1.9666","7.59223","0.01494"
"98.8000","1.9746","7.59430","0.01504"
"99.2000","1.9826","7.59538","0.01513"
"99.6000","1.9904","7.59657","0.01522"
"100.0000","1.9987","7.59962","0.01532"
"100.4000","2.0069","7.60297","0.01542"
"100.8000","2.0143","7.59873","0.01551"
"101.2000","2.0226","7.60300","0.01561"
"101.6000","2.0305","7.60534","0.01570"
"102.0000","2.0386","7.60627","0.01580"
"102.4000","2.0465","7.60718","0.01589"
"102.8000","2.0548","7.61051","0.01599"
"103.2000","2.0627","7.61270","0.01608"
"103.6000","2.0704","7.60989","0.01617"
"104.0000","2.0787","7.61476","0.01627"
"104.4000","2.0866","7.61572","0.01636"
"104.8000","2.0946","7.61635","0.01646"
"105.2000","2.1025","7.61763","0.01655"
"105.6000","2.1107","7.62084","0.01665"
"106.0000","2.1188","7.62408","0.01674"
"106.4000","2.1264","7.62065","0.01683"
"106.8000","2.1347","7.62491","0.01693"
"107.2000","2.1426","7.62607","0.01702"
"107.6000","2.1505","7.62621","0.01711"
"108.0000","2.1585","7.62824","0.01721"
"108.4000","2.1668","7.63226","0.01730"
"108.8000","2.1747","7.63331","0.01740"
"109.2000","2.1825","7.59330","0.01745"
"109.6000","2.1907","7.62130","0.01752"
"110.0000","2.1985","7.63284","0.01761"
"110.4000","2.2066","7.63889","0.01770"
"110.8000","2.2145","7.64054","0.01779"
"111.2000","2.2227","7.64353","0.01788"
"111.6000","2.2307","7.64485","0.01798"
"112.0000","2.2384","7.64254","0.01807"
"112.4000","2.2467","7.64756","0.01816"
"112.8000","2.2545","7.64649","0.01825"
"113.2000","2.2626","7.64742","0.01835"
"113.6000","2.2705","7.64889","0.01844"
"114.0000","2.2786","7.65150","0.01853"
"114.4000","2.2866","7.65326","0.01862"
"114.8000","2.2946","7.65310","0.01872"
"115.2000","2.3028","7.65664","0.01881"
"115.6000","2.3105","7.65516","0.01890"
"116.0000","2.3185","7.65720","0.01899"
"116.4000","2.3264","7.65835","0.01908"
"116.8000","2.3347","7.66214","0.01918"
"117.2000","2.3426","7.66301","0.01927"
"117.6000","2.3505","7.66264","0.01936"
"118.0000","2.3588","7.66719","0.01946"
"118.4000","2.3664","7.66533","0.01954"
"118.8000","2.3746","7.66792","0.01964"
"119.2000","2.3826","7.66957","0.01973"
"119.6000","2.3907","7.67193","0.01982"
"120.0000","2.3985","7.67229","0.01991"
"120.4000","2.4066","7.67335","0.02001"
"120.8000","2.4147","7.67734","0.02010"
"121.2000","2.4225","7.67563","0.02019"
"121.6000","2.4306","7.67794","0.02028"
"122.0000","2.4385","7.67869","0.02037"
"122.4000","2.4466","7.68140","0.02046"
"122.8000","2.4545","7.68304","0.02056"
"123.2000","2.4627","7.68404","0.02065"
"123.6000","2.4708","7.68761","0.02074"
"124.0000","2.4785","7.68579","0.02083"
"124.4000","2.4866","7.68841","0.02092"
"124.8000","2.4945","7.67195","0.02100"
"125.2000","2.5027","7.68501","0.02108"
"125.6000","2.5105","7.69112","0.02117"
"126.0000","2.5186","7.69452","0.02126"
"126.4000","2.5267","7.69778","0.02136"
"126.8000","2.5344","7.69644","0.02144"
"127.2000","2.5426","7.69986","0.02154"
"127.6000","2.5505","7.69974","0.02163"
"128.0000","2.5587","7.70210","0.02172"
"128.4000","2.5665","7.70254","0.02181"
"128.8000","2.5746","7.70400","0.02190"
"129.2000","2.5828","7.70833","0.02199"
"129.6000","2.5905","7.70634","0.02208"
"130.0000","2.5986","7.70875","0.02217"
"130.4000","2.6065","7.70899","0.02226"
"130.8000","2.6146","7.71136","0.02235"
"131.2000","2.6224","7.71206","0.02244"
"131.6000","2.6307","7.71492","0.02254"
"132.0000","2.6387","7.71717","0.02264"
"132.4000","2.6466","7.71628","0.02273"
"132.8000","2.6547","7.71889","0.02282"
"133.2000","2.6624","7.71812","0.02291"
"133.6000","2.6707","7.72228","0.02300"
"134.0000","2.6785","7.72223","0.02309"
"134.4000","2.6866","7.72342","0.02319"
"134.8000","2.6947","7.72698","0.02328"
"135.2000","2.7025","7.72619","0.02336"
"135.6000","2.7107","7.72929","0.02346"
"136.0000","2.7185","7.72866","0.02355"
"136.4000","2.7266","7.73149","0.02364"
"136.8000","2.7345","7.73180","0.02373"
"137.2000","2.7426","7.73325","0.02382"
"137.6000","2.7506","7.73676","0.02391"
"138.0000","2.7586","7.73695","0.02400"
"138.4000","2.7667","7.73899","0.02409"
"138.8000","2.7744","7.73765","0.02418"
"139.2000","2.7826","7.74189","0.02427"
"139.6000","2.7904","7.74147","0.02436"
"140.0000","2.7986","7.74368","0.02445"
"140.4000","2.8067","7.74678","0.02454"
"140.8000","2.8146","7.74653","0.02464"
"141.2000","2.8227","7.74873","0.02472"
"141.6000","2.8304","7.74786","0.02481"
"142.0000","2.8386","7.75177","0.02490"
"142.4000","2.8465","7.75149","0.02499"
"142.8000","2.8546","7.75321","0.02509"
"143.2000","2.8626","7.75552","0.02517"
"143.6000","2.8706","7.75666","0.02527"
"144.0000","2.8787","7.75878","0.02535"
"144.4000","2.8865","7.75768","0.02544"
"144.8000","2.8947","7.76210","0.02554"
"145.2000","2.9025","7.76068","0.02563"
"145.6000","2.9106","7.76221","0.02572"
"146.0000","2.9186","7.76595","0.02581"
"146.4000","2.9267","7.76673","0.02590"
"146.8000","2.9347","7.76821","0.02599"
"147.2000","2.9425","7.76729","0.02608"
"147.6000","2.9506","7.77106","0.02617"
"148.0000","2.9584","7.77026","0.02626"
"148.4000","2.9666","7.77295","0.02635"
"148.8000","2.9746","7.77490","0.02644"
"149.2000","2.9827","7.77640","0.02653"
"149.6000","2.9907","7.77739","0.02662"
"150.0000","2.9984","7.77660","0.02671"
"150.4000","3.0067","7.78160","0.02680"
"150.8000","3.0145","7.77988","0.02689"
"151.2000","3.0226","7.78175","0.02698"
"151.6000","3.0306","7.78408","0.02707"
"152.0000","3.0385","7.78495","0.02716"
"152.4000","3.0467","7.78773","0.02725"
"152.8000","3.0546","7.78722","0.02734"
"153.2000","3.0627","7.79065","0.02743"
"153.6000","3.0705","7.78886","0.02752"
"154.0000","3.0786","7.79146","0.02761"
"154.4000","3.0865","7.79337","0.02770"
"154.8000","3.0946","7.79525","0.02779"
"155.2000","3.1027","7.79663","0.02788"
"155.6000","3.1106","7.79653","0.02797"
"156.0000","3.1187","7.80014","0.02806"
"156.4000","3.1263","7.79779","0.02814"
"156.8000","3.1347","7.80167","0.02824"
"157.2000","3.1426","7.80322","0.02833"
"157.6000","3.1506","7.80358","0.02842"
"158.0000","3.1586","7.80580","0.02851"
"158.4000","3.1665","7.80625","0.02860"
"158.8000","3.1747","7.80968","0.02869"
"159.2000","3.1825","7.80787","0.02878"
"159.6000","3.1907","7.81063","0.02887"
"160.0000","3.1985","7.81146","0.02895"
"160.4000","3.2065","7.81268","0.02904"
"160.8000","3.2146","7.81524","0.02913"
"161.2000","3.2227","7.81614","0.02923"
"161.6000","3.2307","7.81889","0.02931"
"162.0000","3.2384","7.81625","0.02940"
"162.4000","3.2466","7.81979","0.02949"
"162.8000","3.2544","7.82087","0.02958"
"163.2000","3.2626","7.82233","0.02967"
"163.6000","3.2707","7.82474","0.02976"
"164.0000","3.2787","7.82541","0.02985"
"164.4000","3.2866","7.82682","0.02994"
"164.8000","3.2944","7.82573","0.03003"
"165.2000","3.3027","7.82997","0.03012"
"165.6000","3.3105","7.82983","0.03020"
"166.0000","3.3186","7.81409","0.03028"
"166.4000","3.3266","7.82702","0.03036"
"166.8000","3.3347","7.83345","0.03045"
"167.2000","3.3426","7.83666","0.03054"
"167.6000","3.3504","7.83523","0.03062"
"168.0000","3.3588","7.83996","0.03072"
"168.4000","3.3664","7.83859","0.03080"
"168.8000","3.3744","7.83931","0.03089"
"169.2000","3.3826","7.84331","0.03098"
"169.6000","3.3907","7.84482","0.03107"
"170.0000","3.3986","7.84494","0.03116"
"170.4000","3.4065","7.84390","0.03124"
"170.8000","3.4147","7.82642","0.03131"
"171.2000","3.4224","7.83912","0.03139"
"171.6000","3.4305","7.84695","0.03148"
"172.0000","3.4386","7.85131","0.03156"
"172.4000","3.4468","7.85460","0.03165"
"172.8000","3.4545","7.85442","0.03174"
"173.2000","3.4625","7.85359","0.03183"
"173.6000","3.4708","7.85889","0.03192"
"174.0000","3.4784","7.85595","0.03200"
"174.4000","3.4865","7.85728","0.03209"
"174.8000","3.4946","7.86034","0.03218"
"175.2000","3.5026","7.86115","0.03227"
"175.6000","3.5106","7.86260","0.03236"
"176.0000","3.5185","7.86240","0.03245"
"176.4000","3.5268","7.86597","0.03254"
"176.8000","3.5344","7.86358","0.03263"
"177.2000","3.5424","7.86514","0.03272"
"177.6000","3.5506","7.86805","0.03281"
"178.0000","3.5588","7.87088","0.03290"
"178.4000","3.5665","7.86945","0.03298"
"178.8000","3.5746","7.87027","0.03307"
"179.2000","3.5828","7.87488","0.03316"
"179.6000","3.5903","7.87076","0.03325"
"180.0000","3.5986","7.87462","0.03334"
"180.4000","3.6067","7.87710","0.03343"
"180.8000","3.6146","7.87731","0.03352"
"181.2000","3.6225","7.87841","0.03360"
"181.6000","3.6305","7.87916","0.03370"
"182.0000","3.6388","7.88336","0.03378"
"182.4000","3.6464","7.88042","0.03387"
"182.8000","3.6545","7.88227","0.03396"
"183.2000","3.6626","7.88512","0.03405"
"183.6000","3.6706","7.88597","0.03414"
"184.0000","3.6784","7.88622","0.03423"
"184.4000","3.6867","7.88865","0.03432"
"184.8000","3.6948","7.89197","0.03441"
"185.2000","3.7023","7.88738","0.03449"
"185.6000","3.7106","7.89123","0.03458"
"186.0000","3.7185","7.89313","0.03467"
"186.4000","3.7266","7.89416","0.03476"
"186.8000","3.7345","7.89482","0.03485"
"187.2000","3.7427","7.89683","0.03494"
"187.6000","3.7508","7.89980","0.03503"
"188.0000","3.7583","7.89598","0.03511"
"188.4000","3.7666","7.89998","0.03521"
"188.8000","3.7747","7.90188","0.03530"
"189.2000","3.7826","7.90209","0.03538"
"189.6000","3.7905","7.90245","0.03547"
"190.0000","3.7987","7.90548","0.03556"
"190.4000","3.8068","7.90877","0.03565"
"190.8000","3.8144","7.90459","0.03574"
"191.2000","3.8227","7.90840","0.03583"
"191.6000","3.8306","7.90951","0.03592"
"192.0000","3.8385","7.90954","0.03601"
"192.4000","3.8464","7.91104","0.03609"
"192.8000","3.8548","7.91463","0.03619"
"193.2000","3.8628","7.91631","0.03628"
"193.6000","3.8704","7.91256","0.03636"
"194.0000","3.8786","7.91640","0.03645"
"194.4000","3.8865","7.91713","0.03654"
"194.8000","3.8946","7.91876","0.03663"
"195.2000","3.9025","7.91848","0.03672"
"195.6000","3.9107","7.92189","0.03681"
"196.0000","3.9187","7.92379","0.03690"
"196.4000","3.9263","7.92029","0.03698"
"196.8000","3.9347","7.92536","0.03707"
"197.2000","3.9426","7.92567","0.03716"
"197.6000","3.9506","7.92566","0.03725"
"198.0000","3.9585","7.92706","0.03734"
"198.4000","3.9666","7.92951","0.03743"
"198.8000","3.9747","7.93152","0.03752"
"199.2000","3.9825","7.92975","0.03761"
"199.6000","3.9907","7.93331","0.03770"
"200.0000","3.9985","7.93238","0.03778"
"200.4000","4.0065","7.93370","0.03787"
"200.8000","4.0144","7.93453","0.03796"
"201.2000","4.0227","7.93814","0.03805"
"201.6000","4.0306","7.93887","0.03814"
"202.0000","4.0384","7.93693","0.03823"
"202.4000","4.0467","7.94133","0.03832"
"202.8000","4.0544","7.93997","0.03841"
"203.2000","4.0626","7.94192","0.03850"
"203.6000","4.0706","7.94301","0.03858"
"204.0000","4.0787","7.94555","0.03867"
"204.4000","4.0866","7.94589","0.03876"
"204.8000","4.0945","7.94526","0.03885"
"205.2000","4.1027","7.94972","0.03894"
"205.6000","4.1105","7.94778","0.03903"
"206.0000","4.1186","7.94936","0.03912"
"206.4000","4.1265","7.94979","0.03921"
"206.8000","4.1346","7.95247","0.03930"
"207.2000","4.1426","7.95398","0.03938"
"207.6000","4.1506","7.95357","0.03948"
"208.0000","4.1588","7.95733","0.03957"
"208.4000","4.1665","7.95535","0.03965"
"208.8000","4.1746","7.95662","0.03974"
"209.2000","4.1825","7.95784","0.03983"
"209.6000","4.1907","7.96056","0.03992"
"210.0000","4.1986","7.96071","0.04001"
"210.4000","4.2066","7.96133","0.04010"
"210.8000","4.2147","7.96429","0.04019"
"211.2000","4.2224","7.96223","0.04028"
"211.6000","4.2306","7.96527","0.04037"
"212.0000","4.2386","7.96534","0.04045"
"212.4000","4.2467","7.96754","0.04055"
"212.8000","4.2546","7.96797","0.04063"
"213.2000","4.2626","7.96842","0.04072"
"213.6000","4.2707","7.97246","0.04081"
"214.0000","4.2785","7.97038","0.04090"
"214.4000","4.2866","7.97217","0.04099"
"214.8000","4.2945","7.97255","0.04108"
"215.2000","4.3026","7.97429","0.04117"
"215.6000","4.3105","7.97484","0.04126"
"216.0000","4.3187","7.97685","0.04135"
"216.4000","4.3268","7.96599","0.04142"
"216.8000","4.3345","7.97258","0.04150"
"217.2000","4.3426","7.97859","0.04159"
"217.6000","4.3504","7.97933","0.04167"
"218.0000","4.3587","7.98296","0.04176"
"218.4000","4.3665","7.98313","0.04185"
"218.8000","4.3746","7.98405","0.04194"
"219.2000","4.3827","7.98687","0.04203"
"219.6000","4.3904","7.98498","0.04212"
"220.0000","4.3987","7.98780","0.04221"
"220.4000","4.4066","7.98743","0.04230"
"220.8000","4.4146","7.98910","0.04239"
"221.2000","4.4225","7.98896","0.04247"
"221.6000","4.4306","7.99051","0.04256"
"222.0000","4.4387","7.99338","0.04265"
"222.4000","4.4466","7.99233","0.04274"
"222.8000","4.4547","7.99445","0.04283"
"223.2000","4.4625","7.99275","0.04292"
"223.6000","4.4706","7.99589","0.04301"
"224.0000","4.4784","7.99592","0.04310"
"224.4000","4.4867","7.99758","0.04319"
"224.8000","4.4947","8.00027","0.04328"
"225.2000","4.5025","7.99872","0.04336"
"225.6000","4.5107","8.00107","0.04346"
"226.0000","4.5184","7.99965","0.04354"
"226.4000","4.5266","8.00275","0.04363"
"226.8000","4.5345","8.00266","0.04372"
"227.2000","4.5426","8.00387","0.04381"
"227.6000","4.5506","8.00583","0.04390"
"228.0000","4.5585","8.00588","0.04399"
"228.4000","4.5667","8.00845","0.04408"
"228.8000","4.5745","8.00672","0.04417"
"229.2000","4.5827","8.00984","0.04426"
"229.6000","4.5905","8.00832","0.04435"
"230.0000","4.5985","8.00942","0.04444"
"230.4000","4.6066","8.01314","0.04453"
"230.8000","4.6146","8.01315","0.04462"
"231.2000","4.6227","8.01450","0.04470"
"231.6000","4.6305","8.01301","0.04479"
"232.0000","4.6386","8.01586","0.04488"
"232.4000","4.6464","8.01539","0.04497"
"232.8000","4.6546","8.01715","0.04506"
"233.2000","4.6626","8.01889","0.04515"
"233.6000","4.6707","8.01966","0.04524"
"234.0000","4.6787","8.02070","0.04533"
"234.4000","4.6864","8.01883","0.04542"
"234.8000","4.6947","8.02323","0.04551"
"235.2000","4.7025","8.02197","0.04560"
"235.6000","4.7106","8.02327","0.04569"
"236.0000","4.7186","8.02509","0.04578"
"236.4000","4.7265","8.02539","0.04586"
"236.8000","4.7347","8.02767","0.04596"
"237.2000","4.7425","8.02621","0.04604"
"237.6000","4.7507","8.02918","0.04614"
"238.0000","4.7585","8.02770","0.04622"
"238.4000","4.7666","8.02938","0.04631"
"238.8000","4.7746","8.03143","0.04640"
"239.2000","4.7827","8.03284","0.04649"
"239.6000","4.7907","8.03335","0.04658"
"240.0000","4.7985","8.03210","0.04667"
"240.4000","4.8067","8.03572","0.04676"
"240.8000","4.8144","8.03344","0.04685"
"241.2000","4.8226","8.03612","0.04694"
"241.6000","4.8306","8.03802","0.04703"
"242.0000","4.8386","8.03809","0.04712"
"242.4000","4.8466","8.03920","0.04721"
"242.8000","4.8545","8.03858","0.04730"
"243.2000","4.8627","8.04209","0.04739"
"243.6000","4.8705","8.04019","0.04748"
"244.0000","4.8786","8.01590","0.04755"
"244.4000","4.8865","8.03146","0.04762"
"244.8000","4.8945","8.04019","0.04771"
"245.2000","4.9026","8.04531","0.04780"
"245.6000","4.9106","8.04611","0.04789"
"246.0000","4.9187","8.04967","0.04798"
"246.4000","4.9264","8.04650","0.04807"
"246.8000","4.9346","8.04889","0.04816"
"247.2000","4.9425","8.05004","0.04825"
"247.6000","4.9506","8.05076","0.04834"
"248.0000","4.9587","8.05237","0.04843"
"248.4000","4.9666","8.05184","0.04852"
"248.8000","4.9746","8.05403","0.04861"
"249.2000","4.9824","8.05191","0.04869"
"249.6000","4.9907","8.05498","0.04879"
"250.0000","4.9986","8.05506","0.04888"
"250.4000","5.0066","8.05592","0.04896"
"250.8000","5.0146","8.05681","0.04905"
"251.2000","5.0226","8.05735","0.04914"
"251.6000","5.0306","8.05977","0.04923"
"252.0000","5.0384","8.05720","0.04932"
"252.4000","5.0467","8.06070","0.04942"
"252.8000","5.0545","8.05996","0.04951"
"253.2000","5.0625","8.06007","0.04959"
"253.6000","5.0706","8.06328","0.04969"
"254.0000","5.0787","8.06392","0.04978"
"254.4000","5.0866","8.06464","0.04987"
"254.8000","5.0945","8.06296","0.04996"
"255.2000","5.1027","8.06583","0.05005"
"255.6000","5.1104","8.06493","0.05013"
"256.0000","5.1186","8.06675","0.05023"
"256.4000","5.1266","8.06811","0.05032"
"256.8000","5.1347","8.06917","0.05041"
"257.2000","5.1426","8.07019","0.05050"
"257.6000","5.1504","8.06806","0.05059"
"258.0000","5.1588","8.07258","0.05068"
"258.4000","5.1665","8.07106","0.05077"
"258.8000","5.1745","8.07134","0.05086"
"259.2000","5.1827","8.07397","0.05095"
"259.6000","5.1907","8.07462","0.05104"
"260.0000","5.1986","8.07528","0.05113"
"260.4000","5.2065","8.07436","0.05122"
"260.8000","5.2148","8.07810","0.05131"
"261.2000","5.2224","8.07530","0.05140"
"261.6000","5.2305","8.07673","0.05149"
"262.0000","5.2386","8.07906","0.05158"
"262.4000","5.2467","8.08075","0.05168"
"262.8000","5.2546","8.08065","0.05176"
"263.2000","5.2625","8.07946","0.05185"
"263.6000","5.2708","8.08360","0.05195"
"264.0000","5.2783","8.08021","0.05203"
"264.4000","5.2865","8.08213","0.05213"
"264.8000","5.2947","8.08502","0.05222"
"265.2000","5.3027","8.08511","0.05231"
"265.6000","5.3105","8.08480","0.05240"
"266.0000","5.3185","8.08494","0.05249"
"266.4000","5.3268","8.08930","0.05258"
"266.8000","5.3344","8.08594","0.05267"
"267.2000","5.3426","8.08736","0.05276"
"267.6000","5.3506","8.08913","0.05285"
"268.0000","5.3587","8.09036","0.05294"
"268.4000","5.3665","8.09016","0.05304"
"268.8000","5.3746","8.09039","0.05313"
"269.2000","5.3829","8.09479","0.05322"
"269.6000","5.3903","8.08979","0.05331"
"270.0000","5.3985","8.09182","0.05340"
"270.4000","5.4066","8.09462","0.05349"
"270.8000","5.4147","8.09522","0.05358"
"271.2000","5.4225","8.09466","0.05367"
"271.6000","5.4306","8.09584","0.05376"
"272.0000","5.4388","8.09881","0.05386"
"272.4000","5.4463","8.09441","0.05394"
"272.8000","5.4545","8.09767","0.05403"
"273.2000","5.4627","8.09976","0.05413"
"273.6000","5.4707","8.10019","0.05422"
"274.0000","5.4785","8.09957","0.05431"
"274.4000","5.4866","8.10066","0.05440"
"274.8000","5.4949","8.10471","0.05449"
"275.2000","5.5023","8.09958","0.05458"
"275.6000","5.5106","8.10212","0.05467"
"276.0000","5.5186","8.10435","0.05476"
"276.4000","5.5266","8.10366","0.05486"
"276.8000","5.5345","8.10411","0.05494"
"277.2000","5.5427","8.10668","0.05504"
"277.6000","5.5509","8.10898","0.05513"
"278.0000","5.5584","8.10424","0.05522"
"278.4000","5.5666","8.10718","0.05531"
"278.8000","5.5745","8.10824","0.05540"
"279.2000","5.5827","8.10976","0.05550"
"279.6000","5.5905","8.10866","0.05558"
"280.0000","5.5987","8.11059","0.05568"
"280.4000","5.6068","8.11339","0.05577"
"280.8000","5.6143","8.10825","0.05586"
"281.2000","5.6227","8.11240","0.05595"
"281.6000","5.6306","8.11336","0.05604"
"282.0000","5.6386","8.11260","0.05613"
"282.4000","5.6465","8.11339","0.05622"
"282.8000","5.6547","8.11538","0.05632"
"283.2000","5.6627","8.11703","0.05641"
"283.6000","5.6705","8.11402","0.05650"
"284.0000","5.6787","8.11696","0.05659"
"284.4000","5.6866","8.11682","0.05668"
"284.8000","5.6945","8.11692","0.05677"
"285.2000","5.7024","8.11679","0.05686"
"285.6000","5.7108","8.12075","0.05696"
"286.0000","5.7187","8.12132","0.05705"
"286.4000","5.7264","8.11767","0.05714"
"286.8000","5.7347","8.12172","0.05723"
"287.2000","5.7425","8.12058","0.05732"
"287.6000","5.7506","8.12117","0.05741"
"288.0000","5.7585","8.12203","0.05751"
"288.4000","5.7667","8.12435","0.05760"
"288.8000","5.7747","8.12514","0.05769"
"289.2000","5.7824","8.12230","0.05778"
"289.6000","5.7907","8.12599","0.05787"
"290.0000","5.7986","8.12555","0.05796"
"290.4000","5.8066","8.12527","0.05806"
"290.8000","5.8144","8.12502","0.05815"
"291.2000","5.8227","8.12844","0.05824"
"291.6000","5.8306","8.12882","0.05833"
"292.0000","5.8385","8.12688","0.05842"
"292.4000","5.8468","8.13136","0.05852"
"292.8000","5.8545","8.12856","0.05861"
"293.2000","5.8625","8.12894","0.05870"
"293.6000","5.8705","8.12995","0.05879"
"294.0000","5.8787","8.13243","0.05888"
"294.4000","5.8867","8.13305","0.05898"
"294.8000","5.8945","8.13115","0.05907"
"295.2000","5.9027","8.13383","0.05916"
"295.6000","5.9105","8.13282","0.05925"
"296.0000","5.9186","8.13403","0.05935"
"296.4000","5.9265","8.13372","0.05944"
"296.8000","5.9348","8.13658","0.05953"
"297.2000","5.9426","8.13588","0.05962"
"297.6000","5.9505","8.13503","0.05971"
"298.0000","5.9588","8.13918","0.05980"
"298.4000","5.9665","8.13618","0.05989"
"298.8000","5.9746","8.13765","0.05999"
"299.2000","5.9825","8.13756","0.06008"
"299.6000","5.9906","8.13900","0.06017"
"300.0000","5.9986","8.14009","0.06026"
"300.4000","6.0066","8.13991","0.06036"
"300.8000","6.0148","8.14238","0.06045"
"301.2000","6.0225","8.13973","0.06054"
"301.6000","6.0306","8.14073","0.06064"
"302.0000","6.0384","8.14073","0.06073"
"302.4000","6.0467","8.14360","0.06082"
"302.8000","6.0545","8.14278","0.06091"
"303.2000","6.0626","8.14322","0.06101"
"303.6000","6.0707","8.14609","0.06110"
"304.0000","6.0784","8.14321","0.06119"
"304.4000","6.0866","8.14549","0.06128"
"304.8000","6.0945","8.14501","0.06137"
"305.2000","6.1026","8.14645","0.06147"
"305.6000","6.1106","8.14635","0.06156"
"306.0000","6.1186","8.14663","0.06165"
"306.4000","6.1267","8.14934","0.06174"
"306.8000","6.1345","8.14721","0.06183"
"307.2000","6.1427","8.14911","0.06193"
"307.6000","6.1505","8.14767","0.06202"
"308.0000","6.1586","8.15003","0.06211"
"308.4000","6.1665","8.13124","0.06218"
"308.8000","6.1747","8.14376","0.06227"
"309.2000","6.1828","8.15120","0.06236"
"309.6000","6.1905","8.15041","0.06245"
"310.0000","6.1986","8.15281","0.06254"
"310.4000","6.2064","8.15211","0.06263"
"310.8000","6.2146","8.15433","0.06273"
"311.2000","6.2225","8.15410","0.06282"
"311.6000","6.2306","8.15483","0.06291"
"312.0000","6.2387","8.15625","0.06300"
"312.4000","6.2465","8.15480","0.06309"
"312.8000","6.2547","8.15691","0.06319"
"313.2000","6.2625","8.15542","0.06328"
"313.6000","6.2707","8.15739","0.06337"
"314.0000","6.2785","8.15554","0.06346"
"314.4000","6.2866","8.15655","0.06356"
"314.8000","6.2947","8.15984","0.06365"
"315.2000","6.3026","8.15790","0.06374"
"315.6000","6.3107","8.15946","0.06384"
"316.0000","6.3184","8.15742","0.06393"
"316.4000","6.3266","8.15957","0.06402"
"316.8000","6.3344","8.15887","0.06411"
"317.2000","6.3426","8.16042","0.06421"
"317.6000","6.3507","8.16202","0.06430"
"318.0000","6.3586","8.16103","0.06439"
"318.4000","6.3667","8.16208","0.06449"
"318.8000","6.3744","8.15963","0.06458"
"319.2000","6.3827","8.16351","0.06467"
"319.6000","6.3905","8.16179","0.06476"
"320.0000","6.3986","8.16225","0.06486"
"320.4000","6.4066","8.16424","0.06495"
"320.8000","6.4145","8.16371","0.06504"
"321.2000","6.4227","8.16542","0.06514"
"321.6000","6.4305","8.16336","0.06523"
"322.0000","6.4387","8.16543","0.06532"
"322.4000","6.4465","8.16410","0.06541"
"322.8000","6.4545","8.16515","0.06551"
"323.2000","6.4626","8.16719","0.06560"
"323.6000","6.4707","8.16749","0.06569"
"324.0000","6.4787","8.16807","0.06579"
"324.4000","6.4865","8.16549","0.06588"
"324.8000","6.4947","8.16874","0.06597"
"325.2000","6.5024","8.16670","0.06607"
"325.6000","6.5106","8.16839","0.06616"
"326.0000","6.5187","8.17000","0.06625"
"326.4000","6.5266","8.16954","0.06635"
"326.8000","6.5347","8.17002","0.06644"
"327.2000","6.5425","8.16842","0.06653"
"327.6000","6.5507","8.17147","0.06663"
"328.0000","6.5585","8.16952","0.06672"
"328.4000","6.5666","8.17070","0.06682"
"328.8000","6.5746","8.17145","0.06691"
"329.2000","6.5826","8.17199","0.06700"
"329.6000","6.5906","8.17299","0.06709"
"330.0000","6.5985","8.17133","0.06719"
"330.4000","6.6068","8.17453","0.06728"
"330.8000","6.6144","8.17115","0.06737"
"331.2000","6.6226","8.17275","0.06747"
"331.6000","6.6306","8.17451","0.06756"
"332.0000","6.6386","8.17462","0.06765"
"332.4000","6.6467","8.17523","0.06775"
"332.8000","6.6545","8.17395","0.06784"
"333.2000","6.6627","8.17619","0.06794"
"333.6000","6.6704","8.17390","0.06803"
"334.0000","6.6787","8.17607","0.06812"
"334.4000","6.6866","8.17618","0.06822"
"334.8000","6.6947","8.17702","0.06831"
"335.2000","6.7026","8.17692","0.06841"
"335.6000","6.7105","8.17609","0.06850"
"336.0000","6.7187","8.17921","0.06859"
"336.4000","6.7264","8.17594","0.06869"
"336.8000","6.7347","8.17828","0.06878"
"337.2000","6.7425","8.17815","0.06887"
"337.6000","6.7505","8.17782","0.06897"
"338.0000","6.7587","8.18028","0.06906"
"338.4000","6.7666","8.17936","0.06915"
"338.8000","6.7747","8.18056","0.06925"
"339.2000","6.7824","8.17806","0.06934"
"339.6000","6.7906","8.18032","0.06944"
"340.0000","6.7985","8.18002","0.06953"
"340.4000","6.8066","8.18073","0.06962"
"340.8000","6.8146","8.18144","0.06972"
"341.2000","6.8226","8.18146","0.06981"
"341.6000","6.8306","8.18251","0.06990"
"342.0000","6.8383","8.17942","0.07000"
"342.4000","6.8467","8.18310","0.07009"
"342.8000","6.8545","8.18231","0.07018"
"343.2000","6.8626","8.18211","0.07028"
"343.6000","6.8707","8.18354","0.07037"
"344.0000","6.8786","8.18333","0.07046"
"344.4000","6.8867","8.18477","0.07056"
"344.8000","6.8945","8.18230","0.07065"
"345.2000","6.9027","8.18481","0.07075"
"345.6000","6.9105","8.18316","0.07084"
"346.0000","6.9185","8.18348","0.07093"
"346.4000","6.9266","8.18561","0.07103"
"346.8000","6.9347","8.18617","0.07112"
"347.2000","6.9426","8.18602","0.07121"
"347.6000","6.9504","8.18366","0.07130"
"348.0000","6.9588","8.18729","0.07140"
"348.4000","6.9664","8.18450","0.07149"
"348.8000","6.9745","8.18533","0.07159"
"349.2000","6.9827","8.18738","0.07168"
"349.6000","6.9907","8.18743","0.07177"
"350.0000","6.9986","8.18685","0.07187"
"350.4000","7.0064","8.18560","0.07195"
"350.8000","7.0148","8.18946","0.07205"
"351.2000","7.0225","8.18662","0.07214"
"351.6000","7.0305","8.18694","0.07224"
"352.0000","7.0386","8.18842","0.07233"
"352.4000","7.0467","8.18920","0.07242"
"352.8000","7.0546","8.18911","0.07252"
"353.2000","7.0625","8.18729","0.07261"
"353.6000","7.0708","8.19129","0.07270"
"354.0000","7.0784","8.18715","0.07279"
"354.4000","7.0864","8.18770","0.07289"
"354.8000","7.0946","8.19059","0.07298"
"355.2000","7.1027","8.19114","0.07307"
"355.6000","7.1106","8.18968","0.07316"
"356.0000","7.1186","8.18916","0.07326"
"356.4000","7.1268","8.19197","0.07335"
"356.8000","7.1343","8.18816","0.07344"
"357.2000","7.1425","8.19007","0.07353"
"357.6000","7.1507","8.19153","0.07363"
"358.0000","7.1587","8.19203","0.07372"
"358.4000","7.1665","8.19081","0.07381"
"358.8000","7.1745","8.19051","0.07390"
"359.2000","7.1829","8.19478","0.07400"
"359.6000","7.1904","8.18950","0.07408"
"360.0000","7.1985","8.19089","0.07418"
"360.4000","7.2067","8.19284","0.07427"
"360.8000","7.2146","8.19198","0.07436"
"361.2000","7.2225","8.19212","0.07445"
"361.6000","7.2306","8.19268","0.07455"
"362.0000","7.2389","8.19524","0.07464"
"362.4000","7.2464","8.19014","0.07473"
"362.8000","7.2545","8.19195","0.07482"
"363.2000","7.2626","8.19353","0.07491"
"363.6000","7.2707","8.19417","0.07500"
"364.0000","7.2785","8.19256","0.07509"
"364.4000","7.2866","8.19338","0.07518"
"364.8000","7.2949","8.19620","0.07528"
"365.2000","7.3023","8.19055","0.07536"
"365.6000","7.3106","8.19343","0.07546"
"366.0000","7.3187","8.19495","0.07555"
"366.4000","7.3266","8.19371","0.07564"
"366.8000","7.3345","8.19300","0.07573"
"367.2000","7.3426","8.19468","0.07582"
"367.6000","7.3508","8.19711","0.07591"
"368.0000","7.3584","8.19243","0.07600"
"368.4000","7.3666","8.19464","0.07609"
"368.8000","7.3746","8.19470","0.07618"
"369.2000","7.3826","8.19434","0.07627"
"369.6000","7.3904","8.19411","0.07636"
"370.0000","7.3987","8.19584","0.07645"
"370.4000","7.4068","8.19770","0.07654"
"370.8000","7.4143","8.19214","0.07662"
"371.2000","7.4226","8.19495","0.07671"
"371.6000","7.4305","8.19514","0.07680"
"372.0000","7.4386","8.19504","0.07689"
"372.4000","7.4465","8.19445","0.07698"
"372.8000","7.4547","8.19653","0.07707"
"373.2000","7.4627","8.19691","0.07716"
"373.6000","7.4704","8.19294","0.07724"
"374.0000","7.4787","8.19636","0.07733"
"374.4000","7.4866","8.19549","0.07742"
"374.8000","7.4946","8.19528","0.07750"
"375.2000","7.5025","8.19451","0.07759"
"375.6000","7.5107","8.19652","0.07768"
"376.0000","7.5188","8.19812","0.07777"
"376.4000","7.5264","8.19336","0.07785"
"376.8000","7.5347","8.19644","0.07794"
"377.2000","7.5426","8.19539","0.07803"
"377.6000","7.5505","8.19465","0.07811"
"378.0000","7.5585","8.19483","0.07820"
"378.4000","7.5668","8.19696","0.07828"
"378.8000","7.5747","8.19656","0.07837"
"379.2000","7.5825","8.19367","0.07845"
"379.6000","7.5907","8.19650","0.07853"
"380.0000","7.5984","8.19431","0.07862"
"380.4000","7.6066","8.19555","0.07870"
"380.8000","7.6145","8.19433","0.07879"
"381.2000","7.6227","8.19623","0.07887"
"381.6000","7.6307","8.19624","0.07895"
"382.0000","7.6384","8.19312","0.07903"
"382.4000","7.6468","8.19688","0.07912"
"382.8000","7.6545","8.19432","0.07920"
"383.2000","7.6626","8.19406","0.07928"
"383.6000","7.6705","8.19399","0.07936"
"384.0000","7.6786","8.19496","0.07944"
"384.4000","7.6866","8.19493","0.07952"
"384.8000","7.6946","8.19368","0.07960"
"385.2000","7.7028","8.19591","0.07968"
"385.6000","7.7105","8.19267","0.07976"
"386.0000","7.7186","8.19315","0.07984"
"386.4000","7.7264","8.19232","0.07992"
"386.8000","7.7347","8.19463","0.08000"
"387.2000","7.7426","8.19385","0.08007"
"387.6000","7.7505","8.19211","0.08015"
"388.0000","7.7587","8.19473","0.08023"
"388.4000","7.7664","8.19146","0.08030"
"388.8000","7.7746","8.19244","0.08038"
"389.2000","7.7826","8.19183","0.08045"
"389.6000","7.7907","8.19272","0.08052"
"390.0000","7.7985","8.19123","0.08060"
"390.4000","7.8066","8.19085","0.08067"
"390.8000","7.8147","8.19322","0.08074"
"391.2000","7.8225","8.18964","0.08081"
"391.6000","7.8306","8.19069","0.08088"
"392.0000","7.8385","8.18878","0.08095"
"392.4000","7.8466","8.18976","0.08103"
"392.8000","7.8545","8.18922","0.08109"
"393.2000","7.8626","8.18845","0.08116"
"393.6000","7.8708","8.19050","0.08123"
"394.0000","7.8785","8.18651","0.08129"
"394.4000","7.8866","8.18716","0.08136"
"394.8000","7.8945","8.18605","0.08142"
"395.2000","7.9026","8.18695","0.08149"
"395.6000","7.9105","8.18558","0.08155"
"396.0000","7.9187","8.18540","0.08162"
"396.4000","7.9267","8.18602","0.08168"
"396.8000","7.9345","8.18319","0.08174"
"397.2000","7.9427","8.18443","0.08180"
"397.6000","7.9505","8.18141","0.08186"
"398.0000","7.9587","8.18324","0.08192"
"398.4000","7.9665","8.18053","0.08197"
"398.8000","7.9746","8.18005","0.08203"
"399.2000","7.9828","8.18233","0.08208"
"399.6000","7.9905","8.17796","0.08214"
"400.0000","7.9987","8.17862","0.08219"
"400.4000","8.0065","8.17552","0.08224"
"400.8000","8.0145","8.17571","0.08230"
"401.2000","8.0225","8.17517","0.08235"
"401.6000","8.0306","8.17424","0.08240"
"402.0000","8.0387","8.17415","0.08244"
"402.4000","8.0466","8.17170","0.08249"
"402.8000","8.0546","8.17095","0.08254"
"403.2000","8.0624","8.16759","0.08258"
"403.6000","8.0707","8.16919","0.08262"
"404.0000","8.0785","8.16584","0.08267"
"404.4000","8.0867","8.16536","0.08271"
"404.8000","8.0946","8.16542","0.08275"
"405.2000","8.1025","8.16162","0.08278"
"405.6000","8.1107","8.16255","0.08282"
"406.0000","8.1185","8.15815","0.08286"
"406.4000","8.1266","8.15750","0.08290"
"406.8000","8.1345","8.15523","0.08293"
"407.2000","8.1425","8.15308","0.08296"
"407.6000","8.1507","8.15345","0.08300"
"408.0000","8.1586","8.15054","0.08303"
"408.4000","8.1667","8.14845","0.08306"
"408.8000","8.1745","8.14379","0.08308"
"409.2000","8.1826","8.14396","0.08311"
"409.6000","8.1904","8.13984","0.08314"
"410.0000","8.1987","8.13900","0.08316"
"410.4000","8.2067","8.13717","0.08319"
"410.8000","8.2146","8.13263","0.08321"
"411.2000","8.2227","8.13152","0.08323"
"411.6000","8.2304","8.12574","0.08325"
"412.0000","8.2387","8.12585","0.08327"
"412.4000","8.2465","8.12094","0.08329"
"412.8000","8.2546","8.11749","0.08331"
"413.2000","8.2626","8.11576","0.08332"
"413.6000","8.2706","8.11174","0.08334"
"414.0000","8.2787","8.10881","0.08336"
"414.4000","8.2865","8.10279","0.08337"
"414.8000","8.2947","8.10163","0.08338"
"415.2000","8.3025","8.09450","0.08339"
"415.6000","8.3106","8.09127","0.08341"
"416.0000","8.3186","8.08894","0.08342"
"416.4000","8.3267","8.08417","0.08343"
"416.8000","8.3347","8.07939","0.08344"
"417.2000","8.3425","8.07219","0.08345"
"417.6000","8.3506","8.07019","0.08346"
"418.0000","8.3584","8.06318","0.08346"
"418.4000","8.3666","8.05852","0.08347"
"418.8000","8.3746","8.05409","0.08347"
"419.2000","8.3827","8.04840","0.08348"
"419.6000","8.3907","8.04253","0.08348"
"420.0000","8.3985","8.03448","0.08349"
"420.4000","8.4067","8.03193","0.08349"
"420.8000","8.4145","8.02217","0.08349"
"421.2000","8.4226","8.01630","0.08350"
"421.6000","8.4306","8.01118","0.08350"
"422.0000","8.4385","8.00377","0.08350"
"422.4000","8.4467","7.99832","0.08350"
"422.8000","8.4546","7.98862","0.08350"
"423.2000","8.4627","7.98317","0.08350"
"423.6000","8.4704","7.97272","0.08350"
"424.0000","8.4786","7.96617","0.08350"
"424.4000","8.4865","7.95919","0.08350"
"424.8000","8.4946","7.95102","0.08350"
"425.2000","8.5026","7.94223","0.08350"
"425.6000","8.5106","7.93236","0.08350"
"426.0000","8.5187","7.92595","0.08350"
"426.4000","8.5263","7.91282","0.08349"
"426.8000","8.5347","7.90592","0.08349"
"427.2000","8.5426","7.89693","0.08349"
"427.6000","8.5506","7.88582","0.08348"
"428.0000","8.5586","7.87730","0.08348"
"428.4000","8.5666","7.86600","0.08348"
"428.8000","8.5747","7.85808","0.08347"
"429.2000","8.5825","7.84344","0.08347"
"429.6000","8.5907","7.83401","0.08347"
"430.0000","8.5985","7.82320","0.08346"
"430.4000","8.6065","7.81115","0.08346"
"430.8000","8.6146","7.80079","0.08345"
"431.2000","8.6227","7.78739","0.08344"
"431.6000","8.6307","7.77703","0.08344"
"432.0000","8.6384","7.76026","0.08343"
"432.4000","8.6467","7.74983","0.08343"
"432.8000","8.6544","7.73678","0.08342"
"433.2000","8.6625","7.72245","0.08341"
"433.6000","8.6707","7.70955","0.08341"
"434.0000","8.6787","7.69439","0.08340"
"434.4000","8.6866","7.68062","0.08339"
"434.8000","8.6944","7.66235","0.08338"
"435.2000","8.7027","7.64933","0.08338"
"435.6000","8.7105","7.63219","0.08337"
"436.0000","8.7186","7.61452","0.08336"
"436.4000","8.7266","7.59916","0.08335"
"436.8000","8.7346","7.58119","0.08334"
"437.2000","8.7426","7.56411","0.08333"
"437.6000","8.7505","7.54024","0.08332"
"438.0000","8.7588","7.52224","0.08330"
"438.4000","8.7664","7.49976","0.08329"
"438.8000","8.7744","7.47448","0.08327"
"439.2000","8.7826","7.45052","0.08326"
"439.6000","8.7908","7.41703","0.08324"
"440.0000","8.7986","7.37680","0.08321"
"440.4000","8.8065","7.32316","0.08318"
"440.8000","8.8148","7.24897","0.08313"
"441.2000","8.8224","7.13716","0.08305"
"441.5330","8.8293","6.90130","0.08288"
"441.7380","8.8336","6.59841","0.08266"
"442.1380","8.8415","6.40915","0.08252"
"442.5380","8.8493","6.24316","0.08240"
"442.9320","8.8574","6.01197","0.08225"
"443.0870","8.8606","5.70796","0.08205"
"443.1990","8.8627","5.40358","0.08186"
"443.2890","8.8645","5.09573","0.08166"
"443.3530","8.8659","4.91690","0.08154"