File: Coupon Test Data/Tensile Test_Neebajan_Alan_1.csv
Time,Displacement,Force,Strain 1
(s),(mm),(kN),(mm/mm)
"0.0000","0.0000","0.22379","-0.00006"
"0.4000","0.0065","0.30092","-0.00003"
"0.8000","0.0142","0.40266","0.00002"
"1.2000","0.0223","0.50525","0.00007"
"1.6000","0.0303","0.60406","0.00011"
"2.0000","0.0384","0.70377","0.00016"
"2.4000","0.0464","0.79288","0.00020"
"2.8000","0.0544","0.88841","0.00024"
"3.2000","0.0625","0.98017","0.00029"
"3.6000","0.0703","1.07097","0.00033"
"4.0000","0.0784","1.16100","0.00037"
"4.4000","0.0864","1.25100","0.00041"
"4.8000","0.0944","1.33836","0.00045"
"5.2000","0.1023","1.42333","0.00049"
"5.6000","0.1104","1.51064","0.00054"
"6.0000","0.1185","1.59687","0.00057"
"6.4000","0.1263","1.67018","0.00061"
"6.8000","0.1345","1.75526","0.00065"
"7.2000","0.1423","1.83615","0.00069"
"7.6000","0.1504","1.91801","0.00073"
"8.0000","0.1583","1.99053","0.00076"
"8.4000","0.1665","2.07196","0.00080"
"8.8000","0.1746","2.15263","0.00084"
"9.2000","0.1824","2.22823","0.00087"
"9.6000","0.1904","2.30145","0.00091"
"10.0000","0.1983","2.37395","0.00094"
"10.4000","0.2064","2.45168","0.00098"
"10.8000","0.2143","2.52521","0.00101"
"11.2000","0.2224","2.59710","0.00105"
"11.6000","0.2305","2.66864","0.00108"
"12.0000","0.2383","2.73993","0.00111"
"12.4000","0.2465","2.81363","0.00115"
"12.8000","0.2543","2.87789","0.00118"
"13.2000","0.2624","2.94920","0.00121"
"13.6000","0.2703","3.01810","0.00125"
"14.0000","0.2784","3.08692","0.00128"
"14.4000","0.2864","3.15044","0.00131"
"14.8000","0.2944","3.21741","0.00134"
"15.2000","0.3025","3.28445","0.00137"
"15.6000","0.3103","3.34774","0.00140"
"16.0000","0.3184","3.40896","0.00143"
"16.4000","0.3262","3.47185","0.00146"
"16.8000","0.3344","3.53588","0.00149"
"17.2000","0.3425","3.59895","0.00152"
"17.6000","0.3504","3.65360","0.00155"
"18.0000","0.3585","3.71495","0.00158"
"18.4000","0.3662","3.77352","0.00160"
"18.8000","0.3744","3.83576","0.00163"
"19.2000","0.3823","3.88929","0.00166"
"19.6000","0.3904","3.94904","0.00169"
"20.0000","0.3984","4.01014","0.00172"
"20.4000","0.4064","4.06906","0.00175"
"20.8000","0.4145","4.12163","0.00177"
"21.2000","0.4223","4.17669","0.00180"
"21.6000","0.4305","4.23538","0.00183"
"22.0000","0.4383","4.28914","0.00185"
"22.4000","0.4463","4.34120","0.00188"
"22.8000","0.4544","4.39939","0.00191"
"23.2000","0.4624","4.45643","0.00194"
"23.6000","0.4705","4.50804","0.00196"
"24.0000","0.4783","4.56291","0.00199"
"24.4000","0.4864","4.62174","0.00202"
"24.8000","0.4942","4.67649","0.00205"
"25.2000","0.5024","4.72933","0.00207"
"25.6000","0.5104","4.78731","0.00210"
"26.0000","0.5185","4.84459","0.00213"
"26.4000","0.5265","4.90026","0.00216"
"26.8000","0.5343","4.94985","0.00218"
"27.2000","0.5425","5.00973","0.00221"
"27.6000","0.5503","5.06328","0.00224"
"28.0000","0.5584","5.11494","0.00227"
"28.4000","0.5663","5.17253","0.00230"
"28.8000","0.5743","5.22859","0.00233"
"29.2000","0.5825","5.28547","0.00236"
"29.6000","0.5904","5.33519","0.00238"
"30.0000","0.5985","5.39330","0.00241"
"30.4000","0.6063","5.44631","0.00244"
"30.8000","0.6144","5.49701","0.00247"
"31.2000","0.6223","5.55397","0.00250"
"31.6000","0.6304","5.61042","0.00253"
"32.0000","0.6385","5.66495","0.00256"
"32.4000","0.6464","5.71483","0.00258"
"32.8000","0.6545","5.77234","0.00261"
"33.2000","0.6622","5.82347","0.00264"
"33.6000","0.6705","5.87528","0.00267"
"34.0000","0.6784","5.93195","0.00270"
"34.4000","0.6864","5.98600","0.00273"
"34.8000","0.6944","6.03920","0.00276"
"35.2000","0.7024","6.08979","0.00279"
"35.6000","0.7105","6.14541","0.00282"
"36.0000","0.7183","6.19620","0.00285"
"36.4000","0.7265","6.24538","0.00288"
"36.8000","0.7343","6.29843","0.00291"
"37.2000","0.7423","6.35062","0.00295"
"37.6000","0.7504","6.39753","0.00298"
"38.0000","0.7585","6.44939","0.00301"
"38.4000","0.7665","6.50175","0.00305"
"38.8000","0.7742","6.54359","0.00308"
"39.2000","0.7825","6.59538","0.00311"
"39.6000","0.7903","6.64184","0.00315"
"40.0000","0.7983","6.68659","0.00318"
"40.4000","0.8065","6.73425","0.00322"
"40.8000","0.8145","6.77669","0.00326"
"41.2000","0.8224","6.81938","0.00330"
"41.6000","0.8302","6.85690","0.00334"
"42.0000","0.8385","6.89884","0.00339"
"42.4000","0.8463","6.93528","0.00343"
"42.8000","0.8544","6.96929","0.00348"
"43.2000","0.8624","7.00343","0.00353"
"43.6000","0.8705","7.03478","0.00359"
"44.0000","0.8784","7.06372","0.00364"
"44.4000","0.8863","7.08600","0.00371"
"44.8000","0.8946","7.11266","0.00377"
"45.2000","0.9022","7.13196","0.00384"
"45.6000","0.9103","7.14969","0.00391"
"46.0000","0.9185","7.17005","0.00399"
"46.4000","0.9266","7.17632","0.00405"
"46.8000","0.9344","7.19440","0.00412"
"47.2000","0.9423","7.20726","0.00420"
"47.6000","0.9506","7.22106","0.00428"
"48.0000","0.9582","7.22892","0.00437"
"48.4000","0.9663","7.23893","0.00445"
"48.8000","0.9745","7.24951","0.00454"
"49.2000","0.9826","7.25855","0.00463"
"49.6000","0.9903","7.26546","0.00472"
"50.0000","0.9982","7.27001","0.00481"
"50.4000","1.0067","7.28092","0.00490"
"50.8000","1.0143","7.28345","0.00499"
"51.2000","1.0224","7.28850","0.00509"
"51.6000","1.0305","7.29624","0.00518"
"52.0000","1.0384","7.30111","0.00527"
"52.4000","1.0463","7.30548","0.00537"
"52.8000","1.0543","7.30414","0.00546"
"53.2000","1.0626","7.31421","0.00555"
"53.6000","1.0702","7.31559","0.00564"
"54.0000","1.0783","7.32009","0.00573"
"54.4000","1.0865","7.32605","0.00583"
"54.8000","1.0946","7.32941","0.00593"
"55.2000","1.1024","7.33151","0.00602"
"55.6000","1.1104","7.33352","0.00612"
"56.0000","1.1187","7.34055","0.00622"
"56.4000","1.1261","7.33828","0.00631"
"56.8000","1.1343","7.34245","0.00641"
"57.2000","1.1425","7.34791","0.00651"
"57.6000","1.1505","7.34957","0.00661"
"58.0000","1.1583","7.35136","0.00671"
"58.4000","1.1664","7.35392","0.00681"
"58.8000","1.1747","7.35996","0.00691"
"59.2000","1.1822","7.35708","0.00700"
"59.6000","1.1904","7.36049","0.00710"
"60.0000","1.1985","7.36457","0.00720"
"60.4000","1.2065","7.36662","0.00730"
"60.8000","1.2143","7.36855","0.00740"
"61.2000","1.2225","7.37049","0.00750"
"61.6000","1.2307","7.37599","0.00760"
"62.0000","1.2381","7.37203","0.00769"
"62.4000","1.2464","7.37604","0.00779"
"62.8000","1.2544","7.38032","0.00789"
"63.2000","1.2625","7.38147","0.00799"
"63.6000","1.2704","7.38260","0.00809"
"64.0000","1.2785","7.38555","0.00819"
"64.4000","1.2866","7.38928","0.00829"
"64.8000","1.2941","7.38640","0.00838"
"65.2000","1.3024","7.39092","0.00848"
"65.6000","1.3105","7.39366","0.00858"
"66.0000","1.3184","7.39478","0.00868"
"66.4000","1.3263","7.39579","0.00877"
"66.8000","1.3345","7.39889","0.00887"
"67.2000","1.3427","7.40387","0.00897"
"67.6000","1.3502","7.39921","0.00907"
"68.0000","1.3585","7.40354","0.00916"
"68.4000","1.3664","7.40628","0.00926"
"68.8000","1.3743","7.40652","0.00936"
"69.2000","1.3823","7.40890","0.00945"
"69.6000","1.3906","7.41246","0.00955"
"70.0000","1.3986","7.41492","0.00965"
"70.4000","1.4062","7.41201","0.00975"
"70.8000","1.4144","7.41635","0.00984"
"71.2000","1.4223","7.41783","0.00994"
"71.6000","1.4304","7.41978","0.01003"
"72.0000","1.4383","7.42076","0.01013"
"72.4000","1.4466","7.42407","0.01023"
"72.8000","1.4546","7.42698","0.01032"
"73.2000","1.4622","7.42377","0.01042"
"73.6000","1.4705","7.42913","0.01052"
"74.0000","1.4784","7.43024","0.01061"
"74.4000","1.4864","7.43067","0.01071"
"74.8000","1.4943","7.43248","0.01080"
"75.2000","1.5025","7.43590","0.01090"
"75.6000","1.5105","7.43851","0.01099"
"76.0000","1.5183","7.43641","0.01109"
"76.4000","1.5265","7.42811","0.01116"
"76.8000","1.5344","7.43847","0.01125"
"77.2000","1.5424","7.44286","0.01134"
"77.6000","1.5503","7.44475","0.01143"
"78.0000","1.5585","7.44802","0.01153"
"78.4000","1.5665","7.44996","0.01162"
"78.8000","1.5743","7.44789","0.01172"
"79.2000","1.5826","7.45257","0.01181"
"79.6000","1.5903","7.45199","0.01190"
"80.0000","1.5984","7.45369","0.01200"
"80.4000","1.6064","7.45593","0.01209"
"80.8000","1.6145","7.45860","0.01219"
"81.2000","1.6224","7.45962","0.01228"
"81.6000","1.6303","7.45939","0.01237"
"82.0000","1.6386","7.46438","0.01247"
"82.4000","1.6463","7.46298","0.01256"
"82.8000","1.6544","7.46494","0.01265"
"83.2000","1.6623","7.44699","0.01272"
"83.6000","1.6705","7.46548","0.01280"
"84.0000","1.6784","7.47183","0.01289"
"84.4000","1.6864","7.47222","0.01299"
"84.8000","1.6946","7.47623","0.01308"
"85.2000","1.7023","7.47448","0.01317"
"85.6000","1.7104","7.47612","0.01326"
"86.0000","1.7183","7.47803","0.01336"
"86.4000","1.7265","7.48091","0.01345"
"86.8000","1.7344","7.48150","0.01354"
"87.2000","1.7424","7.48253","0.01363"
"87.6000","1.7506","7.48630","0.01373"
"88.0000","1.7582","7.48441","0.01382"
"88.4000","1.7664","7.48772","0.01391"
"88.8000","1.7744","7.48849","0.01400"
"89.2000","1.7825","7.49125","0.01410"
"89.6000","1.7904","7.49251","0.01419"
"90.0000","1.7984","7.49325","0.01428"
"90.4000","1.8066","7.49809","0.01437"
"90.8000","1.8143","7.49589","0.01446"
"91.2000","1.8224","7.49818","0.01455"
"91.6000","1.8303","7.49938","0.01465"
"92.0000","1.8384","7.50179","0.01474"
"92.4000","1.8463","7.50312","0.01483"
"92.8000","1.8545","7.50528","0.01492"
"93.2000","1.8626","7.50816","0.01501"
"93.6000","1.8703","7.50714","0.01510"
"94.0000","1.8785","7.50976","0.01519"
"94.4000","1.8862","7.50985","0.01529"
"94.8000","1.8945","7.51357","0.01538"
"95.2000","1.9023","7.51411","0.01547"
"95.6000","1.9104","7.51568","0.01556"
"96.0000","1.9185","7.51945","0.01565"
"96.4000","1.9263","7.51824","0.01574"
"96.8000","1.9345","7.52145","0.01583"
"97.2000","1.9424","7.52162","0.01592"
"97.6000","1.9505","7.52399","0.01602"
"98.0000","1.9583","7.52463","0.01611"
"98.4000","1.9664","7.52649","0.01620"
"98.8000","1.9745","7.53028","0.01629"
"99.2000","1.9824","7.52958","0.01638"
"99.6000","1.9905","7.53249","0.01647"
"100.0000","1.9983","7.53169","0.01656"
"100.4000","2.0064","7.53518","0.01665"
"100.8000","2.0143","7.53595","0.01674"
"101.2000","2.0225","7.53782","0.01683"
"101.6000","2.0306","7.54146","0.01692"
"102.0000","2.0384","7.54033","0.01701"
"102.4000","2.0465","7.54298","0.01710"
"102.8000","2.0542","7.54274","0.01719"
"103.2000","2.0624","7.54608","0.01728"
"103.6000","2.0704","7.54708","0.01737"
"104.0000","2.0784","7.54843","0.01746"
"104.4000","2.0864","7.55138","0.01755"
"104.8000","2.0944","7.55238","0.01764"
"105.2000","2.1025","7.55479","0.01774"
"105.6000","2.1103","7.55328","0.01782"
"106.0000","2.1185","7.55778","0.01792"
"106.4000","2.1263","7.55688","0.01801"
"106.8000","2.1344","7.55868","0.01809"
"107.2000","2.1424","7.56310","0.01818"
"107.6000","2.1504","7.56314","0.01828"
"108.0000","2.1586","7.56556","0.01837"
"108.4000","2.1662","7.56400","0.01845"
"108.8000","2.1744","7.56753","0.01854"
"109.2000","2.1823","7.56881","0.01864"
"109.6000","2.1904","7.57025","0.01873"
"110.0000","2.1985","7.57323","0.01882"
"110.4000","2.2065","7.57440","0.01891"
"110.8000","2.2145","7.57577","0.01900"
"111.2000","2.2223","7.57498","0.01909"
"111.6000","2.2305","7.57956","0.01918"
"112.0000","2.2383","7.57844","0.01926"
"112.4000","2.2465","7.58133","0.01935"
"112.8000","2.2544","7.58353","0.01945"
"113.2000","2.2624","7.58405","0.01953"
"113.6000","2.2706","7.58708","0.01962"
"114.0000","2.2783","7.57642","0.01969"
"114.4000","2.2865","7.58785","0.01978"
"114.8000","2.2943","7.58942","0.01986"
"115.2000","2.3024","7.59138","0.01995"
"115.6000","2.3104","7.59488","0.02004"
"116.0000","2.3185","7.59650","0.02013"
"116.4000","2.3264","7.59698","0.02022"
"116.8000","2.3344","7.59743","0.02031"
"117.2000","2.3425","7.60076","0.02040"
"117.6000","2.3502","7.59897","0.02048"
"118.0000","2.3585","7.60270","0.02058"
"118.4000","2.3664","7.60469","0.02067"
"118.8000","2.3745","7.60587","0.02076"
"119.2000","2.3825","7.60751","0.02084"
"119.6000","2.3903","7.60723","0.02093"
"120.0000","2.3985","7.61169","0.02102"
"120.4000","2.4063","7.61010","0.02111"
"120.8000","2.4145","7.61217","0.02120"
"121.2000","2.4224","7.61477","0.02129"
"121.6000","2.4303","7.61531","0.02138"
"122.0000","2.4385","7.61813","0.02147"
"122.4000","2.4465","7.61845","0.02156"
"122.8000","2.4546","7.62188","0.02164"
"123.2000","2.4623","7.61925","0.02173"
"123.6000","2.4704","7.62239","0.02182"
"124.0000","2.4783","7.62478","0.02191"
"124.4000","2.4864","7.62465","0.02200"
"124.8000","2.4945","7.61669","0.02207"
"125.2000","2.5024","7.62575","0.02216"
"125.6000","2.5105","7.63149","0.02224"
"126.0000","2.5182","7.63091","0.02233"
"126.4000","2.5265","7.63416","0.02242"
"126.8000","2.5344","7.63549","0.02251"
"127.2000","2.5424","7.63637","0.02259"
"127.6000","2.5505","7.63821","0.02268"
"128.0000","2.5584","7.63917","0.02277"
"128.4000","2.5665","7.64233","0.02286"
"128.8000","2.5742","7.64006","0.02295"
"129.2000","2.5825","7.64397","0.02304"
"129.6000","2.5903","7.64454","0.02312"
"130.0000","2.5983","7.64500","0.02321"
"130.4000","2.6065","7.64925","0.02330"
"130.8000","2.6145","7.65041","0.02339"
"131.2000","2.6225","7.65172","0.02348"
"131.6000","2.6303","7.65020","0.02357"
"132.0000","2.6385","7.65385","0.02366"
"132.4000","2.6462","7.65411","0.02374"
"132.8000","2.6544","7.65592","0.02383"
"133.2000","2.6624","7.65824","0.02392"
"133.6000","2.6705","7.66045","0.02401"
"134.0000","2.6784","7.66155","0.02410"
"134.4000","2.6862","7.65983","0.02418"
"134.8000","2.6946","7.66515","0.02427"
"135.2000","2.7023","7.66495","0.02436"
"135.6000","2.7103","7.66510","0.02445"
"136.0000","2.7185","7.66862","0.02454"
"136.4000","2.7265","7.66981","0.02463"
"136.8000","2.7344","7.67157","0.02471"
"137.2000","2.7423","7.67073","0.02480"
"137.6000","2.7506","7.67476","0.02489"
"138.0000","2.7582","7.67326","0.02498"
"138.4000","2.7663","7.67504","0.02506"
"138.8000","2.7744","7.67862","0.02515"
"139.2000","2.7826","7.68072","0.02524"
"139.6000","2.7904","7.68094","0.02533"
"140.0000","2.7983","7.68030","0.02542"
"140.4000","2.8066","7.68518","0.02551"
"140.8000","2.8142","7.68295","0.02559"
"141.2000","2.8223","7.68524","0.02568"
"141.6000","2.8305","7.68898","0.02577"
"142.0000","2.8385","7.68985","0.02586"
"142.4000","2.8463","7.68995","0.02594"
"142.8000","2.8543","7.69074","0.02603"
"143.2000","2.8626","7.69583","0.02612"
"143.6000","2.8703","7.69304","0.02621"
"144.0000","2.8784","7.69482","0.02630"
"144.4000","2.8864","7.69756","0.02638"
"144.8000","2.8945","7.69917","0.02647"
"145.2000","2.9023","7.70029","0.02656"
"145.6000","2.9104","7.70074","0.02665"
"146.0000","2.9187","7.70561","0.02674"
"146.4000","2.9261","7.70173","0.02682"
"146.8000","2.9343","7.70429","0.02691"
"147.2000","2.9424","7.70816","0.02700"
"147.6000","2.9505","7.70955","0.02709"
"148.0000","2.9584","7.70920","0.02718"
"148.4000","2.9665","7.71089","0.02726"
"148.8000","2.9746","7.71476","0.02735"
"149.2000","2.9821","7.71120","0.02744"
"149.6000","2.9904","7.71470","0.02753"
"150.0000","2.9984","7.71700","0.02761"
"150.4000","3.0065","7.71846","0.02770"
"150.8000","3.0143","7.71866","0.02779"
"151.2000","3.0224","7.72047","0.02788"
"151.6000","3.0307","7.72547","0.02797"
"152.0000","3.0382","7.72104","0.02805"
"152.4000","3.0464","7.72363","0.02814"
"152.8000","3.0545","7.72686","0.02823"
"153.2000","3.0624","7.72688","0.02832"
"153.6000","3.0703","7.72805","0.02840"
"154.0000","3.0785","7.73020","0.02849"
"154.4000","3.0867","7.72458","0.02856"
"154.8000","3.0942","7.72732","0.02864"
"155.2000","3.1024","7.73347","0.02873"
"155.6000","3.1104","7.73610","0.02882"
"156.0000","3.1185","7.73800","0.02890"
"156.4000","3.1263","7.73771","0.02899"
"156.8000","3.1345","7.74025","0.02908"
"157.2000","3.1426","7.74354","0.02917"
"157.6000","3.1501","7.73911","0.02925"
"158.0000","3.1585","7.74358","0.02934"
"158.4000","3.1665","7.74557","0.02943"
"158.8000","3.1744","7.74509","0.02952"
"159.2000","3.1823","7.74618","0.02960"
"159.6000","3.1905","7.74947","0.02969"
"160.0000","3.1986","7.75191","0.02978"
"160.4000","3.2063","7.74897","0.02987"
"160.8000","3.2145","7.75249","0.02995"
"161.2000","3.2224","7.75317","0.03004"
"161.6000","3.2304","7.75402","0.03013"
"162.0000","3.2382","7.75498","0.03021"
"162.4000","3.2466","7.75879","0.03030"
"162.8000","3.2545","7.76069","0.03039"
"163.2000","3.2622","7.75751","0.03048"
"163.6000","3.2705","7.76203","0.03056"
"164.0000","3.2783","7.76183","0.03065"
"164.4000","3.2863","7.76289","0.03074"
"164.8000","3.2944","7.76460","0.03083"
"165.2000","3.3026","7.76748","0.03092"
"165.6000","3.3105","7.76839","0.03100"
"166.0000","3.3182","7.76668","0.03109"
"166.4000","3.3265","7.77150","0.03118"
"166.8000","3.3344","7.77099","0.03126"
"167.2000","3.3424","7.77172","0.03135"
"167.6000","3.3503","7.77236","0.03144"
"168.0000","3.3585","7.77371","0.03152"
"168.4000","3.3665","7.77683","0.03161"
"168.8000","3.3743","7.77523","0.03169"
"169.2000","3.3826","7.77960","0.03178"
"169.6000","3.3903","7.77890","0.03187"
"170.0000","3.3984","7.78017","0.03196"
"170.4000","3.4063","7.78150","0.03204"
"170.8000","3.4145","7.78492","0.03213"
"171.2000","3.4225","7.78564","0.03222"
"171.6000","3.4304","7.78508","0.03230"
"172.0000","3.4385","7.78856","0.03239"
"172.4000","3.4462","7.78724","0.03247"
"172.8000","3.4544","7.78995","0.03257"
"173.2000","3.4624","7.79042","0.03265"
"173.6000","3.4705","7.79284","0.03274"
"174.0000","3.4784","7.79373","0.03283"
"174.4000","3.4863","7.79332","0.03291"
"174.8000","3.4946","7.79809","0.03300"
"175.2000","3.5023","7.79599","0.03309"
"175.6000","3.5104","7.79759","0.03318"
"176.0000","3.5183","7.79892","0.03326"
"176.4000","3.5264","7.80074","0.03335"
"176.8000","3.5343","7.80180","0.03344"
"177.2000","3.5425","7.80314","0.03352"
"177.6000","3.5506","7.80597","0.03361"
"178.0000","3.5583","7.80358","0.03370"
"178.4000","3.5664","7.80609","0.03379"
"178.8000","3.5743","7.80649","0.03387"
"179.2000","3.5825","7.80986","0.03396"
"179.6000","3.5904","7.81011","0.03405"
"180.0000","3.5984","7.81083","0.03414"
"180.4000","3.6066","7.81453","0.03422"
"180.8000","3.6142","7.81216","0.03431"
"181.2000","3.6224","7.81491","0.03440"
"181.6000","3.6304","7.81543","0.03449"
"182.0000","3.6385","7.81725","0.03458"
"182.4000","3.6463","7.81763","0.03466"
"182.8000","3.6544","7.81919","0.03475"
"183.2000","3.6625","7.82248","0.03484"
"183.6000","3.6703","7.82086","0.03493"
"184.0000","3.6785","7.82329","0.03501"
"184.4000","3.6863","7.82285","0.03510"
"184.8000","3.6944","7.82536","0.03519"
"185.2000","3.7023","7.82621","0.03527"
"185.6000","3.7105","7.82772","0.03537"
"186.0000","3.7186","7.83072","0.03545"
"186.4000","3.7263","7.82870","0.03554"
"186.8000","3.7345","7.83098","0.03563"
"187.2000","3.7423","7.83077","0.03571"
"187.6000","3.7504","7.83369","0.03580"
"188.0000","3.7583","7.83375","0.03589"
"188.4000","3.7665","7.83556","0.03598"
"188.8000","3.7745","7.83771","0.03607"
"189.2000","3.7823","7.83685","0.03615"
"189.6000","3.7905","7.84006","0.03624"
"190.0000","3.7983","7.83867","0.03633"
"190.4000","3.8065","7.84138","0.03642"
"190.8000","3.8143","7.84124","0.03650"
"191.2000","3.8224","7.84241","0.03659"
"191.6000","3.8306","7.84660","0.03668"
"192.0000","3.8384","7.84495","0.03677"
"192.4000","3.8465","7.84699","0.03685"
"192.8000","3.8543","7.84590","0.03694"
"193.2000","3.8624","7.84879","0.03703"
"193.6000","3.8702","7.84900","0.03711"
"194.0000","3.8785","7.85124","0.03721"
"194.4000","3.8865","7.85337","0.03729"
"194.8000","3.8945","7.85294","0.03738"
"195.2000","3.9025","7.85475","0.03747"
"195.6000","3.9102","7.85293","0.03755"
"196.0000","3.9185","7.85737","0.03764"
"196.4000","3.9263","7.85667","0.03773"
"196.8000","3.9344","7.85774","0.03782"
"197.2000","3.9425","7.86078","0.03790"
"197.6000","3.9504","7.86059","0.03799"
"198.0000","3.9585","7.86281","0.03808"
"198.4000","3.9663","7.86139","0.03817"
"198.8000","3.9745","7.86427","0.03826"
"199.2000","3.9823","7.86343","0.03834"
"199.6000","3.9904","7.86495","0.03843"
"200.0000","3.9984","7.86771","0.03852"
"200.4000","4.0065","7.86879","0.03860"
"200.8000","4.0145","7.87012","0.03869"
"201.2000","4.0223","7.86818","0.03878"
"201.6000","4.0305","7.87207","0.03887"
"202.0000","4.0382","7.87070","0.03896"
"202.4000","4.0464","7.87285","0.03904"
"202.8000","4.0545","7.87545","0.03914"
"203.2000","4.0625","7.87545","0.03922"
"203.6000","4.0705","7.87651","0.03931"
"204.0000","4.0783","7.87567","0.03940"
"204.4000","4.0865","7.87918","0.03948"
"204.8000","4.0943","7.86672","0.03955"
"205.2000","4.1024","7.87598","0.03964"
"205.6000","4.1104","7.88108","0.03972"
"206.0000","4.1184","7.88357","0.03981"
"206.4000","4.1265","7.88514","0.03990"
"206.8000","4.1344","7.88372","0.03998"
"207.2000","4.1426","7.88765","0.04007"
"207.6000","4.1503","7.88493","0.04016"
"208.0000","4.1584","7.88660","0.04025"
"208.4000","4.1664","7.88931","0.04034"
"208.8000","4.1745","7.89028","0.04043"
"209.2000","4.1825","7.89107","0.04051"
"209.6000","4.1904","7.89013","0.04060"
"210.0000","4.1985","7.89302","0.04069"
"210.4000","4.2062","7.87381","0.04076"
"210.8000","4.2145","7.88392","0.04084"
"211.2000","4.2224","7.89252","0.04092"
"211.6000","4.2305","7.89621","0.04101"
"212.0000","4.2385","7.89829","0.04109"
"212.4000","4.2464","7.89778","0.04118"
"212.8000","4.2545","7.90137","0.04127"
"213.2000","4.2622","7.89850","0.04135"
"213.6000","4.2705","7.90142","0.04144"
"214.0000","4.2783","7.90224","0.04153"
"214.4000","4.2863","7.90229","0.04162"
"214.8000","4.2945","7.90553","0.04171"
"215.2000","4.3025","7.90500","0.04180"
"215.6000","4.3106","7.90689","0.04188"
"216.0000","4.3183","7.90445","0.04197"
"216.4000","4.3264","7.90713","0.04206"
"216.8000","4.3343","7.90771","0.04215"
"217.2000","4.3424","7.90897","0.04224"
"217.6000","4.3504","7.91014","0.04233"
"218.0000","4.3585","7.91164","0.04242"
"218.4000","4.3664","7.91302","0.04250"
"218.8000","4.3742","7.91023","0.04259"
"219.2000","4.3826","7.91475","0.04268"
"219.6000","4.3904","7.91453","0.04277"
"220.0000","4.3984","7.91443","0.04286"
"220.4000","4.4065","7.91702","0.04295"
"220.8000","4.4144","7.91738","0.04304"
"221.2000","4.4225","7.91960","0.04312"
"221.6000","4.4303","7.91725","0.04321"
"222.0000","4.4385","7.91992","0.04330"
"222.4000","4.4463","7.92016","0.04339"
"222.8000","4.4543","7.92023","0.04348"
"223.2000","4.4624","7.92262","0.04357"
"223.6000","4.4706","7.92518","0.04366"
"224.0000","4.4784","7.92465","0.04375"
"224.4000","4.4863","7.92255","0.04383"
"224.8000","4.4946","7.92729","0.04392"
"225.2000","4.5022","7.92503","0.04401"
"225.6000","4.5104","7.92696","0.04410"
"226.0000","4.5185","7.92941","0.04419"
"226.4000","4.5265","7.92994","0.04428"
"226.8000","4.5344","7.93083","0.04437"
"227.2000","4.5422","7.92931","0.04446"
"227.6000","4.5506","7.93325","0.04455"
"228.0000","4.5584","7.93243","0.04463"
"228.4000","4.5663","7.93209","0.04472"
"228.8000","4.5744","7.93448","0.04481"
"229.2000","4.5825","7.93656","0.04490"
"229.6000","4.5903","7.93622","0.04499"
"230.0000","4.5983","7.93557","0.04508"
"230.4000","4.6067","7.94003","0.04517"
"230.8000","4.6142","7.93647","0.04525"
"231.2000","4.6223","7.93828","0.04534"
"231.6000","4.6304","7.94139","0.04543"
"232.0000","4.6385","7.94247","0.04553"
"232.4000","4.6464","7.94213","0.04561"
"232.8000","4.6544","7.94175","0.04570"
"233.2000","4.6626","7.94561","0.04579"
"233.6000","4.6701","7.94233","0.04588"
"234.0000","4.6783","7.94446","0.04597"
"234.4000","4.6865","7.94689","0.04606"
"234.8000","4.6945","7.94757","0.04615"
"235.2000","4.7023","7.94720","0.04624"
"235.6000","4.7103","7.94758","0.04633"
"236.0000","4.7187","7.95261","0.04642"
"236.4000","4.7262","7.94809","0.04651"
"236.8000","4.7344","7.94988","0.04660"
"237.2000","4.7425","7.95260","0.04669"
"237.6000","4.7504","7.95259","0.04678"
"238.0000","4.7583","7.95301","0.04687"
"238.4000","4.7665","7.95447","0.04696"
"238.8000","4.7747","7.95774","0.04705"
"239.2000","4.7822","7.95299","0.04713"
"239.6000","4.7903","7.95545","0.04723"
"240.0000","4.7984","7.95786","0.04732"
"240.4000","4.8065","7.95920","0.04741"
"240.8000","4.8143","7.95819","0.04750"
"241.2000","4.8225","7.95950","0.04759"
"241.6000","4.8307","7.96325","0.04768"
"242.0000","4.8381","7.95793","0.04776"
"242.4000","4.8464","7.96124","0.04786"
"242.8000","4.8545","7.96383","0.04795"
"243.2000","4.8624","7.96310","0.04804"
"243.6000","4.8703","7.96332","0.04813"
"244.0000","4.8784","7.96529","0.04822"
"244.4000","4.8866","7.96833","0.04831"
"244.8000","4.8943","7.96436","0.04840"
"245.2000","4.9025","7.96701","0.04849"
"245.6000","4.9104","7.96801","0.04858"
"246.0000","4.9184","7.96845","0.04867"
"246.4000","4.9263","7.96864","0.04876"
"246.8000","4.9345","7.97078","0.04885"
"247.2000","4.9426","7.97330","0.04894"
"247.6000","4.9501","7.96853","0.04903"
"248.0000","4.9584","7.97218","0.04912"
"248.4000","4.9663","7.97340","0.04921"
"248.8000","4.9744","7.97352","0.04930"
"249.2000","4.9823","7.97374","0.04939"
"249.6000","4.9906","7.97629","0.04948"
"250.0000","4.9986","7.97761","0.04957"
"250.4000","5.0062","7.97392","0.04966"
"250.8000","5.0145","7.97834","0.04976"
"251.2000","5.0224","7.97830","0.04985"
"251.6000","5.0304","7.97838","0.04994"
"252.0000","5.0383","7.97825","0.05003"
"252.4000","5.0465","7.98058","0.05012"
"252.8000","5.0545","7.98285","0.05021"
"253.2000","5.0622","7.97914","0.05030"
"253.6000","5.0705","7.98283","0.05039"
"254.0000","5.0784","7.98264","0.05048"
"254.4000","5.0863","7.98226","0.05057"
"254.8000","5.0943","7.98330","0.05066"
"255.2000","5.1026","7.98640","0.05075"
"255.6000","5.1105","7.98675","0.05084"
"256.0000","5.1183","7.98425","0.05094"
"256.4000","5.1265","7.98796","0.05103"
"256.8000","5.1343","7.98651","0.05112"
"257.2000","5.1424","7.98842","0.05121"
"257.6000","5.1504","7.98799","0.05130"
"258.0000","5.1586","7.99035","0.05139"
"258.4000","5.1665","7.99130","0.05148"
"258.8000","5.1742","7.98868","0.05157"
"259.2000","5.1825","7.99302","0.05167"
"259.6000","5.1903","7.99161","0.05175"
"260.0000","5.1984","7.99190","0.05184"
"260.4000","5.2063","7.99268","0.05194"
"260.8000","5.2145","7.99463","0.05203"
"261.2000","5.2224","7.99526","0.05212"
"261.6000","5.2304","7.99447","0.05221"
"262.0000","5.2386","7.99776","0.05230"
"262.4000","5.2463","7.99501","0.05239"
"262.8000","5.2544","7.99627","0.05248"
"263.2000","5.2623","7.99660","0.05257"
"263.6000","5.2705","7.99927","0.05266"
"264.0000","5.2784","7.99940","0.05276"
"264.4000","5.2864","7.99861","0.05285"
"264.8000","5.2946","8.00187","0.05294"
"265.2000","5.3022","7.99947","0.05303"
"265.6000","5.3104","8.00111","0.05312"
"266.0000","5.3184","8.00184","0.05321"
"266.4000","5.3265","8.00329","0.05330"
"266.8000","5.3344","8.00276","0.05339"
"267.2000","5.3424","8.00305","0.05349"
"267.6000","5.3505","8.00652","0.05358"
"268.0000","5.3583","8.00406","0.05367"
"268.4000","5.3664","8.00555","0.05376"
"268.8000","5.3743","8.00494","0.05385"
"269.2000","5.3824","8.00699","0.05394"
"269.6000","5.3903","8.00755","0.05404"
"270.0000","5.3985","8.00790","0.05413"
"270.4000","5.4067","8.01073","0.05422"
"270.8000","5.4143","8.00744","0.05431"
"271.2000","5.4224","8.00938","0.05440"
"271.6000","5.4303","8.00925","0.05450"
"272.0000","5.4385","8.01131","0.05459"
"272.4000","5.4463","8.01089","0.05468"
"272.8000","5.4545","8.01194","0.05477"
"273.2000","5.4625","8.01380","0.05486"
"273.6000","5.4703","8.01172","0.05496"
"274.0000","5.4785","8.01451","0.05505"
"274.4000","5.4863","8.01326","0.05514"
"274.8000","5.4945","8.01534","0.05523"
"275.2000","5.5023","8.01449","0.05532"
"275.6000","5.5104","8.01513","0.05542"
"276.0000","5.5186","8.01883","0.05551"
"276.4000","5.5264","8.01598","0.05560"
"276.8000","5.5345","8.01739","0.05570"
"277.2000","5.5423","8.01654","0.05578"
"277.6000","5.5504","8.01864","0.05588"
"278.0000","5.5583","8.01850","0.05597"
"278.4000","5.5665","8.01994","0.05606"
"278.8000","5.5745","8.02143","0.05616"
"279.2000","5.5824","8.01987","0.05625"
"279.6000","5.5905","8.02148","0.05634"
"280.0000","5.5982","8.01947","0.05643"
"280.4000","5.6065","8.02279","0.05653"
"280.8000","5.6143","8.02218","0.05662"
"281.2000","5.6225","8.02277","0.05671"
"281.6000","5.6305","8.02470","0.05681"
"282.0000","5.6383","8.02346","0.05690"
"282.4000","5.6465","8.02578","0.05699"
"282.8000","5.6543","8.02393","0.05708"
"283.2000","5.6625","8.02606","0.05718"
"283.6000","5.6703","8.02520","0.05727"
"284.0000","5.6784","8.02604","0.05736"
"284.4000","5.6865","8.02847","0.05745"
"284.8000","5.6944","8.02787","0.05755"
"285.2000","5.7025","8.02927","0.05764"
"285.6000","5.7103","8.02668","0.05773"
"286.0000","5.7185","8.02961","0.05782"
"286.4000","5.7262","8.02835","0.05792"
"286.8000","5.7344","8.02988","0.05801"
"287.2000","5.7425","8.03208","0.05811"
"287.6000","5.7504","8.03089","0.05820"
"288.0000","5.7585","8.03174","0.05829"
"288.4000","5.7662","8.02993","0.05838"
"288.8000","5.7745","8.03318","0.05848"
"289.2000","5.7823","8.03191","0.05857"
"289.6000","5.7904","8.03289","0.05867"
"290.0000","5.7984","8.03441","0.05876"
"290.4000","5.8064","8.03447","0.05885"
"290.8000","5.8145","8.03560","0.05895"
"291.2000","5.8223","8.03342","0.05904"
"291.6000","5.8306","8.03683","0.05913"
"292.0000","5.8383","8.03429","0.05923"
"292.4000","5.8464","8.03533","0.05932"
"292.8000","5.8544","8.03791","0.05941"
"293.2000","5.8625","8.03774","0.05951"
"293.6000","5.8705","8.03842","0.05960"
"294.0000","5.8783","8.03646","0.05970"
"294.4000","5.8865","8.03915","0.05979"
"294.8000","5.8942","8.03767","0.05988"
"295.2000","5.9024","8.03905","0.05998"
"295.6000","5.9104","8.04007","0.06007"
"296.0000","5.9185","8.04100","0.06017"
"296.4000","5.9265","8.04095","0.06026"
"296.8000","5.9343","8.03922","0.06036"
"297.2000","5.9425","8.04307","0.06045"
"297.6000","5.9503","8.04015","0.06054"
"298.0000","5.9585","8.04175","0.06064"
"298.4000","5.9664","8.04274","0.06073"
"298.8000","5.9744","8.04242","0.06083"
"299.2000","5.9825","8.04428","0.06092"
"299.6000","5.9904","8.04311","0.06101"
"300.0000","5.9985","8.04524","0.06111"
"300.4000","6.0063","8.04267","0.06120"
"300.8000","6.0144","8.04440","0.06130"
"301.2000","6.0223","8.04487","0.06139"
"301.6000","6.0305","8.04627","0.06149"
"302.0000","6.0385","8.04651","0.06158"
"302.4000","6.0464","8.04526","0.06168"
"302.8000","6.0545","8.04806","0.06177"
"303.2000","6.0622","8.04474","0.06187"
"303.6000","6.0705","8.04766","0.06196"
"304.0000","6.0784","8.04840","0.06206"
"304.4000","6.0864","8.04777","0.06215"
"304.8000","6.0945","8.04889","0.06225"
"305.2000","6.1024","8.04834","0.06234"
"305.6000","6.1105","8.05061","0.06244"
"306.0000","6.1183","8.04819","0.06253"
"306.4000","6.1265","8.05025","0.06263"
"306.8000","6.1343","8.04957","0.06272"
"307.2000","6.1424","8.05003","0.06282"
"307.6000","6.1504","8.05170","0.06292"
"308.0000","6.1585","8.05150","0.06301"
"308.4000","6.1665","8.05318","0.06311"
"308.8000","6.1742","8.04965","0.06320"
"309.2000","6.1825","8.05267","0.06330"
"309.6000","6.1903","8.05199","0.06339"
"310.0000","6.1984","8.05255","0.06349"
"310.4000","6.2065","8.05413","0.06359"
"310.8000","6.2145","8.05391","0.06368"
"311.2000","6.2224","8.05454","0.06378"
"311.6000","6.2302","8.05232","0.06387"
"312.0000","6.2385","8.05560","0.06397"
"312.4000","6.2463","8.05429","0.06407"
"312.8000","6.2544","8.05452","0.06416"
"313.2000","6.2625","8.05585","0.06426"
"313.6000","6.2705","8.05630","0.06436"
"314.0000","6.2784","8.05704","0.06445"
"314.4000","6.2863","8.05450","0.06455"
"314.8000","6.2946","8.05804","0.06465"
"315.2000","6.3022","8.05583","0.06474"
"315.6000","6.3103","8.05567","0.06484"
"316.0000","6.3185","8.05858","0.06493"
"316.4000","6.3266","8.05912","0.06503"
"316.8000","6.3344","8.05838","0.06513"
"317.2000","6.3423","8.05681","0.06522"
"317.6000","6.3506","8.05976","0.06532"
"318.0000","6.3582","8.05691","0.06541"
"318.4000","6.3663","8.05849","0.06551"
"318.8000","6.3745","8.06018","0.06561"
"319.2000","6.3825","8.06060","0.06571"
"319.6000","6.3904","8.06032","0.06581"
"320.0000","6.3983","8.05867","0.06590"
"320.4000","6.4066","8.06288","0.06600"
"320.8000","6.4142","8.05946","0.06610"
"321.2000","6.4223","8.05981","0.06619"
"321.6000","6.4305","8.06210","0.06629"
"322.0000","6.4385","8.06220","0.06639"
"322.4000","6.4463","8.06184","0.06648"
"322.8000","6.4544","8.06149","0.06659"
"323.2000","6.4627","8.06462","0.06669"
"323.6000","6.4702","8.05859","0.06678"
"324.0000","6.4783","8.04740","0.06685"
"324.4000","6.4864","8.05897","0.06694"
"324.8000","6.4946","8.06453","0.06704"
"325.2000","6.5024","8.06422","0.06713"
"325.6000","6.5104","8.06400","0.06723"
"326.0000","6.5187","8.06815","0.06733"
"326.4000","6.5261","8.06251","0.06742"
"326.8000","6.5344","8.06467","0.06752"
"327.2000","6.5425","8.06684","0.06762"
"327.6000","6.5505","8.06599","0.06772"
"328.0000","6.5583","8.06537","0.06781"
"328.4000","6.5664","8.06575","0.06791"
"328.8000","6.5746","8.06884","0.06801"
"329.2000","6.5823","8.06471","0.06811"
"329.6000","6.5904","8.06593","0.06821"
"330.0000","6.5985","8.06681","0.06831"
"330.4000","6.6064","8.06698","0.06841"
"330.8000","6.6142","8.06608","0.06850"
"331.2000","6.6225","8.06754","0.06860"
"331.6000","6.6307","8.07022","0.06870"
"332.0000","6.6381","8.06419","0.06880"
"332.4000","6.6464","8.06695","0.06890"
"332.8000","6.6544","8.06840","0.06900"
"333.2000","6.6624","8.06789","0.06910"
"333.6000","6.6704","8.06791","0.06920"
"334.0000","6.6785","8.06849","0.06930"
"334.4000","6.6866","8.07050","0.06940"
"334.8000","6.6941","8.06598","0.06949"
"335.2000","6.7024","8.06890","0.06960"
"335.6000","6.7105","8.06981","0.06969"
"336.0000","6.7184","8.06911","0.06979"
"336.4000","6.7262","8.06779","0.06989"
"336.8000","6.7345","8.07043","0.06999"
"337.2000","6.7426","8.07231","0.07009"
"337.6000","6.7502","8.06698","0.07019"
"338.0000","6.7585","8.07065","0.07030"
"338.4000","6.7664","8.07014","0.07039"
"338.8000","6.7743","8.06877","0.07049"
"339.2000","6.7823","8.06987","0.07059"
"339.6000","6.7905","8.07163","0.07070"
"340.0000","6.7986","8.07256","0.07080"
"340.4000","6.8062","8.06836","0.07089"
"340.8000","6.8144","8.07072","0.07100"
"341.2000","6.8224","8.07151","0.07110"
"341.6000","6.8304","8.07122","0.07120"
"342.0000","6.8383","8.07016","0.07130"
"342.4000","6.8466","8.07300","0.07140"
"342.8000","6.8545","8.07295","0.07150"
"343.2000","6.8622","8.06881","0.07160"
"343.6000","6.8706","8.07344","0.07171"
"344.0000","6.8784","8.07165","0.07181"
"344.4000","6.8864","8.07125","0.07191"
"344.8000","6.8943","8.07123","0.07201"
"345.2000","6.9025","8.07296","0.07211"
"345.6000","6.9105","8.07410","0.07221"
"346.0000","6.9183","8.07084","0.07231"
"346.4000","6.9266","8.07377","0.07242"
"346.8000","6.9344","8.07192","0.07252"
"347.2000","6.9423","8.07156","0.07262"
"347.6000","6.9503","8.07192","0.07272"
"348.0000","6.9586","8.07462","0.07282"
"348.4000","6.9665","8.07386","0.07292"
"348.8000","6.9743","8.07128","0.07303"
"349.2000","6.9825","8.07457","0.07313"
"349.6000","6.9902","8.07235","0.07323"
"350.0000","6.9984","8.07308","0.07334"
"350.4000","7.0064","8.07296","0.07344"
"350.8000","7.0145","8.07467","0.07354"
"351.2000","7.0225","8.07448","0.07364"
"351.6000","7.0303","8.07229","0.07375"
"352.0000","7.0385","8.07546","0.07385"
"352.4000","7.0463","8.07306","0.07395"
"352.8000","7.0544","8.07356","0.07405"
"353.2000","7.0623","8.07266","0.07416"
"353.6000","7.0704","8.07475","0.07426"
"354.0000","7.0784","8.07518","0.07437"
"354.4000","7.0864","8.07354","0.07447"
"354.8000","7.0947","8.07656","0.07457"
"355.2000","7.1023","8.07303","0.07467"
"355.6000","7.1104","8.07356","0.07478"
"356.0000","7.1183","8.07373","0.07488"
"356.4000","7.1265","8.07532","0.07499"
"356.8000","7.1344","8.07454","0.07509"
"357.2000","7.1424","8.07418","0.07520"
"357.6000","7.1505","8.07606","0.07530"
"358.0000","7.1582","8.07325","0.07540"
"358.4000","7.1664","8.07513","0.07551"
"358.8000","7.1744","8.07439","0.07562"
"359.2000","7.1825","8.07557","0.07572"
"359.6000","7.1903","8.07430","0.07582"
"360.0000","7.1984","8.07400","0.07593"
"360.4000","7.2066","8.07729","0.07604"
"360.8000","7.2143","8.07385","0.07614"
"361.2000","7.2225","8.07505","0.07625"
"361.6000","7.2303","8.07394","0.07635"
"362.0000","7.2384","8.07497","0.07646"
"362.4000","7.2463","8.07457","0.07656"
"362.8000","7.2545","8.07533","0.07667"
"363.2000","7.2626","8.07675","0.07678"
"363.6000","7.2703","8.07367","0.07688"
"364.0000","7.2784","8.07499","0.07699"
"364.4000","7.2862","8.07342","0.07709"
"364.8000","7.2945","8.07579","0.07720"
"365.2000","7.3023","8.07461","0.07731"
"365.6000","7.3104","8.07443","0.07741"
"366.0000","7.3185","8.07650","0.07752"
"366.4000","7.3263","8.07390","0.07763"
"366.8000","7.3345","8.07563","0.07773"
"367.2000","7.3424","8.07422","0.07784"
"367.6000","7.3505","8.07495","0.07795"
"368.0000","7.3583","8.07371","0.07806"
"368.4000","7.3664","8.07426","0.07816"
"368.8000","7.3745","8.07669","0.07827"
"369.2000","7.3824","8.07443","0.07838"
"369.6000","7.3905","8.07573","0.07849"
"370.0000","7.3983","8.07298","0.07860"
"370.4000","7.4064","8.07470","0.07871"
"370.8000","7.4143","8.07374","0.07881"
"371.2000","7.4225","8.07462","0.07892"
"371.6000","7.4306","8.07626","0.07903"
"372.0000","7.4384","8.07385","0.07914"
"372.4000","7.4465","8.07479","0.07925"
"372.8000","7.4543","8.07269","0.07936"
"373.2000","7.4625","8.07469","0.07947"
"373.6000","7.4703","8.07324","0.07958"
"374.0000","7.4785","8.07376","0.07969"
"374.4000","7.4865","8.07499","0.07980"
"374.8000","7.4944","8.07381","0.07991"
"375.2000","7.5025","8.07531","0.08003"
"375.6000","7.5103","8.07239","0.08013"
"376.0000","7.5185","8.07476","0.08025"
"376.4000","7.5263","8.07245","0.08036"
"376.8000","7.5344","8.07244","0.08047"
"377.2000","7.5425","8.07501","0.08058"
"377.6000","7.5504","8.07358","0.08069"
"378.0000","7.5585","8.07408","0.08080"
"378.4000","7.5663","8.07139","0.08092"
"378.8000","7.5744","8.07338","0.08103"
"379.2000","7.5823","8.07169","0.08114"
"379.6000","7.5905","8.07269","0.08125"
"380.0000","7.5985","8.07322","0.08137"
"380.4000","7.6065","8.07311","0.08148"
"380.8000","7.6145","8.07275","0.08159"
"381.2000","7.6222","8.07004","0.08171"
"381.6000","7.6305","8.07341","0.08182"
"382.0000","7.6383","8.07081","0.08194"
"382.4000","7.6465","8.07107","0.08205"
"382.8000","7.6544","8.07204","0.08216"
"383.2000","7.6624","8.07105","0.08227"
"383.6000","7.6705","8.07259","0.08239"
"384.0000","7.6784","8.06995","0.08251"
"384.4000","7.6865","8.07168","0.08262"
"384.8000","7.6943","8.06925","0.08274"
"385.2000","7.7024","8.06972","0.08285"
"385.6000","7.7104","8.07058","0.08297"
"386.0000","7.7185","8.07127","0.08309"
"386.4000","7.7265","8.07061","0.08320"
"386.8000","7.7343","8.06839","0.08332"
"387.2000","7.7425","8.07089","0.08343"
"387.6000","7.7502","8.06737","0.08355"
"388.0000","7.7585","8.06919","0.08367"
"388.4000","7.7664","8.06964","0.08378"
"388.8000","7.7745","8.06874","0.08390"
"389.2000","7.7825","8.06854","0.08402"
"389.6000","7.7903","8.06710","0.08414"
"390.0000","7.7985","8.06973","0.08426"
"390.4000","7.8063","8.06658","0.08438"
"390.8000","7.8145","8.06717","0.08450"
"391.2000","7.8223","8.06714","0.08461"
"391.6000","7.8304","8.06714","0.08473"
"392.0000","7.8385","8.06779","0.08485"
"392.4000","7.8464","8.06557","0.08497"
"392.8000","7.8546","8.06760","0.08509"
"393.2000","7.8622","8.06357","0.08521"
"393.6000","7.8705","8.06525","0.08534"
"394.0000","7.8783","8.06505","0.08545"
"394.4000","7.8864","8.06472","0.08558"
"394.8000","7.8945","8.06535","0.08570"
"395.2000","7.9024","8.06371","0.08582"
"395.6000","7.9105","8.06483","0.08594"
"396.0000","7.9182","8.06169","0.08606"
"396.4000","7.9265","8.06380","0.08619"
"396.8000","7.9344","8.06272","0.08631"
"397.2000","7.9424","8.06205","0.08643"
"397.6000","7.9505","8.06250","0.08656"
"398.0000","7.9584","8.06158","0.08668"
"398.4000","7.9665","8.06289","0.08680"
"398.8000","7.9742","8.05915","0.08693"
"399.2000","7.9825","8.06132","0.08705"
"399.6000","7.9903","8.05973","0.08718"
"400.0000","7.9983","8.05861","0.08730"
"400.4000","8.0065","8.06063","0.08743"
"400.8000","8.0145","8.06009","0.08756"
"401.2000","8.0225","8.05943","0.08769"
"401.6000","8.0303","8.05581","0.08781"
"402.0000","8.0385","8.05805","0.08794"
"402.4000","8.0462","8.05599","0.08807"
"402.8000","8.0543","8.05615","0.08819"
"403.2000","8.0624","8.05661","0.08832"
"403.6000","8.0705","8.05655","0.08845"
"404.0000","8.0784","8.05591","0.08858"
"404.4000","8.0862","8.05260","0.08871"
"404.8000","8.0946","8.05599","0.08884"
"405.2000","8.1023","8.05286","0.08897"
"405.6000","8.1103","8.05172","0.08910"
"406.0000","8.1185","8.05334","0.08924"
"406.4000","8.1265","8.05248","0.08937"
"406.8000","8.1344","8.05195","0.08950"
"407.2000","8.1423","8.04962","0.08963"
"407.6000","8.1506","8.05136","0.08976"
"408.0000","8.1582","8.04758","0.08989"
"408.4000","8.1663","8.04771","0.09003"
"408.8000","8.1744","8.04910","0.09016"
"409.2000","8.1826","8.04891","0.09030"
"409.6000","8.1904","8.04685","0.09043"
"410.0000","8.1983","8.04426","0.09057"
"410.4000","8.2067","8.04717","0.09071"
"410.8000","8.2142","8.04216","0.09084"
"411.2000","8.2223","8.04242","0.09098"
"411.6000","8.2305","8.04388","0.09112"
"412.0000","8.2385","8.04264","0.09125"
"412.4000","8.2463","8.04064","0.09139"
"412.8000","8.2543","8.03924","0.09153"
"413.2000","8.2627","8.04222","0.09167"
"413.6000","8.2703","8.03683","0.09180"
"414.0000","8.2784","8.03666","0.09195"
"414.4000","8.2865","8.03695","0.09209"
"414.8000","8.2945","8.03617","0.09223"
"415.2000","8.3023","8.03468","0.09237"
"415.6000","8.3104","8.03282","0.09251"
"416.0000","8.3187","8.03538","0.09265"
"416.4000","8.3261","8.02872","0.09279"
"416.8000","8.3343","8.02888","0.09293"
"417.2000","8.3424","8.02998","0.09308"
"417.6000","8.3505","8.02880","0.09322"
"418.0000","8.3584","8.02599","0.09337"
"418.4000","8.3664","8.02513","0.09351"
"418.8000","8.3746","8.02650","0.09366"
"419.2000","8.3821","8.01993","0.09380"
"419.6000","8.3904","8.02123","0.09395"
"420.0000","8.3985","8.02060","0.09410"
"420.4000","8.4065","8.01856","0.09424"
"420.8000","8.4143","8.01623","0.09439"
"421.2000","8.4224","8.01519","0.09454"
"421.6000","8.4307","8.01732","0.09469"
"422.0000","8.4382","8.00929","0.09483"
"422.4000","8.4464","8.00967","0.09498"
"422.8000","8.4545","8.00946","0.09514"
"423.2000","8.4624","8.00624","0.09529"
"423.6000","8.4703","8.00455","0.09543"
"424.0000","8.4785","8.00400","0.09559"
"424.4000","8.4866","8.00358","0.09574"
"424.8000","8.4942","7.99616","0.09589"
"425.2000","8.5024","7.99652","0.09604"
"425.6000","8.5104","7.99506","0.09620"
"426.0000","8.5185","7.99324","0.09635"
"426.4000","8.5263","7.98911","0.09650"
"426.8000","8.5345","7.98823","0.09666"
"427.2000","8.5426","7.98777","0.09681"
"427.6000","8.5501","7.97962","0.09696"
"428.0000","8.5584","7.98074","0.09712"
"428.4000","8.5664","7.97842","0.09728"
"428.8000","8.5744","7.97431","0.09743"
"429.2000","8.5823","7.97114","0.09759"
"429.6000","8.5905","7.97004","0.09775"
"430.0000","8.5986","7.96862","0.09790"
"430.4000","8.6063","7.96103","0.09806"
"430.8000","8.6145","7.96031","0.09822"
"431.2000","8.6224","7.95606","0.09837"
"431.6000","8.6303","7.95219","0.09853"
"432.0000","8.6382","7.94916","0.09869"
"432.4000","8.6466","7.94750","0.09885"
"432.8000","8.6546","7.94458","0.09901"
"433.2000","8.6622","7.93612","0.09917"
"433.6000","8.6705","7.93558","0.09933"
"434.0000","8.6783","7.93081","0.09949"
"434.4000","8.6864","7.92633","0.09965"
"434.8000","8.6943","7.92175","0.09981"
"435.2000","8.7026","7.91963","0.09998"
"435.6000","8.7105","7.91502","0.10014"
"436.0000","8.7183","7.90739","0.10030"
"436.4000","8.7265","7.90636","0.10046"
"436.8000","8.7343","7.89936","0.10063"
"437.2000","8.7424","7.89463","0.10079"
"437.6000","8.7503","7.88878","0.10096"
"438.0000","8.7585","7.88524","0.10112"
"438.4000","8.7665","7.88159","0.10128"
"438.8000","8.7743","7.87190","0.10145"
"439.2000","8.7826","7.86978","0.10162"
"439.6000","8.7903","7.86182","0.10178"
"440.0000","8.7983","7.85560","0.10194"
"440.4000","8.8063","7.85078","0.10211"
"440.8000","8.8145","7.84604","0.10228"
"441.2000","8.8224","7.83888","0.10244"
"441.6000","8.8304","7.83096","0.10261"
"442.0000","8.8385","7.82696","0.10278"
"442.4000","8.8463","7.81776","0.10294"
"442.8000","8.8544","7.81194","0.10311"
"443.2000","8.8623","7.80378","0.10328"
"443.6000","8.8706","7.79879","0.10345"
"444.0000","8.8784","7.79089","0.10362"
"444.4000","8.8863","7.78146","0.10379"
"444.8000","8.8946","7.77822","0.10396"
"445.2000","8.9023","7.76631","0.10412"
"445.6000","8.9104","7.75891","0.10430"
"446.0000","8.9183","7.75098","0.10446"
"446.4000","8.9264","7.74347","0.10464"
"446.8000","8.9344","7.73608","0.10481"
"447.2000","8.9424","7.72567","0.10498"
"447.6000","8.9506","7.71882","0.10515"
"448.0000","8.9584","7.70749","0.10532"
"448.4000","8.9664","7.69879","0.10549"
"448.8000","8.9742","7.68885","0.10566"
"449.2000","8.9825","7.68206","0.10584"
"449.6000","8.9903","7.67085","0.10601"
"450.0000","8.9984","7.66023","0.10618"
"450.4000","9.0066","7.65382","0.10635"
"450.8000","9.0142","7.63982","0.10653"
"451.2000","9.0225","7.63110","0.10670"
"451.6000","9.0304","7.61998","0.10687"
"452.0000","9.0385","7.60951","0.10705"
"452.4000","9.0464","7.59930","0.10722"
"452.8000","9.0544","7.58731","0.10740"
"453.2000","9.0625","7.57873","0.10757"
"453.6000","9.0704","7.56469","0.10775"
"454.0000","9.0784","7.55331","0.10793"
"454.4000","9.0863","7.54024","0.10810"
"454.8000","9.0944","7.53031","0.10828"
"455.2000","9.1023","7.51733","0.10845"
"455.6000","9.1105","7.50456","0.10864"
"456.0000","9.1186","7.49425","0.10881"
"456.4000","9.1263","7.47783","0.10899"
"456.8000","9.1345","7.46659","0.10917"
"457.2000","9.1422","7.45195","0.10934"
"457.6000","9.1505","7.44015","0.10952"
"458.0000","9.1584","7.42566","0.10970"
"458.4000","9.1665","7.41084","0.10988"
"458.8000","9.1745","7.39923","0.11006"
"459.2000","9.1823","7.38202","0.11024"
"459.6000","9.1905","7.36837","0.11042"
"460.0000","9.1984","7.35120","0.11060"
"460.4000","9.2065","7.33709","0.11078"
"460.8000","9.2143","7.32029","0.11096"
"461.2000","9.2224","7.30360","0.11114"
"461.6000","9.2305","7.29084","0.11132"
"462.0000","9.2384","7.27092","0.11151"
"462.4000","9.2465","7.25427","0.11169"
"462.8000","9.2543","7.23514","0.11188"
"463.2000","9.2624","7.21909","0.11206"
"463.6000","9.2703","7.20029","0.11224"
"464.0000","9.2785","7.18082","0.11243"
"464.4000","9.2865","7.16310","0.11261"
"464.8000","9.2945","7.14090","0.11280"
"465.2000","9.3025","7.12094","0.11299"
"465.6000","9.3102","7.09794","0.11318"
"466.0000","9.3185","7.07902","0.11337"
"466.4000","9.3263","7.05534","0.11356"
"466.8000","9.3344","7.03041","0.11375"
"467.2000","9.3425","7.00713","0.11394"
"467.6000","9.3504","6.97519","0.11414"
"468.0000","9.3585","6.94332","0.11435"
"468.4000","9.3664","6.90419","0.11456"
"468.8000","9.3745","6.86456","0.11478"
"469.2000","9.3824","6.79524","0.11502"
"469.6000","9.3904","6.66711","0.11536"
"470.0000","9.3985","6.48545","0.11574"
"470.4000","9.4065","6.36193","0.11605"
"470.8000","9.4145","6.26186","0.11632"
"471.2000","9.4223","6.15675","0.11658"
"471.6000","9.4305","6.05324","0.11686"
"472.0000","9.4382","5.96116","0.11712"
"472.4000","9.4465","5.82558","0.11746"
"472.8000","9.4545","5.64071","0.11784"
"473.2000","9.4625","5.45589","0.11823"
"473.6000","9.4705","5.27635","0.11862"
"474.0000","9.4784","5.00723","0.11914"
"474.2690","9.4838","4.84661","0.11946"