File: Coupon Test Data/Tensile Test_Neebajan_Alan_12.csv
Time,Displacement,Force,Strain 1
(s),(mm),(kN),(mm/mm)
"0.0000","0.0000","0.18477","0.00001"
"0.3000","0.0043","0.22596","0.00004"
"0.6000","0.0104","0.29121","0.00008"
"0.9000","0.0165","0.35507","0.00012"
"1.2000","0.0224","0.41532","0.00015"
"1.5000","0.0286","0.47776","0.00019"
"1.8000","0.0345","0.53744","0.00022"
"2.1000","0.0405","0.59776","0.00026"
"2.4000","0.0465","0.65359","0.00029"
"2.7000","0.0526","0.71287","0.00033"
"3.0000","0.0586","0.76981","0.00037"
"3.3000","0.0644","0.82267","0.00040"
"3.6000","0.0706","0.88136","0.00043"
"3.9000","0.0765","0.93708","0.00047"
"4.2000","0.0827","0.99253","0.00050"
"4.5000","0.0884","1.04427","0.00053"
"4.8000","0.0947","1.09708","0.00056"
"5.1000","0.1005","1.15021","0.00059"
"5.4000","0.1066","1.20464","0.00063"
"5.7000","0.1125","1.25726","0.00066"
"6.0000","0.1186","1.31068","0.00069"
"6.3000","0.1246","1.35967","0.00072"
"6.6000","0.1305","1.41085","0.00075"
"6.9000","0.1367","1.46529","0.00078"
"7.2000","0.1425","1.51493","0.00081"
"7.5000","0.1485","1.56576","0.00084"
"7.8000","0.1544","1.61177","0.00087"
"8.1000","0.1606","1.66367","0.00090"
"8.4000","0.1666","1.71369","0.00093"
"8.7000","0.1725","1.76235","0.00096"
"9.0000","0.1785","1.80786","0.00099"
"9.3000","0.1846","1.85778","0.00102"
"9.6000","0.1904","1.90485","0.00105"
"9.9000","0.1966","1.95394","0.00108"
"10.2000","0.2025","1.99724","0.00110"
"10.5000","0.2086","2.04621","0.00113"
"10.8000","0.2145","2.09271","0.00116"
"11.1000","0.2206","2.14039","0.00119"
"11.4000","0.2266","2.18271","0.00122"
"11.7000","0.2324","2.22750","0.00125"
"12.0000","0.2386","2.27481","0.00127"
"12.3000","0.2445","2.31932","0.00130"
"12.6000","0.2508","2.36303","0.00133"
"12.9000","0.2564","2.40499","0.00135"
"13.2000","0.2626","2.45164","0.00138"
"13.5000","0.2685","2.49246","0.00141"
"13.8000","0.2745","2.53449","0.00143"
"14.1000","0.2805","2.57768","0.00146"
"14.4000","0.2865","2.62071","0.00148"
"14.7000","0.2927","2.66096","0.00151"
"15.0000","0.2986","2.70218","0.00153"
"15.3000","0.3046","2.74523","0.00156"
"15.6000","0.3105","2.78577","0.00158"
"15.9000","0.3165","2.82382","0.00161"
"16.2000","0.3225","2.86478","0.00163"
"16.5000","0.3285","2.90631","0.00166"
"16.8000","0.3346","2.94298","0.00168"
"17.1000","0.3406","2.98320","0.00171"
"17.4000","0.3465","3.02207","0.00173"
"17.7000","0.3526","3.06294","0.00175"
"18.0000","0.3584","3.09677","0.00177"
"18.3000","0.3646","3.13776","0.00180"
"18.6000","0.3704","3.17518","0.00182"
"18.9000","0.3767","3.21267","0.00185"
"19.2000","0.3826","3.25081","0.00187"
"19.5000","0.3886","3.28917","0.00189"
"19.8000","0.3945","3.32703","0.00192"
"20.1000","0.4004","3.36029","0.00194"
"20.4000","0.4066","3.40011","0.00197"
"20.7000","0.4125","3.43559","0.00199"
"21.0000","0.4188","3.47215","0.00201"
"21.3000","0.4245","3.50676","0.00203"
"21.6000","0.4306","3.54407","0.00206"
"21.9000","0.4364","3.57749","0.00208"
"22.2000","0.4425","3.61161","0.00210"
"22.5000","0.4485","3.64646","0.00212"
"22.8000","0.4545","3.68137","0.00215"
"23.1000","0.4606","3.71355","0.00217"
"23.4000","0.4667","3.74966","0.00219"
"23.7000","0.4725","3.78346","0.00221"
"24.0000","0.4785","3.81490","0.00223"
"24.3000","0.4844","3.84889","0.00225"
"24.6000","0.4906","3.88503","0.00228"
"24.9000","0.4965","3.91900","0.00230"
"25.2000","0.5026","3.95141","0.00232"
"25.5000","0.5087","3.98719","0.00234"
"25.8000","0.5144","4.01975","0.00237"
"26.1000","0.5206","4.05129","0.00239"
"26.4000","0.5264","4.08536","0.00241"
"26.7000","0.5327","4.12288","0.00243"
"27.0000","0.5384","4.15016","0.00245"
"27.3000","0.5448","4.18902","0.00248"
"27.6000","0.5506","4.22184","0.00250"
"27.9000","0.5566","4.25239","0.00252"
"28.2000","0.5625","4.28583","0.00254"
"28.5000","0.5685","4.32057","0.00257"
"28.8000","0.5746","4.35181","0.00259"
"29.1000","0.5805","4.38492","0.00261"
"29.4000","0.5867","4.42149","0.00264"
"29.7000","0.5926","4.45043","0.00266"
"30.0000","0.5985","4.48469","0.00268"
"30.3000","0.6044","4.51690","0.00270"
"30.6000","0.6105","4.54843","0.00273"
"30.9000","0.6166","4.58289","0.00275"
"31.2000","0.6226","4.61232","0.00278"
"31.5000","0.6285","4.64629","0.00280"
"31.8000","0.6347","4.67892","0.00282"
"32.1000","0.6404","4.70865","0.00285"
"32.4000","0.6465","4.74047","0.00287"
"32.7000","0.6523","4.77053","0.00289"
"33.0000","0.6587","4.80403","0.00292"
"33.3000","0.6645","4.83335","0.00294"
"33.6000","0.6707","4.86519","0.00297"
"33.9000","0.6767","4.89536","0.00300"
"34.2000","0.6825","4.92418","0.00302"
"34.5000","0.6885","4.95345","0.00305"
"34.8000","0.6944","4.98229","0.00308"
"35.1000","0.7008","5.01288","0.00310"
"35.4000","0.7065","5.03923","0.00313"
"35.7000","0.7127","5.06976","0.00316"
"36.0000","0.7186","5.09377","0.00319"
"36.3000","0.7246","5.12229","0.00322"
"36.6000","0.7305","5.14809","0.00325"
"36.9000","0.7364","5.16805","0.00327"
"37.2000","0.7426","5.19763","0.00331"
"37.5000","0.7486","5.22103","0.00335"
"37.8000","0.7546","5.24054","0.00338"
"38.1000","0.7607","5.26459","0.00341"
"38.4000","0.7665","5.28688","0.00345"
"38.7000","0.7725","5.30631","0.00349"
"39.0000","0.7784","5.32170","0.00353"
"39.3000","0.7847","5.34206","0.00357"
"39.6000","0.7906","5.35956","0.00362"
"39.9000","0.7966","5.37633","0.00366"
"40.2000","0.8026","5.39189","0.00372"
"40.5000","0.8085","5.40505","0.00377"
"40.8000","0.8146","5.41705","0.00382"
"41.1000","0.8203","5.42858","0.00387"
"41.4000","0.8267","5.44159","0.00394"
"41.7000","0.8326","5.45133","0.00399"
"42.0000","0.8386","5.46022","0.00406"
"42.3000","0.8446","5.46937","0.00412"
"42.6000","0.8504","5.47598","0.00418"
"42.9000","0.8566","5.48462","0.00425"
"43.2000","0.8624","5.48895","0.00431"
"43.5000","0.8688","5.49246","0.00436"
"43.8000","0.8746","5.50130","0.00443"
"44.1000","0.8806","5.50875","0.00450"
"44.4000","0.8865","5.51140","0.00457"
"44.7000","0.8926","5.51782","0.00464"
"45.0000","0.8986","5.52048","0.00471"
"45.3000","0.9044","5.52382","0.00478"
"45.6000","0.9106","5.53135","0.00485"
"45.9000","0.9167","5.53437","0.00493"
"46.2000","0.9226","5.53823","0.00501"
"46.5000","0.9286","5.54028","0.00508"
"46.8000","0.9345","5.54454","0.00516"
"47.1000","0.9406","5.54698","0.00524"
"47.4000","0.9464","5.54984","0.00531"
"47.7000","0.9526","5.55407","0.00540"
"48.0000","0.9587","5.55677","0.00547"
"48.3000","0.9645","5.55838","0.00555"
"48.6000","0.9707","5.56143","0.00563"
"48.9000","0.9765","5.56275","0.00571"
"49.2000","0.9827","5.56622","0.00580"
"49.5000","0.9883","5.56608","0.00587"
"49.8000","0.9947","5.57192","0.00596"
"50.1000","1.0006","5.57276","0.00604"
"50.4000","1.0067","5.57483","0.00612"
"50.7000","1.0125","5.57562","0.00620"
"51.0000","1.0185","5.57757","0.00628"
"51.3000","1.0246","5.58081","0.00636"
"51.6000","1.0304","5.58029","0.00644"
"51.9000","1.0368","5.58530","0.00653"
"52.2000","1.0427","5.58498","0.00661"
"52.5000","1.0486","5.58746","0.00669"
"52.8000","1.0545","5.58723","0.00678"
"53.1000","1.0606","5.59002","0.00686"
"53.4000","1.0666","5.59125","0.00694"
"53.7000","1.0725","5.59170","0.00702"
"54.0000","1.0785","5.59491","0.00710"
"54.3000","1.0847","5.59655","0.00719"
"54.6000","1.0905","5.59715","0.00727"
"54.9000","1.0966","5.59765","0.00736"
"55.2000","1.1024","5.59903","0.00744"
"55.5000","1.1086","5.60176","0.00752"
"55.8000","1.1144","5.60214","0.00760"
"56.1000","1.1206","5.60486","0.00769"
"56.4000","1.1267","5.60368","0.00777"
"56.7000","1.1326","5.60292","0.00783"
"57.0000","1.1386","5.60785","0.00791"
"57.3000","1.1445","5.60860","0.00799"
"57.6000","1.1507","5.61193","0.00808"
"57.9000","1.1564","5.61030","0.00816"
"58.2000","1.1627","5.61425","0.00824"
"58.5000","1.1686","5.60961","0.00832"
"58.8000","1.1746","5.61095","0.00838"
"59.1000","1.1805","5.61588","0.00846"
"59.4000","1.1865","5.61710","0.00854"
"59.7000","1.1926","5.62015","0.00863"
"60.0000","1.1985","5.61885","0.00871"
"60.3000","1.2046","5.62212","0.00879"
"60.6000","1.2106","5.62159","0.00888"
"60.9000","1.2166","5.62366","0.00896"
"61.2000","1.2225","5.62252","0.00904"
"61.5000","1.2285","5.62460","0.00912"
"61.8000","1.2346","5.62618","0.00921"
"62.1000","1.2406","5.62706","0.00929"
"62.4000","1.2464","5.62829","0.00937"
"62.7000","1.2527","5.63041","0.00946"
"63.0000","1.2585","5.63004","0.00954"
"63.3000","1.2646","5.63122","0.00962"
"63.6000","1.2703","5.63069","0.00970"
"63.9000","1.2767","5.63473","0.00979"
"64.2000","1.2825","5.63481","0.00987"
"64.5000","1.2886","5.63639","0.00995"
"64.8000","1.2947","5.63756","0.01004"
"65.1000","1.3005","5.63741","0.01012"
"65.4000","1.3067","5.63946","0.01020"
"65.7000","1.3124","5.63814","0.01028"
"66.0000","1.3188","5.64304","0.01037"
"66.3000","1.3245","5.64110","0.01045"
"66.6000","1.3306","5.64444","0.01053"
"66.9000","1.3365","5.64354","0.01061"
"67.2000","1.3427","5.64581","0.01069"
"67.5000","1.3486","5.64513","0.01078"
"67.8000","1.3545","5.64571","0.01086"
"68.1000","1.3606","5.64860","0.01094"
"68.4000","1.3666","5.64940","0.01102"
"68.7000","1.3725","5.65016","0.01110"
"69.0000","1.3786","5.65061","0.01118"
"69.3000","1.3845","5.65171","0.01126"
"69.6000","1.3906","5.65219","0.01134"
"69.9000","1.3965","5.65278","0.01142"
"70.2000","1.4026","5.65540","0.01150"
"70.5000","1.4086","5.65620","0.01159"
"70.8000","1.4144","5.65631","0.01166"
"71.1000","1.4206","5.65796","0.01174"
"71.4000","1.4265","5.65783","0.01182"
"71.7000","1.4327","5.65983","0.01191"
"72.0000","1.4384","5.65826","0.01198"
"72.3000","1.4447","5.66270","0.01207"
"72.6000","1.4505","5.66254","0.01214"
"72.9000","1.4566","5.66406","0.01222"
"73.2000","1.4626","5.66402","0.01230"
"73.5000","1.4686","5.66475","0.01238"
"73.8000","1.4747","5.66662","0.01246"
"74.1000","1.4805","5.66551","0.01254"
"74.4000","1.4867","5.66926","0.01262"
"74.7000","1.4926","5.66846","0.01269"
"75.0000","1.4985","5.67027","0.01277"
"75.3000","1.5045","5.66968","0.01285"
"75.6000","1.5106","5.67173","0.01293"
"75.9000","1.5166","5.67241","0.01301"
"76.2000","1.5225","5.67213","0.01308"
"76.5000","1.5285","5.67429","0.01316"
"76.8000","1.5346","5.67552","0.01324"
"77.1000","1.5404","5.67593","0.01331"
"77.4000","1.5466","5.67627","0.01339"
"77.7000","1.5525","5.67691","0.01347"
"78.0000","1.5587","5.67859","0.01354"
"78.3000","1.5645","5.67882","0.01362"
"78.6000","1.5706","5.68041","0.01370"
"78.9000","1.5766","5.68168","0.01377"
"79.2000","1.5824","5.68161","0.01385"
"79.5000","1.5886","5.68341","0.01393"
"79.8000","1.5945","5.68293","0.01400"
"80.1000","1.6008","5.68612","0.01408"
"80.4000","1.6065","5.68410","0.01415"
"80.7000","1.6127","5.68744","0.01423"
"81.0000","1.6186","5.68737","0.01430"
"81.3000","1.6246","5.68863","0.01438"
"81.6000","1.6306","5.68852","0.01445"
"81.9000","1.6365","5.68892","0.01453"
"82.2000","1.6427","5.69189","0.01460"
"82.5000","1.6486","5.69073","0.01468"
"82.8000","1.6546","5.69346","0.01475"
"83.1000","1.6606","5.69263","0.01482"
"83.4000","1.6665","5.69445","0.01490"
"83.7000","1.6725","5.69386","0.01497"
"84.0000","1.6785","5.69555","0.01505"
"84.3000","1.6847","5.69696","0.01512"
"84.6000","1.6906","5.69739","0.01519"
"84.9000","1.6965","5.69786","0.01527"
"85.2000","1.7026","5.69962","0.01534"
"85.5000","1.7084","5.69957","0.01541"
"85.8000","1.7146","5.70098","0.01549"
"86.1000","1.7204","5.70045","0.01556"
"86.4000","1.7268","5.70352","0.01563"
"86.7000","1.7326","5.70349","0.01571"
"87.0000","1.7386","5.70424","0.01578"
"87.3000","1.7446","5.70534","0.01585"
"87.6000","1.7504","5.70523","0.01592"
"87.9000","1.7566","5.70752","0.01600"
"88.2000","1.7624","5.70590","0.01607"
"88.5000","1.7688","5.71058","0.01614"
"88.8000","1.7745","5.70844","0.01621"
"89.1000","1.7806","5.71117","0.01628"
"89.4000","1.7865","5.70992","0.01636"
"89.7000","1.7926","5.71242","0.01643"
"90.0000","1.7985","5.71208","0.01650"
"90.3000","1.8045","5.71247","0.01657"
"90.6000","1.8106","5.71499","0.01664"
"90.9000","1.8167","5.71546","0.01672"
"91.2000","1.8225","5.71565","0.01679"
"91.5000","1.8285","5.71595","0.01686"
"91.8000","1.8344","5.71701","0.01693"
"92.1000","1.8406","5.71829","0.01700"
"92.4000","1.8465","5.71828","0.01707"
"92.7000","1.8527","5.72045","0.01715"
"93.0000","1.8587","5.72138","0.01722"
"93.3000","1.8644","5.72081","0.01729"
"93.6000","1.8706","5.72248","0.01736"
"93.9000","1.8764","5.72246","0.01743"
"94.2000","1.8828","5.71239","0.01749"
"94.5000","1.8884","5.71840","0.01755"
"94.8000","1.8948","5.72649","0.01762"
"95.1000","1.9006","5.72738","0.01769"
"95.4000","1.9066","5.72850","0.01776"
"95.7000","1.9125","5.72806","0.01783"
"96.0000","1.9185","5.72870","0.01790"
"96.3000","1.9246","5.73101","0.01797"
"96.6000","1.9305","5.72953","0.01804"
"96.9000","1.9367","5.73307","0.01811"
"97.2000","1.9426","5.73218","0.01818"
"97.5000","1.9486","5.73331","0.01825"
"97.8000","1.9544","5.73259","0.01832"
"98.1000","1.9605","5.73452","0.01839"
"98.4000","1.9666","5.73574","0.01846"
"98.7000","1.9726","5.73520","0.01853"
"99.0000","1.9786","5.73721","0.01860"
"99.3000","1.9847","5.73832","0.01867"
"99.6000","1.9905","5.73818","0.01874"
"99.9000","1.9966","5.73845","0.01881"
"100.2000","2.0023","5.73896","0.01888"
"100.5000","2.0087","5.74152","0.01895"
"100.8000","2.0145","5.74113","0.01902"
"101.1000","2.0206","5.74286","0.01909"
"101.4000","2.0267","5.74413","0.01916"
"101.7000","2.0325","5.74369","0.01923"
"102.0000","2.0386","5.74487","0.01930"
"102.3000","2.0444","5.74449","0.01937"
"102.6000","2.0508","5.74819","0.01944"
"102.9000","2.0565","5.74620","0.01951"
"103.2000","2.0627","5.74930","0.01958"
"103.5000","2.0686","5.74915","0.01965"
"103.8000","2.0746","5.74999","0.01972"
"104.1000","2.0805","5.74985","0.01979"
"104.4000","2.0864","5.75027","0.01986"
"104.7000","2.0927","5.75371","0.01993"
"105.0000","2.0986","5.75241","0.02000"
"105.3000","2.1047","5.75468","0.02007"
"105.6000","2.1106","5.75386","0.02014"
"105.9000","2.1165","5.75531","0.02020"
"106.2000","2.1225","5.75488","0.02028"
"106.5000","2.1284","5.75653","0.02034"
"106.8000","2.1346","5.75842","0.02042"
"107.1000","2.1406","5.75862","0.02049"
"107.4000","2.1465","5.75890","0.02056"
"107.7000","2.1527","5.76068","0.02062"
"108.0000","2.1585","5.76029","0.02069"
"108.3000","2.1646","5.76134","0.02076"
"108.6000","2.1703","5.76068","0.02083"
"108.9000","2.1767","5.76475","0.02090"
"109.2000","2.1826","5.76459","0.02097"
"109.5000","2.1886","5.76512","0.02104"
"109.8000","2.1946","5.74996","0.02109"
"110.1000","2.2005","5.76091","0.02115"
"110.4000","2.2066","5.76724","0.02122"
"110.7000","2.2123","5.76701","0.02129"
"111.0000","2.2188","5.77229","0.02136"
"111.3000","2.2246","5.76975","0.02143"
"111.6000","2.2307","5.77196","0.02150"
"111.9000","2.2365","5.77064","0.02157"
"112.2000","2.2426","5.77283","0.02164"
"112.5000","2.2485","5.77215","0.02171"
"112.8000","2.2544","5.77245","0.02177"
"113.1000","2.2606","5.77514","0.02184"
"113.4000","2.2667","5.77579","0.02192"
"113.7000","2.2725","5.77593","0.02198"
"114.0000","2.2786","5.77617","0.02206"
"114.3000","2.2844","5.77678","0.02212"
"114.6000","2.2906","5.77779","0.02219"
"114.9000","2.2964","5.77791","0.02226"
"115.2000","2.3026","5.78034","0.02233"
"115.5000","2.3087","5.78124","0.02240"
"115.8000","2.3145","5.78069","0.02247"
"116.1000","2.3206","5.78216","0.02254"
"116.4000","2.3265","5.78189","0.02261"
"116.7000","2.3327","5.78399","0.02268"
"117.0000","2.3383","5.78214","0.02275"
"117.3000","2.3447","5.78691","0.02282"
"117.6000","2.3506","5.78628","0.02289"
"117.9000","2.3566","5.78707","0.02296"
"118.2000","2.3626","5.78695","0.02303"
"118.5000","2.3685","5.78758","0.02309"
"118.8000","2.3746","5.78968","0.02316"
"119.1000","2.3804","5.78844","0.02323"
"119.4000","2.3867","5.79226","0.02330"
"119.7000","2.3927","5.79144","0.02337"
"120.0000","2.3986","5.79246","0.02344"
"120.3000","2.4045","5.79181","0.02351"
"120.6000","2.4106","5.79324","0.02358"
"120.9000","2.4166","5.79413","0.02365"
"121.2000","2.4224","5.79383","0.02372"
"121.5000","2.4285","5.79640","0.02379"
"121.8000","2.4347","5.79764","0.02386"
"122.1000","2.4405","5.79709","0.02393"
"122.4000","2.4466","5.79731","0.02400"
"122.7000","2.4524","5.79755","0.02407"
"123.0000","2.4586","5.79999","0.02414"
"123.3000","2.4645","5.79996","0.02421"
"123.6000","2.4707","5.80208","0.02428"
"123.9000","2.4767","5.80301","0.02435"
"124.2000","2.4825","5.80233","0.02441"
"124.5000","2.4886","5.80351","0.02448"
"124.8000","2.4944","5.80296","0.02455"
"125.1000","2.5007","5.80633","0.02462"
"125.4000","2.5064","5.80440","0.02469"
"125.7000","2.5127","5.80806","0.02476"
"126.0000","2.5186","5.80767","0.02483"
"126.3000","2.5246","5.80858","0.02490"
"126.6000","2.5306","5.80824","0.02497"
"126.9000","2.5365","5.80821","0.02504"
"127.2000","2.5426","5.81131","0.02511"
"127.5000","2.5485","5.81035","0.02518"
"127.8000","2.5546","5.81306","0.02525"
"128.1000","2.5606","5.81252","0.02532"
"128.4000","2.5666","5.81388","0.02539"
"128.7000","2.5725","5.81279","0.02546"
"129.0000","2.5785","5.81417","0.02553"
"129.3000","2.5846","5.81543","0.02560"
"129.6000","2.5906","5.81609","0.02567"
"129.9000","2.5965","5.81674","0.02574"
"130.2000","2.6027","5.81873","0.02581"
"130.5000","2.6085","5.81781","0.02588"
"130.8000","2.6146","5.81912","0.02595"
"131.1000","2.6204","5.81813","0.02602"
"131.4000","2.6267","5.82181","0.02609"
"131.7000","2.6326","5.82167","0.02616"
"132.0000","2.6386","5.82266","0.02623"
"132.3000","2.6447","5.82365","0.02630"
"132.6000","2.6505","5.82313","0.02637"
"132.9000","2.6567","5.82518","0.02644"
"133.2000","2.6624","5.82343","0.02651"
"133.5000","2.6688","5.82786","0.02658"
"133.8000","2.6745","5.82584","0.02665"
"134.1000","2.6806","5.82876","0.02672"
"134.4000","2.6865","5.82763","0.02679"
"134.7000","2.6926","5.82961","0.02686"
"135.0000","2.6986","5.82902","0.02693"
"135.3000","2.7045","5.82909","0.02699"
"135.6000","2.7105","5.83128","0.02706"
"135.9000","2.7166","5.83234","0.02713"
"136.2000","2.7225","5.83266","0.02720"
"136.5000","2.7286","5.83311","0.02727"
"136.8000","2.7345","5.83361","0.02734"
"137.1000","2.7406","5.83436","0.02741"
"137.4000","2.7465","5.83441","0.02748"
"137.7000","2.7526","5.83663","0.02755"
"138.0000","2.7587","5.83746","0.02762"
"138.3000","2.7644","5.83699","0.02769"
"138.6000","2.7706","5.83882","0.02776"
"138.9000","2.7765","5.83824","0.02783"
"139.2000","2.7828","5.84061","0.02790"
"139.5000","2.7884","5.83818","0.02796"
"139.8000","2.7947","5.84262","0.02803"
"140.1000","2.8005","5.84186","0.02810"
"140.4000","2.8066","5.84343","0.02817"
"140.7000","2.8125","5.84307","0.02824"
"141.0000","2.8186","5.84384","0.02831"
"141.3000","2.8247","5.84524","0.02838"
"141.6000","2.8305","5.83328","0.02844"
"141.9000","2.8367","5.84338","0.02850"
"142.2000","2.8426","5.84591","0.02857"
"142.5000","2.8485","5.84833","0.02863"
"142.8000","2.8545","5.84814","0.02870"
"143.1000","2.8606","5.84988","0.02877"
"143.4000","2.8666","5.85022","0.02884"
"143.7000","2.8726","5.84994","0.02891"
"144.0000","2.8785","5.85142","0.02898"
"144.3000","2.8847","5.85291","0.02905"
"144.6000","2.8904","5.85227","0.02911"
"144.9000","2.8966","5.85326","0.02919"
"145.2000","2.9024","5.85299","0.02926"
"145.5000","2.9087","5.85527","0.02933"
"145.8000","2.9145","5.85444","0.02940"
"146.1000","2.9207","5.85650","0.02946"
"146.4000","2.9266","5.85690","0.02954"
"146.7000","2.9325","5.85694","0.02961"
"147.0000","2.9386","5.85813","0.02967"
"147.3000","2.9445","5.85780","0.02974"
"147.6000","2.9508","5.86040","0.02982"
"147.9000","2.9564","5.85852","0.02988"
"148.2000","2.9626","5.86139","0.02995"
"148.5000","2.9685","5.86131","0.03002"
"148.8000","2.9746","5.86214","0.03009"
"149.1000","2.9805","5.86227","0.03016"
"149.4000","2.9865","5.86235","0.03023"
"149.7000","2.9927","5.86504","0.03030"
"150.0000","2.9986","5.86397","0.03037"
"150.3000","3.0046","5.86582","0.03044"
"150.6000","3.0106","5.86576","0.03051"
"150.9000","3.0165","5.86658","0.03058"
"151.2000","3.0226","5.86699","0.03065"
"151.5000","3.0285","5.86758","0.03072"
"151.8000","3.0347","5.86938","0.03079"
"152.1000","3.0406","5.86910","0.03086"
"152.4000","3.0465","5.86999","0.03093"
"152.7000","3.0526","5.87094","0.03100"
"153.0000","3.0585","5.87135","0.03107"
"153.3000","3.0646","5.87198","0.03114"
"153.6000","3.0704","5.87148","0.03120"
"153.9000","3.0767","5.87423","0.03128"
"154.2000","3.0826","5.87428","0.03135"
"154.5000","3.0886","5.87465","0.03142"
"154.8000","3.0946","5.87558","0.03148"
"155.1000","3.1004","5.87520","0.03155"
"155.4000","3.1066","5.87755","0.03163"
"155.7000","3.1124","5.87575","0.03169"
"156.0000","3.1188","5.88006","0.03177"
"156.3000","3.1246","5.87778","0.03183"
"156.6000","3.1306","5.87997","0.03190"
"156.9000","3.1365","5.87900","0.03197"
"157.2000","3.1425","5.88116","0.03204"
"157.5000","3.1486","5.88126","0.03211"
"157.8000","3.1545","5.88089","0.03218"
"158.1000","3.1606","5.88353","0.03225"
"158.4000","3.1667","5.88373","0.03232"
"158.7000","3.1726","5.88403","0.03239"
"159.0000","3.1785","5.88375","0.03246"
"159.3000","3.1844","5.88492","0.03253"
"159.6000","3.1906","5.88582","0.03260"
"159.9000","3.1965","5.88586","0.03267"
"160.2000","3.2027","5.88752","0.03274"
"160.5000","3.2087","5.88852","0.03281"
"160.8000","3.2144","5.88760","0.03288"
"161.1000","3.2206","5.88921","0.03295"
"161.4000","3.2264","5.88860","0.03302"
"161.7000","3.2327","5.89156","0.03309"
"162.0000","3.2384","5.88922","0.03316"
"162.3000","3.2448","5.89313","0.03323"
"162.6000","3.2506","5.89253","0.03330"
"162.9000","3.2566","5.89336","0.03337"
"163.2000","3.2625","5.89263","0.03344"
"163.5000","3.2684","5.89335","0.03351"
"163.8000","3.2746","5.89591","0.03358"
"164.1000","3.2805","5.89441","0.03365"
"164.4000","3.2868","5.89776","0.03372"
"164.7000","3.2926","5.89648","0.03379"
"165.0000","3.2986","5.89756","0.03386"
"165.3000","3.3044","5.89673","0.03393"
"165.6000","3.3105","5.89854","0.03400"
"165.9000","3.3166","5.89949","0.03407"
"166.2000","3.3225","5.89878","0.03414"
"166.5000","3.3286","5.90045","0.03421"
"166.8000","3.3347","5.90175","0.03429"
"167.1000","3.3405","5.90113","0.03435"
"167.4000","3.3466","5.90140","0.03443"
"167.7000","3.3523","5.90137","0.03449"
"168.0000","3.3587","5.90388","0.03457"
"168.3000","3.3645","5.90332","0.03463"
"168.6000","3.3707","5.90519","0.03471"
"168.9000","3.3767","5.90586","0.03478"
"169.2000","3.3825","5.90520","0.03484"
"169.5000","3.3885","5.90607","0.03492"
"169.8000","3.3944","5.90585","0.03499"
"170.1000","3.4008","5.90930","0.03506"
"170.4000","3.4065","5.90704","0.03513"
"170.7000","3.4127","5.90999","0.03520"
"171.0000","3.4186","5.90949","0.03527"
"171.3000","3.4246","5.90988","0.03534"
"171.6000","3.4305","5.90986","0.03541"
"171.9000","3.4364","5.90997","0.03548"
"172.2000","3.4427","5.91306","0.03555"
"172.5000","3.4486","5.91181","0.03562"
"172.8000","3.4546","5.91379","0.03569"
"173.1000","3.4606","5.91302","0.03576"
"173.4000","3.4665","5.91426","0.03583"
"173.7000","3.4725","5.91348","0.03590"
"174.0000","3.4784","5.91466","0.03597"
"174.3000","3.4846","5.91652","0.03605"
"174.6000","3.4906","5.91650","0.03612"
"174.9000","3.4965","5.91649","0.03619"
"175.2000","3.5027","5.91825","0.03626"
"175.5000","3.5085","5.91734","0.03633"
"175.8000","3.5146","5.91865","0.03640"
"176.1000","3.5203","5.91731","0.03647"
"176.4000","3.5267","5.92151","0.03654"
"176.7000","3.5326","5.92082","0.03661"
"177.0000","3.5386","5.92139","0.03668"
"177.3000","3.5446","5.92175","0.03675"
"177.6000","3.5505","5.92152","0.03682"
"177.9000","3.5566","5.92333","0.03690"
"178.2000","3.5624","5.92166","0.03696"
"178.5000","3.5688","5.92637","0.03704"
"178.8000","3.5746","5.92389","0.03711"
"179.1000","3.5807","5.92610","0.03718"
"179.4000","3.5865","5.90818","0.03723"
"179.7000","3.5926","5.92071","0.03729"
"180.0000","3.5985","5.92443","0.03736"
"180.3000","3.6044","5.92621","0.03743"
"180.6000","3.6106","5.92931","0.03750"
"180.9000","3.6167","5.92998","0.03757"
"181.2000","3.6225","5.92955","0.03764"
"181.5000","3.6286","5.92956","0.03771"
"181.8000","3.6344","5.92983","0.03778"
"182.1000","3.6406","5.93066","0.03785"
"182.4000","3.6464","5.93041","0.03793"
"182.7000","3.6527","5.93301","0.03800"
"183.0000","3.6587","5.93333","0.03807"
"183.3000","3.6645","5.93244","0.03814"
"183.6000","3.6707","5.93364","0.03821"
"183.9000","3.6764","5.93276","0.03828"
"184.2000","3.6827","5.93501","0.03836"
"184.5000","3.6883","5.93292","0.03843"
"184.8000","3.6947","5.93721","0.03850"
"185.1000","3.7006","5.93659","0.03857"
"185.4000","3.7067","5.93719","0.03864"
"185.7000","3.7125","5.93662","0.03871"
"186.0000","3.7185","5.93693","0.03878"
"186.3000","3.7246","5.93866","0.03885"
"186.6000","3.7304","5.93733","0.03892"
"186.9000","3.7367","5.94077","0.03900"
"187.2000","3.7427","5.93979","0.03907"
"187.5000","3.7486","5.94051","0.03914"
"187.8000","3.7545","5.93967","0.03921"
"188.1000","3.7606","5.94098","0.03928"
"188.4000","3.7666","5.94171","0.03936"
"188.7000","3.7725","5.94098","0.03943"
"189.0000","3.7785","5.94311","0.03950"
"189.3000","3.7847","5.94411","0.03958"
"189.6000","3.7905","5.94338","0.03964"
"189.9000","3.7966","5.94358","0.03972"
"190.2000","3.8024","5.94331","0.03979"
"190.5000","3.8086","5.94553","0.03986"
"190.8000","3.8144","5.94519","0.03993"
"191.1000","3.8206","5.94706","0.04000"
"191.4000","3.8267","5.94797","0.04008"
"191.7000","3.8325","5.94689","0.04015"
"192.0000","3.8386","5.94799","0.04022"
"192.3000","3.8445","5.94706","0.04029"
"192.6000","3.8508","5.95023","0.04036"
"192.9000","3.8564","5.94770","0.04043"
"193.2000","3.8626","5.95116","0.04051"
"193.5000","3.8686","5.95082","0.04058"
"193.8000","3.8746","5.95136","0.04065"
"194.1000","3.8805","5.95069","0.04072"
"194.4000","3.8864","5.95054","0.04079"
"194.7000","3.8926","5.95321","0.04087"
"195.0000","3.8985","5.95200","0.04094"
"195.3000","3.9046","5.95448","0.04101"
"195.6000","3.9106","5.95364","0.04109"
"195.9000","3.9166","5.95453","0.04116"
"196.2000","3.9225","5.95347","0.04123"
"196.5000","3.9285","5.95462","0.04130"
"196.8000","3.9346","5.95592","0.04137"
"197.1000","3.9406","5.95589","0.04145"
"197.4000","3.9465","5.95619","0.04152"
"197.7000","3.9527","5.95788","0.04159"
"198.0000","3.9585","5.95694","0.04166"
"198.3000","3.9646","5.95799","0.04174"
"198.6000","3.9704","5.95661","0.04181"
"198.9000","3.9767","5.95989","0.04188"
"199.2000","3.9826","5.95953","0.04195"
"199.5000","3.9886","5.96041","0.04203"
"199.8000","3.9947","5.96142","0.04210"
"200.1000","4.0005","5.96027","0.04217"
"200.4000","4.0067","5.96183","0.04225"
"200.7000","4.0124","5.95988","0.04232"
"201.0000","4.0188","5.96424","0.04239"
"201.3000","4.0245","5.96175","0.04246"
"201.6000","4.0306","5.96445","0.04254"
"201.9000","4.0365","5.96308","0.04261"
"202.2000","4.0426","5.96472","0.04268"
"202.5000","4.0485","5.96386","0.04275"
"202.8000","4.0544","5.96374","0.04283"
"203.1000","4.0606","5.96581","0.04290"
"203.4000","4.0666","5.96628","0.04297"
"203.7000","4.0725","5.96640","0.04304"
"204.0000","4.0786","5.96655","0.04312"
"204.3000","4.0845","5.96687","0.04319"
"204.6000","4.0906","5.96739","0.04326"
"204.9000","4.0965","5.96709","0.04334"
"205.2000","4.1027","5.96902","0.04341"
"205.5000","4.1086","5.96940","0.04348"
"205.8000","4.1144","5.96896","0.04356"
"206.1000","4.1206","5.97043","0.04363"
"206.4000","4.1265","5.96961","0.04370"
"206.7000","4.1328","5.97174","0.04378"
"207.0000","4.1384","5.96907","0.04385"
"207.3000","4.1447","5.97292","0.04393"
"207.6000","4.1505","5.97221","0.04400"
"207.9000","4.1566","5.97336","0.04407"
"208.2000","4.1626","5.97289","0.04415"
"208.5000","4.1686","5.97297","0.04422"
"208.8000","4.1747","5.97442","0.04429"
"209.1000","4.1805","5.97287","0.04437"
"209.4000","4.1867","5.97580","0.04444"
"209.7000","4.1926","5.97478","0.04451"
"210.0000","4.1985","5.96208","0.04457"
"210.3000","4.2045","5.96947","0.04464"
"210.6000","4.2106","5.97485","0.04471"
"210.9000","4.2166","5.97683","0.04478"
"211.2000","4.2225","5.97663","0.04485"
"211.5000","4.2285","5.97818","0.04492"
"211.8000","4.2346","5.97916","0.04500"
"212.1000","4.2404","5.97862","0.04507"
"212.4000","4.2466","5.97914","0.04515"
"212.7000","4.2524","5.97875","0.04522"
"213.0000","4.2587","5.98052","0.04529"
"213.3000","4.2645","5.97963","0.04537"
"213.6000","4.2706","5.98089","0.04544"
"213.9000","4.2766","5.98158","0.04552"
"214.2000","4.2825","5.98086","0.04559"
"214.5000","4.2886","5.98222","0.04566"
"214.8000","4.2945","5.98112","0.04574"
"215.1000","4.3008","5.98390","0.04581"
"215.4000","4.3065","5.98169","0.04588"
"215.7000","4.3127","5.98432","0.04596"
"216.0000","4.3185","5.98366","0.04603"
"216.3000","4.3246","5.98450","0.04611"
"216.6000","4.3306","5.98425","0.04618"
"216.9000","4.3365","5.98385","0.04626"
"217.2000","4.3427","5.98643","0.04633"
"217.5000","4.3486","5.98475","0.04641"
"217.8000","4.3546","5.98670","0.04648"
"218.1000","4.3606","5.98565","0.04656"
"218.4000","4.3665","5.98659","0.04663"
"218.7000","4.3725","5.98607","0.04670"
"219.0000","4.3785","5.98705","0.04678"
"219.3000","4.3847","5.98800","0.04685"
"219.6000","4.3906","5.98791","0.04693"
"219.9000","4.3965","5.98789","0.04700"
"220.2000","4.4026","5.98925","0.04708"
"220.5000","4.4084","5.98859","0.04715"
"220.8000","4.4147","5.98981","0.04723"
"221.1000","4.4204","5.98851","0.04730"
"221.4000","4.4267","5.99112","0.04738"
"221.7000","4.4326","5.99077","0.04745"
"222.0000","4.4386","5.99116","0.04753"
"222.3000","4.4446","5.99151","0.04760"
"222.6000","4.4504","5.99097","0.04768"
"222.9000","4.4566","5.99299","0.04775"
"223.2000","4.4624","5.99095","0.04783"
"223.5000","4.4688","5.99495","0.04790"
"223.8000","4.4746","5.99221","0.04798"
"224.1000","4.4806","5.99408","0.04805"
"224.4000","4.4864","5.99251","0.04813"
"224.7000","4.4926","5.99468","0.04820"
"225.0000","4.4986","5.99427","0.04828"
"225.3000","4.5045","5.99383","0.04835"
"225.6000","4.5106","5.99563","0.04843"
"225.9000","4.5167","5.99620","0.04851"
"226.2000","4.5225","5.99564","0.04858"
"226.5000","4.5285","5.99563","0.04866"
"226.8000","4.5344","5.99572","0.04873"
"227.1000","4.5406","5.99694","0.04881"
"227.4000","4.5465","5.99642","0.04888"
"227.7000","4.5527","5.99800","0.04896"
"228.0000","4.5587","5.99829","0.04904"
"228.3000","4.5644","5.99736","0.04911"
"228.6000","4.5706","5.99847","0.04919"
"228.9000","4.5764","5.99770","0.04927"
"229.2000","4.5827","6.00023","0.04934"
"229.5000","4.5884","5.99758","0.04942"
"229.8000","4.5948","6.00136","0.04950"
"230.1000","4.6006","6.00026","0.04957"
"230.4000","4.6066","6.00072","0.04965"
"230.7000","4.6125","5.99999","0.04972"
"231.0000","4.6185","6.00032","0.04980"
"231.3000","4.6246","6.00212","0.04988"
"231.6000","4.6305","6.00054","0.04995"
"231.9000","4.6367","6.00352","0.05003"
"232.2000","4.6426","6.00221","0.05011"
"232.5000","4.6485","6.00270","0.05018"
"232.8000","4.6545","6.00189","0.05026"
"233.1000","4.6605","6.00285","0.05033"
"233.4000","4.6666","6.00384","0.05041"
"233.7000","4.6725","6.00266","0.05049"
"234.0000","4.6786","6.00425","0.05057"
"234.3000","4.6847","6.00504","0.05064"
"234.6000","4.6905","6.00440","0.05072"
"234.9000","4.6966","6.00425","0.05080"
"235.2000","4.7023","6.00386","0.05087"
"235.5000","4.7087","6.00620","0.05095"
"235.8000","4.7145","6.00527","0.05103"
"236.1000","4.7207","6.00648","0.05111"
"236.4000","4.7267","6.00698","0.05119"
"236.7000","4.7325","6.00598","0.05126"
"237.0000","4.7386","6.00684","0.05134"
"237.3000","4.7444","6.00597","0.05142"
"237.6000","4.7508","6.00927","0.05150"
"237.9000","4.7565","6.00675","0.05157"
"238.2000","4.7627","6.00926","0.05165"
"238.5000","4.7686","6.00831","0.05173"
"238.8000","4.7746","6.00884","0.05181"
"239.1000","4.7805","6.00829","0.05188"
"239.4000","4.7864","6.00785","0.05196"
"239.7000","4.7927","6.01072","0.05204"
"240.0000","4.7986","6.00912","0.05212"
"240.3000","4.8046","6.01080","0.05220"
"240.6000","4.8106","6.00957","0.05228"
"240.9000","4.8165","6.01015","0.05235"
"241.2000","4.8224","6.00933","0.05243"
"241.5000","4.8284","6.01027","0.05251"
"241.8000","4.8346","6.01170","0.05259"
"242.1000","4.8406","6.01175","0.05267"
"242.4000","4.8465","6.01118","0.05275"
"242.7000","4.8527","6.01254","0.05282"
"243.0000","4.8585","6.01117","0.05290"
"243.3000","4.8646","6.01224","0.05298"
"243.6000","4.8703","6.01050","0.05306"
"243.9000","4.8767","6.01421","0.05314"
"244.2000","4.8826","6.01357","0.05322"
"244.5000","4.8886","6.01369","0.05330"
"244.8000","4.8946","6.01393","0.05338"
"245.1000","4.9005","6.01312","0.05345"
"245.4000","4.9066","6.01465","0.05353"
"245.7000","4.9124","6.01246","0.05361"
"246.0000","4.9188","6.01691","0.05369"
"246.3000","4.9246","6.01438","0.05377"
"246.6000","4.9307","6.01623","0.05385"
"246.9000","4.9365","6.01447","0.05393"
"247.2000","4.9426","6.01604","0.05401"
"247.5000","4.9485","6.01493","0.05409"
"247.8000","4.9544","6.01465","0.05417"
"248.1000","4.9606","6.01683","0.05425"
"248.4000","4.9667","6.01713","0.05433"
"248.7000","4.9725","6.01630","0.05441"
"249.0000","4.9786","6.01618","0.05449"
"249.3000","4.9844","6.01609","0.05457"
"249.6000","4.9906","6.01683","0.05465"
"249.9000","4.9964","6.01625","0.05473"
"250.2000","5.0026","6.01849","0.05481"
"250.5000","5.0088","6.01886","0.05489"
"250.8000","5.0145","6.01726","0.05497"
"251.1000","5.0207","6.01840","0.05505"
"251.4000","5.0264","6.01709","0.05513"
"251.7000","5.0327","6.01941","0.05521"
"252.0000","5.0383","6.01641","0.05529"
"252.3000","5.0448","6.02101","0.05537"
"252.6000","5.0506","6.01942","0.05545"
"252.9000","5.0567","6.02016","0.05554"
"253.2000","5.0625","6.01862","0.05561"
"253.5000","5.0685","6.01908","0.05570"
"253.8000","5.0746","6.02027","0.05578"
"254.1000","5.0804","6.01869","0.05586"
"254.4000","5.0867","6.02178","0.05594"
"254.7000","5.0927","6.02096","0.05602"
"255.0000","5.0986","6.02107","0.05610"
"255.3000","5.1045","6.01963","0.05618"
"255.6000","5.1106","6.02062","0.05627"
"255.9000","5.1166","6.02094","0.05635"
"256.2000","5.1225","6.02041","0.05643"
"256.5000","5.1285","6.02161","0.05651"
"256.8000","5.1348","6.02297","0.05659"
"257.1000","5.1405","6.02130","0.05667"
"257.4000","5.1466","6.02152","0.05675"
"257.7000","5.1524","6.02040","0.05684"
"258.0000","5.1587","6.02291","0.05692"
"258.3000","5.1644","6.02138","0.05700"
"258.6000","5.1707","6.02338","0.05708"
"258.9000","5.1767","6.02337","0.05717"
"259.2000","5.1825","6.02244","0.05725"
"259.5000","5.1886","6.02276","0.05733"
"259.8000","5.1944","6.02192","0.05741"
"260.1000","5.2008","6.02433","0.05750"
"260.4000","5.2064","6.02176","0.05758"
"260.7000","5.2126","6.02457","0.05766"
"261.0000","5.2186","6.02375","0.05775"
"261.3000","5.2246","6.02394","0.05783"
"261.6000","5.2305","6.02307","0.05791"
"261.9000","5.2365","6.02261","0.05799"
"262.2000","5.2426","6.02480","0.05808"
"262.5000","5.2485","6.02354","0.05816"
"262.8000","5.2545","6.02521","0.05824"
"263.1000","5.2607","6.02494","0.05833"
"263.4000","5.2665","6.02478","0.05841"
"263.7000","5.2726","6.02405","0.05850"
"264.0000","5.2785","6.02400","0.05858"
"264.3000","5.2847","6.02554","0.05867"
"264.6000","5.2905","6.02459","0.05875"
"264.9000","5.2965","6.02524","0.05883"
"265.2000","5.3027","6.02607","0.05892"
"265.5000","5.3085","6.02531","0.05900"
"265.8000","5.3146","6.02505","0.05909"
"266.1000","5.3204","6.02387","0.05917"
"266.4000","5.3267","6.02642","0.05926"
"266.7000","5.3325","6.02598","0.05934"
"267.0000","5.3386","6.02611","0.05943"
"267.3000","5.3447","6.02674","0.05951"
"267.6000","5.3505","6.02519","0.05960"
"267.9000","5.3566","6.02639","0.05968"
"268.2000","5.3624","6.02422","0.05977"
"268.5000","5.3688","6.02789","0.05986"
"268.8000","5.3745","6.02531","0.05994"
"269.1000","5.3806","6.02721","0.06002"
"269.4000","5.3865","6.02592","0.06011"
"269.7000","5.3926","6.02708","0.06020"
"270.0000","5.3986","6.02608","0.06028"
"270.3000","5.4044","6.02518","0.06037"
"270.6000","5.4106","6.02720","0.06045"
"270.9000","5.4166","6.02716","0.06054"
"271.2000","5.4225","6.02727","0.06063"
"271.5000","5.4286","6.02663","0.06071"
"271.8000","5.4345","6.02682","0.06080"
"272.1000","5.4406","6.02648","0.06089"
"272.4000","5.4465","6.02614","0.06097"
"272.7000","5.4526","6.02728","0.06106"
"273.0000","5.4587","6.02773","0.06115"
"273.3000","5.4644","6.02657","0.06123"
"273.6000","5.4707","6.02803","0.06133"
"273.9000","5.4765","6.02622","0.06141"
"274.2000","5.4827","6.02805","0.06150"
"274.5000","5.4884","6.02502","0.06158"
"274.8000","5.4947","6.02862","0.06167"
"275.1000","5.5005","6.02736","0.06176"
"275.4000","5.5066","6.02803","0.06185"
"275.7000","5.5126","6.02703","0.06194"
"276.0000","5.5185","6.02681","0.06203"
"276.3000","5.5247","6.02813","0.06212"
"276.6000","5.5305","6.02616","0.06221"
"276.9000","5.5367","6.02861","0.06230"
"277.2000","5.5426","6.02680","0.06238"
"277.5000","5.5485","6.02752","0.06247"
"277.8000","5.5545","6.02650","0.06256"
"278.1000","5.5606","6.02754","0.06265"
"278.4000","5.5666","6.02736","0.06274"
"278.7000","5.5725","6.02618","0.06283"
"279.0000","5.5785","6.02706","0.06292"
"279.3000","5.5846","6.02772","0.06301"
"279.6000","5.5904","6.02667","0.06310"
"279.9000","5.5966","6.02676","0.06319"
"280.2000","5.6024","6.02583","0.06328"
"280.5000","5.6087","6.02734","0.06337"
"280.8000","5.6145","6.02615","0.06346"
"281.1000","5.6206","6.02737","0.06355"
"281.4000","5.6266","6.02727","0.06364"
"281.7000","5.6325","6.02625","0.06374"
"282.0000","5.6386","6.02690","0.06383"
"282.3000","5.6445","6.02572","0.06392"
"282.6000","5.6508","6.02806","0.06401"
"282.9000","5.6565","6.02520","0.06410"
"283.2000","5.6626","6.02718","0.06419"
"283.5000","5.6685","6.02623","0.06429"
"283.8000","5.6746","6.02644","0.06438"
"284.1000","5.6805","6.02575","0.06447"
"284.4000","5.6865","6.02521","0.06457"
"284.7000","5.6927","6.02701","0.06466"
"285.0000","5.6986","6.02497","0.06476"
"285.3000","5.7046","6.02622","0.06485"
"285.6000","5.7105","6.02497","0.06494"
"285.9000","5.7165","6.02555","0.06503"
"286.2000","5.7225","6.02440","0.06513"
"286.5000","5.7285","6.02482","0.06522"
"286.8000","5.7346","6.02534","0.06532"
"287.1000","5.7406","6.02483","0.06541"
"287.4000","5.7465","6.02395","0.06551"
"287.7000","5.7526","6.02495","0.06560"
"288.0000","5.7584","6.02361","0.06570"
"288.3000","5.7647","6.02449","0.06580"
"288.6000","5.7704","6.02213","0.06589"
"288.9000","5.7768","6.02502","0.06599"
"289.2000","5.7826","6.02356","0.06608"
"289.5000","5.7886","6.02336","0.06618"
"289.8000","5.7946","6.02304","0.06628"
"290.1000","5.8004","6.02206","0.06637"
"290.4000","5.8066","6.02354","0.06647"
"290.7000","5.8124","6.02084","0.06657"
"291.0000","5.8188","6.02433","0.06667"
"291.3000","5.8245","6.02099","0.06676"
"291.6000","5.8306","6.02239","0.06686"
"291.9000","5.8364","6.02019","0.06696"
"292.2000","5.8426","6.02179","0.06706"
"292.5000","5.8486","6.02062","0.06716"
"292.8000","5.8545","6.01957","0.06726"
"293.1000","5.8606","6.02079","0.06736"
"293.4000","5.8667","6.02032","0.06746"
"293.7000","5.8725","6.01936","0.06755"
"294.0000","5.8785","6.01857","0.06766"
"294.3000","5.8844","6.01819","0.06775"
"294.6000","5.8906","6.01873","0.06786"
"294.9000","5.8965","6.01729","0.06797"
"295.2000","5.9027","6.01850","0.06807"
"295.5000","5.9087","6.01783","0.06817"
"295.8000","5.9145","6.01616","0.06827"
"296.1000","5.9206","6.01657","0.06838"
"296.4000","5.9264","6.01505","0.06847"
"296.7000","5.9327","6.01685","0.06858"
"297.0000","5.9384","6.01316","0.06868"
"297.3000","5.9448","6.01613","0.06879"
"297.6000","5.9506","6.01437","0.06889"
"297.9000","5.9566","6.01413","0.06900"
"298.2000","5.9625","6.01258","0.06910"
"298.5000","5.9685","6.01211","0.06920"
"298.8000","5.9747","6.01312","0.06931"
"299.1000","5.9805","6.01030","0.06941"
"299.4000","5.9867","6.01240","0.06952"
"299.7000","5.9926","6.01013","0.06963"
"300.0000","5.9985","6.00997","0.06973"
"300.3000","6.0044","6.00790","0.06984"
"300.6000","6.0105","6.00828","0.06995"
"300.9000","6.0166","6.00820","0.07006"
"301.2000","6.0225","6.00587","0.07017"
"301.5000","6.0286","6.00657","0.07028"
"301.8000","6.0347","6.00603","0.07039"
"302.1000","6.0405","6.00407","0.07050"
"302.4000","6.0466","6.00277","0.07060"
"302.7000","6.0523","6.00142","0.07071"
"303.0000","6.0586","6.00265","0.07083"
"303.3000","6.0645","6.00074","0.07093"
"303.6000","6.0706","6.00056","0.07105"
"303.9000","6.0767","5.99984","0.07116"
"304.2000","6.0825","5.99732","0.07127"
"304.5000","6.0885","5.99707","0.07138"
"304.8000","6.0944","5.99479","0.07149"
"305.1000","6.1008","5.99677","0.07160"
"305.4000","6.1065","5.99235","0.07172"
"305.7000","6.1127","5.99370","0.07183"
"306.0000","6.1186","5.99150","0.07194"
"306.3000","6.1246","5.99040","0.07205"
"306.6000","6.1305","5.98798","0.07217"
"306.9000","6.1364","5.98622","0.07228"
"307.2000","6.1427","5.98755","0.07240"
"307.5000","6.1486","5.98417","0.07251"
"307.8000","6.1546","5.98419","0.07263"
"308.1000","6.1606","5.98093","0.07275"
"308.4000","6.1665","5.98011","0.07286"
"308.7000","6.1725","5.97708","0.07298"
"309.0000","6.1784","5.97649","0.07309"
"309.3000","6.1847","5.97585","0.07321"
"309.6000","6.1906","5.97321","0.07333"
"309.9000","6.1965","5.97083","0.07345"
"310.2000","6.2027","5.97011","0.07356"
"310.5000","6.2085","5.96671","0.07368"
"310.8000","6.2146","5.96549","0.07380"
"311.1000","6.2203","5.96173","0.07392"
"311.4000","6.2267","5.96281","0.07404"
"311.7000","6.2326","5.95942","0.07416"
"312.0000","6.2386","5.95700","0.07428"
"312.3000","6.2447","5.95484","0.07440"
"312.6000","6.2505","5.95126","0.07452"
"312.9000","6.2566","5.95040","0.07464"
"313.2000","6.2623","5.94530","0.07476"
"313.5000","6.2688","5.94731","0.07488"
"313.8000","6.2746","5.94098","0.07500"
"314.1000","6.2807","5.94049","0.07512"
"314.4000","6.2866","5.93527","0.07524"
"314.7000","6.2926","5.93385","0.07537"
"315.0000","6.2985","5.92955","0.07549"
"315.3000","6.3044","5.92607","0.07561"
"315.6000","6.3106","5.92529","0.07573"
"315.9000","6.3167","5.92140","0.07586"
"316.2000","6.3225","5.91749","0.07598"
"316.5000","6.3286","5.91350","0.07611"
"316.8000","6.3344","5.91017","0.07623"
"317.1000","6.3405","5.90680","0.07635"
"317.4000","6.3464","5.90253","0.07648"
"317.7000","6.3527","5.90052","0.07660"
"318.0000","6.3587","5.89636","0.07673"
"318.3000","6.3645","5.89129","0.07685"
"318.6000","6.3707","5.88803","0.07698"
"318.9000","6.3764","5.88282","0.07710"
"319.2000","6.3827","5.88039","0.07723"
"319.5000","6.3883","5.87315","0.07735"
"319.8000","6.3947","5.87296","0.07748"
"320.1000","6.4006","5.86708","0.07760"
"320.4000","6.4067","5.86266","0.07773"
"320.7000","6.4126","5.85670","0.07785"
"321.0000","6.4185","5.85180","0.07798"
"321.3000","6.4246","5.84866","0.07811"
"321.6000","6.4304","5.84134","0.07823"
"321.9000","6.4367","5.83965","0.07836"
"322.2000","6.4427","5.83256","0.07849"
"322.5000","6.4486","5.82800","0.07862"
"322.8000","6.4545","5.82072","0.07874"
"323.1000","6.4605","5.81653","0.07887"
"323.4000","6.4666","5.81113","0.07900"
"323.7000","6.4725","5.80405","0.07913"
"324.0000","6.4785","5.80028","0.07926"
"324.3000","6.4847","5.79428","0.07939"
"324.6000","6.4905","5.78751","0.07951"
"324.9000","6.4966","5.78043","0.07965"
"325.2000","6.5024","5.77456","0.07977"
"325.5000","6.5086","5.76957","0.07991"
"325.8000","6.5145","5.76216","0.08003"
"326.1000","6.5206","5.75689","0.08017"
"326.4000","6.5267","5.75049","0.08030"
"326.7000","6.5326","5.74251","0.08043"
"327.0000","6.5387","5.73593","0.08056"
"327.3000","6.5445","5.72742","0.08069"
"327.6000","6.5508","5.72310","0.08082"
"327.9000","6.5564","5.71312","0.08095"
"328.2000","6.5626","5.70898","0.08108"
"328.5000","6.5686","5.69987","0.08122"
"328.8000","6.5746","5.69245","0.08135"
"329.1000","6.5805","5.68347","0.08149"
"329.4000","6.5864","5.67509","0.08162"
"329.7000","6.5926","5.66968","0.08175"
"330.0000","6.5985","5.65895","0.08189"
"330.3000","6.6046","5.65344","0.08202"
"330.6000","6.6106","5.64242","0.08216"
"330.9000","6.6166","5.63551","0.08229"
"331.2000","6.6225","5.62418","0.08242"
"331.5000","6.6285","5.61680","0.08256"
"331.8000","6.6346","5.60796","0.08270"
"332.1000","6.6405","5.59880","0.08283"
"332.4000","6.6465","5.58994","0.08296"
"332.7000","6.6527","5.58076","0.08310"
"333.0000","6.6585","5.57009","0.08324"
"333.3000","6.6647","5.55966","0.08338"
"333.6000","6.6704","5.54914","0.08351"
"333.9000","6.6767","5.54139","0.08365"
"334.2000","6.6826","5.53033","0.08378"
"334.5000","6.6886","5.51998","0.08392"
"334.8000","6.6947","5.50903","0.08406"
"335.1000","6.7005","5.49711","0.08420"
"335.4000","6.7067","5.48671","0.08434"
"335.7000","6.7124","5.47293","0.08448"
"336.0000","6.7188","5.46523","0.08462"
"336.3000","6.7245","5.45017","0.08476"
"336.6000","6.7306","5.44104","0.08490"
"336.9000","6.7365","5.42604","0.08504"
"337.2000","6.7427","5.41523","0.08518"
"337.5000","6.7486","5.40062","0.08532"
"337.8000","6.7545","5.38736","0.08546"
"338.1000","6.7606","5.37607","0.08561"
"338.4000","6.7666","5.36166","0.08575"
"338.7000","6.7725","5.34839","0.08589"
"339.0000","6.7786","5.33212","0.08604"
"339.3000","6.7845","5.31836","0.08618"
"339.6000","6.7906","5.30157","0.08633"
"339.9000","6.7965","5.28591","0.08648"
"340.2000","6.8026","5.27047","0.08663"
"340.5000","6.8086","5.25324","0.08677"
"340.8000","6.8144","5.23463","0.08692"
"341.1000","6.8206","5.21373","0.08708"
"341.4000","6.8265","5.19192","0.08723"
"341.7000","6.8327","5.16781","0.08740"
"342.0000","6.8384","5.14336","0.08755"
"342.3000","6.8447","5.11974","0.08771"
"342.6000","6.8506","5.08883","0.08788"
"342.9000","6.8566","5.05560","0.08805"
"343.2000","6.8626","5.01924","0.08823"
"343.5000","6.8686","4.97732","0.08842"
"343.8000","6.8747","4.93288","0.08861"
"344.1000","6.8805","4.88452","0.08881"
"344.4000","6.8867","4.83253","0.08902"
"344.7000","6.8926","4.74900","0.08927"
"345.0000","6.8986","4.59309","0.08964"
"345.3000","6.9046","4.43606","0.09003"
"345.6000","6.9106","4.35291","0.09028"
"345.9000","6.9167","4.26413","0.09055"
"346.2000","6.9226","4.15271","0.09085"
"346.3310","6.9252","3.92155","0.09125"
"346.3600","6.9259","3.68406","0.09164"
"346.3710","6.9261","3.61554","0.09175"