File: Coupon Test Data/Tensile Test_Neebajan_Alan_3.csv
Time,Displacement,Force,Strain 1
(s),(mm),(kN),(mm/mm)
"0.0000","0.0000","0.16113","-0.00023"
"0.4000","0.0063","0.23379","-0.00019"
"0.8000","0.0142","0.32991","-0.00015"
"1.2000","0.0224","0.42738","-0.00010"
"1.6000","0.0304","0.52164","-0.00006"
"2.0000","0.0385","0.61430","-0.00002"
"2.4000","0.0465","0.69862","0.00002"
"2.8000","0.0543","0.78206","0.00006"
"3.2000","0.0625","0.87003","0.00010"
"3.6000","0.0704","0.94982","0.00014"
"4.0000","0.0784","1.03066","0.00018"
"4.4000","0.0864","1.11030","0.00021"
"4.8000","0.0945","1.18646","0.00025"
"5.2000","0.1026","1.26301","0.00029"
"5.6000","0.1105","1.33570","0.00032"
"6.0000","0.1185","1.40211","0.00035"
"6.4000","0.1264","1.47244","0.00038"
"6.8000","0.1344","1.54252","0.00041"
"7.2000","0.1423","1.60490","0.00044"
"7.6000","0.1505","1.67446","0.00047"
"8.0000","0.1585","1.74060","0.00051"
"8.4000","0.1664","1.80313","0.00054"
"8.8000","0.1745","1.86264","0.00056"
"9.2000","0.1823","1.92285","0.00059"
"9.6000","0.1905","1.98487","0.00062"
"10.0000","0.1985","2.04013","0.00064"
"10.4000","0.2064","2.09887","0.00067"
"10.8000","0.2145","2.15640","0.00070"
"11.2000","0.2224","2.20582","0.00072"
"11.6000","0.2305","2.26332","0.00075"
"12.0000","0.2384","2.31626","0.00077"
"12.4000","0.2465","2.37076","0.00080"
"12.8000","0.2544","2.42004","0.00082"
"13.2000","0.2624","2.47375","0.00084"
"13.6000","0.2705","2.52684","0.00087"
"14.0000","0.2785","2.57412","0.00089"
"14.4000","0.2866","2.62547","0.00092"
"14.8000","0.2943","2.67305","0.00094"
"15.2000","0.3025","2.71879","0.00096"
"15.6000","0.3104","2.77053","0.00098"
"16.0000","0.3184","2.82103","0.00101"
"16.4000","0.3265","2.86911","0.00103"
"16.8000","0.3345","2.91751","0.00105"
"17.2000","0.3425","2.96810","0.00107"
"17.6000","0.3503","3.01054","0.00109"
"18.0000","0.3585","3.06224","0.00112"
"18.4000","0.3664","3.11299","0.00114"
"18.8000","0.3744","3.16236","0.00117"
"19.2000","0.3825","3.20832","0.00119"
"19.6000","0.3905","3.25911","0.00121"
"20.0000","0.3985","3.30969","0.00124"
"20.4000","0.4063","3.35285","0.00126"
"20.8000","0.4145","3.40541","0.00128"
"21.2000","0.4224","3.44993","0.00130"
"21.6000","0.4303","3.49976","0.00133"
"22.0000","0.4385","3.55206","0.00135"
"22.4000","0.4466","3.59794","0.00137"
"22.8000","0.4545","3.64849","0.00140"
"23.2000","0.4624","3.69647","0.00142"
"23.6000","0.4706","3.74428","0.00144"
"24.0000","0.4783","3.79327","0.00147"
"24.4000","0.4864","3.83907","0.00149"
"24.8000","0.4945","3.89135","0.00151"
"25.2000","0.5026","3.93876","0.00153"
"25.6000","0.5104","3.98731","0.00156"
"26.0000","0.5183","4.03221","0.00158"
"26.4000","0.5267","4.08313","0.00161"
"26.8000","0.5344","4.12982","0.00163"
"27.2000","0.5424","4.17571","0.00165"
"27.6000","0.5505","4.22529","0.00168"
"28.0000","0.5585","4.27328","0.00170"
"28.4000","0.5664","4.31800","0.00172"
"28.8000","0.5744","4.36193","0.00174"
"29.2000","0.5826","4.41000","0.00177"
"29.6000","0.5903","4.45401","0.00179"
"30.0000","0.5983","4.49938","0.00181"
"30.4000","0.6064","4.54695","0.00184"
"30.8000","0.6147","4.58925","0.00186"
"31.2000","0.6224","4.63428","0.00188"
"31.6000","0.6304","4.67833","0.00190"
"32.0000","0.6387","4.72623","0.00193"
"32.4000","0.6462","4.76854","0.00195"
"32.8000","0.6544","4.81411","0.00197"
"33.2000","0.6625","4.86160","0.00200"
"33.6000","0.6705","4.90736","0.00202"
"34.0000","0.6784","4.95162","0.00205"
"34.4000","0.6864","4.99648","0.00207"
"34.8000","0.6947","5.04447","0.00209"
"35.2000","0.7023","5.08796","0.00212"
"35.6000","0.7104","5.13317","0.00214"
"36.0000","0.7185","5.18027","0.00217"
"36.4000","0.7265","5.22691","0.00219"
"36.8000","0.7343","5.27153","0.00222"
"37.2000","0.7425","5.31770","0.00224"
"37.6000","0.7507","5.36649","0.00227"
"38.0000","0.7582","5.40813","0.00229"
"38.4000","0.7664","5.45540","0.00231"
"38.8000","0.7744","5.50328","0.00234"
"39.2000","0.7825","5.54937","0.00237"
"39.6000","0.7905","5.59529","0.00239"
"40.0000","0.7985","5.64161","0.00242"
"40.4000","0.8066","5.68924","0.00245"
"40.8000","0.8142","5.73166","0.00247"
"41.2000","0.8224","5.77863","0.00250"
"41.6000","0.8305","5.82639","0.00253"
"42.0000","0.8385","5.87199","0.00255"
"42.4000","0.8463","5.91644","0.00258"
"42.8000","0.8546","5.96376","0.00261"
"43.2000","0.8627","6.01155","0.00264"
"43.6000","0.8703","6.05216","0.00266"
"44.0000","0.8785","6.09897","0.00270"
"44.4000","0.8865","6.14518","0.00273"
"44.8000","0.8944","6.18851","0.00275"
"45.2000","0.9023","6.23283","0.00278"
"45.6000","0.9106","6.27879","0.00282"
"46.0000","0.9187","6.32414","0.00285"
"46.4000","0.9262","6.36274","0.00288"
"46.8000","0.9345","6.40698","0.00291"
"47.2000","0.9425","6.45022","0.00294"
"47.6000","0.9505","6.49138","0.00298"
"48.0000","0.9584","6.53153","0.00302"
"48.4000","0.9666","6.57322","0.00305"
"48.8000","0.9746","6.61359","0.00309"
"49.2000","0.9822","6.64647","0.00313"
"49.6000","0.9905","6.68557","0.00317"
"50.0000","0.9985","6.72196","0.00321"
"50.4000","1.0064","6.75375","0.00326"
"50.8000","1.0143","6.78606","0.00330"
"51.2000","1.0226","6.81786","0.00335"
"51.6000","1.0307","6.84680","0.00341"
"52.0000","1.0384","6.86965","0.00346"
"52.4000","1.0466","6.89624","0.00352"
"52.8000","1.0545","6.91730","0.00359"
"53.2000","1.0624","6.93621","0.00365"
"53.6000","1.0703","6.95376","0.00372"
"54.0000","1.0786","6.97111","0.00380"
"54.4000","1.0866","6.98587","0.00387"
"54.8000","1.0943","6.99446","0.00395"
"55.2000","1.1026","7.00889","0.00403"
"55.6000","1.1104","7.01808","0.00411"
"56.0000","1.1184","7.02662","0.00419"
"56.4000","1.1265","7.03571","0.00428"
"56.8000","1.1346","7.04429","0.00436"
"57.2000","1.1425","7.05139","0.00444"
"57.6000","1.1503","7.05534","0.00453"
"58.0000","1.1586","7.06449","0.00461"
"58.4000","1.1664","7.06798","0.00470"
"58.8000","1.1744","7.07315","0.00479"
"59.2000","1.1824","7.07807","0.00488"
"59.6000","1.1905","7.08381","0.00497"
"60.0000","1.1985","7.08930","0.00505"
"60.4000","1.2064","7.09041","0.00515"
"60.8000","1.2147","7.09731","0.00524"
"61.2000","1.2224","7.09873","0.00533"
"61.6000","1.2304","7.10215","0.00542"
"62.0000","1.2384","7.10607","0.00551"
"62.4000","1.2466","7.11096","0.00560"
"62.8000","1.2545","7.11329","0.00569"
"63.2000","1.2624","7.11444","0.00578"
"63.6000","1.2706","7.11524","0.00586"
"64.0000","1.2783","7.12015","0.00595"
"64.4000","1.2865","7.12479","0.00604"
"64.8000","1.2945","7.12675","0.00614"
"65.2000","1.3026","7.13014","0.00623"
"65.6000","1.3105","7.13240","0.00633"
"66.0000","1.3184","7.13351","0.00642"
"66.4000","1.3266","7.13922","0.00652"
"66.8000","1.3344","7.13856","0.00661"
"67.2000","1.3425","7.14096","0.00671"
"67.6000","1.3504","7.14373","0.00680"
"68.0000","1.3585","7.14650","0.00690"
"68.4000","1.3664","7.14886","0.00700"
"68.8000","1.3746","7.15081","0.00710"
"69.2000","1.3827","7.15428","0.00720"
"69.6000","1.3904","7.15362","0.00729"
"70.0000","1.3985","7.15710","0.00739"
"70.4000","1.4063","7.15846","0.00749"
"70.8000","1.4146","7.16207","0.00759"
"71.2000","1.4224","7.16364","0.00769"
"71.6000","1.4305","7.16481","0.00779"
"72.0000","1.4386","7.16932","0.00789"
"72.4000","1.4463","7.16840","0.00798"
"72.8000","1.4545","7.17170","0.00808"
"73.2000","1.4625","7.17278","0.00819"
"73.6000","1.4706","7.17545","0.00828"
"74.0000","1.4784","7.17638","0.00838"
"74.4000","1.4865","7.17855","0.00848"
"74.8000","1.4946","7.18289","0.00858"
"75.2000","1.5024","7.18176","0.00869"
"75.6000","1.5105","7.18473","0.00879"
"76.0000","1.5184","7.18526","0.00889"
"76.4000","1.5265","7.18830","0.00899"
"76.8000","1.5343","7.18973","0.00909"
"77.2000","1.5425","7.19148","0.00919"
"77.6000","1.5507","7.19524","0.00929"
"78.0000","1.5584","7.19440","0.00939"
"78.4000","1.5665","7.19698","0.00949"
"78.8000","1.5743","7.19754","0.00959"
"79.2000","1.5825","7.20125","0.00969"
"79.6000","1.5904","7.20182","0.00979"
"80.0000","1.5985","7.20379","0.00989"
"80.4000","1.6066","7.20701","0.00999"
"80.8000","1.6144","7.20704","0.01009"
"81.2000","1.6226","7.21026","0.01019"
"81.6000","1.6304","7.20946","0.01029"
"82.0000","1.6386","7.21316","0.01039"
"82.4000","1.6464","7.21385","0.01049"
"82.8000","1.6545","7.21523","0.01059"
"83.2000","1.6626","7.21973","0.01069"
"83.6000","1.6705","7.21903","0.01078"
"84.0000","1.6786","7.22179","0.01088"
"84.4000","1.6864","7.22132","0.01098"
"84.8000","1.6945","7.22446","0.01108"
"85.2000","1.7023","7.22543","0.01118"
"85.6000","1.7105","7.22788","0.01128"
"86.0000","1.7186","7.23052","0.01138"
"86.4000","1.7265","7.23113","0.01148"
"86.8000","1.7345","7.23319","0.01157"
"87.2000","1.7423","7.23264","0.01167"
"87.6000","1.7505","7.23729","0.01177"
"88.0000","1.7584","7.23686","0.01187"
"88.4000","1.7665","7.23844","0.01197"
"88.8000","1.7745","7.24223","0.01206"
"89.2000","1.7825","7.24265","0.01216"
"89.6000","1.7906","7.24516","0.01226"
"90.0000","1.7984","7.24464","0.01235"
"90.4000","1.8066","7.24248","0.01245"
"90.8000","1.8144","7.24182","0.01252"
"91.2000","1.8224","7.24919","0.01262"
"91.6000","1.8304","7.25366","0.01271"
"92.0000","1.8386","7.25548","0.01281"
"92.4000","1.8466","7.25663","0.01290"
"92.8000","1.8544","7.25557","0.01299"
"93.2000","1.8625","7.25980","0.01309"
"93.6000","1.8703","7.25893","0.01319"
"94.0000","1.8785","7.26145","0.01328"
"94.4000","1.8865","7.26425","0.01338"
"94.8000","1.8945","7.26515","0.01347"
"95.2000","1.9025","7.26677","0.01357"
"95.6000","1.9104","7.26654","0.01366"
"96.0000","1.9186","7.27098","0.01376"
"96.4000","1.9264","7.27010","0.01385"
"96.8000","1.9345","7.27213","0.01395"
"97.2000","1.9425","7.27468","0.01404"
"97.6000","1.9505","7.27625","0.01413"
"98.0000","1.9585","7.27859","0.01423"
"98.4000","1.9665","7.27784","0.01432"
"98.8000","1.9747","7.28210","0.01442"
"99.2000","1.9823","7.28028","0.01451"
"99.6000","1.9905","7.28282","0.01460"
"100.0000","1.9984","7.28584","0.01469"
"100.4000","2.0065","7.28704","0.01479"
"100.8000","2.0145","7.28896","0.01488"
"101.2000","2.0224","7.28931","0.01497"
"101.6000","2.0306","7.29258","0.01507"
"102.0000","2.0383","7.29126","0.01516"
"102.4000","2.0465","7.29472","0.01525"
"102.8000","2.0545","7.29643","0.01534"
"103.2000","2.0625","7.29759","0.01544"
"103.6000","2.0705","7.29912","0.01553"
"104.0000","2.0784","7.29990","0.01562"
"104.4000","2.0866","7.26724","0.01567"
"104.8000","2.0943","7.28922","0.01574"
"105.2000","2.1026","7.30397","0.01583"
"105.6000","2.1104","7.30854","0.01592"
"106.0000","2.1184","7.30942","0.01601"
"106.4000","2.1266","7.31267","0.01610"
"106.8000","2.1345","7.31264","0.01619"
"107.2000","2.1426","7.31469","0.01628"
"107.6000","2.1503","7.31313","0.01637"
"108.0000","2.1585","7.31600","0.01647"
"108.4000","2.1663","7.31698","0.01655"
"108.8000","2.1745","7.31895","0.01665"
"109.2000","2.1826","7.32103","0.01674"
"109.6000","2.1905","7.32216","0.01683"
"110.0000","2.1985","7.32430","0.01692"
"110.4000","2.2062","7.32274","0.01701"
"110.8000","2.2146","7.32740","0.01710"
"111.2000","2.2224","7.32786","0.01719"
"111.6000","2.2304","7.32824","0.01728"
"112.0000","2.2385","7.33146","0.01738"
"112.4000","2.2465","7.33308","0.01746"
"112.8000","2.2545","7.33475","0.01756"
"113.2000","2.2624","7.33381","0.01765"
"113.6000","2.2706","7.33762","0.01774"
"114.0000","2.2783","7.33726","0.01783"
"114.4000","2.2864","7.33893","0.01791"
"114.8000","2.2945","7.34219","0.01800"
"115.2000","2.3027","7.34411","0.01810"
"115.6000","2.3105","7.34528","0.01819"
"116.0000","2.3184","7.34396","0.01827"
"116.4000","2.3266","7.34844","0.01837"
"116.8000","2.3343","7.34776","0.01845"
"117.2000","2.3424","7.34937","0.01855"
"117.6000","2.3506","7.35292","0.01864"
"118.0000","2.3586","7.35445","0.01873"
"118.4000","2.3664","7.35486","0.01881"
"118.8000","2.3743","7.35519","0.01891"
"119.2000","2.3827","7.36014","0.01900"
"119.6000","2.3903","7.35825","0.01908"
"120.0000","2.3984","7.35993","0.01918"
"120.4000","2.4065","7.36271","0.01926"
"120.8000","2.4146","7.36488","0.01936"
"121.2000","2.4224","7.36611","0.01944"
"121.6000","2.4304","7.36592","0.01953"
"122.0000","2.4387","7.37072","0.01962"
"122.4000","2.4462","7.36810","0.01971"
"122.8000","2.4543","7.36998","0.01980"
"123.2000","2.4625","7.37422","0.01989"
"123.6000","2.4706","7.37568","0.01998"
"124.0000","2.4784","7.37575","0.02007"
"124.4000","2.4865","7.37673","0.02016"
"124.8000","2.4947","7.36776","0.02023"
"125.2000","2.5022","7.37451","0.02031"
"125.6000","2.5104","7.38089","0.02040"
"126.0000","2.5186","7.38489","0.02049"
"126.4000","2.5266","7.38624","0.02058"
"126.8000","2.5344","7.38608","0.02066"
"127.2000","2.5424","7.38739","0.02075"
"127.6000","2.5508","7.39269","0.02084"
"128.0000","2.5583","7.38880","0.02093"
"128.4000","2.5664","7.39101","0.02102"
"128.8000","2.5745","7.39435","0.02111"
"129.2000","2.5825","7.39501","0.02120"
"129.6000","2.5904","7.39612","0.02128"
"130.0000","2.5985","7.39813","0.02138"
"130.4000","2.6067","7.40179","0.02147"
"130.8000","2.6142","7.39821","0.02155"
"131.2000","2.6224","7.40159","0.02164"
"131.6000","2.6305","7.40416","0.02173"
"132.0000","2.6386","7.40589","0.02182"
"132.4000","2.6464","7.40603","0.02190"
"132.8000","2.6546","7.40787","0.02200"
"133.2000","2.6627","7.41173","0.02208"
"133.6000","2.6702","7.40814","0.02217"
"134.0000","2.6785","7.41212","0.02226"
"134.4000","2.6865","7.41465","0.02235"
"134.8000","2.6945","7.41483","0.02244"
"135.2000","2.7024","7.41548","0.02253"
"135.6000","2.7105","7.41871","0.02261"
"136.0000","2.7187","7.42195","0.02270"
"136.4000","2.7263","7.41849","0.02279"
"136.8000","2.7345","7.42198","0.02288"
"137.2000","2.7425","7.42362","0.02296"
"137.6000","2.7504","7.42488","0.02305"
"138.0000","2.7583","7.42590","0.02314"
"138.4000","2.7666","7.42895","0.02323"
"138.8000","2.7747","7.43179","0.02332"
"139.2000","2.7823","7.42808","0.02340"
"139.6000","2.7905","7.43240","0.02349"
"140.0000","2.7984","7.43385","0.02358"
"140.4000","2.8065","7.43465","0.02367"
"140.8000","2.8145","7.43625","0.02376"
"141.2000","2.8226","7.43894","0.02385"
"141.6000","2.8306","7.44046","0.02393"
"142.0000","2.8383","7.43855","0.02402"
"142.4000","2.8465","7.44289","0.02411"
"142.8000","2.8545","7.44373","0.02420"
"143.2000","2.8624","7.44438","0.02428"
"143.6000","2.8703","7.44493","0.02437"
"144.0000","2.8786","7.44891","0.02446"
"144.4000","2.8866","7.45102","0.02455"
"144.8000","2.8943","7.44863","0.02464"
"145.2000","2.9027","7.45314","0.02473"
"145.6000","2.9104","7.45278","0.02481"
"146.0000","2.9184","7.45336","0.02490"
"146.4000","2.9263","7.45564","0.02499"
"146.8000","2.9346","7.45894","0.02508"
"147.2000","2.9426","7.46027","0.02516"
"147.6000","2.9504","7.45844","0.02525"
"148.0000","2.9585","7.46244","0.02534"
"148.4000","2.9664","7.46271","0.02543"
"148.8000","2.9745","7.46425","0.02552"
"149.2000","2.9824","7.46471","0.02560"
"149.6000","2.9907","7.46858","0.02569"
"150.0000","2.9985","7.46876","0.02578"
"150.4000","3.0063","7.46795","0.02586"
"150.8000","3.0147","7.47348","0.02595"
"151.2000","3.0224","7.47176","0.02604"
"151.6000","3.0305","7.47299","0.02613"
"152.0000","3.0384","7.47478","0.02621"
"152.4000","3.0465","7.47685","0.02630"
"152.8000","3.0545","7.47936","0.02639"
"153.2000","3.0625","7.47876","0.02648"
"153.6000","3.0707","7.48198","0.02656"
"154.0000","3.0784","7.48123","0.02665"
"154.4000","3.0864","7.48270","0.02674"
"154.8000","3.0943","7.48379","0.02683"
"155.2000","3.1026","7.48783","0.02691"
"155.6000","3.1105","7.48779","0.02700"
"156.0000","3.1185","7.48807","0.02709"
"156.4000","3.1266","7.49197","0.02718"
"156.8000","3.1343","7.48987","0.02726"
"157.2000","3.1425","7.49291","0.02735"
"157.6000","3.1504","7.49367","0.02744"
"158.0000","3.1585","7.49573","0.02752"
"158.4000","3.1664","7.49689","0.02761"
"158.8000","3.1744","7.49744","0.02770"
"159.2000","3.1826","7.50157","0.02779"
"159.6000","3.1904","7.49990","0.02787"
"160.0000","3.1985","7.50167","0.02796"
"160.4000","3.2064","7.50237","0.02805"
"160.8000","3.2145","7.50489","0.02814"
"161.2000","3.2224","7.50579","0.02822"
"161.6000","3.2306","7.49056","0.02830"
"162.0000","3.2387","7.50446","0.02838"
"162.4000","3.2464","7.50740","0.02846"
"162.8000","3.2545","7.51118","0.02854"
"163.2000","3.2623","7.51084","0.02863"
"163.6000","3.2705","7.49969","0.02869"
"164.0000","3.2785","7.51100","0.02877"
"164.4000","3.2865","7.51609","0.02886"
"164.8000","3.2946","7.51997","0.02894"
"165.2000","3.3024","7.51909","0.02903"
"165.6000","3.3106","7.52205","0.02911"
"166.0000","3.3184","7.52148","0.02920"
"166.4000","3.3266","7.52401","0.02929"
"166.8000","3.3344","7.52393","0.02937"
"167.2000","3.3425","7.52497","0.02946"
"167.6000","3.3506","7.52905","0.02955"
"168.0000","3.3584","7.52706","0.02963"
"168.4000","3.3666","7.52922","0.02972"
"168.8000","3.3744","7.52902","0.02980"
"169.2000","3.3824","7.53124","0.02989"
"169.6000","3.3903","7.53217","0.02998"
"170.0000","3.3986","7.53440","0.03007"
"170.4000","3.4066","7.53633","0.03015"
"170.8000","3.4145","7.53576","0.03024"
"171.2000","3.4225","7.53798","0.03033"
"171.6000","3.4303","7.53708","0.03041"
"172.0000","3.4386","7.54109","0.03050"
"172.4000","3.4464","7.54061","0.03059"
"172.8000","3.4545","7.54193","0.03067"
"173.2000","3.4626","7.54518","0.03076"
"173.6000","3.4704","7.54428","0.03085"
"174.0000","3.4786","7.54708","0.03093"
"174.4000","3.4864","7.54616","0.03102"
"174.8000","3.4945","7.54883","0.03111"
"175.2000","3.5024","7.54861","0.03119"
"175.6000","3.5105","7.55027","0.03128"
"176.0000","3.5185","7.55336","0.03136"
"176.4000","3.5266","7.55409","0.03145"
"176.8000","3.5346","7.55534","0.03154"
"177.2000","3.5423","7.55397","0.03163"
"177.6000","3.5505","7.55787","0.03171"
"178.0000","3.5583","7.55720","0.03180"
"178.4000","3.5665","7.55912","0.03189"
"178.8000","3.5746","7.56196","0.03197"
"179.2000","3.5825","7.56217","0.03206"
"179.6000","3.5906","7.56361","0.03215"
"180.0000","3.5983","7.56256","0.03223"
"180.4000","3.6066","7.56633","0.03232"
"180.8000","3.6144","7.56594","0.03241"
"181.2000","3.6225","7.56736","0.03249"
"181.6000","3.6305","7.56961","0.03258"
"182.0000","3.6385","7.57083","0.03267"
"182.4000","3.6466","7.57269","0.03276"
"182.8000","3.6544","7.57122","0.03284"
"183.2000","3.6626","7.57508","0.03293"
"183.6000","3.6703","7.57337","0.03302"
"184.0000","3.6784","7.57497","0.03310"
"184.4000","3.6864","7.57815","0.03319"
"184.8000","3.6945","7.57914","0.03328"
"185.2000","3.7026","7.58024","0.03336"
"185.6000","3.7104","7.57950","0.03345"
"186.0000","3.7185","7.58267","0.03353"
"186.4000","3.7263","7.58162","0.03362"
"186.8000","3.7345","7.58436","0.03371"
"187.2000","3.7425","7.58610","0.03379"
"187.6000","3.7506","7.58698","0.03388"
"188.0000","3.7585","7.58792","0.03397"
"188.4000","3.7664","7.58745","0.03405"
"188.8000","3.7746","7.59171","0.03414"
"189.2000","3.7823","7.58956","0.03423"
"189.6000","3.7905","7.59201","0.03431"
"190.0000","3.7984","7.59393","0.03440"
"190.4000","3.8064","7.59429","0.03449"
"190.8000","3.8145","7.59669","0.03457"
"191.2000","3.8225","7.59661","0.03466"
"191.6000","3.8306","7.59932","0.03475"
"192.0000","3.8383","7.59756","0.03483"
"192.4000","3.8465","7.60000","0.03492"
"192.8000","3.8543","7.60098","0.03500"
"193.2000","3.8625","7.60326","0.03509"
"193.6000","3.8706","7.60426","0.03518"
"194.0000","3.8785","7.60435","0.03527"
"194.4000","3.8865","7.60719","0.03535"
"194.8000","3.8942","7.60492","0.03544"
"195.2000","3.9026","7.60881","0.03553"
"195.6000","3.9105","7.60963","0.03561"
"196.0000","3.9184","7.60972","0.03570"
"196.4000","3.9266","7.61220","0.03579"
"196.8000","3.9345","7.61247","0.03587"
"197.2000","3.9425","7.61493","0.03596"
"197.6000","3.9504","7.61326","0.03604"
"198.0000","3.9586","7.61607","0.03613"
"198.4000","3.9664","7.61645","0.03622"
"198.8000","3.9744","7.61737","0.03631"
"199.2000","3.9825","7.61985","0.03639"
"199.6000","3.9906","7.62104","0.03648"
"200.0000","3.9986","7.62259","0.03657"
"200.4000","4.0063","7.62011","0.03665"
"200.8000","4.0146","7.62390","0.03674"
"201.2000","4.0223","7.62395","0.03683"
"201.6000","4.0304","7.62506","0.03691"
"202.0000","4.0386","7.62736","0.03700"
"202.4000","4.0466","7.62825","0.03709"
"202.8000","4.0545","7.62938","0.03717"
"203.2000","4.0623","7.62794","0.03726"
"203.6000","4.0706","7.63222","0.03735"
"204.0000","4.0784","7.63144","0.03743"
"204.4000","4.0864","7.63215","0.03752"
"204.8000","4.0945","7.63422","0.03761"
"205.2000","4.1025","7.63552","0.03769"
"205.6000","4.1105","7.63702","0.03778"
"206.0000","4.1183","7.63556","0.03786"
"206.4000","4.1267","7.63991","0.03795"
"206.8000","4.1343","7.63717","0.03804"
"207.2000","4.1423","7.62933","0.03810"
"207.6000","4.1505","7.63959","0.03819"
"208.0000","4.1587","7.64347","0.03827"
"208.4000","4.1665","7.64361","0.03835"
"208.8000","4.1744","7.64367","0.03844"
"209.2000","4.1827","7.64753","0.03853"
"209.6000","4.1902","7.64518","0.03861"
"210.0000","4.1984","7.64715","0.03870"
"210.4000","4.2066","7.64958","0.03879"
"210.8000","4.2146","7.65057","0.03887"
"211.2000","4.2224","7.65052","0.03896"
"211.6000","4.2303","7.65026","0.03904"
"212.0000","4.2387","7.65544","0.03913"
"212.4000","4.2463","7.65221","0.03922"
"212.8000","4.2544","7.65340","0.03930"
"213.2000","4.2625","7.65616","0.03939"
"213.6000","4.2705","7.65693","0.03948"
"214.0000","4.2784","7.65758","0.03956"
"214.4000","4.2865","7.65791","0.03965"
"214.8000","4.2947","7.66144","0.03974"
"215.2000","4.3022","7.65824","0.03982"
"215.6000","4.3104","7.66035","0.03991"
"216.0000","4.3185","7.66287","0.03999"
"216.4000","4.3266","7.66465","0.04008"
"216.8000","4.3344","7.66374","0.04017"
"217.2000","4.3425","7.66439","0.04025"
"217.6000","4.3508","7.66872","0.04034"
"218.0000","4.3582","7.66414","0.04042"
"218.4000","4.3664","7.66731","0.04051"
"218.8000","4.3746","7.67015","0.04060"
"219.2000","4.3825","7.66984","0.04069"
"219.6000","4.3904","7.67006","0.04077"
"220.0000","4.3985","7.67166","0.04086"
"220.4000","4.4067","7.67556","0.04094"
"220.8000","4.4143","7.67165","0.04103"
"221.2000","4.4225","7.67414","0.04112"
"221.6000","4.4305","7.67593","0.04120"
"222.0000","4.4385","7.67631","0.04129"
"222.4000","4.4463","7.67689","0.04138"
"222.8000","4.4546","7.67908","0.04146"
"223.2000","4.4628","7.68229","0.04155"
"223.6000","4.4702","7.67747","0.04163"
"224.0000","4.4784","7.68036","0.04172"
"224.4000","4.4865","7.68265","0.04181"
"224.8000","4.4945","7.68313","0.04190"
"225.2000","4.5024","7.68305","0.04198"
"225.6000","4.5106","7.68554","0.04207"
"226.0000","4.5187","7.68772","0.04215"
"226.4000","4.5262","7.68399","0.04224"
"226.8000","4.5345","7.68795","0.04233"
"227.2000","4.5425","7.68899","0.04241"
"227.6000","4.5505","7.68930","0.04250"
"228.0000","4.5583","7.68920","0.04258"
"228.4000","4.5665","7.69174","0.04267"
"228.8000","4.5747","7.69482","0.04276"
"229.2000","4.5823","7.69053","0.04284"
"229.6000","4.5906","7.69405","0.04293"
"230.0000","4.5985","7.69478","0.04302"
"230.4000","4.6064","7.69461","0.04310"
"230.8000","4.6143","7.69575","0.04319"
"231.2000","4.6226","7.69892","0.04328"
"231.6000","4.6306","7.69978","0.04336"
"232.0000","4.6383","7.69705","0.04345"
"232.4000","4.6466","7.70076","0.04354"
"232.8000","4.6544","7.70011","0.04362"
"233.2000","4.6625","7.70157","0.04371"
"233.6000","4.6704","7.70159","0.04379"
"234.0000","4.6786","7.68082","0.04386"
"234.4000","4.6866","7.69643","0.04394"
"234.8000","4.6943","7.70027","0.04402"
"235.2000","4.7026","7.70711","0.04411"
"235.6000","4.7105","7.70778","0.04419"
"236.0000","4.7185","7.70797","0.04428"
"236.4000","4.7264","7.70860","0.04436"
"236.8000","4.7345","7.71069","0.04445"
"237.2000","4.7425","7.71221","0.04454"
"237.6000","4.7504","7.71049","0.04462"
"238.0000","4.7587","7.71361","0.04471"
"238.4000","4.7664","7.71150","0.04479"
"238.8000","4.7744","7.71313","0.04488"
"239.2000","4.7823","7.71354","0.04497"
"239.6000","4.7906","7.71641","0.04506"
"240.0000","4.7985","7.71684","0.04514"
"240.4000","4.8064","7.71521","0.04523"
"240.8000","4.8146","7.71901","0.04531"
"241.2000","4.8223","7.71718","0.04540"
"241.6000","4.8305","7.71879","0.04549"
"242.0000","4.8385","7.71991","0.04557"
"242.4000","4.8466","7.72149","0.04566"
"242.8000","4.8544","7.72129","0.04574"
"243.2000","4.8624","7.72124","0.04583"
"243.6000","4.8706","7.72490","0.04592"
"244.0000","4.8784","7.72273","0.04600"
"244.4000","4.8865","7.72426","0.04609"
"244.8000","4.8944","7.72424","0.04618"
"245.2000","4.9025","7.72651","0.04626"
"245.6000","4.9104","7.72751","0.04635"
"246.0000","4.9185","7.72734","0.04644"
"246.4000","4.9267","7.73029","0.04652"
"246.8000","4.9344","7.72780","0.04661"
"247.2000","4.9424","7.72924","0.04669"
"247.6000","4.9503","7.72989","0.04678"
"248.0000","4.9586","7.73238","0.04687"
"248.4000","4.9664","7.73183","0.04695"
"248.8000","4.9745","7.73278","0.04704"
"249.2000","4.9826","7.73501","0.04713"
"249.6000","4.9903","7.73289","0.04721"
"250.0000","4.9985","7.73583","0.04730"
"250.4000","5.0064","7.73531","0.04739"
"250.8000","5.0146","7.73707","0.04747"
"251.2000","5.0224","7.73689","0.04756"
"251.6000","5.0305","7.73751","0.04765"
"252.0000","5.0387","7.74137","0.04773"
"252.4000","5.0464","7.73840","0.04782"
"252.8000","5.0545","7.74016","0.04790"
"253.2000","5.0624","7.73999","0.04799"
"253.6000","5.0704","7.74123","0.04808"
"254.0000","5.0784","7.74194","0.04816"
"254.4000","5.0866","7.74375","0.04825"
"254.8000","5.0946","7.74518","0.04834"
"255.2000","5.1025","7.74379","0.04842"
"255.6000","5.1105","7.74539","0.04851"
"256.0000","5.1183","7.74403","0.04859"
"256.4000","5.1266","7.74775","0.04868"
"256.8000","5.1344","7.74695","0.04877"
"257.2000","5.1425","7.74807","0.04885"
"257.6000","5.1506","7.75065","0.04894"
"258.0000","5.1583","7.74835","0.04902"
"258.4000","5.1666","7.75133","0.04911"
"258.8000","5.1744","7.74989","0.04920"
"259.2000","5.1825","7.75148","0.04928"
"259.6000","5.1904","7.75199","0.04937"
"260.0000","5.1984","7.75227","0.04946"
"260.4000","5.2065","7.75490","0.04954"
"260.8000","5.2145","7.75450","0.04963"
"261.2000","5.2226","7.75544","0.04972"
"261.6000","5.2304","7.75385","0.04980"
"262.0000","5.2385","7.75666","0.04989"
"262.4000","5.2463","7.75575","0.04997"
"262.8000","5.2546","7.75824","0.05006"
"263.2000","5.2626","7.75966","0.05015"
"263.6000","5.2705","7.75825","0.05023"
"264.0000","5.2786","7.76052","0.05032"
"264.4000","5.2863","7.75834","0.05040"
"264.8000","5.2945","7.76134","0.05049"
"265.2000","5.3024","7.76147","0.05058"
"265.6000","5.3105","7.76155","0.05066"
"266.0000","5.3185","7.76344","0.05075"
"266.4000","5.3265","7.76371","0.05084"
"266.8000","5.3345","7.76501","0.05092"
"267.2000","5.3424","7.76369","0.05101"
"267.6000","5.3506","7.76623","0.05109"
"268.0000","5.3583","7.76449","0.05118"
"268.4000","5.3665","7.76615","0.05127"
"268.8000","5.3745","7.76803","0.05135"
"269.2000","5.3825","7.76799","0.05144"
"269.6000","5.3906","7.76963","0.05152"
"270.0000","5.3983","7.76705","0.05161"
"270.4000","5.4065","7.77001","0.05169"
"270.8000","5.4143","7.76926","0.05178"
"271.2000","5.4225","7.77067","0.05187"
"271.6000","5.4306","7.77229","0.05195"
"272.0000","5.4385","7.77248","0.05204"
"272.4000","5.4465","7.77298","0.05212"
"272.8000","5.4543","7.77168","0.05221"
"273.2000","5.4626","7.77524","0.05230"
"273.6000","5.4704","7.77304","0.05238"
"274.0000","5.4785","7.77433","0.05247"
"274.4000","5.4864","7.77585","0.05255"
"274.8000","5.4944","7.77629","0.05264"
"275.2000","5.5026","7.77788","0.05272"
"275.6000","5.5104","7.77632","0.05281"
"276.0000","5.5186","7.77899","0.05289"
"276.4000","5.5264","7.77722","0.05298"
"276.8000","5.5345","7.77810","0.05306"
"277.2000","5.5424","7.77967","0.05315"
"277.6000","5.5506","7.78101","0.05324"
"278.0000","5.5586","7.78112","0.05332"
"278.4000","5.5664","7.77983","0.05340"
"278.8000","5.5745","7.78277","0.05349"
"279.2000","5.5822","7.78029","0.05357"
"279.6000","5.5906","7.78293","0.05366"
"280.0000","5.5985","7.78385","0.05375"
"280.4000","5.6065","7.78339","0.05383"
"280.8000","5.6146","7.78499","0.05392"
"281.2000","5.6224","7.78401","0.05400"
"281.6000","5.6306","7.78685","0.05409"
"282.0000","5.6384","7.78492","0.05417"
"282.4000","5.6465","7.78643","0.05426"
"282.8000","5.6544","7.78682","0.05434"
"283.2000","5.6624","7.78740","0.05443"
"283.6000","5.6705","7.78883","0.05451"
"284.0000","5.6785","7.78866","0.05460"
"284.4000","5.6866","7.79069","0.05468"
"284.8000","5.6943","7.78702","0.05477"
"285.2000","5.7025","7.78986","0.05485"
"285.6000","5.7103","7.79042","0.05493"
"286.0000","5.7184","7.79094","0.05502"
"286.4000","5.7266","7.79246","0.05511"
"286.8000","5.7345","7.79209","0.05519"
"287.2000","5.7425","7.79345","0.05528"
"287.6000","5.7503","7.79125","0.05536"
"288.0000","5.7586","7.79421","0.05544"
"288.4000","5.7664","7.79357","0.05553"
"288.8000","5.7745","7.79383","0.05561"
"289.2000","5.7825","7.79506","0.05570"
"289.6000","5.7905","7.79519","0.05578"
"290.0000","5.7985","7.79724","0.05587"
"290.4000","5.8063","7.79438","0.05595"
"290.8000","5.8146","7.79760","0.05603"
"291.2000","5.8223","7.79626","0.05612"
"291.6000","5.8303","7.79641","0.05620"
"292.0000","5.8385","7.79928","0.05629"
"292.4000","5.8466","7.79966","0.05637"
"292.8000","5.8545","7.79931","0.05645"
"293.2000","5.8624","7.78601","0.05651"
"293.6000","5.8706","7.79672","0.05659"
"294.0000","5.8783","7.79840","0.05667"
"294.4000","5.8864","7.80098","0.05676"
"294.8000","5.8945","7.80295","0.05684"
"295.2000","5.9026","7.80352","0.05692"
"295.6000","5.9105","7.80345","0.05701"
"296.0000","5.9183","7.80147","0.05709"
"296.4000","5.9267","7.80553","0.05717"
"296.8000","5.9343","7.80302","0.05725"
"297.2000","5.9424","7.80330","0.05734"
"297.6000","5.9505","7.80551","0.05742"
"298.0000","5.9586","7.80617","0.05750"
"298.4000","5.9664","7.80555","0.05759"
"298.8000","5.9744","7.80459","0.05767"
"299.2000","5.9827","7.80775","0.05775"
"299.6000","5.9903","7.80456","0.05783"
"300.0000","5.9984","7.80564","0.05792"
"300.4000","6.0065","7.80761","0.05800"
"300.8000","6.0146","7.80890","0.05808"
"301.2000","6.0225","7.80818","0.05816"
"301.6000","6.0304","7.80700","0.05824"
"302.0000","6.0387","7.81041","0.05833"
"302.4000","6.0462","7.80656","0.05840"
"302.8000","6.0544","7.80805","0.05849"
"303.2000","6.0626","7.81067","0.05857"
"303.6000","6.0706","7.81055","0.05865"
"304.0000","6.0784","7.80953","0.05873"
"304.4000","6.0864","7.80981","0.05881"
"304.8000","6.0947","7.81349","0.05890"
"305.2000","6.1023","7.80906","0.05897"
"305.6000","6.1104","7.81063","0.05906"
"306.0000","6.1185","7.81230","0.05914"
"306.4000","6.1265","7.81279","0.05922"
"306.8000","6.1344","7.81219","0.05930"
"307.2000","6.1425","7.81246","0.05938"
"307.6000","6.1508","7.81641","0.05946"
"308.0000","6.1582","7.81090","0.05953"
"308.4000","6.1664","7.81254","0.05962"
"308.8000","6.1745","7.81494","0.05970"
"309.2000","6.1826","7.81509","0.05978"
"309.6000","6.1904","7.81398","0.05985"
"310.0000","6.1985","7.81507","0.05993"
"310.4000","6.2067","7.81730","0.06001"
"310.8000","6.2142","7.81283","0.06009"
"311.2000","6.2225","7.81569","0.06017"
"311.6000","6.2306","7.81681","0.06025"
"312.0000","6.2385","7.81661","0.06033"
"312.4000","6.2463","7.81566","0.06040"
"312.8000","6.2545","7.81713","0.06049"
"313.2000","6.2627","7.82038","0.06056"
"313.6000","6.2702","7.81499","0.06064"
"314.0000","6.2785","7.81741","0.06072"
"314.4000","6.2865","7.81821","0.06079"
"314.8000","6.2944","7.81713","0.06087"
"315.2000","6.3023","7.81782","0.06094"
"315.6000","6.3106","7.81984","0.06103"
"316.0000","6.3187","7.82111","0.06110"
"316.4000","6.3262","7.81636","0.06117"
"316.8000","6.3345","7.81907","0.06125"
"317.2000","6.3425","7.81949","0.06132"
"317.6000","6.3505","7.81988","0.06140"
"318.0000","6.3584","7.81868","0.06147"
"318.4000","6.3666","7.82051","0.06155"
"318.8000","6.3747","7.82226","0.06162"
"319.2000","6.3822","7.81736","0.06170"
"319.6000","6.3905","7.82082","0.06177"
"320.0000","6.3985","7.82121","0.06185"
"320.4000","6.4065","7.82011","0.06192"
"320.8000","6.4144","7.81967","0.06199"
"321.2000","6.4226","7.82190","0.06206"
"321.6000","6.4306","7.82309","0.06214"
"322.0000","6.4384","7.81952","0.06221"
"322.4000","6.4466","7.82192","0.06228"
"322.8000","6.4544","7.82074","0.06235"
"323.2000","6.4624","7.82084","0.06242"
"323.6000","6.4703","7.82059","0.06249"
"324.0000","6.4786","7.82292","0.06256"
"324.4000","6.4866","7.82313","0.06263"
"324.8000","6.4943","7.81963","0.06270"
"325.2000","6.5026","7.82295","0.06277"
"325.6000","6.5103","7.82142","0.06284"
"326.0000","6.5184","7.82165","0.06290"
"326.4000","6.5265","7.82173","0.06297"
"326.8000","6.5347","7.82304","0.06304"
"327.2000","6.5425","7.82218","0.06311"
"327.6000","6.5503","7.82011","0.06317"
"328.0000","6.5586","7.82335","0.06324"
"328.4000","6.5664","7.82109","0.06330"
"328.8000","6.5745","7.82129","0.06337"
"329.2000","6.5824","7.82070","0.06343"
"329.6000","6.5905","7.82238","0.06349"
"330.0000","6.5985","7.82282","0.06356"
"330.4000","6.6064","7.82014","0.06362"
"330.8000","6.6147","7.82268","0.06368"
"331.2000","6.6224","7.81974","0.06374"
"331.6000","6.6304","7.81953","0.06380"
"332.0000","6.6383","7.81993","0.06386"
"332.4000","6.6466","7.82161","0.06392"
"332.8000","6.6545","7.82044","0.06398"
"333.2000","6.6624","7.81885","0.06404"
"333.6000","6.6706","7.82089","0.06409"
"334.0000","6.6783","7.81778","0.06415"
"334.4000","6.6865","7.81880","0.06420"
"334.8000","6.6944","7.81771","0.06426"
"335.2000","6.7026","7.81857","0.06432"
"335.6000","6.7104","7.81772","0.06437"
"336.0000","6.7184","7.81604","0.06442"
"336.4000","6.7267","7.81853","0.06447"
"336.8000","6.7344","7.81468","0.06452"
"337.2000","6.7425","7.81465","0.06457"
"337.6000","6.7504","7.81376","0.06462"
"338.0000","6.7585","7.81396","0.06466"
"338.4000","6.7664","7.81314","0.06471"
"338.8000","6.7745","7.81237","0.06476"
"339.2000","6.7827","7.81298","0.06480"
"339.6000","6.7904","7.80909","0.06484"
"340.0000","6.7985","7.80923","0.06489"
"340.4000","6.8063","7.80717","0.06493"
"340.8000","6.8145","7.80814","0.06497"
"341.2000","6.8224","7.80612","0.06501"
"341.6000","6.8305","7.80431","0.06505"
"342.0000","6.8387","7.80566","0.06508"
"342.4000","6.8463","7.80093","0.06512"
"342.8000","6.8545","7.80103","0.06515"
"343.2000","6.8625","7.79856","0.06519"
"343.6000","6.8705","7.79782","0.06522"
"344.0000","6.8784","7.79475","0.06525"
"344.4000","6.8865","7.79353","0.06528"
"344.8000","6.8946","7.79382","0.06531"
"345.2000","6.9024","7.78885","0.06534"
"345.6000","6.9106","7.78769","0.06536"
"346.0000","6.9183","7.78356","0.06538"
"346.4000","6.9265","7.78317","0.06541"
"346.8000","6.9344","7.78003","0.06543"
"347.2000","6.9425","7.77698","0.06546"
"347.6000","6.9507","7.77621","0.06547"
"348.0000","6.9584","7.77036","0.06549"
"348.4000","6.9665","7.76831","0.06551"
"348.8000","6.9743","7.76339","0.06553"
"349.2000","6.9825","7.76201","0.06555"
"349.6000","6.9904","7.75697","0.06556"
"350.0000","6.9985","7.75348","0.06557"
"350.4000","7.0066","7.75135","0.06559"
"350.8000","7.0144","7.74501","0.06560"
"351.2000","7.0226","7.74269","0.06561"
"351.6000","7.0304","7.73485","0.06562"
"352.0000","7.0386","7.73257","0.06563"
"352.4000","7.0463","7.72575","0.06564"
"352.8000","7.0544","7.72075","0.06565"
"353.2000","7.0626","7.71915","0.06566"
"353.6000","7.0705","7.71065","0.06566"
"354.0000","7.0786","7.70562","0.06567"
"354.4000","7.0863","7.69750","0.06567"
"354.8000","7.0945","7.69358","0.06567"
"355.2000","7.1023","7.68604","0.06568"
"355.6000","7.1105","7.68017","0.06568"
"356.0000","7.1186","7.67460","0.06568"
"356.4000","7.1265","7.66663","0.06569"
"356.8000","7.1346","7.65991","0.06569"
"357.2000","7.1423","7.64997","0.06569"
"357.6000","7.1506","7.64606","0.06569"
"358.0000","7.1584","7.63550","0.06569"
"358.4000","7.1665","7.62716","0.06569"
"358.8000","7.1745","7.62203","0.06569"
"359.2000","7.1824","7.61230","0.06569"
"359.6000","7.1906","7.60426","0.06569"
"360.0000","7.1984","7.59310","0.06568"
"360.4000","7.2066","7.58633","0.06568"
"360.8000","7.2144","7.57495","0.06568"
"361.2000","7.2225","7.56606","0.06568"
"361.6000","7.2305","7.55898","0.06568"
"362.0000","7.2386","7.54853","0.06567"
"362.4000","7.2466","7.53836","0.06567"
"362.8000","7.2544","7.52540","0.06566"
"363.2000","7.2626","7.51862","0.06566"
"363.6000","7.2703","7.50560","0.06565"
"364.0000","7.2786","7.49497","0.06565"
"364.4000","7.2866","7.48626","0.06565"
"364.8000","7.2945","7.47376","0.06564"
"365.2000","7.3026","7.46410","0.06564"
"365.6000","7.3103","7.44994","0.06563"
"366.0000","7.3186","7.44099","0.06562"
"366.4000","7.3264","7.42686","0.06562"
"366.8000","7.3345","7.41490","0.06561"
"367.2000","7.3425","7.40436","0.06561"
"367.6000","7.3505","7.39181","0.06560"
"368.0000","7.3585","7.37942","0.06559"
"368.4000","7.3665","7.36415","0.06559"
"368.8000","7.3746","7.35478","0.06558"
"369.2000","7.3823","7.33730","0.06557"
"369.6000","7.3905","7.32521","0.06557"
"370.0000","7.3984","7.31395","0.06556"
"370.4000","7.4065","7.29862","0.06555"
"370.8000","7.4146","7.28591","0.06555"
"371.2000","7.4225","7.26974","0.06554"
"371.6000","7.4306","7.25799","0.06553"
"372.0000","7.4383","7.24047","0.06552"
"372.4000","7.4465","7.22602","0.06551"
"372.8000","7.4545","7.21288","0.06550"
"373.2000","7.4625","7.19657","0.06550"
"373.6000","7.4705","7.18114","0.06548"
"374.0000","7.4785","7.16557","0.06548"
"374.4000","7.4865","7.15188","0.06547"
"374.8000","7.4943","7.13103","0.06546"
"375.2000","7.5026","7.11754","0.06545"
"375.6000","7.5104","7.10130","0.06544"
"376.0000","7.5184","7.08244","0.06543"
"376.4000","7.5265","7.06850","0.06542"
"376.8000","7.5345","7.04952","0.06541"
"377.2000","7.5426","7.03343","0.06540"
"377.6000","7.5503","7.01217","0.06539"
"378.0000","7.5585","6.99536","0.06538"
"378.4000","7.5664","6.97922","0.06537"
"378.8000","7.5744","6.95855","0.06536"
"379.2000","7.5825","6.94011","0.06535"
"379.6000","7.5906","6.92183","0.06534"
"380.0000","7.5985","6.90296","0.06533"
"380.4000","7.6063","6.87939","0.06531"
"380.8000","7.6146","6.86226","0.06530"
"381.2000","7.6224","6.84151","0.06529"
"381.6000","7.6304","6.81865","0.06528"
"382.0000","7.6385","6.80005","0.06527"
"382.4000","7.6465","6.77786","0.06525"
"382.8000","7.6545","6.75715","0.06524"
"383.2000","7.6623","6.73086","0.06522"
"383.6000","7.6707","6.71026","0.06521"
"384.0000","7.6784","6.68745","0.06520"
"384.4000","7.6863","6.66172","0.06518"
"384.8000","7.6945","6.64044","0.06517"
"385.2000","7.7027","6.61589","0.06516"
"385.6000","7.7105","6.59093","0.06514"
"386.0000","7.7184","6.56125","0.06512"
"386.4000","7.7266","6.53698","0.06511"
"386.8000","7.7343","6.50915","0.06509"
"387.2000","7.7424","6.47811","0.06508"
"387.6000","7.7506","6.44939","0.06506"
"388.0000","7.7586","6.41843","0.06504"
"388.4000","7.7664","6.38781","0.06502"
"388.8000","7.7744","6.35184","0.06500"
"389.2000","7.7827","6.31688","0.06497"
"389.6000","7.7904","6.27567","0.06495"
"390.0000","7.7984","6.22948","0.06492"
"390.4000","7.8065","6.17585","0.06489"
"390.8000","7.8146","6.09629","0.06483"
"391.2000","7.8225","5.91638","0.06472"
"391.2580","7.8238","5.53231","0.06448"
"391.2650","7.8240","5.03875","0.06384"
"391.2690","7.8242","4.71713","0.06343"
"391.2700","7.8243","4.63558","0.06332"