File: Coupon Test Data/Tensile Test_Neebajan_Alan_14.csv
Time,Displacement,Force,Strain 1
(s),(mm),(kN),(mm/mm)
"0.0000","0.0000","0.18435","-0.00039"
"0.4000","0.0063","0.25925","-0.00035"
"0.8000","0.0143","0.36079","-0.00031"
"1.2000","0.0222","0.45826","-0.00026"
"1.6000","0.0305","0.55809","-0.00021"
"2.0000","0.0385","0.64895","-0.00017"
"2.4000","0.0465","0.74116","-0.00012"
"2.8000","0.0545","0.82934","-0.00008"
"3.2000","0.0624","0.90994","-0.00004"
"3.6000","0.0705","0.99916","0.00000"
"4.0000","0.0784","1.08398","0.00004"
"4.4000","0.0865","1.16423","0.00008"
"4.8000","0.0944","1.24711","0.00012"
"5.2000","0.1024","1.32281","0.00015"
"5.6000","0.1105","1.40482","0.00019"
"6.0000","0.1185","1.48350","0.00023"
"6.4000","0.1266","1.55663","0.00027"
"6.8000","0.1344","1.63052","0.00030"
"7.2000","0.1425","1.70138","0.00033"
"7.6000","0.1504","1.77471","0.00037"
"8.0000","0.1584","1.84192","0.00040"
"8.4000","0.1666","1.91507","0.00044"
"8.8000","0.1746","1.98143","0.00047"
"9.2000","0.1825","2.04917","0.00050"
"9.6000","0.1903","2.11418","0.00053"
"10.0000","0.1986","2.18105","0.00057"
"10.4000","0.2065","2.24605","0.00060"
"10.8000","0.2144","2.30702","0.00063"
"11.2000","0.2225","2.37214","0.00066"
"11.6000","0.2305","2.43191","0.00069"
"12.0000","0.2385","2.49495","0.00072"
"12.4000","0.2464","2.55114","0.00074"
"12.8000","0.2546","2.61462","0.00077"
"13.2000","0.2624","2.67016","0.00080"
"13.6000","0.2703","2.72887","0.00083"
"14.0000","0.2785","2.78698","0.00085"
"14.4000","0.2866","2.84524","0.00088"
"14.8000","0.2945","2.89948","0.00091"
"15.2000","0.3024","2.95117","0.00094"
"15.6000","0.3106","3.01013","0.00097"
"16.0000","0.3183","3.05979","0.00099"
"16.4000","0.3264","3.11592","0.00101"
"16.8000","0.3346","3.16856","0.00104"
"17.2000","0.3426","3.22185","0.00107"
"17.6000","0.3504","3.26956","0.00109"
"18.0000","0.3584","3.31880","0.00111"
"18.4000","0.3667","3.37221","0.00114"
"18.8000","0.3744","3.41864","0.00116"
"19.2000","0.3824","3.46945","0.00119"
"19.6000","0.3905","3.51998","0.00121"
"20.0000","0.3985","3.56944","0.00124"
"20.4000","0.4064","3.61817","0.00126"
"20.8000","0.4145","3.66627","0.00128"
"21.2000","0.4227","3.71692","0.00131"
"21.6000","0.4303","3.76358","0.00133"
"22.0000","0.4384","3.81075","0.00135"
"22.4000","0.4465","3.85828","0.00138"
"22.8000","0.4547","3.90952","0.00140"
"23.2000","0.4625","3.95502","0.00142"
"23.6000","0.4705","4.00002","0.00144"
"24.0000","0.4787","4.05062","0.00147"
"24.4000","0.4862","4.09239","0.00149"
"24.8000","0.4944","4.13979","0.00151"
"25.2000","0.5026","4.18908","0.00154"
"25.6000","0.5106","4.22982","0.00156"
"26.0000","0.5184","4.27623","0.00158"
"26.4000","0.5264","4.32319","0.00160"
"26.8000","0.5347","4.37148","0.00163"
"27.2000","0.5424","4.41491","0.00165"
"27.6000","0.5504","4.46111","0.00167"
"28.0000","0.5585","4.50878","0.00170"
"28.4000","0.5665","4.55580","0.00172"
"28.8000","0.5744","4.60159","0.00174"
"29.2000","0.5826","4.64880","0.00177"
"29.6000","0.5907","4.69711","0.00179"
"30.0000","0.5983","4.74048","0.00181"
"30.4000","0.6064","4.78763","0.00184"
"30.8000","0.6145","4.83589","0.00187"
"31.2000","0.6225","4.88361","0.00189"
"31.6000","0.6304","4.92940","0.00191"
"32.0000","0.6386","4.97750","0.00194"
"32.4000","0.6467","5.02581","0.00196"
"32.8000","0.6542","5.06938","0.00199"
"33.2000","0.6625","5.11757","0.00201"
"33.6000","0.6705","5.16605","0.00204"
"34.0000","0.6785","5.21371","0.00206"
"34.4000","0.6864","5.25967","0.00209"
"34.8000","0.6945","5.30784","0.00211"
"35.2000","0.7027","5.35749","0.00214"
"35.6000","0.7103","5.40120","0.00216"
"36.0000","0.7185","5.44944","0.00219"
"36.4000","0.7265","5.49788","0.00221"
"36.8000","0.7344","5.54469","0.00224"
"37.2000","0.7424","5.59222","0.00227"
"37.6000","0.7506","5.64142","0.00229"
"38.0000","0.7586","5.68953","0.00232"
"38.4000","0.7663","5.73424","0.00234"
"38.8000","0.7745","5.78233","0.00237"
"39.2000","0.7825","5.82989","0.00240"
"39.6000","0.7905","5.87802","0.00243"
"40.0000","0.7984","5.92428","0.00245"
"40.4000","0.8067","5.97330","0.00248"
"40.8000","0.8146","6.02132","0.00251"
"41.2000","0.8222","6.06460","0.00253"
"41.6000","0.8306","6.11303","0.00256"
"42.0000","0.8385","6.16160","0.00259"
"42.4000","0.8465","6.20595","0.00262"
"42.8000","0.8544","6.25174","0.00265"
"43.2000","0.8625","6.30037","0.00268"
"43.6000","0.8706","6.34721","0.00271"
"44.0000","0.8784","6.38992","0.00274"
"44.4000","0.8866","6.43648","0.00277"
"44.8000","0.8945","6.48244","0.00280"
"45.2000","0.9024","6.52486","0.00283"
"45.6000","0.9103","6.56771","0.00286"
"46.0000","0.9187","6.61501","0.00289"
"46.4000","0.9265","6.65684","0.00293"
"46.8000","0.9344","6.69543","0.00296"
"47.2000","0.9426","6.74238","0.00300"
"47.6000","0.9503","6.77709","0.00303"
"48.0000","0.9585","6.81981","0.00307"
"48.4000","0.9665","6.85939","0.00311"
"48.8000","0.9746","6.89205","0.00315"
"49.2000","0.9826","6.93113","0.00319"
"49.6000","0.9903","6.96436","0.00324"
"50.0000","0.9986","6.99951","0.00328"
"50.4000","1.0065","7.02177","0.00332"
"50.8000","1.0144","7.05294","0.00338"
"51.2000","1.0224","7.08126","0.00343"
"51.6000","1.0306","7.10832","0.00349"
"52.0000","1.0385","7.13147","0.00355"
"52.4000","1.0465","7.14996","0.00362"
"52.8000","1.0547","7.17222","0.00368"
"53.2000","1.0624","7.17579","0.00373"
"53.6000","1.0705","7.19992","0.00380"
"54.0000","1.0784","7.21205","0.00387"
"54.4000","1.0866","7.22684","0.00395"
"54.8000","1.0946","7.23954","0.00403"
"55.2000","1.1025","7.24829","0.00411"
"55.6000","1.1107","7.26030","0.00419"
"56.0000","1.1183","7.26617","0.00427"
"56.4000","1.1265","7.27460","0.00436"
"56.8000","1.1345","7.27608","0.00443"
"57.2000","1.1426","7.28758","0.00451"
"57.6000","1.1505","7.29445","0.00459"
"58.0000","1.1585","7.29887","0.00468"
"58.4000","1.1667","7.30692","0.00476"
"58.8000","1.1744","7.30854","0.00485"
"59.2000","1.1825","7.31348","0.00493"
"59.6000","1.1904","7.31759","0.00501"
"60.0000","1.1985","7.32268","0.00510"
"60.4000","1.2064","7.32645","0.00518"
"60.8000","1.2146","7.32987","0.00527"
"61.2000","1.2227","7.33496","0.00536"
"61.6000","1.2304","7.33537","0.00544"
"62.0000","1.2385","7.33978","0.00553"
"62.4000","1.2463","7.34176","0.00562"
"62.8000","1.2546","7.34667","0.00570"
"63.2000","1.2625","7.34850","0.00579"
"63.6000","1.2705","7.35065","0.00588"
"64.0000","1.2787","7.35590","0.00596"
"64.4000","1.2863","7.35526","0.00605"
"64.8000","1.2945","7.35917","0.00614"
"65.2000","1.3025","7.36073","0.00623"
"65.6000","1.3105","7.36350","0.00632"
"66.0000","1.3184","7.36542","0.00640"
"66.4000","1.3265","7.36796","0.00649"
"66.8000","1.3346","7.37227","0.00658"
"67.2000","1.3425","7.37178","0.00667"
"67.6000","1.3506","7.37485","0.00676"
"68.0000","1.3584","7.37528","0.00685"
"68.4000","1.3665","7.37912","0.00694"
"68.8000","1.3743","7.38010","0.00703"
"69.2000","1.3826","7.38259","0.00712"
"69.6000","1.3907","7.38636","0.00721"
"70.0000","1.3985","7.38565","0.00730"
"70.4000","1.4066","7.38198","0.00739"
"70.8000","1.4143","7.38442","0.00746"
"71.2000","1.4226","7.39293","0.00755"
"71.6000","1.4304","7.39394","0.00764"
"72.0000","1.4386","7.39539","0.00774"
"72.4000","1.4466","7.39886","0.00783"
"72.8000","1.4544","7.39870","0.00792"
"73.2000","1.4626","7.40184","0.00801"
"73.6000","1.4704","7.40104","0.00810"
"74.0000","1.4786","7.40473","0.00820"
"74.4000","1.4864","7.40462","0.00829"
"74.8000","1.4945","7.40638","0.00838"
"75.2000","1.5025","7.41108","0.00847"
"75.6000","1.5105","7.41123","0.00857"
"76.0000","1.5186","7.41284","0.00866"
"76.4000","1.5264","7.41244","0.00875"
"76.8000","1.5345","7.41593","0.00885"
"77.2000","1.5423","7.41669","0.00894"
"77.6000","1.5505","7.41900","0.00903"
"78.0000","1.5586","7.42180","0.00913"
"78.4000","1.5666","7.42270","0.00922"
"78.8000","1.5746","7.42470","0.00931"
"79.2000","1.5823","7.42369","0.00941"
"79.6000","1.5906","7.42861","0.00950"
"80.0000","1.5984","7.42804","0.00960"
"80.4000","1.6065","7.42940","0.00969"
"80.8000","1.6145","7.43310","0.00978"
"81.2000","1.6225","7.43388","0.00988"
"81.6000","1.6306","7.43629","0.00997"
"82.0000","1.6385","7.43567","0.01007"
"82.4000","1.6466","7.43915","0.01016"
"82.8000","1.6544","7.43892","0.01026"
"83.2000","1.6625","7.44090","0.01035"
"83.6000","1.6705","7.44411","0.01044"
"84.0000","1.6786","7.44533","0.01054"
"84.4000","1.6866","7.42976","0.01060"
"84.8000","1.6944","7.44365","0.01068"
"85.2000","1.7026","7.45167","0.01077"
"85.6000","1.7103","7.45079","0.01087"
"86.0000","1.7185","7.45307","0.01096"
"86.4000","1.7266","7.45575","0.01106"
"86.8000","1.7345","7.45615","0.01115"
"87.2000","1.7426","7.45754","0.01125"
"87.6000","1.7504","7.45748","0.01134"
"88.0000","1.7586","7.46181","0.01143"
"88.4000","1.7664","7.46055","0.01153"
"88.8000","1.7745","7.46254","0.01162"
"89.2000","1.7825","7.46491","0.01172"
"89.6000","1.7905","7.46665","0.01181"
"90.0000","1.7986","7.46874","0.01191"
"90.4000","1.8065","7.46823","0.01200"
"90.8000","1.8146","7.47242","0.01210"
"91.2000","1.8223","7.47028","0.01219"
"91.6000","1.8305","7.47332","0.01228"
"92.0000","1.8384","7.47587","0.01238"
"92.4000","1.8465","7.47710","0.01247"
"92.8000","1.8546","7.47933","0.01257"
"93.2000","1.8625","7.47926","0.01266"
"93.6000","1.8706","7.48250","0.01275"
"94.0000","1.8783","7.48142","0.01284"
"94.4000","1.8866","7.48518","0.01294"
"94.8000","1.8945","7.48656","0.01304"
"95.2000","1.9025","7.48767","0.01313"
"95.6000","1.9105","7.48907","0.01322"
"96.0000","1.9185","7.49029","0.01331"
"96.4000","1.9266","7.49412","0.01341"
"96.8000","1.9343","7.49190","0.01350"
"97.2000","1.9426","7.49542","0.01360"
"97.6000","1.9504","7.49686","0.01369"
"98.0000","1.9584","7.49748","0.01378"
"98.4000","1.9666","7.50122","0.01387"
"98.8000","1.9746","7.50208","0.01397"
"99.2000","1.9826","7.50418","0.01406"
"99.6000","1.9904","7.50262","0.01415"
"100.0000","1.9986","7.50634","0.01425"
"100.4000","2.0063","7.50728","0.01434"
"100.8000","2.0145","7.50931","0.01443"
"101.2000","2.0226","7.51142","0.01453"
"101.6000","2.0306","7.51268","0.01462"
"102.0000","2.0385","7.51477","0.01471"
"102.4000","2.0463","7.51323","0.01480"
"102.8000","2.0547","7.51848","0.01490"
"103.2000","2.0624","7.51827","0.01499"
"103.6000","2.0704","7.51879","0.01508"
"104.0000","2.0786","7.52232","0.01517"
"104.4000","2.0866","7.52385","0.01526"
"104.8000","2.0945","7.52531","0.01536"
"105.2000","2.1024","7.52480","0.01545"
"105.6000","2.1107","7.52864","0.01554"
"106.0000","2.1184","7.52787","0.01563"
"106.4000","2.1264","7.52073","0.01570"
"106.8000","2.1345","7.53155","0.01579"
"107.2000","2.1427","7.53563","0.01588"
"107.6000","2.1505","7.53643","0.01597"
"108.0000","2.1584","7.53537","0.01606"
"108.4000","2.1667","7.54003","0.01615"
"108.8000","2.1743","7.53852","0.01624"
"109.2000","2.1824","7.54035","0.01634"
"109.6000","2.1906","7.54396","0.01643"
"110.0000","2.1986","7.54526","0.01652"
"110.4000","2.2064","7.54560","0.01661"
"110.8000","2.2144","7.54582","0.01670"
"111.2000","2.2227","7.55092","0.01679"
"111.6000","2.2304","7.54909","0.01688"
"112.0000","2.2384","7.55039","0.01697"
"112.4000","2.2465","7.55329","0.01706"
"112.8000","2.2546","7.55533","0.01716"
"113.2000","2.2624","7.55622","0.01725"
"113.6000","2.2705","7.55673","0.01734"
"114.0000","2.2788","7.56165","0.01743"
"114.4000","2.2863","7.55814","0.01752"
"114.8000","2.2944","7.56065","0.01761"
"115.2000","2.3025","7.56466","0.01770"
"115.6000","2.3106","7.56601","0.01779"
"116.0000","2.3185","7.56616","0.01788"
"116.4000","2.3265","7.56763","0.01797"
"116.8000","2.3347","7.57162","0.01806"
"117.2000","2.3422","7.56896","0.01815"
"117.6000","2.3505","7.57221","0.01825"
"118.0000","2.3586","7.57502","0.01834"
"118.4000","2.3666","7.57589","0.01843"
"118.8000","2.3744","7.57625","0.01852"
"119.2000","2.3825","7.57814","0.01861"
"119.6000","2.3908","7.58352","0.01870"
"120.0000","2.3983","7.57934","0.01878"
"120.4000","2.4065","7.58204","0.01888"
"120.8000","2.4146","7.58539","0.01897"
"121.2000","2.4225","7.58569","0.01906"
"121.6000","2.4304","7.58693","0.01915"
"122.0000","2.4386","7.58958","0.01924"
"122.4000","2.4468","7.59309","0.01933"
"122.8000","2.4543","7.58929","0.01942"
"123.2000","2.4625","7.59283","0.01951"
"123.6000","2.4705","7.59531","0.01960"
"124.0000","2.4786","7.59696","0.01969"
"124.4000","2.4864","7.59727","0.01978"
"124.8000","2.4946","7.59955","0.01987"
"125.2000","2.5027","7.60323","0.01996"
"125.6000","2.5102","7.59927","0.02005"
"126.0000","2.5185","7.60362","0.02014"
"126.4000","2.5266","7.60600","0.02023"
"126.8000","2.5345","7.60605","0.02032"
"127.2000","2.5424","7.60690","0.02041"
"127.6000","2.5506","7.61038","0.02050"
"128.0000","2.5587","7.61365","0.02059"
"128.4000","2.5664","7.61054","0.02067"
"128.8000","2.5746","7.61424","0.02077"
"129.2000","2.5825","7.61495","0.02085"
"129.6000","2.5905","7.61615","0.02095"
"130.0000","2.5983","7.61740","0.02103"
"130.4000","2.6067","7.62102","0.02112"
"130.8000","2.6147","7.62360","0.02122"
"131.2000","2.6223","7.59595","0.02128"
"131.6000","2.6306","7.61691","0.02136"
"132.0000","2.6384","7.62428","0.02145"
"132.4000","2.6465","7.62708","0.02153"
"132.8000","2.6545","7.62872","0.02162"
"133.2000","2.6627","7.63151","0.02171"
"133.6000","2.6706","7.63298","0.02180"
"134.0000","2.6783","7.63137","0.02189"
"134.4000","2.6866","7.63581","0.02198"
"134.8000","2.6945","7.63548","0.02207"
"135.2000","2.7025","7.63639","0.02215"
"135.6000","2.7104","7.63711","0.02224"
"136.0000","2.7186","7.64032","0.02233"
"136.4000","2.7266","7.64314","0.02242"
"136.8000","2.7344","7.64095","0.02251"
"137.2000","2.7427","7.64525","0.02260"
"137.6000","2.7504","7.64455","0.02268"
"138.0000","2.7584","7.64548","0.02277"
"138.4000","2.7664","7.64760","0.02286"
"138.8000","2.7747","7.65103","0.02295"
"139.2000","2.7826","7.65167","0.02304"
"139.6000","2.7904","7.65106","0.02313"
"140.0000","2.7986","7.65488","0.02322"
"140.4000","2.8063","7.65395","0.02330"
"140.8000","2.8145","7.65631","0.02339"
"141.2000","2.8224","7.65715","0.02348"
"141.6000","2.8307","7.66000","0.02357"
"142.0000","2.8385","7.66099","0.02366"
"142.4000","2.8464","7.66060","0.02374"
"142.8000","2.8547","7.64765","0.02382"
"143.2000","2.8624","7.65777","0.02390"
"143.6000","2.8705","7.66424","0.02398"
"144.0000","2.8784","7.66691","0.02407"
"144.4000","2.8865","7.66979","0.02416"
"144.8000","2.8944","7.67135","0.02424"
"145.2000","2.9025","7.67197","0.02433"
"145.6000","2.9107","7.67521","0.02442"
"146.0000","2.9184","7.67319","0.02451"
"146.4000","2.9265","7.67550","0.02460"
"146.8000","2.9344","7.67610","0.02468"
"147.2000","2.9426","7.67938","0.02477"
"147.6000","2.9505","7.68023","0.02486"
"148.0000","2.9585","7.68035","0.02495"
"148.4000","2.9667","7.68455","0.02504"
"148.8000","2.9743","7.68252","0.02512"
"149.2000","2.9825","7.68531","0.02521"
"149.6000","2.9905","7.68643","0.02530"
"150.0000","2.9986","7.68778","0.02539"
"150.4000","3.0064","7.68854","0.02547"
"150.8000","3.0145","7.69050","0.02556"
"151.2000","3.0226","7.69385","0.02565"
"151.6000","3.0305","7.69273","0.02574"
"152.0000","3.0385","7.69482","0.02583"
"152.4000","3.0464","7.69431","0.02591"
"152.8000","3.0546","7.69791","0.02600"
"153.2000","3.0624","7.69834","0.02609"
"153.6000","3.0706","7.70020","0.02618"
"154.0000","3.0787","7.70357","0.02627"
"154.4000","3.0864","7.70138","0.02635"
"154.8000","3.0946","7.70405","0.02644"
"155.2000","3.1023","7.70402","0.02653"
"155.6000","3.1105","7.70703","0.02662"
"156.0000","3.1185","7.70816","0.02670"
"156.4000","3.1265","7.70892","0.02680"
"156.8000","3.1346","7.71147","0.02688"
"157.2000","3.1424","7.71144","0.02697"
"157.6000","3.1506","7.71391","0.02706"
"158.0000","3.1584","7.71336","0.02715"
"158.4000","3.1666","7.71653","0.02724"
"158.8000","3.1744","7.71599","0.02732"
"159.2000","3.1826","7.71828","0.02741"
"159.6000","3.1906","7.72170","0.02750"
"160.0000","3.1984","7.72036","0.02758"
"160.4000","3.2067","7.72332","0.02767"
"160.8000","3.2143","7.72199","0.02776"
"161.2000","3.2225","7.72459","0.02784"
"161.6000","3.2304","7.72646","0.02793"
"162.0000","3.2385","7.72772","0.02802"
"162.4000","3.2466","7.73015","0.02811"
"162.8000","3.2545","7.73023","0.02820"
"163.2000","3.2625","7.73182","0.02828"
"163.6000","3.2703","7.73115","0.02837"
"164.0000","3.2786","7.73516","0.02846"
"164.4000","3.2864","7.73462","0.02855"
"164.8000","3.2946","7.73652","0.02864"
"165.2000","3.3025","7.73877","0.02872"
"165.6000","3.3104","7.73870","0.02881"
"166.0000","3.3186","7.74213","0.02890"
"166.4000","3.3264","7.74046","0.02898"
"166.8000","3.3346","7.74357","0.02907"
"167.2000","3.3424","7.74354","0.02915"
"167.6000","3.3505","7.74479","0.02924"
"168.0000","3.3586","7.74843","0.02933"
"168.4000","3.3666","7.74901","0.02942"
"168.8000","3.3746","7.75015","0.02950"
"169.2000","3.3824","7.74886","0.02959"
"169.6000","3.3905","7.75249","0.02968"
"170.0000","3.3983","7.75202","0.02976"
"170.4000","3.4065","7.75451","0.02985"
"170.8000","3.4146","7.75681","0.02994"
"171.2000","3.4225","7.75730","0.03002"
"171.6000","3.4306","7.75876","0.03011"
"172.0000","3.4383","7.75785","0.03020"
"172.4000","3.4466","7.76213","0.03029"
"172.8000","3.4545","7.76161","0.03037"
"173.2000","3.4625","7.76255","0.03046"
"173.6000","3.4705","7.76494","0.03055"
"174.0000","3.4785","7.76622","0.03063"
"174.4000","3.4866","7.76803","0.03072"
"174.8000","3.4944","7.76684","0.03081"
"175.2000","3.5027","7.77101","0.03090"
"175.6000","3.5104","7.76887","0.03098"
"176.0000","3.5185","7.77095","0.03107"
"176.4000","3.5265","7.77377","0.03115"
"176.8000","3.5345","7.77458","0.03124"
"177.2000","3.5426","7.77637","0.03133"
"177.6000","3.5504","7.77552","0.03141"
"178.0000","3.5585","7.77864","0.03150"
"178.4000","3.5663","7.77786","0.03159"
"178.8000","3.5745","7.78054","0.03167"
"179.2000","3.5826","7.78224","0.03176"
"179.6000","3.5906","7.78321","0.03185"
"180.0000","3.5985","7.78404","0.03194"
"180.4000","3.6064","7.78414","0.03202"
"180.8000","3.6146","7.78823","0.03211"
"181.2000","3.6223","7.78564","0.03219"
"181.6000","3.6305","7.78850","0.03228"
"182.0000","3.6384","7.79015","0.03237"
"182.4000","3.6464","7.79042","0.03245"
"182.8000","3.6546","7.79351","0.03254"
"183.2000","3.6625","7.79175","0.03263"
"183.6000","3.6706","7.78304","0.03269"
"184.0000","3.6784","7.79029","0.03277"
"184.4000","3.6865","7.79625","0.03285"
"184.8000","3.6944","7.79845","0.03294"
"185.2000","3.7025","7.80079","0.03303"
"185.6000","3.7106","7.80197","0.03311"
"186.0000","3.7185","7.78478","0.03318"
"186.4000","3.7266","7.79835","0.03326"
"186.8000","3.7343","7.80068","0.03334"
"187.2000","3.7426","7.80622","0.03343"
"187.6000","3.7504","7.80721","0.03351"
"188.0000","3.7585","7.80784","0.03360"
"188.4000","3.7666","7.80994","0.03369"
"188.8000","3.7745","7.81047","0.03377"
"189.2000","3.7826","7.81270","0.03386"
"189.6000","3.7904","7.81078","0.03395"
"190.0000","3.7986","7.81370","0.03403"
"190.4000","3.8064","7.81362","0.03412"
"190.8000","3.8144","7.81459","0.03420"
"191.2000","3.8225","7.81710","0.03429"
"191.6000","3.8306","7.81836","0.03438"
"192.0000","3.8386","7.81971","0.03446"
"192.4000","3.8463","7.81727","0.03455"
"192.8000","3.8546","7.82131","0.03464"
"193.2000","3.8623","7.82093","0.03472"
"193.6000","3.8704","7.82212","0.03481"
"194.0000","3.8786","7.82497","0.03490"
"194.4000","3.8866","7.82599","0.03498"
"194.8000","3.8945","7.82623","0.03506"
"195.2000","3.9023","7.82562","0.03515"
"195.6000","3.9107","7.82971","0.03524"
"196.0000","3.9184","7.82866","0.03532"
"196.4000","3.9265","7.82967","0.03541"
"196.8000","3.9345","7.83180","0.03550"
"197.2000","3.9426","7.83345","0.03558"
"197.6000","3.9505","7.83457","0.03567"
"198.0000","3.9584","7.83316","0.03575"
"198.4000","3.9667","7.83779","0.03584"
"198.8000","3.9743","7.83526","0.03593"
"199.2000","3.9823","7.83627","0.03601"
"199.6000","3.9906","7.84020","0.03610"
"200.0000","3.9987","7.84164","0.03619"
"200.4000","4.0065","7.84113","0.03627"
"200.8000","4.0145","7.84126","0.03636"
"201.2000","4.0227","7.84511","0.03645"
"201.6000","4.0302","7.84222","0.03653"
"202.0000","4.0384","7.84496","0.03662"
"202.4000","4.0466","7.84748","0.03670"
"202.8000","4.0546","7.84848","0.03679"
"203.2000","4.0624","7.84822","0.03687"
"203.6000","4.0704","7.84859","0.03696"
"204.0000","4.0788","7.85401","0.03705"
"204.4000","4.0863","7.85006","0.03713"
"204.8000","4.0944","7.85148","0.03722"
"205.2000","4.1026","7.85463","0.03731"
"205.6000","4.1105","7.85527","0.03739"
"206.0000","4.1184","7.85584","0.03748"
"206.4000","4.1265","7.85693","0.03757"
"206.8000","4.1348","7.86037","0.03765"
"207.2000","4.1423","7.85662","0.03773"
"207.6000","4.1504","7.85904","0.03782"
"208.0000","4.1585","7.86162","0.03791"
"208.4000","4.1667","7.86363","0.03800"
"208.8000","4.1744","7.86264","0.03808"
"209.2000","4.1825","7.86376","0.03817"
"209.6000","4.1908","7.86783","0.03825"
"210.0000","4.1982","7.86333","0.03834"
"210.4000","4.2065","7.86692","0.03843"
"210.8000","4.2146","7.86922","0.03851"
"211.2000","4.2225","7.86904","0.03860"
"211.6000","4.2304","7.86937","0.03868"
"212.0000","4.2385","7.87154","0.03877"
"212.4000","4.2467","7.87495","0.03886"
"212.8000","4.2543","7.87111","0.03894"
"213.2000","4.2625","7.87393","0.03903"
"213.6000","4.2705","7.87550","0.03911"
"214.0000","4.2785","7.87590","0.03920"
"214.4000","4.2864","7.87648","0.03929"
"214.8000","4.2946","7.87895","0.03937"
"215.2000","4.3028","7.88211","0.03946"
"215.6000","4.3103","7.87713","0.03954"
"216.0000","4.3185","7.88058","0.03963"
"216.4000","4.3265","7.88262","0.03971"
"216.8000","4.3345","7.88317","0.03980"
"217.2000","4.3424","7.88322","0.03988"
"217.6000","4.3506","7.88611","0.03997"
"218.0000","4.3586","7.88761","0.04006"
"218.4000","4.3663","7.88449","0.04014"
"218.8000","4.3746","7.88853","0.04023"
"219.2000","4.3825","7.88921","0.04031"
"219.6000","4.3905","7.88963","0.04040"
"220.0000","4.3984","7.88969","0.04049"
"220.4000","4.4066","7.89235","0.04058"
"220.8000","4.4147","7.89513","0.04066"
"221.2000","4.4223","7.89141","0.04074"
"221.6000","4.4306","7.89509","0.04083"
"222.0000","4.4385","7.89531","0.04092"
"222.4000","4.4464","7.89542","0.04100"
"222.8000","4.4544","7.89688","0.04109"
"223.2000","4.4627","7.89985","0.04118"
"223.6000","4.4706","7.90051","0.04126"
"224.0000","4.4784","7.89824","0.04135"
"224.4000","4.4866","7.90174","0.04143"
"224.8000","4.4944","7.90132","0.04152"
"225.2000","4.5025","7.90287","0.04160"
"225.6000","4.5104","7.90298","0.04169"
"226.0000","4.5187","7.90563","0.04178"
"226.4000","4.5266","7.90665","0.04186"
"226.8000","4.5343","7.90426","0.04195"
"227.2000","4.5426","7.90901","0.04204"
"227.6000","4.5505","7.90832","0.04212"
"228.0000","4.5585","7.90844","0.04221"
"228.4000","4.5664","7.90953","0.04229"
"228.8000","4.5745","7.91147","0.04238"
"229.2000","4.5825","7.91296","0.04246"
"229.6000","4.5905","7.91174","0.04255"
"230.0000","4.5987","7.91531","0.04264"
"230.4000","4.6064","7.91354","0.04272"
"230.8000","4.6145","7.91474","0.04281"
"231.2000","4.6223","7.91516","0.04289"
"231.6000","4.6306","7.91833","0.04298"
"232.0000","4.6385","7.91892","0.04307"
"232.4000","4.6465","7.91767","0.04315"
"232.8000","4.6547","7.92130","0.04324"
"233.2000","4.6623","7.91940","0.04332"
"233.6000","4.6705","7.92140","0.04341"
"234.0000","4.6785","7.92232","0.04350"
"234.4000","4.6866","7.92406","0.04358"
"234.8000","4.6945","7.92406","0.04367"
"235.2000","4.7025","7.92439","0.04375"
"235.6000","4.7107","7.92775","0.04384"
"236.0000","4.7184","7.92561","0.04392"
"236.4000","4.7265","7.92738","0.04401"
"236.8000","4.7344","7.92738","0.04409"
"237.2000","4.7425","7.92944","0.04418"
"237.6000","4.7504","7.93040","0.04426"
"238.0000","4.7585","7.93088","0.04435"
"238.4000","4.7667","7.93391","0.04444"
"238.8000","4.7744","7.93117","0.04452"
"239.2000","4.7825","7.93278","0.04461"
"239.6000","4.7904","7.93356","0.04469"
"240.0000","4.7986","7.93585","0.04478"
"240.4000","4.8064","7.93558","0.04487"
"240.8000","4.8145","7.93667","0.04495"
"241.2000","4.8226","7.93919","0.04504"
"241.6000","4.8304","7.93698","0.04512"
"242.0000","4.8386","7.93954","0.04521"
"242.4000","4.8464","7.93913","0.04529"
"242.8000","4.8546","7.94133","0.04538"
"243.2000","4.8624","7.94101","0.04546"
"243.6000","4.8705","7.94175","0.04555"
"244.0000","4.8787","7.94549","0.04564"
"244.4000","4.8864","7.94334","0.04572"
"244.8000","4.8946","7.94482","0.04581"
"245.2000","4.9024","7.94423","0.04589"
"245.6000","4.9105","7.94607","0.04598"
"246.0000","4.9184","7.94652","0.04606"
"246.4000","4.9266","7.94853","0.04615"
"246.8000","4.9347","7.95029","0.04624"
"247.2000","4.9424","7.94852","0.04632"
"247.6000","4.9506","7.95088","0.04641"
"248.0000","4.9583","7.94935","0.04649"
"248.4000","4.9666","7.95265","0.04658"
"248.8000","4.9744","7.95187","0.04667"
"249.2000","4.9825","7.95277","0.04675"
"249.6000","4.9906","7.94973","0.04684"
"250.0000","4.9984","7.94304","0.04690"
"250.4000","5.0066","7.95285","0.04698"
"250.8000","5.0144","7.95510","0.04706"
"251.2000","5.0226","7.95800","0.04715"
"251.6000","5.0304","7.95748","0.04723"
"252.0000","5.0385","7.95888","0.04732"
"252.4000","5.0466","7.96159","0.04740"
"252.8000","5.0545","7.96109","0.04749"
"253.2000","5.0626","7.96249","0.04757"
"253.6000","5.0704","7.96021","0.04766"
"254.0000","5.0786","7.96331","0.04775"
"254.4000","5.0863","7.96226","0.04783"
"254.8000","5.0945","7.96384","0.04792"
"255.2000","5.1026","7.96634","0.04800"
"255.6000","5.1105","7.96508","0.04809"
"256.0000","5.1186","7.96640","0.04817"
"256.4000","5.1263","7.96511","0.04826"
"256.8000","5.1346","7.96817","0.04834"
"257.2000","5.1424","7.96728","0.04843"
"257.6000","5.1506","7.96831","0.04851"
"258.0000","5.1585","7.96993","0.04860"
"258.4000","5.1665","7.97018","0.04868"
"258.8000","5.1746","7.97199","0.04877"
"259.2000","5.1824","7.97010","0.04886"
"259.6000","5.1906","7.97336","0.04894"
"260.0000","5.1984","7.97132","0.04903"
"260.4000","5.2065","7.97247","0.04911"
"260.8000","5.2145","7.97557","0.04920"
"261.2000","5.2225","7.97523","0.04928"
"261.6000","5.2306","7.97642","0.04937"
"262.0000","5.2384","7.97460","0.04945"
"262.4000","5.2465","7.97705","0.04954"
"262.8000","5.2544","7.97646","0.04962"
"263.2000","5.2625","7.97827","0.04971"
"263.6000","5.2706","7.97942","0.04979"
"264.0000","5.2786","7.98031","0.04988"
"264.4000","5.2865","7.98028","0.04996"
"264.8000","5.2944","7.97922","0.05005"
"265.2000","5.3026","7.98315","0.05013"
"265.6000","5.3104","7.97769","0.05022"
"266.0000","5.3186","7.96887","0.05028"
"266.4000","5.3265","7.97936","0.05036"
"266.8000","5.3345","7.98295","0.05044"
"267.2000","5.3426","7.98683","0.05053"
"267.6000","5.3505","7.98548","0.05061"
"268.0000","5.3586","7.98828","0.05070"
"268.4000","5.3664","7.98619","0.05078"
"268.8000","5.3745","7.98726","0.05087"
"269.2000","5.3825","7.98898","0.05095"
"269.6000","5.3906","7.98974","0.05104"
"270.0000","5.3986","7.98967","0.05112"
"270.4000","5.4065","7.98986","0.05121"
"270.8000","5.4146","7.99181","0.05129"
"271.2000","5.4222","7.98861","0.05137"
"271.6000","5.4306","7.99285","0.05146"
"272.0000","5.4385","7.99265","0.05154"
"272.4000","5.4465","7.99262","0.05163"
"272.8000","5.4546","7.99449","0.05172"
"273.2000","5.4624","7.99335","0.05180"
"273.6000","5.4706","7.99629","0.05189"
"274.0000","5.4784","7.99395","0.05197"
"274.4000","5.4865","7.99564","0.05206"
"274.8000","5.4945","7.99684","0.05214"
"275.2000","5.5024","7.99633","0.05222"
"275.6000","5.5105","7.99801","0.05231"
"276.0000","5.5186","7.99878","0.05240"
"276.4000","5.5266","8.00008","0.05248"
"276.8000","5.5343","7.99699","0.05256"
"277.2000","5.5426","8.00038","0.05265"
"277.6000","5.5503","7.99962","0.05273"
"278.0000","5.5585","8.00075","0.05282"
"278.4000","5.5666","8.00276","0.05291"
"278.8000","5.5746","8.00226","0.05299"
"279.2000","5.5826","8.00344","0.05307"
"279.6000","5.5903","8.00095","0.05316"
"280.0000","5.5986","8.00463","0.05324"
"280.4000","5.6065","8.00444","0.05333"
"280.8000","5.6144","8.00408","0.05341"
"281.2000","5.6225","8.00575","0.05350"
"281.6000","5.6306","8.00656","0.05358"
"282.0000","5.6385","8.00768","0.05366"
"282.4000","5.6464","8.00521","0.05375"
"282.8000","5.6547","8.00872","0.05384"
"283.2000","5.6624","8.00721","0.05392"
"283.6000","5.6704","8.00752","0.05400"
"284.0000","5.6785","8.01063","0.05409"
"284.4000","5.6866","8.01106","0.05417"
"284.8000","5.6945","8.01098","0.05426"
"285.2000","5.7024","8.00949","0.05434"
"285.6000","5.7107","8.01222","0.05443"
"286.0000","5.7183","8.01023","0.05451"
"286.4000","5.7264","8.01195","0.05460"
"286.8000","5.7346","8.01364","0.05468"
"287.2000","5.7426","8.01452","0.05476"
"287.6000","5.7504","8.01402","0.05485"
"288.0000","5.7583","8.01290","0.05493"
"288.4000","5.7668","8.01759","0.05502"
"288.8000","5.7744","8.01460","0.05510"
"289.2000","5.7824","8.01474","0.05519"
"289.6000","5.7906","8.01751","0.05527"
"290.0000","5.7986","8.01794","0.05536"
"290.4000","5.8065","8.01813","0.05544"
"290.8000","5.8145","8.01743","0.05553"
"291.2000","5.8227","8.02071","0.05561"
"291.6000","5.8303","8.01728","0.05570"
"292.0000","5.8384","8.01859","0.05578"
"292.4000","5.8465","8.02058","0.05587"
"292.8000","5.8547","8.02251","0.05595"
"293.2000","5.8625","8.02116","0.05603"
"293.6000","5.8705","8.02050","0.05612"
"294.0000","5.8787","8.02452","0.05620"
"294.4000","5.8862","8.02019","0.05628"
"294.8000","5.8944","8.02240","0.05637"
"295.2000","5.9026","8.02467","0.05646"
"295.6000","5.9106","8.02441","0.05654"
"296.0000","5.9184","8.02371","0.05662"
"296.4000","5.9264","8.02462","0.05671"
"296.8000","5.9348","8.02828","0.05679"
"297.2000","5.9423","8.02374","0.05688"
"297.6000","5.9505","8.02568","0.05696"
"298.0000","5.9586","8.02733","0.05704"
"298.4000","5.9665","8.02756","0.05713"
"298.8000","5.9744","8.02743","0.05721"
"299.2000","5.9826","8.02826","0.05730"
"299.6000","5.9908","8.03161","0.05738"
"300.0000","5.9982","8.02593","0.05746"
"300.4000","6.0064","8.02852","0.05755"
"300.8000","6.0145","8.03096","0.05763"
"301.2000","6.0226","8.03078","0.05772"
"301.6000","6.0304","8.03021","0.05780"
"302.0000","6.0386","8.03155","0.05788"
"302.4000","6.0467","8.03382","0.05797"
"302.8000","6.0542","8.02938","0.05805"
"303.2000","6.0625","8.03261","0.05814"
"303.6000","6.0706","8.03385","0.05822"
"304.0000","6.0786","8.03376","0.05830"
"304.4000","6.0864","8.03305","0.05839"
"304.8000","6.0945","8.03450","0.05847"
"305.2000","6.1027","8.03776","0.05855"
"305.6000","6.1103","8.03262","0.05864"
"306.0000","6.1185","8.03534","0.05872"
"306.4000","6.1265","8.03657","0.05881"
"306.8000","6.1345","8.03557","0.05889"
"307.2000","6.1424","8.03586","0.05897"
"307.6000","6.1507","8.03852","0.05906"
"308.0000","6.1587","8.03954","0.05914"
"308.4000","6.1663","8.03540","0.05922"
"308.8000","6.1745","8.03851","0.05931"
"309.2000","6.1824","8.03864","0.05939"
"309.6000","6.1905","8.03934","0.05948"
"310.0000","6.1984","8.03866","0.05956"
"310.4000","6.2067","8.04077","0.05965"
"310.8000","6.2147","8.04227","0.05973"
"311.2000","6.2223","8.03783","0.05981"
"311.6000","6.2306","8.04166","0.05990"
"312.0000","6.2385","8.04183","0.05998"
"312.4000","6.2465","8.04106","0.06006"
"312.8000","6.2544","8.04116","0.06014"
"313.2000","6.2626","8.04334","0.06023"
"313.6000","6.2706","8.04437","0.06031"
"314.0000","6.2784","8.04149","0.06039"
"314.4000","6.2866","8.04455","0.06048"
"314.8000","6.2944","8.04315","0.06056"
"315.2000","6.3025","8.04353","0.06064"
"315.6000","6.3103","8.04349","0.06073"
"316.0000","6.3187","8.04623","0.06081"
"316.4000","6.3266","8.04675","0.06090"
"316.8000","6.3344","8.04356","0.06098"
"317.2000","6.3426","8.04675","0.06106"
"317.6000","6.3504","8.04559","0.06114"
"318.0000","6.3585","8.04631","0.06122"
"318.4000","6.3665","8.04669","0.06131"
"318.8000","6.3746","8.04830","0.06139"
"319.2000","6.3825","8.04804","0.06147"
"319.6000","6.3904","8.04669","0.06156"
"320.0000","6.3987","8.04995","0.06164"
"320.4000","6.4064","8.04776","0.06172"
"320.8000","6.4145","8.04846","0.06180"
"321.2000","6.4224","8.04811","0.06189"
"321.6000","6.4305","8.05007","0.06197"
"322.0000","6.4385","8.05100","0.06205"
"322.4000","6.4465","8.04930","0.06213"
"322.8000","6.4548","8.05265","0.06222"
"323.2000","6.4624","8.04946","0.06230"
"323.6000","6.4705","8.05003","0.06238"
"324.0000","6.4784","8.05074","0.06246"
"324.4000","6.4866","8.05284","0.06255"
"324.8000","6.4945","8.05209","0.06263"
"325.2000","6.5025","8.05176","0.06271"
"325.6000","6.5106","8.05399","0.06279"
"326.0000","6.5183","8.05134","0.06287"
"326.4000","6.5265","8.05342","0.06296"
"326.8000","6.5345","8.05275","0.06304"
"327.2000","6.5426","8.05421","0.06312"
"327.6000","6.5505","8.05394","0.06320"
"328.0000","6.5585","8.05348","0.06328"
"328.4000","6.5667","8.05667","0.06337"
"328.8000","6.5744","8.05392","0.06345"
"329.2000","6.5826","8.05486","0.06353"
"329.6000","6.5904","8.05437","0.06361"
"330.0000","6.5985","8.05587","0.06369"
"330.4000","6.6064","8.05568","0.06377"
"330.8000","6.6146","8.05651","0.06385"
"331.2000","6.6227","8.05786","0.06394"
"331.6000","6.6304","8.05531","0.06402"
"332.0000","6.6385","8.05711","0.06410"
"332.4000","6.6464","8.05577","0.06418"
"332.8000","6.6546","8.05816","0.06426"
"333.2000","6.6625","8.05731","0.06434"
"333.6000","6.6705","8.05745","0.06442"
"334.0000","6.6786","8.05999","0.06450"
"334.4000","6.6863","8.05721","0.06458"
"334.8000","6.6945","8.05939","0.06466"
"335.2000","6.7025","8.05854","0.06474"
"335.6000","6.7106","8.05951","0.06483"
"336.0000","6.7184","8.05831","0.06490"
"336.4000","6.7265","8.05945","0.06499"
"336.8000","6.7346","8.06163","0.06507"
"337.2000","6.7425","8.05970","0.06515"
"337.6000","6.7506","8.06087","0.06523"
"338.0000","6.7584","8.05898","0.06531"
"338.4000","6.7665","8.06120","0.06539"
"338.8000","6.7744","8.06031","0.06547"
"339.2000","6.7826","8.06151","0.06555"
"339.6000","6.7907","8.06335","0.06563"
"340.0000","6.7985","8.06101","0.06571"
"340.4000","6.8066","8.06225","0.06579"
"340.8000","6.8143","8.06056","0.06587"
"341.2000","6.8225","8.06290","0.06595"
"341.6000","6.8305","8.06215","0.06603"
"342.0000","6.8385","8.06233","0.06611"
"342.4000","6.8466","8.06379","0.06619"
"342.8000","6.8545","8.06288","0.06627"
"343.2000","6.8626","8.06446","0.06635"
"343.6000","6.8704","8.06206","0.06643"
"344.0000","6.8786","8.06476","0.06651"
"344.4000","6.8864","8.06277","0.06658"
"344.8000","6.8945","8.06329","0.06666"
"345.2000","6.9026","8.06578","0.06674"
"345.6000","6.9105","8.06467","0.06682"
"346.0000","6.9186","8.06537","0.06690"
"346.4000","6.9264","8.06322","0.06698"
"346.8000","6.9345","8.06520","0.06706"
"347.2000","6.9423","8.06428","0.06714"
"347.6000","6.9506","8.06561","0.06721"
"348.0000","6.9586","8.06654","0.06729"
"348.4000","6.9666","8.06602","0.06737"
"348.8000","6.9746","8.06622","0.06745"
"349.2000","6.9823","8.06396","0.06753"
"349.6000","6.9906","8.06764","0.06761"
"350.0000","6.9984","8.06544","0.06768"
"350.4000","7.0065","8.06554","0.06776"
"350.8000","7.0145","8.06735","0.06784"
"351.2000","7.0225","8.06669","0.06792"
"351.6000","7.0306","8.06791","0.06800"
"352.0000","7.0384","8.06600","0.06807"
"352.4000","7.0466","8.06830","0.06815"
"352.8000","7.0544","8.06605","0.06823"
"353.2000","7.0625","8.06689","0.06831"
"353.6000","7.0705","8.06828","0.06838"
"354.0000","7.0786","8.06901","0.06846"
"354.4000","7.0866","8.06856","0.06854"
"354.8000","7.0944","8.06638","0.06861"
"355.2000","7.1026","8.06945","0.06869"
"355.6000","7.1103","8.06683","0.06876"
"356.0000","7.1185","8.06838","0.06884"
"356.4000","7.1265","8.06949","0.06892"
"356.8000","7.1346","8.06914","0.06900"
"357.2000","7.1426","8.06945","0.06907"
"357.6000","7.1504","8.06765","0.06915"
"358.0000","7.1586","8.07048","0.06923"
"358.4000","7.1664","8.06822","0.06930"
"358.8000","7.1745","8.06907","0.06938"
"359.2000","7.1825","8.06946","0.06945"
"359.6000","7.1905","8.06964","0.06953"
"360.0000","7.1985","8.07047","0.06960"
"360.4000","7.2065","8.06901","0.06968"
"360.8000","7.2147","8.07134","0.06975"
"361.2000","7.2223","8.06769","0.06983"
"361.6000","7.2305","8.06953","0.06990"
"362.0000","7.2384","8.07032","0.06998"
"362.4000","7.2465","8.07056","0.07005"
"362.8000","7.2546","8.07099","0.07013"
"363.2000","7.2625","8.06987","0.07020"
"363.6000","7.2706","8.07128","0.07028"
"364.0000","7.2783","8.06876","0.07035"
"364.4000","7.2866","8.07104","0.07042"
"364.8000","7.2945","8.07083","0.07050"
"365.2000","7.3025","8.07099","0.07057"
"365.6000","7.3105","8.07088","0.07064"
"366.0000","7.3185","8.07023","0.07072"
"366.4000","7.3266","8.07283","0.07079"
"366.8000","7.3344","8.06931","0.07086"
"367.2000","7.3426","8.07131","0.07094"
"367.6000","7.3504","8.07082","0.07101"
"368.0000","7.3584","8.07013","0.07108"
"368.4000","7.3665","8.07234","0.07115"
"368.8000","7.3746","8.07206","0.07123"
"369.2000","7.3826","8.07229","0.07130"
"369.6000","7.3904","8.06953","0.07137"
"370.0000","7.3986","8.07185","0.07144"
"370.4000","7.4063","8.07060","0.07151"
"370.8000","7.4145","8.07130","0.07159"
"371.2000","7.4225","8.07187","0.07166"
"371.6000","7.4306","8.07201","0.07173"
"372.0000","7.4385","8.07205","0.07180"
"372.4000","7.4463","8.06930","0.07187"
"372.8000","7.4547","8.07341","0.07194"
"373.2000","7.4624","8.07099","0.07201"
"373.6000","7.4704","8.07013","0.07208"
"374.0000","7.4786","8.07266","0.07215"
"374.4000","7.4866","8.07250","0.07222"
"374.8000","7.4945","8.07262","0.07229"
"375.2000","7.5024","8.07060","0.07236"
"375.6000","7.5107","8.07288","0.07243"
"376.0000","7.5184","8.07082","0.07250"
"376.4000","7.5264","8.07071","0.07257"
"376.8000","7.5345","8.07191","0.07264"
"377.2000","7.5428","8.07432","0.07271"
"377.6000","7.5505","8.07219","0.07278"
"378.0000","7.5584","8.06995","0.07284"
"378.4000","7.5667","8.07379","0.07292"
"378.8000","7.5742","8.07000","0.07298"
"379.2000","7.5825","8.07096","0.07305"
"379.6000","7.5906","8.07281","0.07312"
"380.0000","7.5986","8.07228","0.07318"
"380.4000","7.6065","8.07158","0.07325"
"380.8000","7.6144","8.07046","0.07332"
"381.2000","7.6227","8.07361","0.07339"
"381.6000","7.6304","8.07099","0.07345"
"382.0000","7.6384","8.07075","0.07352"
"382.4000","7.6465","8.07149","0.07358"
"382.8000","7.6546","8.07245","0.07365"
"383.2000","7.6624","8.07122","0.07371"
"383.6000","7.6705","8.07046","0.07378"
"384.0000","7.6788","8.07415","0.07384"
"384.4000","7.6862","8.06873","0.07391"
"384.8000","7.6944","8.07023","0.07397"
"385.2000","7.7025","8.07195","0.07403"
"385.6000","7.7106","8.07172","0.07410"
"386.0000","7.7185","8.07128","0.07416"
"386.4000","7.7265","8.07038","0.07423"
"386.8000","7.7347","8.07274","0.07429"
"387.2000","7.7422","8.06889","0.07435"
"387.6000","7.7504","8.07035","0.07442"
"388.0000","7.7586","8.07158","0.07448"
"388.4000","7.7666","8.07147","0.07454"
"388.8000","7.7744","8.06944","0.07460"
"389.2000","7.7825","8.07044","0.07466"
"389.6000","7.7908","8.07372","0.07472"
"390.0000","7.7983","8.06797","0.07478"
"390.4000","7.8065","8.06969","0.07485"
"390.8000","7.8145","8.07056","0.07491"
"391.2000","7.8225","8.06972","0.07497"
"391.6000","7.8304","8.06956","0.07503"
"392.0000","7.8386","8.07036","0.07508"
"392.4000","7.8468","8.07233","0.07514"
"392.8000","7.8543","8.06690","0.07520"
"393.2000","7.8625","8.06896","0.07526"
"393.6000","7.8705","8.06981","0.07532"
"394.0000","7.8786","8.06967","0.07538"
"394.4000","7.8864","8.06805","0.07544"
"394.8000","7.8946","8.06945","0.07550"
"395.2000","7.9027","8.07084","0.07556"
"395.6000","7.9102","8.06568","0.07561"
"396.0000","7.9185","8.06879","0.07567"
"396.4000","7.9266","8.06921","0.07572"
"396.8000","7.9345","8.06742","0.07578"
"397.2000","7.9424","8.06671","0.07583"
"397.6000","7.9506","8.06868","0.07589"
"398.0000","7.9587","8.06985","0.07595"
"398.4000","7.9663","8.06526","0.07600"
"398.8000","7.9746","8.06729","0.07606"
"399.2000","7.9825","8.06670","0.07611"
"399.6000","7.9905","8.06609","0.07616"
"400.0000","7.9983","8.06531","0.07622"
"400.4000","8.0067","8.06743","0.07627"
"400.8000","8.0147","8.06785","0.07632"
"401.2000","8.0223","8.06297","0.07637"
"401.6000","8.0306","8.06578","0.07642"
"402.0000","8.0384","8.06487","0.07648"
"402.4000","8.0465","8.06459","0.07652"
"402.8000","8.0545","8.06433","0.07658"
"403.2000","8.0627","8.06554","0.07663"
"403.6000","8.0706","8.06506","0.07667"
"404.0000","8.0783","8.06185","0.07672"
"404.4000","8.0866","8.06486","0.07677"
"404.8000","8.0945","8.06294","0.07682"
"405.2000","8.1025","8.06228","0.07687"
"405.6000","8.1104","8.06156","0.07691"
"406.0000","8.1186","8.06318","0.07696"
"406.4000","8.1266","8.06348","0.07701"
"406.8000","8.1344","8.05986","0.07705"
"407.2000","8.1427","8.06241","0.07710"
"407.6000","8.1504","8.06008","0.07714"
"408.0000","8.1584","8.05969","0.07719"
"408.4000","8.1664","8.05959","0.07723"
"408.8000","8.1746","8.06128","0.07728"
"409.2000","8.1826","8.06012","0.07732"
"409.6000","8.1904","8.05744","0.07736"
"410.0000","8.1986","8.05976","0.07740"
"410.4000","8.2064","8.05687","0.07744"
"410.8000","8.2145","8.05746","0.07749"
"411.2000","8.2224","8.05614","0.07753"
"411.6000","8.2307","8.05759","0.07757"
"412.0000","8.2385","8.05652","0.07761"
"412.4000","8.2464","8.05404","0.07765"
"412.8000","8.2547","8.05701","0.07769"
"413.2000","8.2624","8.05397","0.07772"
"413.6000","8.2705","8.05321","0.07776"
"414.0000","8.2784","8.05267","0.07780"
"414.4000","8.2865","8.05301","0.07784"
"414.8000","8.2944","8.05236","0.07787"
"415.2000","8.3025","8.05142","0.07791"
"415.6000","8.3107","8.05243","0.07794"
"416.0000","8.3184","8.04840","0.07798"
"416.4000","8.3265","8.04878","0.07801"
"416.8000","8.3343","8.04733","0.07805"
"417.2000","8.3426","8.04874","0.07808"
"417.6000","8.3505","8.04716","0.07811"
"418.0000","8.3585","8.04554","0.07814"
"418.4000","8.3666","8.04699","0.07817"
"418.8000","8.3743","8.04322","0.07820"
"419.2000","8.3825","8.04387","0.07823"
"419.6000","8.3905","8.04231","0.07826"
"420.0000","8.3986","8.04190","0.07829"
"420.4000","8.4064","8.03996","0.07832"
"420.8000","8.4145","8.03933","0.07835"
"421.2000","8.4227","8.04064","0.07838"
"421.6000","8.4304","8.03631","0.07840"
"422.0000","8.4386","8.03625","0.07843"
"422.4000","8.4464","8.03374","0.07845"
"422.8000","8.4545","8.03406","0.07848"
"423.2000","8.4624","8.03242","0.07850"
"423.6000","8.4706","8.03113","0.07853"
"424.0000","8.4787","8.03155","0.07855"
"424.4000","8.4864","8.02717","0.07857"
"424.8000","8.4945","8.02655","0.07859"
"425.2000","8.5024","8.02414","0.07861"
"425.6000","8.5106","8.02427","0.07863"
"426.0000","8.5184","8.02128","0.07865"
"426.4000","8.5266","8.01988","0.07867"
"426.8000","8.5346","8.01958","0.07869"
"427.2000","8.5424","8.01557","0.07870"
"427.6000","8.5506","8.01556","0.07872"
"428.0000","8.5584","8.01102","0.07874"
"428.4000","8.5666","8.01097","0.07875"
"428.8000","8.5744","8.00742","0.07877"
"429.2000","8.5825","8.00525","0.07878"
"429.6000","8.5906","8.00579","0.07880"
"430.0000","8.5985","8.00060","0.07881"
"430.4000","8.6066","7.99907","0.07882"
"430.8000","8.6144","7.99465","0.07883"
"431.2000","8.6225","7.99345","0.07885"
"431.6000","8.6303","7.99011","0.07886"
"432.0000","8.6386","7.98820","0.07887"
"432.4000","8.6466","7.98595","0.07888"
"432.8000","8.6545","7.98121","0.07889"
"433.2000","8.6626","7.97909","0.07890"
"433.6000","8.6703","7.97330","0.07890"
"434.0000","8.6786","7.97332","0.07892"
"434.4000","8.6864","7.96756","0.07892"
"434.8000","8.6945","7.96410","0.07893"
"435.2000","8.7026","7.96279","0.07894"
"435.6000","8.7105","7.95693","0.07894"
"436.0000","8.7186","7.95419","0.07895"
"436.4000","8.7264","7.94792","0.07895"
"436.8000","8.7346","7.94567","0.07896"
"437.2000","8.7424","7.93956","0.07896"
"437.6000","8.7505","7.93548","0.07897"
"438.0000","8.7585","7.93325","0.07897"
"438.4000","8.7666","7.92754","0.07898"
"438.8000","8.7746","7.92269","0.07898"
"439.2000","8.7824","7.91454","0.07898"
"439.6000","8.7905","7.91289","0.07899"
"440.0000","8.7983","7.90576","0.07899"
"440.4000","8.8066","7.90062","0.07899"
"440.8000","8.8146","7.89668","0.07899"
"441.2000","8.8225","7.88985","0.07899"
"441.6000","8.8306","7.88439","0.07899"
"442.0000","8.8384","7.87608","0.07899"
"442.4000","8.8466","7.87300","0.07899"
"442.8000","8.8544","7.86429","0.07899"
"443.2000","8.8625","7.85781","0.07899"
"443.6000","8.8705","7.85250","0.07899"
"444.0000","8.8785","7.84563","0.07899"
"444.4000","8.8866","7.83930","0.07899"
"444.8000","8.8945","7.82919","0.07898"
"445.2000","8.9027","7.82502","0.07898"
"445.6000","8.9103","7.81412","0.07898"
"446.0000","8.9185","7.80713","0.07898"
"446.4000","8.9265","7.80187","0.07898"
"446.8000","8.9346","7.79283","0.07897"
"447.2000","8.9426","7.78460","0.07897"
"447.6000","8.9504","7.77455","0.07897"
"448.0000","8.9586","7.76866","0.07896"
"448.4000","8.9663","7.75710","0.07896"
"448.8000","8.9745","7.74936","0.07896"
"449.2000","8.9825","7.74114","0.07895"
"449.6000","8.9906","7.73172","0.07895"
"450.0000","8.9985","7.72210","0.07895"
"450.4000","9.0064","7.71127","0.07894"
"450.8000","9.0146","7.70504","0.07894"
"451.2000","9.0224","7.69091","0.07893"
"451.6000","9.0306","7.68194","0.07893"
"452.0000","9.0384","7.67312","0.07892"
"452.4000","9.0464","7.66165","0.07892"
"452.8000","9.0546","7.65290","0.07891"
"453.2000","9.0625","7.64025","0.07891"
"453.6000","9.0706","7.63116","0.07890"
"454.0000","9.0784","7.61683","0.07890"
"454.4000","9.0865","7.60685","0.07889"
"454.8000","9.0944","7.59618","0.07889"
"455.2000","9.1025","7.58431","0.07888"
"455.6000","9.1106","7.57258","0.07888"
"456.0000","9.1185","7.55985","0.07887"
"456.4000","9.1265","7.54993","0.07886"
"456.8000","9.1343","7.53370","0.07885"
"457.2000","9.1426","7.52339","0.07885"
"457.6000","9.1505","7.51122","0.07884"
"458.0000","9.1585","7.49660","0.07883"
"458.4000","9.1666","7.48529","0.07883"
"458.8000","9.1745","7.47184","0.07882"
"459.2000","9.1825","7.45936","0.07881"
"459.6000","9.1904","7.44215","0.07880"
"460.0000","9.1986","7.43011","0.07880"
"460.4000","9.2064","7.41629","0.07879"
"460.8000","9.2144","7.40131","0.07878"
"461.2000","9.2225","7.38866","0.07877"
"461.6000","9.2306","7.37355","0.07877"
"462.0000","9.2386","7.35969","0.07876"
"462.4000","9.2464","7.34095","0.07875"
"462.8000","9.2546","7.32846","0.07874"
"463.2000","9.2624","7.31293","0.07873"
"463.6000","9.2705","7.29586","0.07872"
"464.0000","9.2786","7.28189","0.07872"
"464.4000","9.2866","7.26591","0.07871"
"464.8000","9.2945","7.24962","0.07870"
"465.2000","9.3023","7.23063","0.07869"
"465.6000","9.3107","7.21673","0.07868"
"466.0000","9.3184","7.19800","0.07867"
"466.4000","9.3265","7.18008","0.07866"
"466.8000","9.3345","7.16424","0.07865"
"467.2000","9.3426","7.14703","0.07864"
"467.6000","9.3505","7.12986","0.07863"
"468.0000","9.3584","7.10766","0.07862"
"468.4000","9.3667","7.09239","0.07861"
"468.8000","9.3743","7.07182","0.07860"
"469.2000","9.3824","7.05143","0.07859"
"469.6000","9.3905","7.03518","0.07858"
"470.0000","9.3987","7.01508","0.07857"
"470.4000","9.4065","6.99456","0.07855"
"470.8000","9.4145","6.97251","0.07854"
"471.2000","9.4227","6.95544","0.07853"
"471.6000","9.4303","6.93237","0.07852"
"472.0000","9.4384","6.91121","0.07851"
"472.4000","9.4466","6.89225","0.07850"
"472.8000","9.4547","6.87107","0.07848"
"473.2000","9.4624","6.84936","0.07847"
"473.6000","9.4704","6.82568","0.07846"
"474.0000","9.4788","6.80756","0.07845"
"474.4000","9.4863","6.78155","0.07844"
"474.8000","9.4945","6.75758","0.07842"
"475.2000","9.5026","6.73741","0.07841"
"475.6000","9.5105","6.71341","0.07839"
"476.0000","9.5184","6.68920","0.07838"
"476.4000","9.5266","6.66277","0.07837"
"476.8000","9.5348","6.64065","0.07835"
"477.2000","9.5423","6.61140","0.07834"
"477.6000","9.5504","6.58454","0.07832"
"478.0000","9.5585","6.55902","0.07831"
"478.4000","9.5666","6.52969","0.07829"
"478.8000","9.5744","6.49973","0.07827"
"479.2000","9.5826","6.46727","0.07825"
"479.6000","9.5908","6.43820","0.07824"
"480.0000","9.5982","6.40191","0.07822"
"480.4000","9.6065","6.36657","0.07819"
"480.8000","9.6146","6.33244","0.07818"
"481.2000","9.6226","6.29436","0.07815"
"481.6000","9.6304","6.25544","0.07813"
"482.0000","9.6386","6.21200","0.07811"
"482.4000","9.6467","6.16579","0.07808"
"482.8000","9.6544","6.10282","0.07804"
"483.2000","9.6625","6.02544","0.07800"
"483.6000","9.6706","5.92052","0.07793"
"483.9690","9.6779","5.72322","0.07782"
"483.9860","9.6783","5.27118","0.07751"
"483.9900","9.6785","4.82098","0.07724"