File: Coupon Test Data/Tensile Test_Neebajan_Alan_17.csv
Time,Displacement,Force,Strain 1
(s),(mm),(kN),(mm/mm)
"0.0000","0.0000","0.19358","0.00003"
"0.4000","0.0050","0.23632","0.00006"
"0.8000","0.0133","0.31961","0.00011"
"1.2000","0.0215","0.39992","0.00016"
"1.6000","0.0292","0.47371","0.00020"
"2.0000","0.0373","0.55106","0.00025"
"2.4000","0.0454","0.62765","0.00030"
"2.8000","0.0535","0.69760","0.00035"
"3.2000","0.0614","0.77077","0.00039"
"3.6000","0.0695","0.84554","0.00044"
"4.0000","0.0776","0.91635","0.00048"
"4.4000","0.0852","0.97657","0.00052"
"4.8000","0.0934","1.04809","0.00057"
"5.2000","0.1015","1.12046","0.00061"
"5.6000","0.1095","1.18583","0.00065"
"6.0000","0.1173","1.25257","0.00070"
"6.4000","0.1255","1.32471","0.00074"
"6.8000","0.1336","1.39337","0.00078"
"7.2000","0.1413","1.45503","0.00082"
"7.6000","0.1495","1.52436","0.00087"
"8.0000","0.1575","1.59297","0.00091"
"8.4000","0.1654","1.65338","0.00095"
"8.8000","0.1733","1.72052","0.00099"
"9.2000","0.1816","1.78868","0.00103"
"9.6000","0.1896","1.85080","0.00107"
"10.0000","0.1973","1.91332","0.00111"
"10.4000","0.2054","1.97967","0.00115"
"10.8000","0.2134","2.04022","0.00119"
"11.2000","0.2215","2.10495","0.00123"
"11.6000","0.2294","2.16697","0.00127"
"12.0000","0.2376","2.22879","0.00131"
"12.4000","0.2456","2.29292","0.00135"
"12.8000","0.2532","2.34753","0.00138"
"13.2000","0.2615","2.41272","0.00143"
"13.6000","0.2695","2.47524","0.00147"
"14.0000","0.2774","2.53155","0.00150"
"14.4000","0.2853","2.59270","0.00154"
"14.8000","0.2935","2.65401","0.00158"
"15.2000","0.3015","2.71200","0.00162"
"15.6000","0.3094","2.77089","0.00165"
"16.0000","0.3176","2.82791","0.00169"
"16.4000","0.3254","2.88708","0.00173"
"16.8000","0.3334","2.94570","0.00177"
"17.2000","0.3413","2.99997","0.00180"
"17.6000","0.3496","3.06099","0.00184"
"18.0000","0.3575","3.11436","0.00187"
"18.4000","0.3654","3.17118","0.00191"
"18.8000","0.3735","3.23025","0.00195"
"19.2000","0.3814","3.28214","0.00198"
"19.6000","0.3894","3.33939","0.00202"
"20.0000","0.3974","3.39146","0.00206"
"20.4000","0.4056","3.44975","0.00210"
"20.8000","0.4134","3.50041","0.00213"
"21.2000","0.4213","3.55479","0.00216"
"21.6000","0.4296","3.61210","0.00220"
"22.0000","0.4374","3.66086","0.00224"
"22.4000","0.4454","3.71611","0.00227"
"22.8000","0.4534","3.76483","0.00231"
"23.2000","0.4615","3.82070","0.00234"
"23.6000","0.4694","3.87278","0.00238"
"24.0000","0.4774","3.92192","0.00241"
"24.4000","0.4856","3.97701","0.00245"
"24.8000","0.4934","4.02233","0.00248"
"25.2000","0.5014","4.07529","0.00252"
"25.6000","0.5094","4.12209","0.00255"
"26.0000","0.5176","4.17607","0.00259"
"26.4000","0.5255","4.22251","0.00262"
"26.8000","0.5335","4.27247","0.00266"
"27.2000","0.5416","4.32399","0.00269"
"27.6000","0.5493","4.36625","0.00273"
"28.0000","0.5574","4.41730","0.00276"
"28.4000","0.5654","4.45974","0.00279"
"28.8000","0.5735","4.50902","0.00283"
"29.2000","0.5814","4.54899","0.00286"
"29.6000","0.5894","4.59568","0.00290"
"30.0000","0.5976","4.64317","0.00294"
"30.4000","0.6054","4.67916","0.00297"
"30.8000","0.6134","4.72397","0.00301"
"31.2000","0.6214","4.75885","0.00305"
"31.6000","0.6294","4.80205","0.00309"
"32.0000","0.6373","4.84058","0.00313"
"32.4000","0.6455","4.87275","0.00317"
"32.8000","0.6536","4.91191","0.00321"
"33.2000","0.6614","4.94292","0.00325"
"33.6000","0.6695","4.97533","0.00330"
"34.0000","0.6773","5.00552","0.00334"
"34.4000","0.6855","5.03509","0.00339"
"34.8000","0.6934","5.06123","0.00345"
"35.2000","0.7015","5.08535","0.00350"
"35.6000","0.7096","5.10874","0.00356"
"36.0000","0.7173","5.12128","0.00361"
"36.4000","0.7255","5.14080","0.00367"
"36.8000","0.7334","5.15660","0.00374"
"37.2000","0.7415","5.17098","0.00382"
"37.6000","0.7493","5.18240","0.00389"
"38.0000","0.7575","5.19291","0.00397"
"38.4000","0.7655","5.20408","0.00405"
"38.8000","0.7734","5.21001","0.00414"
"39.2000","0.7815","5.21702","0.00422"
"39.6000","0.7894","5.22309","0.00430"
"40.0000","0.7975","5.23003","0.00438"
"40.4000","0.8053","5.23513","0.00447"
"40.8000","0.8135","5.23932","0.00456"
"41.2000","0.8216","5.24434","0.00465"
"41.6000","0.8294","5.24801","0.00473"
"42.0000","0.8375","5.25185","0.00482"
"42.4000","0.8453","5.25455","0.00491"
"42.8000","0.8535","5.25886","0.00501"
"43.2000","0.8614","5.26118","0.00510"
"43.6000","0.8695","5.26397","0.00519"
"44.0000","0.8775","5.26820","0.00528"
"44.4000","0.8854","5.26935","0.00538"
"44.8000","0.8936","5.27240","0.00547"
"45.2000","0.9014","5.27296","0.00556"
"45.6000","0.9096","5.27643","0.00566"
"46.0000","0.9173","5.27758","0.00575"
"46.4000","0.9254","5.27911","0.00585"
"46.8000","0.9335","5.28341","0.00594"
"47.2000","0.9415","5.28368","0.00604"
"47.6000","0.9495","5.28520","0.00613"
"48.0000","0.9574","5.28586","0.00623"
"48.4000","0.9655","5.28872","0.00633"
"48.8000","0.9733","5.28948","0.00642"
"49.2000","0.9815","5.29105","0.00652"
"49.6000","0.9895","5.29376","0.00662"
"50.0000","0.9976","5.29472","0.00671"
"50.4000","1.0055","5.29580","0.00681"
"50.8000","1.0133","5.29545","0.00691"
"51.2000","1.0216","5.29908","0.00700"
"51.6000","1.0294","5.29866","0.00710"
"52.0000","1.0374","5.29957","0.00720"
"52.4000","1.0455","5.30288","0.00729"
"52.8000","1.0534","5.30337","0.00739"
"53.2000","1.0615","5.30461","0.00749"
"53.6000","1.0694","5.30434","0.00759"
"54.0000","1.0775","5.30697","0.00768"
"54.4000","1.0854","5.30668","0.00778"
"54.8000","1.0934","5.30788","0.00788"
"55.2000","1.1014","5.31061","0.00798"
"55.6000","1.1096","5.31157","0.00807"
"56.0000","1.1175","5.31222","0.00817"
"56.4000","1.1254","5.31167","0.00827"
"56.8000","1.1335","5.31487","0.00837"
"57.2000","1.1413","5.31394","0.00846"
"57.6000","1.1495","5.31547","0.00856"
"58.0000","1.1575","5.31777","0.00866"
"58.4000","1.1655","5.31804","0.00876"
"58.8000","1.1736","5.31948","0.00886"
"59.2000","1.1814","5.31929","0.00895"
"59.6000","1.1896","5.32200","0.00906"
"60.0000","1.1974","5.32133","0.00915"
"60.4000","1.2055","5.32241","0.00925"
"60.8000","1.2134","5.32424","0.00935"
"61.2000","1.2215","5.32532","0.00945"
"61.6000","1.2295","5.32640","0.00954"
"62.0000","1.2375","5.32622","0.00964"
"62.4000","1.2456","5.32916","0.00974"
"62.8000","1.2533","5.32724","0.00984"
"63.2000","1.2615","5.32925","0.00994"
"63.6000","1.2694","5.33137","0.01003"
"64.0000","1.2775","5.33165","0.01013"
"64.4000","1.2856","5.33322","0.01023"
"64.8000","1.2935","5.33316","0.01033"
"65.2000","1.3015","5.33538","0.01043"
"65.6000","1.3093","5.33443","0.01052"
"66.0000","1.3175","5.33608","0.01062"
"66.4000","1.3255","5.33789","0.01072"
"66.8000","1.3334","5.33815","0.01082"
"67.2000","1.3415","5.33907","0.01091"
"67.6000","1.3495","5.34052","0.01101"
"68.0000","1.3575","5.34234","0.01111"
"68.4000","1.3653","5.34042","0.01121"
"68.8000","1.3736","5.34341","0.01131"
"69.2000","1.3813","5.34388","0.01140"
"69.6000","1.3894","5.34410","0.01150"
"70.0000","1.3975","5.34678","0.01160"
"70.4000","1.4055","5.34704","0.01169"
"70.8000","1.4136","5.34868","0.01179"
"71.2000","1.4213","5.34711","0.01189"
"71.6000","1.4295","5.34935","0.01199"
"72.0000","1.4374","5.35098","0.01208"
"72.4000","1.4454","5.35115","0.01218"
"72.8000","1.4535","5.35246","0.01227"
"73.2000","1.4616","5.35436","0.01237"
"73.6000","1.4694","5.35478","0.01247"
"74.0000","1.4773","5.35370","0.01256"
"74.4000","1.4856","5.35719","0.01267"
"74.8000","1.4934","5.34873","0.01275"
"75.2000","1.5014","5.35434","0.01283"
"75.6000","1.5095","5.35993","0.01292"
"76.0000","1.5175","5.36124","0.01302"
"76.4000","1.5254","5.36216","0.01311"
"76.8000","1.5334","5.36083","0.01321"
"77.2000","1.5416","5.36341","0.01331"
"77.6000","1.5493","5.34874","0.01336"
"78.0000","1.5573","5.36237","0.01345"
"78.4000","1.5655","5.36713","0.01355"
"78.8000","1.5736","5.36845","0.01364"
"79.2000","1.5815","5.36838","0.01374"
"79.6000","1.5894","5.36744","0.01383"
"80.0000","1.5976","5.37012","0.01393"
"80.4000","1.6053","5.36931","0.01402"
"80.8000","1.6134","5.37014","0.01412"
"81.2000","1.6216","5.37247","0.01421"
"81.6000","1.6296","5.37342","0.01431"
"82.0000","1.6374","5.37343","0.01440"
"82.4000","1.6454","5.37372","0.01450"
"82.8000","1.6537","5.37689","0.01460"
"83.2000","1.6613","5.37549","0.01469"
"83.6000","1.6694","5.37629","0.01478"
"84.0000","1.6775","5.37861","0.01488"
"84.4000","1.6855","5.37970","0.01497"
"84.8000","1.6934","5.38026","0.01507"
"85.2000","1.7015","5.38041","0.01517"
"85.6000","1.7097","5.38370","0.01526"
"86.0000","1.7172","5.38150","0.01535"
"86.4000","1.7253","5.38260","0.01545"
"86.8000","1.7335","5.38566","0.01554"
"87.2000","1.7416","5.38658","0.01564"
"87.6000","1.7494","5.38648","0.01573"
"88.0000","1.7575","5.38729","0.01583"
"88.4000","1.7657","5.39003","0.01592"
"88.8000","1.7732","5.38812","0.01601"
"89.2000","1.7814","5.39003","0.01611"
"89.6000","1.7895","5.39192","0.01620"
"90.0000","1.7975","5.39304","0.01630"
"90.4000","1.8053","5.39295","0.01639"
"90.8000","1.8134","5.39405","0.01649"
"91.2000","1.8217","5.39773","0.01658"
"91.6000","1.8293","5.39468","0.01667"
"92.0000","1.8374","5.39626","0.01677"
"92.4000","1.8455","5.39875","0.01686"
"92.8000","1.8535","5.39899","0.01696"
"93.2000","1.8613","5.39960","0.01705"
"93.6000","1.8696","5.40151","0.01715"
"94.0000","1.8777","5.40378","0.01724"
"94.4000","1.8852","5.40101","0.01733"
"94.8000","1.8934","5.40337","0.01743"
"95.2000","1.9014","5.40535","0.01752"
"95.6000","1.9095","5.40638","0.01762"
"96.0000","1.9174","5.40626","0.01771"
"96.4000","1.9256","5.40785","0.01780"
"96.8000","1.9337","5.41034","0.01790"
"97.2000","1.9412","5.40750","0.01799"
"97.6000","1.9495","5.41034","0.01808"
"98.0000","1.9575","5.41218","0.01818"
"98.4000","1.9655","5.41196","0.01827"
"98.8000","1.9734","5.41264","0.01836"
"99.2000","1.9815","5.41498","0.01846"
"99.6000","1.9896","5.41711","0.01855"
"100.0000","1.9973","5.41478","0.01864"
"100.4000","2.0055","5.41695","0.01873"
"100.8000","2.0135","5.41810","0.01883"
"101.2000","2.0214","5.41868","0.01892"
"101.6000","2.0293","5.41954","0.01901"
"102.0000","2.0376","5.42174","0.01911"
"102.4000","2.0457","5.42355","0.01920"
"102.8000","2.0533","5.42105","0.01929"
"103.2000","2.0615","5.42385","0.01938"
"103.6000","2.0694","5.42510","0.01948"
"104.0000","2.0774","5.42536","0.01957"
"104.4000","2.0854","5.42611","0.01966"
"104.8000","2.0936","5.42834","0.01975"
"105.2000","2.1015","5.42931","0.01985"
"105.6000","2.1093","5.42800","0.01994"
"106.0000","2.1176","5.43130","0.02003"
"106.4000","2.1255","5.43127","0.02012"
"106.8000","2.1334","5.43158","0.02022"
"107.2000","2.1414","5.43259","0.02031"
"107.6000","2.1495","5.43463","0.02040"
"108.0000","2.1575","5.43662","0.02049"
"108.4000","2.1654","5.43478","0.02059"
"108.8000","2.1736","5.43750","0.02068"
"109.2000","2.1814","5.43780","0.02077"
"109.6000","2.1894","5.43798","0.02086"
"110.0000","2.1974","5.43938","0.02095"
"110.4000","2.2056","5.44178","0.02105"
"110.8000","2.2135","5.44225","0.02114"
"111.2000","2.2214","5.44155","0.02123"
"111.6000","2.2296","5.44424","0.02133"
"112.0000","2.2373","5.44374","0.02141"
"112.4000","2.2455","5.44513","0.02151"
"112.8000","2.2534","5.44572","0.02160"
"113.2000","2.2616","5.44768","0.02169"
"113.6000","2.2695","5.44874","0.02178"
"114.0000","2.2774","5.44799","0.02188"
"114.4000","2.2856","5.45142","0.02197"
"114.8000","2.2934","5.45053","0.02206"
"115.2000","2.3014","5.45107","0.02215"
"115.6000","2.3094","5.45230","0.02224"
"116.0000","2.3175","5.45399","0.02233"
"116.4000","2.3254","5.45498","0.02243"
"116.8000","2.3335","5.45546","0.02252"
"117.2000","2.3417","5.45756","0.02261"
"117.6000","2.3494","5.45645","0.02270"
"118.0000","2.3574","5.45771","0.02280"
"118.4000","2.3653","5.45847","0.02289"
"118.8000","2.3735","5.46086","0.02298"
"119.2000","2.3814","5.46114","0.02307"
"119.6000","2.3895","5.46160","0.02316"
"120.0000","2.3976","5.46439","0.02325"
"120.4000","2.4053","5.46296","0.02334"
"120.8000","2.4135","5.46440","0.02343"
"121.2000","2.4215","5.46556","0.02353"
"121.6000","2.4295","5.46678","0.02362"
"122.0000","2.4374","5.46701","0.02371"
"122.4000","2.4455","5.46800","0.02381"
"122.8000","2.4536","5.47072","0.02390"
"123.2000","2.4614","5.46953","0.02399"
"123.6000","2.4695","5.47107","0.02408"
"124.0000","2.4774","5.47120","0.02417"
"124.4000","2.4854","5.47291","0.02426"
"124.8000","2.4933","5.47383","0.02435"
"125.2000","2.5016","5.47491","0.02444"
"125.6000","2.5097","5.47700","0.02454"
"126.0000","2.5174","5.47586","0.02463"
"126.4000","2.5255","5.47709","0.02472"
"126.8000","2.5334","5.47754","0.02481"
"127.2000","2.5415","5.47958","0.02490"
"127.6000","2.5494","5.47958","0.02499"
"128.0000","2.5575","5.48098","0.02508"
"128.4000","2.5656","5.48283","0.02517"
"128.8000","2.5734","5.48227","0.02526"
"129.2000","2.5815","5.48433","0.02535"
"129.6000","2.5894","5.48388","0.02544"
"130.0000","2.5975","5.48559","0.02553"
"130.4000","2.6054","5.48573","0.02562"
"130.8000","2.6134","5.48669","0.02571"
"131.2000","2.6216","5.48187","0.02579"
"131.6000","2.6294","5.48749","0.02587"
"132.0000","2.6375","5.49020","0.02596"
"132.4000","2.6454","5.49049","0.02605"
"132.8000","2.6535","5.49220","0.02614"
"133.2000","2.6613","5.49210","0.02623"
"133.6000","2.6695","5.49380","0.02633"
"134.0000","2.6776","5.49546","0.02642"
"134.4000","2.6855","5.49510","0.02651"
"134.8000","2.6935","5.49628","0.02660"
"135.2000","2.7013","5.49556","0.02669"
"135.6000","2.7095","5.49829","0.02678"
"136.0000","2.7174","5.49791","0.02687"
"136.4000","2.7255","5.49884","0.02696"
"136.8000","2.7335","5.50127","0.02705"
"137.2000","2.7414","5.50106","0.02714"
"137.6000","2.7495","5.50256","0.02723"
"138.0000","2.7574","5.50198","0.02732"
"138.4000","2.7655","5.50386","0.02742"
"138.8000","2.7734","5.50387","0.02751"
"139.2000","2.7814","5.50465","0.02760"
"139.6000","2.7895","5.50714","0.02768"
"140.0000","2.7976","5.50782","0.02778"
"140.4000","2.8056","5.50836","0.02787"
"140.8000","2.8133","5.50738","0.02796"
"141.2000","2.8215","5.51020","0.02805"
"141.6000","2.8293","5.50946","0.02814"
"142.0000","2.8375","5.51091","0.02823"
"142.4000","2.8455","5.51293","0.02832"
"142.8000","2.8535","5.51313","0.02841"
"143.2000","2.8615","5.51396","0.02850"
"143.6000","2.8693","5.51351","0.02860"
"144.0000","2.8775","5.51621","0.02869"
"144.4000","2.8854","5.51564","0.02878"
"144.8000","2.8935","5.51659","0.02887"
"145.2000","2.9015","5.51832","0.02896"
"145.6000","2.9095","5.51932","0.02905"
"146.0000","2.9175","5.52028","0.02914"
"146.4000","2.9254","5.51935","0.02923"
"146.8000","2.9336","5.52221","0.02932"
"147.2000","2.9413","5.52105","0.02941"
"147.6000","2.9494","5.52205","0.02950"
"148.0000","2.9574","5.52433","0.02959"
"148.4000","2.9655","5.52505","0.02968"
"148.8000","2.9735","5.52561","0.02977"
"149.2000","2.9814","5.52541","0.02986"
"149.6000","2.9895","5.52779","0.02995"
"150.0000","2.9973","5.52666","0.03004"
"150.4000","3.0055","5.52859","0.03013"
"150.8000","3.0134","5.52961","0.03022"
"151.2000","3.0215","5.53056","0.03032"
"151.6000","3.0295","5.53124","0.03041"
"152.0000","3.0374","5.53097","0.03050"
"152.4000","3.0456","5.53384","0.03059"
"152.8000","3.0533","5.53235","0.03067"
"153.2000","3.0615","5.53381","0.03077"
"153.6000","3.0694","5.53533","0.03086"
"154.0000","3.0774","5.53571","0.03095"
"154.4000","3.0855","5.53746","0.03104"
"154.8000","3.0935","5.53731","0.03113"
"155.2000","3.1016","5.53898","0.03122"
"155.6000","3.1094","5.53776","0.03131"
"156.0000","3.1175","5.53951","0.03140"
"156.4000","3.1253","5.54056","0.03149"
"156.8000","3.1335","5.54148","0.03159"
"157.2000","3.1415","5.54254","0.03168"
"157.6000","3.1495","5.54294","0.03177"
"158.0000","3.1575","5.54456","0.03186"
"158.4000","3.1653","5.54282","0.03194"
"158.8000","3.1736","5.54568","0.03204"
"159.2000","3.1814","5.54640","0.03213"
"159.6000","3.1894","5.54623","0.03222"
"160.0000","3.1975","5.54790","0.03231"
"160.4000","3.2055","5.54870","0.03240"
"160.8000","3.2135","5.54996","0.03249"
"161.2000","3.2214","5.54870","0.03258"
"161.6000","3.2296","5.55091","0.03267"
"162.0000","3.2374","5.55098","0.03276"
"162.4000","3.2453","5.55147","0.03285"
"162.8000","3.2535","5.55342","0.03294"
"163.2000","3.2616","5.54321","0.03300"
"163.6000","3.2695","5.55310","0.03309"
"164.0000","3.2773","5.55402","0.03317"
"164.4000","3.2856","5.55708","0.03326"
"164.8000","3.2933","5.55719","0.03335"
"165.2000","3.3014","5.55749","0.03344"
"165.6000","3.3096","5.55942","0.03353"
"166.0000","3.3176","5.56011","0.03362"
"166.4000","3.3254","5.55995","0.03371"
"166.8000","3.3333","5.55943","0.03380"
"167.2000","3.3416","5.56242","0.03390"
"167.6000","3.3494","5.56136","0.03398"
"168.0000","3.3574","5.56177","0.03408"
"168.4000","3.3655","5.56343","0.03417"
"168.8000","3.3736","5.56479","0.03426"
"169.2000","3.3814","5.56498","0.03435"
"169.6000","3.3894","5.56422","0.03444"
"170.0000","3.3977","5.56750","0.03453"
"170.4000","3.4053","5.56575","0.03462"
"170.8000","3.4133","5.56621","0.03471"
"171.2000","3.4215","5.56916","0.03480"
"171.6000","3.4296","5.57000","0.03489"
"172.0000","3.4375","5.56969","0.03498"
"172.4000","3.4454","5.56951","0.03507"
"172.8000","3.4536","5.57193","0.03516"
"173.2000","3.4613","5.57085","0.03525"
"173.6000","3.4694","5.57178","0.03534"
"174.0000","3.4775","5.57331","0.03543"
"174.4000","3.4856","5.57506","0.03552"
"174.8000","3.4933","5.57430","0.03561"
"175.2000","3.5014","5.57451","0.03570"
"175.6000","3.5097","5.57814","0.03580"
"176.0000","3.5173","5.57542","0.03589"
"176.4000","3.5254","5.57636","0.03598"
"176.8000","3.5335","5.57854","0.03607"
"177.2000","3.5415","5.57869","0.03616"
"177.6000","3.5494","5.57951","0.03625"
"178.0000","3.5575","5.58004","0.03634"
"178.4000","3.5657","5.58217","0.03643"
"178.8000","3.5733","5.58010","0.03652"
"179.2000","3.5813","5.58121","0.03661"
"179.6000","3.5895","5.58310","0.03670"
"180.0000","3.5976","5.58454","0.03679"
"180.4000","3.6054","5.58360","0.03688"
"180.8000","3.6135","5.58464","0.03698"
"181.2000","3.6217","5.58722","0.03706"
"181.6000","3.6292","5.58389","0.03715"
"182.0000","3.6375","5.58667","0.03725"
"182.4000","3.6455","5.58822","0.03734"
"182.8000","3.6535","5.58777","0.03743"
"183.2000","3.6614","5.58850","0.03752"
"183.6000","3.6695","5.58958","0.03761"
"184.0000","3.6777","5.59192","0.03770"
"184.4000","3.6853","5.58941","0.03779"
"184.8000","3.6934","5.59075","0.03788"
"185.2000","3.7015","5.59249","0.03797"
"185.6000","3.7094","5.59243","0.03806"
"186.0000","3.7173","5.59259","0.03815"
"186.4000","3.7256","5.59501","0.03824"
"186.8000","3.7336","5.59626","0.03834"
"187.2000","3.7412","5.59313","0.03843"
"187.6000","3.7495","5.59604","0.03852"
"188.0000","3.7574","5.59671","0.03861"
"188.4000","3.7655","5.59715","0.03870"
"188.8000","3.7734","5.59734","0.03879"
"189.2000","3.7816","5.59927","0.03888"
"189.6000","3.7896","5.60056","0.03897"
"190.0000","3.7972","5.59789","0.03906"
"190.4000","3.8055","5.60069","0.03915"
"190.8000","3.8135","5.60142","0.03924"
"191.2000","3.8214","5.60120","0.03934"
"191.6000","3.8293","5.60148","0.03943"
"192.0000","3.8376","5.60364","0.03952"
"192.4000","3.8456","5.60518","0.03961"
"192.8000","3.8533","5.60249","0.03970"
"193.2000","3.8615","5.60488","0.03979"
"193.6000","3.8695","5.60549","0.03988"
"194.0000","3.8774","5.60520","0.03997"
"194.4000","3.8853","5.60592","0.04006"
"194.8000","3.8936","5.60863","0.04016"
"195.2000","3.9016","5.60901","0.04025"
"195.6000","3.9093","5.60681","0.04034"
"196.0000","3.9175","5.60928","0.04043"
"196.4000","3.9254","5.60920","0.04052"
"196.8000","3.9335","5.61010","0.04061"
"197.2000","3.9414","5.61006","0.04070"
"197.6000","3.9496","5.61204","0.04079"
"198.0000","3.9575","5.61282","0.04088"
"198.4000","3.9653","5.61083","0.04097"
"198.8000","3.9736","5.61406","0.04107"
"199.2000","3.9814","5.61366","0.04116"
"199.6000","3.9894","5.61335","0.04125"
"200.0000","3.9974","5.61439","0.04134"
"200.4000","4.0055","5.61579","0.04143"
"200.8000","4.0135","5.61664","0.04152"
"201.2000","4.0214","5.61588","0.04161"
"201.6000","4.0296","5.61790","0.04171"
"202.0000","4.0374","5.61687","0.04180"
"202.4000","4.0454","5.61750","0.04189"
"202.8000","4.0533","5.61804","0.04198"
"203.2000","4.0616","5.62010","0.04207"
"203.6000","4.0695","5.62022","0.04216"
"204.0000","4.0774","5.61947","0.04225"
"204.4000","4.0856","5.62216","0.04234"
"204.8000","4.0933","5.62063","0.04243"
"205.2000","4.1014","5.62181","0.04252"
"205.6000","4.1095","5.62260","0.04262"
"206.0000","4.1176","5.62373","0.04271"
"206.4000","4.1254","5.62358","0.04280"
"206.8000","4.1334","5.62376","0.04289"
"207.2000","4.1416","5.62629","0.04299"
"207.6000","4.1494","5.62454","0.04308"
"208.0000","4.1575","5.62551","0.04317"
"208.4000","4.1654","5.62561","0.04326"
"208.8000","4.1735","5.62719","0.04335"
"209.2000","4.1814","5.62777","0.04344"
"209.6000","4.1895","5.61267","0.04352"
"210.0000","4.1976","5.62446","0.04360"
"210.4000","4.2054","5.62757","0.04369"
"210.8000","4.2135","5.62950","0.04378"
"211.2000","4.2214","5.63025","0.04387"
"211.6000","4.2296","5.63179","0.04396"
"212.0000","4.2374","5.63131","0.04405"
"212.4000","4.2455","5.63187","0.04415"
"212.8000","4.2536","5.63357","0.04424"
"213.2000","4.2613","5.63203","0.04433"
"213.6000","4.2695","5.63373","0.04442"
"214.0000","4.2774","5.63329","0.04451"
"214.4000","4.2855","5.63438","0.04461"
"214.8000","4.2934","5.63440","0.04470"
"215.2000","4.3015","5.63474","0.04479"
"215.6000","4.3096","5.63712","0.04488"
"216.0000","4.3174","5.63562","0.04497"
"216.4000","4.3255","5.63655","0.04506"
"216.8000","4.3334","5.63638","0.04515"
"217.2000","4.3415","5.63751","0.04525"
"217.6000","4.3493","5.63751","0.04534"
"218.0000","4.3576","5.63877","0.04543"
"218.4000","4.3656","5.64018","0.04552"
"218.8000","4.3734","5.63880","0.04561"
"219.2000","4.3815","5.63999","0.04570"
"219.6000","4.3893","5.63924","0.04580"
"220.0000","4.3975","5.64125","0.04589"
"220.4000","4.4054","5.64093","0.04598"
"220.8000","4.4135","5.64132","0.04607"
"221.2000","4.4216","5.64327","0.04617"
"221.6000","4.4294","5.64231","0.04626"
"222.0000","4.4375","5.64353","0.04635"
"222.4000","4.4454","5.64299","0.04644"
"222.8000","4.4535","5.64426","0.04653"
"223.2000","4.4614","5.64388","0.04663"
"223.6000","4.4695","5.64462","0.04672"
"224.0000","4.4775","5.64643","0.04681"
"224.4000","4.4855","5.64615","0.04690"
"224.8000","4.4936","5.64689","0.04700"
"225.2000","4.5013","5.64552","0.04709"
"225.6000","4.5095","5.64761","0.04718"
"226.0000","4.5173","5.64701","0.04727"
"226.4000","4.5255","5.64789","0.04737"
"226.8000","4.5336","5.64967","0.04746"
"227.2000","4.5415","5.64888","0.04755"
"227.6000","4.5495","5.64976","0.04764"
"228.0000","4.5573","5.64869","0.04774"
"228.4000","4.5655","5.65073","0.04783"
"228.8000","4.5734","5.65010","0.04792"
"229.2000","4.5815","5.65071","0.04801"
"229.6000","4.5895","5.65206","0.04811"
"230.0000","4.5975","5.65227","0.04820"
"230.4000","4.6055","5.65313","0.04829"
"230.8000","4.6134","5.65169","0.04839"
"231.2000","4.6216","5.65385","0.04848"
"231.6000","4.6293","5.65251","0.04857"
"232.0000","4.6374","5.65317","0.04866"
"232.4000","4.6455","5.65539","0.04876"
"232.8000","4.6536","5.65537","0.04885"
"233.2000","4.6616","5.65544","0.04895"
"233.6000","4.6694","5.65456","0.04903"
"234.0000","4.6775","5.65652","0.04913"
"234.4000","4.6853","5.65564","0.04922"
"234.8000","4.6935","5.65663","0.04931"
"235.2000","4.7015","5.65757","0.04941"
"235.6000","4.7095","5.65810","0.04950"
"236.0000","4.7175","5.65819","0.04959"
"236.4000","4.7253","5.65710","0.04969"
"236.8000","4.7336","5.65991","0.04978"
"237.2000","4.7414","5.65825","0.04987"
"237.6000","4.7495","5.65893","0.04997"
"238.0000","4.7574","5.66009","0.05006"
"238.4000","4.7654","5.66020","0.05015"
"238.8000","4.7735","5.66144","0.05025"
"239.2000","4.7815","5.66045","0.05034"
"239.6000","4.7896","5.66215","0.05043"
"240.0000","4.7973","5.66067","0.05052"
"240.4000","4.8055","5.66169","0.05062"
"240.8000","4.8134","5.66271","0.05071"
"241.2000","4.8215","5.66337","0.05080"
"241.6000","4.8295","5.66363","0.05090"
"242.0000","4.8375","5.66293","0.05099"
"242.4000","4.8455","5.66476","0.05109"
"242.8000","4.8532","5.66275","0.05118"
"243.2000","4.8615","5.66465","0.05127"
"243.6000","4.8695","5.66540","0.05137"
"244.0000","4.8775","5.66515","0.05146"
"244.4000","4.8855","5.66579","0.05155"
"244.8000","4.8934","5.66570","0.05165"
"245.2000","4.9016","5.66742","0.05174"
"245.6000","4.9094","5.66556","0.05183"
"246.0000","4.9175","5.66683","0.05193"
"246.4000","4.9254","5.66710","0.05202"
"246.8000","4.9334","5.66754","0.05211"
"247.2000","4.9415","5.66861","0.05221"
"247.6000","4.9495","5.66853","0.05230"
"248.0000","4.9576","5.66973","0.05240"
"248.4000","4.9653","5.66739","0.05249"
"248.8000","4.9735","5.66927","0.05258"
"249.2000","4.9813","5.66942","0.05268"
"249.6000","4.9894","5.66963","0.05277"
"250.0000","4.9976","5.67093","0.05287"
"250.4000","5.0055","5.67093","0.05296"
"250.8000","5.0135","5.67124","0.05305"
"251.2000","5.0213","5.66993","0.05315"
"251.6000","5.0296","5.67206","0.05325"
"252.0000","5.0374","5.67144","0.05334"
"252.4000","5.0454","5.67158","0.05343"
"252.8000","5.0535","5.67260","0.05352"
"253.2000","5.0615","5.67307","0.05362"
"253.6000","5.0695","5.67381","0.05371"
"254.0000","5.0773","5.67217","0.05381"
"254.4000","5.0856","5.67450","0.05390"
"254.8000","5.0933","5.67339","0.05399"
"255.2000","5.1013","5.67302","0.05409"
"255.6000","5.1095","5.67533","0.05419"
"256.0000","5.1176","5.67592","0.05428"
"256.4000","5.1255","5.67529","0.05437"
"256.8000","5.1334","5.67428","0.05447"
"257.2000","5.1416","5.67643","0.05456"
"257.6000","5.1493","5.67494","0.05465"
"258.0000","5.1574","5.67565","0.05475"
"258.4000","5.1655","5.67677","0.05485"
"258.8000","5.1736","5.67747","0.05494"
"259.2000","5.1814","5.67718","0.05504"
"259.6000","5.1893","5.67599","0.05513"
"260.0000","5.1977","5.67917","0.05522"
"260.4000","5.2054","5.67731","0.05532"
"260.8000","5.2134","5.67704","0.05541"
"261.2000","5.2215","5.67895","0.05551"
"261.6000","5.2295","5.67936","0.05560"
"262.0000","5.2374","5.67896","0.05570"
"262.4000","5.2454","5.67854","0.05579"
"262.8000","5.2537","5.68083","0.05589"
"263.2000","5.2613","5.67842","0.05598"
"263.6000","5.2694","5.67912","0.05608"
"264.0000","5.2775","5.68068","0.05617"
"264.4000","5.2856","5.68149","0.05627"
"264.8000","5.2935","5.68085","0.05636"
"265.2000","5.3014","5.68024","0.05646"
"265.6000","5.3097","5.68288","0.05656"
"266.0000","5.3172","5.67992","0.05665"
"266.4000","5.3254","5.68088","0.05674"
"266.8000","5.3336","5.68277","0.05684"
"267.2000","5.3415","5.68243","0.05694"
"267.6000","5.3494","5.68183","0.05703"
"268.0000","5.3574","5.68231","0.05713"
"268.4000","5.3657","5.68474","0.05722"
"268.8000","5.3733","5.68175","0.05732"
"269.2000","5.3814","5.68269","0.05741"
"269.6000","5.3895","5.68382","0.05751"
"270.0000","5.3975","5.68412","0.05761"
"270.4000","5.4053","5.68363","0.05770"
"270.8000","5.4135","5.68431","0.05780"
"271.2000","5.4217","5.68661","0.05789"
"271.6000","5.4292","5.68269","0.05799"
"272.0000","5.4374","5.68400","0.05808"
"272.4000","5.4455","5.68558","0.05818"
"272.8000","5.4535","5.68569","0.05828"
"273.2000","5.4614","5.68486","0.05837"
"273.6000","5.4696","5.68596","0.05847"
"274.0000","5.4776","5.68726","0.05856"
"274.4000","5.4852","5.68424","0.05866"
"274.8000","5.4934","5.68632","0.05876"
"275.2000","5.5015","5.68716","0.05885"
"275.6000","5.5095","5.68691","0.05895"
"276.0000","5.5174","5.68631","0.05904"
"276.4000","5.5255","5.68729","0.05914"
"276.8000","5.5337","5.68951","0.05924"
"277.2000","5.5413","5.68579","0.05933"
"277.6000","5.5495","5.68757","0.05943"
"278.0000","5.5575","5.68855","0.05953"
"278.4000","5.5654","5.68766","0.05962"
"278.8000","5.5733","5.68773","0.05972"
"279.2000","5.5816","5.68970","0.05982"
"279.6000","5.5897","5.69016","0.05991"
"280.0000","5.5973","5.68707","0.06001"
"280.4000","5.6055","5.68916","0.06011"
"280.8000","5.6134","5.68913","0.06020"
"281.2000","5.6215","5.68987","0.06030"
"281.6000","5.6294","5.68877","0.06040"
"282.0000","5.6376","5.69027","0.06049"
"282.4000","5.6456","5.69141","0.06059"
"282.8000","5.6532","5.68803","0.06069"
"283.2000","5.6616","5.69079","0.06079"
"283.6000","5.6695","5.69072","0.06088"
"284.0000","5.6774","5.68965","0.06098"
"284.4000","5.6854","5.69026","0.06108"
"284.8000","5.6935","5.69168","0.06117"
"285.2000","5.7015","5.69209","0.06127"
"285.6000","5.7094","5.69011","0.06137"
"286.0000","5.7176","5.69183","0.06146"
"286.4000","5.7255","5.69105","0.06156"
"286.8000","5.7334","5.69092","0.06166"
"287.2000","5.7413","5.69061","0.06175"
"287.6000","5.7496","5.69310","0.06185"
"288.0000","5.7575","5.69280","0.06195"
"288.4000","5.7653","5.69071","0.06205"
"288.8000","5.7736","5.69343","0.06215"
"289.2000","5.7813","5.69189","0.06224"
"289.6000","5.7894","5.69215","0.06234"
"290.0000","5.7974","5.69245","0.06244"
"290.4000","5.8056","5.69335","0.06254"
"290.8000","5.8135","5.69362","0.06264"
"291.2000","5.8213","5.69206","0.06273"
"291.6000","5.8296","5.69439","0.06283"
"292.0000","5.8375","5.69356","0.06293"
"292.4000","5.8454","5.69286","0.06303"
"292.8000","5.8533","5.69251","0.06313"
"293.2000","5.8616","5.69444","0.06322"
"293.6000","5.8694","5.69423","0.06332"
"294.0000","5.8774","5.69330","0.06342"
"294.4000","5.8857","5.69579","0.06352"
"294.8000","5.8934","5.69344","0.06361"
"295.2000","5.9014","5.69362","0.06372"
"295.6000","5.9094","5.69393","0.06381"
"296.0000","5.9175","5.69510","0.06391"
"296.4000","5.9255","5.69526","0.06401"
"296.8000","5.9334","5.69430","0.06411"
"297.2000","5.9416","5.69565","0.06421"
"297.6000","5.9494","5.69457","0.06430"
"298.0000","5.9574","5.69494","0.06440"
"298.4000","5.9654","5.69447","0.06450"
"298.8000","5.9736","5.69598","0.06460"
"299.2000","5.9814","5.69511","0.06470"
"299.6000","5.9895","5.69494","0.06480"
"300.0000","5.9976","5.69716","0.06490"
"300.4000","6.0054","5.69473","0.06499"
"300.8000","6.0135","5.69549","0.06510"
"301.2000","6.0214","5.69491","0.06519"
"301.6000","6.0295","5.69593","0.06529"
"302.0000","6.0374","5.69614","0.06539"
"302.4000","6.0455","5.69614","0.06549"
"302.8000","6.0536","5.69736","0.06559"
"303.2000","6.0614","5.69561","0.06569"
"303.6000","6.0695","5.69604","0.06579"
"304.0000","6.0773","5.69562","0.06588"
"304.4000","6.0855","5.69711","0.06599"
"304.8000","6.0934","5.69623","0.06608"
"305.2000","6.1015","5.69635","0.06618"
"305.6000","6.1096","5.69782","0.06628"
"306.0000","6.1173","5.69603","0.06639"
"306.4000","6.1255","5.69745","0.06648"
"306.8000","6.1334","5.69645","0.06658"
"307.2000","6.1415","5.69723","0.06668"
"307.6000","6.1494","5.69654","0.06678"
"308.0000","6.1575","5.69670","0.06688"
"308.4000","6.1656","5.69837","0.06699"
"308.8000","6.1735","5.69703","0.06708"
"309.2000","6.1815","5.69765","0.06719"
"309.6000","6.1894","5.69618","0.06728"
"310.0000","6.1975","5.69756","0.06738"
"310.4000","6.2053","5.69697","0.06748"
"310.8000","6.2135","5.69742","0.06759"
"311.2000","6.2216","5.69897","0.06769"
"311.6000","6.2294","5.69707","0.06779"
"312.0000","6.2375","5.69776","0.06789"
"312.4000","6.2453","5.69666","0.06799"
"312.8000","6.2535","5.69804","0.06809"
"313.2000","6.2614","5.69738","0.06819"
"313.6000","6.2695","5.69766","0.06829"
"314.0000","6.2775","5.69865","0.06839"
"314.4000","6.2855","5.69804","0.06849"
"314.8000","6.2935","5.69871","0.06859"
"315.2000","6.3014","5.69727","0.06869"
"315.6000","6.3096","5.69871","0.06880"
"316.0000","6.3173","5.69712","0.06890"
"316.4000","6.3254","5.69746","0.06900"
"316.8000","6.3335","5.69936","0.06910"
"317.2000","6.3415","5.69836","0.06920"
"317.6000","6.3495","5.69856","0.06930"
"318.0000","6.3574","5.69712","0.06940"
"318.4000","6.3655","5.69848","0.06951"
"318.8000","6.3733","5.69736","0.06961"
"319.2000","6.3815","5.69834","0.06971"
"319.6000","6.3895","5.69928","0.06981"
"320.0000","6.3975","5.69868","0.06991"
"320.4000","6.4055","5.69870","0.07002"
"320.8000","6.4133","5.69708","0.07011"
"321.2000","6.4216","5.69938","0.07022"
"321.6000","6.4294","5.69769","0.07032"
"322.0000","6.4375","5.69768","0.07042"
"322.4000","6.4455","5.69890","0.07052"
"322.8000","6.4534","5.69875","0.07063"
"323.2000","6.4615","5.69927","0.07073"
"323.6000","6.4694","5.69773","0.07083"
"324.0000","6.4776","5.69903","0.07094"
"324.4000","6.4854","5.69757","0.07104"
"324.8000","6.4934","5.69788","0.07114"
"325.2000","6.5014","5.69895","0.07124"
"325.6000","6.5096","5.69929","0.07134"
"326.0000","6.5176","5.69906","0.07145"
"326.4000","6.5254","5.69738","0.07155"
"326.8000","6.5336","5.69943","0.07165"
"327.2000","6.5413","5.69731","0.07175"
"327.6000","6.5495","5.69816","0.07186"
"328.0000","6.5575","5.69920","0.07196"
"328.4000","6.5655","5.69851","0.07206"
"328.8000","6.5735","5.69849","0.07217"
"329.2000","6.5814","5.69777","0.07227"
"329.6000","6.5896","5.69945","0.07238"
"330.0000","6.5974","5.69745","0.07248"
"330.4000","6.6055","5.69815","0.07258"
"330.8000","6.6134","5.69830","0.07269"
"331.2000","6.6214","5.69841","0.07279"
"331.6000","6.6295","5.69888","0.07289"
"332.0000","6.6375","5.69777","0.07300"
"332.4000","6.6456","5.69950","0.07311"
"332.8000","6.6533","5.69677","0.07321"
"333.2000","6.6615","5.69763","0.07331"
"333.6000","6.6694","5.69837","0.07341"
"334.0000","6.6775","5.69818","0.07352"
"334.4000","6.6855","5.69854","0.07362"
"334.8000","6.6935","5.69784","0.07373"
"335.2000","6.7015","5.69866","0.07383"
"335.6000","6.7093","5.69691","0.07394"
"336.0000","6.7176","5.69822","0.07404"
"336.4000","6.7254","5.69785","0.07415"
"336.8000","6.7335","5.69775","0.07425"
"337.2000","6.7415","5.69801","0.07436"
"337.6000","6.7495","5.69755","0.07446"
"338.0000","6.7575","5.69895","0.07457"
"338.4000","6.7653","5.69632","0.07467"
"338.8000","6.7736","5.69781","0.07478"
"339.2000","6.7814","5.69729","0.07488"
"339.6000","6.7893","5.69644","0.07499"
"340.0000","6.7975","5.69832","0.07509"
"340.4000","6.8056","5.69801","0.07520"
"340.8000","6.8135","5.69790","0.07531"
"341.2000","6.8213","5.69599","0.07541"
"341.6000","6.8295","5.69749","0.07552"
"342.0000","6.8373","5.69666","0.07562"
"342.4000","6.8454","5.69678","0.07573"
"342.8000","6.8535","5.69720","0.07584"
"343.2000","6.8616","5.69744","0.07594"
"343.6000","6.8694","5.69715","0.07605"
"344.0000","6.8773","5.69534","0.07615"
"344.4000","6.8856","5.69786","0.07626"
"344.8000","6.8934","5.69647","0.07637"
"345.2000","6.9014","5.69579","0.07648"
"345.6000","6.9095","5.69682","0.07658"
"346.0000","6.9175","5.69692","0.07669"
"346.4000","6.9254","5.69664","0.07680"
"346.8000","6.9334","5.69518","0.07690"
"347.2000","6.9416","5.69688","0.07701"
"347.6000","6.9493","5.69523","0.07712"
"348.0000","6.9573","5.69517","0.07722"
"348.4000","6.9655","5.69645","0.07733"
"348.8000","6.9736","5.69686","0.07744"
"349.2000","6.9815","5.69604","0.07755"
"349.6000","6.9894","5.69438","0.07765"
"350.0000","6.9977","5.69683","0.07776"
"350.4000","7.0052","5.69430","0.07787"
"350.8000","7.0134","5.69457","0.07798"
"351.2000","7.0216","5.69605","0.07809"
"351.6000","7.0296","5.69596","0.07819"
"352.0000","7.0374","5.69470","0.07830"
"352.4000","7.0454","5.69409","0.07841"
"352.8000","7.0537","5.69650","0.07852"
"353.2000","7.0613","5.69379","0.07863"
"353.6000","7.0694","5.69362","0.07873"
"354.0000","7.0775","5.69485","0.07884"
"354.4000","7.0855","5.69496","0.07895"
"354.8000","7.0934","5.69440","0.07906"
"355.2000","7.1015","5.69361","0.07917"
"355.6000","7.1097","5.69592","0.07928"
"356.0000","7.1172","5.69236","0.07939"
"356.4000","7.1253","5.69286","0.07949"
"356.8000","7.1335","5.69450","0.07960"
"357.2000","7.1416","5.69453","0.07972"
"357.6000","7.1494","5.69321","0.07982"
"358.0000","7.1575","5.69307","0.07993"
"358.4000","7.1657","5.69461","0.08004"
"358.8000","7.1732","5.69150","0.08015"
"359.2000","7.1814","5.69257","0.08026"
"359.6000","7.1895","5.69331","0.08037"
"360.0000","7.1975","5.69319","0.08048"
"360.4000","7.2053","5.69186","0.08059"
"360.8000","7.2135","5.69217","0.08070"
"361.2000","7.2217","5.69460","0.08082"
"361.6000","7.2293","5.69038","0.08092"
"362.0000","7.2374","5.69115","0.08103"
"362.4000","7.2455","5.69243","0.08114"
"362.8000","7.2534","5.69129","0.08125"
"363.2000","7.2613","5.69119","0.08136"
"363.6000","7.2696","5.69210","0.08148"
"364.0000","7.2777","5.69296","0.08159"
"364.4000","7.2853","5.68931","0.08170"
"364.8000","7.2934","5.69037","0.08181"
"365.2000","7.3014","5.69104","0.08192"
"365.6000","7.3095","5.69103","0.08203"
"366.0000","7.3174","5.68968","0.08214"
"366.4000","7.3256","5.69078","0.08226"
"366.8000","7.3337","5.69211","0.08237"
"367.2000","7.3412","5.68782","0.08248"
"367.6000","7.3495","5.68962","0.08259"
"368.0000","7.3575","5.69016","0.08271"
"368.4000","7.3655","5.68902","0.08282"
"368.8000","7.3733","5.68841","0.08293"
"369.2000","7.3815","5.68975","0.08304"
"369.6000","7.3896","5.69065","0.08315"
"370.0000","7.3973","5.68725","0.08327"
"370.4000","7.4055","5.68847","0.08338"
"370.8000","7.4135","5.68806","0.08349"
"371.2000","7.4214","5.68747","0.08360"
"371.6000","7.4293","5.68728","0.08372"
"372.0000","7.4376","5.68875","0.08383"
"372.4000","7.4456","5.68908","0.08394"
"372.8000","7.4533","5.68551","0.08406"
"373.2000","7.4615","5.68728","0.08417"
"373.6000","7.4694","5.68675","0.08428"
"374.0000","7.4774","5.68620","0.08440"
"374.4000","7.4854","5.68588","0.08451"
"374.8000","7.4936","5.68711","0.08463"
"375.2000","7.5015","5.68656","0.08474"
"375.6000","7.5093","5.68418","0.08485"
"376.0000","7.5176","5.68652","0.08497"
"376.4000","7.5254","5.68509","0.08508"
"376.8000","7.5334","5.68442","0.08520"
"377.2000","7.5413","5.68390","0.08531"
"377.6000","7.5495","5.68501","0.08542"
"378.0000","7.5575","5.68537","0.08554"
"378.4000","7.5654","5.68281","0.08565"
"378.8000","7.5736","5.68448","0.08577"
"379.2000","7.5814","5.68313","0.08588"
"379.6000","7.5894","5.68211","0.08600"
"380.0000","7.5974","5.68233","0.08611"
"380.4000","7.6056","5.68363","0.08623"
"380.8000","7.6135","5.68273","0.08634"
"381.2000","7.6214","5.68114","0.08646"
"381.6000","7.6296","5.68256","0.08657"
"382.0000","7.6373","5.68039","0.08669"
"382.4000","7.6455","5.68108","0.08680"
"382.8000","7.6534","5.68009","0.08691"
"383.2000","7.6616","5.68073","0.08703"
"383.6000","7.6695","5.68024","0.08715"
"384.0000","7.6774","5.67862","0.08726"
"384.4000","7.6856","5.68096","0.08738"
"384.8000","7.6934","5.67835","0.08749"
"385.2000","7.7014","5.67784","0.08761"
"385.6000","7.7094","5.67781","0.08772"
"386.0000","7.7175","5.67802","0.08784"
"386.4000","7.7254","5.67749","0.08795"
"386.8000","7.7335","5.67683","0.08807"
"387.2000","7.7416","5.67775","0.08818"
"387.6000","7.7494","5.67512","0.08830"
"388.0000","7.7574","5.67522","0.08841"
"388.4000","7.7653","5.67459","0.08853"
"388.8000","7.7736","5.67555","0.08864"
"389.2000","7.7814","5.67435","0.08876"
"389.6000","7.7895","5.67337","0.08888"
"390.0000","7.7976","5.67442","0.08899"
"390.4000","7.8053","5.67207","0.08910"
"390.8000","7.8135","5.67218","0.08922"
"391.2000","7.8214","5.67129","0.08933"
"391.6000","7.8295","5.67134","0.08945"
"392.0000","7.8374","5.66966","0.08956"
"392.4000","7.8455","5.66952","0.08968"
"392.8000","7.8536","5.67061","0.08979"
"393.2000","7.8614","5.66765","0.08991"
"393.6000","7.8695","5.66782","0.09002"
"394.0000","7.8774","5.66598","0.09013"
"394.4000","7.8855","5.66624","0.09025"
"394.8000","7.8933","5.66529","0.09036"
"395.2000","7.9015","5.66438","0.09047"
"395.6000","7.9097","5.66518","0.09059"
"396.0000","7.9174","5.66197","0.09070"
"396.4000","7.9255","5.66135","0.09081"
"396.8000","7.9333","5.66009","0.09092"
"397.2000","7.9415","5.65987","0.09104"
"397.6000","7.9494","5.65802","0.09115"
"398.0000","7.9575","5.65719","0.09126"
"398.4000","7.9655","5.65680","0.09137"
"398.8000","7.9734","5.65436","0.09148"
"399.2000","7.9815","5.65401","0.09159"
"399.6000","7.9894","5.65073","0.09170"
"400.0000","7.9976","5.65110","0.09181"
"400.4000","8.0053","5.64800","0.09192"
"400.8000","8.0134","5.64663","0.09203"
"401.2000","8.0216","5.64720","0.09215"
"401.6000","8.0294","5.64309","0.09226"
"402.0000","8.0376","5.64167","0.09237"
"402.4000","8.0453","5.63814","0.09247"
"402.8000","8.0534","5.63704","0.09258"
"403.2000","8.0614","5.63478","0.09269"
"403.6000","8.0695","5.63218","0.09281"
"404.0000","8.0776","5.63058","0.09291"
"404.4000","8.0855","5.62729","0.09302"
"404.8000","8.0935","5.62429","0.09314"
"405.2000","8.1013","5.62008","0.09324"
"405.6000","8.1095","5.61910","0.09336"
"406.0000","8.1173","5.61397","0.09347"
"406.4000","8.1256","5.61116","0.09358"
"406.8000","8.1335","5.60883","0.09369"
"407.2000","8.1414","5.60379","0.09381"
"407.6000","8.1496","5.60121","0.09392"
"408.0000","8.1574","5.59496","0.09403"
"408.4000","8.1655","5.59164","0.09415"
"408.8000","8.1734","5.58676","0.09427"
"409.2000","8.1814","5.58147","0.09438"
"409.6000","8.1895","5.57871","0.09450"
"410.0000","8.1975","5.57321","0.09462"
"410.4000","8.2055","5.56734","0.09475"
"410.8000","8.2134","5.56069","0.09487"
"411.2000","8.2215","5.55666","0.09500"
"411.6000","8.2293","5.54914","0.09512"
"412.0000","8.2375","5.54365","0.09525"
"412.4000","8.2455","5.53842","0.09538"
"412.8000","8.2535","5.53093","0.09551"
"413.2000","8.2616","5.52465","0.09564"
"413.6000","8.2693","5.51596","0.09577"
"414.0000","8.2776","5.51095","0.09591"
"414.4000","8.2854","5.50172","0.09604"
"414.8000","8.2935","5.49370","0.09619"
"415.2000","8.3015","5.48777","0.09632"
"415.6000","8.3094","5.47910","0.09646"
"416.0000","8.3175","5.47082","0.09661"
"416.4000","8.3254","5.46044","0.09675"
"416.8000","8.3336","5.45328","0.09690"
"417.2000","8.3414","5.44208","0.09704"
"417.6000","8.3495","5.43271","0.09719"
"418.0000","8.3574","5.42506","0.09734"
"418.4000","8.3655","5.41407","0.09749"
"418.8000","8.3735","5.40341","0.09765"
"419.2000","8.3814","5.39157","0.09780"
"419.6000","8.3895","5.38240","0.09795"
"420.0000","8.3973","5.36887","0.09811"
"420.4000","8.4055","5.35695","0.09827"
"420.8000","8.4135","5.34632","0.09843"
"421.2000","8.4215","5.33308","0.09859"
"421.6000","8.4295","5.32006","0.09876"
"422.0000","8.4374","5.30582","0.09892"
"422.4000","8.4455","5.29443","0.09908"
"422.8000","8.4533","5.27767","0.09925"
"423.2000","8.4615","5.26343","0.09941"
"423.6000","8.4694","5.25081","0.09958"
"424.0000","8.4774","5.23419","0.09975"
"424.4000","8.4855","5.21945","0.09992"
"424.8000","8.4935","5.20180","0.10009"
"425.2000","8.5016","5.18584","0.10026"
"425.6000","8.5093","5.16431","0.10043"
"426.0000","8.5175","5.14402","0.10061"
"426.4000","8.5254","5.12441","0.10078"
"426.8000","8.5335","5.10206","0.10096"
"427.2000","8.5415","5.08090","0.10114"
"427.6000","8.5495","5.05913","0.10132"
"428.0000","8.5575","5.03800","0.10150"
"428.4000","8.5652","5.01150","0.10168"
"428.8000","8.5736","4.98856","0.10187"
"429.2000","8.5814","4.96609","0.10205"
"429.6000","8.5894","4.93851","0.10223"
"430.0000","8.5975","4.91170","0.10242"
"430.4000","8.6055","4.88011","0.10262"
"430.8000","8.6135","4.84288","0.10282"
"431.2000","8.6214","4.80175","0.10302"
"431.6000","8.6296","4.76214","0.10323"
"432.0000","8.6374","4.72123","0.10343"
"432.4000","8.6454","4.67018","0.10365"
"432.8000","8.6535","4.61401","0.10388"
"433.2000","8.6616","4.53261","0.10414"
"433.6000","8.6696","4.36098","0.10448"
"433.8660","8.6751","4.09167","0.10487"
"433.8910","8.6756","3.71835","0.10521"
"433.8980","8.6758","3.40853","0.10545"