File: Coupon Test Data/Tensile Test_Neebajan_Alan_21.csv
Time,Displacement,Force,Strain 1
(s),(mm),(kN),(mm/mm)
"0.0000","0.0000","0.19470","-0.00006"
"0.3000","0.0044","0.23608","-0.00003"
"0.6000","0.0106","0.30320","0.00000"
"0.9000","0.0165","0.36435","0.00004"
"1.2000","0.0226","0.42753","0.00008"
"1.5000","0.0284","0.48707","0.00011"
"1.8000","0.0344","0.54778","0.00015"
"2.1000","0.0405","0.60914","0.00018"
"2.4000","0.0465","0.66359","0.00021"
"2.7000","0.0526","0.72089","0.00025"
"3.0000","0.0585","0.77825","0.00028"
"3.3000","0.0645","0.82852","0.00031"
"3.6000","0.0704","0.88136","0.00034"
"3.9000","0.0764","0.93825","0.00037"
"4.2000","0.0826","0.99085","0.00040"
"4.5000","0.0886","1.04408","0.00043"
"4.8000","0.0945","1.09792","0.00047"
"5.1000","0.1006","1.14978","0.00050"
"5.4000","0.1064","1.19915","0.00052"
"5.7000","0.1125","1.25427","0.00056"
"6.0000","0.1183","1.29946","0.00058"
"6.3000","0.1246","1.35504","0.00061"
"6.6000","0.1306","1.40644","0.00064"
"6.9000","0.1366","1.45202","0.00067"
"7.2000","0.1426","1.50346","0.00070"
"7.5000","0.1485","1.55105","0.00073"
"7.8000","0.1545","1.59844","0.00076"
"8.1000","0.1604","1.64610","0.00078"
"8.4000","0.1667","1.69447","0.00081"
"8.7000","0.1725","1.74082","0.00084"
"9.0000","0.1786","1.78510","0.00087"
"9.3000","0.1845","1.83133","0.00089"
"9.6000","0.1906","1.87623","0.00092"
"9.9000","0.1965","1.92070","0.00095"
"10.2000","0.2024","1.96370","0.00097"
"10.5000","0.2085","2.00970","0.00100"
"10.8000","0.2147","2.05195","0.00102"
"11.1000","0.2205","2.09562","0.00105"
"11.4000","0.2265","2.13594","0.00107"
"11.7000","0.2324","2.18024","0.00110"
"12.0000","0.2385","2.22019","0.00112"
"12.3000","0.2444","2.26354","0.00115"
"12.6000","0.2506","2.30484","0.00117"
"12.9000","0.2567","2.34566","0.00120"
"13.2000","0.2625","2.38557","0.00122"
"13.5000","0.2686","2.42521","0.00124"
"13.8000","0.2745","2.46470","0.00127"
"14.1000","0.2806","2.50579","0.00129"
"14.4000","0.2863","2.54199","0.00132"
"14.7000","0.2926","2.58404","0.00134"
"15.0000","0.2986","2.62337","0.00136"
"15.3000","0.3046","2.66046","0.00138"
"15.6000","0.3105","2.69772","0.00141"
"15.9000","0.3165","2.73603","0.00143"
"16.2000","0.3226","2.77451","0.00145"
"16.5000","0.3284","2.80973","0.00148"
"16.8000","0.3347","2.85016","0.00150"
"17.1000","0.3406","2.88559","0.00152"
"17.4000","0.3466","2.92179","0.00154"
"17.7000","0.3524","2.95637","0.00156"
"18.0000","0.3586","2.99380","0.00159"
"18.3000","0.3645","3.02809","0.00161"
"18.6000","0.3705","3.06271","0.00163"
"18.9000","0.3765","3.09799","0.00165"
"19.2000","0.3827","3.13425","0.00167"
"19.5000","0.3885","3.16649","0.00169"
"19.8000","0.3946","3.20099","0.00171"
"20.1000","0.4004","3.23404","0.00173"
"20.4000","0.4066","3.26958","0.00175"
"20.7000","0.4124","3.30201","0.00177"
"21.0000","0.4186","3.33678","0.00179"
"21.3000","0.4247","3.37067","0.00181"
"21.6000","0.4305","3.40154","0.00184"
"21.9000","0.4366","3.43471","0.00185"
"22.2000","0.4424","3.46553","0.00187"
"22.5000","0.4488","3.49920","0.00189"
"22.8000","0.4544","3.52893","0.00191"
"23.1000","0.4606","3.56245","0.00193"
"23.4000","0.4665","3.59308","0.00195"
"23.7000","0.4726","3.62539","0.00197"
"24.0000","0.4785","3.65574","0.00199"
"24.3000","0.4845","3.68730","0.00201"
"24.6000","0.4905","3.72029","0.00203"
"24.9000","0.4965","3.75165","0.00205"
"25.2000","0.5026","3.78330","0.00207"
"25.5000","0.5086","3.81525","0.00209"
"25.8000","0.5145","3.84526","0.00211"
"26.1000","0.5205","3.87562","0.00213"
"26.4000","0.5265","3.90625","0.00215"
"26.7000","0.5326","3.93842","0.00217"
"27.0000","0.5385","3.96817","0.00219"
"27.3000","0.5444","3.99814","0.00220"
"27.6000","0.5506","4.02914","0.00223"
"27.9000","0.5564","4.05834","0.00225"
"28.2000","0.5626","4.08812","0.00226"
"28.5000","0.5683","4.11737","0.00228"
"28.8000","0.5747","4.14676","0.00230"
"29.1000","0.5805","4.17830","0.00232"
"29.4000","0.5866","4.20454","0.00234"
"29.7000","0.5926","4.23783","0.00236"
"30.0000","0.5985","4.26369","0.00238"
"30.3000","0.6046","4.29729","0.00240"
"30.6000","0.6104","4.32271","0.00242"
"30.9000","0.6167","4.35825","0.00244"
"31.2000","0.6225","4.38399","0.00246"
"31.5000","0.6286","4.41735","0.00248"
"31.8000","0.6345","4.44549","0.00250"
"32.1000","0.6406","4.47656","0.00252"
"32.4000","0.6465","4.50835","0.00254"
"32.7000","0.6524","4.53301","0.00256"
"33.0000","0.6585","4.56830","0.00258"
"33.3000","0.6646","4.59374","0.00260"
"33.6000","0.6704","4.62604","0.00262"
"33.9000","0.6766","4.65856","0.00264"
"34.2000","0.6825","4.68530","0.00266"
"34.5000","0.6886","4.71844","0.00269"
"34.8000","0.6945","4.74191","0.00270"
"35.1000","0.7006","4.77654","0.00273"
"35.4000","0.7066","4.80940","0.00275"
"35.7000","0.7124","4.83186","0.00277"
"36.0000","0.7186","4.86688","0.00279"
"36.3000","0.7245","4.89700","0.00282"
"36.6000","0.7307","4.92273","0.00284"
"36.9000","0.7364","4.95308","0.00286"
"37.2000","0.7426","4.98635","0.00289"
"37.5000","0.7486","5.00772","0.00290"
"37.8000","0.7546","5.04028","0.00293"
"38.1000","0.7606","5.07065","0.00296"
"38.4000","0.7665","5.09041","0.00297"
"38.7000","0.7727","5.12391","0.00300"
"39.0000","0.7785","5.15210","0.00303"
"39.3000","0.7847","5.18273","0.00305"
"39.6000","0.7905","5.19960","0.00307"
"39.9000","0.7965","5.23092","0.00310"
"40.2000","0.8024","5.25760","0.00313"
"40.5000","0.8086","5.28499","0.00316"
"40.8000","0.8146","5.30027","0.00318"
"41.1000","0.8205","5.32843","0.00321"
"41.4000","0.8264","5.35427","0.00325"
"41.7000","0.8326","5.37908","0.00328"
"42.0000","0.8384","5.40001","0.00331"
"42.3000","0.8446","5.41110","0.00333"
"42.6000","0.8504","5.43632","0.00336"
"42.9000","0.8567","5.45890","0.00340"
"43.2000","0.8625","5.47825","0.00344"
"43.5000","0.8686","5.49741","0.00347"
"43.8000","0.8746","5.51454","0.00351"
"44.1000","0.8804","5.52942","0.00355"
"44.4000","0.8866","5.54531","0.00359"
"44.7000","0.8924","5.55812","0.00363"
"45.0000","0.8988","5.57472","0.00367"
"45.3000","0.9044","5.58391","0.00371"
"45.6000","0.9107","5.59852","0.00376"
"45.9000","0.9165","5.60752","0.00380"
"46.2000","0.9226","5.60253","0.00384"
"46.5000","0.9285","5.62045","0.00387"
"46.8000","0.9345","5.63381","0.00391"
"47.1000","0.9407","5.64320","0.00396"
"47.4000","0.9466","5.64718","0.00401"
"47.7000","0.9525","5.65769","0.00405"
"48.0000","0.9585","5.66449","0.00410"
"48.3000","0.9644","5.67219","0.00415"
"48.6000","0.9705","5.67757","0.00420"
"48.9000","0.9765","5.68405","0.00425"
"49.2000","0.9826","5.69104","0.00430"
"49.5000","0.9886","5.69587","0.00435"
"49.8000","0.9944","5.70125","0.00440"
"50.1000","1.0006","5.70613","0.00445"
"50.4000","1.0064","5.70751","0.00449"
"50.7000","1.0127","5.71490","0.00454"
"51.0000","1.0184","5.71774","0.00459"
"51.3000","1.0248","5.72446","0.00464"
"51.6000","1.0306","5.72673","0.00469"
"51.9000","1.0366","5.73097","0.00474"
"52.2000","1.0425","5.73418","0.00479"
"52.5000","1.0485","5.73774","0.00484"
"52.8000","1.0546","5.74173","0.00489"
"53.1000","1.0605","5.74335","0.00493"
"53.4000","1.0668","5.74961","0.00499"
"53.7000","1.0726","5.75040","0.00503"
"54.0000","1.0786","5.75473","0.00508"
"54.3000","1.0844","5.75588","0.00513"
"54.6000","1.0906","5.76000","0.00518"
"54.9000","1.0966","5.76186","0.00523"
"55.2000","1.1025","5.76336","0.00528"
"55.5000","1.1086","5.76828","0.00534"
"55.8000","1.1147","5.76985","0.00539"
"56.1000","1.1205","5.77243","0.00544"
"56.4000","1.1265","5.77346","0.00549"
"56.7000","1.1324","5.77674","0.00554"
"57.0000","1.1386","5.77858","0.00559"
"57.3000","1.1445","5.78044","0.00564"
"57.6000","1.1506","5.78366","0.00570"
"57.9000","1.1567","5.78619","0.00575"
"58.2000","1.1624","5.78672","0.00580"
"58.5000","1.1685","5.78126","0.00584"
"58.8000","1.1744","5.78914","0.00589"
"59.1000","1.1807","5.79444","0.00594"
"59.4000","1.1864","5.79352","0.00600"
"59.7000","1.1927","5.79814","0.00605"
"60.0000","1.1987","5.79957","0.00611"
"60.3000","1.2046","5.80064","0.00616"
"60.6000","1.2105","5.80180","0.00621"
"60.9000","1.2164","5.80325","0.00627"
"61.2000","1.2226","5.80697","0.00632"
"61.5000","1.2285","5.80578","0.00638"
"61.8000","1.2347","5.81078","0.00644"
"62.1000","1.2406","5.81024","0.00649"
"62.4000","1.2465","5.81306","0.00654"
"62.7000","1.2524","5.81242","0.00660"
"63.0000","1.2585","5.81576","0.00666"
"63.3000","1.2646","5.81692","0.00672"
"63.6000","1.2705","5.79722","0.00675"
"63.9000","1.2765","5.81494","0.00680"
"64.2000","1.2827","5.82280","0.00686"
"64.5000","1.2884","5.82325","0.00691"
"64.8000","1.2945","5.82412","0.00697"
"65.1000","1.3003","5.82470","0.00703"
"65.4000","1.3067","5.82800","0.00709"
"65.7000","1.3125","5.82787","0.00715"
"66.0000","1.3186","5.83003","0.00721"
"66.3000","1.3247","5.83178","0.00727"
"66.6000","1.3304","5.83176","0.00732"
"66.9000","1.3366","5.83405","0.00739"
"67.2000","1.3423","5.83371","0.00744"
"67.5000","1.3488","5.83865","0.00751"
"67.8000","1.3545","5.83636","0.00757"
"68.1000","1.3607","5.84063","0.00763"
"68.4000","1.3666","5.84020","0.00769"
"68.7000","1.3726","5.84235","0.00775"
"69.0000","1.3785","5.84195","0.00781"
"69.3000","1.3844","5.84332","0.00787"
"69.6000","1.3906","5.84677","0.00794"
"69.9000","1.3966","5.84634","0.00800"
"70.2000","1.4026","5.84863","0.00806"
"70.5000","1.4086","5.84885","0.00812"
"70.8000","1.4145","5.85047","0.00818"
"71.1000","1.4205","5.85062","0.00825"
"71.4000","1.4264","5.85202","0.00831"
"71.7000","1.4326","5.85479","0.00837"
"72.0000","1.4386","5.85492","0.00844"
"72.3000","1.4445","5.85600","0.00850"
"72.6000","1.4507","5.85789","0.00857"
"72.9000","1.4564","5.85781","0.00863"
"73.2000","1.4626","5.85953","0.00869"
"73.5000","1.4683","5.85912","0.00875"
"73.8000","1.4747","5.86367","0.00882"
"74.1000","1.4806","5.86324","0.00888"
"74.4000","1.4866","5.86467","0.00895"
"74.7000","1.4926","5.86531","0.00901"
"75.0000","1.4985","5.86624","0.00908"
"75.3000","1.5046","5.86781","0.00914"
"75.6000","1.5104","5.86705","0.00920"
"75.9000","1.5167","5.87173","0.00927"
"76.2000","1.5226","5.87037","0.00934"
"76.5000","1.5286","5.87265","0.00940"
"76.8000","1.5345","5.87218","0.00947"
"77.1000","1.5406","5.87437","0.00953"
"77.4000","1.5465","5.87446","0.00960"
"77.7000","1.5524","5.87453","0.00966"
"78.0000","1.5586","5.87821","0.00973"
"78.3000","1.5647","5.87855","0.00980"
"78.6000","1.5705","5.87928","0.00986"
"78.9000","1.5765","5.87917","0.00993"
"79.2000","1.5824","5.88079","0.00999"
"79.5000","1.5885","5.88152","0.01006"
"79.8000","1.5944","5.88231","0.01013"
"80.1000","1.6006","5.88467","0.01020"
"80.4000","1.6067","5.88610","0.01026"
"80.7000","1.6125","5.88537","0.01033"
"81.0000","1.6186","5.88725","0.01039"
"81.3000","1.6244","5.88705","0.01046"
"81.6000","1.6307","5.88953","0.01053"
"81.9000","1.6363","5.88799","0.01059"
"82.2000","1.6427","5.89255","0.01066"
"82.5000","1.6487","5.89285","0.01073"
"82.8000","1.6546","5.89303","0.01080"
"83.1000","1.6606","5.89340","0.01086"
"83.4000","1.6665","5.89389","0.01093"
"83.7000","1.6726","5.89660","0.01100"
"84.0000","1.6784","5.89507","0.01106"
"84.3000","1.6847","5.89979","0.01113"
"84.6000","1.6906","5.89836","0.01120"
"84.9000","1.6966","5.90021","0.01127"
"85.2000","1.7025","5.89870","0.01134"
"85.5000","1.7085","5.90149","0.01140"
"85.8000","1.7146","5.90174","0.01147"
"86.1000","1.7204","5.90225","0.01154"
"86.4000","1.7265","5.90435","0.01161"
"86.7000","1.7327","5.90606","0.01168"
"87.0000","1.7385","5.90537","0.01174"
"87.3000","1.7446","5.90605","0.01181"
"87.6000","1.7504","5.90653","0.01188"
"87.9000","1.7566","5.90893","0.01195"
"88.2000","1.7625","5.90900","0.01201"
"88.5000","1.7686","5.91056","0.01208"
"88.8000","1.7748","5.91290","0.01215"
"89.1000","1.7805","5.91110","0.01222"
"89.4000","1.7867","5.91352","0.01229"
"89.7000","1.7924","5.91206","0.01235"
"90.0000","1.7988","5.91642","0.01243"
"90.3000","1.8044","5.91373","0.01249"
"90.6000","1.8107","5.91825","0.01256"
"90.9000","1.8166","5.91716","0.01263"
"91.2000","1.8226","5.91877","0.01270"
"91.5000","1.8285","5.91795","0.01277"
"91.8000","1.8344","5.91874","0.01283"
"92.1000","1.8406","5.91091","0.01288"
"92.4000","1.8465","5.91852","0.01294"
"92.7000","1.8526","5.92363","0.01301"
"93.0000","1.8586","5.92377","0.01308"
"93.3000","1.8646","5.92524","0.01314"
"93.6000","1.8705","5.92436","0.01321"
"93.9000","1.8766","5.92590","0.01328"
"94.2000","1.8826","5.92689","0.01335"
"94.5000","1.8886","5.92775","0.01342"
"94.8000","1.8944","5.92787","0.01348"
"95.1000","1.9007","5.93042","0.01355"
"95.4000","1.9064","5.92907","0.01362"
"95.7000","1.9127","5.93115","0.01369"
"96.0000","1.9183","5.92930","0.01375"
"96.3000","1.9247","5.93394","0.01382"
"96.6000","1.9305","5.93301","0.01389"
"96.9000","1.9366","5.93511","0.01396"
"97.2000","1.9426","5.93492","0.01402"
"97.5000","1.9485","5.93553","0.01409"
"97.8000","1.9546","5.93641","0.01416"
"98.1000","1.9604","5.93576","0.01423"
"98.4000","1.9667","5.93955","0.01430"
"98.7000","1.9725","5.93838","0.01436"
"99.0000","1.9786","5.94078","0.01443"
"99.3000","1.9845","5.94015","0.01450"
"99.6000","1.9906","5.94215","0.01457"
"99.9000","1.9965","5.94175","0.01464"
"100.2000","2.0025","5.94200","0.01471"
"100.5000","2.0085","5.94436","0.01477"
"100.8000","2.0146","5.94540","0.01484"
"101.1000","2.0205","5.94587","0.01491"
"101.4000","2.0266","5.94644","0.01498"
"101.7000","2.0325","5.94705","0.01504"
"102.0000","2.0386","5.94770","0.01511"
"102.3000","2.0444","5.94777","0.01518"
"102.6000","2.0506","5.95006","0.01525"
"102.9000","2.0566","5.95101","0.01532"
"103.2000","2.0624","5.95068","0.01538"
"103.5000","2.0686","5.95270","0.01545"
"103.8000","2.0745","5.95229","0.01552"
"104.1000","2.0807","5.95432","0.01559"
"104.4000","2.0864","5.95252","0.01565"
"104.7000","2.0927","5.95640","0.01572"
"105.0000","2.0985","5.95641","0.01579"
"105.3000","2.1046","5.95741","0.01586"
"105.6000","2.1106","5.95771","0.01593"
"105.9000","2.1165","5.95809","0.01599"
"106.2000","2.1227","5.96009","0.01607"
"106.5000","2.1285","5.95874","0.01613"
"106.8000","2.1347","5.96246","0.01620"
"107.1000","2.1406","5.96149","0.01627"
"107.4000","2.1465","5.96336","0.01633"
"107.7000","2.1525","5.96253","0.01640"
"108.0000","2.1586","5.96448","0.01647"
"108.3000","2.1646","5.96468","0.01654"
"108.6000","2.1705","5.96468","0.01661"
"108.9000","2.1764","5.96620","0.01667"
"109.2000","2.1826","5.96833","0.01674"
"109.5000","2.1885","5.96775","0.01681"
"109.8000","2.1946","5.96835","0.01687"
"110.1000","2.2004","5.96843","0.01694"
"110.4000","2.2067","5.97093","0.01701"
"110.7000","2.2125","5.97073","0.01708"
"111.0000","2.2186","5.97223","0.01714"
"111.3000","2.2246","5.97349","0.01721"
"111.6000","2.2304","5.97290","0.01728"
"111.9000","2.2366","5.97511","0.01735"
"112.2000","2.2424","5.97373","0.01741"
"112.5000","2.2488","5.97760","0.01748"
"112.8000","2.2544","5.97495","0.01755"
"113.1000","2.2607","5.97883","0.01761"
"113.4000","2.2665","5.97766","0.01768"
"113.7000","2.2726","5.97990","0.01775"
"114.0000","2.2785","5.97946","0.01781"
"114.3000","2.2845","5.98002","0.01788"
"114.6000","2.2906","5.98206","0.01795"
"114.9000","2.2966","5.98174","0.01802"
"115.2000","2.3026","5.98321","0.01808"
"115.5000","2.3085","5.98325","0.01815"
"115.8000","2.3145","5.98449","0.01822"
"116.1000","2.3205","5.98459","0.01828"
"116.4000","2.3265","5.98541","0.01835"
"116.7000","2.3326","5.98725","0.01842"
"117.0000","2.3386","5.98753","0.01848"
"117.3000","2.3445","5.96654","0.01853"
"117.6000","2.3506","5.98254","0.01859"
"117.9000","2.3564","5.98768","0.01865"
"118.2000","2.3626","5.99114","0.01872"
"118.5000","2.3683","5.99038","0.01878"
"118.8000","2.3747","5.99413","0.01885"
"119.1000","2.3806","5.99335","0.01891"
"119.4000","2.3866","5.99439","0.01898"
"119.7000","2.3925","5.99446","0.01905"
"120.0000","2.3984","5.99482","0.01911"
"120.3000","2.4046","5.99665","0.01918"
"120.6000","2.4104","5.99543","0.01924"
"120.9000","2.4168","5.99935","0.01931"
"121.2000","2.4225","5.99762","0.01938"
"121.5000","2.4286","5.99969","0.01944"
"121.8000","2.4344","5.99877","0.01951"
"122.1000","2.4405","6.00065","0.01958"
"122.4000","2.4466","6.00092","0.01964"
"122.7000","2.4525","6.00050","0.01971"
"123.0000","2.4586","6.00327","0.01978"
"123.3000","2.4647","6.00352","0.01984"
"123.6000","2.4705","6.00385","0.01991"
"123.9000","2.4765","6.00374","0.01997"
"124.2000","2.4824","6.00495","0.02004"
"124.5000","2.4885","6.00593","0.02011"
"124.8000","2.4945","6.00628","0.02017"
"125.1000","2.5006","6.00785","0.02024"
"125.4000","2.5067","6.00904","0.02031"
"125.7000","2.5125","6.00836","0.02037"
"126.0000","2.5186","6.00983","0.02044"
"126.3000","2.5244","6.00973","0.02050"
"126.6000","2.5307","6.01213","0.02057"
"126.9000","2.5364","6.01044","0.02063"
"127.2000","2.5427","6.01396","0.02070"
"127.5000","2.5486","6.01412","0.02077"
"127.8000","2.5546","6.01452","0.02083"
"128.1000","2.5605","6.01462","0.02090"
"128.4000","2.5664","6.01500","0.02096"
"128.7000","2.5727","6.01777","0.02103"
"129.0000","2.5785","6.01591","0.02109"
"129.3000","2.5847","6.01960","0.02116"
"129.6000","2.5906","6.01825","0.02123"
"129.9000","2.5965","6.01988","0.02129"
"130.2000","2.6024","6.01865","0.02136"
"130.5000","2.6085","6.02105","0.02142"
"130.8000","2.6146","6.02186","0.02149"
"131.1000","2.6206","6.02189","0.02155"
"131.4000","2.6265","6.02284","0.02162"
"131.7000","2.6327","6.02466","0.02169"
"132.0000","2.6385","6.02370","0.02175"
"132.3000","2.6446","6.02468","0.02182"
"132.6000","2.6503","6.02461","0.02188"
"132.9000","2.6566","6.02760","0.02195"
"133.2000","2.6625","6.02694","0.02201"
"133.5000","2.6686","6.02858","0.02208"
"133.8000","2.6747","6.02970","0.02215"
"134.1000","2.6804","6.02888","0.02221"
"134.4000","2.6866","6.03049","0.02227"
"134.7000","2.6923","6.02952","0.02234"
"135.0000","2.6988","6.03397","0.02241"
"135.3000","2.7044","6.03095","0.02247"
"135.6000","2.7107","6.03469","0.02254"
"135.9000","2.7166","6.03381","0.02260"
"136.2000","2.7226","6.03522","0.02267"
"136.5000","2.7285","6.03419","0.02273"
"136.8000","2.7344","6.03501","0.02280"
"137.1000","2.7406","6.03785","0.02286"
"137.4000","2.7466","6.03725","0.02293"
"137.7000","2.7526","6.03883","0.02299"
"138.0000","2.7586","6.03859","0.02306"
"138.3000","2.7645","6.03929","0.02312"
"138.6000","2.7705","6.03929","0.02319"
"138.9000","2.7764","6.04024","0.02325"
"139.2000","2.7826","6.04233","0.02332"
"139.5000","2.7886","6.04214","0.02338"
"139.8000","2.7945","6.04254","0.02345"
"140.1000","2.8007","6.04419","0.02351"
"140.4000","2.8064","6.04385","0.02358"
"140.7000","2.8126","6.04507","0.02365"
"141.0000","2.8183","6.04379","0.02371"
"141.3000","2.8247","6.04808","0.02378"
"141.6000","2.8306","6.04733","0.02384"
"141.9000","2.8367","6.04850","0.02391"
"142.2000","2.8426","6.04851","0.02397"
"142.5000","2.8485","6.04868","0.02404"
"142.8000","2.8545","6.05002","0.02410"
"143.1000","2.8604","6.04919","0.02416"
"143.4000","2.8667","6.05340","0.02423"
"143.7000","2.8726","6.05172","0.02429"
"144.0000","2.8786","6.05359","0.02436"
"144.3000","2.8845","6.05280","0.02442"
"144.6000","2.8906","6.05430","0.02449"
"144.9000","2.8965","6.05436","0.02455"
"145.2000","2.9024","6.05393","0.02461"
"145.5000","2.9085","6.05707","0.02469"
"145.8000","2.9147","6.05738","0.02475"
"146.1000","2.9205","6.05763","0.02482"
"146.4000","2.9265","6.05748","0.02488"
"146.7000","2.9324","6.05837","0.02495"
"147.0000","2.9385","6.05921","0.02501"
"147.3000","2.9444","6.05932","0.02507"
"147.6000","2.9506","6.06161","0.02514"
"147.9000","2.9567","6.06258","0.02520"
"148.2000","2.9625","6.06177","0.02527"
"148.5000","2.9686","6.06321","0.02533"
"148.8000","2.9745","6.06284","0.02539"
"149.1000","2.9807","6.06500","0.02546"
"149.4000","2.9863","6.06308","0.02552"
"149.7000","2.9927","6.06714","0.02559"
"150.0000","2.9986","6.06723","0.02565"
"150.3000","3.0046","6.06744","0.02572"
"150.6000","3.0106","6.05544","0.02576"
"150.9000","3.0165","6.06334","0.02582"
"151.2000","3.0226","6.06895","0.02588"
"151.5000","3.0284","6.06859","0.02594"
"151.8000","3.0347","6.07308","0.02601"
"152.1000","3.0406","6.07167","0.02607"
"152.4000","3.0466","6.07282","0.02613"
"152.7000","3.0525","6.07138","0.02620"
"153.0000","3.0585","6.07348","0.02626"
"153.3000","3.0646","6.07364","0.02632"
"153.6000","3.0705","6.07351","0.02639"
"153.9000","3.0765","6.07496","0.02645"
"154.2000","3.0827","6.07697","0.02652"
"154.5000","3.0885","6.07572","0.02658"
"154.8000","3.0946","6.07644","0.02664"
"155.1000","3.1004","6.07613","0.02671"
"155.4000","3.1066","6.07850","0.02677"
"155.7000","3.1124","6.07798","0.02683"
"156.0000","3.1186","6.08007","0.02690"
"156.3000","3.1247","6.08126","0.02696"
"156.6000","3.1305","6.07995","0.02702"
"156.9000","3.1366","6.08149","0.02709"
"157.2000","3.1424","6.08033","0.02715"
"157.5000","3.1488","6.08415","0.02722"
"157.8000","3.1544","6.08140","0.02728"
"158.1000","3.1607","6.08553","0.02734"
"158.4000","3.1666","6.08459","0.02741"
"158.7000","3.1726","6.08587","0.02747"
"159.0000","3.1785","6.08490","0.02753"
"159.3000","3.1845","6.08526","0.02760"
"159.6000","3.1906","6.08765","0.02766"
"159.9000","3.1965","6.08695","0.02772"
"160.2000","3.2025","6.08869","0.02779"
"160.5000","3.2086","6.08882","0.02785"
"160.8000","3.2145","6.08950","0.02791"
"161.1000","3.2205","6.08923","0.02797"
"161.4000","3.2265","6.08981","0.02804"
"161.7000","3.2326","6.09168","0.02810"
"162.0000","3.2385","6.09158","0.02816"
"162.3000","3.2444","6.09231","0.02822"
"162.6000","3.2507","6.09393","0.02829"
"162.9000","3.2565","6.09320","0.02835"
"163.2000","3.2627","6.09436","0.02842"
"163.5000","3.2683","6.09280","0.02848"
"163.8000","3.2747","6.09684","0.02854"
"164.1000","3.2805","6.09620","0.02860"
"164.4000","3.2866","6.09774","0.02867"
"164.7000","3.2926","6.09766","0.02873"
"165.0000","3.2985","6.09797","0.02879"
"165.3000","3.3046","6.09904","0.02886"
"165.6000","3.3104","6.09815","0.02892"
"165.9000","3.3168","6.10168","0.02899"
"166.2000","3.3225","6.10000","0.02905"
"166.5000","3.3286","6.10217","0.02911"
"166.8000","3.3345","6.10151","0.02917"
"167.1000","3.3406","6.10317","0.02923"
"167.4000","3.3465","6.10256","0.02930"
"167.7000","3.3524","6.10225","0.02936"
"168.0000","3.3585","6.10468","0.02942"
"168.3000","3.3646","6.10505","0.02949"
"168.6000","3.3705","6.10585","0.02955"
"168.9000","3.3766","6.10567","0.02961"
"169.2000","3.3825","6.10639","0.02967"
"169.5000","3.3886","6.10682","0.02974"
"169.8000","3.3945","6.10691","0.02980"
"170.1000","3.4006","6.10865","0.02986"
"170.4000","3.4066","6.10960","0.02993"
"170.7000","3.4124","6.10898","0.02999"
"171.0000","3.4186","6.11084","0.03006"
"171.3000","3.4245","6.11012","0.03012"
"171.6000","3.4307","6.11222","0.03018"
"171.9000","3.4364","6.11006","0.03024"
"172.2000","3.4426","6.11354","0.03031"
"172.5000","3.4486","6.11370","0.03037"
"172.8000","3.4546","6.11418","0.03043"
"173.1000","3.4606","6.11453","0.03049"
"173.4000","3.4665","6.11439","0.03056"
"173.7000","3.4727","6.11666","0.03062"
"174.0000","3.4785","6.11478","0.03068"
"174.3000","3.4847","6.11835","0.03074"
"174.6000","3.4905","6.11681","0.03081"
"174.9000","3.4965","6.11851","0.03087"
"175.2000","3.5025","6.11720","0.03093"
"175.5000","3.5086","6.11935","0.03099"
"175.8000","3.5146","6.11940","0.03105"
"176.1000","3.5205","6.11929","0.03112"
"176.4000","3.5265","6.12028","0.03117"
"176.7000","3.5326","6.12205","0.03124"
"177.0000","3.5384","6.12146","0.03130"
"177.3000","3.5446","6.12244","0.03136"
"177.6000","3.5504","6.12202","0.03142"
"177.9000","3.5567","6.12426","0.03149"
"178.2000","3.5625","6.12340","0.03155"
"178.5000","3.5686","6.12488","0.03161"
"178.8000","3.5746","6.12574","0.03167"
"179.1000","3.5804","6.12517","0.03173"
"179.4000","3.5866","6.12708","0.03180"
"179.7000","3.5924","6.12572","0.03186"
"180.0000","3.5988","6.12946","0.03192"
"180.3000","3.6044","6.12660","0.03198"
"180.6000","3.6106","6.12985","0.03204"
"180.9000","3.6165","6.12888","0.03210"
"181.2000","3.6226","6.13062","0.03217"
"181.5000","3.6285","6.12972","0.03223"
"181.8000","3.6345","6.13005","0.03229"
"182.1000","3.6407","6.13230","0.03235"
"182.4000","3.6466","6.13153","0.03241"
"182.7000","3.6525","6.13266","0.03247"
"183.0000","3.6585","6.13267","0.03253"
"183.3000","3.6644","6.13341","0.03260"
"183.6000","3.6705","6.13360","0.03266"
"183.9000","3.6765","6.13405","0.03272"
"184.2000","3.6826","6.13566","0.03278"
"184.5000","3.6886","6.13552","0.03284"
"184.8000","3.6944","6.13556","0.03290"
"185.1000","3.7006","6.13703","0.03296"
"185.4000","3.7064","6.13660","0.03302"
"185.7000","3.7127","6.13821","0.03309"
"186.0000","3.7184","6.13656","0.03314"
"186.3000","3.7248","6.14031","0.03321"
"186.6000","3.7306","6.13939","0.03327"
"186.9000","3.7366","6.14030","0.03333"
"187.2000","3.7425","6.14031","0.03339"
"187.5000","3.7485","6.14075","0.03345"
"187.8000","3.7546","6.14209","0.03351"
"188.1000","3.7605","6.14092","0.03357"
"188.4000","3.7668","6.14451","0.03363"
"188.7000","3.7726","6.14275","0.03369"
"189.0000","3.7786","6.14421","0.03376"
"189.3000","3.7844","6.14340","0.03381"
"189.6000","3.7905","6.14502","0.03388"
"189.9000","3.7966","6.14515","0.03394"
"190.2000","3.8025","6.14449","0.03400"
"190.5000","3.8086","6.14708","0.03406"
"190.8000","3.8147","6.14704","0.03412"
"191.1000","3.8205","6.14710","0.03418"
"191.4000","3.8265","6.14676","0.03424"
"191.7000","3.8324","6.14772","0.03430"
"192.0000","3.8386","6.14857","0.03436"
"192.3000","3.8445","6.14852","0.03442"
"192.6000","3.8506","6.15009","0.03449"
"192.9000","3.8567","6.15090","0.03454"
"193.2000","3.8624","6.14972","0.03460"
"193.5000","3.8685","6.15131","0.03466"
"193.8000","3.8744","6.15081","0.03472"
"194.1000","3.8807","6.15338","0.03479"
"194.4000","3.8864","6.15119","0.03484"
"194.7000","3.8927","6.15451","0.03491"
"195.0000","3.8986","6.15426","0.03496"
"195.3000","3.9046","6.15427","0.03502"
"195.6000","3.9105","6.15427","0.03508"
"195.9000","3.9164","6.15435","0.03514"
"196.2000","3.9226","6.15696","0.03520"
"196.5000","3.9285","6.15501","0.03526"
"196.8000","3.9347","6.15862","0.03532"
"197.1000","3.9406","6.15684","0.03539"
"197.4000","3.9465","6.15803","0.03544"
"197.7000","3.9524","6.15656","0.03550"
"198.0000","3.9585","6.15866","0.03556"
"198.3000","3.9646","6.15930","0.03562"
"198.6000","3.9705","6.15911","0.03568"
"198.9000","3.9766","6.16003","0.03574"
"199.2000","3.9827","6.16136","0.03580"
"199.5000","3.9885","6.16042","0.03586"
"199.8000","3.9945","6.16088","0.03592"
"200.1000","4.0004","6.16091","0.03598"
"200.4000","4.0066","6.16320","0.03604"
"200.7000","4.0126","6.16287","0.03610"
"201.0000","4.0186","6.16356","0.03616"
"201.3000","4.0247","6.16512","0.03622"
"201.6000","4.0304","6.16317","0.03627"
"201.9000","4.0366","6.16528","0.03633"
"202.2000","4.0423","6.16348","0.03639"
"202.5000","4.0488","6.16792","0.03645"
"202.8000","4.0544","6.16465","0.03651"
"203.1000","4.0607","6.15476","0.03654"
"203.4000","4.0665","6.16196","0.03660"
"203.7000","4.0726","6.16701","0.03666"
"204.0000","4.0785","6.16725","0.03671"
"204.3000","4.0844","6.16805","0.03677"
"204.6000","4.0906","6.17085","0.03683"
"204.9000","4.0966","6.16997","0.03689"
"205.2000","4.1027","6.17144","0.03695"
"205.5000","4.1086","6.17042","0.03700"
"205.8000","4.1145","6.17138","0.03706"
"206.1000","4.1204","6.17051","0.03712"
"206.4000","4.1265","6.17171","0.03718"
"206.7000","4.1326","6.17280","0.03724"
"207.0000","4.1387","6.17318","0.03730"
"207.3000","4.1445","6.17245","0.03735"
"207.6000","4.1507","6.17464","0.03741"
"207.9000","4.1564","6.17277","0.03747"
"208.2000","4.1627","6.17483","0.03753"
"208.5000","4.1683","6.17231","0.03758"
"208.8000","4.1747","6.17684","0.03764"
"209.1000","4.1806","6.17537","0.03770"
"209.4000","4.1866","6.17665","0.03776"
"209.7000","4.1926","6.17587","0.03782"
"210.0000","4.1985","6.17616","0.03787"
"210.3000","4.2045","6.17693","0.03793"
"210.6000","4.2103","6.17590","0.03799"
"210.9000","4.2167","6.17985","0.03805"
"211.2000","4.2226","6.17809","0.03810"
"211.5000","4.2287","6.17953","0.03816"
"211.8000","4.2345","6.17813","0.03822"
"212.1000","4.2406","6.17978","0.03828"
"212.4000","4.2465","6.17916","0.03833"
"212.7000","4.2524","6.17923","0.03839"
"213.0000","4.2585","6.18152","0.03845"
"213.3000","4.2647","6.18214","0.03850"
"213.6000","4.2705","6.18154","0.03856"
"213.9000","4.2766","6.18181","0.03861"
"214.2000","4.2824","6.18157","0.03867"
"214.5000","4.2886","6.18275","0.03873"
"214.8000","4.2944","6.18183","0.03878"
"215.1000","4.3006","6.18460","0.03884"
"215.4000","4.3067","6.18483","0.03890"
"215.7000","4.3125","6.18386","0.03895"
"216.0000","4.3186","6.18490","0.03901"
"216.3000","4.3245","6.18434","0.03907"
"216.6000","4.3307","6.18606","0.03912"
"216.9000","4.3363","6.18394","0.03918"
"217.2000","4.3427","6.18796","0.03924"
"217.5000","4.3486","6.18747","0.03929"
"217.8000","4.3546","6.18736","0.03935"
"218.1000","4.3605","6.18688","0.03940"
"218.4000","4.3665","6.18693","0.03946"
"218.7000","4.3726","6.18897","0.03951"
"219.0000","4.3784","6.18729","0.03957"
"219.3000","4.3847","6.19068","0.03963"
"219.6000","4.3906","6.18942","0.03968"
"219.9000","4.3966","6.19026","0.03974"
"220.2000","4.4025","6.18899","0.03979"
"220.5000","4.4086","6.19051","0.03985"
"220.8000","4.4146","6.19057","0.03990"
"221.1000","4.4204","6.19009","0.03996"
"221.4000","4.4265","6.19151","0.04001"
"221.7000","4.4327","6.19334","0.04007"
"222.0000","4.4385","6.19196","0.04012"
"222.3000","4.4446","6.19192","0.04018"
"222.6000","4.4504","6.19124","0.04023"
"222.9000","4.4566","6.19373","0.04029"
"223.2000","4.4625","6.19286","0.04034"
"223.5000","4.4686","6.19462","0.04040"
"223.8000","4.4747","6.19551","0.04046"
"224.1000","4.4805","6.19382","0.04051"
"224.4000","4.4866","6.19552","0.04057"
"224.7000","4.4924","6.19368","0.04062"
"225.0000","4.4988","6.19745","0.04067"
"225.3000","4.5044","6.19410","0.04072"
"225.6000","4.5107","6.19802","0.04078"
"225.9000","4.5165","6.19652","0.04083"
"226.2000","4.5226","6.19779","0.04089"
"226.5000","4.5285","6.19641","0.04094"
"226.8000","4.5344","6.19664","0.04099"
"227.1000","4.5406","6.19858","0.04105"
"227.4000","4.5465","6.19783","0.04110"
"227.7000","4.5526","6.19942","0.04116"
"228.0000","4.5586","6.19915","0.04121"
"228.3000","4.5646","6.19928","0.04126"
"228.6000","4.5705","6.19863","0.04132"
"228.9000","4.5765","6.19910","0.04137"
"229.2000","4.5826","6.20062","0.04142"
"229.5000","4.5886","6.20029","0.04148"
"229.8000","4.5944","6.20060","0.04153"
"230.1000","4.6007","6.20214","0.04158"
"230.4000","4.6064","6.20081","0.04163"
"230.7000","4.6126","6.20181","0.04169"
"231.0000","4.6183","6.19992","0.04174"
"231.3000","4.6247","6.20351","0.04179"
"231.6000","4.6305","6.20243","0.04184"
"231.9000","4.6366","6.20375","0.04189"
"232.2000","4.6426","6.20375","0.04194"
"232.5000","4.6485","6.20340","0.04200"
"232.8000","4.6546","6.20423","0.04205"
"233.1000","4.6604","6.20278","0.04210"
"233.4000","4.6667","6.20608","0.04215"
"233.7000","4.6725","6.20415","0.04220"
"234.0000","4.6786","6.20603","0.04225"
"234.3000","4.6845","6.20511","0.04230"
"234.6000","4.6906","6.20617","0.04236"
"234.9000","4.6966","6.20543","0.04241"
"235.2000","4.7024","6.20463","0.04246"
"235.5000","4.7086","6.20691","0.04251"
"235.8000","4.7146","6.20696","0.04256"
"236.1000","4.7205","6.20728","0.04261"
"236.4000","4.7266","6.20693","0.04266"
"236.7000","4.7325","6.20726","0.04271"
"237.0000","4.7386","6.20738","0.04276"
"237.3000","4.7445","6.20715","0.04281"
"237.6000","4.7506","6.20851","0.04286"
"237.9000","4.7566","6.20903","0.04290"
"238.2000","4.7624","6.20808","0.04295"
"238.5000","4.7686","6.20964","0.04300"
"238.8000","4.7745","6.20844","0.04305"
"239.1000","4.7807","6.21018","0.04310"
"239.4000","4.7864","6.20790","0.04315"
"239.7000","4.7927","6.21095","0.04320"
"240.0000","4.7986","6.21050","0.04325"
"240.3000","4.8046","6.21090","0.04330"
"240.6000","4.8106","6.21099","0.04335"
"240.9000","4.8165","6.21032","0.04340"
"241.2000","4.8227","6.21215","0.04345"
"241.5000","4.8285","6.20978","0.04349"
"241.8000","4.8347","6.21299","0.04354"
"242.1000","4.8405","6.21117","0.04358"
"242.4000","4.8465","6.21250","0.04363"
"242.7000","4.8525","6.21117","0.04368"
"243.0000","4.8586","6.21283","0.04372"
"243.3000","4.8646","6.21244","0.04377"
"243.6000","4.8705","6.21190","0.04382"
"243.9000","4.8765","6.21234","0.04387"
"244.2000","4.8826","6.21384","0.04391"
"244.5000","4.8884","6.21264","0.04396"
"244.8000","4.8946","6.21356","0.04400"
"245.1000","4.9004","6.21248","0.04405"
"245.4000","4.9067","6.21446","0.04410"
"245.7000","4.9125","6.21334","0.04414"
"246.0000","4.9186","6.21427","0.04419"
"246.3000","4.9246","6.21488","0.04423"
"246.6000","4.9304","6.21378","0.04427"
"246.9000","4.9366","6.21527","0.04432"
"247.2000","4.9424","6.21356","0.04436"
"247.5000","4.9488","6.21685","0.04441"
"247.8000","4.9544","6.21361","0.04445"
"248.1000","4.9607","6.21647","0.04449"
"248.4000","4.9665","6.21493","0.04454"
"248.7000","4.9726","6.21638","0.04458"
"249.0000","4.9785","6.21519","0.04462"
"249.3000","4.9845","6.21521","0.04466"
"249.6000","4.9906","6.21679","0.04471"
"249.9000","4.9966","6.21589","0.04475"
"250.2000","5.0026","6.21651","0.04479"
"250.5000","5.0086","6.21580","0.04483"
"250.8000","5.0144","6.21601","0.04487"
"251.1000","5.0205","6.21607","0.04491"
"251.4000","5.0265","6.21601","0.04496"
"251.7000","5.0326","6.21716","0.04500"
"252.0000","5.0386","6.21650","0.04504"
"252.3000","5.0444","6.21605","0.04508"
"252.6000","5.0506","6.21715","0.04512"
"252.9000","5.0564","6.21632","0.04516"
"253.2000","5.0627","6.21761","0.04520"
"253.5000","5.0684","6.21531","0.04524"
"253.8000","5.0748","6.21839","0.04528"
"254.1000","5.0806","6.21699","0.04532"
"254.4000","5.0866","6.21763","0.04535"
"254.7000","5.0925","6.21687","0.04539"
"255.0000","5.0985","6.21673","0.04543"
"255.3000","5.1046","6.21786","0.04547"
"255.6000","5.1104","6.21608","0.04550"
"255.9000","5.1168","6.21911","0.04554"
"256.2000","5.1226","6.21688","0.04558"
"256.5000","5.1286","6.21788","0.04561"
"256.8000","5.1344","6.21643","0.04565"
"257.1000","5.1405","6.21743","0.04569"
"257.4000","5.1466","6.21730","0.04572"
"257.7000","5.1525","6.21598","0.04576"
"258.0000","5.1586","6.21777","0.04579"
"258.3000","5.1647","6.21721","0.04582"
"258.6000","5.1705","6.21681","0.04586"
"258.9000","5.1765","6.21594","0.04589"
"259.2000","5.1824","6.21620","0.04593"
"259.5000","5.1886","6.21675","0.04596"
"259.8000","5.1945","6.21587","0.04599"
"260.1000","5.2006","6.21671","0.04603"
"260.4000","5.2066","6.21692","0.04606"
"260.7000","5.2124","6.21546","0.04609"
"261.0000","5.2185","6.21615","0.04612"
"261.3000","5.2244","6.21514","0.04615"
"261.6000","5.2307","6.21702","0.04618"
"261.9000","5.2364","6.21384","0.04621"
"262.2000","5.2427","6.21662","0.04624"
"262.5000","5.2486","6.21574","0.04627"
"262.8000","5.2546","6.21502","0.04630"
"263.1000","5.2605","6.21409","0.04633"
"263.4000","5.2664","6.21342","0.04636"
"263.7000","5.2726","6.21543","0.04639"
"264.0000","5.2785","6.21276","0.04641"
"264.3000","5.2847","6.21549","0.04644"
"264.6000","5.2906","6.21319","0.04647"
"264.9000","5.2965","6.21349","0.04649"
"265.2000","5.3024","6.21124","0.04652"
"265.5000","5.3085","6.21244","0.04655"
"265.8000","5.3146","6.21245","0.04657"
"266.1000","5.3205","6.21077","0.04660"
"266.4000","5.3265","6.21083","0.04662"
"266.7000","5.3327","6.21163","0.04664"
"267.0000","5.3385","6.20951","0.04666"
"267.3000","5.3445","6.20918","0.04669"
"267.6000","5.3503","6.20801","0.04671"
"267.9000","5.3566","6.20987","0.04674"
"268.2000","5.3625","6.20796","0.04675"
"268.5000","5.3686","6.20811","0.04678"
"268.8000","5.3747","6.20783","0.04680"
"269.1000","5.3804","6.20566","0.04682"
"269.4000","5.3866","6.20613","0.04684"
"269.7000","5.3923","6.20363","0.04686"
"270.0000","5.3988","6.20701","0.04688"
"270.3000","5.4045","6.20246","0.04690"
"270.6000","5.4107","6.20475","0.04691"
"270.9000","5.4166","6.20200","0.04693"
"271.2000","5.4226","6.20227","0.04695"
"271.5000","5.4285","6.19972","0.04696"
"271.8000","5.4344","6.19883","0.04698"
"272.1000","5.4406","6.20022","0.04700"
"272.4000","5.4466","6.19769","0.04701"
"272.7000","5.4526","6.19740","0.04703"
"273.0000","5.4586","6.19570","0.04704"
"273.3000","5.4645","6.19483","0.04705"
"273.6000","5.4705","6.19301","0.04707"
"273.9000","5.4764","6.19200","0.04708"
"274.2000","5.4826","6.19234","0.04709"
"274.5000","5.4886","6.19015","0.04711"
"274.8000","5.4945","6.18863","0.04712"
"275.1000","5.5007","6.18833","0.04713"
"275.4000","5.5064","6.18555","0.04714"
"275.7000","5.5126","6.18483","0.04715"
"276.0000","5.5183","6.18133","0.04716"
"276.3000","5.5247","6.18369","0.04717"
"276.6000","5.5306","6.18061","0.04718"
"276.9000","5.5367","6.17948","0.04719"
"277.2000","5.5426","6.17694","0.04720"
"277.5000","5.5485","6.17513","0.04721"
"277.8000","5.5545","6.17413","0.04721"
"278.1000","5.5604","6.17068","0.04722"
"278.4000","5.5668","6.17247","0.04723"
"278.7000","5.5726","6.16770","0.04723"
"279.0000","5.5786","6.16687","0.04724"
"279.3000","5.5845","6.16340","0.04725"
"279.6000","5.5906","6.16234","0.04725"
"279.9000","5.5965","6.15934","0.04726"
"280.2000","5.6024","6.15616","0.04726"
"280.5000","5.6086","6.15646","0.04727"
"280.8000","5.6147","6.15333","0.04727"
"281.1000","5.6205","6.15048","0.04728"
"281.4000","5.6266","6.14689","0.04728"
"281.7000","5.6324","6.14470","0.04728"
"282.0000","5.6385","6.14206","0.04729"
"282.3000","5.6444","6.13898","0.04729"
"282.6000","5.6506","6.13772","0.04729"
"282.9000","5.6567","6.13518","0.04729"
"283.2000","5.6625","6.13049","0.04730"
"283.5000","5.6686","6.12832","0.04730"
"283.8000","5.6745","6.12412","0.04730"
"284.1000","5.6807","6.12258","0.04730"
"284.4000","5.6863","6.11665","0.04730"
"284.7000","5.6927","6.11705","0.04731"
"285.0000","5.6987","6.11269","0.04730"
"285.3000","5.7046","6.10849","0.04731"
"285.6000","5.7106","6.10429","0.04730"
"285.9000","5.7164","6.10016","0.04730"
"286.2000","5.7226","6.09854","0.04731"
"286.5000","5.7284","6.09193","0.04730"
"286.8000","5.7347","6.09177","0.04731"
"287.1000","5.7406","6.08522","0.04730"
"287.4000","5.7466","6.08241","0.04730"
"287.7000","5.7525","6.07566","0.04730"
"288.0000","5.7586","6.07316","0.04730"
"288.3000","5.7646","6.06807","0.04730"
"288.6000","5.7705","6.06319","0.04730"
"288.9000","5.7765","6.05984","0.04730"
"289.2000","5.7827","6.05604","0.04730"
"289.5000","5.7885","6.04961","0.04729"
"289.8000","5.7946","6.04456","0.04729"
"290.1000","5.8004","6.03893","0.04729"
"290.4000","5.8066","6.03608","0.04729"
"290.7000","5.8124","6.02960","0.04728"
"291.0000","5.8186","6.02587","0.04729"
"291.3000","5.8247","6.02068","0.04728"
"291.6000","5.8305","6.01389","0.04728"
"291.9000","5.8366","6.00921","0.04727"
"292.2000","5.8424","6.00185","0.04727"
"292.5000","5.8488","5.99943","0.04727"
"292.8000","5.8544","5.99016","0.04726"
"293.1000","5.8607","5.98817","0.04726"
"293.4000","5.8666","5.98033","0.04726"
"293.7000","5.8727","5.97494","0.04725"
"294.0000","5.8785","5.96683","0.04725"
"294.3000","5.8845","5.96073","0.04725"
"294.6000","5.8906","5.95646","0.04724"
"294.9000","5.8965","5.94829","0.04724"
"295.2000","5.9025","5.94347","0.04723"
"295.5000","5.9086","5.93554","0.04723"
"295.8000","5.9145","5.92922","0.04723"
"296.1000","5.9205","5.92087","0.04722"
"296.4000","5.9265","5.91429","0.04722"
"296.7000","5.9326","5.90845","0.04721"
"297.0000","5.9386","5.90049","0.04721"
"297.3000","5.9445","5.89388","0.04720"
"297.6000","5.9507","5.88663","0.04720"
"297.9000","5.9565","5.87835","0.04719"
"298.2000","5.9626","5.87065","0.04719"
"298.5000","5.9683","5.86162","0.04718"
"298.8000","5.9747","5.85700","0.04718"
"299.1000","5.9805","5.84807","0.04717"
"299.4000","5.9866","5.84073","0.04717"
"299.7000","5.9926","5.83213","0.04716"
"300.0000","5.9986","5.82338","0.04716"
"300.3000","6.0046","5.81528","0.04715"
"300.6000","6.0105","5.80498","0.04714"
"300.9000","6.0167","5.79976","0.04714"
"301.2000","6.0225","5.78868","0.04714"
"301.5000","6.0286","5.78189","0.04713"
"301.8000","6.0345","5.77080","0.04712"
"302.1000","6.0406","5.76271","0.04712"
"302.4000","6.0466","5.75214","0.04711"
"302.7000","6.0524","5.74178","0.04710"
"303.0000","6.0586","5.73486","0.04710"
"303.3000","6.0646","5.72383","0.04709"
"303.6000","6.0705","5.71496","0.04709"
"303.9000","6.0766","5.70298","0.04708"
"304.2000","6.0825","5.69423","0.04707"
"304.5000","6.0886","5.68225","0.04706"
"304.8000","6.0945","5.67205","0.04706"
"305.1000","6.1006","5.66183","0.04705"
"305.4000","6.1066","5.65150","0.04704"
"305.7000","6.1124","5.63925","0.04703"
"306.0000","6.1186","5.62811","0.04703"
"306.3000","6.1245","5.61477","0.04702"
"306.6000","6.1307","5.60291","0.04701"
"306.9000","6.1364","5.58766","0.04700"
"307.2000","6.1427","5.57646","0.04699"
"307.5000","6.1486","5.56037","0.04698"
"307.8000","6.1545","5.54183","0.04697"
"308.1000","6.1606","5.52122","0.04695"
"308.4000","6.1665","5.49732","0.04694"
"308.7000","6.1727","5.46771","0.04692"
"309.0000","6.1785","5.41436","0.04689"
"309.3000","6.1847","5.34491","0.04684"
"309.6000","6.1906","5.23925","0.04677"
"309.8270","6.1951","5.01440","0.04663"
"310.1270","6.2012","4.93014","0.04657"
"310.4270","6.2070","4.88087","0.04654"
"310.7270","6.2132","4.79578","0.04648"
"311.0270","6.2192","4.70471","0.04642"
"311.3270","6.2251","4.61405","0.04636"
"311.6270","6.2311","4.53466","0.04631"
"311.9270","6.2370","4.45852","0.04626"
"312.2270","6.2433","4.36929","0.04620"
"312.5270","6.2490","4.25651","0.04612"
"312.7160","6.2531","4.02851","0.04597"
"312.9860","6.2583","3.80801","0.04582"
"313.0320","6.2593","3.73058","0.04577"