File: Coupon Test Data/Tensile Test_Neebajan_Alan_8.csv
Time,Displacement,Force,Strain 1
(s),(mm),(kN),(mm/mm)
"0.0000","-9.0515","0.18981","-0.00024"
"0.5000","-9.0432","0.30065","-0.00020"
"1.0000","-9.0330","0.44058","-0.00014"
"1.5000","-9.0231","0.57227","-0.00009"
"2.0000","-9.0131","0.69440","-0.00004"
"2.5000","-9.0032","0.81724","0.00001"
"3.0000","-8.9930","0.93166","0.00006"
"3.5000","-8.9828","1.05165","0.00010"
"4.0000","-8.9730","1.15928","0.00015"
"4.5000","-8.9630","1.26485","0.00019"
"5.0000","-8.9530","1.37325","0.00023"
"5.5000","-8.9430","1.47252","0.00028"
"6.0000","-8.9332","1.56683","0.00032"
"6.5000","-8.9232","1.66438","0.00036"
"7.0000","-8.9129","1.76106","0.00040"
"7.5000","-8.9030","1.85020","0.00043"
"8.0000","-8.8929","1.93898","0.00047"
"8.5000","-8.8829","2.02377","0.00051"
"9.0000","-8.8730","2.11068","0.00054"
"9.5000","-8.8631","2.19210","0.00058"
"10.0000","-8.8530","2.27292","0.00061"
"10.5000","-8.8430","2.35244","0.00064"
"11.0000","-8.8331","2.42989","0.00068"
"11.5000","-8.8230","2.51007","0.00071"
"12.0000","-8.8130","2.58499","0.00075"
"12.5000","-8.8029","2.65994","0.00078"
"13.0000","-8.7931","2.73106","0.00081"
"13.5000","-8.7830","2.80393","0.00084"
"14.0000","-8.7729","2.87616","0.00087"
"14.5000","-8.7632","2.94517","0.00090"
"15.0000","-8.7530","3.01698","0.00093"
"15.5000","-8.7429","3.08564","0.00096"
"16.0000","-8.7331","3.15233","0.00099"
"16.5000","-8.7230","3.21872","0.00102"
"17.0000","-8.7130","3.28487","0.00105"
"17.5000","-8.7029","3.35305","0.00108"
"18.0000","-8.6930","3.41653","0.00111"
"18.5000","-8.6829","3.48184","0.00114"
"19.0000","-8.6730","3.54475","0.00116"
"19.5000","-8.6631","3.60656","0.00119"
"20.0000","-8.6530","3.67030","0.00122"
"20.5000","-8.6431","3.73189","0.00124"
"21.0000","-8.6330","3.79553","0.00127"
"21.5000","-8.6232","3.85590","0.00130"
"22.0000","-8.6129","3.92027","0.00133"
"22.5000","-8.6027","3.98361","0.00135"
"23.0000","-8.5931","4.04345","0.00138"
"23.5000","-8.5830","4.10600","0.00140"
"24.0000","-8.5730","4.16786","0.00143"
"24.5000","-8.5631","4.23097","0.00146"
"25.0000","-8.5531","4.29308","0.00149"
"25.5000","-8.5430","4.35662","0.00151"
"26.0000","-8.5329","4.42084","0.00154"
"26.5000","-8.5229","4.48316","0.00157"
"27.0000","-8.5129","4.54560","0.00159"
"27.5000","-8.5030","4.60810","0.00162"
"28.0000","-8.4930","4.67126","0.00165"
"28.5000","-8.4832","4.73220","0.00168"
"29.0000","-8.4731","4.79667","0.00170"
"29.5000","-8.4629","4.86139","0.00173"
"30.0000","-8.4531","4.92381","0.00176"
"30.5000","-8.4428","4.98933","0.00179"
"31.0000","-8.4328","5.05237","0.00181"
"31.5000","-8.4230","5.11633","0.00184"
"32.0000","-8.4132","5.17830","0.00187"
"32.5000","-8.4029","5.24474","0.00190"
"33.0000","-8.3929","5.30913","0.00193"
"33.5000","-8.3831","5.37162","0.00196"
"34.0000","-8.3730","5.43713","0.00198"
"34.5000","-8.3629","5.50171","0.00201"
"35.0000","-8.3529","5.56746","0.00204"
"35.5000","-8.3431","5.63067","0.00207"
"36.0000","-8.3330","5.69611","0.00210"
"36.5000","-8.3229","5.76337","0.00213"
"37.0000","-8.3131","5.82588","0.00216"
"37.5000","-8.3029","5.89328","0.00219"
"38.0000","-8.2930","5.95737","0.00222"
"38.5000","-8.2831","6.02150","0.00225"
"39.0000","-8.2730","6.08668","0.00228"
"39.5000","-8.2630","6.15244","0.00231"
"40.0000","-8.2529","6.21989","0.00234"
"40.5000","-8.2431","6.28319","0.00237"
"41.0000","-8.2329","6.35081","0.00241"
"41.5000","-8.2229","6.41598","0.00244"
"42.0000","-8.2131","6.47928","0.00247"
"42.5000","-8.2031","6.54350","0.00250"
"43.0000","-8.1931","6.60861","0.00253"
"43.5000","-8.1829","6.67530","0.00257"
"44.0000","-8.1731","6.73772","0.00260"
"44.5000","-8.1630","6.80420","0.00263"
"45.0000","-8.1527","6.87172","0.00267"
"45.5000","-8.1430","6.93338","0.00270"
"46.0000","-8.1330","6.99671","0.00273"
"46.5000","-8.1230","7.05917","0.00277"
"47.0000","-8.1131","7.12228","0.00280"
"47.5000","-8.1031","7.18437","0.00284"
"48.0000","-8.0929","7.24803","0.00287"
"48.5000","-8.0829","7.31111","0.00291"
"49.0000","-8.0730","7.37153","0.00295"
"49.5000","-8.0629","7.43256","0.00299"
"50.0000","-8.0529","7.49251","0.00303"
"50.5000","-8.0430","7.55109","0.00307"
"51.0000","-8.0333","7.60547","0.00311"
"51.5000","-8.0230","7.66402","0.00315"
"52.0000","-8.0129","7.72121","0.00320"
"52.5000","-8.0030","7.77491","0.00325"
"53.0000","-7.9929","7.82878","0.00329"
"53.5000","-7.9828","7.87988","0.00334"
"54.0000","-7.9730","7.92990","0.00339"
"54.5000","-7.9631","7.97354","0.00345"
"55.0000","-7.9530","8.01838","0.00351"
"55.5000","-7.9430","8.06357","0.00357"
"56.0000","-7.9331","8.10143","0.00364"
"56.5000","-7.9230","8.13428","0.00370"
"57.0000","-7.9130","8.17003","0.00378"
"57.5000","-7.9029","8.20102","0.00386"
"58.0000","-7.8930","8.22394","0.00394"
"58.5000","-7.8829","8.23668","0.00402"
"59.0000","-7.8729","8.26746","0.00410"
"59.5000","-7.8632","8.28170","0.00420"
"60.0000","-7.8529","8.29997","0.00430"
"60.5000","-7.8429","8.31377","0.00440"
"61.0000","-7.8331","8.32465","0.00450"
"61.5000","-7.8231","8.33478","0.00461"
"62.0000","-7.8129","8.34617","0.00472"
"62.5000","-7.8028","8.35815","0.00482"
"63.0000","-7.7930","8.36361","0.00493"
"63.5000","-7.7830","8.37229","0.00505"
"64.0000","-7.7729","8.38101","0.00516"
"64.5000","-7.7631","8.38477","0.00527"
"65.0000","-7.7531","8.38966","0.00539"
"65.5000","-7.7431","8.39602","0.00550"
"66.0000","-7.7329","8.40365","0.00562"
"66.5000","-7.7231","8.40612","0.00574"
"67.0000","-7.7128","8.41314","0.00586"
"67.5000","-7.7027","8.41957","0.00598"
"68.0000","-7.6931","8.42153","0.00609"
"68.5000","-7.6830","8.42486","0.00621"
"69.0000","-7.6730","8.42843","0.00633"
"69.5000","-7.6631","8.43238","0.00645"
"70.0000","-7.6532","8.43474","0.00657"
"70.5000","-7.6429","8.44017","0.00669"
"71.0000","-7.6328","8.44568","0.00681"
"71.5000","-7.6230","8.44759","0.00694"
"72.0000","-7.6129","8.45052","0.00706"
"72.5000","-7.6029","8.45486","0.00718"
"73.0000","-7.5930","8.45724","0.00730"
"73.5000","-7.5833","8.45586","0.00743"
"74.0000","-7.5731","8.46075","0.00755"
"74.5000","-7.5629","8.46700","0.00768"
"75.0000","-7.5530","8.46783","0.00780"
"75.5000","-7.5428","8.47149","0.00792"
"76.0000","-7.5329","8.47417","0.00805"
"76.5000","-7.5230","8.47765","0.00817"
"77.0000","-7.5130","8.47799","0.00829"
"77.5000","-7.5029","8.48167","0.00842"
"78.0000","-7.4930","8.48467","0.00854"
"78.5000","-7.4832","8.48480","0.00866"
"79.0000","-7.4729","8.48891","0.00879"
"79.5000","-7.4629","8.49202","0.00892"
"80.0000","-7.4529","8.49510","0.00904"
"80.5000","-7.4431","8.49469","0.00916"
"81.0000","-7.4330","8.49920","0.00929"
"81.5000","-7.4228","8.50314","0.00941"
"82.0000","-7.4131","8.50207","0.00953"
"82.5000","-7.4030","8.49712","0.00965"
"83.0000","-7.3929","8.50761","0.00976"
"83.5000","-7.3831","8.48248","0.00986"
"84.0000","-7.3730","8.50779","0.00996"
"84.5000","-7.3629","8.51630","0.01008"
"85.0000","-7.3529","8.52094","0.01020"
"85.5000","-7.3430","8.51967","0.01032"
"86.0000","-7.3329","8.52173","0.01044"
"86.5000","-7.3229","8.52496","0.01056"
"87.0000","-7.3131","8.52623","0.01069"
"87.5000","-7.3031","8.52614","0.01081"
"88.0000","-7.2930","8.52844","0.01093"
"88.5000","-7.2830","8.53191","0.01105"
"89.0000","-7.2732","8.53219","0.01117"
"89.5000","-7.2628","8.53828","0.01130"
"90.0000","-7.2527","8.54169","0.01142"
"90.5000","-7.2431","8.54038","0.01153"
"91.0000","-7.2331","8.54213","0.01166"
"91.5000","-7.2230","8.54486","0.01178"
"92.0000","-7.2130","8.54680","0.01190"
"92.5000","-7.2032","8.54695","0.01202"
"93.0000","-7.1930","8.55051","0.01214"
"93.5000","-7.1828","8.55587","0.01226"
"94.0000","-7.1729","8.55679","0.01238"
"94.5000","-7.1629","8.55833","0.01251"
"95.0000","-7.1529","8.56082","0.01262"
"95.5000","-7.1430","8.56289","0.01274"
"96.0000","-7.1332","8.56133","0.01286"
"96.5000","-7.1230","8.56536","0.01298"
"97.0000","-7.1129","8.56910","0.01310"
"97.5000","-7.1031","8.57002","0.01322"
"98.0000","-7.0928","8.57431","0.01334"
"98.5000","-7.0828","8.57570","0.01346"
"99.0000","-7.0730","8.57780","0.01358"
"99.5000","-7.0631","8.57737","0.01370"
"100.0000","-7.0529","8.58177","0.01382"
"100.5000","-7.0430","8.58422","0.01393"
"101.0000","-7.0331","8.58375","0.01405"
"101.5000","-7.0230","8.58666","0.01417"
"102.0000","-7.0129","8.59025","0.01429"
"102.5000","-7.0029","8.59319","0.01441"
"103.0000","-6.9931","8.59240","0.01452"
"103.5000","-6.9830","8.59570","0.01464"
"104.0000","-6.9729","8.60033","0.01476"
"104.5000","-6.9631","8.59873","0.01487"
"105.0000","-6.9529","8.60304","0.01499"
"105.5000","-6.9429","8.60476","0.01511"
"106.0000","-6.9331","8.60562","0.01522"
"106.5000","-6.9230","8.60661","0.01534"
"107.0000","-6.9129","8.60386","0.01544"
"107.5000","-6.9029","8.61439","0.01555"
"108.0000","-6.8931","8.61484","0.01567"
"108.5000","-6.8828","8.61879","0.01579"
"109.0000","-6.8728","8.62078","0.01590"
"109.5000","-6.8631","8.62030","0.01602"
"110.0000","-6.8531","8.62103","0.01613"
"110.5000","-6.8430","8.62432","0.01625"
"111.0000","-6.8329","8.62759","0.01637"
"111.5000","-6.8231","8.62693","0.01648"
"112.0000","-6.8129","8.63188","0.01660"
"112.5000","-6.8027","8.63692","0.01671"
"113.0000","-6.7930","8.63570","0.01683"
"113.5000","-6.7830","8.63690","0.01694"
"114.0000","-6.7730","8.63810","0.01706"
"114.5000","-6.7631","8.64100","0.01717"
"115.0000","-6.7531","8.64156","0.01729"
"115.5000","-6.7429","8.64519","0.01741"
"116.0000","-6.7328","8.64899","0.01752"
"116.5000","-6.7230","8.64986","0.01764"
"117.0000","-6.7129","8.65193","0.01775"
"117.5000","-6.7029","8.65470","0.01787"
"118.0000","-6.6930","8.65622","0.01798"
"118.5000","-6.6833","8.65419","0.01809"
"119.0000","-6.6730","8.65870","0.01821"
"119.5000","-6.6629","8.66239","0.01833"
"120.0000","-6.6530","8.66292","0.01844"
"120.5000","-6.6429","8.66655","0.01856"
"121.0000","-6.6328","8.66927","0.01867"
"121.5000","-6.6229","8.67096","0.01878"
"122.0000","-6.6131","8.67003","0.01890"
"122.5000","-6.6030","8.67350","0.01901"
"123.0000","-6.5930","8.67713","0.01913"
"123.5000","-6.5831","8.67646","0.01924"
"124.0000","-6.5729","8.67907","0.01935"
"124.5000","-6.5630","8.68192","0.01947"
"125.0000","-6.5529","8.68545","0.01958"
"125.5000","-6.5430","8.68506","0.01969"
"126.0000","-6.5329","8.68807","0.01981"
"126.5000","-6.5229","8.69139","0.01992"
"127.0000","-6.5132","8.68975","0.02003"
"127.5000","-6.5029","8.69509","0.02015"
"128.0000","-6.4929","8.69665","0.02026"
"128.5000","-6.4831","8.69664","0.02038"
"129.0000","-6.4731","8.69828","0.02049"
"129.5000","-6.4629","8.70204","0.02061"
"130.0000","-6.4528","8.70511","0.02072"
"130.5000","-6.4430","8.69556","0.02080"
"131.0000","-6.4329","8.70745","0.02091"
"131.5000","-6.4229","8.71259","0.02102"
"132.0000","-6.4130","8.71236","0.02113"
"132.5000","-6.4031","8.71298","0.02125"
"133.0000","-6.3931","8.71485","0.02136"
"133.5000","-6.3830","8.70796","0.02146"
"134.0000","-6.3731","8.71557","0.02157"
"134.5000","-6.3628","8.72273","0.02168"
"135.0000","-6.3527","8.72712","0.02179"
"135.5000","-6.3431","8.72610","0.02190"
"136.0000","-6.3330","8.72743","0.02201"
"136.5000","-6.3230","8.72840","0.02213"
"137.0000","-6.3131","8.73048","0.02224"
"137.5000","-6.3032","8.73102","0.02235"
"138.0000","-6.2929","8.73500","0.02246"
"138.5000","-6.2828","8.73864","0.02257"
"139.0000","-6.2729","8.73911","0.02269"
"139.5000","-6.2630","8.74040","0.02280"
"140.0000","-6.2529","8.74393","0.02291"
"140.5000","-6.2430","8.74536","0.02302"
"141.0000","-6.2332","8.74291","0.02313"
"141.5000","-6.2231","8.74645","0.02325"
"142.0000","-6.2129","8.75121","0.02336"
"142.5000","-6.2030","8.75154","0.02347"
"143.0000","-6.1928","8.75476","0.02358"
"143.5000","-6.1829","8.75676","0.02370"
"144.0000","-6.1730","8.75866","0.02381"
"144.5000","-6.1631","8.75834","0.02392"
"145.0000","-6.1529","8.76164","0.02403"
"145.5000","-6.1430","8.76383","0.02414"
"146.0000","-6.1332","8.76316","0.02425"
"146.5000","-6.1229","8.76729","0.02437"
"147.0000","-6.1129","8.76956","0.02448"
"147.5000","-6.1029","8.77184","0.02459"
"148.0000","-6.0931","8.77117","0.02470"
"148.5000","-6.0829","8.77528","0.02481"
"149.0000","-6.0728","8.77829","0.02492"
"149.5000","-6.0632","8.77656","0.02504"
"150.0000","-6.0530","8.78095","0.02515"
"150.5000","-6.0429","8.78347","0.02526"
"151.0000","-6.0330","8.78345","0.02537"
"151.5000","-6.0230","8.78434","0.02548"
"152.0000","-6.0130","8.78711","0.02560"
"152.5000","-6.0028","8.79243","0.02571"
"153.0000","-5.9930","8.79148","0.02582"
"153.5000","-5.9829","8.79414","0.02593"
"154.0000","-5.9729","8.79662","0.02604"
"154.5000","-5.9631","8.79665","0.02615"
"155.0000","-5.9530","8.79777","0.02627"
"155.5000","-5.9430","8.79995","0.02638"
"156.0000","-5.9329","8.80298","0.02649"
"156.5000","-5.9232","8.80246","0.02660"
"157.0000","-5.9129","8.80771","0.02671"
"157.5000","-5.9027","8.81202","0.02682"
"158.0000","-5.8931","8.80994","0.02693"
"158.5000","-5.8831","8.81144","0.02704"
"159.0000","-5.8730","8.81351","0.02715"
"159.5000","-5.8630","8.81514","0.02727"
"160.0000","-5.8531","8.81534","0.02738"
"160.5000","-5.8430","8.81877","0.02749"
"161.0000","-5.8328","8.82343","0.02760"
"161.5000","-5.8229","8.82404","0.02771"
"162.0000","-5.8129","8.82488","0.02783"
"162.5000","-5.8029","8.82751","0.02794"
"163.0000","-5.7930","8.82750","0.02804"
"163.5000","-5.7832","8.82129","0.02814"
"164.0000","-5.7730","8.82990","0.02825"
"164.5000","-5.7629","8.83468","0.02836"
"165.0000","-5.7531","8.83571","0.02847"
"165.5000","-5.7428","8.83949","0.02858"
"166.0000","-5.7328","8.84088","0.02869"
"166.5000","-5.7230","8.84185","0.02881"
"167.0000","-5.7131","8.84138","0.02891"
"167.5000","-5.7029","8.84507","0.02903"
"168.0000","-5.6929","8.84730","0.02914"
"168.5000","-5.6831","8.84619","0.02925"
"169.0000","-5.6730","8.84904","0.02936"
"169.5000","-5.6629","8.85218","0.02947"
"170.0000","-5.6528","8.85462","0.02958"
"170.5000","-5.6431","8.85318","0.02969"
"171.0000","-5.6330","8.85655","0.02980"
"171.5000","-5.6229","8.86093","0.02991"
"172.0000","-5.6131","8.85842","0.03002"
"172.5000","-5.6029","8.86252","0.03013"
"173.0000","-5.5929","8.86405","0.03025"
"173.5000","-5.5831","8.86423","0.03035"
"174.0000","-5.5730","8.86562","0.03047"
"174.5000","-5.5629","8.86822","0.03058"
"175.0000","-5.5528","8.87259","0.03069"
"175.5000","-5.5431","8.87111","0.03080"
"176.0000","-5.5329","8.87507","0.03091"
"176.5000","-5.5228","8.87705","0.03102"
"177.0000","-5.5131","8.87601","0.03113"
"177.5000","-5.5031","8.87696","0.03124"
"178.0000","-5.4930","8.88010","0.03135"
"178.5000","-5.4829","8.88297","0.03146"
"179.0000","-5.4731","8.88186","0.03157"
"179.5000","-5.4629","8.88610","0.03168"
"180.0000","-5.4527","8.89068","0.03180"
"180.5000","-5.4430","8.86238","0.03189"
"181.0000","-5.4330","8.88290","0.03199"
"181.5000","-5.4230","8.89064","0.03209"
"182.0000","-5.4131","8.89448","0.03220"
"182.5000","-5.4031","8.89501","0.03231"
"183.0000","-5.3929","8.89797","0.03243"
"183.5000","-5.3829","8.90093","0.03253"
"184.0000","-5.3730","8.90146","0.03264"
"184.5000","-5.3628","8.90327","0.03276"
"185.0000","-5.3528","8.90504","0.03287"
"185.5000","-5.3430","8.90581","0.03298"
"186.0000","-5.3333","8.90337","0.03309"
"186.5000","-5.3231","8.90712","0.03320"
"187.0000","-5.3128","8.91140","0.03331"
"187.5000","-5.3030","8.91134","0.03342"
"188.0000","-5.2929","8.91418","0.03353"
"188.5000","-5.2828","8.91642","0.03364"
"189.0000","-5.2729","8.91738","0.03375"
"189.5000","-5.2630","8.91654","0.03386"
"190.0000","-5.2530","8.91917","0.03397"
"190.5000","-5.2430","8.92219","0.03408"
"191.0000","-5.2331","8.92105","0.03419"
"191.5000","-5.2229","8.92395","0.03431"
"192.0000","-5.2129","8.92654","0.03442"
"192.5000","-5.2029","8.92863","0.03453"
"193.0000","-5.1930","8.92761","0.03464"
"193.5000","-5.1830","8.93049","0.03475"
"194.0000","-5.1728","8.93381","0.03486"
"194.5000","-5.1632","8.93229","0.03497"
"195.0000","-5.1529","8.93621","0.03508"
"195.5000","-5.1429","8.93729","0.03519"
"196.0000","-5.1331","8.93693","0.03530"
"196.5000","-5.1231","8.93816","0.03541"
"197.0000","-5.1128","8.94262","0.03553"
"197.5000","-5.1028","8.94539","0.03564"
"198.0000","-5.0931","8.93101","0.03574"
"198.5000","-5.0830","8.94134","0.03584"
"199.0000","-5.0729","8.94871","0.03595"
"199.5000","-5.0630","8.94984","0.03606"
"200.0000","-5.0531","8.94959","0.03617"
"200.5000","-5.0431","8.95144","0.03628"
"201.0000","-5.0330","8.95498","0.03639"
"201.5000","-5.0231","8.95406","0.03650"
"202.0000","-5.0128","8.95877","0.03661"
"202.5000","-5.0027","8.96151","0.03673"
"203.0000","-4.9931","8.95945","0.03684"
"203.5000","-4.9830","8.96082","0.03695"
"204.0000","-4.9730","8.96207","0.03706"
"204.5000","-4.9631","8.96335","0.03717"
"205.0000","-4.9532","8.96331","0.03728"
"205.5000","-4.9429","8.96716","0.03739"
"206.0000","-4.9328","8.97045","0.03750"
"206.5000","-4.9229","8.97043","0.03761"
"207.0000","-4.9129","8.97153","0.03772"
"207.5000","-4.9029","8.97410","0.03784"
"208.0000","-4.8930","8.97452","0.03795"
"208.5000","-4.8832","8.97224","0.03805"
"209.0000","-4.8731","8.97564","0.03817"
"209.5000","-4.8629","8.97984","0.03828"
"210.0000","-4.8530","8.97976","0.03839"
"210.5000","-4.8428","8.98270","0.03850"
"211.0000","-4.8328","8.98365","0.03861"
"211.5000","-4.8230","8.98509","0.03872"
"212.0000","-4.8131","8.98453","0.03883"
"212.5000","-4.8029","8.98729","0.03895"
"213.0000","-4.7930","8.98893","0.03905"
"213.5000","-4.7832","8.98798","0.03916"
"214.0000","-4.7729","8.99111","0.03928"
"214.5000","-4.7629","8.99281","0.03939"
"215.0000","-4.7529","8.99526","0.03950"
"215.5000","-4.7431","8.99402","0.03961"
"216.0000","-4.7329","8.99738","0.03972"
"216.5000","-4.7228","9.00019","0.03984"
"217.0000","-4.7132","8.99767","0.03995"
"217.5000","-4.7030","9.00151","0.04006"
"218.0000","-4.6929","9.00348","0.04017"
"218.5000","-4.6830","9.00302","0.04028"
"219.0000","-4.6730","9.00339","0.04039"
"219.5000","-4.6630","9.00563","0.04050"
"220.0000","-4.6528","9.01067","0.04061"
"220.5000","-4.6430","9.00896","0.04072"
"221.0000","-4.6329","9.01133","0.04084"
"221.5000","-4.6229","9.01283","0.04095"
"222.0000","-4.6131","9.01222","0.04106"
"222.5000","-4.6031","9.01317","0.04117"
"223.0000","-4.5930","9.01509","0.04128"
"223.5000","-4.5829","9.01731","0.04140"
"224.0000","-4.5732","9.01625","0.04150"
"224.5000","-4.5628","9.02125","0.04162"
"225.0000","-4.5527","9.02460","0.04173"
"225.5000","-4.5431","9.02196","0.04184"
"226.0000","-4.5331","9.02327","0.04195"
"226.5000","-4.5230","9.02470","0.04206"
"227.0000","-4.5130","9.02592","0.04217"
"227.5000","-4.5031","9.02526","0.04228"
"228.0000","-4.4930","9.02817","0.04240"
"228.5000","-4.4828","9.03245","0.04251"
"229.0000","-4.4729","9.03231","0.04262"
"229.5000","-4.4629","9.03303","0.04273"
"230.0000","-4.4529","9.03503","0.04285"
"230.5000","-4.4430","9.03609","0.04296"
"231.0000","-4.4332","9.03328","0.04307"
"231.5000","-4.4231","9.03646","0.04318"
"232.0000","-4.4129","9.03974","0.04329"
"232.5000","-4.4031","9.03969","0.04340"
"233.0000","-4.3928","9.04297","0.04352"
"233.5000","-4.3828","9.04384","0.04363"
"234.0000","-4.3730","9.04463","0.04374"
"234.5000","-4.3632","9.04361","0.04385"
"235.0000","-4.3529","9.04704","0.04396"
"235.5000","-4.3429","9.04847","0.04408"
"236.0000","-4.3331","9.04683","0.04419"
"236.5000","-4.3230","9.04900","0.04430"
"237.0000","-4.3129","9.05171","0.04441"
"237.5000","-4.3029","9.05365","0.04452"
"238.0000","-4.2931","9.05203","0.04464"
"238.5000","-4.2830","9.05488","0.04475"
"239.0000","-4.2728","9.05841","0.04486"
"239.5000","-4.2631","9.05518","0.04497"
"240.0000","-4.2529","9.05920","0.04509"
"240.5000","-4.2429","9.06012","0.04520"
"241.0000","-4.2331","9.05967","0.04531"
"241.5000","-4.2230","9.06062","0.04542"
"242.0000","-4.2129","9.06279","0.04554"
"242.5000","-4.2028","9.06600","0.04565"
"243.0000","-4.1931","9.06430","0.04576"
"243.5000","-4.1829","9.06781","0.04587"
"244.0000","-4.1729","9.06898","0.04598"
"244.5000","-4.1631","9.06781","0.04610"
"245.0000","-4.1531","9.06815","0.04621"
"245.5000","-4.1430","9.05601","0.04630"
"246.0000","-4.1329","9.06796","0.04641"
"246.5000","-4.1231","9.07062","0.04652"
"247.0000","-4.1129","9.07563","0.04663"
"247.5000","-4.1027","9.08022","0.04675"
"248.0000","-4.0930","9.07775","0.04686"
"248.5000","-4.0830","9.07750","0.04697"
"249.0000","-4.0730","9.07766","0.04708"
"249.5000","-4.0631","9.07993","0.04719"
"250.0000","-4.0531","9.07950","0.04730"
"250.5000","-4.0429","9.08188","0.04742"
"251.0000","-4.0328","9.08477","0.04753"
"251.5000","-4.0230","9.08471","0.04764"
"252.0000","-4.0129","9.08589","0.04776"
"252.5000","-4.0029","9.08718","0.04787"
"253.0000","-3.9930","9.08754","0.04798"
"253.5000","-3.9833","9.08478","0.04809"
"254.0000","-3.9730","9.08847","0.04821"
"254.5000","-3.9628","9.09141","0.04832"
"255.0000","-3.9531","9.09023","0.04843"
"255.5000","-3.9429","9.07526","0.04852"
"256.0000","-3.9328","9.09065","0.04862"
"256.5000","-3.9229","9.09517","0.04873"
"257.0000","-3.9131","9.09477","0.04884"
"257.5000","-3.9030","9.09728","0.04896"
"258.0000","-3.8930","9.09976","0.04907"
"258.5000","-3.8831","9.09789","0.04918"
"259.0000","-3.8729","9.09979","0.04929"
"259.5000","-3.8629","9.10122","0.04941"
"260.0000","-3.8529","9.10317","0.04952"
"260.5000","-3.8430","9.10189","0.04963"
"261.0000","-3.8329","9.10396","0.04974"
"261.5000","-3.8229","9.10590","0.04986"
"262.0000","-3.8132","9.10342","0.04997"
"262.5000","-3.8029","9.10755","0.05008"
"263.0000","-3.7929","9.10817","0.05019"
"263.5000","-3.7831","9.10709","0.05031"
"264.0000","-3.7731","9.10754","0.05042"
"264.5000","-3.7629","9.11023","0.05054"
"265.0000","-3.7528","9.11330","0.05065"
"265.5000","-3.7430","9.11133","0.05076"
"266.0000","-3.7329","9.11279","0.05088"
"266.5000","-3.7229","9.11523","0.05099"
"267.0000","-3.7130","9.11429","0.05110"
"267.5000","-3.7031","9.11400","0.05121"
"268.0000","-3.6931","9.11521","0.05133"
"268.5000","-3.6829","9.11847","0.05144"
"269.0000","-3.6731","9.11676","0.05155"
"269.5000","-3.6628","9.12030","0.05167"
"270.0000","-3.6527","9.12333","0.05178"
"270.5000","-3.6431","9.12081","0.05190"
"271.0000","-3.6330","9.12192","0.05201"
"271.5000","-3.6230","9.12199","0.05212"
"272.0000","-3.6131","9.12269","0.05223"
"272.5000","-3.6032","9.12237","0.05235"
"273.0000","-3.5929","9.12586","0.05247"
"273.5000","-3.5828","9.12811","0.05258"
"274.0000","-3.5729","9.12740","0.05270"
"274.5000","-3.5630","9.12791","0.05281"
"275.0000","-3.5529","9.13047","0.05292"
"275.5000","-3.5430","9.13006","0.05304"
"276.0000","-3.5333","9.12709","0.05315"
"276.5000","-3.5231","9.12982","0.05326"
"277.0000","-3.5129","9.13368","0.05338"
"277.5000","-3.5030","9.13300","0.05349"
"278.0000","-3.4929","9.13496","0.05361"
"278.5000","-3.4828","9.13581","0.05372"
"279.0000","-3.4730","9.13630","0.05383"
"279.5000","-3.4631","9.13525","0.05395"
"280.0000","-3.4529","9.13744","0.05406"
"280.5000","-3.4430","9.13871","0.05418"
"281.0000","-3.4332","9.13704","0.05429"
"281.5000","-3.4229","9.14002","0.05441"
"282.0000","-3.4129","9.14115","0.05452"
"282.5000","-3.4029","9.14249","0.05464"
"283.0000","-3.3931","9.14015","0.05475"
"283.5000","-3.3829","9.14361","0.05487"
"284.0000","-3.3728","9.14553","0.05498"
"284.5000","-3.3632","9.14230","0.05510"
"285.0000","-3.3530","9.14575","0.05521"
"285.5000","-3.3429","9.14752","0.05533"
"286.0000","-3.3330","9.14579","0.05544"
"286.5000","-3.3231","9.14562","0.05556"
"287.0000","-3.3130","9.14776","0.05567"
"287.5000","-3.3028","9.15182","0.05579"
"288.0000","-3.2930","9.14901","0.05590"
"288.5000","-3.2829","9.15127","0.05602"
"289.0000","-3.2729","9.15229","0.05613"
"289.5000","-3.2631","9.15103","0.05625"
"290.0000","-3.2530","9.15147","0.05636"
"290.5000","-3.2430","9.15241","0.05648"
"291.0000","-3.2329","9.15428","0.05659"
"291.5000","-3.2232","9.15253","0.05671"
"292.0000","-3.2128","9.15688","0.05683"
"292.5000","-3.2027","9.15935","0.05694"
"293.0000","-3.1931","9.15674","0.05705"
"293.5000","-3.1831","9.15703","0.05717"
"294.0000","-3.1730","9.15811","0.05728"
"294.5000","-3.1630","9.15827","0.05740"
"295.0000","-3.1531","9.15753","0.05752"
"295.5000","-3.1430","9.15965","0.05763"
"296.0000","-3.1328","9.16331","0.05775"
"296.5000","-3.1229","9.16269","0.05786"
"297.0000","-3.1129","9.16297","0.05798"
"297.5000","-3.1029","9.16407","0.05809"
"298.0000","-3.0930","9.16466","0.05821"
"298.5000","-3.0832","9.16136","0.05833"
"299.0000","-3.0731","9.16333","0.05844"
"299.5000","-3.0629","9.16667","0.05856"
"300.0000","-3.0531","9.16603","0.05867"
"300.5000","-3.0428","9.16822","0.05879"
"301.0000","-3.0328","9.16867","0.05891"
"301.5000","-3.0230","9.16836","0.05902"
"302.0000","-3.0131","9.16759","0.05914"
"302.5000","-3.0029","9.17023","0.05926"
"303.0000","-2.9930","9.17066","0.05937"
"303.5000","-2.9832","9.16834","0.05949"
"304.0000","-2.9730","9.17063","0.05961"
"304.5000","-2.9629","9.17300","0.05972"
"305.0000","-2.9529","9.17377","0.05984"
"305.5000","-2.9431","9.17116","0.05995"
"306.0000","-2.9330","9.17298","0.06007"
"306.5000","-2.9228","9.17617","0.06019"
"307.0000","-2.9131","9.17368","0.06030"
"307.5000","-2.9029","9.17591","0.06042"
"308.0000","-2.8929","9.17607","0.06054"
"308.5000","-2.8832","9.17495","0.06065"
"309.0000","-2.8730","9.17555","0.06077"
"309.5000","-2.8629","9.17804","0.06089"
"310.0000","-2.8529","9.17996","0.06100"
"310.5000","-2.8431","9.17742","0.06112"
"311.0000","-2.8329","9.17991","0.06124"
"311.5000","-2.8228","9.18078","0.06135"
"312.0000","-2.8130","9.18012","0.06147"
"312.5000","-2.8032","9.17906","0.06159"
"313.0000","-2.7931","9.18087","0.06170"
"313.5000","-2.7829","9.18239","0.06182"
"314.0000","-2.7731","9.18060","0.06194"
"314.5000","-2.7629","9.18432","0.06206"
"315.0000","-2.7527","9.18745","0.06218"
"315.5000","-2.7430","9.18419","0.06229"
"316.0000","-2.7330","9.18373","0.06241"
"316.5000","-2.7230","9.18407","0.06253"
"317.0000","-2.7131","9.18516","0.06265"
"317.5000","-2.7031","9.18408","0.06276"
"318.0000","-2.6929","9.18631","0.06288"
"318.5000","-2.6828","9.18885","0.06300"
"319.0000","-2.6730","9.18819","0.06312"
"319.5000","-2.6629","9.18895","0.06324"
"320.0000","-2.6528","9.18964","0.06336"
"320.5000","-2.6430","9.18879","0.06347"
"321.0000","-2.6333","9.18579","0.06359"
"321.5000","-2.6230","9.18930","0.06371"
"322.0000","-2.6129","9.19133","0.06383"
"322.5000","-2.6031","9.18978","0.06394"
"323.0000","-2.5929","9.19205","0.06407"
"323.5000","-2.5828","9.19327","0.06419"
"324.0000","-2.5729","9.19324","0.06430"
"324.5000","-2.5631","9.19103","0.06442"
"325.0000","-2.5530","9.19269","0.06454"
"325.5000","-2.5430","9.19419","0.06466"
"326.0000","-2.5331","9.19227","0.06478"
"326.5000","-2.5229","9.19376","0.06490"
"327.0000","-2.5129","9.19496","0.06501"
"327.5000","-2.5029","9.19654","0.06513"
"328.0000","-2.4930","9.19484","0.06525"
"328.5000","-2.4829","9.19594","0.06537"
"329.0000","-2.4729","9.19776","0.06549"
"329.5000","-2.4632","9.19478","0.06561"
"330.0000","-2.4529","9.19835","0.06573"
"330.5000","-2.4429","9.19868","0.06585"
"331.0000","-2.4331","9.19686","0.06597"
"331.5000","-2.4231","9.19668","0.06609"
"332.0000","-2.4129","9.19903","0.06621"
"332.5000","-2.4028","9.20164","0.06633"
"333.0000","-2.3931","9.19878","0.06644"
"333.5000","-2.3829","9.20053","0.06657"
"334.0000","-2.3729","9.20220","0.06669"
"334.5000","-2.3631","9.20040","0.06680"
"335.0000","-2.3531","9.19958","0.06692"
"335.5000","-2.3431","9.20052","0.06705"
"336.0000","-2.3329","9.20280","0.06717"
"336.5000","-2.3231","9.20058","0.06729"
"337.0000","-2.3128","9.20359","0.06741"
"337.5000","-2.3027","9.20598","0.06753"
"338.0000","-2.2931","9.20289","0.06765"
"338.5000","-2.2830","9.20348","0.06777"
"339.0000","-2.2730","9.20326","0.06789"
"339.5000","-2.2631","9.20356","0.06800"
"340.0000","-2.2532","9.20246","0.06813"
"340.5000","-2.2429","9.20526","0.06825"
"341.0000","-2.2328","9.20714","0.06837"
"341.5000","-2.2230","9.20586","0.06849"
"342.0000","-2.2130","9.20606","0.06861"
"342.5000","-2.2029","9.20818","0.06873"
"343.0000","-2.1930","9.20740","0.06885"
"343.5000","-2.1833","9.20334","0.06897"
"344.0000","-2.1731","9.20553","0.06909"
"344.5000","-2.1629","9.20882","0.06921"
"345.0000","-2.1530","9.20742","0.06933"
"345.5000","-2.1428","9.20902","0.06946"
"346.0000","-2.1328","9.20933","0.06958"
"346.5000","-2.1230","9.20954","0.06970"
"347.0000","-2.1131","9.20764","0.06982"
"347.5000","-2.1029","9.20919","0.06994"
"348.0000","-2.0930","9.21008","0.07006"
"348.5000","-2.0832","9.20771","0.07018"
"349.0000","-2.0729","9.20999","0.07031"
"349.5000","-2.0629","9.21062","0.07043"
"350.0000","-2.0529","9.21135","0.07055"
"350.5000","-2.0431","9.20894","0.07067"
"351.0000","-2.0329","9.21166","0.07079"
"351.5000","-2.0228","9.21292","0.07091"
"352.0000","-2.0132","9.20876","0.07103"
"352.5000","-2.0030","9.21202","0.07116"
"353.0000","-1.9929","9.21299","0.07128"
"353.5000","-1.9830","9.21106","0.07140"
"354.0000","-1.9730","9.21061","0.07152"
"354.5000","-1.9630","9.21147","0.07165"
"355.0000","-1.9528","9.21523","0.07177"
"355.5000","-1.9430","9.21253","0.07189"
"356.0000","-1.9329","9.21390","0.07201"
"356.5000","-1.9229","9.21428","0.07213"
"357.0000","-1.9131","9.21256","0.07225"
"357.5000","-1.9030","9.21248","0.07238"
"358.0000","-1.8930","9.21279","0.07250"
"358.5000","-1.8830","9.21416","0.07262"
"359.0000","-1.8732","9.21198","0.07275"
"359.5000","-1.8629","9.21573","0.07287"
"360.0000","-1.8527","9.21817","0.07299"
"360.5000","-1.8431","9.21449","0.07311"
"361.0000","-1.8331","9.21415","0.07323"
"361.5000","-1.8230","9.21465","0.07336"
"362.0000","-1.8130","9.21478","0.07348"
"362.5000","-1.8031","9.21331","0.07360"
"363.0000","-1.7930","9.21486","0.07373"
"363.5000","-1.7828","9.21779","0.07385"
"364.0000","-1.7729","9.21675","0.07397"
"364.5000","-1.7629","9.21623","0.07410"
"365.0000","-1.7529","9.21663","0.07422"
"365.5000","-1.7430","9.21689","0.07434"
"366.0000","-1.7332","9.21318","0.07447"
"366.5000","-1.7230","9.21485","0.07459"
"367.0000","-1.7129","9.21701","0.07471"
"367.5000","-1.7031","9.21568","0.07483"
"368.0000","-1.6928","9.21812","0.07496"
"368.5000","-1.6828","9.21823","0.07508"
"369.0000","-1.6730","9.21753","0.07521"
"369.5000","-1.6631","9.21553","0.07533"
"370.0000","-1.6529","9.21803","0.07545"
"370.5000","-1.6429","9.21824","0.07558"
"371.0000","-1.6331","9.21546","0.07570"
"371.5000","-1.6230","9.21689","0.07582"
"372.0000","-1.6129","9.21828","0.07595"
"372.5000","-1.6029","9.21857","0.07607"
"373.0000","-1.5931","9.21620","0.07619"
"373.5000","-1.5830","9.21793","0.07632"
"374.0000","-1.5729","9.21995","0.07645"
"374.5000","-1.5631","9.21642","0.07657"
"375.0000","-1.5529","9.21874","0.07669"
"375.5000","-1.5429","9.21842","0.07682"
"376.0000","-1.5331","9.21680","0.07694"
"376.5000","-1.5230","9.21701","0.07707"
"377.0000","-1.5129","9.21805","0.07719"
"377.5000","-1.5029","9.22008","0.07731"
"378.0000","-1.4931","9.21752","0.07743"
"378.5000","-1.4829","9.21933","0.07756"
"379.0000","-1.4728","9.21979","0.07769"
"379.5000","-1.4631","9.21746","0.07781"
"380.0000","-1.4531","9.21631","0.07793"
"380.5000","-1.4430","9.21787","0.07806"
"381.0000","-1.4329","9.21901","0.07818"
"381.5000","-1.4231","9.21611","0.07830"
"382.0000","-1.4129","9.21881","0.07843"
"382.5000","-1.4027","9.22250","0.07856"
"383.0000","-1.3930","9.21871","0.07868"
"383.5000","-1.3830","9.21778","0.07880"
"384.0000","-1.3730","9.21748","0.07893"
"384.5000","-1.3631","9.21808","0.07905"
"385.0000","-1.3531","9.21657","0.07917"
"385.5000","-1.3429","9.21825","0.07930"
"386.0000","-1.3328","9.22002","0.07942"
"386.5000","-1.3230","9.21868","0.07955"
"387.0000","-1.3129","9.21879","0.07967"
"387.5000","-1.3029","9.21956","0.07980"
"388.0000","-1.2930","9.21832","0.07992"
"388.5000","-1.2833","9.21465","0.08004"
"389.0000","-1.2730","9.21714","0.08017"
"389.5000","-1.2629","9.21870","0.08029"
"390.0000","-1.2531","9.21732","0.08042"
"390.5000","-1.2429","9.21873","0.08054"
"391.0000","-1.2328","9.21960","0.08067"
"391.5000","-1.2229","9.21873","0.08079"
"392.0000","-1.2131","9.21597","0.08091"
"392.5000","-1.2030","9.21706","0.08104"
"393.0000","-1.1930","9.21854","0.08116"
"393.5000","-1.1831","9.21589","0.08128"
"394.0000","-1.1730","9.21688","0.08141"
"394.5000","-1.1629","9.21757","0.08153"
"395.0000","-1.1529","9.21854","0.08165"
"395.5000","-1.1430","9.21571","0.08178"
"396.0000","-1.1329","9.21705","0.08190"
"396.5000","-1.1229","9.21818","0.08202"
"397.0000","-1.1133","9.21434","0.08214"
"397.5000","-1.1029","9.21760","0.08227"
"398.0000","-1.0929","9.21741","0.08239"
"398.5000","-1.0831","9.21478","0.08251"
"399.0000","-1.0731","9.21452","0.08264"
"399.5000","-1.0629","9.21616","0.08276"
"400.0000","-1.0528","9.21840","0.08288"
"400.5000","-1.0430","9.21472","0.08300"
"401.0000","-1.0330","9.21578","0.08312"
"401.5000","-1.0229","9.21700","0.08325"
"402.0000","-1.0131","9.21457","0.08337"
"402.5000","-1.0031","9.21353","0.08349"
"403.0000","-0.9931","9.21379","0.08361"
"403.5000","-0.9829","9.21570","0.08373"
"404.0000","-0.9731","9.21283","0.08385"
"404.5000","-0.9628","9.21538","0.08398"
"405.0000","-0.9527","9.21695","0.08410"
"405.5000","-0.9431","9.21356","0.08422"
"406.0000","-0.9330","9.21365","0.08434"
"406.5000","-0.9230","9.21268","0.08446"
"407.0000","-0.9131","9.21184","0.08458"
"407.5000","-0.9032","9.21041","0.08469"
"408.0000","-0.8929","9.21290","0.08482"
"408.5000","-0.8828","9.21419","0.08493"
"409.0000","-0.8730","9.21230","0.08505"
"409.5000","-0.8629","9.21193","0.08517"
"410.0000","-0.8529","9.21275","0.08529"
"410.5000","-0.8430","9.21156","0.08541"
"411.0000","-0.8333","9.20698","0.08552"
"411.5000","-0.8231","9.20848","0.08564"
"412.0000","-0.8129","9.21185","0.08576"
"412.5000","-0.8030","9.20983","0.08587"
"413.0000","-0.7928","9.21039","0.08599"
"413.5000","-0.7829","9.20994","0.08611"
"414.0000","-0.7730","9.20926","0.08622"
"414.5000","-0.7630","9.20747","0.08633"
"415.0000","-0.7529","9.20816","0.08645"
"415.5000","-0.7430","9.20771","0.08656"
"416.0000","-0.7332","9.20508","0.08667"
"416.5000","-0.7229","9.20674","0.08679"
"417.0000","-0.7128","9.20698","0.08690"
"417.5000","-0.7029","9.20681","0.08701"
"418.0000","-0.6931","9.20342","0.08712"
"418.5000","-0.6830","9.20514","0.08723"
"419.0000","-0.6728","9.20613","0.08734"
"419.5000","-0.6631","9.20177","0.08745"
"420.0000","-0.6530","9.20354","0.08756"
"420.5000","-0.6429","9.20373","0.08767"
"421.0000","-0.6331","9.20067","0.08777"
"421.5000","-0.6231","9.19937","0.08788"
"422.0000","-0.6129","9.20090","0.08799"
"422.5000","-0.6028","9.20265","0.08809"
"423.0000","-0.5930","9.19890","0.08819"
"423.5000","-0.5829","9.19901","0.08830"
"424.0000","-0.5729","9.19884","0.08840"
"424.5000","-0.5631","9.19716","0.08850"
"425.0000","-0.5531","9.19531","0.08860"
"425.5000","-0.5430","9.19473","0.08870"
"426.0000","-0.5330","9.19482","0.08880"
"426.5000","-0.5231","9.19202","0.08889"
"427.0000","-0.5128","9.19518","0.08899"
"427.5000","-0.5027","9.19557","0.08909"
"428.0000","-0.4931","9.19063","0.08918"
"428.5000","-0.4831","9.18945","0.08927"
"429.0000","-0.4730","9.18929","0.08937"
"429.5000","-0.4630","9.18778","0.08946"
"430.0000","-0.4531","9.18469","0.08955"
"430.5000","-0.4430","9.18490","0.08963"
"431.0000","-0.4328","9.18704","0.08973"
"431.5000","-0.4229","9.18451","0.08981"
"432.0000","-0.4129","9.18263","0.08989"
"432.5000","-0.4029","9.18156","0.08998"
"433.0000","-0.3930","9.17988","0.09006"
"433.5000","-0.3832","9.17458","0.09014"
"434.0000","-0.3730","9.17498","0.09022"
"434.5000","-0.3629","9.17535","0.09030"
"435.0000","-0.3531","9.17192","0.09037"
"435.5000","-0.3428","9.17270","0.09045"
"436.0000","-0.3328","9.17076","0.09052"
"436.5000","-0.3230","9.16788","0.09059"
"437.0000","-0.3131","9.16422","0.09067"
"437.5000","-0.3029","9.16410","0.09074"
"438.0000","-0.2929","9.16181","0.09080"
"438.5000","-0.2831","9.15703","0.09087"
"439.0000","-0.2730","9.15564","0.09094"
"439.5000","-0.2629","9.15513","0.09100"
"440.0000","-0.2529","9.15323","0.09106"
"440.5000","-0.2431","9.14760","0.09112"
"441.0000","-0.2330","9.14620","0.09118"
"441.5000","-0.2228","9.14620","0.09124"
"442.0000","-0.2131","9.13941","0.09130"
"442.5000","-0.2029","9.13840","0.09135"
"443.0000","-0.1929","9.13495","0.09141"
"443.5000","-0.1831","9.13055","0.09146"
"444.0000","-0.1730","9.12681","0.09151"
"444.5000","-0.1629","9.12443","0.09156"
"445.0000","-0.1528","9.12331","0.09161"
"445.5000","-0.1431","9.11647","0.09166"
"446.0000","-0.1329","9.11446","0.09171"
"446.5000","-0.1228","9.11084","0.09175"
"447.0000","-0.1131","9.10424","0.09180"
"447.5000","-0.1031","9.09873","0.09184"
"448.0000","-0.0930","9.09611","0.09188"
"448.5000","-0.0829","9.09240","0.09192"
"449.0000","-0.0731","9.08468","0.09196"
"449.5000","-0.0629","9.08304","0.09200"
"450.0000","-0.0527","9.08125","0.09204"
"450.5000","-0.0430","9.07214","0.09208"
"451.0000","-0.0330","9.06593","0.09211"
"451.5000","-0.0230","9.05977","0.09215"
"452.0000","-0.0131","9.05522","0.09218"
"452.5000","-0.0031","9.04747","0.09221"
"453.0000","0.0071","9.04289","0.09225"
"453.5000","0.0172","9.03900","0.09228"
"454.0000","0.0270","9.03134","0.09231"
"454.5000","0.0371","9.02446","0.09234"
"455.0000","0.0472","9.01850","0.09237"
"455.5000","0.0570","9.01097","0.09240"
"456.0000","0.0667","8.99992","0.09242"
"456.5000","0.0770","8.99531","0.09245"
"457.0000","0.0871","8.98930","0.09247"
"457.5000","0.0970","8.97993","0.09250"
"458.0000","0.1071","8.97406","0.09252"
"458.5000","0.1172","8.96668","0.09255"
"459.0000","0.1271","8.95783","0.09257"
"459.5000","0.1369","8.94664","0.09259"
"460.0000","0.1470","8.93933","0.09261"
"460.5000","0.1570","8.93258","0.09263"
"461.0000","0.1669","8.92029","0.09265"
"461.5000","0.1771","8.91214","0.09267"
"462.0000","0.1871","8.90361","0.09268"
"462.5000","0.1971","8.89548","0.09270"
"463.0000","0.2070","8.88268","0.09272"
"463.5000","0.2171","8.87423","0.09273"
"464.0000","0.2271","8.86559","0.09274"
"464.5000","0.2368","8.85163","0.09276"
"465.0000","0.2471","8.84419","0.09277"
"465.5000","0.2571","8.83254","0.09278"
"466.0000","0.2669","8.82019","0.09279"
"466.5000","0.2769","8.80857","0.09280"
"467.0000","0.2871","8.79835","0.09281"
"467.5000","0.2972","8.78949","0.09282"
"468.0000","0.3070","8.77494","0.09283"
"468.5000","0.3171","8.76345","0.09284"
"469.0000","0.3271","8.75337","0.09285"
"469.5000","0.3369","8.73824","0.09285"
"470.0000","0.3469","8.72448","0.09286"
"470.5000","0.3569","8.71237","0.09286"
"471.0000","0.3671","8.70124","0.09287"
"471.5000","0.3769","8.68496","0.09287"
"472.0000","0.3872","8.67447","0.09288"
"472.5000","0.3973","8.66314","0.09288"
"473.0000","0.4069","8.64695","0.09288"
"473.5000","0.4170","8.63117","0.09288"
"474.0000","0.4270","8.61590","0.09288"
"474.5000","0.4369","8.60235","0.09288"
"475.0000","0.4468","8.58595","0.09288"
"475.5000","0.4571","8.57255","0.09288"
"476.0000","0.4672","8.55951","0.09289"
"476.5000","0.4771","8.54258","0.09288"
"477.0000","0.4871","8.52619","0.09288"
"477.5000","0.4971","8.51164","0.09288"
"478.0000","0.5070","8.49466","0.09287"
"478.5000","0.5168","8.47360","0.09287"
"479.0000","0.5269","8.45859","0.09286"
"479.5000","0.5371","8.44392","0.09286"
"480.0000","0.5470","8.42462","0.09285"
"480.5000","0.5572","8.40819","0.09284"
"481.0000","0.5671","8.39018","0.09284"
"481.5000","0.5770","8.37287","0.09283"
"482.0000","0.5869","8.35093","0.09282"
"482.5000","0.5971","8.33321","0.09281"
"483.0000","0.6070","8.31517","0.09280"
"483.5000","0.6168","8.29312","0.09279"
"484.0000","0.6271","8.27329","0.09278"
"484.5000","0.6371","8.25347","0.09277"
"485.0000","0.6471","8.23376","0.09276"
"485.5000","0.6569","8.21039","0.09275"
"486.0000","0.6671","8.19019","0.09274"
"486.5000","0.6771","8.16942","0.09273"
"487.0000","0.6868","8.14365","0.09272"
"487.5000","0.6970","8.12226","0.09271"
"488.0000","0.7071","8.09871","0.09270"
"488.5000","0.7169","8.07279","0.09268"
"489.0000","0.7270","8.04650","0.09267"
"489.5000","0.7370","8.02156","0.09265"
"490.0000","0.7472","8.00018","0.09264"
"490.5000","0.7570","7.97013","0.09263"
"491.0000","0.7671","7.94248","0.09261"
"491.5000","0.7771","7.91542","0.09260"
"492.0000","0.7869","7.88456","0.09258"
"492.5000","0.7970","7.85146","0.09256"
"493.0000","0.8070","7.81974","0.09254"
"493.5000","0.8171","7.78820","0.09253"
"494.0000","0.8268","7.75078","0.09250"
"494.5000","0.8372","7.71264","0.09248"
"495.0000","0.8473","7.67494","0.09246"
"495.5000","0.8570","7.63195","0.09244"
"496.0000","0.8670","7.58542","0.09241"
"496.5000","0.8770","7.53650","0.09238"
"497.0000","0.8870","7.47924","0.09234"
"497.5000","0.8969","7.41137","0.09230"
"498.0000","0.9070","7.34277","0.09225"
"498.5000","0.9172","7.25479","0.09219"
"499.0000","0.9272","7.06119","0.09205"
"499.1210","0.9296","6.54990","0.09255"
"499.1260","0.9298","5.79213","0.09362"
"499.1280","0.9299","5.42762","0.09396"