File: Coupon Test Data/Tensile Test_Neebajan_Alan_19.csv
Time,Displacement,Force,Strain 1
(s),(mm),(kN),(mm/mm)
"0.0000","0.0000","0.20874","-0.00010"
"0.4000","0.0063","0.27687","-0.00007"
"0.8000","0.0144","0.37012","-0.00002"
"1.2000","0.0226","0.46238","0.00002"
"1.6000","0.0304","0.54918","0.00007"
"2.0000","0.0384","0.63690","0.00011"
"2.4000","0.0464","0.72009","0.00015"
"2.8000","0.0545","0.80609","0.00020"
"3.2000","0.0625","0.88155","0.00023"
"3.6000","0.0705","0.96346","0.00027"
"4.0000","0.0786","1.04741","0.00031"
"4.4000","0.0864","1.12012","0.00035"
"4.8000","0.0944","1.19815","0.00039"
"5.2000","0.1025","1.27153","0.00043"
"5.6000","0.1106","1.34933","0.00047"
"6.0000","0.1184","1.41573","0.00050"
"6.4000","0.1265","1.49153","0.00054"
"6.8000","0.1346","1.55926","0.00057"
"7.2000","0.1424","1.62514","0.00061"
"7.6000","0.1505","1.69592","0.00064"
"8.0000","0.1584","1.75821","0.00067"
"8.4000","0.1665","1.82903","0.00071"
"8.8000","0.1744","1.89132","0.00074"
"9.2000","0.1826","1.95317","0.00077"
"9.6000","0.1907","2.02145","0.00081"
"10.0000","0.1985","2.07683","0.00084"
"10.4000","0.2065","2.13770","0.00087"
"10.8000","0.2144","2.19032","0.00089"
"11.2000","0.2225","2.24346","0.00092"
"11.6000","0.2304","2.29136","0.00094"
"12.0000","0.2385","2.33953","0.00097"
"12.4000","0.2466","2.38728","0.00099"
"12.8000","0.2544","2.43214","0.00102"
"13.2000","0.2625","2.47658","0.00104"
"13.6000","0.2705","2.52651","0.00107"
"14.0000","0.2785","2.57224","0.00109"
"14.4000","0.2864","2.61772","0.00111"
"14.8000","0.2945","2.66241","0.00113"
"15.2000","0.3026","2.70657","0.00115"
"15.6000","0.3105","2.74799","0.00118"
"16.0000","0.3186","2.79018","0.00120"
"16.4000","0.3264","2.83033","0.00122"
"16.8000","0.3345","2.87520","0.00124"
"17.2000","0.3423","2.91865","0.00126"
"17.6000","0.3506","2.96518","0.00129"
"18.0000","0.3586","3.01358","0.00131"
"18.4000","0.3665","3.05612","0.00134"
"18.8000","0.3745","3.10060","0.00136"
"19.2000","0.3823","3.14435","0.00138"
"19.6000","0.3905","3.19000","0.00141"
"20.0000","0.3984","3.23176","0.00143"
"20.4000","0.4065","3.27793","0.00145"
"20.8000","0.4146","3.32477","0.00148"
"21.2000","0.4225","3.37045","0.00150"
"21.6000","0.4305","3.41595","0.00152"
"22.0000","0.4385","3.46231","0.00155"
"22.4000","0.4465","3.50976","0.00157"
"22.8000","0.4544","3.55282","0.00159"
"23.2000","0.4625","3.59879","0.00162"
"23.6000","0.4705","3.64522","0.00164"
"24.0000","0.4786","3.69104","0.00167"
"24.4000","0.4866","3.73641","0.00169"
"24.8000","0.4944","3.77657","0.00172"
"25.2000","0.5025","3.82357","0.00174"
"25.6000","0.5103","3.86803","0.00176"
"26.0000","0.5185","3.91467","0.00179"
"26.4000","0.5266","3.95942","0.00181"
"26.8000","0.5346","3.99765","0.00183"
"27.2000","0.5426","4.03366","0.00185"
"27.6000","0.5504","4.06603","0.00187"
"28.0000","0.5586","4.09854","0.00189"
"28.4000","0.5664","4.12812","0.00191"
"28.8000","0.5745","4.15807","0.00192"
"29.2000","0.5825","4.19360","0.00194"
"29.6000","0.5905","4.22972","0.00197"
"30.0000","0.5986","4.26323","0.00198"
"30.4000","0.6065","4.29707","0.00201"
"30.8000","0.6146","4.33411","0.00202"
"31.2000","0.6224","4.36716","0.00204"
"31.6000","0.6305","4.40370","0.00207"
"32.0000","0.6385","4.44250","0.00209"
"32.4000","0.6466","4.48131","0.00211"
"32.8000","0.6546","4.51954","0.00213"
"33.2000","0.6624","4.55865","0.00215"
"33.6000","0.6705","4.59852","0.00218"
"34.0000","0.6783","4.63612","0.00220"
"34.4000","0.6865","4.67566","0.00222"
"34.8000","0.6945","4.71319","0.00224"
"35.2000","0.7026","4.75182","0.00227"
"35.6000","0.7105","4.78928","0.00229"
"36.0000","0.7184","4.82675","0.00231"
"36.4000","0.7266","4.86790","0.00234"
"36.8000","0.7344","4.90453","0.00236"
"37.2000","0.7425","4.94569","0.00238"
"37.6000","0.7504","4.98564","0.00241"
"38.0000","0.7584","5.02465","0.00243"
"38.4000","0.7665","5.06641","0.00245"
"38.8000","0.7745","5.10402","0.00248"
"39.2000","0.7826","5.14246","0.00250"
"39.6000","0.7904","5.18051","0.00253"
"40.0000","0.7985","5.22325","0.00255"
"40.4000","0.8064","5.26496","0.00258"
"40.8000","0.8145","5.30991","0.00261"
"41.2000","0.8225","5.35342","0.00263"
"41.6000","0.8305","5.39465","0.00266"
"42.0000","0.8385","5.43498","0.00269"
"42.4000","0.8463","5.47140","0.00271"
"42.8000","0.8546","5.51681","0.00274"
"43.2000","0.8625","5.56039","0.00277"
"43.6000","0.8704","5.60217","0.00280"
"44.0000","0.8786","5.64615","0.00283"
"44.4000","0.8865","5.68553","0.00285"
"44.8000","0.8946","5.72496","0.00288"
"45.2000","0.9024","5.76252","0.00291"
"45.6000","0.9106","5.80577","0.00294"
"46.0000","0.9184","5.84671","0.00297"
"46.4000","0.9264","5.88734","0.00300"
"46.8000","0.9345","5.92749","0.00304"
"47.2000","0.9427","5.94217","0.00305"
"47.6000","0.9505","5.99473","0.00309"
"48.0000","0.9583","6.03785","0.00313"
"48.4000","0.9666","6.08419","0.00317"
"48.8000","0.9743","6.12146","0.00321"
"49.2000","0.9824","6.15722","0.00325"
"49.6000","0.9906","6.19403","0.00329"
"50.0000","0.9986","6.22766","0.00333"
"50.4000","1.0065","6.26056","0.00338"
"50.8000","1.0143","6.29067","0.00342"
"51.2000","1.0226","6.32374","0.00348"
"51.6000","1.0305","6.35179","0.00353"
"52.0000","1.0384","6.37683","0.00358"
"52.4000","1.0465","6.36641","0.00361"
"52.8000","1.0546","6.41611","0.00366"
"53.2000","1.0624","6.43872","0.00373"
"53.6000","1.0704","6.46053","0.00380"
"54.0000","1.0787","6.48430","0.00388"
"54.4000","1.0863","6.49905","0.00395"
"54.8000","1.0944","6.51538","0.00404"
"55.2000","1.1025","6.53292","0.00412"
"55.6000","1.1106","6.54562","0.00420"
"56.0000","1.1186","6.55657","0.00429"
"56.4000","1.1264","6.56448","0.00438"
"56.8000","1.1347","6.57625","0.00447"
"57.2000","1.1423","6.58105","0.00456"
"57.6000","1.1504","6.58982","0.00465"
"58.0000","1.1586","6.59890","0.00474"
"58.4000","1.1666","6.60658","0.00484"
"58.8000","1.1744","6.61132","0.00493"
"59.2000","1.1824","6.61582","0.00503"
"59.6000","1.1908","6.62460","0.00513"
"60.0000","1.1983","6.62640","0.00523"
"60.4000","1.2065","6.63114","0.00533"
"60.8000","1.2145","6.63778","0.00543"
"61.2000","1.2225","6.64123","0.00552"
"61.6000","1.2304","6.64080","0.00561"
"62.0000","1.2385","6.64762","0.00571"
"62.4000","1.2468","6.65388","0.00581"
"62.8000","1.2543","6.65342","0.00591"
"63.2000","1.2624","6.65735","0.00602"
"63.6000","1.2705","6.66314","0.00612"
"64.0000","1.2786","6.66602","0.00622"
"64.4000","1.2865","6.66811","0.00633"
"64.8000","1.2946","6.67076","0.00643"
"65.2000","1.3027","6.67640","0.00654"
"65.6000","1.3102","6.67504","0.00664"
"66.0000","1.3185","6.67865","0.00675"
"66.4000","1.3266","6.68300","0.00685"
"66.8000","1.3345","6.68381","0.00696"
"67.2000","1.3424","6.68610","0.00707"
"67.6000","1.3505","6.68937","0.00718"
"68.0000","1.3588","6.69402","0.00728"
"68.4000","1.3664","6.69167","0.00738"
"68.8000","1.3745","6.69510","0.00749"
"69.2000","1.3826","6.69866","0.00760"
"69.6000","1.3905","6.70045","0.00770"
"70.0000","1.3984","6.70193","0.00780"
"70.4000","1.4066","6.70458","0.00791"
"70.8000","1.4148","6.70870","0.00801"
"71.2000","1.4223","6.70568","0.00811"
"71.6000","1.4305","6.70956","0.00822"
"72.0000","1.4385","6.71315","0.00832"
"72.4000","1.4465","6.71429","0.00843"
"72.8000","1.4545","6.71595","0.00853"
"73.2000","1.4626","6.71906","0.00863"
"73.6000","1.4707","6.72155","0.00874"
"74.0000","1.4783","6.71977","0.00884"
"74.4000","1.4865","6.72372","0.00895"
"74.8000","1.4945","6.72587","0.00905"
"75.2000","1.5025","6.72673","0.00916"
"75.6000","1.5104","6.72800","0.00926"
"76.0000","1.5186","6.70809","0.00932"
"76.4000","1.5266","6.73179","0.00941"
"76.8000","1.5343","6.73234","0.00950"
"77.2000","1.5426","6.73570","0.00961"
"77.6000","1.5505","6.72948","0.00969"
"78.0000","1.5584","6.73712","0.00979"
"78.4000","1.5664","6.74032","0.00989"
"78.8000","1.5747","6.74330","0.01000"
"79.2000","1.5827","6.74490","0.01010"
"79.6000","1.5904","6.74297","0.01020"
"80.0000","1.5986","6.74684","0.01031"
"80.4000","1.6064","6.74765","0.01040"
"80.8000","1.6145","6.74946","0.01051"
"81.2000","1.6225","6.75026","0.01061"
"81.6000","1.6307","6.75306","0.01071"
"82.0000","1.6386","6.75521","0.01081"
"82.4000","1.6463","6.75370","0.01091"
"82.8000","1.6546","6.75836","0.01101"
"83.2000","1.6625","6.75919","0.01111"
"83.6000","1.6705","6.75960","0.01121"
"84.0000","1.6784","6.76150","0.01131"
"84.4000","1.6866","6.76411","0.01141"
"84.8000","1.6945","6.76614","0.01151"
"85.2000","1.7025","6.76560","0.01161"
"85.6000","1.7107","6.76938","0.01171"
"86.0000","1.7184","6.76860","0.01181"
"86.4000","1.7265","6.77041","0.01191"
"86.8000","1.7344","6.77194","0.01201"
"87.2000","1.7426","6.77479","0.01211"
"87.6000","1.7506","6.77639","0.01221"
"88.0000","1.7585","6.77566","0.01230"
"88.4000","1.7666","6.77948","0.01240"
"88.8000","1.7743","6.77925","0.01250"
"89.2000","1.7825","6.78131","0.01260"
"89.6000","1.7905","6.78300","0.01270"
"90.0000","1.7986","6.78535","0.01280"
"90.4000","1.8065","6.78622","0.01290"
"90.8000","1.8145","6.78687","0.01300"
"91.2000","1.8226","6.79096","0.01309"
"91.6000","1.8304","6.78949","0.01319"
"92.0000","1.8385","6.79146","0.01329"
"92.4000","1.8464","6.79284","0.01338"
"92.8000","1.8545","6.79508","0.01348"
"93.2000","1.8625","6.79701","0.01358"
"93.6000","1.8705","6.79732","0.01368"
"94.0000","1.8787","6.80063","0.01378"
"94.4000","1.8864","6.79968","0.01387"
"94.8000","1.8945","6.80115","0.01397"
"95.2000","1.9024","6.80322","0.01406"
"95.6000","1.9106","6.80582","0.01416"
"96.0000","1.9185","6.80635","0.01426"
"96.4000","1.9266","6.80744","0.01436"
"96.8000","1.9346","6.81046","0.01445"
"97.2000","1.9424","6.80966","0.01455"
"97.6000","1.9506","6.81241","0.01465"
"98.0000","1.9585","6.81287","0.01474"
"98.4000","1.9666","6.81511","0.01484"
"98.8000","1.9744","6.81615","0.01493"
"99.2000","1.9825","6.81710","0.01503"
"99.6000","1.9907","6.82123","0.01513"
"100.0000","1.9984","6.81981","0.01522"
"100.4000","2.0066","6.82189","0.01532"
"100.8000","2.0144","6.82261","0.01541"
"101.2000","2.0225","6.82461","0.01551"
"101.6000","2.0304","6.82589","0.01560"
"102.0000","2.0386","6.82801","0.01570"
"102.4000","2.0467","6.83019","0.01579"
"102.8000","2.0545","6.82953","0.01589"
"103.2000","2.0625","6.83180","0.01598"
"103.6000","2.0703","6.83196","0.01608"
"104.0000","2.0786","6.83534","0.01618"
"104.4000","2.0864","6.83569","0.01627"
"104.8000","2.0945","6.83685","0.01637"
"105.2000","2.1026","6.84025","0.01646"
"105.6000","2.1104","6.83924","0.01655"
"106.0000","2.1186","6.84185","0.01665"
"106.4000","2.1265","6.84199","0.01674"
"106.8000","2.1346","6.84410","0.01684"
"107.2000","2.1424","6.84468","0.01693"
"107.6000","2.1505","6.84623","0.01703"
"108.0000","2.1586","6.84952","0.01712"
"108.4000","2.1665","6.84922","0.01722"
"108.8000","2.1746","6.85125","0.01731"
"109.2000","2.1824","6.85056","0.01741"
"109.6000","2.1905","6.85369","0.01750"
"110.0000","2.1983","6.85421","0.01759"
"110.4000","2.2066","6.85612","0.01769"
"110.8000","2.2146","6.85898","0.01778"
"111.2000","2.2225","6.85871","0.01788"
"111.6000","2.2306","6.86038","0.01797"
"112.0000","2.2384","6.85988","0.01806"
"112.4000","2.2466","6.86339","0.01816"
"112.8000","2.2544","6.86336","0.01825"
"113.2000","2.2625","6.86516","0.01835"
"113.6000","2.2706","6.86763","0.01844"
"114.0000","2.2785","6.85752","0.01853"
"114.4000","2.2866","6.86666","0.01861"
"114.8000","2.2945","6.86934","0.01870"
"115.2000","2.3026","6.87307","0.01880"
"115.6000","2.3104","6.87261","0.01889"
"116.0000","2.3185","6.87383","0.01898"
"116.4000","2.3265","6.87755","0.01907"
"116.8000","2.3346","6.87798","0.01917"
"117.2000","2.3426","6.87883","0.01926"
"117.6000","2.3504","6.87848","0.01935"
"118.0000","2.3586","6.88134","0.01944"
"118.4000","2.3663","6.88113","0.01953"
"118.8000","2.3745","6.88349","0.01963"
"119.2000","2.3826","6.88569","0.01972"
"119.6000","2.3906","6.88693","0.01982"
"120.0000","2.3985","6.88767","0.01991"
"120.4000","2.4064","6.88714","0.02000"
"120.8000","2.4146","6.89165","0.02010"
"121.2000","2.4224","6.89022","0.02019"
"121.6000","2.4305","6.89164","0.02028"
"122.0000","2.4385","6.89444","0.02038"
"122.4000","2.4465","6.89501","0.02047"
"122.8000","2.4546","6.89711","0.02056"
"123.2000","2.4625","6.89656","0.02066"
"123.6000","2.4706","6.89967","0.02075"
"124.0000","2.4784","6.89905","0.02084"
"124.4000","2.4865","6.90061","0.02093"
"124.8000","2.4944","6.90296","0.02103"
"125.2000","2.5026","6.90479","0.02112"
"125.6000","2.5106","6.90554","0.02122"
"126.0000","2.5185","6.90527","0.02131"
"126.4000","2.5266","6.90866","0.02140"
"126.8000","2.5343","6.90716","0.02149"
"127.2000","2.5426","6.91000","0.02158"
"127.6000","2.5505","6.91202","0.02168"
"128.0000","2.5585","6.91241","0.02177"
"128.4000","2.5666","6.91403","0.02186"
"128.8000","2.5745","6.91447","0.02195"
"129.2000","2.5826","6.91762","0.02205"
"129.6000","2.5904","6.91648","0.02214"
"130.0000","2.5986","6.91860","0.02223"
"130.4000","2.6064","6.91985","0.02232"
"130.8000","2.6145","6.92106","0.02241"
"131.2000","2.6225","6.92303","0.02250"
"131.6000","2.6306","6.92352","0.02260"
"132.0000","2.6386","6.92648","0.02269"
"132.4000","2.6463","6.92391","0.02278"
"132.8000","2.6546","6.92701","0.02287"
"133.2000","2.6624","6.92895","0.02296"
"133.6000","2.6705","6.92967","0.02305"
"134.0000","2.6786","6.93141","0.02315"
"134.4000","2.6866","6.93229","0.02324"
"134.8000","2.6945","6.93395","0.02333"
"135.2000","2.7023","6.93283","0.02342"
"135.6000","2.7106","6.93631","0.02351"
"136.0000","2.7184","6.93674","0.02360"
"136.4000","2.7265","6.93759","0.02370"
"136.8000","2.7345","6.93951","0.02379"
"137.2000","2.7425","6.94066","0.02388"
"137.6000","2.7505","6.94292","0.02397"
"138.0000","2.7584","6.94125","0.02406"
"138.4000","2.7667","6.94452","0.02415"
"138.8000","2.7744","6.94457","0.02424"
"139.2000","2.7824","6.94501","0.02433"
"139.6000","2.7906","6.94872","0.02443"
"140.0000","2.7987","6.94989","0.02452"
"140.4000","2.8065","6.95055","0.02461"
"140.8000","2.8144","6.94977","0.02470"
"141.2000","2.8226","6.95312","0.02479"
"141.6000","2.8303","6.95271","0.02488"
"142.0000","2.8384","6.95423","0.02497"
"142.4000","2.8466","6.95643","0.02506"
"142.8000","2.8547","6.95795","0.02515"
"143.2000","2.8625","6.95851","0.02524"
"143.6000","2.8703","6.95783","0.02533"
"144.0000","2.8787","6.96257","0.02543"
"144.4000","2.8864","6.96130","0.02551"
"144.8000","2.8944","6.96167","0.02561"
"145.2000","2.9026","6.96471","0.02570"
"145.6000","2.9106","6.96616","0.02579"
"146.0000","2.9185","6.96675","0.02588"
"146.4000","2.9265","6.96665","0.02597"
"146.8000","2.9347","6.97018","0.02606"
"147.2000","2.9423","6.96840","0.02615"
"147.6000","2.9504","6.96997","0.02624"
"148.0000","2.9585","6.97280","0.02633"
"148.4000","2.9667","6.97459","0.02642"
"148.8000","2.9745","6.97428","0.02651"
"149.2000","2.9825","6.97421","0.02660"
"149.6000","2.9907","6.97822","0.02670"
"150.0000","2.9982","6.97623","0.02678"
"150.4000","3.0064","6.97810","0.02687"
"150.8000","3.0146","6.98107","0.02697"
"151.2000","3.0226","6.98178","0.02705"
"151.6000","3.0304","6.98098","0.02714"
"152.0000","3.0384","6.96911","0.02720"
"152.4000","3.0467","6.98438","0.02728"
"152.8000","3.0543","6.98471","0.02737"
"153.2000","3.0625","6.98698","0.02746"
"153.6000","3.0705","6.98938","0.02755"
"154.0000","3.0786","6.99064","0.02764"
"154.4000","3.0864","6.99066","0.02773"
"154.8000","3.0945","6.99150","0.02782"
"155.2000","3.1028","6.99533","0.02791"
"155.6000","3.1103","6.99141","0.02800"
"156.0000","3.1184","6.99364","0.02809"
"156.4000","3.1265","6.99677","0.02818"
"156.8000","3.1346","6.99737","0.02827"
"157.2000","3.1425","6.99784","0.02836"
"157.6000","3.1506","6.98652","0.02844"
"158.0000","3.1587","6.99847","0.02853"
"158.4000","3.1663","6.99932","0.02861"
"158.8000","3.1745","7.00281","0.02870"
"159.2000","3.1826","7.00451","0.02879"
"159.6000","3.1906","7.00530","0.02888"
"160.0000","3.1983","7.00492","0.02897"
"160.4000","3.2066","7.00724","0.02907"
"160.8000","3.2147","7.01064","0.02916"
"161.2000","3.2223","7.00654","0.02924"
"161.6000","3.2306","7.00960","0.02934"
"162.0000","3.2385","7.01159","0.02943"
"162.4000","3.2465","7.01131","0.02952"
"162.8000","3.2544","7.01301","0.02961"
"163.2000","3.2626","7.01528","0.02970"
"163.6000","3.2707","7.01698","0.02979"
"164.0000","3.2783","7.01399","0.02988"
"164.4000","3.2865","7.01683","0.02997"
"164.8000","3.2945","7.01848","0.03006"
"165.2000","3.3025","7.01952","0.03015"
"165.6000","3.3104","7.01934","0.03024"
"166.0000","3.3187","7.02232","0.03033"
"166.4000","3.3266","7.02398","0.03042"
"166.8000","3.3343","7.02097","0.03050"
"167.2000","3.3426","7.02554","0.03060"
"167.6000","3.3505","7.02601","0.03069"
"168.0000","3.3585","7.02552","0.03078"
"168.4000","3.3664","7.02731","0.03087"
"168.8000","3.3745","7.02958","0.03096"
"169.2000","3.3826","7.03182","0.03105"
"169.6000","3.3904","7.02946","0.03114"
"170.0000","3.3986","7.03208","0.03123"
"170.4000","3.4065","7.03296","0.03132"
"170.8000","3.4144","7.03286","0.03141"
"171.2000","3.4223","7.03403","0.03150"
"171.6000","3.4307","7.03796","0.03159"
"172.0000","3.4386","7.03823","0.03168"
"172.4000","3.4464","7.03615","0.03176"
"172.8000","3.4546","7.04047","0.03186"
"173.2000","3.4624","7.03952","0.03194"
"173.6000","3.4705","7.04094","0.03204"
"174.0000","3.4785","7.04189","0.03213"
"174.4000","3.4866","7.04417","0.03222"
"174.8000","3.4946","7.04511","0.03231"
"175.2000","3.5024","7.04401","0.03240"
"175.6000","3.5106","7.04791","0.03249"
"176.0000","3.5185","7.04719","0.03258"
"176.4000","3.5265","7.04760","0.03267"
"176.8000","3.5344","7.04858","0.03276"
"177.2000","3.5426","7.05095","0.03285"
"177.6000","3.5505","7.05247","0.03294"
"178.0000","3.5585","7.05162","0.03303"
"178.4000","3.5667","7.05473","0.03312"
"178.8000","3.5744","7.05365","0.03321"
"179.2000","3.5825","7.05462","0.03330"
"179.6000","3.5904","7.05593","0.03339"
"180.0000","3.5986","7.05871","0.03348"
"180.4000","3.6066","7.05912","0.03357"
"180.8000","3.6145","7.05852","0.03367"
"181.2000","3.6226","7.06145","0.03376"
"181.6000","3.6304","7.06029","0.03385"
"182.0000","3.6385","7.06236","0.03394"
"182.4000","3.6465","7.06268","0.03403"
"182.8000","3.6546","7.06476","0.03412"
"183.2000","3.6625","7.06519","0.03421"
"183.6000","3.6705","7.06521","0.03430"
"184.0000","3.6787","7.06915","0.03439"
"184.4000","3.6864","7.06726","0.03448"
"184.8000","3.6945","7.06854","0.03457"
"185.2000","3.7024","7.06969","0.03466"
"185.6000","3.7105","7.07099","0.03475"
"186.0000","3.7184","7.07214","0.03484"
"186.4000","3.7266","7.07338","0.03493"
"186.8000","3.7347","7.07523","0.03502"
"187.2000","3.7424","7.07381","0.03511"
"187.6000","3.7505","7.07557","0.03520"
"188.0000","3.7584","7.07562","0.03529"
"188.4000","3.7666","7.07858","0.03538"
"188.8000","3.7744","7.07860","0.03547"
"189.2000","3.7825","7.07941","0.03557"
"189.6000","3.7907","7.08238","0.03566"
"190.0000","3.7983","7.08033","0.03575"
"190.4000","3.8065","7.08276","0.03584"
"190.8000","3.8145","7.08290","0.03593"
"191.2000","3.8226","7.08445","0.03602"
"191.6000","3.8304","7.08452","0.03611"
"192.0000","3.8385","7.08575","0.03620"
"192.4000","3.8466","7.08889","0.03629"
"192.8000","3.8545","7.08756","0.03638"
"193.2000","3.8626","7.08931","0.03647"
"193.6000","3.8704","7.08858","0.03656"
"194.0000","3.8785","7.09096","0.03665"
"194.4000","3.8864","7.09142","0.03674"
"194.8000","3.8946","7.09266","0.03684"
"195.2000","3.9027","7.09521","0.03693"
"195.6000","3.9105","7.09390","0.03702"
"196.0000","3.9186","7.09546","0.03711"
"196.4000","3.9264","7.09531","0.03720"
"196.8000","3.9346","7.09769","0.03729"
"197.2000","3.9424","7.09742","0.03738"
"197.6000","3.9506","7.09856","0.03747"
"198.0000","3.9586","7.10067","0.03756"
"198.4000","3.9664","7.10019","0.03765"
"198.8000","3.9746","7.10264","0.03774"
"199.2000","3.9824","7.10121","0.03783"
"199.6000","3.9906","7.10364","0.03793"
"200.0000","3.9984","7.10322","0.03801"
"200.4000","4.0065","7.10420","0.03810"
"200.8000","4.0146","7.10760","0.03820"
"201.2000","4.0225","7.10711","0.03829"
"201.6000","4.0306","7.10816","0.03838"
"202.0000","4.0384","7.10720","0.03847"
"202.4000","4.0465","7.10955","0.03856"
"202.8000","4.0544","7.10944","0.03865"
"203.2000","4.0626","7.11123","0.03874"
"203.6000","4.0706","7.11302","0.03883"
"204.0000","4.0786","7.11313","0.03892"
"204.4000","4.0866","7.11408","0.03902"
"204.8000","4.0943","7.11265","0.03910"
"205.2000","4.1026","7.11649","0.03920"
"205.6000","4.1104","7.11552","0.03929"
"206.0000","4.1185","7.11665","0.03938"
"206.4000","4.1265","7.11894","0.03947"
"206.8000","4.1345","7.11902","0.03956"
"207.2000","4.1426","7.12053","0.03966"
"207.6000","4.1505","7.11959","0.03974"
"208.0000","4.1586","7.12189","0.03984"
"208.4000","4.1664","7.12113","0.03993"
"208.8000","4.1745","7.12223","0.04002"
"209.2000","4.1825","7.12455","0.04011"
"209.6000","4.1906","7.12590","0.04020"
"210.0000","4.1986","7.12621","0.04029"
"210.4000","4.2064","7.11243","0.04036"
"210.8000","4.2146","7.12476","0.04045"
"211.2000","4.2223","7.12627","0.04054"
"211.6000","4.2306","7.12907","0.04063"
"212.0000","4.2386","7.13097","0.04072"
"212.4000","4.2465","7.13098","0.04081"
"212.8000","4.2546","7.13227","0.04091"
"213.2000","4.2624","7.13126","0.04100"
"213.6000","4.2706","7.13426","0.04110"
"214.0000","4.2784","7.13297","0.04119"
"214.4000","4.2865","7.13418","0.04128"
"214.8000","4.2945","7.13556","0.04137"
"215.2000","4.3025","7.13628","0.04146"
"215.6000","4.3105","7.13741","0.04155"
"216.0000","4.3185","7.13682","0.04164"
"216.4000","4.3266","7.13957","0.04174"
"216.8000","4.3343","7.13719","0.04183"
"217.2000","4.3425","7.13918","0.04192"
"217.6000","4.3504","7.14114","0.04201"
"218.0000","4.3586","7.14163","0.04210"
"218.4000","4.3666","7.14252","0.04220"
"218.8000","4.3745","7.14236","0.04229"
"219.2000","4.3826","7.14449","0.04238"
"219.6000","4.3903","7.14280","0.04247"
"220.0000","4.3986","7.14526","0.04257"
"220.4000","4.4065","7.14596","0.04266"
"220.8000","4.4145","7.14637","0.04275"
"221.2000","4.4226","7.14737","0.04284"
"221.6000","4.4305","7.14740","0.04293"
"222.0000","4.4386","7.15027","0.04303"
"222.4000","4.4463","7.14788","0.04311"
"222.8000","4.4546","7.15050","0.04321"
"223.2000","4.4624","7.15072","0.04330"
"223.6000","4.4704","7.15056","0.04339"
"224.0000","4.4786","7.15342","0.04349"
"224.4000","4.4866","7.15349","0.04358"
"224.8000","4.4946","7.15463","0.04367"
"225.2000","4.5024","7.15294","0.04376"
"225.6000","4.5106","7.15552","0.04386"
"226.0000","4.5183","7.15556","0.04395"
"226.4000","4.5265","7.15655","0.04404"
"226.8000","4.5346","7.15812","0.04413"
"227.2000","4.5426","7.15879","0.04423"
"227.6000","4.5505","7.15970","0.04432"
"228.0000","4.5583","7.15755","0.04441"
"228.4000","4.5667","7.16148","0.04450"
"228.8000","4.5744","7.16095","0.04459"
"229.2000","4.5824","7.16081","0.04469"
"229.6000","4.5906","7.16314","0.04478"
"230.0000","4.5986","7.16369","0.04487"
"230.4000","4.6065","7.16446","0.04496"
"230.8000","4.6144","7.16320","0.04506"
"231.2000","4.6226","7.16579","0.04515"
"231.6000","4.6304","7.16490","0.04524"
"232.0000","4.6384","7.16552","0.04533"
"232.4000","4.6465","7.16776","0.04543"
"232.8000","4.6547","7.16924","0.04552"
"233.2000","4.6625","7.16906","0.04561"
"233.6000","4.6704","7.16752","0.04570"
"234.0000","4.6787","7.17125","0.04580"
"234.4000","4.6863","7.16927","0.04589"
"234.8000","4.6944","7.17032","0.04599"
"235.2000","4.7026","7.17287","0.04608"
"235.6000","4.7106","7.17323","0.04617"
"236.0000","4.7184","7.17298","0.04626"
"236.4000","4.7264","7.17277","0.04636"
"236.8000","4.7347","7.17638","0.04645"
"237.2000","4.7424","7.17404","0.04654"
"237.6000","4.7505","7.17500","0.04664"
"238.0000","4.7586","7.17677","0.04673"
"238.4000","4.7666","7.17777","0.04682"
"238.8000","4.7744","7.17785","0.04691"
"239.2000","4.7825","7.17749","0.04701"
"239.6000","4.7908","7.18119","0.04710"
"240.0000","4.7983","7.17748","0.04719"
"240.4000","4.8064","7.17875","0.04729"
"240.8000","4.8145","7.18193","0.04738"
"241.2000","4.8226","7.18263","0.04748"
"241.6000","4.8304","7.18188","0.04757"
"242.0000","4.8385","7.18236","0.04766"
"242.4000","4.8467","7.18534","0.04776"
"242.8000","4.8542","7.18191","0.04785"
"243.2000","4.8625","7.18430","0.04794"
"243.6000","4.8706","7.18585","0.04804"
"244.0000","4.8786","7.18645","0.04813"
"244.4000","4.8864","7.18605","0.04822"
"244.8000","4.8945","7.18671","0.04832"
"245.2000","4.9028","7.19056","0.04841"
"245.6000","4.9103","7.18645","0.04850"
"246.0000","4.9185","7.18798","0.04860"
"246.4000","4.9266","7.19018","0.04870"
"246.8000","4.9345","7.18988","0.04879"
"247.2000","4.9424","7.19017","0.04888"
"247.6000","4.9506","7.19187","0.04898"
"248.0000","4.9588","7.19406","0.04907"
"248.4000","4.9663","7.19003","0.04916"
"248.8000","4.9745","7.19256","0.04926"
"249.2000","4.9825","7.19385","0.04935"
"249.6000","4.9906","7.19491","0.04945"
"250.0000","4.9984","7.19426","0.04954"
"250.4000","5.0066","7.19544","0.04964"
"250.8000","5.0147","7.19805","0.04973"
"251.2000","5.0222","7.17527","0.04979"
"251.6000","5.0305","7.19157","0.04988"
"252.0000","5.0386","7.19791","0.04997"
"252.4000","5.0465","7.19865","0.05006"
"252.8000","5.0544","7.19911","0.05015"
"253.2000","5.0626","7.20111","0.05025"
"253.6000","5.0707","7.20285","0.05035"
"254.0000","5.0784","7.19943","0.05044"
"254.4000","5.0866","7.20168","0.05054"
"254.8000","5.0945","7.20183","0.05063"
"255.2000","5.1025","7.20208","0.05072"
"255.6000","5.1104","7.20192","0.05082"
"256.0000","5.1187","7.20429","0.05092"
"256.4000","5.1267","7.20573","0.05101"
"256.8000","5.1343","7.20191","0.05111"
"257.2000","5.1426","7.20489","0.05120"
"257.6000","5.1504","7.20522","0.05129"
"258.0000","5.1585","7.20534","0.05139"
"258.4000","5.1665","7.20575","0.05149"
"258.8000","5.1747","7.20780","0.05158"
"259.2000","5.1826","7.20835","0.05168"
"259.6000","5.1903","7.20589","0.05177"
"260.0000","5.1986","7.20915","0.05187"
"260.4000","5.2065","7.20874","0.05197"
"260.8000","5.2145","7.20871","0.05206"
"261.2000","5.2224","7.20885","0.05216"
"261.6000","5.2306","7.21098","0.05226"
"262.0000","5.2386","7.21230","0.05235"
"262.4000","5.2464","7.20956","0.05245"
"262.8000","5.2546","7.21243","0.05254"
"263.2000","5.2625","7.21176","0.05264"
"263.6000","5.2704","7.21165","0.05273"
"264.0000","5.2784","7.21246","0.05283"
"264.4000","5.2867","7.21502","0.05293"
"264.8000","5.2946","7.21497","0.05302"
"265.2000","5.3025","7.21337","0.05312"
"265.6000","5.3106","7.21597","0.05322"
"266.0000","5.3184","7.21451","0.05331"
"266.4000","5.3265","7.21599","0.05341"
"266.8000","5.3345","7.21572","0.05351"
"267.2000","5.3426","7.21748","0.05361"
"267.6000","5.3505","7.21778","0.05370"
"268.0000","5.3584","7.21622","0.05380"
"268.4000","5.3667","7.22009","0.05390"
"268.8000","5.3744","7.21804","0.05400"
"269.2000","5.3825","7.21829","0.05409"
"269.6000","5.3905","7.21913","0.05419"
"270.0000","5.3985","7.22018","0.05429"
"270.4000","5.4065","7.22071","0.05438"
"270.8000","5.4145","7.22083","0.05448"
"271.2000","5.4227","7.22267","0.05458"
"271.6000","5.4305","7.22086","0.05468"
"272.0000","5.4385","7.22173","0.05477"
"272.4000","5.4463","7.22121","0.05487"
"272.8000","5.4546","7.22445","0.05497"
"273.2000","5.4625","7.22362","0.05507"
"273.6000","5.4705","7.22334","0.05516"
"274.0000","5.4787","7.22619","0.05526"
"274.4000","5.4863","7.22344","0.05536"
"274.8000","5.4946","7.22531","0.05546"
"275.2000","5.5025","7.22534","0.05555"
"275.6000","5.5105","7.22609","0.05565"
"276.0000","5.5185","7.22673","0.05575"
"276.4000","5.5265","7.22651","0.05585"
"276.8000","5.5346","7.22873","0.05595"
"277.2000","5.5425","7.22739","0.05604"
"277.6000","5.5505","7.22780","0.05614"
"278.0000","5.5584","7.22708","0.05624"
"278.4000","5.5665","7.22931","0.05634"
"278.8000","5.5743","7.22896","0.05644"
"279.2000","5.5826","7.22995","0.05654"
"279.6000","5.5907","7.23207","0.05664"
"280.0000","5.5984","7.22924","0.05673"
"280.4000","5.6066","7.23074","0.05684"
"280.8000","5.6144","7.23010","0.05693"
"281.2000","5.6225","7.23175","0.05703"
"281.6000","5.6305","7.23228","0.05713"
"282.0000","5.6385","7.23207","0.05723"
"282.4000","5.6466","7.23348","0.05733"
"282.8000","5.6544","7.23267","0.05743"
"283.2000","5.6626","7.23410","0.05753"
"283.6000","5.6705","7.23303","0.05763"
"284.0000","5.6786","7.23465","0.05773"
"284.4000","5.6864","7.23360","0.05783"
"284.8000","5.6945","7.23475","0.05793"
"285.2000","5.7026","7.23687","0.05803"
"285.6000","5.7104","7.23502","0.05813"
"286.0000","5.7186","7.23682","0.05823"
"286.4000","5.7264","7.23482","0.05833"
"286.8000","5.7345","7.23651","0.05843"
"287.2000","5.7424","7.23650","0.05853"
"287.6000","5.7506","7.23739","0.05863"
"288.0000","5.7586","7.23897","0.05873"
"288.4000","5.7665","7.23785","0.05883"
"288.8000","5.7746","7.23857","0.05893"
"289.2000","5.7824","7.23718","0.05903"
"289.6000","5.7906","7.23986","0.05913"
"290.0000","5.7984","7.23866","0.05923"
"290.4000","5.8065","7.23911","0.05933"
"290.8000","5.8146","7.24097","0.05943"
"291.2000","5.8224","7.24000","0.05953"
"291.6000","5.8306","7.24161","0.05963"
"292.0000","5.8384","7.23974","0.05974"
"292.4000","5.8466","7.24156","0.05984"
"292.8000","5.8544","7.24086","0.05994"
"293.2000","5.8625","7.24102","0.06004"
"293.6000","5.8705","7.24281","0.06014"
"294.0000","5.8786","7.24321","0.06024"
"294.4000","5.8866","7.24336","0.06035"
"294.8000","5.8944","7.24132","0.06044"
"295.2000","5.9026","7.24413","0.06055"
"295.6000","5.9103","7.24259","0.06065"
"296.0000","5.9186","7.24361","0.06075"
"296.4000","5.9266","7.24528","0.06086"
"296.8000","5.9345","7.24444","0.06096"
"297.2000","5.9426","7.24502","0.06106"
"297.6000","5.9503","7.24356","0.06116"
"298.0000","5.9586","7.24606","0.06127"
"298.4000","5.9664","7.24506","0.06137"
"298.8000","5.9745","7.24530","0.06147"
"299.2000","5.9825","7.24653","0.06158"
"299.6000","5.9905","7.24685","0.06168"
"300.0000","5.9985","7.24733","0.06178"
"300.4000","6.0065","7.24599","0.06189"
"300.8000","6.0147","7.24816","0.06199"
"301.2000","6.0223","7.24553","0.06209"
"301.6000","6.0305","7.24658","0.06220"
"302.0000","6.0385","7.24852","0.06230"
"302.4000","6.0466","7.24854","0.06241"
"302.8000","6.0546","7.24901","0.06251"
"303.2000","6.0624","7.24758","0.06261"
"303.6000","6.0706","7.24960","0.06272"
"304.0000","6.0783","7.24762","0.06282"
"304.4000","6.0866","7.24921","0.06293"
"304.8000","6.0945","7.24975","0.06303"
"305.2000","6.1026","7.25004","0.06313"
"305.6000","6.1105","7.24987","0.06324"
"306.0000","6.1184","7.24897","0.06334"
"306.4000","6.1266","7.25207","0.06345"
"306.8000","6.1344","7.24898","0.06355"
"307.2000","6.1425","7.25030","0.06366"
"307.6000","6.1504","7.25093","0.06376"
"308.0000","6.1584","7.25085","0.06386"
"308.4000","6.1666","7.25225","0.06397"
"308.8000","6.1745","7.25149","0.06408"
"309.2000","6.1826","7.25292","0.06418"
"309.6000","6.1904","7.25037","0.06429"
"310.0000","6.1985","7.25182","0.06439"
"310.4000","6.2064","7.25213","0.06450"
"310.8000","6.2145","7.25283","0.06461"
"311.2000","6.2226","7.25320","0.06471"
"311.6000","6.2305","7.25268","0.06482"
"312.0000","6.2386","7.25440","0.06492"
"312.4000","6.2463","7.25122","0.06503"
"312.8000","6.2546","7.25379","0.06514"
"313.2000","6.2625","7.25383","0.06524"
"313.6000","6.2705","7.25325","0.06535"
"314.0000","6.2786","7.25432","0.06546"
"314.4000","6.2865","7.25429","0.06557"
"314.8000","6.2946","7.25540","0.06567"
"315.2000","6.3024","7.25304","0.06578"
"315.6000","6.3106","7.25494","0.06589"
"316.0000","6.3184","7.25409","0.06599"
"316.4000","6.3264","7.25421","0.06610"
"316.8000","6.3345","7.25572","0.06621"
"317.2000","6.3426","7.25589","0.06632"
"317.6000","6.3506","7.25661","0.06643"
"318.0000","6.3584","7.25335","0.06654"
"318.4000","6.3666","7.25598","0.06665"
"318.8000","6.3744","7.25517","0.06675"
"319.2000","6.3824","7.25519","0.06686"
"319.6000","6.3906","7.25685","0.06698"
"320.0000","6.3986","7.25694","0.06708"
"320.4000","6.4065","7.25648","0.06719"
"320.8000","6.4144","7.25501","0.06730"
"321.2000","6.4227","7.25766","0.06741"
"321.6000","6.4304","7.25590","0.06752"
"322.0000","6.4385","7.25602","0.06763"
"322.4000","6.4465","7.25699","0.06774"
"322.8000","6.4546","7.25747","0.06785"
"323.2000","6.4625","7.25760","0.06796"
"323.6000","6.4704","7.25573","0.06807"
"324.0000","6.4787","7.25877","0.06819"
"324.4000","6.4863","7.25597","0.06829"
"324.8000","6.4944","7.25570","0.06840"
"325.2000","6.5026","7.25855","0.06852"
"325.6000","6.5107","7.25879","0.06863"
"326.0000","6.5185","7.25753","0.06874"
"326.4000","6.5264","7.25667","0.06885"
"326.8000","6.5347","7.25905","0.06896"
"327.2000","6.5423","7.25640","0.06907"
"327.6000","6.5505","7.25728","0.06918"
"328.0000","6.5586","7.25840","0.06930"
"328.4000","6.5666","7.25891","0.06941"
"328.8000","6.5744","7.25766","0.06952"
"329.2000","6.5824","7.25695","0.06963"
"329.6000","6.5907","7.26070","0.06975"
"330.0000","6.5983","7.25689","0.06986"
"330.4000","6.6065","7.25722","0.06997"
"330.8000","6.6146","7.25883","0.07008"
"331.2000","6.6225","7.25849","0.07020"
"331.6000","6.6304","7.25824","0.07031"
"332.0000","6.6385","7.25818","0.07042"
"332.4000","6.6468","7.26044","0.07054"
"332.8000","6.6543","7.25633","0.07065"
"333.2000","6.6624","7.25759","0.07077"
"333.6000","6.6705","7.25898","0.07088"
"334.0000","6.6787","7.25966","0.07100"
"334.4000","6.6865","7.25818","0.07111"
"334.8000","6.6945","7.25801","0.07123"
"335.2000","6.7028","7.26089","0.07134"
"335.6000","6.7102","7.25596","0.07145"
"336.0000","6.7185","7.25792","0.07157"
"336.4000","6.7266","7.25963","0.07169"
"336.8000","6.7346","7.25875","0.07180"
"337.2000","6.7424","7.25747","0.07192"
"337.6000","6.7505","7.25870","0.07203"
"338.0000","6.7587","7.26094","0.07215"
"338.4000","6.7663","7.25659","0.07227"
"338.8000","6.7745","7.25785","0.07238"
"339.2000","6.7825","7.25865","0.07250"
"339.6000","6.7905","7.25854","0.07262"
"340.0000","6.7984","7.25774","0.07273"
"340.4000","6.8066","7.25888","0.07285"
"340.8000","6.8148","7.26075","0.07297"
"341.2000","6.8223","7.25576","0.07308"
"341.6000","6.8305","7.25776","0.07320"
"342.0000","6.8385","7.25867","0.07332"
"342.4000","6.8465","7.25819","0.07344"
"342.8000","6.8545","7.25736","0.07356"
"343.2000","6.8627","7.25868","0.07368"
"343.6000","6.8706","7.25922","0.07380"
"344.0000","6.8783","7.25584","0.07392"
"344.4000","6.8865","7.25835","0.07404"
"344.8000","6.8945","7.25811","0.07416"
"345.2000","6.9025","7.25742","0.07428"
"345.6000","6.9104","7.25659","0.07440"
"346.0000","6.9186","7.25812","0.07452"
"346.4000","6.9267","7.25967","0.07464"
"346.8000","6.9343","7.25515","0.07476"
"347.2000","6.9426","7.25750","0.07488"
"347.6000","6.9505","7.25717","0.07500"
"348.0000","6.9584","7.25588","0.07512"
"348.4000","6.9664","7.25645","0.07524"
"348.8000","6.9747","7.25835","0.07537"
"349.2000","6.9827","7.25814","0.07549"
"349.6000","6.9904","7.25484","0.07561"
"350.0000","6.9986","7.25700","0.07574"
"350.4000","7.0064","7.25596","0.07586"
"350.8000","7.0145","7.25617","0.07598"
"351.2000","7.0224","7.25512","0.07610"
"351.6000","7.0306","7.25664","0.07623"
"352.0000","7.0386","7.25676","0.07635"
"352.4000","7.0463","7.25346","0.07647"
"352.8000","7.0546","7.25651","0.07660"
"353.2000","7.0625","7.25521","0.07672"
"353.6000","7.0705","7.25432","0.07685"
"354.0000","7.0784","7.25411","0.07697"
"354.4000","7.0865","7.25532","0.07710"
"354.8000","7.0945","7.25556","0.07723"
"355.2000","7.1025","7.25347","0.07735"
"355.6000","7.1107","7.25529","0.07748"
"356.0000","7.1184","7.25304","0.07760"
"356.4000","7.1265","7.25300","0.07773"
"356.8000","7.1344","7.25270","0.07786"
"357.2000","7.1426","7.25438","0.07799"
"357.6000","7.1506","7.25393","0.07811"
"358.0000","7.1584","7.25162","0.07824"
"358.4000","7.1667","7.25395","0.07837"
"358.8000","7.1743","7.25140","0.07849"
"359.2000","7.1825","7.25190","0.07862"
"359.6000","7.1905","7.25173","0.07875"
"360.0000","7.1986","7.25225","0.07888"
"360.4000","7.2065","7.25118","0.07901"
"360.8000","7.2145","7.25031","0.07914"
"361.2000","7.2227","7.25275","0.07927"
"361.6000","7.2304","7.24955","0.07940"
"362.0000","7.2385","7.24983","0.07953"
"362.4000","7.2464","7.24902","0.07966"
"362.8000","7.2545","7.24996","0.07980"
"363.2000","7.2625","7.24999","0.07992"
"363.6000","7.2705","7.24879","0.08006"
"364.0000","7.2787","7.25033","0.08019"
"364.4000","7.2864","7.24737","0.08032"
"364.8000","7.2945","7.24737","0.08046"
"365.2000","7.3024","7.24705","0.08059"
"365.6000","7.3106","7.24800","0.08072"
"366.0000","7.3185","7.24664","0.08085"
"366.4000","7.3265","7.24655","0.08099"
"366.8000","7.3346","7.24770","0.08112"
"367.2000","7.3423","7.24481","0.08126"
"367.6000","7.3506","7.24604","0.08139"
"368.0000","7.3585","7.24426","0.08153"
"368.4000","7.3666","7.24502","0.08166"
"368.8000","7.3744","7.24391","0.08180"
"369.2000","7.3825","7.24334","0.08194"
"369.6000","7.3907","7.24568","0.08207"
"370.0000","7.3984","7.24217","0.08221"
"370.4000","7.4065","7.24252","0.08235"
"370.8000","7.4144","7.24145","0.08248"
"371.2000","7.4225","7.24136","0.08262"
"371.6000","7.4304","7.24070","0.08275"
"372.0000","7.4386","7.24109","0.08290"
"372.4000","7.4466","7.24160","0.08303"
"372.8000","7.4545","7.23908","0.08317"
"373.2000","7.4626","7.23942","0.08331"
"373.6000","7.4703","7.23740","0.08345"
"374.0000","7.4786","7.23904","0.08359"
"374.4000","7.4865","7.23723","0.08373"
"374.8000","7.4945","7.23659","0.08387"
"375.2000","7.5026","7.23794","0.08401"
"375.6000","7.5104","7.23534","0.08415"
"376.0000","7.5186","7.23608","0.08429"
"376.4000","7.5265","7.23405","0.08443"
"376.8000","7.5345","7.23435","0.08458"
"377.2000","7.5424","7.23260","0.08472"
"377.6000","7.5505","7.23245","0.08486"
"378.0000","7.5586","7.23363","0.08500"
"378.4000","7.5665","7.23162","0.08514"
"378.8000","7.5746","7.23171","0.08528"
"379.2000","7.5824","7.22865","0.08543"
"379.6000","7.5905","7.22987","0.08557"
"380.0000","7.5983","7.22796","0.08571"
"380.4000","7.6066","7.22778","0.08586"
"380.8000","7.6147","7.22880","0.08601"
"381.2000","7.6225","7.22596","0.08615"
"381.6000","7.6306","7.22599","0.08630"
"382.0000","7.6383","7.22349","0.08644"
"382.4000","7.6466","7.22467","0.08659"
"382.8000","7.6545","7.22279","0.08674"
"383.2000","7.6625","7.22201","0.08688"
"383.6000","7.6705","7.22211","0.08703"
"384.0000","7.6786","7.22136","0.08718"
"384.4000","7.6866","7.22071","0.08732"
"384.8000","7.6944","7.21712","0.08747"
"385.2000","7.7026","7.21912","0.08762"
"385.6000","7.7104","7.21544","0.08777"
"386.0000","7.7185","7.21501","0.08792"
"386.4000","7.7265","7.21613","0.08807"
"386.8000","7.7346","7.21407","0.08822"
"387.2000","7.7426","7.21374","0.08837"
"387.6000","7.7504","7.21027","0.08852"
"388.0000","7.7585","7.21094","0.08867"
"388.4000","7.7664","7.20882","0.08882"
"388.8000","7.7745","7.20784","0.08897"
"389.2000","7.7826","7.20761","0.08912"
"389.6000","7.7906","7.20642","0.08928"
"390.0000","7.7985","7.20457","0.08943"
"390.4000","7.8064","7.20221","0.08958"
"390.8000","7.8146","7.20346","0.08973"
"391.2000","7.8223","7.19910","0.08988"
"391.6000","7.8306","7.19935","0.09004"
"392.0000","7.8385","7.19816","0.09019"
"392.4000","7.8465","7.19593","0.09034"
"392.8000","7.8546","7.19638","0.09050"
"393.2000","7.8625","7.19257","0.09065"
"393.6000","7.8706","7.19263","0.09080"
"394.0000","7.8784","7.18895","0.09096"
"394.4000","7.8865","7.18773","0.09111"
"394.8000","7.8945","7.18773","0.09127"
"395.2000","7.9025","7.18578","0.09142"
"395.6000","7.9106","7.18361","0.09158"
"396.0000","7.9185","7.18103","0.09174"
"396.4000","7.9265","7.18058","0.09190"
"396.8000","7.9343","7.17564","0.09205"
"397.2000","7.9426","7.17604","0.09221"
"397.6000","7.9505","7.17389","0.09236"
"398.0000","7.9585","7.17066","0.09253"
"398.4000","7.9666","7.16951","0.09268"
"398.8000","7.9745","7.16576","0.09284"
"399.2000","7.9826","7.16570","0.09300"
"399.6000","7.9904","7.16012","0.09316"
"400.0000","7.9986","7.15840","0.09332"
"400.4000","8.0065","7.15629","0.09348"
"400.8000","8.0144","7.15272","0.09364"
"401.2000","8.0226","7.15101","0.09380"
"401.6000","8.0306","7.14713","0.09396"
"402.0000","8.0386","7.14514","0.09412"
"402.4000","8.0464","7.13838","0.09428"
"402.8000","8.0546","7.13675","0.09445"
"403.2000","8.0624","7.13335","0.09460"
"403.6000","8.0705","7.12906","0.09477"
"404.0000","8.0786","7.12567","0.09493"
"404.4000","8.0865","7.12062","0.09510"
"404.8000","8.0945","7.11731","0.09526"
"405.2000","8.1023","7.10998","0.09542"
"405.6000","8.1106","7.10673","0.09559"
"406.0000","8.1185","7.10116","0.09575"
"406.4000","8.1265","7.09501","0.09592"
"406.8000","8.1345","7.08993","0.09609"
"407.2000","8.1426","7.08433","0.09625"
"407.6000","8.1505","7.07935","0.09642"
"408.0000","8.1584","7.06952","0.09659"
"408.4000","8.1667","7.06517","0.09676"
"408.8000","8.1744","7.05741","0.09692"
"409.2000","8.1824","7.04942","0.09709"
"409.6000","8.1906","7.04475","0.09726"
"410.0000","8.1986","7.03699","0.09743"
"410.4000","8.2066","7.02880","0.09760"
"410.8000","8.2144","7.01866","0.09777"
"411.2000","8.2226","7.01282","0.09794"
"411.6000","8.2303","7.00318","0.09811"
"412.0000","8.2384","6.99477","0.09829"
"412.4000","8.2466","6.98695","0.09846"
"412.8000","8.2547","6.97869","0.09863"
"413.2000","8.2625","6.96936","0.09880"
"413.6000","8.2703","6.95771","0.09897"
"414.0000","8.2787","6.95184","0.09915"
"414.4000","8.2864","6.93992","0.09932"
"414.8000","8.2944","6.92920","0.09949"
"415.2000","8.3026","6.92176","0.09967"
"415.6000","8.3106","6.91156","0.09984"
"416.0000","8.3185","6.90133","0.10001"
"416.4000","8.3265","6.88871","0.10019"
"416.8000","8.3347","6.88055","0.10037"
"417.2000","8.3423","6.86730","0.10053"
"417.6000","8.3504","6.85665","0.10071"
"418.0000","8.3585","6.84739","0.10089"
"418.4000","8.3667","6.83617","0.10106"
"418.8000","8.3745","6.82425","0.10124"
"419.2000","8.3825","6.81094","0.10141"
"419.6000","8.3907","6.80270","0.10159"
"420.0000","8.3982","6.78759","0.10176"
"420.4000","8.4064","6.77577","0.10194"
"420.8000","8.4146","6.76567","0.10212"
"421.2000","8.4226","6.75281","0.10230"
"421.6000","8.4304","6.73982","0.10247"
"422.0000","8.4385","6.72635","0.10265"
"422.4000","8.4467","6.71656","0.10283"
"422.8000","8.4544","6.69955","0.10301"
"423.2000","8.4625","6.68657","0.10319"
"423.6000","8.4705","6.67488","0.10336"
"424.0000","8.4785","6.66124","0.10354"
"424.4000","8.4864","6.64780","0.10371"
"424.8000","8.4946","6.63243","0.10390"
"425.2000","8.5028","6.62150","0.10408"
"425.6000","8.5103","6.60285","0.10425"
"426.0000","8.5184","6.58898","0.10444"
"426.4000","8.5265","6.57684","0.10461"
"426.8000","8.5346","6.56115","0.10480"
"427.2000","8.5425","6.54529","0.10498"
"427.6000","8.5506","6.53038","0.10516"
"428.0000","8.5587","6.51745","0.10534"
"428.4000","8.5662","6.49785","0.10551"
"428.8000","8.5745","6.48343","0.10570"
"429.2000","8.5826","6.46867","0.10588"
"429.6000","8.5905","6.45172","0.10606"
"430.0000","8.5984","6.43547","0.10624"
"430.4000","8.6066","6.41872","0.10643"
"430.8000","8.6148","6.40513","0.10661"
"431.2000","8.6223","6.38313","0.10679"
"431.6000","8.6305","6.36670","0.10698"
"432.0000","8.6386","6.35178","0.10716"
"432.4000","8.6464","6.33270","0.10735"
"432.8000","8.6544","6.31538","0.10753"
"433.2000","8.6627","6.29778","0.10772"
"433.6000","8.6707","6.28136","0.10790"
"434.0000","8.6783","6.25876","0.10808"
"434.4000","8.6865","6.24204","0.10827"
"434.8000","8.6945","6.22406","0.10846"
"435.2000","8.7026","6.20426","0.10864"
"435.6000","8.7104","6.18474","0.10883"
"436.0000","8.7187","6.16571","0.10902"
"436.4000","8.7267","6.14810","0.10921"
"436.8000","8.7343","6.12399","0.10939"
"437.2000","8.7426","6.10533","0.10958"
"437.6000","8.7506","6.08594","0.10977"
"438.0000","8.7585","6.06349","0.10996"
"438.4000","8.7664","6.04313","0.11014"
"438.8000","8.7746","6.02302","0.11033"
"439.2000","8.7826","6.00299","0.11052"
"439.6000","8.7904","5.97739","0.11072"
"440.0000","8.7986","5.95696","0.11091"
"440.4000","8.8065","5.93487","0.11110"
"440.8000","8.8145","5.91176","0.11129"
"441.2000","8.8224","5.88972","0.11148"
"441.6000","8.8307","5.86673","0.11167"
"442.0000","8.8386","5.84470","0.11186"
"442.4000","8.8464","5.81744","0.11206"
"442.8000","8.8546","5.79510","0.11225"
"443.2000","8.8624","5.77077","0.11244"
"443.6000","8.8705","5.74469","0.11263"
"444.0000","8.8785","5.72004","0.11283"
"444.4000","8.8866","5.69507","0.11303"
"444.8000","8.8945","5.66951","0.11322"
"445.2000","8.9024","5.64048","0.11342"
"445.6000","8.9106","5.61531","0.11362"
"446.0000","8.9185","5.58659","0.11381"
"446.4000","8.9265","5.55771","0.11400"
"446.8000","8.9344","5.53000","0.11420"
"447.2000","8.9425","5.50066","0.11440"
"447.6000","8.9505","5.47282","0.11460"
"448.0000","8.9585","5.43871","0.11481"
"448.4000","8.9667","5.40846","0.11501"
"448.8000","8.9745","5.37645","0.11521"
"449.2000","8.9825","5.34291","0.11542"
"449.6000","8.9904","5.31064","0.11562"
"450.0000","8.9986","5.27655","0.11584"
"450.4000","9.0065","5.24209","0.11604"
"450.8000","9.0145","5.20412","0.11626"
"451.2000","9.0226","5.16706","0.11647"
"451.6000","9.0304","5.12543","0.11669"
"452.0000","9.0385","5.08074","0.11692"
"452.4000","9.0465","5.03499","0.11714"
"452.8000","9.0546","4.97304","0.11740"
"453.2000","9.0625","4.87979","0.11769"
"453.2690","9.0641","4.46710","0.11826"
"453.2710","9.0642","4.28765","0.11849"