File: Coupon Test Data/Tensile Test_Neebajan_Alan_4.csv
Time,Displacement,Force,Strain 1
(s),(mm),(kN),(mm/mm)
"0.0000","0.0000","0.19674","-0.00011"
"0.4000","0.0064","0.25572","-0.00007"
"0.8000","0.0142","0.33300","-0.00003"
"1.2000","0.0222","0.41106","0.00002"
"1.6000","0.0305","0.49003","0.00007"
"2.0000","0.0386","0.56656","0.00012"
"2.4000","0.0464","0.64027","0.00016"
"2.8000","0.0543","0.71342","0.00021"
"3.2000","0.0626","0.78396","0.00025"
"3.6000","0.0704","0.85346","0.00030"
"4.0000","0.0784","0.92526","0.00034"
"4.4000","0.0865","0.99509","0.00039"
"4.8000","0.0945","1.06617","0.00043"
"5.2000","0.1024","1.13135","0.00047"
"5.6000","0.1104","1.19747","0.00051"
"6.0000","0.1186","1.26863","0.00056"
"6.4000","0.1263","1.33418","0.00060"
"6.8000","0.1343","1.39908","0.00064"
"7.2000","0.1425","1.46701","0.00068"
"7.6000","0.1506","1.53589","0.00073"
"8.0000","0.1585","1.60089","0.00077"
"8.4000","0.1664","1.66291","0.00081"
"8.8000","0.1746","1.73096","0.00085"
"9.2000","0.1823","1.79329","0.00089"
"9.6000","0.1904","1.85898","0.00093"
"10.0000","0.1985","1.92163","0.00097"
"10.4000","0.2066","1.98679","0.00101"
"10.8000","0.2144","2.04951","0.00105"
"11.2000","0.2224","2.10899","0.00109"
"11.6000","0.2307","2.17564","0.00113"
"12.0000","0.2384","2.23559","0.00117"
"12.4000","0.2464","2.29365","0.00121"
"12.8000","0.2545","2.35820","0.00125"
"13.2000","0.2625","2.41977","0.00129"
"13.6000","0.2703","2.47605","0.00133"
"14.0000","0.2785","2.53884","0.00137"
"14.4000","0.2867","2.60154","0.00141"
"14.8000","0.2943","2.65393","0.00144"
"15.2000","0.3024","2.71504","0.00148"
"15.6000","0.3105","2.77612","0.00152"
"16.0000","0.3186","2.83215","0.00156"
"16.4000","0.3264","2.88971","0.00159"
"16.8000","0.3345","2.94906","0.00163"
"17.2000","0.3427","3.00525","0.00167"
"17.6000","0.3502","3.05890","0.00170"
"18.0000","0.3584","3.11774","0.00174"
"18.4000","0.3666","3.17245","0.00178"
"18.8000","0.3745","3.22890","0.00182"
"19.2000","0.3824","3.28317","0.00185"
"19.6000","0.3905","3.33688","0.00189"
"20.0000","0.3987","3.39425","0.00192"
"20.4000","0.4063","3.44212","0.00196"
"20.8000","0.4145","3.49797","0.00199"
"21.2000","0.4225","3.55290","0.00203"
"21.6000","0.4305","3.60189","0.00207"
"22.0000","0.4383","3.65486","0.00210"
"22.4000","0.4466","3.71001","0.00214"
"22.8000","0.4547","3.75961","0.00217"
"23.2000","0.4622","3.80840","0.00221"
"23.6000","0.4705","3.86222","0.00224"
"24.0000","0.4785","3.90995","0.00228"
"24.4000","0.4865","3.96078","0.00232"
"24.8000","0.4944","4.00869","0.00235"
"25.2000","0.5026","4.05799","0.00238"
"25.6000","0.5106","4.10808","0.00242"
"26.0000","0.5182","4.14963","0.00245"
"26.4000","0.5265","4.20126","0.00248"
"26.8000","0.5345","4.25051","0.00252"
"27.2000","0.5425","4.29348","0.00255"
"27.6000","0.5504","4.34151","0.00259"
"28.0000","0.5585","4.39067","0.00262"
"28.4000","0.5667","4.43453","0.00266"
"28.8000","0.5743","4.47791","0.00269"
"29.2000","0.5825","4.52527","0.00273"
"29.6000","0.5905","4.56631","0.00276"
"30.0000","0.5984","4.61094","0.00279"
"30.4000","0.6063","4.65396","0.00283"
"30.8000","0.6146","4.69559","0.00286"
"31.2000","0.6226","4.73912","0.00289"
"31.6000","0.6304","4.77555","0.00293"
"32.0000","0.6385","4.81776","0.00296"
"32.4000","0.6464","4.85876","0.00300"
"32.8000","0.6545","4.89579","0.00303"
"33.2000","0.6624","4.93632","0.00307"
"33.6000","0.6706","4.97744","0.00310"
"34.0000","0.6786","5.01298","0.00314"
"34.4000","0.6863","5.04890","0.00318"
"34.8000","0.6946","5.08545","0.00322"
"35.2000","0.7025","5.12139","0.00325"
"35.6000","0.7104","5.15642","0.00330"
"36.0000","0.7184","5.18968","0.00334"
"36.4000","0.7266","5.21970","0.00338"
"36.8000","0.7345","5.25164","0.00343"
"37.2000","0.7424","5.27939","0.00347"
"37.6000","0.7506","5.30710","0.00352"
"38.0000","0.7584","5.33004","0.00357"
"38.4000","0.7664","5.35233","0.00363"
"38.8000","0.7743","5.36632","0.00368"
"39.2000","0.7826","5.38950","0.00374"
"39.6000","0.7905","5.40586","0.00381"
"40.0000","0.7984","5.41856","0.00388"
"40.4000","0.8066","5.43284","0.00396"
"40.8000","0.8143","5.44161","0.00403"
"41.2000","0.8225","5.45074","0.00411"
"41.6000","0.8305","5.45954","0.00419"
"42.0000","0.8386","5.46718","0.00427"
"42.4000","0.8465","5.47351","0.00435"
"42.8000","0.8544","5.47833","0.00444"
"43.2000","0.8626","5.48551","0.00453"
"43.6000","0.8704","5.48788","0.00461"
"44.0000","0.8785","5.49233","0.00470"
"44.4000","0.8864","5.49612","0.00479"
"44.8000","0.8945","5.50021","0.00489"
"45.2000","0.9024","5.50409","0.00498"
"45.6000","0.9105","5.50573","0.00507"
"46.0000","0.9187","5.51031","0.00517"
"46.4000","0.9264","5.51089","0.00525"
"46.8000","0.9345","5.51328","0.00535"
"47.2000","0.9424","5.51597","0.00544"
"47.6000","0.9506","5.51897","0.00554"
"48.0000","0.9584","5.52033","0.00563"
"48.4000","0.9665","5.52203","0.00573"
"48.8000","0.9746","5.52534","0.00583"
"49.2000","0.9823","5.52492","0.00592"
"49.6000","0.9906","5.52761","0.00602"
"50.0000","0.9985","5.52864","0.00611"
"50.4000","1.0066","5.53068","0.00621"
"50.8000","1.0144","5.53216","0.00630"
"51.2000","1.0225","5.53318","0.00640"
"51.6000","1.0307","5.53697","0.00650"
"52.0000","1.0384","5.53571","0.00660"
"52.4000","1.0465","5.53721","0.00669"
"52.8000","1.0544","5.53838","0.00679"
"53.2000","1.0625","5.54036","0.00689"
"53.6000","1.0703","5.54133","0.00698"
"54.0000","1.0786","5.54287","0.00709"
"54.4000","1.0867","5.54533","0.00719"
"54.8000","1.0945","5.54425","0.00728"
"55.2000","1.1025","5.54626","0.00738"
"55.6000","1.1103","5.54633","0.00748"
"56.0000","1.1186","5.54889","0.00758"
"56.4000","1.1264","5.54926","0.00767"
"56.8000","1.1345","5.55003","0.00777"
"57.2000","1.1426","5.55310","0.00787"
"57.6000","1.1504","5.55226","0.00797"
"58.0000","1.1586","5.55405","0.00807"
"58.4000","1.1665","5.55414","0.00817"
"58.8000","1.1745","5.55575","0.00827"
"59.2000","1.1824","5.55600","0.00836"
"59.6000","1.1905","5.55732","0.00846"
"60.0000","1.1986","5.56034","0.00856"
"60.4000","1.2065","5.55965","0.00866"
"60.8000","1.2146","5.56120","0.00876"
"61.2000","1.2224","5.56044","0.00886"
"61.6000","1.2305","5.56300","0.00896"
"62.0000","1.2383","5.56316","0.00906"
"62.4000","1.2465","5.56425","0.00916"
"62.8000","1.2546","5.56694","0.00926"
"63.2000","1.2625","5.56636","0.00936"
"63.6000","1.2705","5.56744","0.00945"
"64.0000","1.2783","5.56744","0.00955"
"64.4000","1.2866","5.56993","0.00965"
"64.8000","1.2944","5.56971","0.00975"
"65.2000","1.3025","5.57074","0.00985"
"65.6000","1.3105","5.57295","0.00995"
"66.0000","1.3185","5.57353","0.01005"
"66.4000","1.3266","5.57476","0.01015"
"66.8000","1.3344","5.57377","0.01025"
"67.2000","1.3426","5.57657","0.01035"
"67.6000","1.3504","5.57595","0.01044"
"68.0000","1.3584","5.57672","0.01054"
"68.4000","1.3665","5.57994","0.01064"
"68.8000","1.3746","5.58024","0.01074"
"69.2000","1.3826","5.58064","0.01084"
"69.6000","1.3904","5.58013","0.01094"
"70.0000","1.3985","5.58287","0.01103"
"70.4000","1.4063","5.58238","0.01113"
"70.8000","1.4145","5.58391","0.01123"
"71.2000","1.4225","5.58582","0.01133"
"71.6000","1.4306","5.58658","0.01143"
"72.0000","1.4385","5.58723","0.01152"
"72.4000","1.4464","5.58647","0.01162"
"72.8000","1.4546","5.58971","0.01172"
"73.2000","1.4624","5.58872","0.01181"
"73.6000","1.4705","5.57722","0.01190"
"74.0000","1.4785","5.57656","0.01196"
"74.4000","1.4864","5.59050","0.01204"
"74.8000","1.4946","5.59509","0.01214"
"75.2000","1.5025","5.59439","0.01224"
"75.6000","1.5106","5.59621","0.01233"
"76.0000","1.5184","5.59519","0.01243"
"76.4000","1.5265","5.59629","0.01253"
"76.8000","1.5344","5.59810","0.01262"
"77.2000","1.5426","5.59930","0.01272"
"77.6000","1.5505","5.59951","0.01282"
"78.0000","1.5585","5.59975","0.01291"
"78.4000","1.5665","5.60225","0.01301"
"78.8000","1.5743","5.60054","0.01310"
"79.2000","1.5826","5.60288","0.01320"
"79.6000","1.5905","5.60432","0.01330"
"80.0000","1.5985","5.60440","0.01339"
"80.4000","1.6066","5.60617","0.01349"
"80.8000","1.6144","5.60585","0.01359"
"81.2000","1.6226","5.60856","0.01368"
"81.6000","1.6304","5.60732","0.01378"
"82.0000","1.6385","5.60856","0.01388"
"82.4000","1.6465","5.61040","0.01397"
"82.8000","1.6544","5.61067","0.01407"
"83.2000","1.6625","5.61221","0.01416"
"83.6000","1.6706","5.61311","0.01426"
"84.0000","1.6786","5.61458","0.01436"
"84.4000","1.6863","5.61267","0.01445"
"84.8000","1.6946","5.61594","0.01454"
"85.2000","1.7023","5.61635","0.01464"
"85.6000","1.7105","5.61707","0.01473"
"86.0000","1.7186","5.61885","0.01483"
"86.4000","1.7265","5.61909","0.01492"
"86.8000","1.7346","5.62091","0.01502"
"87.2000","1.7423","5.61953","0.01511"
"87.6000","1.7506","5.62195","0.01521"
"88.0000","1.7585","5.62349","0.01530"
"88.4000","1.7664","5.62296","0.01540"
"88.8000","1.7745","5.62458","0.01549"
"89.2000","1.7826","5.62645","0.01559"
"89.6000","1.7905","5.62733","0.01568"
"90.0000","1.7984","5.62592","0.01577"
"90.4000","1.8067","5.62903","0.01587"
"90.8000","1.8143","5.62864","0.01596"
"91.2000","1.8224","5.62904","0.01606"
"91.6000","1.8305","5.63187","0.01615"
"92.0000","1.8386","5.63277","0.01625"
"92.4000","1.8466","5.63364","0.01634"
"92.8000","1.8544","5.63245","0.01643"
"93.2000","1.8626","5.63526","0.01653"
"93.6000","1.8703","5.63520","0.01662"
"94.0000","1.8784","5.63585","0.01671"
"94.4000","1.8866","5.63777","0.01681"
"94.8000","1.8946","5.63925","0.01690"
"95.2000","1.9024","5.63957","0.01700"
"95.6000","1.9103","5.63905","0.01709"
"96.0000","1.9187","5.64259","0.01718"
"96.4000","1.9264","5.64157","0.01728"
"96.8000","1.9344","5.64207","0.01737"
"97.2000","1.9425","5.64456","0.01747"
"97.6000","1.9505","5.64547","0.01756"
"98.0000","1.9584","5.64612","0.01765"
"98.4000","1.9664","5.64605","0.01774"
"98.8000","1.9747","5.64870","0.01784"
"99.2000","1.9823","5.64726","0.01793"
"99.6000","1.9904","5.64846","0.01802"
"100.0000","1.9985","5.65097","0.01811"
"100.4000","2.0067","5.65256","0.01821"
"100.8000","2.0145","5.65225","0.01830"
"101.2000","2.0225","5.65227","0.01839"
"101.6000","2.0307","5.65580","0.01849"
"102.0000","2.0382","5.65356","0.01857"
"102.4000","2.0464","5.65492","0.01867"
"102.8000","2.0546","5.65759","0.01876"
"103.2000","2.0626","5.65820","0.01885"
"103.6000","2.0704","5.65836","0.01894"
"104.0000","2.0784","5.65915","0.01904"
"104.4000","2.0867","5.66243","0.01913"
"104.8000","2.0944","5.66040","0.01922"
"105.2000","2.1024","5.66150","0.01931"
"105.6000","2.1105","5.66356","0.01941"
"106.0000","2.1186","5.66480","0.01950"
"106.4000","2.1264","5.66493","0.01959"
"106.8000","2.1345","5.66586","0.01968"
"107.2000","2.1428","5.66911","0.01977"
"107.6000","2.1502","5.66599","0.01986"
"108.0000","2.1584","5.66784","0.01995"
"108.4000","2.1665","5.67052","0.02005"
"108.8000","2.1746","5.67110","0.02014"
"109.2000","2.1824","5.67095","0.02023"
"109.6000","2.1906","5.67259","0.02032"
"110.0000","2.1987","5.67518","0.02041"
"110.4000","2.2062","5.67240","0.02050"
"110.8000","2.2145","5.67504","0.02059"
"111.2000","2.2226","5.67676","0.02069"
"111.6000","2.2305","5.67717","0.02078"
"112.0000","2.2384","5.67743","0.02087"
"112.4000","2.2466","5.67917","0.02096"
"112.8000","2.2547","5.68218","0.02105"
"113.2000","2.2623","5.67891","0.02114"
"113.6000","2.2705","5.68109","0.02123"
"114.0000","2.2785","5.68314","0.02132"
"114.4000","2.2864","5.68296","0.02141"
"114.8000","2.2944","5.68386","0.02151"
"115.2000","2.3027","5.68627","0.02160"
"115.6000","2.3107","5.68784","0.02169"
"116.0000","2.3183","5.68528","0.02178"
"116.4000","2.3265","5.68795","0.02187"
"116.8000","2.3344","5.68903","0.02196"
"117.2000","2.3425","5.69011","0.02205"
"117.6000","2.3504","5.69016","0.02214"
"118.0000","2.3586","5.69212","0.02223"
"118.4000","2.3667","5.69411","0.02232"
"118.8000","2.3742","5.69142","0.02241"
"119.2000","2.3825","5.69468","0.02250"
"119.6000","2.3905","5.69580","0.02259"
"120.0000","2.3985","5.69560","0.02268"
"120.4000","2.4064","5.69616","0.02277"
"120.8000","2.4146","5.69873","0.02287"
"121.2000","2.4226","5.70035","0.02295"
"121.6000","2.4304","5.69843","0.02305"
"122.0000","2.4386","5.70104","0.02314"
"122.4000","2.4465","5.70117","0.02322"
"122.8000","2.4544","5.70176","0.02332"
"123.2000","2.4623","5.70284","0.02341"
"123.6000","2.4706","5.70506","0.02350"
"124.0000","2.4786","5.70623","0.02359"
"124.4000","2.4864","5.70440","0.02367"
"124.8000","2.4946","5.70736","0.02377"
"125.2000","2.5024","5.70764","0.02385"
"125.6000","2.5105","5.70826","0.02394"
"126.0000","2.5185","5.70920","0.02404"
"126.4000","2.5266","5.71136","0.02412"
"126.8000","2.5345","5.71179","0.02422"
"127.2000","2.5424","5.71115","0.02430"
"127.6000","2.5506","5.71439","0.02439"
"128.0000","2.5584","5.71377","0.02448"
"128.4000","2.5665","5.71439","0.02457"
"128.8000","2.5744","5.71507","0.02466"
"129.2000","2.5825","5.71699","0.02475"
"129.6000","2.5905","5.71866","0.02484"
"130.0000","2.5985","5.71760","0.02493"
"130.4000","2.6067","5.72027","0.02502"
"130.8000","2.6144","5.71162","0.02509"
"131.2000","2.6224","5.71866","0.02518"
"131.6000","2.6304","5.72162","0.02526"
"132.0000","2.6386","5.72398","0.02535"
"132.4000","2.6465","5.72428","0.02544"
"132.8000","2.6545","5.72450","0.02553"
"133.2000","2.6626","5.72665","0.02562"
"133.6000","2.6703","5.72553","0.02571"
"134.0000","2.6785","5.72731","0.02580"
"134.4000","2.6864","5.72773","0.02589"
"134.8000","2.6946","5.72948","0.02598"
"135.2000","2.7024","5.72973","0.02607"
"135.6000","2.7104","5.72998","0.02616"
"136.0000","2.7187","5.73339","0.02625"
"136.4000","2.7264","5.72182","0.02632"
"136.8000","2.7345","5.72818","0.02640"
"137.2000","2.7424","5.73293","0.02648"
"137.6000","2.7505","5.73537","0.02657"
"138.0000","2.7584","5.73619","0.02666"
"138.4000","2.7666","5.73710","0.02675"
"138.8000","2.7747","5.73903","0.02684"
"139.2000","2.7824","5.73761","0.02693"
"139.6000","2.7905","5.73900","0.02702"
"140.0000","2.7983","5.73925","0.02711"
"140.4000","2.8065","5.74135","0.02719"
"140.8000","2.8144","5.74176","0.02728"
"141.2000","2.8225","5.74228","0.02737"
"141.6000","2.8306","5.74461","0.02746"
"142.0000","2.8384","5.74354","0.02755"
"142.4000","2.8466","5.74523","0.02764"
"142.8000","2.8545","5.74538","0.02773"
"143.2000","2.8625","5.74672","0.02782"
"143.6000","2.8704","5.74688","0.02790"
"144.0000","2.8785","5.74814","0.02799"
"144.4000","2.8866","5.75053","0.02808"
"144.8000","2.8944","5.74959","0.02817"
"145.2000","2.9026","5.75127","0.02826"
"145.6000","2.9104","5.75090","0.02835"
"146.0000","2.9185","5.75254","0.02844"
"146.4000","2.9263","5.75293","0.02853"
"146.8000","2.9346","5.75421","0.02862"
"147.2000","2.9427","5.75671","0.02871"
"147.6000","2.9505","5.75547","0.02879"
"148.0000","2.9585","5.75666","0.02888"
"148.4000","2.9664","5.75674","0.02897"
"148.8000","2.9746","5.75878","0.02906"
"149.2000","2.9824","5.75858","0.02915"
"149.6000","2.9905","5.75986","0.02924"
"150.0000","2.9986","5.76166","0.02932"
"150.4000","3.0064","5.76148","0.02941"
"150.8000","3.0146","5.76327","0.02950"
"151.2000","3.0224","5.76240","0.02959"
"151.6000","3.0306","5.76465","0.02968"
"152.0000","3.0384","5.76420","0.02977"
"152.4000","3.0465","5.76501","0.02986"
"152.8000","3.0546","5.76792","0.02994"
"153.2000","3.0625","5.76758","0.03003"
"153.6000","3.0706","5.76873","0.03012"
"154.0000","3.0784","5.76780","0.03021"
"154.4000","3.0865","5.77002","0.03030"
"154.8000","3.0944","5.77026","0.03038"
"155.2000","3.1026","5.77156","0.03047"
"155.6000","3.1106","5.77307","0.03056"
"156.0000","3.1186","5.77355","0.03065"
"156.4000","3.1266","5.77430","0.03074"
"156.8000","3.1343","5.77328","0.03083"
"157.2000","3.1426","5.77654","0.03092"
"157.6000","3.1504","5.77588","0.03100"
"158.0000","3.1585","5.77657","0.03109"
"158.4000","3.1665","5.77860","0.03118"
"158.8000","3.1745","5.77905","0.03127"
"159.2000","3.1826","5.78025","0.03136"
"159.6000","3.1904","5.77961","0.03144"
"160.0000","3.1986","5.78184","0.03153"
"160.4000","3.2064","5.78117","0.03162"
"160.8000","3.2145","5.78220","0.03171"
"161.2000","3.2225","5.78416","0.03180"
"161.6000","3.2306","5.78525","0.03189"
"162.0000","3.2386","5.78582","0.03197"
"162.4000","3.2464","5.78480","0.03206"
"162.8000","3.2546","5.78763","0.03215"
"163.2000","3.2623","5.78660","0.03224"
"163.6000","3.2705","5.78809","0.03233"
"164.0000","3.2786","5.78994","0.03242"
"164.4000","3.2866","5.79025","0.03251"
"164.8000","3.2946","5.79101","0.03259"
"165.2000","3.3024","5.79056","0.03268"
"165.6000","3.3106","5.79320","0.03277"
"166.0000","3.3184","5.79230","0.03285"
"166.4000","3.3265","5.79346","0.03295"
"166.8000","3.3344","5.79460","0.03303"
"167.2000","3.3425","5.79571","0.03312"
"167.6000","3.3506","5.79686","0.03321"
"168.0000","3.3585","5.79627","0.03330"
"168.4000","3.3666","5.79898","0.03339"
"168.8000","3.3743","5.79713","0.03347"
"169.2000","3.3825","5.79859","0.03356"
"169.6000","3.3904","5.80035","0.03365"
"170.0000","3.3985","5.80103","0.03374"
"170.4000","3.4066","5.80195","0.03383"
"170.8000","3.4145","5.80190","0.03392"
"171.2000","3.4226","5.80381","0.03401"
"171.6000","3.4303","5.80249","0.03409"
"172.0000","3.4385","5.80481","0.03418"
"172.4000","3.4465","5.80554","0.03427"
"172.8000","3.4545","5.80601","0.03436"
"173.2000","3.4625","5.80712","0.03445"
"173.6000","3.4705","5.80720","0.03454"
"174.0000","3.4786","5.80966","0.03463"
"174.4000","3.4863","5.80767","0.03471"
"174.8000","3.4946","5.80977","0.03481"
"175.2000","3.5024","5.81051","0.03489"
"175.6000","3.5104","5.81057","0.03498"
"176.0000","3.5185","5.81291","0.03507"
"176.4000","3.5266","5.81347","0.03516"
"176.8000","3.5346","5.81429","0.03525"
"177.2000","3.5424","5.81298","0.03533"
"177.6000","3.5505","5.81516","0.03542"
"178.0000","3.5583","5.81529","0.03551"
"178.4000","3.5664","5.81635","0.03560"
"178.8000","3.5746","5.81773","0.03569"
"179.2000","3.5826","5.81838","0.03577"
"179.6000","3.5905","5.81946","0.03586"
"180.0000","3.5983","5.81794","0.03595"
"180.4000","3.6066","5.82094","0.03604"
"180.8000","3.6145","5.82101","0.03613"
"181.2000","3.6224","5.82091","0.03621"
"181.6000","3.6305","5.82264","0.03630"
"182.0000","3.6386","5.82371","0.03639"
"182.4000","3.6465","5.82435","0.03648"
"182.8000","3.6544","5.82363","0.03656"
"183.2000","3.6627","5.82606","0.03666"
"183.6000","3.6704","5.82524","0.03674"
"184.0000","3.6784","5.82582","0.03683"
"184.4000","3.6865","5.82785","0.03692"
"184.8000","3.6947","5.82939","0.03701"
"185.2000","3.7025","5.82927","0.03710"
"185.6000","3.7104","5.82820","0.03718"
"186.0000","3.7187","5.83143","0.03727"
"186.4000","3.7263","5.82991","0.03736"
"186.8000","3.7344","5.83066","0.03745"
"187.2000","3.7426","5.83316","0.03754"
"187.6000","3.7506","5.83381","0.03763"
"188.0000","3.7584","5.83374","0.03771"
"188.4000","3.7664","5.83358","0.03780"
"188.8000","3.7747","5.83663","0.03789"
"189.2000","3.7824","5.83530","0.03798"
"189.6000","3.7904","5.83564","0.03807"
"190.0000","3.7985","5.83711","0.03815"
"190.4000","3.8066","5.83893","0.03824"
"190.8000","3.8144","5.83867","0.03833"
"191.2000","3.8225","5.83881","0.03842"
"191.6000","3.8307","5.84194","0.03851"
"192.0000","3.8383","5.83912","0.03859"
"192.4000","3.8464","5.84042","0.03868"
"192.8000","3.8545","5.84276","0.03877"
"193.2000","3.8626","5.84339","0.03886"
"193.6000","3.8705","5.84347","0.03895"
"194.0000","3.8785","5.84370","0.03904"
"194.4000","3.8867","5.84612","0.03913"
"194.8000","3.8942","5.84401","0.03921"
"195.2000","3.9024","5.84558","0.03930"
"195.6000","3.9106","5.84725","0.03939"
"196.0000","3.9186","5.84811","0.03948"
"196.4000","3.9264","5.84745","0.03956"
"196.8000","3.9345","5.84856","0.03965"
"197.2000","3.9427","5.85168","0.03974"
"197.6000","3.9503","5.84847","0.03983"
"198.0000","3.9585","5.85039","0.03992"
"198.4000","3.9665","5.85179","0.04001"
"198.8000","3.9745","5.84290","0.04007"
"199.2000","3.9824","5.85026","0.04015"
"199.6000","3.9906","5.85341","0.04024"
"200.0000","3.9987","5.85587","0.04033"
"200.4000","4.0063","5.85358","0.04042"
"200.8000","4.0144","5.85511","0.04051"
"201.2000","4.0225","5.85694","0.04059"
"201.6000","4.0306","5.85751","0.04068"
"202.0000","4.0384","5.85679","0.04077"
"202.4000","4.0466","5.85859","0.04086"
"202.8000","4.0547","5.86035","0.04095"
"203.2000","4.0622","5.85708","0.04103"
"203.6000","4.0705","5.86016","0.04112"
"204.0000","4.0785","5.86102","0.04121"
"204.4000","4.0865","5.86060","0.04130"
"204.8000","4.0944","5.86115","0.04139"
"205.2000","4.1025","5.86286","0.04148"
"205.6000","4.1107","5.86512","0.04157"
"206.0000","4.1183","5.86215","0.04165"
"206.4000","4.1266","5.86414","0.04174"
"206.8000","4.1345","5.86489","0.04183"
"207.2000","4.1424","5.86488","0.04192"
"207.6000","4.1503","5.86550","0.04201"
"208.0000","4.1587","5.86785","0.04210"
"208.4000","4.1667","5.86871","0.04218"
"208.8000","4.1743","5.86598","0.04227"
"209.2000","4.1825","5.86862","0.04236"
"209.6000","4.1904","5.86917","0.04245"
"210.0000","4.1985","5.86943","0.04254"
"210.4000","4.2064","5.86982","0.04262"
"210.8000","4.2147","5.87198","0.04272"
"211.2000","4.2226","5.87260","0.04280"
"211.6000","4.2303","5.87046","0.04289"
"212.0000","4.2386","5.87319","0.04298"
"212.4000","4.2465","5.86451","0.04305"
"212.8000","4.2545","5.87105","0.04313"
"213.2000","4.2623","5.87327","0.04322"
"213.6000","4.2706","5.87611","0.04331"
"214.0000","4.2786","5.87763","0.04340"
"214.4000","4.2864","5.87524","0.04348"
"214.8000","4.2947","5.87789","0.04357"
"215.2000","4.3024","5.87736","0.04366"
"215.6000","4.3104","5.87739","0.04375"
"216.0000","4.3184","5.87840","0.04384"
"216.4000","4.3266","5.88032","0.04393"
"216.8000","4.3346","5.88058","0.04401"
"217.2000","4.3424","5.87939","0.04410"
"217.6000","4.3506","5.88163","0.04419"
"218.0000","4.3584","5.88081","0.04428"
"218.4000","4.3665","5.88183","0.04437"
"218.8000","4.3745","5.88219","0.04446"
"219.2000","4.3826","5.88365","0.04455"
"219.6000","4.3905","5.88404","0.04463"
"220.0000","4.3984","5.88305","0.04472"
"220.4000","4.4067","5.88613","0.04481"
"220.8000","4.4144","5.88478","0.04490"
"221.2000","4.4225","5.88510","0.04499"
"221.6000","4.4304","5.88586","0.04507"
"222.0000","4.4385","5.88734","0.04516"
"222.4000","4.4465","5.88794","0.04525"
"222.8000","4.4545","5.88773","0.04534"
"223.2000","4.4627","5.88982","0.04543"
"223.6000","4.4704","5.88796","0.04552"
"224.0000","4.4785","5.88897","0.04561"
"224.4000","4.4864","5.88943","0.04570"
"224.8000","4.4946","5.89142","0.04578"
"225.2000","4.5025","5.89126","0.04587"
"225.6000","4.5105","5.89123","0.04596"
"226.0000","4.5186","5.89362","0.04605"
"226.4000","4.5263","5.89206","0.04614"
"226.8000","4.5345","5.89320","0.04623"
"227.2000","4.5425","5.89374","0.04632"
"227.6000","4.5506","5.89472","0.04640"
"228.0000","4.5584","5.89456","0.04649"
"228.4000","4.5665","5.89522","0.04658"
"228.8000","4.5746","5.89744","0.04667"
"229.2000","4.5824","5.89585","0.04676"
"229.6000","4.5905","5.89714","0.04685"
"230.0000","4.5984","5.89682","0.04694"
"230.4000","4.6065","5.89824","0.04703"
"230.8000","4.6144","5.89856","0.04711"
"231.2000","4.6225","5.89910","0.04721"
"231.6000","4.6306","5.90098","0.04730"
"232.0000","4.6384","5.89962","0.04738"
"232.4000","4.6465","5.90060","0.04747"
"232.8000","4.6544","5.90056","0.04756"
"233.2000","4.6625","5.90199","0.04765"
"233.6000","4.6704","5.90172","0.04774"
"234.0000","4.6786","5.90269","0.04783"
"234.4000","4.6866","5.90424","0.04792"
"234.8000","4.6944","5.90296","0.04801"
"235.2000","4.7026","5.90485","0.04810"
"235.6000","4.7104","5.90416","0.04819"
"236.0000","4.7186","5.90535","0.04828"
"236.4000","4.7264","5.90518","0.04837"
"236.8000","4.7345","5.90562","0.04846"
"237.2000","4.7426","5.90806","0.04855"
"237.6000","4.7505","5.90698","0.04863"
"238.0000","4.7586","5.90785","0.04873"
"238.4000","4.7664","5.90711","0.04881"
"238.8000","4.7745","5.90846","0.04890"
"239.2000","4.7824","5.90840","0.04899"
"239.6000","4.7906","5.90959","0.04908"
"240.0000","4.7986","5.91076","0.04917"
"240.4000","4.8065","5.91023","0.04926"
"240.8000","4.8146","5.91118","0.04935"
"241.2000","4.8223","5.91003","0.04944"
"241.6000","4.8305","5.91260","0.04953"
"242.0000","4.8384","5.91188","0.04962"
"242.4000","4.8465","5.91245","0.04971"
"242.8000","4.8546","5.91416","0.04980"
"243.2000","4.8624","5.91353","0.04988"
"243.6000","4.8706","5.91494","0.04998"
"244.0000","4.8784","5.91391","0.05006"
"244.4000","4.8865","5.91523","0.05015"
"244.8000","4.8944","5.91470","0.05024"
"245.2000","4.9025","5.91562","0.05033"
"245.6000","4.9105","5.91734","0.05042"
"246.0000","4.9186","5.91757","0.05051"
"246.4000","4.9266","5.91780","0.05061"
"246.8000","4.9344","5.91653","0.05069"
"247.2000","4.9425","5.91882","0.05078"
"247.6000","4.9503","5.91780","0.05087"
"248.0000","4.9585","5.91902","0.05096"
"248.4000","4.9666","5.92060","0.05105"
"248.8000","4.9746","5.92019","0.05114"
"249.2000","4.9826","5.92057","0.05123"
"249.6000","4.9903","5.91967","0.05132"
"250.0000","4.9986","5.92217","0.05141"
"250.4000","5.0064","5.92115","0.05150"
"250.8000","5.0145","5.92177","0.05159"
"251.2000","5.0225","5.92303","0.05168"
"251.6000","5.0305","5.92350","0.05177"
"252.0000","5.0386","5.92426","0.05186"
"252.4000","5.0464","5.92284","0.05195"
"252.8000","5.0546","5.92511","0.05204"
"253.2000","5.0623","5.92350","0.05213"
"253.6000","5.0705","5.92444","0.05222"
"254.0000","5.0784","5.92599","0.05231"
"254.4000","5.0865","5.92643","0.05240"
"254.8000","5.0946","5.92678","0.05249"
"255.2000","5.1025","5.92570","0.05258"
"255.6000","5.1106","5.92759","0.05267"
"256.0000","5.1183","5.92633","0.05276"
"256.4000","5.1265","5.92798","0.05285"
"256.8000","5.1345","5.92857","0.05294"
"257.2000","5.1425","5.92874","0.05303"
"257.6000","5.1505","5.92944","0.05312"
"258.0000","5.1584","5.92861","0.05321"
"258.4000","5.1666","5.93133","0.05330"
"258.8000","5.1744","5.92916","0.05339"
"259.2000","5.1825","5.93025","0.05348"
"259.6000","5.1904","5.93120","0.05357"
"260.0000","5.1984","5.93108","0.05366"
"260.4000","5.2065","5.93256","0.05375"
"260.8000","5.2145","5.93227","0.05384"
"261.2000","5.2226","5.93356","0.05393"
"261.6000","5.2304","5.93156","0.05402"
"262.0000","5.2385","5.93298","0.05411"
"262.4000","5.2464","5.93354","0.05420"
"262.8000","5.2545","5.93425","0.05429"
"263.2000","5.2625","5.93482","0.05439"
"263.6000","5.2705","5.93482","0.05447"
"264.0000","5.2785","5.93619","0.05457"
"264.4000","5.2863","5.93404","0.05465"
"264.8000","5.2946","5.93644","0.05475"
"265.2000","5.3025","5.93656","0.05484"
"265.6000","5.3105","5.93615","0.05493"
"266.0000","5.3186","5.93737","0.05502"
"266.4000","5.3265","5.93734","0.05511"
"266.8000","5.3345","5.93860","0.05520"
"267.2000","5.3424","5.93701","0.05529"
"267.6000","5.3506","5.93852","0.05538"
"268.0000","5.3584","5.93822","0.05547"
"268.4000","5.3664","5.93842","0.05556"
"268.8000","5.3745","5.93996","0.05565"
"269.2000","5.3826","5.94045","0.05574"
"269.6000","5.3906","5.94084","0.05583"
"270.0000","5.3984","5.93903","0.05592"
"270.4000","5.4066","5.94130","0.05602"
"270.8000","5.4143","5.94057","0.05611"
"271.2000","5.4224","5.94078","0.05620"
"271.6000","5.4306","5.94247","0.05629"
"272.0000","5.4386","5.94294","0.05638"
"272.4000","5.4464","5.94250","0.05647"
"272.8000","5.4543","5.94149","0.05656"
"273.2000","5.4627","5.94421","0.05665"
"273.6000","5.4704","5.94281","0.05674"
"274.0000","5.4784","5.94291","0.05683"
"274.4000","5.4865","5.94418","0.05693"
"274.8000","5.4946","5.94484","0.05702"
"275.2000","5.5024","5.94525","0.05711"
"275.6000","5.5104","5.94405","0.05720"
"276.0000","5.5187","5.94661","0.05729"
"276.4000","5.5263","5.94478","0.05738"
"276.8000","5.5343","5.94473","0.05747"
"277.2000","5.5425","5.94691","0.05756"
"277.6000","5.5507","5.94782","0.05766"
"278.0000","5.5585","5.94680","0.05774"
"278.4000","5.5664","5.94641","0.05784"
"278.8000","5.5747","5.94869","0.05793"
"279.2000","5.5822","5.94630","0.05802"
"279.6000","5.5904","5.94762","0.05811"
"280.0000","5.5986","5.94892","0.05820"
"280.4000","5.6066","5.94956","0.05829"
"280.8000","5.6144","5.94893","0.05838"
"281.2000","5.6224","5.94840","0.05848"
"281.6000","5.6307","5.95163","0.05857"
"282.0000","5.6383","5.94875","0.05866"
"282.4000","5.6464","5.94911","0.05875"
"282.8000","5.6546","5.95107","0.05884"
"283.2000","5.6625","5.95090","0.05893"
"283.6000","5.6704","5.95068","0.05902"
"284.0000","5.6785","5.95107","0.05912"
"284.4000","5.6867","5.95330","0.05921"
"284.8000","5.6943","5.95018","0.05930"
"285.2000","5.7024","5.95126","0.05939"
"285.6000","5.7105","5.95281","0.05948"
"286.0000","5.7187","5.95395","0.05958"
"286.4000","5.7265","5.95258","0.05967"
"286.8000","5.7345","5.95271","0.05976"
"287.2000","5.7428","5.95541","0.05985"
"287.6000","5.7502","5.95176","0.05994"
"288.0000","5.7584","5.95343","0.06003"
"288.4000","5.7666","5.95494","0.06013"
"288.8000","5.7745","5.95462","0.06022"
"289.2000","5.7824","5.95401","0.06031"
"289.6000","5.7905","5.95517","0.06040"
"290.0000","5.7987","5.95724","0.06050"
"290.4000","5.8063","5.95398","0.06059"
"290.8000","5.8145","5.95512","0.06068"
"291.2000","5.8225","5.95629","0.06077"
"291.6000","5.8305","5.95608","0.06086"
"292.0000","5.8383","5.95606","0.06095"
"292.4000","5.8466","5.95734","0.06105"
"292.8000","5.8547","5.95883","0.06114"
"293.2000","5.8623","5.95517","0.06123"
"293.6000","5.8705","5.95708","0.06133"
"294.0000","5.8785","5.95823","0.06142"
"294.4000","5.8865","5.95800","0.06151"
"294.8000","5.8944","5.95753","0.06160"
"295.2000","5.9026","5.95925","0.06170"
"295.6000","5.9107","5.95998","0.06179"
"296.0000","5.9183","5.95680","0.06188"
"296.4000","5.9265","5.95935","0.06197"
"296.8000","5.9345","5.95960","0.06207"
"297.2000","5.9425","5.95952","0.06216"
"297.6000","5.9504","5.95880","0.06225"
"298.0000","5.9586","5.96031","0.06234"
"298.4000","5.9667","5.96207","0.06244"
"298.8000","5.9743","5.95853","0.06253"
"299.2000","5.9826","5.96074","0.06262"
"299.6000","5.9905","5.96088","0.06272"
"300.0000","5.9984","5.95999","0.06281"
"300.4000","6.0064","5.96093","0.06290"
"300.8000","6.0146","5.96256","0.06299"
"301.2000","6.0226","5.96246","0.06309"
"301.6000","6.0304","5.96064","0.06318"
"302.0000","6.0386","5.96234","0.06327"
"302.4000","6.0464","5.96176","0.06336"
"302.8000","6.0545","5.96247","0.06346"
"303.2000","6.0624","5.96181","0.06355"
"303.6000","6.0707","5.96376","0.06365"
"304.0000","6.0786","5.96387","0.06374"
"304.4000","6.0863","5.96133","0.06383"
"304.8000","6.0946","5.96445","0.06392"
"305.2000","6.1025","5.96336","0.06402"
"305.6000","6.1105","5.96279","0.06411"
"306.0000","6.1184","5.96325","0.06420"
"306.4000","6.1265","5.96447","0.06430"
"306.8000","6.1346","5.96527","0.06439"
"307.2000","6.1424","5.96368","0.06448"
"307.6000","6.1506","5.96540","0.06458"
"308.0000","6.1585","5.96436","0.06467"
"308.4000","6.1664","5.96410","0.06477"
"308.8000","6.1743","5.96405","0.06486"
"309.2000","6.1827","5.96668","0.06496"
"309.6000","6.1905","5.96584","0.06505"
"310.0000","6.1984","5.96455","0.06514"
"310.4000","6.2067","5.96720","0.06524"
"310.8000","6.2143","5.96492","0.06533"
"311.2000","6.2225","5.96578","0.06543"
"311.6000","6.2305","5.96618","0.06552"
"312.0000","6.2386","5.96663","0.06561"
"312.4000","6.2465","5.96697","0.06570"
"312.8000","6.2544","5.96588","0.06580"
"313.2000","6.2626","5.96785","0.06589"
"313.6000","6.2705","5.96688","0.06599"
"314.0000","6.2785","5.96681","0.06608"
"314.4000","6.2864","5.96647","0.06617"
"314.8000","6.2946","5.96812","0.06627"
"315.2000","6.3024","5.96771","0.06636"
"315.6000","6.3105","5.96778","0.06646"
"316.0000","6.3187","5.96959","0.06655"
"316.4000","6.3264","5.96718","0.06665"
"316.8000","6.3345","5.96802","0.06674"
"317.2000","6.3423","5.96769","0.06683"
"317.6000","6.3506","5.96906","0.06693"
"318.0000","6.3585","5.96880","0.06702"
"318.4000","6.3665","5.96854","0.06712"
"318.8000","6.3746","5.97002","0.06721"
"319.2000","6.3824","5.96830","0.06730"
"319.6000","6.3905","5.96922","0.06740"
"320.0000","6.3985","5.96877","0.06749"
"320.4000","6.4066","5.96978","0.06759"
"320.8000","6.4144","5.96889","0.06768"
"321.2000","6.4225","5.96931","0.06778"
"321.6000","6.4306","5.97144","0.06787"
"322.0000","6.4384","5.96943","0.06797"
"322.4000","6.4465","5.97013","0.06806"
"322.8000","6.4544","5.96940","0.06816"
"323.2000","6.4625","5.97025","0.06825"
"323.6000","6.4704","5.97019","0.06835"
"324.0000","6.4786","5.97079","0.06844"
"324.4000","6.4866","5.97179","0.06854"
"324.8000","6.4945","5.97023","0.06863"
"325.2000","6.5025","5.97092","0.06873"
"325.6000","6.5103","5.96970","0.06882"
"326.0000","6.5186","5.97169","0.06892"
"326.4000","6.5264","5.97077","0.06901"
"326.8000","6.5345","5.97086","0.06911"
"327.2000","6.5426","5.97232","0.06920"
"327.6000","6.5504","5.97078","0.06930"
"328.0000","6.5586","5.97196","0.06939"
"328.4000","6.5664","5.97106","0.06949"
"328.8000","6.5745","5.97166","0.06958"
"329.2000","6.5824","5.97119","0.06968"
"329.6000","6.5905","5.97159","0.06977"
"330.0000","6.5986","5.97301","0.06987"
"330.4000","6.6065","5.97232","0.06996"
"330.8000","6.6146","5.97265","0.07006"
"331.2000","6.6224","5.97117","0.07015"
"331.6000","6.6305","5.97285","0.07025"
"332.0000","6.6383","5.97163","0.07035"
"332.4000","6.6465","5.97250","0.07044"
"332.8000","6.6546","5.97382","0.07054"
"333.2000","6.6625","5.97245","0.07064"
"333.6000","6.6705","5.97307","0.07073"
"334.0000","6.6783","5.97163","0.07082"
"334.4000","6.6865","5.97343","0.07092"
"334.8000","6.6944","5.97232","0.07102"
"335.2000","6.7025","5.97267","0.07111"
"335.6000","6.7105","5.97371","0.07121"
"336.0000","6.7185","5.97340","0.07131"
"336.4000","6.7266","5.97412","0.07140"
"336.8000","6.7344","5.97222","0.07150"
"337.2000","6.7426","5.97404","0.07160"
"337.6000","6.7504","5.97240","0.07169"
"338.0000","6.7584","5.97260","0.07179"
"338.4000","6.7665","5.97435","0.07188"
"338.8000","6.7745","5.97421","0.07198"
"339.2000","6.7826","5.97405","0.07208"
"339.6000","6.7904","5.97260","0.07217"
"340.0000","6.7986","5.97417","0.07227"
"340.4000","6.8063","5.97303","0.07237"
"340.8000","6.8145","5.97381","0.07247"
"341.2000","6.8226","5.97448","0.07256"
"341.6000","6.8306","5.97435","0.07266"
"342.0000","6.8386","5.97427","0.07275"
"342.4000","6.8463","5.97265","0.07285"
"342.8000","6.8546","5.97507","0.07295"
"343.2000","6.8624","5.97311","0.07304"
"343.6000","6.8705","5.97340","0.07314"
"344.0000","6.8784","5.97442","0.07324"
"344.4000","6.8864","5.97431","0.07333"
"344.8000","6.8945","5.97504","0.07343"
"345.2000","6.9025","5.97392","0.07353"
"345.6000","6.9106","5.97512","0.07363"
"346.0000","6.9184","5.97312","0.07372"
"346.4000","6.9265","5.97386","0.07382"
"346.8000","6.9344","5.97438","0.07392"
"347.2000","6.9426","5.97493","0.07402"
"347.6000","6.9506","5.97486","0.07412"
"348.0000","6.9584","5.97365","0.07421"
"348.4000","6.9666","5.97537","0.07431"
"348.8000","6.9743","5.97305","0.07441"
"349.2000","6.9826","5.97455","0.07451"
"349.6000","6.9905","5.97480","0.07460"
"350.0000","6.9985","5.97432","0.07470"
"350.4000","7.0065","5.97484","0.07480"
"350.8000","7.0144","5.97428","0.07490"
"351.2000","7.0226","5.97577","0.07499"
"351.6000","7.0304","5.97363","0.07509"
"352.0000","7.0386","5.97450","0.07519"
"352.4000","7.0464","5.97435","0.07529"
"352.8000","7.0545","5.97445","0.07539"
"353.2000","7.0625","5.97531","0.07549"
"353.6000","7.0705","5.97452","0.07559"
"354.0000","7.0786","5.97569","0.07568"
"354.4000","7.0863","5.97298","0.07578"
"354.8000","7.0946","5.97450","0.07588"
"355.2000","7.1024","5.97438","0.07598"
"355.6000","7.1105","5.97426","0.07608"
"356.0000","7.1186","5.97527","0.07618"
"356.4000","7.1266","5.97480","0.07628"
"356.8000","7.1345","5.97499","0.07637"
"357.2000","7.1423","5.97327","0.07647"
"357.6000","7.1506","5.97524","0.07657"
"358.0000","7.1585","5.97446","0.07667"
"358.4000","7.1665","5.97383","0.07677"
"358.8000","7.1745","5.97444","0.07687"
"359.2000","7.1825","5.97479","0.07697"
"359.6000","7.1905","5.97535","0.07707"
"360.0000","7.1983","5.97297","0.07717"
"360.4000","7.2066","5.97501","0.07727"
"360.8000","7.2144","5.97393","0.07736"
"361.2000","7.2224","5.97345","0.07746"
"361.6000","7.2305","5.97495","0.07756"
"362.0000","7.2386","5.97516","0.07767"
"362.4000","7.2465","5.97459","0.07776"
"362.8000","7.2544","5.97295","0.07786"
"363.2000","7.2626","5.97481","0.07796"
"363.6000","7.2703","5.97319","0.07806"
"364.0000","7.2784","5.97371","0.07816"
"364.4000","7.2866","5.97446","0.07826"
"364.8000","7.2946","5.97481","0.07836"
"365.2000","7.3025","5.97406","0.07846"
"365.6000","7.3103","5.97265","0.07856"
"366.0000","7.3187","5.97556","0.07867"
"366.4000","7.3264","5.97317","0.07876"
"366.8000","7.3344","5.97273","0.07886"
"367.2000","7.3426","5.97433","0.07896"
"367.6000","7.3506","5.97431","0.07906"
"368.0000","7.3584","5.97365","0.07916"
"368.4000","7.3664","5.97289","0.07926"
"368.8000","7.3747","5.97492","0.07937"
"369.2000","7.3823","5.97223","0.07947"
"369.6000","7.3904","5.97243","0.07957"
"370.0000","7.3985","5.97390","0.07967"
"370.4000","7.4067","5.97454","0.07977"
"370.8000","7.4145","5.97333","0.07987"
"371.2000","7.4225","5.97225","0.07997"
"371.6000","7.4307","5.97471","0.08007"
"372.0000","7.4382","5.97161","0.08017"
"372.4000","7.4464","5.97231","0.08027"
"372.8000","7.4546","5.97383","0.08038"
"373.2000","7.4626","5.97356","0.08048"
"373.6000","7.4704","5.97242","0.08058"
"374.0000","7.4784","5.97245","0.08068"
"374.4000","7.4867","5.97465","0.08078"
"374.8000","7.4943","5.97141","0.08088"
"375.2000","7.5025","5.97189","0.08098"
"375.6000","7.5105","5.97266","0.08109"
"376.0000","7.5185","5.97276","0.08119"
"376.4000","7.5264","5.97220","0.08129"
"376.8000","7.5345","5.97225","0.08139"
"377.2000","7.5428","5.97438","0.08151"
"377.6000","7.5502","5.97006","0.08161"
"378.0000","7.5584","5.97118","0.08171"
"378.4000","7.5665","5.97270","0.08181"
"378.8000","7.5746","5.97238","0.08191"
"379.2000","7.5824","5.97149","0.08202"
"379.6000","7.5906","5.97198","0.08212"
"380.0000","7.5987","5.97330","0.08222"
"380.4000","7.6062","5.96969","0.08232"
"380.8000","7.6145","5.97141","0.08243"
"381.2000","7.6226","5.97199","0.08253"
"381.6000","7.6305","5.97157","0.08263"
"382.0000","7.6384","5.97059","0.08274"
"382.4000","7.6465","5.97145","0.08284"
"382.8000","7.6547","5.97343","0.08294"
"383.2000","7.6623","5.96915","0.08304"
"383.6000","7.6705","5.97037","0.08315"
"384.0000","7.6786","5.97123","0.08325"
"384.4000","7.6864","5.97018","0.08335"
"384.8000","7.6943","5.96992","0.08345"
"385.2000","7.7026","5.97155","0.08356"
"385.6000","7.7107","5.97201","0.08366"
"386.0000","7.7183","5.96841","0.08376"
"386.4000","7.7265","5.97017","0.08387"
"386.8000","7.7344","5.97008","0.08397"
"387.2000","7.7425","5.97023","0.08408"
"387.6000","7.7504","5.96928","0.08418"
"388.0000","7.7586","5.97028","0.08429"
"388.4000","7.7667","5.97096","0.08439"
"388.8000","7.7743","5.96765","0.08449"
"389.2000","7.7826","5.96995","0.08460"
"389.6000","7.7905","5.96964","0.08470"
"390.0000","7.7985","5.96865","0.08481"
"390.4000","7.8064","5.96835","0.08491"
"390.8000","7.8146","5.96980","0.08502"
"391.2000","7.8226","5.97012","0.08512"
"391.6000","7.8304","5.96752","0.08522"
"392.0000","7.8386","5.96935","0.08533"
"392.4000","7.8464","5.96796","0.08544"
"392.8000","7.8544","5.96767","0.08554"
"393.2000","7.8623","5.96745","0.08564"
"393.6000","7.8706","5.96901","0.08575"
"394.0000","7.8786","5.96904","0.08586"
"394.4000","7.8864","5.96634","0.08596"
"394.8000","7.8946","5.96843","0.08607"
"395.2000","7.9024","5.96719","0.08617"
"395.6000","7.9105","5.96712","0.08628"
"396.0000","7.9185","5.96710","0.08638"
"396.4000","7.9266","5.96777","0.08649"
"396.8000","7.9345","5.96722","0.08659"
"397.2000","7.9424","5.96579","0.08670"
"397.6000","7.9506","5.96806","0.08681"
"398.0000","7.9584","5.96602","0.08691"
"398.4000","7.9665","5.96596","0.08702"
"398.8000","7.9744","5.96539","0.08713"
"399.2000","7.9825","5.96642","0.08723"
"399.6000","7.9905","5.96676","0.08734"
"400.0000","7.9985","5.96502","0.08744"
"400.4000","8.0067","5.96693","0.08755"
"400.8000","8.0144","5.96466","0.08766"
"401.2000","8.0224","5.96454","0.08777"
"401.6000","8.0304","5.96483","0.08787"
"402.0000","8.0386","5.96597","0.08798"
"402.4000","8.0465","5.96485","0.08809"
"402.8000","8.0545","5.96430","0.08820"
"403.2000","8.0626","5.96555","0.08830"
"403.6000","8.0703","5.96350","0.08841"
"404.0000","8.0785","5.96436","0.08852"
"404.4000","8.0865","5.96358","0.08863"
"404.8000","8.0946","5.96430","0.08874"
"405.2000","8.1025","5.96347","0.08884"
"405.6000","8.1104","5.96300","0.08895"
"406.0000","8.1186","5.96491","0.08906"
"406.4000","8.1264","5.96270","0.08917"
"406.8000","8.1345","5.96279","0.08927"
"407.2000","8.1424","5.96234","0.08938"
"407.6000","8.1505","5.96301","0.08949"
"408.0000","8.1584","5.96225","0.08960"
"408.4000","8.1666","5.96253","0.08971"
"408.8000","8.1747","5.96330","0.08982"
"409.2000","8.1824","5.96086","0.08992"
"409.6000","8.1905","5.96175","0.09004"
"410.0000","8.1984","5.96088","0.09014"
"410.4000","8.2065","5.96197","0.09025"
"410.8000","8.2144","5.96121","0.09036"
"411.2000","8.2225","5.96067","0.09048"
"411.6000","8.2307","5.96207","0.09058"
"412.0000","8.2383","5.95951","0.09069"
"412.4000","8.2465","5.96060","0.09080"
"412.8000","8.2545","5.96005","0.09091"
"413.2000","8.2625","5.96009","0.09102"
"413.6000","8.2704","5.95915","0.09114"
"414.0000","8.2785","5.95936","0.09125"
"414.4000","8.2866","5.96045","0.09135"
"414.8000","8.2945","5.95908","0.09147"
"415.2000","8.3026","5.95921","0.09158"
"415.6000","8.3103","5.95733","0.09169"
"416.0000","8.3185","5.95909","0.09180"
"416.4000","8.3263","5.95783","0.09191"
"416.8000","8.3346","5.95840","0.09202"
"417.2000","8.3427","5.95950","0.09213"
"417.6000","8.3505","5.95705","0.09225"
"418.0000","8.3586","5.95766","0.09236"
"418.4000","8.3663","5.95615","0.09247"
"418.8000","8.3745","5.95726","0.09258"
"419.2000","8.3825","5.95677","0.09269"
"419.6000","8.3905","5.95636","0.09280"
"420.0000","8.3985","5.95704","0.09292"
"420.4000","8.4065","5.95616","0.09303"
"420.8000","8.4146","5.95658","0.09314"
"421.2000","8.4225","5.95467","0.09325"
"421.6000","8.4306","5.95582","0.09337"
"422.0000","8.4383","5.95407","0.09347"
"422.4000","8.4465","5.95477","0.09359"
"422.8000","8.4545","5.95586","0.09370"
"423.2000","8.4625","5.95436","0.09382"
"423.6000","8.4706","5.95495","0.09393"
"424.0000","8.4784","5.95267","0.09404"
"424.4000","8.4865","5.95374","0.09415"
"424.8000","8.4944","5.95314","0.09427"
"425.2000","8.5025","5.95305","0.09438"
"425.6000","8.5106","5.95360","0.09450"
"426.0000","8.5185","5.95299","0.09461"
"426.4000","8.5265","5.95239","0.09472"
"426.8000","8.5344","5.95096","0.09483"
"427.2000","8.5425","5.95256","0.09495"
"427.6000","8.5504","5.95070","0.09506"
"428.0000","8.5586","5.95112","0.09518"
"428.4000","8.5665","5.95127","0.09529"
"428.8000","8.5744","5.95045","0.09541"
"429.2000","8.5826","5.95148","0.09552"
"429.6000","8.5904","5.94925","0.09563"
"430.0000","8.5986","5.95044","0.09575"
"430.4000","8.6064","5.94870","0.09586"
"430.8000","8.6145","5.94854","0.09598"
"431.2000","8.6225","5.94953","0.09609"
"431.6000","8.6305","5.94924","0.09621"
"432.0000","8.6386","5.94872","0.09633"
"432.4000","8.6464","5.94705","0.09644"
"432.8000","8.6546","5.94836","0.09656"
"433.2000","8.6623","5.94612","0.09667"
"433.6000","8.6705","5.94666","0.09679"
"434.0000","8.6785","5.94708","0.09691"
"434.4000","8.6865","5.94628","0.09703"
"434.8000","8.6945","5.94607","0.09714"
"435.2000","8.7024","5.94456","0.09726"
"435.6000","8.7106","5.94623","0.09737"
"436.0000","8.7184","5.94413","0.09749"
"436.4000","8.7265","5.94381","0.09761"
"436.8000","8.7345","5.94387","0.09773"
"437.2000","8.7425","5.94373","0.09784"
"437.6000","8.7505","5.94368","0.09796"
"438.0000","8.7585","5.94193","0.09808"
"438.4000","8.7666","5.94324","0.09820"
"438.8000","8.7744","5.94019","0.09831"
"439.2000","8.7825","5.94068","0.09843"
"439.6000","8.7904","5.94094","0.09855"
"440.0000","8.7985","5.94023","0.09867"
"440.4000","8.8066","5.94021","0.09879"
"440.8000","8.8145","5.93892","0.09890"
"441.2000","8.8226","5.93954","0.09902"
"441.6000","8.8303","5.93703","0.09914"
"442.0000","8.8386","5.93794","0.09926"
"442.4000","8.8465","5.93726","0.09938"
"442.8000","8.8545","5.93630","0.09950"
"443.2000","8.8625","5.93580","0.09962"
"443.6000","8.8705","5.93506","0.09974"
"444.0000","8.8785","5.93584","0.09985"
"444.4000","8.8863","5.93270","0.09997"
"444.8000","8.8946","5.93373","0.10010"
"445.2000","8.9024","5.93256","0.10022"
"445.6000","8.9104","5.93114","0.10033"
"446.0000","8.9185","5.93215","0.10046"
"446.4000","8.9266","5.93110","0.10058"
"446.8000","8.9346","5.93047","0.10070"
"447.2000","8.9423","5.92758","0.10082"
"447.6000","8.9506","5.92847","0.10094"
"448.0000","8.9583","5.92687","0.10106"
"448.4000","8.9665","5.92649","0.10118"
"448.8000","8.9746","5.92604","0.10130"
"449.2000","8.9826","5.92509","0.10143"
"449.6000","8.9905","5.92411","0.10154"
"450.0000","8.9983","5.92108","0.10166"
"450.4000","9.0066","5.92256","0.10179"
"450.8000","9.0144","5.92031","0.10191"
"451.2000","9.0224","5.91861","0.10203"
"451.6000","9.0306","5.91882","0.10216"
"452.0000","9.0386","5.91746","0.10228"
"452.4000","9.0465","5.91627","0.10240"
"452.8000","9.0544","5.91333","0.10253"
"453.2000","9.0626","5.91366","0.10265"
"453.6000","9.0703","5.91088","0.10277"
"454.0000","9.0784","5.90930","0.10289"
"454.4000","9.0865","5.90913","0.10302"
"454.8000","9.0947","5.90801","0.10315"
"455.2000","9.1025","5.90571","0.10327"
"455.6000","9.1104","5.90211","0.10340"
"456.0000","9.1187","5.90271","0.10352"
"456.4000","9.1263","5.89895","0.10364"
"456.8000","9.1344","5.89724","0.10377"
"457.2000","9.1426","5.89656","0.10390"
"457.6000","9.1506","5.89456","0.10403"
"458.0000","9.1584","5.89121","0.10415"
"458.4000","9.1664","5.88831","0.10428"
"458.8000","9.1747","5.88831","0.10441"
"459.2000","9.1824","5.88324","0.10454"
"459.6000","9.1904","5.88066","0.10467"
"460.0000","9.1985","5.87891","0.10480"
"460.4000","9.2065","5.87656","0.10493"
"460.8000","9.2144","5.87350","0.10505"
"461.2000","9.2225","5.86936","0.10519"
"461.6000","9.2308","5.86837","0.10532"
"462.0000","9.2383","5.86197","0.10545"
"462.4000","9.2463","5.85865","0.10558"
"462.8000","9.2545","5.85709","0.10571"
"463.2000","9.2626","5.85316","0.10585"
"463.6000","9.2704","5.84797","0.10598"
"464.0000","9.2785","5.84376","0.10612"
"464.4000","9.2867","5.84133","0.10625"
"464.8000","9.2942","5.83351","0.10639"
"465.2000","9.3024","5.83026","0.10653"
"465.6000","9.3106","5.82626","0.10667"
"466.0000","9.3186","5.82095","0.10681"
"466.4000","9.3264","5.81473","0.10694"
"466.8000","9.3345","5.80913","0.10708"
"467.2000","9.3428","5.80614","0.10723"
"467.6000","9.3503","5.79601","0.10737"
"468.0000","9.3585","5.79013","0.10753"
"468.4000","9.3666","5.78543","0.10768"
"468.8000","9.3745","5.77774","0.10783"
"469.2000","9.3824","5.77059","0.10798"
"469.6000","9.3906","5.76365","0.10814"
"470.0000","9.3987","5.75743","0.10829"
"470.4000","9.4063","5.74592","0.10845"
"470.8000","9.4144","5.73897","0.10861"
"471.2000","9.4225","5.73137","0.10877"
"471.6000","9.4306","5.72245","0.10893"
"472.0000","9.4384","5.71229","0.10910"
"472.4000","9.4466","5.70305","0.10926"
"472.8000","9.4547","5.69550","0.10942"
"473.2000","9.4622","5.68132","0.10959"
"473.6000","9.4705","5.67241","0.10976"
"474.0000","9.4786","5.66256","0.10992"
"474.4000","9.4865","5.65038","0.11009"
"474.8000","9.4944","5.63912","0.11025"
"475.2000","9.5026","5.62829","0.11043"
"475.6000","9.5107","5.61772","0.11060"
"476.0000","9.5183","5.60136","0.11077"
"476.4000","9.5266","5.59014","0.11094"
"476.8000","9.5345","5.57771","0.11111"
"477.2000","9.5425","5.56351","0.11129"
"477.6000","9.5503","5.55024","0.11146"
"478.0000","9.5586","5.53653","0.11164"
"478.4000","9.5667","5.52358","0.11182"
"478.8000","9.5743","5.50505","0.11200"
"479.2000","9.5825","5.49150","0.11218"
"479.6000","9.5904","5.47666","0.11235"
"480.0000","9.5985","5.45952","0.11254"
"480.4000","9.6064","5.44309","0.11272"
"480.8000","9.6147","5.42757","0.11290"
"481.2000","9.6226","5.41132","0.11308"
"481.6000","9.6303","5.39105","0.11326"
"482.0000","9.6386","5.37499","0.11345"
"482.4000","9.6465","5.35633","0.11364"
"482.8000","9.6545","5.33678","0.11382"
"483.2000","9.6624","5.31802","0.11401"
"483.6000","9.6706","5.29903","0.11420"
"484.0000","9.6786","5.28046","0.11438"
"484.4000","9.6864","5.25602","0.11457"
"484.8000","9.6946","5.23637","0.11477"
"485.2000","9.7025","5.21494","0.11496"
"485.6000","9.7104","5.19165","0.11515"
"486.0000","9.7184","5.16953","0.11534"
"486.4000","9.7267","5.14661","0.11554"
"486.8000","9.7346","5.12313","0.11573"
"487.2000","9.7424","5.09613","0.11593"
"487.6000","9.7506","5.07120","0.11613"
"488.0000","9.7584","5.04282","0.11633"
"488.4000","9.7665","5.01354","0.11653"
"488.8000","9.7745","4.98453","0.11673"
"489.2000","9.7826","4.95411","0.11694"
"489.6000","9.7905","4.92346","0.11714"
"490.0000","9.7984","4.88699","0.11736"
"490.4000","9.8067","4.85165","0.11758"
"490.8000","9.8145","4.81221","0.11780"
"491.2000","9.8225","4.77150","0.11802"
"491.6000","9.8304","4.73301","0.11824"
"492.0000","9.8385","4.69153","0.11847"
"492.4000","9.8465","4.64803","0.11870"
"492.8000","9.8545","4.59894","0.11893"
"493.2000","9.8627","4.54634","0.11918"
"493.6000","9.8704","4.48488","0.11943"
"494.0000","9.8785","4.41312","0.11971"
"494.4000","9.8864","4.33139","0.12000"
"494.8000","9.8946","4.23671","0.12032"
"495.1850","9.9022","4.04371","0.12078"
"495.2120","9.9028","3.65667","0.12106"
"495.2130","9.9029","3.57056","0.12110"