File: Coupon Test Data/Tensile Test_Neebajan_Alan_6.csv
Time,Displacement,Force,Strain 1
(s),(mm),(kN),(mm/mm)
"0.0000","-8.1072","0.17921","-0.00018"
"0.3000","-8.1028","0.22089","-0.00015"
"0.6000","-8.0970","0.28428","-0.00012"
"0.9000","-8.0908","0.34960","-0.00008"
"1.2000","-8.0849","0.41153","-0.00005"
"1.5000","-8.0785","0.47741","-0.00001"
"1.8000","-8.0728","0.53605","0.00003"
"2.1000","-8.0667","0.59802","0.00006"
"2.4000","-8.0609","0.65489","0.00010"
"2.7000","-8.0547","0.71541","0.00013"
"3.0000","-8.0488","0.77047","0.00016"
"3.3000","-8.0428","0.82876","0.00020"
"3.6000","-8.0367","0.88768","0.00023"
"3.9000","-8.0306","0.94463","0.00026"
"4.2000","-8.0248","0.99911","0.00030"
"4.5000","-8.0188","1.04999","0.00033"
"4.8000","-8.0129","1.10541","0.00036"
"5.1000","-8.0068","1.16170","0.00039"
"5.4000","-8.0008","1.21710","0.00042"
"5.7000","-7.9946","1.26856","0.00045"
"6.0000","-7.9886","1.32316","0.00048"
"6.3000","-7.9829","1.37541","0.00052"
"6.6000","-7.9767","1.43033","0.00055"
"6.9000","-7.9709","1.47793","0.00058"
"7.2000","-7.9646","1.53383","0.00061"
"7.5000","-7.9589","1.58368","0.00064"
"7.8000","-7.9525","1.63822","0.00067"
"8.1000","-7.9467","1.68601","0.00070"
"8.4000","-7.9406","1.73855","0.00073"
"8.7000","-7.9348","1.78828","0.00076"
"9.0000","-7.9288","1.83526","0.00079"
"9.3000","-7.9227","1.88753","0.00082"
"9.6000","-7.9168","1.93666","0.00085"
"9.9000","-7.9106","1.98539","0.00088"
"10.2000","-7.9047","2.03405","0.00090"
"10.5000","-7.8987","2.08210","0.00093"
"10.8000","-7.8928","2.12697","0.00096"
"11.1000","-7.8867","2.17740","0.00099"
"11.4000","-7.8807","2.22204","0.00102"
"11.7000","-7.8747","2.26987","0.00104"
"12.0000","-7.8687","2.31833","0.00107"
"12.3000","-7.8626","2.36318","0.00110"
"12.6000","-7.8568","2.40834","0.00113"
"12.9000","-7.8508","2.45203","0.00115"
"13.2000","-7.8449","2.49748","0.00118"
"13.5000","-7.8387","2.54352","0.00121"
"13.8000","-7.8328","2.58726","0.00123"
"14.1000","-7.8266","2.63362","0.00126"
"14.4000","-7.8206","2.67686","0.00129"
"14.7000","-7.8148","2.71934","0.00131"
"15.0000","-7.8088","2.76199","0.00134"
"15.3000","-7.8029","2.80474","0.00137"
"15.6000","-7.7966","2.84951","0.00139"
"15.9000","-7.7908","2.88910","0.00142"
"16.2000","-7.7846","2.93395","0.00144"
"16.5000","-7.7787","2.97476","0.00147"
"16.8000","-7.7727","3.01611","0.00149"
"17.1000","-7.7668","3.05610","0.00152"
"17.4000","-7.7608","3.09692","0.00155"
"17.7000","-7.7547","3.13946","0.00157"
"18.0000","-7.7487","3.17826","0.00160"
"18.3000","-7.7427","3.21980","0.00162"
"18.6000","-7.7367","3.25900","0.00164"
"18.9000","-7.7308","3.29774","0.00167"
"19.2000","-7.7248","3.33661","0.00169"
"19.5000","-7.7188","3.37616","0.00172"
"19.8000","-7.7126","3.41660","0.00174"
"20.1000","-7.7067","3.45423","0.00177"
"20.4000","-7.7007","3.49290","0.00179"
"20.7000","-7.6946","3.53177","0.00182"
"21.0000","-7.6888","3.56846","0.00184"
"21.3000","-7.6827","3.60569","0.00187"
"21.6000","-7.6769","3.64210","0.00189"
"21.9000","-7.6706","3.68172","0.00191"
"22.2000","-7.6647","3.71853","0.00194"
"22.5000","-7.6587","3.75499","0.00196"
"22.8000","-7.6526","3.79227","0.00199"
"23.1000","-7.6468","3.82647","0.00201"
"23.4000","-7.6407","3.86372","0.00203"
"23.7000","-7.6349","3.89759","0.00206"
"24.0000","-7.6285","3.93728","0.00208"
"24.3000","-7.6228","3.96962","0.00210"
"24.6000","-7.6166","4.00672","0.00213"
"24.9000","-7.6107","4.03993","0.00215"
"25.2000","-7.6047","4.07532","0.00217"
"25.5000","-7.5988","4.10827","0.00219"
"25.8000","-7.5929","4.14133","0.00221"
"26.1000","-7.5867","4.17697","0.00224"
"26.4000","-7.5807","4.20973","0.00226"
"26.7000","-7.5747","4.24294","0.00228"
"27.0000","-7.5687","4.27470","0.00230"
"27.3000","-7.5628","4.30702","0.00233"
"27.6000","-7.5568","4.33859","0.00235"
"27.9000","-7.5509","4.37087","0.00237"
"28.2000","-7.5446","4.40466","0.00239"
"28.5000","-7.5386","4.43709","0.00241"
"28.8000","-7.5328","4.46787","0.00244"
"29.1000","-7.5266","4.50059","0.00246"
"29.4000","-7.5208","4.53108","0.00248"
"29.7000","-7.5146","4.56324","0.00250"
"30.0000","-7.5090","4.59211","0.00252"
"30.3000","-7.5026","4.62580","0.00255"
"30.6000","-7.4967","4.65553","0.00256"
"30.9000","-7.4906","4.68513","0.00259"
"31.2000","-7.4847","4.71431","0.00261"
"31.5000","-7.4788","4.74325","0.00263"
"31.8000","-7.4727","4.77342","0.00265"
"32.1000","-7.4669","4.80057","0.00267"
"32.4000","-7.4605","4.83269","0.00269"
"32.7000","-7.4546","4.85906","0.00271"
"33.0000","-7.4486","4.88740","0.00274"
"33.3000","-7.4428","4.91376","0.00276"
"33.6000","-7.4367","4.94280","0.00278"
"33.9000","-7.4307","4.96958","0.00280"
"34.2000","-7.4249","4.99611","0.00283"
"34.5000","-7.4188","5.02492","0.00285"
"34.8000","-7.4126","5.05260","0.00287"
"35.1000","-7.4068","5.07874","0.00289"
"35.4000","-7.4007","5.10414","0.00292"
"35.7000","-7.3949","5.13076","0.00294"
"36.0000","-7.3887","5.15644","0.00297"
"36.3000","-7.3829","5.18177","0.00299"
"36.6000","-7.3766","5.20780","0.00302"
"36.9000","-7.3705","5.23334","0.00305"
"37.2000","-7.3647","5.25578","0.00308"
"37.5000","-7.3587","5.27883","0.00310"
"37.8000","-7.3528","5.30122","0.00313"
"38.1000","-7.3466","5.32461","0.00316"
"38.4000","-7.3409","5.34304","0.00319"
"38.7000","-7.3346","5.36707","0.00323"
"39.0000","-7.3286","5.38484","0.00326"
"39.3000","-7.3227","5.40355","0.00329"
"39.6000","-7.3167","5.42168","0.00332"
"39.9000","-7.3108","5.43862","0.00336"
"40.2000","-7.3046","5.45678","0.00340"
"40.5000","-7.2988","5.46966","0.00343"
"40.8000","-7.2926","5.48688","0.00348"
"41.1000","-7.2867","5.49403","0.00351"
"41.4000","-7.2807","5.51073","0.00355"
"41.7000","-7.2748","5.52064","0.00359"
"42.0000","-7.2687","5.53373","0.00363"
"42.3000","-7.2627","5.54435","0.00368"
"42.6000","-7.2568","5.55378","0.00372"
"42.9000","-7.2508","5.56362","0.00377"
"43.2000","-7.2446","5.57326","0.00382"
"43.5000","-7.2388","5.58007","0.00386"
"43.8000","-7.2327","5.58769","0.00391"
"44.1000","-7.2269","5.59407","0.00396"
"44.4000","-7.2206","5.60353","0.00400"
"44.7000","-7.2148","5.60896","0.00405"
"45.0000","-7.2087","5.61601","0.00410"
"45.3000","-7.2025","5.62224","0.00415"
"45.6000","-7.1967","5.62644","0.00420"
"45.9000","-7.1906","5.63254","0.00425"
"46.2000","-7.1848","5.63556","0.00430"
"46.5000","-7.1785","5.64400","0.00435"
"46.8000","-7.1728","5.64530","0.00440"
"47.1000","-7.1666","5.65279","0.00445"
"47.4000","-7.1607","5.65508","0.00450"
"47.7000","-7.1546","5.66007","0.00455"
"48.0000","-7.1487","5.66219","0.00461"
"48.3000","-7.1428","5.66566","0.00466"
"48.6000","-7.1367","5.67128","0.00471"
"48.9000","-7.1307","5.67370","0.00476"
"49.2000","-7.1247","5.67791","0.00481"
"49.5000","-7.1186","5.68012","0.00486"
"49.8000","-7.1127","5.68360","0.00492"
"50.1000","-7.1067","5.68548","0.00497"
"50.4000","-7.1008","5.68834","0.00502"
"50.7000","-7.0946","5.69268","0.00507"
"51.0000","-7.0887","5.69496","0.00512"
"51.3000","-7.0828","5.69733","0.00517"
"51.6000","-7.0766","5.70060","0.00523"
"51.9000","-7.0708","5.70206","0.00528"
"52.2000","-7.0646","5.70479","0.00534"
"52.5000","-7.0590","5.70523","0.00538"
"52.8000","-7.0526","5.71092","0.00544"
"53.1000","-7.0467","5.71217","0.00549"
"53.4000","-7.0407","5.71487","0.00554"
"53.7000","-7.0347","5.71630","0.00560"
"54.0000","-7.0287","5.71809","0.00565"
"54.3000","-7.0226","5.72080","0.00570"
"54.6000","-7.0168","5.72075","0.00576"
"54.9000","-7.0105","5.72590","0.00581"
"55.2000","-7.0047","5.72568","0.00586"
"55.5000","-6.9988","5.72891","0.00592"
"55.8000","-6.9928","5.72919","0.00597"
"56.1000","-6.9867","5.73222","0.00603"
"56.4000","-6.9807","5.73321","0.00608"
"56.7000","-6.9748","5.73387","0.00614"
"57.0000","-6.9687","5.73758","0.00619"
"57.3000","-6.9626","5.73915","0.00625"
"57.6000","-6.9568","5.74065","0.00630"
"57.9000","-6.9507","5.74117","0.00636"
"58.2000","-6.9448","5.74343","0.00642"
"58.5000","-6.9386","5.74480","0.00647"
"58.8000","-6.9328","5.74616","0.00653"
"59.1000","-6.9266","5.74849","0.00659"
"59.4000","-6.9206","5.75062","0.00664"
"59.7000","-6.9148","5.75086","0.00670"
"60.0000","-6.9087","5.75332","0.00676"
"60.3000","-6.9028","5.75352","0.00682"
"60.6000","-6.8965","5.75682","0.00688"
"60.9000","-6.8908","5.75538","0.00693"
"61.2000","-6.8846","5.75985","0.00699"
"61.5000","-6.8787","5.76040","0.00705"
"61.8000","-6.8727","5.76181","0.00711"
"62.1000","-6.8667","5.76252","0.00717"
"62.4000","-6.8607","5.76325","0.00723"
"62.7000","-6.8546","5.76662","0.00729"
"63.0000","-6.8487","5.76556","0.00735"
"63.3000","-6.8426","5.76939","0.00741"
"63.6000","-6.8367","5.76873","0.00747"
"63.9000","-6.8308","5.77140","0.00753"
"64.2000","-6.8248","5.77083","0.00759"
"64.5000","-6.8187","5.77337","0.00765"
"64.8000","-6.8126","5.77448","0.00772"
"65.1000","-6.8067","5.77499","0.00778"
"65.4000","-6.8008","5.77646","0.00783"
"65.7000","-6.7947","5.77862","0.00790"
"66.0000","-6.7888","5.77896","0.00796"
"66.3000","-6.7827","5.78023","0.00802"
"66.6000","-6.7768","5.78056","0.00808"
"66.9000","-6.7705","5.78352","0.00815"
"67.2000","-6.7647","5.78282","0.00821"
"67.5000","-6.7587","5.78072","0.00826"
"67.8000","-6.7526","5.78588","0.00832"
"68.1000","-6.7469","5.78687","0.00838"
"68.4000","-6.7407","5.78953","0.00844"
"68.7000","-6.7348","5.78828","0.00851"
"69.0000","-6.7284","5.79288","0.00857"
"69.3000","-6.7228","5.79061","0.00863"
"69.6000","-6.7166","5.79418","0.00870"
"69.9000","-6.7108","5.79322","0.00876"
"70.2000","-6.7047","5.79571","0.00882"
"70.5000","-6.6987","5.79546","0.00889"
"70.8000","-6.6928","5.79621","0.00895"
"71.1000","-6.6866","5.79911","0.00902"
"71.4000","-6.6806","5.79912","0.00909"
"71.7000","-6.6747","5.80038","0.00915"
"72.0000","-6.6687","5.80056","0.00922"
"72.3000","-6.6629","5.80208","0.00928"
"72.6000","-6.6567","5.80305","0.00934"
"72.9000","-6.6508","5.80351","0.00941"
"73.2000","-6.6446","5.80581","0.00948"
"73.5000","-6.6386","5.80652","0.00954"
"73.8000","-6.6328","5.80681","0.00960"
"74.1000","-6.6267","5.80850","0.00967"
"74.4000","-6.6209","5.80883","0.00974"
"74.7000","-6.6145","5.81098","0.00980"
"75.0000","-6.6089","5.80936","0.00987"
"75.3000","-6.6025","5.81359","0.00994"
"75.6000","-6.5967","5.81348","0.01000"
"75.9000","-6.5906","5.81474","0.01007"
"76.2000","-6.5847","5.81496","0.01013"
"76.5000","-6.5788","5.81569","0.01020"
"76.8000","-6.5726","5.81801","0.01027"
"77.1000","-6.5668","5.81688","0.01033"
"77.4000","-6.5605","5.82113","0.01040"
"77.7000","-6.5546","5.81994","0.01047"
"78.0000","-6.5487","5.82171","0.01053"
"78.3000","-6.5428","5.82102","0.01060"
"78.6000","-6.5368","5.82322","0.01067"
"78.9000","-6.5307","5.82402","0.01074"
"79.2000","-6.5247","5.82358","0.01080"
"79.5000","-6.5187","5.82622","0.01087"
"79.8000","-6.5126","5.82706","0.01094"
"80.1000","-6.5068","5.82742","0.01100"
"80.4000","-6.5007","5.82760","0.01107"
"80.7000","-6.4949","5.82872","0.01114"
"81.0000","-6.4886","5.80474","0.01117"
"81.3000","-6.4828","5.82171","0.01123"
"81.6000","-6.4766","5.83144","0.01129"
"81.9000","-6.4706","5.83495","0.01136"
"82.2000","-6.4648","5.83454","0.01142"
"82.5000","-6.4587","5.83558","0.01149"
"82.8000","-6.4529","5.83516","0.01155"
"83.1000","-6.4465","5.83816","0.01162"
"83.4000","-6.4408","5.83635","0.01169"
"83.7000","-6.4345","5.83972","0.01176"
"84.0000","-6.4286","5.83968","0.01183"
"84.3000","-6.4227","5.84012","0.01189"
"84.6000","-6.4168","5.84027","0.01196"
"84.9000","-6.4108","5.84078","0.01203"
"85.2000","-6.4046","5.84398","0.01210"
"85.5000","-6.3987","5.84227","0.01217"
"85.8000","-6.3926","5.84570","0.01223"
"86.1000","-6.3867","5.84454","0.01230"
"86.4000","-6.3807","5.84630","0.01237"
"86.7000","-6.3748","5.84536","0.01243"
"87.0000","-6.3688","5.84765","0.01250"
"87.3000","-6.3626","5.84893","0.01257"
"87.6000","-6.3567","5.84913","0.01264"
"87.9000","-6.3507","5.84999","0.01271"
"88.2000","-6.3446","5.85197","0.01278"
"88.5000","-6.3388","5.85139","0.01285"
"88.8000","-6.3327","5.85225","0.01291"
"89.1000","-6.3270","5.85207","0.01298"
"89.4000","-6.3206","5.85577","0.01305"
"89.7000","-6.3147","5.85530","0.01312"
"90.0000","-6.3086","5.85656","0.01319"
"90.3000","-6.3026","5.85750","0.01326"
"90.6000","-6.2968","5.85718","0.01332"
"90.9000","-6.2907","5.85912","0.01339"
"91.2000","-6.2849","5.85810","0.01346"
"91.5000","-6.2784","5.86304","0.01353"
"91.8000","-6.2727","5.86030","0.01360"
"92.1000","-6.2665","5.86358","0.01367"
"92.4000","-6.2607","5.86254","0.01373"
"92.7000","-6.2546","5.86449","0.01380"
"93.0000","-6.2488","5.86379","0.01387"
"93.3000","-6.2429","5.86435","0.01393"
"93.6000","-6.2367","5.86745","0.01401"
"93.9000","-6.2306","5.86744","0.01407"
"94.2000","-6.2247","5.86837","0.01414"
"94.5000","-6.2187","5.86856","0.01421"
"94.8000","-6.2128","5.86914","0.01428"
"95.1000","-6.2067","5.86374","0.01433"
"95.4000","-6.2008","5.86878","0.01439"
"95.7000","-6.1946","5.87304","0.01446"
"96.0000","-6.1886","5.87369","0.01453"
"96.3000","-6.1828","5.87373","0.01460"
"96.6000","-6.1766","5.87536","0.01467"
"96.9000","-6.1708","5.87479","0.01473"
"97.2000","-6.1646","5.87645","0.01480"
"97.5000","-6.1590","5.87509","0.01487"
"97.8000","-6.1525","5.87973","0.01494"
"98.1000","-6.1466","5.87930","0.01500"
"98.4000","-6.1406","5.88007","0.01507"
"98.7000","-6.1347","5.88013","0.01514"
"99.0000","-6.1288","5.88078","0.01521"
"99.3000","-6.1227","5.88246","0.01528"
"99.6000","-6.1169","5.88128","0.01534"
"99.9000","-6.1105","5.88565","0.01541"
"100.2000","-6.1046","5.88450","0.01548"
"100.5000","-6.0987","5.88584","0.01555"
"100.8000","-6.0927","5.88505","0.01561"
"101.1000","-6.0867","5.88678","0.01568"
"101.4000","-6.0807","5.88730","0.01575"
"101.7000","-6.0749","5.88686","0.01582"
"102.0000","-6.0687","5.89001","0.01589"
"102.3000","-6.0626","5.89074","0.01596"
"102.6000","-6.0568","5.89068","0.01602"
"102.9000","-6.0507","5.89077","0.01609"
"103.2000","-6.0449","5.89157","0.01616"
"103.5000","-6.0387","5.89304","0.01623"
"103.8000","-6.0328","5.89326","0.01629"
"104.1000","-6.0266","5.89547","0.01636"
"104.4000","-6.0205","5.89667","0.01643"
"104.7000","-6.0147","5.89570","0.01649"
"105.0000","-6.0086","5.89712","0.01656"
"105.3000","-6.0028","5.89679","0.01663"
"105.6000","-5.9966","5.89963","0.01670"
"105.9000","-5.9909","5.89800","0.01676"
"106.2000","-5.9846","5.90204","0.01683"
"106.5000","-5.9786","5.90175","0.01690"
"106.8000","-5.9726","5.90249","0.01697"
"107.1000","-5.9667","5.90223","0.01703"
"107.4000","-5.9608","5.90243","0.01710"
"107.7000","-5.9546","5.90535","0.01717"
"108.0000","-5.9488","5.90390","0.01724"
"108.3000","-5.9426","5.90754","0.01731"
"108.6000","-5.9366","5.90667","0.01737"
"108.9000","-5.9307","5.90803","0.01744"
"109.2000","-5.9248","5.90684","0.01751"
"109.5000","-5.9187","5.90868","0.01757"
"109.8000","-5.9127","5.90953","0.01764"
"110.1000","-5.9068","5.90986","0.01771"
"110.4000","-5.9008","5.91121","0.01777"
"110.7000","-5.8945","5.91329","0.01784"
"111.0000","-5.8888","5.91230","0.01791"
"111.3000","-5.8827","5.91328","0.01798"
"111.6000","-5.8769","5.91282","0.01804"
"111.9000","-5.8706","5.91601","0.01811"
"112.2000","-5.8648","5.91586","0.01818"
"112.5000","-5.8586","5.91738","0.01824"
"112.8000","-5.8526","5.91842","0.01831"
"113.1000","-5.8468","5.91774","0.01838"
"113.4000","-5.8406","5.91952","0.01845"
"113.7000","-5.8348","5.91809","0.01851"
"114.0000","-5.8285","5.92235","0.01858"
"114.3000","-5.8228","5.92017","0.01864"
"114.6000","-5.8166","5.92376","0.01871"
"114.9000","-5.8107","5.92288","0.01878"
"115.2000","-5.8046","5.92463","0.01884"
"115.5000","-5.7987","5.92384","0.01891"
"115.8000","-5.7928","5.92412","0.01898"
"116.1000","-5.7867","5.92669","0.01904"
"116.4000","-5.7807","5.92678","0.01911"
"116.7000","-5.7747","5.92804","0.01918"
"117.0000","-5.7686","5.92830","0.01924"
"117.3000","-5.7627","5.92881","0.01931"
"117.6000","-5.7567","5.92900","0.01938"
"117.9000","-5.7508","5.92946","0.01944"
"118.2000","-5.7446","5.93174","0.01951"
"118.5000","-5.7386","5.93232","0.01958"
"118.8000","-5.7328","5.93239","0.01964"
"119.1000","-5.7266","5.93423","0.01971"
"119.4000","-5.7208","5.93377","0.01977"
"119.7000","-5.7145","5.93547","0.01984"
"120.0000","-5.7089","5.93364","0.01990"
"120.3000","-5.7025","5.93808","0.01997"
"120.6000","-5.6967","5.93736","0.02004"
"120.9000","-5.6906","5.93905","0.02010"
"121.2000","-5.6847","5.93883","0.02017"
"121.5000","-5.6787","5.93957","0.02023"
"121.8000","-5.6726","5.94071","0.02030"
"122.1000","-5.6668","5.93967","0.02037"
"122.4000","-5.6606","5.94320","0.02043"
"122.7000","-5.6547","5.94234","0.02050"
"123.0000","-5.6487","5.94409","0.02056"
"123.3000","-5.6428","5.94363","0.02063"
"123.6000","-5.6366","5.94529","0.02070"
"123.9000","-5.6307","5.94537","0.02077"
"124.2000","-5.6248","5.94513","0.02083"
"124.5000","-5.6188","5.94726","0.02090"
"124.8000","-5.6126","5.94853","0.02096"
"125.1000","-5.6068","5.94844","0.02103"
"125.4000","-5.6007","5.94897","0.02109"
"125.7000","-5.5948","5.94954","0.02116"
"126.0000","-5.5886","5.95084","0.02123"
"126.3000","-5.5828","5.95054","0.02129"
"126.6000","-5.5766","5.95280","0.02136"
"126.9000","-5.5706","5.95327","0.02143"
"127.2000","-5.5648","5.95336","0.02149"
"127.5000","-5.5587","5.95457","0.02155"
"127.8000","-5.5528","5.95442","0.02162"
"128.1000","-5.5465","5.95661","0.02169"
"128.4000","-5.5409","5.95499","0.02175"
"128.7000","-5.5346","5.95807","0.02182"
"129.0000","-5.5287","5.95843","0.02188"
"129.3000","-5.5227","5.95899","0.02195"
"129.6000","-5.5167","5.95930","0.02201"
"129.9000","-5.5107","5.95928","0.02208"
"130.2000","-5.5046","5.96189","0.02214"
"130.5000","-5.4987","5.96033","0.02221"
"130.8000","-5.4927","5.96332","0.02227"
"131.1000","-5.4867","5.96285","0.02234"
"131.4000","-5.4808","5.96403","0.02240"
"131.7000","-5.4747","5.96397","0.02247"
"132.0000","-5.4687","5.95641","0.02252"
"132.3000","-5.4626","5.96321","0.02258"
"132.6000","-5.4567","5.96528","0.02265"
"132.9000","-5.4507","5.96768","0.02271"
"133.2000","-5.4447","5.96892","0.02278"
"133.5000","-5.4388","5.96921","0.02284"
"133.8000","-5.4327","5.96956","0.02291"
"134.1000","-5.4268","5.96965","0.02297"
"134.4000","-5.4206","5.97162","0.02304"
"134.7000","-5.4147","5.97168","0.02310"
"135.0000","-5.4087","5.97222","0.02317"
"135.3000","-5.4027","5.97365","0.02323"
"135.6000","-5.3969","5.97281","0.02329"
"135.9000","-5.3907","5.97502","0.02336"
"136.2000","-5.3848","5.97349","0.02342"
"136.5000","-5.3785","5.97789","0.02349"
"136.8000","-5.3728","5.97529","0.02356"
"137.1000","-5.3667","5.97817","0.02362"
"137.4000","-5.3608","5.97702","0.02368"
"137.7000","-5.3547","5.97907","0.02375"
"138.0000","-5.3487","5.97898","0.02382"
"138.3000","-5.3428","5.97890","0.02388"
"138.6000","-5.3366","5.98176","0.02395"
"138.9000","-5.3306","5.98130","0.02401"
"139.2000","-5.3247","5.98229","0.02407"
"139.5000","-5.3187","5.98190","0.02414"
"139.8000","-5.3128","5.98329","0.02420"
"140.1000","-5.3067","5.98371","0.02427"
"140.4000","-5.3008","5.98417","0.02433"
"140.7000","-5.2946","5.98587","0.02440"
"141.0000","-5.2886","5.98653","0.02446"
"141.3000","-5.2828","5.98610","0.02453"
"141.6000","-5.2767","5.98770","0.02459"
"141.9000","-5.2709","5.98732","0.02466"
"142.2000","-5.2646","5.98960","0.02472"
"142.5000","-5.2589","5.98774","0.02478"
"142.8000","-5.2525","5.99172","0.02485"
"143.1000","-5.2467","5.99106","0.02492"
"143.4000","-5.2406","5.99192","0.02498"
"143.7000","-5.2348","5.99171","0.02505"
"144.0000","-5.2288","5.99235","0.02511"
"144.3000","-5.2226","5.99457","0.02517"
"144.6000","-5.2168","5.99321","0.02524"
"144.9000","-5.2104","5.99693","0.02530"
"145.2000","-5.2047","5.99537","0.02537"
"145.5000","-5.1987","5.99689","0.02543"
"145.8000","-5.1928","5.99613","0.02550"
"146.1000","-5.1867","5.99806","0.02556"
"146.4000","-5.1807","5.99850","0.02563"
"146.7000","-5.1748","5.99780","0.02569"
"147.0000","-5.1687","6.00009","0.02575"
"147.3000","-5.1626","6.00085","0.02582"
"147.6000","-5.1568","6.00088","0.02588"
"147.9000","-5.1507","6.00068","0.02595"
"148.2000","-5.1449","6.00133","0.02601"
"148.5000","-5.1386","6.00317","0.02608"
"148.8000","-5.1328","6.00302","0.02614"
"149.1000","-5.1266","6.00482","0.02620"
"149.4000","-5.1206","5.99118","0.02624"
"149.7000","-5.1148","5.99998","0.02630"
"150.0000","-5.1087","6.00510","0.02637"
"150.3000","-5.1029","6.00651","0.02643"
"150.6000","-5.0965","6.00980","0.02649"
"150.9000","-5.0908","6.00771","0.02656"
"151.2000","-5.0845","6.01072","0.02662"
"151.5000","-5.0786","6.01065","0.02668"
"151.8000","-5.0727","6.01073","0.02675"
"152.1000","-5.0668","6.01064","0.02681"
"152.4000","-5.0609","6.01081","0.02687"
"152.7000","-5.0546","6.01370","0.02694"
"153.0000","-5.0488","6.01191","0.02700"
"153.3000","-5.0426","6.01491","0.02707"
"153.6000","-5.0367","6.01390","0.02713"
"153.9000","-5.0307","6.01523","0.02719"
"154.2000","-5.0248","6.01403","0.02726"
"154.5000","-5.0188","6.01585","0.02732"
"154.8000","-5.0126","6.01718","0.02739"
"155.1000","-5.0067","6.01698","0.02745"
"155.4000","-5.0007","6.01765","0.02751"
"155.7000","-4.9946","6.01943","0.02758"
"156.0000","-4.9888","6.01849","0.02764"
"156.3000","-4.9827","6.01936","0.02770"
"156.6000","-4.9770","6.01847","0.02777"
"156.9000","-4.9706","6.02248","0.02783"
"157.2000","-4.9647","6.02161","0.02790"
"157.5000","-4.9586","6.02267","0.02796"
"157.8000","-4.9526","6.02340","0.02802"
"158.1000","-4.9468","6.02279","0.02809"
"158.4000","-4.9407","6.02459","0.02815"
"158.7000","-4.9349","6.02309","0.02821"
"159.0000","-4.9284","6.02791","0.02828"
"159.3000","-4.9228","6.02508","0.02834"
"159.6000","-4.9166","6.02803","0.02841"
"159.9000","-4.9107","6.02680","0.02847"
"160.2000","-4.9046","6.02858","0.02853"
"160.5000","-4.8988","6.02757","0.02860"
"160.8000","-4.8928","6.02798","0.02866"
"161.1000","-4.8866","6.03094","0.02872"
"161.4000","-4.8806","6.03062","0.02879"
"161.7000","-4.8747","6.03121","0.02885"
"162.0000","-4.8687","6.03134","0.02892"
"162.3000","-4.8628","6.03186","0.02898"
"162.6000","-4.8567","6.03237","0.02904"
"162.9000","-4.8509","6.03258","0.02911"
"163.2000","-4.8446","6.03516","0.02917"
"163.5000","-4.8386","6.03522","0.02923"
"163.8000","-4.8328","6.03493","0.02930"
"164.1000","-4.8266","6.03627","0.02936"
"164.4000","-4.8208","6.03575","0.02942"
"164.7000","-4.8146","6.03731","0.02948"
"165.0000","-4.8090","6.03556","0.02955"
"165.3000","-4.8026","6.03997","0.02961"
"165.6000","-4.7967","6.03966","0.02967"
"165.9000","-4.7906","6.04026","0.02974"
"166.2000","-4.7847","6.04017","0.02980"
"166.5000","-4.7788","6.04042","0.02986"
"166.8000","-4.7727","6.04195","0.02993"
"167.1000","-4.7669","6.04071","0.02999"
"167.4000","-4.7605","6.04462","0.03005"
"167.7000","-4.7546","6.04339","0.03012"
"168.0000","-4.7486","6.04444","0.03018"
"168.3000","-4.7428","6.04357","0.03024"
"168.6000","-4.7367","6.04513","0.03031"
"168.9000","-4.7307","6.04552","0.03037"
"169.2000","-4.7249","6.04474","0.03043"
"169.5000","-4.7187","6.04749","0.03050"
"169.8000","-4.7126","6.04820","0.03056"
"170.1000","-4.7068","6.04799","0.03062"
"170.4000","-4.7007","6.04795","0.03069"
"170.7000","-4.6949","6.04829","0.03075"
"171.0000","-4.6887","6.04966","0.03081"
"171.3000","-4.6828","6.04960","0.03088"
"171.6000","-4.6766","6.05171","0.03094"
"171.9000","-4.6705","6.05284","0.03100"
"172.2000","-4.6647","6.05152","0.03107"
"172.5000","-4.6586","6.05289","0.03113"
"172.8000","-4.6528","6.05232","0.03119"
"173.1000","-4.6465","6.05503","0.03126"
"173.4000","-4.6409","6.05272","0.03131"
"173.7000","-4.6346","6.05651","0.03138"
"174.0000","-4.6286","6.05645","0.03144"
"174.3000","-4.6226","6.05677","0.03150"
"174.6000","-4.6167","6.05636","0.03157"
"174.9000","-4.6108","6.05626","0.03163"
"175.2000","-4.6046","6.05906","0.03169"
"175.5000","-4.5988","6.05748","0.03175"
"175.8000","-4.5926","6.06088","0.03182"
"176.1000","-4.5866","6.05969","0.03188"
"176.4000","-4.5807","6.06076","0.03194"
"176.7000","-4.5748","6.05934","0.03201"
"177.0000","-4.5687","6.06119","0.03207"
"177.3000","-4.5627","6.06187","0.03213"
"177.6000","-4.5568","6.06183","0.03219"
"177.9000","-4.5508","6.06295","0.03225"
"178.2000","-4.5446","6.06470","0.03232"
"178.5000","-4.5388","6.06377","0.03238"
"178.8000","-4.5327","6.06375","0.03244"
"179.1000","-4.5269","6.05647","0.03249"
"179.4000","-4.5206","6.06402","0.03255"
"179.7000","-4.5148","6.06552","0.03261"
"180.0000","-4.5087","6.06763","0.03267"
"180.3000","-4.5025","6.06918","0.03273"
"180.6000","-4.4968","6.06798","0.03280"
"180.9000","-4.4906","6.06962","0.03286"
"181.2000","-4.4849","6.06790","0.03292"
"181.5000","-4.4785","6.07215","0.03299"
"181.8000","-4.4728","6.06927","0.03305"
"182.1000","-4.4666","6.07279","0.03311"
"182.4000","-4.4607","6.07137","0.03317"
"182.7000","-4.4546","6.07273","0.03323"
"183.0000","-4.4487","6.07169","0.03330"
"183.3000","-4.4428","6.07180","0.03336"
"183.6000","-4.4367","6.07433","0.03342"
"183.9000","-4.4307","6.07412","0.03348"
"184.2000","-4.4247","6.07515","0.03354"
"184.5000","-4.4186","6.07512","0.03361"
"184.8000","-4.4127","6.07568","0.03367"
"185.1000","-4.4067","6.07564","0.03373"
"185.4000","-4.4008","6.07562","0.03379"
"185.7000","-4.3946","6.07763","0.03386"
"186.0000","-4.3887","6.07777","0.03392"
"186.3000","-4.3828","6.07780","0.03398"
"186.6000","-4.3766","6.07926","0.03404"
"186.9000","-4.3708","6.07888","0.03410"
"187.2000","-4.3646","6.08048","0.03416"
"187.5000","-4.3589","6.07826","0.03422"
"187.8000","-4.3525","6.08216","0.03429"
"188.1000","-4.3467","6.08158","0.03435"
"188.4000","-4.3406","6.08286","0.03441"
"188.7000","-4.3346","6.08261","0.03447"
"189.0000","-4.3287","6.08273","0.03453"
"189.3000","-4.3226","6.08399","0.03459"
"189.6000","-4.3168","6.08248","0.03466"
"189.9000","-4.3105","6.08600","0.03472"
"190.2000","-4.3047","6.08484","0.03478"
"190.5000","-4.2987","6.08623","0.03484"
"190.8000","-4.2928","6.08545","0.03490"
"191.1000","-4.2867","6.08714","0.03496"
"191.4000","-4.2807","6.08705","0.03502"
"191.7000","-4.2748","6.08634","0.03508"
"192.0000","-4.2687","6.08834","0.03515"
"192.3000","-4.2626","6.08908","0.03521"
"192.6000","-4.2568","6.08912","0.03527"
"192.9000","-4.2507","6.08930","0.03533"
"193.2000","-4.2448","6.08954","0.03539"
"193.5000","-4.2386","6.09065","0.03545"
"193.8000","-4.2328","6.09025","0.03552"
"194.1000","-4.2267","6.09174","0.03558"
"194.4000","-4.2206","6.09281","0.03564"
"194.7000","-4.2148","6.09215","0.03570"
"195.0000","-4.2086","6.09354","0.03576"
"195.3000","-4.2028","6.09265","0.03582"
"195.6000","-4.1965","6.09519","0.03588"
"195.9000","-4.1908","6.09310","0.03594"
"196.2000","-4.1846","6.09631","0.03601"
"196.5000","-4.1787","6.09611","0.03607"
"196.8000","-4.1727","6.09668","0.03613"
"197.1000","-4.1667","6.09667","0.03619"
"197.4000","-4.1607","6.09644","0.03625"
"197.7000","-4.1545","6.09878","0.03631"
"198.0000","-4.1487","6.09684","0.03637"
"198.3000","-4.1426","6.09960","0.03643"
"198.6000","-4.1367","6.09843","0.03649"
"198.9000","-4.1308","6.09987","0.03655"
"199.2000","-4.1248","6.09896","0.03662"
"199.5000","-4.1187","6.10052","0.03668"
"199.8000","-4.1126","6.10117","0.03674"
"200.1000","-4.1067","6.10090","0.03680"
"200.4000","-4.1008","6.10133","0.03686"
"200.7000","-4.0947","6.10291","0.03692"
"201.0000","-4.0888","6.10232","0.03698"
"201.3000","-4.0826","6.10334","0.03704"
"201.6000","-4.0768","6.10246","0.03710"
"201.9000","-4.0706","6.10519","0.03716"
"202.2000","-4.0647","6.10455","0.03723"
"202.5000","-4.0587","6.10542","0.03728"
"202.8000","-4.0527","6.10595","0.03735"
"203.1000","-4.0468","6.10538","0.03741"
"203.4000","-4.0406","6.10724","0.03747"
"203.7000","-4.0349","6.10556","0.03752"
"204.0000","-4.0284","6.10991","0.03759"
"204.3000","-4.0228","6.10686","0.03765"
"204.6000","-4.0166","6.10944","0.03771"
"204.9000","-4.0108","6.10799","0.03777"
"205.2000","-4.0047","6.11005","0.03783"
"205.5000","-3.9987","6.10950","0.03789"
"205.8000","-3.9928","6.10950","0.03795"
"206.1000","-3.9866","6.11144","0.03801"
"206.4000","-3.9806","6.11121","0.03807"
"206.7000","-3.9747","6.11148","0.03813"
"207.0000","-3.9687","6.11145","0.03819"
"207.3000","-3.9629","6.11209","0.03825"
"207.6000","-3.9567","6.11281","0.03831"
"207.9000","-3.9508","6.11268","0.03837"
"208.2000","-3.9446","6.11451","0.03843"
"208.5000","-3.9386","6.11448","0.03849"
"208.8000","-3.9328","6.11397","0.03855"
"209.1000","-3.9267","6.11529","0.03861"
"209.4000","-3.9209","6.11484","0.03867"
"209.7000","-3.9146","6.11679","0.03873"
"210.0000","-3.9089","6.11465","0.03878"
"210.3000","-3.9025","6.11852","0.03885"
"210.6000","-3.8966","6.11746","0.03891"
"210.9000","-3.8906","6.11807","0.03897"
"211.2000","-3.8847","6.11777","0.03903"
"211.5000","-3.8788","6.11805","0.03908"
"211.8000","-3.8726","6.11996","0.03915"
"212.1000","-3.8668","6.11834","0.03921"
"212.4000","-3.8605","6.12168","0.03927"
"212.7000","-3.8547","6.12013","0.03932"
"213.0000","-3.8487","6.12118","0.03938"
"213.3000","-3.8428","6.12050","0.03944"
"213.6000","-3.8367","6.12164","0.03950"
"213.9000","-3.8307","6.12226","0.03956"
"214.2000","-3.8248","6.12125","0.03962"
"214.5000","-3.8186","6.12348","0.03968"
"214.8000","-3.8126","6.12387","0.03974"
"215.1000","-3.8068","6.12360","0.03980"
"215.4000","-3.8007","6.12328","0.03986"
"215.7000","-3.7949","6.12353","0.03991"
"216.0000","-3.7887","6.12534","0.03998"
"216.3000","-3.7828","6.12481","0.04003"
"216.6000","-3.7766","6.12627","0.04010"
"216.9000","-3.7706","6.12699","0.04016"
"217.2000","-3.7648","6.12597","0.04021"
"217.5000","-3.7587","6.12698","0.04027"
"217.8000","-3.7529","6.12639","0.04033"
"218.1000","-3.7465","6.12933","0.04039"
"218.4000","-3.7408","6.12693","0.04045"
"218.7000","-3.7345","6.12999","0.04051"
"219.0000","-3.7286","6.12949","0.04057"
"219.3000","-3.7227","6.12970","0.04062"
"219.6000","-3.7167","6.12926","0.04068"
"219.9000","-3.7108","6.12909","0.04074"
"220.2000","-3.7046","6.13183","0.04080"
"220.5000","-3.6987","6.13002","0.04086"
"220.8000","-3.6926","6.13270","0.04092"
"221.1000","-3.6867","6.13137","0.04097"
"221.4000","-3.6807","6.13238","0.04103"
"221.7000","-3.6748","6.13113","0.04109"
"222.0000","-3.6688","6.13246","0.04115"
"222.3000","-3.6627","6.13360","0.04121"
"222.6000","-3.6567","6.13350","0.04127"
"222.9000","-3.6507","6.13375","0.04132"
"223.2000","-3.6446","6.13533","0.04138"
"223.5000","-3.6388","6.13406","0.04144"
"223.8000","-3.6327","6.13491","0.04150"
"224.1000","-3.6270","6.13388","0.04155"
"224.4000","-3.6206","6.13718","0.04162"
"224.7000","-3.6147","6.13635","0.04167"
"225.0000","-3.6086","6.13707","0.04173"
"225.3000","-3.6026","6.13757","0.04179"
"225.6000","-3.5968","6.13674","0.04184"
"225.9000","-3.5907","6.13819","0.04190"
"226.2000","-3.5849","6.13650","0.04196"
"226.5000","-3.5784","6.14093","0.04202"
"226.8000","-3.5727","6.13815","0.04208"
"227.1000","-3.5665","6.14070","0.04213"
"227.4000","-3.5607","6.13927","0.04219"
"227.7000","-3.5546","6.14063","0.04225"
"228.0000","-3.5488","6.13943","0.04231"
"228.3000","-3.5429","6.13944","0.04236"
"228.6000","-3.5367","6.14203","0.04242"
"228.9000","-3.5306","6.14186","0.04248"
"229.2000","-3.5247","6.14214","0.04253"
"229.5000","-3.5186","6.14190","0.04259"
"229.8000","-3.5128","6.14195","0.04265"
"230.1000","-3.5068","6.14223","0.04271"
"230.4000","-3.5009","6.14211","0.04276"
"230.7000","-3.4946","6.14454","0.04282"
"231.0000","-3.4886","6.14451","0.04288"
"231.3000","-3.4828","6.14358","0.04293"
"231.6000","-3.4766","6.14496","0.04299"
"231.9000","-3.4708","6.14380","0.04305"
"232.2000","-3.4646","6.14560","0.04310"
"232.5000","-3.4590","6.14311","0.04316"
"232.8000","-3.4525","6.14773","0.04322"
"233.1000","-3.4467","6.14652","0.04327"
"233.4000","-3.4406","6.14754","0.04333"
"233.7000","-3.4347","6.14664","0.04339"
"234.0000","-3.4288","6.14685","0.04344"
"234.3000","-3.4227","6.14774","0.04350"
"234.6000","-3.4169","6.14648","0.04355"
"234.9000","-3.4105","6.15000","0.04361"
"235.2000","-3.4046","6.14881","0.04367"
"235.5000","-3.3986","6.14952","0.04372"
"235.8000","-3.3927","6.14842","0.04378"
"236.1000","-3.3867","6.14961","0.04384"
"236.4000","-3.3807","6.14958","0.04389"
"236.7000","-3.3748","6.14896","0.04394"
"237.0000","-3.3688","6.15098","0.04400"
"237.3000","-3.3625","6.15206","0.04406"
"237.6000","-3.3568","6.15085","0.04411"
"237.9000","-3.3507","6.15099","0.04417"
"238.2000","-3.3449","6.15064","0.04422"
"238.5000","-3.3386","6.15240","0.04428"
"238.8000","-3.3329","6.15127","0.04433"
"239.1000","-3.3266","6.15377","0.04439"
"239.4000","-3.3205","6.15387","0.04444"
"239.7000","-3.3147","6.15295","0.04450"
"240.0000","-3.3087","6.15340","0.04455"
"240.3000","-3.3028","6.15282","0.04460"
"240.6000","-3.2966","6.15494","0.04466"
"240.9000","-3.2909","6.15270","0.04471"
"241.2000","-3.2846","6.15598","0.04477"
"241.5000","-3.2786","6.15575","0.04482"
"241.8000","-3.2726","6.15552","0.04488"
"242.1000","-3.2667","6.15505","0.04493"
"242.4000","-3.2608","6.15465","0.04499"
"242.7000","-3.2547","6.15700","0.04504"
"243.0000","-3.2488","6.15521","0.04509"
"243.3000","-3.2427","6.15801","0.04515"
"243.6000","-3.2366","6.15743","0.04520"
"243.9000","-3.2307","6.15772","0.04525"
"244.2000","-3.2247","6.15679","0.04531"
"244.5000","-3.2188","6.15750","0.04536"
"244.8000","-3.2126","6.15848","0.04542"
"245.1000","-3.2068","6.15752","0.04547"
"245.4000","-3.2007","6.15898","0.04552"
"245.7000","-3.1946","6.16003","0.04558"
"246.0000","-3.1887","6.15935","0.04563"
"246.3000","-3.1827","6.15893","0.04568"
"246.6000","-3.1769","6.15845","0.04573"
"246.9000","-3.1706","6.16062","0.04579"
"247.2000","-3.1648","6.16023","0.04584"
"247.5000","-3.1587","6.16095","0.04589"
"247.8000","-3.1526","6.16221","0.04594"
"248.1000","-3.1468","6.16035","0.04600"
"248.4000","-3.1406","6.16173","0.04605"
"248.7000","-3.1349","6.15957","0.04610"
"249.0000","-3.1285","6.16361","0.04616"
"249.3000","-3.1228","6.16062","0.04621"
"249.6000","-3.1167","6.16353","0.04626"
"249.9000","-3.1107","6.16235","0.04631"
"250.2000","-3.1046","6.16356","0.04636"
"250.5000","-3.0987","6.16248","0.04642"
"250.8000","-3.0928","6.16176","0.04646"
"251.1000","-3.0866","6.16425","0.04652"
"251.4000","-3.0807","6.16372","0.04657"
"251.7000","-3.0747","6.16482","0.04662"
"252.0000","-3.0686","6.16415","0.04667"
"252.3000","-3.0627","6.16462","0.04672"
"252.6000","-3.0567","6.16400","0.04677"
"252.9000","-3.0508","6.16408","0.04682"
"253.2000","-3.0446","6.16542","0.04688"
"253.5000","-3.0386","6.16571","0.04693"
"253.8000","-3.0328","6.16508","0.04698"
"254.1000","-3.0266","6.16663","0.04703"
"254.4000","-3.0208","6.16515","0.04708"
"254.7000","-3.0146","6.16665","0.04713"
"255.0000","-3.0089","6.16416","0.04718"
"255.3000","-3.0026","6.16783","0.04723"
"255.6000","-2.9967","6.16687","0.04727"
"255.9000","-2.9907","6.16792","0.04733"
"256.2000","-2.9847","6.16726","0.04738"
"256.5000","-2.9787","6.16729","0.04742"
"256.8000","-2.9726","6.16835","0.04748"
"257.1000","-2.9668","6.16662","0.04752"
"257.4000","-2.9605","6.16967","0.04757"
"257.7000","-2.9547","6.16778","0.04762"
"258.0000","-2.9487","6.16895","0.04767"
"258.3000","-2.9428","6.16799","0.04772"
"258.6000","-2.9367","6.16929","0.04777"
"258.9000","-2.9307","6.16890","0.04782"
"259.2000","-2.9248","6.16783","0.04787"
"259.5000","-2.9187","6.16958","0.04792"
"259.8000","-2.9126","6.17015","0.04796"
"260.1000","-2.9068","6.16984","0.04801"
"260.4000","-2.9006","6.16969","0.04806"
"260.7000","-2.8948","6.16935","0.04811"
"261.0000","-2.8886","6.17008","0.04816"
"261.3000","-2.8828","6.16942","0.04820"
"261.6000","-2.8766","6.17097","0.04825"
"261.9000","-2.8706","6.17118","0.04829"
"262.2000","-2.8648","6.17039","0.04834"
"262.5000","-2.8587","6.17140","0.04839"
"262.8000","-2.8528","6.17056","0.04843"
"263.1000","-2.8465","6.17254","0.04848"
"263.4000","-2.8408","6.16989","0.04852"
"263.7000","-2.8346","6.17265","0.04857"
"264.0000","-2.8287","6.17200","0.04862"
"264.3000","-2.8227","6.17202","0.04866"
"264.6000","-2.8167","6.17197","0.04871"
"264.9000","-2.8107","6.17156","0.04875"
"265.2000","-2.8046","6.17351","0.04880"
"265.5000","-2.7988","6.17119","0.04885"
"265.8000","-2.7926","6.17363","0.04889"
"266.1000","-2.7867","6.17227","0.04893"
"266.4000","-2.7808","6.17326","0.04898"
"266.7000","-2.7748","6.17210","0.04902"
"267.0000","-2.7687","6.17326","0.04907"
"267.3000","-2.7626","6.17340","0.04911"
"267.6000","-2.7567","6.17278","0.04915"
"267.9000","-2.7508","6.17280","0.04920"
"268.2000","-2.7446","6.17423","0.04924"
"268.5000","-2.7388","6.17304","0.04928"
"268.8000","-2.7326","6.17378","0.04933"
"269.1000","-2.7269","6.17206","0.04937"
"269.4000","-2.7205","6.17481","0.04941"
"269.7000","-2.7147","6.17358","0.04945"
"270.0000","-2.7087","6.17399","0.04949"
"270.3000","-2.7027","6.17436","0.04954"
"270.6000","-2.6968","6.17348","0.04958"
"270.9000","-2.6906","6.17504","0.04962"
"271.2000","-2.6848","6.17273","0.04966"
"271.5000","-2.6784","6.17668","0.04970"
"271.8000","-2.6728","6.17325","0.04974"
"272.1000","-2.6666","6.17543","0.04978"
"272.4000","-2.6608","6.17384","0.04982"
"272.7000","-2.6547","6.17542","0.04986"
"273.0000","-2.6487","6.17426","0.04990"
"273.3000","-2.6427","6.17383","0.04994"
"273.6000","-2.6366","6.17549","0.04998"
"273.9000","-2.6306","6.17471","0.05002"
"274.2000","-2.6247","6.17452","0.05006"
"274.5000","-2.6187","6.17417","0.05010"
"274.8000","-2.6129","6.17436","0.05014"
"275.1000","-2.6067","6.17451","0.05018"
"275.4000","-2.6008","6.17403","0.05021"
"275.7000","-2.5946","6.17546","0.05025"
"276.0000","-2.5886","6.17508","0.05029"
"276.3000","-2.5828","6.17400","0.05032"
"276.6000","-2.5767","6.17476","0.05036"
"276.9000","-2.5709","6.17374","0.05040"
"277.2000","-2.5646","6.17530","0.05043"
"277.5000","-2.5589","6.17268","0.05047"
"277.8000","-2.5525","6.17598","0.05051"
"278.1000","-2.5467","6.17470","0.05054"
"278.4000","-2.5407","6.17472","0.05057"
"278.7000","-2.5348","6.17388","0.05061"
"279.0000","-2.5288","6.17402","0.05064"
"279.3000","-2.5226","6.17517","0.05068"
"279.6000","-2.5168","6.17300","0.05071"
"279.9000","-2.5105","6.17588","0.05075"
"280.2000","-2.5047","6.17382","0.05078"
"280.5000","-2.4987","6.17440","0.05081"
"280.8000","-2.4928","6.17280","0.05084"
"281.1000","-2.4867","6.17392","0.05088"
"281.4000","-2.4807","6.17386","0.05091"
"281.7000","-2.4748","6.17211","0.05094"
"282.0000","-2.4686","6.17389","0.05097"
"282.3000","-2.4626","6.17366","0.05100"
"282.6000","-2.4567","6.17263","0.05103"
"282.9000","-2.4507","6.17184","0.05106"
"283.2000","-2.4449","6.17167","0.05109"
"283.5000","-2.4387","6.17264","0.05112"
"283.8000","-2.4328","6.17170","0.05115"
"284.1000","-2.4266","6.17240","0.05118"
"284.4000","-2.4206","6.17257","0.05121"
"284.7000","-2.4148","6.17070","0.05124"
"285.0000","-2.4087","6.17125","0.05127"
"285.3000","-2.4029","6.16988","0.05129"
"285.6000","-2.3965","6.17224","0.05132"
"285.9000","-2.3908","6.16887","0.05135"
"286.2000","-2.3845","6.17137","0.05138"
"286.5000","-2.3786","6.17039","0.05140"
"286.8000","-2.3727","6.16974","0.05143"
"287.1000","-2.3668","6.16851","0.05145"
"287.4000","-2.3609","6.16758","0.05148"
"287.7000","-2.3546","6.16995","0.05150"
"288.0000","-2.3487","6.16721","0.05153"
"288.3000","-2.3426","6.16925","0.05155"
"288.6000","-2.3367","6.16700","0.05157"
"288.9000","-2.3307","6.16720","0.05160"
"289.2000","-2.3248","6.16499","0.05162"
"289.5000","-2.3188","6.16568","0.05164"
"289.8000","-2.3126","6.16601","0.05166"
"290.1000","-2.3067","6.16465","0.05168"
"290.4000","-2.3008","6.16414","0.05171"
"290.7000","-2.2946","6.16481","0.05173"
"291.0000","-2.2888","6.16267","0.05175"
"291.3000","-2.2827","6.16249","0.05177"
"291.6000","-2.2769","6.16061","0.05178"
"291.9000","-2.2706","6.16275","0.05181"
"292.2000","-2.2647","6.16078","0.05182"
"292.5000","-2.2587","6.16043","0.05184"
"292.8000","-2.2526","6.16013","0.05186"
"293.1000","-2.2468","6.15793","0.05188"
"293.4000","-2.2407","6.15858","0.05190"
"293.7000","-2.2349","6.15568","0.05191"
"294.0000","-2.2284","6.15923","0.05193"
"294.3000","-2.2228","6.15458","0.05194"
"294.6000","-2.2165","6.15645","0.05196"
"294.9000","-2.2107","6.15342","0.05197"
"295.2000","-2.2046","6.15359","0.05199"
"295.5000","-2.1988","6.15098","0.05200"
"295.8000","-2.1929","6.14999","0.05202"
"296.1000","-2.1866","6.15144","0.05203"
"296.4000","-2.1806","6.14933","0.05204"
"296.7000","-2.1747","6.14824","0.05205"
"297.0000","-2.1687","6.14637","0.05207"
"297.3000","-2.1628","6.14519","0.05208"
"297.6000","-2.1568","6.14392","0.05209"
"297.9000","-2.1508","6.14237","0.05210"
"298.2000","-2.1446","6.14290","0.05211"
"298.5000","-2.1386","6.14102","0.05212"
"298.8000","-2.1328","6.13868","0.05213"
"299.1000","-2.1266","6.13800","0.05214"
"299.4000","-2.1208","6.13547","0.05215"
"299.7000","-2.1146","6.13553","0.05216"
"300.0000","-2.1090","6.13130","0.05217"
"300.3000","-2.1025","6.13369","0.05218"
"300.6000","-2.0966","6.13083","0.05219"
"300.9000","-2.0906","6.12927","0.05219"
"301.2000","-2.0847","6.12664","0.05220"
"301.5000","-2.0788","6.12451","0.05221"
"301.8000","-2.0727","6.12403","0.05221"
"302.1000","-2.0669","6.12015","0.05222"
"302.4000","-2.0605","6.12194","0.05223"
"302.7000","-2.0546","6.11760","0.05223"
"303.0000","-2.0486","6.11611","0.05224"
"303.3000","-2.0428","6.11242","0.05224"
"303.6000","-2.0367","6.11143","0.05225"
"303.9000","-2.0307","6.10902","0.05225"
"304.2000","-2.0248","6.10547","0.05226"
"304.5000","-2.0187","6.10527","0.05226"
"304.8000","-2.0126","6.10272","0.05227"
"305.1000","-2.0067","6.09961","0.05227"
"305.4000","-2.0007","6.09611","0.05227"
"305.7000","-1.9949","6.09377","0.05227"
"306.0000","-1.9887","6.09199","0.05228"
"306.3000","-1.9829","6.08860","0.05228"
"306.6000","-1.9766","6.08715","0.05228"
"306.9000","-1.9705","6.08473","0.05229"
"307.2000","-1.9647","6.08013","0.05229"
"307.5000","-1.9586","6.07785","0.05229"
"307.8000","-1.9528","6.07333","0.05229"
"308.1000","-1.9465","6.07268","0.05229"
"308.4000","-1.9409","6.06658","0.05229"
"308.7000","-1.9346","6.06681","0.05229"
"309.0000","-1.9286","6.06226","0.05229"
"309.3000","-1.9226","6.05861","0.05229"
"309.6000","-1.9167","6.05409","0.05229"
"309.9000","-1.9108","6.05012","0.05229"
"310.2000","-1.9046","6.04883","0.05230"
"310.5000","-1.8988","6.04250","0.05229"
"310.8000","-1.8926","6.04182","0.05229"
"311.1000","-1.8866","6.03552","0.05229"
"311.4000","-1.8807","6.03272","0.05229"
"311.7000","-1.8748","6.02630","0.05229"
"312.0000","-1.8687","6.02364","0.05229"
"312.3000","-1.8627","6.01924","0.05229"
"312.6000","-1.8568","6.01451","0.05229"
"312.9000","-1.8508","6.01097","0.05229"
"313.2000","-1.8446","6.00721","0.05229"
"313.5000","-1.8388","6.00113","0.05228"
"313.8000","-1.8326","5.99605","0.05228"
"314.1000","-1.8269","5.99043","0.05228"
"314.4000","-1.8206","5.98806","0.05228"
"314.7000","-1.8147","5.98198","0.05228"
"315.0000","-1.8087","5.97771","0.05228"
"315.3000","-1.8026","5.97268","0.05227"
"315.6000","-1.7968","5.96617","0.05227"
"315.9000","-1.7906","5.96169","0.05227"
"316.2000","-1.7849","5.95406","0.05226"
"316.5000","-1.7784","5.95248","0.05226"
"316.8000","-1.7728","5.94340","0.05226"
"317.1000","-1.7666","5.94091","0.05226"
"317.4000","-1.7607","5.93289","0.05225"
"317.7000","-1.7546","5.92804","0.05225"
"318.0000","-1.7487","5.92024","0.05225"
"318.3000","-1.7428","5.91379","0.05224"
"318.6000","-1.7367","5.90975","0.05224"
"318.9000","-1.7307","5.90243","0.05224"
"319.2000","-1.7247","5.89688","0.05223"
"319.5000","-1.7186","5.88903","0.05223"
"319.8000","-1.7127","5.88280","0.05223"
"320.1000","-1.7067","5.87507","0.05222"
"320.4000","-1.7008","5.86821","0.05222"
"320.7000","-1.6946","5.86263","0.05222"
"321.0000","-1.6887","5.85519","0.05221"
"321.3000","-1.6828","5.84804","0.05221"
"321.6000","-1.6766","5.84115","0.05220"
"321.9000","-1.6708","5.83274","0.05220"
"322.2000","-1.6646","5.82548","0.05219"
"322.5000","-1.6589","5.81630","0.05219"
"322.8000","-1.6525","5.81182","0.05219"
"323.1000","-1.6467","5.80300","0.05218"
"323.4000","-1.6406","5.79542","0.05218"
"323.7000","-1.6347","5.78640","0.05217"
"324.0000","-1.6287","5.77791","0.05216"
"324.3000","-1.6226","5.77042","0.05216"
"324.6000","-1.6168","5.75966","0.05215"
"324.9000","-1.6105","5.75438","0.05215"
"325.2000","-1.6047","5.74350","0.05214"
"325.5000","-1.5988","5.73636","0.05213"
"325.8000","-1.5928","5.72525","0.05213"
"326.1000","-1.5867","5.71713","0.05212"
"326.4000","-1.5807","5.70710","0.05212"
"326.7000","-1.5748","5.69679","0.05211"
"327.0000","-1.5687","5.68951","0.05210"
"327.3000","-1.5626","5.67914","0.05210"
"327.6000","-1.5568","5.66965","0.05209"
"327.9000","-1.5507","5.65770","0.05208"
"328.2000","-1.5448","5.64882","0.05208"
"328.5000","-1.5386","5.63755","0.05207"
"328.8000","-1.5328","5.62693","0.05206"
"329.1000","-1.5266","5.61652","0.05205"
"329.4000","-1.5206","5.60607","0.05205"
"329.7000","-1.5148","5.59389","0.05204"
"330.0000","-1.5086","5.58249","0.05203"
"330.3000","-1.5028","5.56930","0.05202"
"330.6000","-1.4965","5.55830","0.05201"
"330.9000","-1.4908","5.54263","0.05200"
"331.2000","-1.4846","5.53174","0.05200"
"331.5000","-1.4787","5.51658","0.05199"
"331.8000","-1.4727","5.50269","0.05198"
"332.1000","-1.4667","5.48662","0.05197"
"332.4000","-1.4607","5.47076","0.05196"
"332.7000","-1.4545","5.45604","0.05195"
"333.0000","-1.4487","5.43547","0.05193"
"333.3000","-1.4426","5.41824","0.05192"
"333.6000","-1.4367","5.37322","0.05189"
"333.9000","-1.4308","5.33085","0.05186"
"334.2000","-1.4248","5.24933","0.05180"
"334.5000","-1.4187","5.19804","0.05177"
"334.8000","-1.4126","5.15926","0.05174"
"335.1000","-1.4067","5.11278","0.05171"
"335.4000","-1.4008","5.05301","0.05166"
"335.7000","-1.3946","4.97875","0.05161"
"336.0000","-1.3888","4.92516","0.05157"
"336.3000","-1.3826","4.85124","0.05152"
"336.6000","-1.3768","4.79603","0.05148"
"336.9000","-1.3705","4.72366","0.05144"
"337.2000","-1.3647","4.66398","0.05139"
"337.5000","-1.3586","4.57674","0.05133"
"337.8000","-1.3526","4.49477","0.05128"
"338.1000","-1.3468","4.37150","0.05119"
"338.4000","-1.3406","4.18759","0.05106"
"338.7000","-1.3347","4.02028","0.05093"
"339.0000","-1.3284","3.89139","0.05084"
"339.3000","-1.3227","3.76441","0.05075"
"339.3940","-1.3210","3.70618","0.05071"