File: Coupon Test Data/Tensile Test_Neebajan_Alan_18.csv
Time,Displacement,Force,Strain 1
(s),(mm),(kN),(mm/mm)
"0.0000","0.0000","0.19860","0.00005"
"0.5000","0.0084","0.30903","0.00009"
"1.0000","0.0182","0.44179","0.00014"
"1.5000","0.0285","0.57425","0.00019"
"2.0000","0.0386","0.70100","0.00025"
"2.5000","0.0485","0.81531","0.00029"
"3.0000","0.0586","0.93135","0.00033"
"3.5000","0.0687","1.04688","0.00038"
"4.0000","0.0787","1.15656","0.00043"
"4.5000","0.0885","1.26753","0.00047"
"5.0000","0.0986","1.37174","0.00051"
"5.5000","0.1086","1.47905","0.00055"
"6.0000","0.1185","1.57740","0.00059"
"6.5000","0.1286","1.67444","0.00063"
"7.0000","0.1385","1.77170","0.00067"
"7.5000","0.1486","1.86751","0.00071"
"8.0000","0.1586","1.95717","0.00075"
"8.5000","0.1687","2.04601","0.00078"
"9.0000","0.1787","2.14022","0.00082"
"9.5000","0.1884","2.22221","0.00085"
"10.0000","0.1987","2.30891","0.00089"
"10.5000","0.2086","2.39033","0.00092"
"11.0000","0.2185","2.47574","0.00095"
"11.5000","0.2285","2.55537","0.00099"
"12.0000","0.2386","2.63460","0.00102"
"12.5000","0.2488","2.71540","0.00105"
"13.0000","0.2586","2.79397","0.00108"
"13.5000","0.2686","2.86919","0.00111"
"14.0000","0.2786","2.94249","0.00114"
"14.5000","0.2885","3.01286","0.00117"
"15.0000","0.2985","3.08758","0.00120"
"15.5000","0.3085","3.15728","0.00123"
"16.0000","0.3187","3.22847","0.00126"
"16.5000","0.3286","3.29533","0.00129"
"17.0000","0.3387","3.36976","0.00132"
"17.5000","0.3488","3.43783","0.00134"
"18.0000","0.3585","3.50029","0.00137"
"18.5000","0.3686","3.56193","0.00139"
"19.0000","0.3786","3.62666","0.00142"
"19.5000","0.3885","3.68738","0.00145"
"20.0000","0.3984","3.74804","0.00147"
"20.5000","0.4086","3.81496","0.00150"
"21.0000","0.4188","3.87577","0.00152"
"21.5000","0.4286","3.93361","0.00155"
"22.0000","0.4386","3.99454","0.00157"
"22.5000","0.4486","4.05987","0.00160"
"23.0000","0.4586","4.11941","0.00163"
"23.5000","0.4684","4.17739","0.00165"
"24.0000","0.4785","4.24106","0.00167"
"24.5000","0.4887","4.29575","0.00170"
"25.0000","0.4986","4.35984","0.00172"
"25.5000","0.5087","4.42331","0.00175"
"26.0000","0.5187","4.48331","0.00177"
"26.5000","0.5286","4.54452","0.00180"
"27.0000","0.5385","4.60231","0.00182"
"27.5000","0.5486","4.66376","0.00185"
"28.0000","0.5586","4.72247","0.00187"
"28.5000","0.5684","4.78272","0.00190"
"29.0000","0.5787","4.84499","0.00193"
"29.5000","0.5886","4.90405","0.00195"
"30.0000","0.5987","4.97049","0.00198"
"30.5000","0.6085","5.03337","0.00201"
"31.0000","0.6187","5.09607","0.00203"
"31.5000","0.6288","5.15975","0.00206"
"32.0000","0.6385","5.21735","0.00208"
"32.5000","0.6486","5.27946","0.00211"
"33.0000","0.6586","5.34036","0.00214"
"33.5000","0.6685","5.40366","0.00216"
"34.0000","0.6785","5.46967","0.00219"
"34.5000","0.6886","5.53292","0.00222"
"35.0000","0.6988","5.59871","0.00225"
"35.5000","0.7086","5.65866","0.00228"
"36.0000","0.7187","5.72061","0.00230"
"36.5000","0.7287","5.78108","0.00233"
"37.0000","0.7385","5.85020","0.00236"
"37.5000","0.7485","5.91046","0.00239"
"38.0000","0.7585","5.97005","0.00241"
"38.5000","0.7686","6.03618","0.00244"
"39.0000","0.7784","6.10275","0.00247"
"39.5000","0.7888","6.16567","0.00250"
"40.0000","0.7989","6.22712","0.00253"
"40.5000","0.8085","6.29624","0.00256"
"41.0000","0.8185","6.35469","0.00259"
"41.5000","0.8286","6.41491","0.00261"
"42.0000","0.8385","6.48708","0.00265"
"42.5000","0.8485","6.54701","0.00268"
"43.0000","0.8586","6.60693","0.00271"
"43.5000","0.8687","6.68103","0.00274"
"44.0000","0.8787","6.74049","0.00277"
"44.5000","0.8886","6.79856","0.00280"
"45.0000","0.8986","6.87086","0.00283"
"45.5000","0.9086","6.92939","0.00286"
"46.0000","0.9184","6.98546","0.00289"
"46.5000","0.9286","7.05840","0.00293"
"47.0000","0.9387","7.11710","0.00296"
"47.5000","0.9485","7.18430","0.00300"
"48.0000","0.9587","7.24287","0.00303"
"48.5000","0.9687","7.29924","0.00306"
"49.0000","0.9786","7.36737","0.00310"
"49.5000","0.9884","7.41713","0.00313"
"50.0000","0.9987","7.48872","0.00317"
"50.5000","1.0087","7.53967","0.00321"
"51.0000","1.0185","7.60467","0.00325"
"51.5000","1.0286","7.65359","0.00328"
"52.0000","1.0386","7.72036","0.00333"
"52.5000","1.0487","7.76862","0.00337"
"53.0000","1.0585","7.82720","0.00342"
"53.5000","1.0686","7.88575","0.00346"
"54.0000","1.0788","7.93168","0.00351"
"54.5000","1.0885","7.98373","0.00356"
"55.0000","1.0987","8.02989","0.00362"
"55.5000","1.1086","8.07168","0.00367"
"56.0000","1.1184","8.11587","0.00373"
"56.5000","1.1285","8.15349","0.00381"
"57.0000","1.1386","8.17553","0.00387"
"57.5000","1.1487","8.22026","0.00394"
"58.0000","1.1585","8.24720","0.00402"
"58.5000","1.1688","8.27396","0.00412"
"59.0000","1.1787","8.29598","0.00421"
"59.5000","1.1885","8.31372","0.00430"
"60.0000","1.1984","8.33001","0.00440"
"60.5000","1.2085","8.34636","0.00450"
"61.0000","1.2187","8.36229","0.00460"
"61.5000","1.2285","8.37317","0.00471"
"62.0000","1.2387","8.38722","0.00482"
"62.5000","1.2489","8.40076","0.00493"
"63.0000","1.2586","8.40784","0.00504"
"63.5000","1.2686","8.41457","0.00515"
"64.0000","1.2785","8.41479","0.00525"
"64.5000","1.2885","8.43057","0.00536"
"65.0000","1.2985","8.43619","0.00547"
"65.5000","1.3087","8.44378","0.00559"
"66.0000","1.3187","8.45170","0.00571"
"66.5000","1.3286","8.45691","0.00582"
"67.0000","1.3387","8.46096","0.00594"
"67.5000","1.3488","8.46764","0.00606"
"68.0000","1.3586","8.47201","0.00618"
"68.5000","1.3683","8.47316","0.00630"
"69.0000","1.3786","8.47996","0.00642"
"69.5000","1.3887","8.48521","0.00654"
"70.0000","1.3985","8.48820","0.00666"
"70.5000","1.4087","8.49319","0.00677"
"71.0000","1.4187","8.49719","0.00690"
"71.5000","1.4287","8.50131","0.00702"
"72.0000","1.4385","8.50196","0.00714"
"72.5000","1.4486","8.50705","0.00726"
"73.0000","1.4587","8.51160","0.00738"
"73.5000","1.4685","8.51221","0.00750"
"74.0000","1.4786","8.51566","0.00762"
"74.5000","1.4886","8.51954","0.00775"
"75.0000","1.4987","8.52418","0.00787"
"75.5000","1.5086","8.52389","0.00799"
"76.0000","1.5187","8.52829","0.00811"
"76.5000","1.5287","8.53260","0.00823"
"77.0000","1.5384","8.51647","0.00834"
"77.5000","1.5487","8.53536","0.00845"
"78.0000","1.5586","8.53999","0.00857"
"78.5000","1.5684","8.54057","0.00869"
"79.0000","1.5785","8.54184","0.00881"
"79.5000","1.5887","8.54613","0.00894"
"80.0000","1.5988","8.55131","0.00906"
"80.5000","1.6086","8.55083","0.00918"
"81.0000","1.6187","8.55386","0.00930"
"81.5000","1.6287","8.55731","0.00943"
"82.0000","1.6386","8.55803","0.00955"
"82.5000","1.6485","8.55786","0.00967"
"83.0000","1.6585","8.56102","0.00979"
"83.5000","1.6686","8.56544","0.00991"
"84.0000","1.6785","8.56546","0.01004"
"84.5000","1.6888","8.57119","0.01016"
"85.0000","1.6989","8.57435","0.01028"
"85.5000","1.7085","8.57409","0.01040"
"86.0000","1.7186","8.57507","0.01052"
"86.5000","1.7286","8.57684","0.01065"
"87.0000","1.7386","8.58019","0.01077"
"87.5000","1.7484","8.58055","0.01089"
"88.0000","1.7586","8.58423","0.01101"
"88.5000","1.7688","8.58781","0.01113"
"89.0000","1.7787","8.58933","0.01126"
"89.5000","1.7887","8.59104","0.01138"
"90.0000","1.7987","8.59387","0.01150"
"90.5000","1.8086","8.56681","0.01157"
"91.0000","1.8183","8.59063","0.01167"
"91.5000","1.8285","8.60033","0.01179"
"92.0000","1.8387","8.60489","0.01191"
"92.5000","1.8486","8.60383","0.01203"
"93.0000","1.8587","8.60577","0.01215"
"93.5000","1.8687","8.60752","0.01227"
"94.0000","1.8787","8.61083","0.01239"
"94.5000","1.8885","8.60969","0.01251"
"95.0000","1.8987","8.61274","0.01263"
"95.5000","1.9086","8.61558","0.01275"
"96.0000","1.9184","8.61513","0.01287"
"96.5000","1.9287","8.61834","0.01299"
"97.0000","1.9387","8.62026","0.01311"
"97.5000","1.9487","8.62340","0.01323"
"98.0000","1.9584","8.62250","0.01335"
"98.5000","1.9687","8.62747","0.01347"
"99.0000","1.9789","8.63101","0.01359"
"99.5000","1.9884","8.62867","0.01371"
"100.0000","1.9986","8.63292","0.01383"
"100.5000","2.0087","8.63498","0.01395"
"101.0000","2.0185","8.63538","0.01407"
"101.5000","2.0285","8.63595","0.01419"
"102.0000","2.0386","8.63893","0.01431"
"102.5000","2.0488","8.64496","0.01443"
"103.0000","2.0586","8.64446","0.01454"
"103.5000","2.0687","8.64714","0.01467"
"104.0000","2.0787","8.64892","0.01478"
"104.5000","2.0885","8.64940","0.01490"
"105.0000","2.0985","8.65015","0.01502"
"105.5000","2.1085","8.65243","0.01514"
"106.0000","2.1186","8.65602","0.01526"
"106.5000","2.1284","8.65572","0.01538"
"107.0000","2.1388","8.66113","0.01550"
"107.5000","2.1489","8.66455","0.01562"
"108.0000","2.1585","8.66367","0.01573"
"108.5000","2.1685","8.66464","0.01585"
"109.0000","2.1786","8.66724","0.01597"
"109.5000","2.1886","8.66887","0.01609"
"110.0000","2.1985","8.66918","0.01620"
"110.5000","2.2086","8.67260","0.01632"
"111.0000","2.2188","8.67727","0.01644"
"111.5000","2.2287","8.67780","0.01656"
"112.0000","2.2386","8.67850","0.01667"
"112.5000","2.2487","8.68176","0.01679"
"113.0000","2.2586","8.68420","0.01691"
"113.5000","2.2684","8.68182","0.01702"
"114.0000","2.2786","8.68597","0.01714"
"114.5000","2.2887","8.68929","0.01726"
"115.0000","2.2985","8.69003","0.01737"
"115.5000","2.3087","8.69318","0.01749"
"116.0000","2.3187","8.67800","0.01759"
"116.5000","2.3286","8.69408","0.01770"
"117.0000","2.3384","8.69707","0.01781"
"117.5000","2.3487","8.70184","0.01793"
"118.0000","2.3587","8.70386","0.01804"
"118.5000","2.3685","8.70266","0.01815"
"119.0000","2.3786","8.70509","0.01827"
"119.5000","2.3886","8.70792","0.01839"
"120.0000","2.3987","8.71044","0.01851"
"120.5000","2.4085","8.70943","0.01862"
"121.0000","2.4186","8.71325","0.01873"
"121.5000","2.4288","8.71738","0.01885"
"122.0000","2.4385","8.71551","0.01896"
"122.5000","2.4487","8.71947","0.01908"
"123.0000","2.4587","8.72065","0.01919"
"123.5000","2.4685","8.72160","0.01931"
"124.0000","2.4785","8.72244","0.01942"
"124.5000","2.4887","8.72558","0.01954"
"125.0000","2.4987","8.72986","0.01965"
"125.5000","2.5085","8.72988","0.01977"
"126.0000","2.5188","8.73350","0.01989"
"126.5000","2.5287","8.73496","0.02000"
"127.0000","2.5385","8.73460","0.02011"
"127.5000","2.5484","8.73493","0.02023"
"128.0000","2.5586","8.73864","0.02035"
"128.5000","2.5687","8.74175","0.02046"
"129.0000","2.5785","8.74108","0.02057"
"129.5000","2.5887","8.74564","0.02069"
"130.0000","2.5989","8.75031","0.02081"
"130.5000","2.6086","8.74921","0.02092"
"131.0000","2.6186","8.74973","0.02103"
"131.5000","2.6286","8.75124","0.02115"
"132.0000","2.6385","8.75413","0.02126"
"132.5000","2.6485","8.75450","0.02138"
"133.0000","2.6587","8.75785","0.02149"
"133.5000","2.6687","8.76093","0.02161"
"134.0000","2.6786","8.76231","0.02172"
"134.5000","2.6887","8.76372","0.02184"
"135.0000","2.6987","8.76619","0.02195"
"135.5000","2.7086","8.76777","0.02207"
"136.0000","2.7183","8.76560","0.02218"
"136.5000","2.7286","8.77065","0.02229"
"137.0000","2.7387","8.77343","0.02241"
"137.5000","2.7485","8.77414","0.02252"
"138.0000","2.7586","8.77683","0.02263"
"138.5000","2.7687","8.77929","0.02275"
"139.0000","2.7787","8.78141","0.02286"
"139.5000","2.7885","8.78048","0.02297"
"140.0000","2.7986","8.78355","0.02309"
"140.5000","2.8087","8.78726","0.02320"
"141.0000","2.8185","8.78642","0.02331"
"141.5000","2.8286","8.78852","0.02343"
"142.0000","2.8386","8.79092","0.02354"
"142.5000","2.8487","8.79467","0.02365"
"143.0000","2.8586","8.79360","0.02377"
"143.5000","2.8687","8.79701","0.02388"
"144.0000","2.8788","8.80061","0.02399"
"144.5000","2.8884","8.79882","0.02410"
"145.0000","2.8987","8.80335","0.02422"
"145.5000","2.9087","8.80453","0.02433"
"146.0000","2.9185","8.80481","0.02444"
"146.5000","2.9284","8.80567","0.02455"
"147.0000","2.9387","8.80961","0.02467"
"147.5000","2.9488","8.81389","0.02478"
"148.0000","2.9586","8.81302","0.02489"
"148.5000","2.9687","8.81550","0.02501"
"149.0000","2.9787","8.81838","0.02512"
"149.5000","2.9885","8.81808","0.02523"
"150.0000","2.9985","8.81849","0.02534"
"150.5000","3.0085","8.82080","0.02546"
"151.0000","3.0187","8.82365","0.02557"
"151.5000","3.0285","8.81082","0.02564"
"152.0000","3.0388","8.82645","0.02575"
"152.5000","3.0489","8.83313","0.02586"
"153.0000","3.0585","8.83294","0.02597"
"153.5000","3.0686","8.83351","0.02608"
"154.0000","3.0786","8.83459","0.02619"
"154.5000","3.0885","8.83649","0.02631"
"155.0000","3.0984","8.83665","0.02642"
"155.5000","3.1087","8.84039","0.02653"
"156.0000","3.1188","8.84332","0.02664"
"156.5000","3.1287","8.84419","0.02676"
"157.0000","3.1386","8.84468","0.02686"
"157.5000","3.1487","8.84829","0.02698"
"158.0000","3.1586","8.83681","0.02706"
"158.5000","3.1683","8.84437","0.02717"
"159.0000","3.1785","8.85106","0.02728"
"159.5000","3.1887","8.85614","0.02739"
"160.0000","3.1986","8.85608","0.02750"
"160.5000","3.2087","8.85831","0.02761"
"161.0000","3.2187","8.85992","0.02772"
"161.5000","3.2286","8.86241","0.02783"
"162.0000","3.2385","8.86134","0.02795"
"162.5000","3.2487","8.86424","0.02806"
"163.0000","3.2586","8.86662","0.02817"
"163.5000","3.2684","8.86611","0.02828"
"164.0000","3.2787","8.86915","0.02839"
"164.5000","3.2887","8.87061","0.02850"
"165.0000","3.2987","8.87332","0.02862"
"165.5000","3.3085","8.87235","0.02872"
"166.0000","3.3187","8.87688","0.02884"
"166.5000","3.3288","8.88009","0.02895"
"167.0000","3.3384","8.87750","0.02906"
"167.5000","3.3487","8.88183","0.02917"
"168.0000","3.3587","8.88360","0.02928"
"168.5000","3.3685","8.88360","0.02939"
"169.0000","3.3785","8.88409","0.02951"
"169.5000","3.3886","8.88688","0.02962"
"170.0000","3.3988","8.89228","0.02973"
"170.5000","3.4086","8.89171","0.02984"
"171.0000","3.4187","8.89382","0.02995"
"171.5000","3.4287","8.89588","0.03006"
"172.0000","3.4385","8.89551","0.03017"
"172.5000","3.4485","8.89610","0.03029"
"173.0000","3.4586","8.89866","0.03040"
"173.5000","3.4687","8.90197","0.03051"
"174.0000","3.4784","8.90121","0.03062"
"174.5000","3.4888","8.90616","0.03073"
"175.0000","3.4989","8.90971","0.03084"
"175.5000","3.5085","8.90828","0.03095"
"176.0000","3.5185","8.90882","0.03106"
"176.5000","3.5286","8.91129","0.03117"
"177.0000","3.5386","8.91284","0.03129"
"177.5000","3.5485","8.91266","0.03140"
"178.0000","3.5586","8.91598","0.03151"
"178.5000","3.5687","8.92026","0.03162"
"179.0000","3.5787","8.92083","0.03173"
"179.5000","3.5886","8.92113","0.03184"
"180.0000","3.5987","8.92395","0.03195"
"180.5000","3.6086","8.92588","0.03206"
"181.0000","3.6184","8.92357","0.03217"
"181.5000","3.6286","8.92725","0.03228"
"182.0000","3.6387","8.93040","0.03240"
"182.5000","3.6485","8.93089","0.03250"
"183.0000","3.6587","8.93408","0.03262"
"183.5000","3.6688","8.93542","0.03273"
"184.0000","3.6786","8.93704","0.03284"
"184.5000","3.6884","8.93637","0.03295"
"185.0000","3.6987","8.94093","0.03306"
"185.5000","3.7087","8.94212","0.03317"
"186.0000","3.7185","8.94107","0.03329"
"186.5000","3.7286","8.94350","0.03340"
"187.0000","3.7387","8.94630","0.03351"
"187.5000","3.7487","8.94923","0.03362"
"188.0000","3.7585","8.94766","0.03373"
"188.5000","3.7686","8.95070","0.03384"
"189.0000","3.7788","8.95486","0.03395"
"189.5000","3.7886","8.95349","0.03406"
"190.0000","3.7987","8.95671","0.03417"
"190.5000","3.8086","8.95710","0.03428"
"191.0000","3.8184","8.95782","0.03439"
"191.5000","3.8285","8.95900","0.03451"
"192.0000","3.8387","8.96186","0.03462"
"192.5000","3.8488","8.96583","0.03473"
"193.0000","3.8585","8.96469","0.03483"
"193.5000","3.8687","8.96801","0.03495"
"194.0000","3.8787","8.96954","0.03506"
"194.5000","3.8886","8.96981","0.03517"
"195.0000","3.8984","8.96901","0.03528"
"195.5000","3.9085","8.97222","0.03539"
"196.0000","3.9187","8.97464","0.03550"
"196.5000","3.9285","8.97387","0.03561"
"197.0000","3.9387","8.97923","0.03572"
"197.5000","3.9489","8.98309","0.03584"
"198.0000","3.9586","8.98124","0.03594"
"198.5000","3.9686","8.98131","0.03605"
"199.0000","3.9786","8.98256","0.03616"
"199.5000","3.9886","8.98575","0.03628"
"200.0000","3.9984","8.98511","0.03639"
"200.5000","4.0086","8.98832","0.03650"
"201.0000","4.0187","8.99108","0.03661"
"201.5000","4.0286","8.99212","0.03672"
"202.0000","4.0387","8.99391","0.03683"
"202.5000","4.0487","8.99554","0.03694"
"203.0000","4.0586","8.99638","0.03705"
"203.5000","4.0683","8.99387","0.03716"
"204.0000","4.0786","8.99874","0.03727"
"204.5000","4.0888","9.00223","0.03738"
"205.0000","4.0985","9.00118","0.03749"
"205.5000","4.1086","9.00379","0.03760"
"206.0000","4.1187","9.00628","0.03772"
"206.5000","4.1287","9.00820","0.03783"
"207.0000","4.1385","8.99299","0.03791"
"207.5000","4.1486","9.00598","0.03802"
"208.0000","4.1586","9.01214","0.03812"
"208.5000","4.1685","9.01213","0.03823"
"209.0000","4.1786","9.01456","0.03834"
"209.5000","4.1886","9.01626","0.03845"
"210.0000","4.1986","9.01896","0.03856"
"210.5000","4.2085","9.01753","0.03868"
"211.0000","4.2187","9.02084","0.03879"
"211.5000","4.2288","9.02401","0.03890"
"212.0000","4.2384","9.02125","0.03900"
"212.5000","4.2487","9.02576","0.03912"
"213.0000","4.2587","9.02615","0.03923"
"213.5000","4.2685","9.02572","0.03934"
"214.0000","4.2784","9.02659","0.03945"
"214.5000","4.2887","9.03009","0.03956"
"215.0000","4.2988","9.03390","0.03967"
"215.5000","4.3086","9.03263","0.03978"
"216.0000","4.3187","9.03459","0.03989"
"216.5000","4.3287","9.03684","0.04000"
"217.0000","4.3386","9.03644","0.04011"
"217.5000","4.3485","9.03638","0.04022"
"218.0000","4.3585","9.03857","0.04033"
"218.5000","4.3687","9.00873","0.04042"
"219.0000","4.3785","9.03111","0.04052"
"219.5000","4.3888","9.04336","0.04063"
"220.0000","4.3989","9.04885","0.04074"
"220.5000","4.4085","9.04831","0.04085"
"221.0000","4.4186","9.04884","0.04095"
"221.5000","4.4286","9.04988","0.04107"
"222.0000","4.4385","9.05094","0.04118"
"222.5000","4.4484","9.05069","0.04128"
"223.0000","4.4587","9.05412","0.04140"
"223.5000","4.4688","9.05718","0.04151"
"224.0000","4.4787","9.05714","0.04162"
"224.5000","4.4886","9.05727","0.04173"
"225.0000","4.4987","9.06057","0.04184"
"225.5000","4.5086","9.06097","0.04195"
"226.0000","4.5183","9.05800","0.04206"
"226.5000","4.5285","9.06171","0.04217"
"227.0000","4.5387","9.06574","0.04228"
"227.5000","4.5486","9.06556","0.04239"
"228.0000","4.5587","9.06738","0.04250"
"228.5000","4.5687","9.06850","0.04261"
"229.0000","4.5786","9.07089","0.04272"
"229.5000","4.5885","9.06943","0.04284"
"230.0000","4.5987","9.07231","0.04295"
"230.5000","4.6086","9.07403","0.04306"
"231.0000","4.6184","9.07303","0.04317"
"231.5000","4.6287","9.07584","0.04329"
"232.0000","4.6387","9.07699","0.04340"
"232.5000","4.6487","9.07929","0.04351"
"233.0000","4.6585","9.07804","0.04362"
"233.5000","4.6687","9.08189","0.04373"
"234.0000","4.6788","9.08459","0.04384"
"234.5000","4.6884","9.08191","0.04395"
"235.0000","4.6986","9.08544","0.04406"
"235.5000","4.7087","9.08727","0.04417"
"236.0000","4.7185","9.08687","0.04428"
"236.5000","4.7285","9.08671","0.04439"
"237.0000","4.7386","9.08917","0.04451"
"237.5000","4.7488","9.09359","0.04461"
"238.0000","4.7586","9.09295","0.04473"
"238.5000","4.7687","9.09481","0.04484"
"239.0000","4.7787","9.09602","0.04495"
"239.5000","4.7885","9.09576","0.04506"
"240.0000","4.7985","9.09574","0.04517"
"240.5000","4.8086","9.09788","0.04528"
"241.0000","4.8187","9.10039","0.04539"
"241.5000","4.8284","9.09923","0.04550"
"242.0000","4.8388","9.10428","0.04561"
"242.5000","4.8489","9.10725","0.04573"
"243.0000","4.8586","9.10483","0.04584"
"243.5000","4.8685","9.10525","0.04595"
"244.0000","4.8786","9.10732","0.04606"
"244.5000","4.8886","9.10842","0.04617"
"245.0000","4.8985","9.10788","0.04628"
"245.5000","4.9086","9.11069","0.04639"
"246.0000","4.9188","9.11403","0.04651"
"246.5000","4.9287","9.11405","0.04662"
"247.0000","4.9387","9.11457","0.04673"
"247.5000","4.9486","9.11667","0.04684"
"248.0000","4.9586","9.11809","0.04695"
"248.5000","4.9683","9.11534","0.04706"
"249.0000","4.9786","9.11857","0.04717"
"249.5000","4.9887","9.12107","0.04729"
"250.0000","4.9985","9.12111","0.04740"
"250.5000","5.0087","9.12381","0.04751"
"251.0000","5.0187","9.12489","0.04762"
"251.5000","5.0286","9.12603","0.04773"
"252.0000","5.0384","9.12489","0.04784"
"252.5000","5.0487","9.12860","0.04795"
"253.0000","5.0587","9.12953","0.04807"
"253.5000","5.0684","9.12806","0.04818"
"254.0000","5.0786","9.13032","0.04829"
"254.5000","5.0886","9.13234","0.04840"
"255.0000","5.0987","9.13468","0.04852"
"255.5000","5.1085","9.13249","0.04863"
"256.0000","5.1186","9.13543","0.04874"
"256.5000","5.1288","9.13940","0.04885"
"257.0000","5.1385","9.13659","0.04896"
"257.5000","5.1487","9.13967","0.04907"
"258.0000","5.1587","9.14021","0.04918"
"258.5000","5.1685","9.14011","0.04929"
"259.0000","5.1785","9.14058","0.04941"
"259.5000","5.1887","9.14297","0.04952"
"260.0000","5.1988","9.14640","0.04963"
"260.5000","5.2085","9.14513","0.04974"
"261.0000","5.2188","9.14829","0.04986"
"261.5000","5.2288","9.14928","0.04997"
"262.0000","5.2385","9.14780","0.05008"
"262.5000","5.2484","9.14769","0.05019"
"263.0000","5.2586","9.15027","0.05030"
"263.5000","5.2687","9.15244","0.05041"
"264.0000","5.2785","9.15117","0.05052"
"264.5000","5.2887","9.15479","0.05064"
"265.0000","5.2989","9.15875","0.05075"
"265.5000","5.3086","9.15673","0.05086"
"266.0000","5.3186","9.15644","0.05097"
"266.5000","5.3285","9.15712","0.05108"
"267.0000","5.3385","9.15923","0.05119"
"267.5000","5.3485","9.15887","0.05130"
"268.0000","5.3587","9.16125","0.05142"
"268.5000","5.3687","9.16397","0.05153"
"269.0000","5.3786","9.16406","0.05164"
"269.5000","5.3887","9.16461","0.05175"
"270.0000","5.3987","9.16661","0.05186"
"270.5000","5.4086","9.16724","0.05197"
"271.0000","5.4183","9.16406","0.05208"
"271.5000","5.4286","9.16813","0.05220"
"272.0000","5.4387","9.17067","0.05231"
"272.5000","5.4485","9.16996","0.05242"
"273.0000","5.4586","9.17209","0.05253"
"273.5000","5.4687","9.17377","0.05265"
"274.0000","5.4787","9.17456","0.05276"
"274.5000","5.4885","9.17289","0.05287"
"275.0000","5.4986","9.17549","0.05298"
"275.5000","5.5086","9.17800","0.05310"
"276.0000","5.5185","9.17635","0.05321"
"276.5000","5.5286","9.17785","0.05332"
"277.0000","5.5386","9.17913","0.05343"
"277.5000","5.5487","9.18174","0.05354"
"278.0000","5.5585","9.18023","0.05366"
"278.5000","5.5687","9.18276","0.05377"
"279.0000","5.5788","9.18540","0.05388"
"279.5000","5.5884","9.18244","0.05399"
"280.0000","5.5987","9.18637","0.05410"
"280.5000","5.6087","9.18643","0.05422"
"281.0000","5.6185","9.17090","0.05430"
"281.5000","5.6284","9.18203","0.05441"
"282.0000","5.6387","9.18876","0.05452"
"282.5000","5.6488","9.19319","0.05463"
"283.0000","5.6586","9.19194","0.05474"
"283.5000","5.6687","9.19337","0.05485"
"284.0000","5.6787","9.19518","0.05496"
"284.5000","5.6885","9.19391","0.05508"
"285.0000","5.6985","9.19299","0.05519"
"285.5000","5.7085","9.19455","0.05530"
"286.0000","5.7187","9.19790","0.05541"
"286.5000","5.7285","9.19608","0.05552"
"287.0000","5.7388","9.19941","0.05564"
"287.5000","5.7489","9.20189","0.05575"
"288.0000","5.7585","9.20034","0.05586"
"288.5000","5.7686","9.20007","0.05597"
"289.0000","5.7786","9.20074","0.05609"
"289.5000","5.7885","9.20163","0.05620"
"290.0000","5.7984","9.20101","0.05631"
"290.5000","5.8087","9.20459","0.05642"
"291.0000","5.8188","9.20669","0.05654"
"291.5000","5.8287","9.20617","0.05665"
"292.0000","5.8386","9.20603","0.05676"
"292.5000","5.8487","9.20889","0.05688"
"293.0000","5.8587","9.20909","0.05699"
"293.5000","5.8683","9.20561","0.05710"
"294.0000","5.8785","9.20861","0.05721"
"294.5000","5.8887","9.21197","0.05733"
"295.0000","5.8986","9.21125","0.05744"
"295.5000","5.9087","9.21284","0.05755"
"296.0000","5.9187","9.21347","0.05766"
"296.5000","5.9286","9.21499","0.05778"
"297.0000","5.9385","9.21321","0.05789"
"297.5000","5.9487","9.21598","0.05800"
"298.0000","5.9586","9.21679","0.05812"
"298.5000","5.9684","9.21521","0.05823"
"299.0000","5.9787","9.21742","0.05834"
"299.5000","5.9887","9.21841","0.05846"
"300.0000","5.9987","9.22060","0.05857"
"300.5000","6.0084","9.21822","0.05868"
"301.0000","6.0187","9.22150","0.05880"
"301.5000","6.0288","9.22350","0.05891"
"302.0000","6.0385","9.22092","0.05902"
"302.5000","6.0487","9.22384","0.05914"
"303.0000","6.0587","9.22474","0.05925"
"303.5000","6.0685","9.22354","0.05936"
"304.0000","6.0785","9.22325","0.05948"
"304.5000","6.0886","9.22539","0.05959"
"305.0000","6.0988","9.22975","0.05970"
"305.5000","6.1086","9.22775","0.05982"
"306.0000","6.1187","9.22905","0.05993"
"306.5000","6.1287","9.22991","0.06004"
"307.0000","6.1385","9.22984","0.06015"
"307.5000","6.1485","9.22866","0.06027"
"308.0000","6.1585","9.23013","0.06038"
"308.5000","6.1686","9.23193","0.06050"
"309.0000","6.1784","9.23038","0.06061"
"309.5000","6.1888","9.23534","0.06072"
"310.0000","6.1989","9.23729","0.06084"
"310.5000","6.2085","9.23439","0.06095"
"311.0000","6.2185","9.23407","0.06107"
"311.5000","6.2286","9.23543","0.06118"
"312.0000","6.2386","9.23699","0.06129"
"312.5000","6.2484","9.23547","0.06141"
"313.0000","6.2586","9.23757","0.06152"
"313.5000","6.2687","9.24065","0.06164"
"314.0000","6.2787","9.24046","0.06175"
"314.5000","6.2887","9.24068","0.06186"
"315.0000","6.2986","9.24154","0.06198"
"315.5000","6.3086","9.24243","0.06209"
"316.0000","6.3184","9.23953","0.06220"
"316.5000","6.3286","9.24197","0.06232"
"317.0000","6.3387","9.24463","0.06244"
"317.5000","6.3485","9.24334","0.06255"
"318.0000","6.3587","9.24564","0.06266"
"318.5000","6.3688","9.24632","0.06278"
"319.0000","6.3787","9.24715","0.06289"
"319.5000","6.3884","9.24511","0.06300"
"320.0000","6.3987","9.24818","0.06312"
"320.5000","6.4087","9.24928","0.06323"
"321.0000","6.4185","9.24711","0.06335"
"321.5000","6.4286","9.24852","0.06347"
"322.0000","6.4387","9.25040","0.06358"
"322.5000","6.4487","9.25181","0.06370"
"323.0000","6.4585","9.24925","0.06381"
"323.5000","6.4686","9.25187","0.06392"
"324.0000","6.4788","9.25545","0.06404"
"324.5000","6.4885","9.25191","0.06415"
"325.0000","6.4987","9.25440","0.06427"
"325.5000","6.5086","9.25406","0.06439"
"326.0000","6.5185","9.25362","0.06450"
"326.5000","6.5285","9.25371","0.06461"
"327.0000","6.5387","9.25539","0.06473"
"327.5000","6.5488","9.25833","0.06484"
"328.0000","6.5585","9.25649","0.06496"
"328.5000","6.5688","9.25943","0.06508"
"329.0000","6.5787","9.25957","0.06519"
"329.5000","6.5885","9.25810","0.06531"
"330.0000","6.5984","9.25699","0.06542"
"330.5000","6.6085","9.25928","0.06554"
"331.0000","6.6187","9.26101","0.06565"
"331.5000","6.6285","9.25915","0.06577"
"332.0000","6.6387","9.26228","0.06588"
"332.5000","6.6489","9.26578","0.06600"
"333.0000","6.6586","9.26340","0.06611"
"333.5000","6.6685","9.26209","0.06623"
"334.0000","6.6786","9.26272","0.06635"
"334.5000","6.6885","9.26398","0.06646"
"335.0000","6.6985","9.26300","0.06658"
"335.5000","6.7087","9.26511","0.06669"
"336.0000","6.7187","9.26738","0.06681"
"336.5000","6.7286","9.26688","0.06692"
"337.0000","6.7387","9.26684","0.06704"
"337.5000","6.7487","9.26844","0.06716"
"338.0000","6.7586","9.26825","0.06727"
"338.5000","6.7683","9.26452","0.06739"
"339.0000","6.7786","9.26832","0.06750"
"339.5000","6.7888","9.27025","0.06762"
"340.0000","6.7986","9.26875","0.06774"
"340.5000","6.8086","9.27030","0.06785"
"341.0000","6.8187","9.27166","0.06797"
"341.5000","6.8287","9.27226","0.06808"
"342.0000","6.8385","9.26973","0.06820"
"342.5000","6.8486","9.27150","0.06831"
"343.0000","6.8587","9.27407","0.06843"
"343.5000","6.8685","9.27197","0.06855"
"344.0000","6.8786","9.27295","0.06866"
"344.5000","6.8886","9.27369","0.06878"
"345.0000","6.8987","9.27591","0.06890"
"345.5000","6.9085","9.27379","0.06901"
"346.0000","6.9187","9.27558","0.06913"
"346.5000","6.9288","9.27770","0.06925"
"347.0000","6.9384","9.27447","0.06937"
"347.5000","6.9487","9.27802","0.06948"
"348.0000","6.9587","9.27758","0.06960"
"348.5000","6.9685","9.27634","0.06972"
"349.0000","6.9784","9.27576","0.06983"
"349.5000","6.9887","9.27866","0.06995"
"350.0000","6.9988","9.28090","0.07007"
"350.5000","7.0086","9.27913","0.07018"
"351.0000","7.0187","9.28061","0.07030"
"351.5000","7.0287","9.28138","0.07042"
"352.0000","7.0386","9.28013","0.07054"
"352.5000","7.0485","9.27861","0.07065"
"353.0000","7.0585","9.28005","0.07077"
"353.5000","7.0687","9.28280","0.07089"
"354.0000","7.0785","9.28062","0.07101"
"354.5000","7.0888","9.28345","0.07112"
"355.0000","7.0989","9.28559","0.07124"
"355.5000","7.1085","9.28314","0.07136"
"356.0000","7.1186","9.28285","0.07148"
"356.5000","7.1286","9.28306","0.07160"
"357.0000","7.1385","9.28339","0.07171"
"357.5000","7.1484","9.28246","0.07183"
"358.0000","7.1587","9.28571","0.07195"
"358.5000","7.1688","9.28714","0.07207"
"359.0000","7.1787","9.28579","0.07218"
"359.5000","7.1886","9.28519","0.07230"
"360.0000","7.1987","9.28768","0.07242"
"360.5000","7.2086","9.28754","0.07253"
"361.0000","7.2183","9.28359","0.07265"
"361.5000","7.2285","9.28616","0.07277"
"362.0000","7.2387","9.28907","0.07289"
"362.5000","7.2486","9.28817","0.07301"
"363.0000","7.2587","9.28917","0.07313"
"363.5000","7.2687","9.28913","0.07324"
"364.0000","7.2786","9.29033","0.07336"
"364.5000","7.2885","9.28804","0.07348"
"365.0000","7.2987","9.29008","0.07360"
"365.5000","7.3086","9.29082","0.07371"
"366.0000","7.3184","9.28861","0.07383"
"366.5000","7.3287","9.29099","0.07395"
"367.0000","7.3387","9.29116","0.07407"
"367.5000","7.3487","9.29243","0.07419"
"368.0000","7.3585","9.28968","0.07431"
"368.5000","7.3687","9.29246","0.07443"
"369.0000","7.3788","9.29453","0.07455"
"369.5000","7.3884","9.29081","0.07466"
"370.0000","7.3986","9.29340","0.07478"
"370.5000","7.4087","9.29410","0.07490"
"371.0000","7.4185","9.29240","0.07502"
"371.5000","7.4285","9.29152","0.07514"
"372.0000","7.4386","9.29310","0.07526"
"372.5000","7.4488","9.29698","0.07538"
"373.0000","7.4586","9.29469","0.07550"
"373.5000","7.4687","9.29575","0.07562"
"374.0000","7.4787","9.29597","0.07574"
"374.5000","7.4885","9.29447","0.07585"
"375.0000","7.4985","9.29388","0.07598"
"375.5000","7.5086","9.29486","0.07610"
"376.0000","7.5187","9.29618","0.07621"
"376.5000","7.5284","9.29407","0.07633"
"377.0000","7.5388","9.29754","0.07645"
"377.5000","7.5489","9.29995","0.07657"
"378.0000","7.5585","9.29698","0.07669"
"378.5000","7.5685","9.29632","0.07681"
"379.0000","7.5786","9.29696","0.07693"
"379.5000","7.5886","9.29752","0.07705"
"380.0000","7.5985","9.29605","0.07717"
"380.5000","7.6086","9.29767","0.07729"
"381.0000","7.6188","9.30022","0.07741"
"381.5000","7.6287","9.29951","0.07753"
"382.0000","7.6387","9.29858","0.07765"
"382.5000","7.6487","9.29947","0.07777"
"383.0000","7.6586","9.29986","0.07789"
"383.5000","7.6684","9.29625","0.07801"
"384.0000","7.6786","9.29847","0.07813"
"384.5000","7.6887","9.30040","0.07825"
"385.0000","7.6985","9.29915","0.07837"
"385.5000","7.7087","9.30081","0.07850"
"386.0000","7.7188","9.30119","0.07862"
"386.5000","7.7286","9.30128","0.07874"
"387.0000","7.7384","9.29906","0.07886"
"387.5000","7.7487","9.30162","0.07898"
"388.0000","7.7587","9.30210","0.07910"
"388.5000","7.7685","9.29955","0.07922"
"389.0000","7.7786","9.30038","0.07934"
"389.5000","7.7887","9.30179","0.07946"
"390.0000","7.7987","9.30268","0.07958"
"390.5000","7.8085","9.29991","0.07970"
"391.0000","7.8186","9.30196","0.07983"
"391.5000","7.8288","9.30440","0.07995"
"392.0000","7.8385","9.30088","0.08007"
"392.5000","7.8487","9.30304","0.08019"
"393.0000","7.8587","9.30265","0.08031"
"393.5000","7.8685","9.30172","0.08043"
"394.0000","7.8785","9.30113","0.08055"
"394.5000","7.8886","9.30257","0.08068"
"395.0000","7.8988","9.30527","0.08080"
"395.5000","7.9085","9.30291","0.08092"
"396.0000","7.9188","9.30475","0.08104"
"396.5000","7.9288","9.30490","0.08116"
"397.0000","7.9385","9.30255","0.08128"
"397.5000","7.9484","9.30132","0.08140"
"398.0000","7.9586","9.30316","0.08153"
"398.5000","7.9687","9.30479","0.08165"
"399.0000","7.9785","9.30194","0.08177"
"399.5000","7.9887","9.30443","0.08190"
"400.0000","7.9989","9.30767","0.08202"
"400.5000","8.0086","9.30504","0.08214"
"401.0000","8.0186","9.30348","0.08226"
"401.5000","8.0285","9.30321","0.08238"
"402.0000","8.0385","9.30422","0.08250"
"402.5000","8.0485","9.30302","0.08263"
"403.0000","8.0587","9.30477","0.08275"
"403.5000","8.0687","9.30633","0.08288"
"404.0000","8.0786","9.30544","0.08300"
"404.5000","8.0887","9.30497","0.08312"
"405.0000","8.0988","9.30636","0.08324"
"405.5000","8.1086","9.30544","0.08337"
"406.0000","8.1183","9.30163","0.08349"
"406.5000","8.1286","9.30487","0.08361"
"407.0000","8.1387","9.30635","0.08374"
"407.5000","8.1485","9.30453","0.08386"
"408.0000","8.1586","9.30578","0.08398"
"408.5000","8.1687","9.30674","0.08411"
"409.0000","8.1787","9.30673","0.08423"
"409.5000","8.1885","9.30403","0.08435"
"410.0000","8.1986","9.30563","0.08448"
"410.5000","8.2087","9.30678","0.08460"
"411.0000","8.2185","9.30433","0.08473"
"411.5000","8.2286","9.30510","0.08485"
"412.0000","8.2387","9.30557","0.08497"
"412.5000","8.2487","9.30730","0.08510"
"413.0000","8.2585","9.30441","0.08522"
"413.5000","8.2687","9.30594","0.08535"
"414.0000","8.2787","9.30731","0.08547"
"414.5000","8.2884","9.30434","0.08559"
"415.0000","8.2988","9.30733","0.08572"
"415.5000","8.3087","9.30630","0.08585"
"416.0000","8.3184","9.30417","0.08597"
"416.5000","8.3284","9.30392","0.08609"
"417.0000","8.3387","9.30640","0.08622"
"417.5000","8.3489","9.30878","0.08635"
"418.0000","8.3586","9.30567","0.08647"
"418.5000","8.3687","9.30616","0.08659"
"419.0000","8.3787","9.30719","0.08672"
"419.5000","8.3886","9.30604","0.08684"
"420.0000","8.3985","9.30374","0.08697"
"420.5000","8.4085","9.30444","0.08709"
"421.0000","8.4186","9.30631","0.08722"
"421.5000","8.4285","9.30399","0.08734"
"422.0000","8.4388","9.30729","0.08747"
"422.5000","8.4489","9.30864","0.08759"
"423.0000","8.4585","9.30570","0.08772"
"423.5000","8.4686","9.30489","0.08784"
"424.0000","8.4786","9.30455","0.08797"
"424.5000","8.4886","9.30533","0.08810"
"425.0000","8.4984","9.30340","0.08822"
"425.5000","8.5087","9.30574","0.08835"
"426.0000","8.5188","9.30687","0.08848"
"426.5000","8.5287","9.30575","0.08860"
"427.0000","8.5386","9.30523","0.08873"
"427.5000","8.5487","9.30651","0.08885"
"428.0000","8.5586","9.30568","0.08898"
"428.5000","8.5683","9.30162","0.08910"
"429.0000","8.5785","9.30371","0.08923"
"429.5000","8.5888","9.30702","0.08936"
"430.0000","8.5986","9.30452","0.08948"
"430.5000","8.6087","9.30516","0.08961"
"431.0000","8.6187","9.30549","0.08974"
"431.5000","8.6287","9.30635","0.08987"
"432.0000","8.6385","9.30363","0.08999"
"432.5000","8.6487","9.30466","0.09012"
"433.0000","8.6586","9.30491","0.09025"
"433.5000","8.6684","9.30255","0.09037"
"434.0000","8.6787","9.30432","0.09050"
"434.5000","8.6887","9.30427","0.09063"
"435.0000","8.6987","9.30493","0.09076"
"435.5000","8.7084","9.30178","0.09088"
"436.0000","8.7187","9.30461","0.09101"
"436.5000","8.7289","9.30645","0.09114"
"437.0000","8.7384","9.30156","0.09127"
"437.5000","8.7486","9.30414","0.09140"
"438.0000","8.7587","9.30411","0.09152"
"438.5000","8.7685","9.30218","0.09165"
"439.0000","8.7785","9.30128","0.09178"
"439.5000","8.7886","9.30214","0.09191"
"440.0000","8.7988","9.30550","0.09204"
"440.5000","8.8086","9.30262","0.09217"
"441.0000","8.8187","9.30346","0.09230"
"441.5000","8.8287","9.30337","0.09242"
"442.0000","8.8385","9.30165","0.09255"
"442.5000","8.8485","9.30054","0.09268"
"443.0000","8.8586","9.30063","0.09281"
"443.5000","8.8687","9.30191","0.09294"
"444.0000","8.8784","9.29951","0.09307"
"444.5000","8.8888","9.30301","0.09320"
"445.0000","8.8989","9.30435","0.09333"
"445.5000","8.9086","9.30099","0.09345"
"446.0000","8.9185","9.29965","0.09358"
"446.5000","8.9286","9.30066","0.09371"
"447.0000","8.9386","9.30023","0.09384"
"447.5000","8.9484","9.29812","0.09397"
"448.0000","8.9586","9.29932","0.09410"
"448.5000","8.9688","9.30202","0.09423"
"449.0000","8.9787","9.30045","0.09436"
"449.5000","8.9887","9.29929","0.09449"
"450.0000","8.9987","9.30004","0.09462"
"450.5000","9.0086","9.29987","0.09475"
"451.0000","9.0184","9.29599","0.09488"
"451.5000","9.0286","9.29789","0.09501"
"452.0000","9.0387","9.29898","0.09514"
"452.5000","9.0485","9.29720","0.09527"
"453.0000","9.0587","9.29869","0.09540"
"453.5000","9.0687","9.29853","0.09553"
"454.0000","9.0786","9.29826","0.09566"
"454.5000","9.0884","9.29556","0.09579"
"455.0000","9.0987","9.29780","0.09592"
"455.5000","9.1087","9.29753","0.09605"
"456.0000","9.1185","9.29454","0.09618"
"456.5000","9.1286","9.29516","0.09632"
"457.0000","9.1386","9.29627","0.09645"
"457.5000","9.1487","9.29677","0.09658"
"458.0000","9.1585","9.29345","0.09671"
"458.5000","9.1686","9.29482","0.09684"
"459.0000","9.1788","9.29715","0.09698"
"459.5000","9.1885","9.29331","0.09711"
"460.0000","9.1987","9.29480","0.09724"
"460.5000","9.2087","9.29400","0.09737"
"461.0000","9.2185","9.29252","0.09750"
"461.5000","9.2285","9.29159","0.09764"
"462.0000","9.2387","9.29224","0.09777"
"462.5000","9.2488","9.29423","0.09790"
"463.0000","9.2585","9.29176","0.09803"
"463.5000","9.2687","9.29320","0.09817"
"464.0000","9.2787","9.29287","0.09830"
"464.5000","9.2885","9.29045","0.09843"
"465.0000","9.2984","9.28836","0.09857"
"465.5000","9.3086","9.28990","0.09870"
"466.0000","9.3187","9.29067","0.09884"
"466.5000","9.3285","9.28758","0.09897"
"467.0000","9.3387","9.29002","0.09911"
"467.5000","9.3489","9.29249","0.09924"
"468.0000","9.3586","9.28928","0.09938"
"468.5000","9.3686","9.28719","0.09951"
"469.0000","9.3786","9.28636","0.09965"
"469.5000","9.3885","9.28708","0.09978"
"470.0000","9.3985","9.28529","0.09992"
"470.5000","9.4087","9.28656","0.10006"
"471.0000","9.4187","9.28716","0.10019"
"471.5000","9.4286","9.28584","0.10033"
"472.0000","9.4387","9.28540","0.10046"
"472.5000","9.4487","9.28573","0.10060"
"473.0000","9.4586","9.28469","0.10074"
"473.5000","9.4683","9.28014","0.10087"
"474.0000","9.4786","9.28282","0.10101"
"474.5000","9.4887","9.28354","0.10115"
"475.0000","9.4985","9.28144","0.10129"
"475.5000","9.5086","9.28215","0.10143"
"476.0000","9.5188","9.28246","0.10157"
"476.5000","9.5287","9.28168","0.10171"
"477.0000","9.5385","9.27830","0.10184"
"477.5000","9.5486","9.27937","0.10199"
"478.0000","9.5586","9.28025","0.10213"
"478.5000","9.5685","9.27705","0.10227"
"479.0000","9.5787","9.27750","0.10241"
"479.5000","9.5886","9.27689","0.10255"
"480.0000","9.5987","9.27794","0.10269"
"480.5000","9.6085","9.27467","0.10284"
"481.0000","9.6187","9.27567","0.10298"
"481.5000","9.6288","9.27672","0.10312"
"482.0000","9.6384","9.27219","0.10326"
"482.5000","9.6487","9.27436","0.10341"
"483.0000","9.6587","9.27304","0.10356"
"483.5000","9.6685","9.27048","0.10370"
"484.0000","9.6784","9.26901","0.10385"
"484.5000","9.6887","9.27037","0.10400"
"485.0000","9.6988","9.27202","0.10414"
"485.5000","9.7086","9.26820","0.10429"
"486.0000","9.7187","9.26805","0.10444"
"486.5000","9.7287","9.26859","0.10459"
"487.0000","9.7385","9.26525","0.10474"
"487.5000","9.7485","9.26314","0.10489"
"488.0000","9.7585","9.26317","0.10504"
"488.5000","9.7687","9.26413","0.10519"
"489.0000","9.7785","9.26050","0.10535"
"489.5000","9.7888","9.26214","0.10551"
"490.0000","9.7989","9.26276","0.10566"
"490.5000","9.8085","9.25882","0.10581"
"491.0000","9.8186","9.25703","0.10597"
"491.5000","9.8286","9.25546","0.10613"
"492.0000","9.8385","9.25433","0.10629"
"492.5000","9.8484","9.25198","0.10645"
"493.0000","9.8587","9.25272","0.10661"
"493.5000","9.8688","9.25272","0.10677"
"494.0000","9.8787","9.25010","0.10693"
"494.5000","9.8886","9.24754","0.10710"
"495.0000","9.8987","9.24799","0.10726"
"495.5000","9.9086","9.24578","0.10743"
"496.0000","9.9183","9.23966","0.10759"
"496.5000","9.9285","9.24010","0.10776"
"497.0000","9.9387","9.24124","0.10793"
"497.5000","9.9486","9.23762","0.10810"
"498.0000","9.9587","9.23629","0.10828"
"498.5000","9.9687","9.23421","0.10845"
"499.0000","9.9786","9.23284","0.10862"
"499.5000","9.9885","9.22819","0.10879"
"500.0000","9.9987","9.22700","0.10897"
"500.5000","10.0086","9.22540","0.10915"
"501.0000","10.0184","9.22077","0.10932"
"501.5000","10.0287","9.21956","0.10950"
"502.0000","10.0387","9.21687","0.10968"
"502.5000","10.0487","9.21520","0.10987"
"503.0000","10.0584","9.20936","0.11005"
"503.5000","10.0687","9.20945","0.11023"
"504.0000","10.0788","9.20742","0.11042"
"504.5000","10.0884","9.19999","0.11060"
"505.0000","10.0986","9.19927","0.11079"
"505.5000","10.1087","9.19617","0.11098"
"506.0000","10.1186","9.19076","0.11116"
"506.5000","10.1285","9.18559","0.11136"
"507.0000","10.1386","9.18277","0.11155"
"507.5000","10.1488","9.18248","0.11174"
"508.0000","10.1586","9.17594","0.11193"
"508.5000","10.1687","9.17191","0.11212"
"509.0000","10.1787","9.16783","0.11232"
"509.5000","10.1885","9.16162","0.11251"
"510.0000","10.1985","9.15543","0.11270"
"510.5000","10.2086","9.15089","0.11290"
"511.0000","10.2187","9.14755","0.11310"
"511.5000","10.2284","9.13986","0.11330"
"512.0000","10.2388","9.13749","0.11350"
"512.5000","10.2489","9.13352","0.11370"
"513.0000","10.2586","9.12470","0.11390"
"513.5000","10.2685","9.11740","0.11410"
"514.0000","10.2786","9.11186","0.11430"
"514.5000","10.2886","9.10533","0.11450"
"515.0000","10.2985","9.09669","0.11470"
"515.5000","10.3086","9.09169","0.11490"
"516.0000","10.3188","9.08752","0.11511"
"516.5000","10.3287","9.07843","0.11531"
"517.0000","10.3386","9.06984","0.11552"
"517.5000","10.3487","9.06370","0.11572"
"518.0000","10.3586","9.05609","0.11593"
"518.5000","10.3684","9.04370","0.11614"
"519.0000","10.3786","9.03712","0.11634"
"519.5000","10.3887","9.02982","0.11655"
"520.0000","10.3985","9.02036","0.11676"
"520.5000","10.4087","9.01251","0.11697"
"521.0000","10.4187","9.00279","0.11718"
"521.5000","10.4286","8.99409","0.11739"
"522.0000","10.4384","8.98171","0.11760"
"522.5000","10.4487","8.97412","0.11781"
"523.0000","10.4587","8.96397","0.11802"
"523.5000","10.4685","8.95073","0.11823"
"524.0000","10.4786","8.94051","0.11844"
"524.5000","10.4887","8.93106","0.11866"
"525.0000","10.4987","8.92101","0.11887"
"525.5000","10.5085","8.90625","0.11908"
"526.0000","10.5186","8.89596","0.11929"
"526.5000","10.5287","8.88710","0.11951"
"527.0000","10.5385","8.87138","0.11972"
"527.5000","10.5487","8.86038","0.11994"
"528.0000","10.5586","8.84686","0.12015"
"528.5000","10.5684","8.83284","0.12037"
"529.0000","10.5785","8.81827","0.12059"
"529.5000","10.5887","8.80612","0.12080"
"530.0000","10.5988","8.79555","0.12102"
"530.5000","10.6085","8.77876","0.12123"
"531.0000","10.6187","8.76502","0.12145"
"531.5000","10.6287","8.75066","0.12167"
"532.0000","10.6386","8.73454","0.12189"
"532.5000","10.6484","8.71678","0.12211"
"533.0000","10.6585","8.70283","0.12233"
"533.5000","10.6687","8.68749","0.12255"
"534.0000","10.6785","8.66911","0.12276"
"534.5000","10.6888","8.65619","0.12299"
"535.0000","10.6989","8.64155","0.12321"
"535.5000","10.7086","8.62126","0.12343"
"536.0000","10.7186","8.60165","0.12365"
"536.5000","10.7285","8.58348","0.12387"
"537.0000","10.7386","8.56775","0.12409"
"537.5000","10.7485","8.54567","0.12432"
"538.0000","10.7587","8.52762","0.12455"
"538.5000","10.7687","8.51024","0.12477"
"539.0000","10.7786","8.48978","0.12499"
"539.5000","10.7887","8.46865","0.12522"
"540.0000","10.7987","8.44862","0.12545"
"540.5000","10.8086","8.42734","0.12567"
"541.0000","10.8183","8.40108","0.12590"
"541.5000","10.8286","8.38071","0.12613"
"542.0000","10.8388","8.35945","0.12636"
"542.5000","10.8485","8.33413","0.12659"
"543.0000","10.8586","8.31004","0.12682"
"543.5000","10.8688","8.28528","0.12705"
"544.0000","10.8787","8.26066","0.12728"
"544.5000","10.8885","8.23002","0.12752"
"545.0000","10.8986","8.20321","0.12775"
"545.5000","10.9087","8.17700","0.12799"
"546.0000","10.9185","8.14461","0.12823"
"546.5000","10.9287","8.11431","0.12847"
"547.0000","10.9386","8.08300","0.12871"
"547.5000","10.9487","8.05094","0.12895"
"548.0000","10.9585","8.01073","0.12920"
"548.5000","10.9687","7.97307","0.12945"
"549.0000","10.9788","7.93110","0.12970"
"549.5000","10.9884","7.87735","0.12996"
"550.0000","10.9987","7.81382","0.13025"
"550.5000","11.0087","7.69680","0.13061"
"550.9680","11.0179","7.45882","0.13110"
"551.2150","11.0231","7.08672","0.13171"
"551.4490","11.0277","6.71391","0.13229"
"551.4580","11.0279","6.16835","0.13306"
"551.4620","11.0281","5.55386","0.13423"