File: Coupon Test Data/Tensile Test_Neebajan_Alan_20.csv
Time,Displacement,Force,Strain 1
(s),(mm),(kN),(mm/mm)
"0.0000","0.0000","0.17086","-0.00017"
"0.4000","0.0066","0.24121","-0.00013"
"0.8000","0.0142","0.32737","-0.00008"
"1.2000","0.0223","0.41661","-0.00004"
"1.6000","0.0304","0.50458","0.00001"
"2.0000","0.0385","0.58637","0.00005"
"2.4000","0.0464","0.66982","0.00010"
"2.8000","0.0545","0.75165","0.00015"
"3.2000","0.0627","0.83574","0.00019"
"3.6000","0.0702","0.91076","0.00023"
"4.0000","0.0784","0.99104","0.00027"
"4.4000","0.0865","1.07115","0.00032"
"4.8000","0.0944","1.14778","0.00036"
"5.2000","0.1024","1.22341","0.00040"
"5.6000","0.1105","1.29696","0.00044"
"6.0000","0.1186","1.37257","0.00048"
"6.4000","0.1263","1.44330","0.00051"
"6.8000","0.1345","1.50781","0.00055"
"7.2000","0.1425","1.58015","0.00059"
"7.6000","0.1504","1.64997","0.00063"
"8.0000","0.1583","1.71881","0.00066"
"8.4000","0.1666","1.78990","0.00070"
"8.8000","0.1746","1.85846","0.00074"
"9.2000","0.1823","1.92199","0.00077"
"9.6000","0.1905","1.98202","0.00081"
"10.0000","0.1984","2.04852","0.00084"
"10.4000","0.2064","2.11343","0.00088"
"10.8000","0.2144","2.17771","0.00091"
"11.2000","0.2226","2.24219","0.00095"
"11.6000","0.2306","2.30517","0.00098"
"12.0000","0.2382","2.35743","0.00101"
"12.4000","0.2465","2.42158","0.00104"
"12.8000","0.2545","2.48339","0.00108"
"13.2000","0.2624","2.54107","0.00111"
"13.6000","0.2703","2.59871","0.00114"
"14.0000","0.2786","2.65355","0.00117"
"14.4000","0.2865","2.71167","0.00120"
"14.8000","0.2943","2.76671","0.00123"
"15.2000","0.3026","2.82601","0.00127"
"15.6000","0.3105","2.87708","0.00130"
"16.0000","0.3184","2.93063","0.00133"
"16.4000","0.3263","2.98637","0.00136"
"16.8000","0.3346","3.04127","0.00139"
"17.2000","0.3426","3.09338","0.00142"
"17.6000","0.3503","3.13792","0.00144"
"18.0000","0.3585","3.19225","0.00147"
"18.4000","0.3664","3.24438","0.00150"
"18.8000","0.3744","3.29591","0.00153"
"19.2000","0.3824","3.34703","0.00156"
"19.6000","0.3906","3.39520","0.00159"
"20.0000","0.3985","3.44592","0.00162"
"20.4000","0.4063","3.49538","0.00165"
"20.8000","0.4146","3.54862","0.00168"
"21.2000","0.4224","3.59220","0.00171"
"21.6000","0.4304","3.64359","0.00174"
"22.0000","0.4384","3.69464","0.00177"
"22.4000","0.4465","3.74605","0.00180"
"22.8000","0.4545","3.79536","0.00183"
"23.2000","0.4624","3.84153","0.00186"
"23.6000","0.4706","3.89411","0.00190"
"24.0000","0.4784","3.94234","0.00192"
"24.4000","0.4864","3.99213","0.00196"
"24.8000","0.4943","4.03712","0.00199"
"25.2000","0.5026","4.08921","0.00202"
"25.6000","0.5105","4.13846","0.00205"
"26.0000","0.5185","4.18758","0.00208"
"26.4000","0.5266","4.23317","0.00211"
"26.8000","0.5343","4.28072","0.00214"
"27.2000","0.5424","4.33097","0.00218"
"27.6000","0.5504","4.37967","0.00221"
"28.0000","0.5585","4.42367","0.00224"
"28.4000","0.5664","4.47207","0.00227"
"28.8000","0.5745","4.52015","0.00231"
"29.2000","0.5826","4.56846","0.00234"
"29.6000","0.5904","4.60763","0.00237"
"30.0000","0.5985","4.65584","0.00241"
"30.4000","0.6064","4.70160","0.00244"
"30.8000","0.6145","4.74706","0.00248"
"31.2000","0.6224","4.78651","0.00251"
"31.6000","0.6305","4.83024","0.00255"
"32.0000","0.6387","4.87487","0.00259"
"32.4000","0.6464","4.91378","0.00263"
"32.8000","0.6544","4.95397","0.00267"
"33.2000","0.6624","4.98639","0.00271"
"33.6000","0.6705","5.02704","0.00275"
"34.0000","0.6784","5.06334","0.00279"
"34.4000","0.6865","5.09880","0.00284"
"34.8000","0.6946","5.13214","0.00289"
"35.2000","0.7024","5.16158","0.00294"
"35.6000","0.7105","5.18532","0.00298"
"36.0000","0.7184","5.21497","0.00304"
"36.4000","0.7266","5.24209","0.00309"
"36.8000","0.7343","5.26529","0.00315"
"37.2000","0.7424","5.28740","0.00322"
"37.6000","0.7506","5.31056","0.00329"
"38.0000","0.7584","5.32622","0.00335"
"38.4000","0.7665","5.34468","0.00342"
"38.8000","0.7744","5.35983","0.00349"
"39.2000","0.7824","5.37403","0.00356"
"39.6000","0.7903","5.38844","0.00364"
"40.0000","0.7985","5.40116","0.00372"
"40.4000","0.8066","5.40822","0.00379"
"40.8000","0.8145","5.42237","0.00387"
"41.2000","0.8225","5.42851","0.00394"
"41.6000","0.8303","5.43943","0.00401"
"42.0000","0.8385","5.44945","0.00410"
"42.4000","0.8464","5.45667","0.00418"
"42.8000","0.8545","5.46396","0.00427"
"43.2000","0.8625","5.47352","0.00435"
"43.6000","0.8704","5.47883","0.00444"
"44.0000","0.8786","5.48559","0.00452"
"44.4000","0.8864","5.49047","0.00461"
"44.8000","0.8945","5.49680","0.00469"
"45.2000","0.9024","5.49993","0.00476"
"45.6000","0.9104","5.50702","0.00485"
"46.0000","0.9185","5.51371","0.00493"
"46.4000","0.9265","5.51709","0.00502"
"46.8000","0.9346","5.52172","0.00511"
"47.2000","0.9424","5.52424","0.00519"
"47.6000","0.9505","5.53033","0.00528"
"48.0000","0.9583","5.53341","0.00537"
"48.4000","0.9665","5.53698","0.00546"
"48.8000","0.9746","5.54277","0.00555"
"49.2000","0.9825","5.54553","0.00563"
"49.6000","0.9905","5.54877","0.00572"
"50.0000","0.9983","5.55098","0.00581"
"50.4000","1.0065","5.55623","0.00590"
"50.8000","1.0144","5.55795","0.00599"
"51.2000","1.0225","5.56093","0.00608"
"51.6000","1.0305","5.56577","0.00617"
"52.0000","1.0385","5.56843","0.00626"
"52.4000","1.0465","5.57150","0.00635"
"52.8000","1.0544","5.57218","0.00644"
"53.2000","1.0626","5.57718","0.00653"
"53.6000","1.0704","5.57811","0.00662"
"54.0000","1.0784","5.58048","0.00671"
"54.4000","1.0865","5.58576","0.00680"
"54.8000","1.0945","5.58765","0.00689"
"55.2000","1.1025","5.58954","0.00699"
"55.6000","1.1104","5.59083","0.00708"
"56.0000","1.1185","5.59520","0.00717"
"56.4000","1.1263","5.58378","0.00725"
"56.8000","1.1345","5.59742","0.00733"
"57.2000","1.1425","5.60257","0.00742"
"57.6000","1.1506","5.60462","0.00752"
"58.0000","1.1585","5.60604","0.00761"
"58.4000","1.1664","5.60654","0.00770"
"58.8000","1.1746","5.61155","0.00779"
"59.2000","1.1824","5.61080","0.00788"
"59.6000","1.1905","5.61335","0.00798"
"60.0000","1.1984","5.61698","0.00807"
"60.4000","1.2064","5.61823","0.00816"
"60.8000","1.2146","5.62129","0.00825"
"61.2000","1.2225","5.62191","0.00835"
"61.6000","1.2306","5.62565","0.00844"
"62.0000","1.2384","5.62554","0.00854"
"62.4000","1.2465","5.62796","0.00863"
"62.8000","1.2544","5.63101","0.00872"
"63.2000","1.2625","5.63292","0.00882"
"63.6000","1.2705","5.63477","0.00891"
"64.0000","1.2785","5.63596","0.00900"
"64.4000","1.2865","5.63973","0.00910"
"64.8000","1.2942","5.63879","0.00919"
"65.2000","1.3025","5.64221","0.00929"
"65.6000","1.3105","5.64505","0.00938"
"66.0000","1.3185","5.64568","0.00947"
"66.4000","1.3265","5.64819","0.00957"
"66.8000","1.3345","5.64982","0.00966"
"67.2000","1.3425","5.65323","0.00975"
"67.6000","1.3504","5.65226","0.00985"
"68.0000","1.3585","5.65513","0.00994"
"68.4000","1.3664","5.65720","0.01003"
"68.8000","1.3744","5.65873","0.01013"
"69.2000","1.3825","5.66162","0.01022"
"69.6000","1.3906","5.65987","0.01030"
"70.0000","1.3986","5.66616","0.01039"
"70.4000","1.4063","5.66521","0.01048"
"70.8000","1.4146","5.66853","0.01058"
"71.2000","1.4223","5.66997","0.01067"
"71.6000","1.4304","5.67105","0.01076"
"72.0000","1.4386","5.67398","0.01085"
"72.4000","1.4466","5.67551","0.01095"
"72.8000","1.4544","5.67712","0.01104"
"73.2000","1.4623","5.67709","0.01113"
"73.6000","1.4706","5.68095","0.01123"
"74.0000","1.4784","5.68168","0.01132"
"74.4000","1.4864","5.68279","0.01141"
"74.8000","1.4945","5.68557","0.01151"
"75.2000","1.5026","5.68766","0.01160"
"75.6000","1.5105","5.68973","0.01169"
"76.0000","1.5184","5.68885","0.01179"
"76.4000","1.5266","5.69298","0.01188"
"76.8000","1.5343","5.69344","0.01197"
"77.2000","1.5423","5.69431","0.01206"
"77.6000","1.5505","5.69828","0.01216"
"78.0000","1.5586","5.70038","0.01225"
"78.4000","1.5665","5.70092","0.01234"
"78.8000","1.5744","5.70117","0.01243"
"79.2000","1.5826","5.70495","0.01253"
"79.6000","1.5903","5.70495","0.01262"
"80.0000","1.5984","5.70665","0.01271"
"80.4000","1.6065","5.70961","0.01280"
"80.8000","1.6146","5.71177","0.01290"
"81.2000","1.6224","5.71260","0.01299"
"81.6000","1.6304","5.71293","0.01308"
"82.0000","1.6387","5.71774","0.01318"
"82.4000","1.6463","5.71643","0.01326"
"82.8000","1.6544","5.71761","0.01336"
"83.2000","1.6626","5.70862","0.01344"
"83.6000","1.6705","5.72124","0.01352"
"84.0000","1.6784","5.72477","0.01361"
"84.4000","1.6865","5.72583","0.01370"
"84.8000","1.6947","5.72915","0.01379"
"85.2000","1.7023","5.72762","0.01388"
"85.6000","1.7104","5.72949","0.01397"
"86.0000","1.7185","5.73279","0.01407"
"86.4000","1.7266","5.73468","0.01416"
"86.8000","1.7344","5.73508","0.01425"
"87.2000","1.7425","5.73608","0.01434"
"87.6000","1.7507","5.74059","0.01443"
"88.0000","1.7582","5.73808","0.01452"
"88.4000","1.7664","5.74051","0.01461"
"88.8000","1.7746","5.74413","0.01471"
"89.2000","1.7825","5.74503","0.01480"
"89.6000","1.7903","5.74570","0.01489"
"90.0000","1.7985","5.74792","0.01498"
"90.4000","1.8067","5.75171","0.01507"
"90.8000","1.8143","5.74936","0.01516"
"91.2000","1.8224","5.75199","0.01525"
"91.6000","1.8305","5.75464","0.01534"
"92.0000","1.8385","5.75604","0.01543"
"92.4000","1.8463","5.75724","0.01553"
"92.8000","1.8546","5.75915","0.01562"
"93.2000","1.8627","5.76288","0.01571"
"93.6000","1.8702","5.76005","0.01580"
"94.0000","1.8784","5.76280","0.01589"
"94.4000","1.8865","5.76600","0.01598"
"94.8000","1.8945","5.76722","0.01607"
"95.2000","1.9024","5.76783","0.01616"
"95.6000","1.9106","5.77062","0.01625"
"96.0000","1.9186","5.77332","0.01634"
"96.4000","1.9262","5.77116","0.01643"
"96.8000","1.9345","5.77481","0.01652"
"97.2000","1.9425","5.77654","0.01661"
"97.6000","1.9505","5.77754","0.01670"
"98.0000","1.9583","5.77870","0.01679"
"98.4000","1.9665","5.78148","0.01689"
"98.8000","1.9747","5.78496","0.01698"
"99.2000","1.9823","5.78201","0.01707"
"99.6000","1.9905","5.78522","0.01716"
"100.0000","1.9985","5.78763","0.01724"
"100.4000","2.0064","5.78802","0.01734"
"100.8000","2.0144","5.78981","0.01743"
"101.2000","2.0226","5.79296","0.01752"
"101.6000","2.0306","5.79486","0.01761"
"102.0000","2.0383","5.79304","0.01770"
"102.4000","2.0465","5.79651","0.01779"
"102.8000","2.0544","5.79774","0.01788"
"103.2000","2.0625","5.79934","0.01797"
"103.6000","2.0704","5.80016","0.01806"
"104.0000","2.0786","5.80303","0.01815"
"104.4000","2.0866","5.80539","0.01824"
"104.8000","2.0943","5.80343","0.01833"
"105.2000","2.1026","5.80781","0.01842"
"105.6000","2.1105","5.80851","0.01851"
"106.0000","2.1184","5.80906","0.01860"
"106.4000","2.1264","5.81093","0.01868"
"106.8000","2.1345","5.81374","0.01878"
"107.2000","2.1425","5.81565","0.01886"
"107.6000","2.1504","5.81475","0.01895"
"108.0000","2.1586","5.81805","0.01904"
"108.4000","2.1664","5.81843","0.01913"
"108.8000","2.1744","5.81958","0.01922"
"109.2000","2.1823","5.82121","0.01931"
"109.6000","2.1906","5.82422","0.01940"
"110.0000","2.1985","5.82567","0.01949"
"110.4000","2.2064","5.82502","0.01958"
"110.8000","2.2146","5.82878","0.01967"
"111.2000","2.2223","5.82877","0.01976"
"111.6000","2.2304","5.83026","0.01985"
"112.0000","2.2384","5.83195","0.01993"
"112.4000","2.2466","5.83436","0.02002"
"112.8000","2.2544","5.83524","0.02011"
"113.2000","2.2624","5.83571","0.02020"
"113.6000","2.2706","5.83961","0.02029"
"114.0000","2.2784","5.83866","0.02038"
"114.4000","2.2865","5.84040","0.02047"
"114.8000","2.2944","5.84166","0.02056"
"115.2000","2.3025","5.84419","0.02065"
"115.6000","2.3104","5.84613","0.02073"
"116.0000","2.3185","5.83718","0.02080"
"116.4000","2.3267","5.84853","0.02089"
"116.8000","2.3344","5.84922","0.02097"
"117.2000","2.3424","5.85082","0.02106"
"117.6000","2.3504","5.85292","0.02115"
"118.0000","2.3585","5.85477","0.02124"
"118.4000","2.3664","5.85539","0.02132"
"118.8000","2.3745","5.85668","0.02141"
"119.2000","2.3826","5.85913","0.02150"
"119.6000","2.3904","5.85874","0.02159"
"120.0000","2.3985","5.86085","0.02168"
"120.4000","2.4064","5.86112","0.02177"
"120.8000","2.4146","5.86428","0.02186"
"121.2000","2.4224","5.86473","0.02194"
"121.6000","2.4305","5.86572","0.02203"
"122.0000","2.4386","5.86997","0.02212"
"122.4000","2.4464","5.86833","0.02221"
"122.8000","2.4545","5.87023","0.02230"
"123.2000","2.4624","5.87095","0.02238"
"123.6000","2.4704","5.87300","0.02248"
"124.0000","2.4784","5.87498","0.02256"
"124.4000","2.4865","5.87610","0.02265"
"124.8000","2.4946","5.87835","0.02274"
"125.2000","2.5025","5.87839","0.02283"
"125.6000","2.5105","5.87978","0.02292"
"126.0000","2.5183","5.88017","0.02300"
"126.4000","2.5265","5.88369","0.02309"
"126.8000","2.5344","5.88366","0.02318"
"127.2000","2.5425","5.88540","0.02327"
"127.6000","2.5506","5.88848","0.02336"
"128.0000","2.5583","5.88737","0.02344"
"128.4000","2.5666","5.89033","0.02353"
"128.8000","2.5744","5.89034","0.02362"
"129.2000","2.5825","5.89217","0.02371"
"129.6000","2.5904","5.89366","0.02380"
"130.0000","2.5984","5.89457","0.02389"
"130.4000","2.6065","5.89770","0.02397"
"130.8000","2.6145","5.89799","0.02406"
"131.2000","2.6225","5.89938","0.02415"
"131.6000","2.6304","5.89924","0.02424"
"132.0000","2.6385","5.90225","0.02433"
"132.4000","2.6463","5.90253","0.02441"
"132.8000","2.6546","5.90473","0.02450"
"133.2000","2.6626","5.90693","0.02459"
"133.6000","2.6704","5.90660","0.02468"
"134.0000","2.6786","5.90895","0.02477"
"134.4000","2.6863","5.90857","0.02485"
"134.8000","2.6945","5.91170","0.02494"
"135.2000","2.7024","5.91186","0.02503"
"135.6000","2.7105","5.91320","0.02512"
"136.0000","2.7185","5.91611","0.02521"
"136.4000","2.7264","5.91653","0.02529"
"136.8000","2.7346","5.91864","0.02538"
"137.2000","2.7424","5.91814","0.02547"
"137.6000","2.7505","5.92063","0.02556"
"138.0000","2.7584","5.92063","0.02565"
"138.4000","2.7665","5.92226","0.02573"
"138.8000","2.7745","5.92555","0.02582"
"139.2000","2.7825","5.92597","0.02591"
"139.6000","2.7906","5.92699","0.02599"
"140.0000","2.7983","5.92657","0.02608"
"140.4000","2.8065","5.92981","0.02617"
"140.8000","2.8143","5.93009","0.02626"
"141.2000","2.8225","5.93179","0.02635"
"141.6000","2.8306","5.91569","0.02642"
"142.0000","2.8386","5.93116","0.02650"
"142.4000","2.8465","5.93619","0.02658"
"142.8000","2.8543","5.93637","0.02666"
"143.2000","2.8626","5.94033","0.02675"
"143.6000","2.8704","5.93929","0.02684"
"144.0000","2.8785","5.94033","0.02693"
"144.4000","2.8865","5.94305","0.02701"
"144.8000","2.8944","5.94348","0.02710"
"145.2000","2.9025","5.94545","0.02719"
"145.6000","2.9104","5.94493","0.02728"
"146.0000","2.9186","5.94761","0.02737"
"146.4000","2.9264","5.94724","0.02745"
"146.8000","2.9345","5.94856","0.02754"
"147.2000","2.9424","5.95106","0.02762"
"147.6000","2.9506","5.95266","0.02771"
"148.0000","2.9585","5.95325","0.02780"
"148.4000","2.9664","5.95317","0.02789"
"148.8000","2.9745","5.95656","0.02797"
"149.2000","2.9822","5.95500","0.02806"
"149.6000","2.9905","5.95757","0.02815"
"150.0000","2.9985","5.95969","0.02824"
"150.4000","3.0065","5.96018","0.02833"
"150.8000","3.0145","5.96175","0.02841"
"151.2000","3.0224","5.96196","0.02850"
"151.6000","3.0306","5.96521","0.02858"
"152.0000","3.0384","5.96392","0.02867"
"152.4000","3.0465","5.96571","0.02876"
"152.8000","3.0544","5.96743","0.02885"
"153.2000","3.0624","5.96839","0.02893"
"153.6000","3.0705","5.97043","0.02902"
"154.0000","3.0785","5.97047","0.02911"
"154.4000","3.0866","5.97322","0.02920"
"154.8000","3.0943","5.97146","0.02928"
"155.2000","3.1025","5.97393","0.02937"
"155.6000","3.1104","5.97580","0.02946"
"156.0000","3.1185","5.96468","0.02953"
"156.4000","3.1266","5.97593","0.02961"
"156.8000","3.1345","5.97930","0.02969"
"157.2000","3.1425","5.98176","0.02978"
"157.6000","3.1503","5.98075","0.02986"
"158.0000","3.1586","5.98365","0.02995"
"158.4000","3.1665","5.98427","0.03004"
"158.8000","3.1744","5.98465","0.03012"
"159.2000","3.1825","5.98644","0.03021"
"159.6000","3.1905","5.98716","0.03030"
"160.0000","3.1985","5.98947","0.03038"
"160.4000","3.2063","5.98788","0.03047"
"160.8000","3.2146","5.99076","0.03056"
"161.2000","3.2224","5.99133","0.03064"
"161.6000","3.2303","5.99155","0.03073"
"162.0000","3.2385","5.99475","0.03082"
"162.4000","3.2466","5.99598","0.03091"
"162.8000","3.2545","5.99642","0.03099"
"163.2000","3.2624","5.99569","0.03108"
"163.6000","3.2706","5.99875","0.03117"
"164.0000","3.2783","5.99863","0.03125"
"164.4000","3.2864","5.99998","0.03134"
"164.8000","3.2945","6.00192","0.03143"
"165.2000","3.3026","6.00348","0.03152"
"165.6000","3.3104","6.00426","0.03160"
"166.0000","3.3183","6.00314","0.03169"
"166.4000","3.3267","6.00734","0.03178"
"166.8000","3.3344","6.00677","0.03186"
"167.2000","3.3424","6.00677","0.03195"
"167.6000","3.3505","6.00967","0.03204"
"168.0000","3.3585","6.01101","0.03213"
"168.4000","3.3664","6.01153","0.03221"
"168.8000","3.3744","6.01145","0.03230"
"169.2000","3.3827","6.01465","0.03239"
"169.6000","3.3903","6.01323","0.03247"
"170.0000","3.3984","6.01449","0.03256"
"170.4000","3.4065","6.01734","0.03265"
"170.8000","3.4147","6.01915","0.03274"
"171.2000","3.4225","6.01888","0.03282"
"171.6000","3.4304","6.01859","0.03291"
"172.0000","3.4387","6.02266","0.03300"
"172.4000","3.4462","6.02061","0.03308"
"172.8000","3.4544","6.02209","0.03317"
"173.2000","3.4626","6.02513","0.03326"
"173.6000","3.4706","6.02587","0.03334"
"174.0000","3.4784","6.02563","0.03343"
"174.4000","3.4864","6.02664","0.03352"
"174.8000","3.4947","6.03031","0.03361"
"175.2000","3.5024","6.02823","0.03369"
"175.6000","3.5104","6.02929","0.03378"
"176.0000","3.5185","6.03156","0.03387"
"176.4000","3.5265","6.03288","0.03395"
"176.8000","3.5343","6.03316","0.03404"
"177.2000","3.5425","6.03409","0.03412"
"177.6000","3.5507","6.03775","0.03421"
"178.0000","3.5582","6.03457","0.03430"
"178.4000","3.5664","6.03655","0.03439"
"178.8000","3.5745","6.03929","0.03447"
"179.2000","3.5825","6.04012","0.03456"
"179.6000","3.5904","6.03990","0.03465"
"180.0000","3.5985","6.04162","0.03473"
"180.4000","3.6067","6.04450","0.03482"
"180.8000","3.6142","6.04156","0.03491"
"181.2000","3.6224","6.04425","0.03500"
"181.6000","3.6306","6.04632","0.03509"
"182.0000","3.6385","6.04668","0.03517"
"182.4000","3.6463","6.04680","0.03526"
"182.8000","3.6545","6.04854","0.03535"
"183.2000","3.6627","6.05233","0.03544"
"183.6000","3.6703","6.04837","0.03552"
"184.0000","3.6785","6.05061","0.03561"
"184.4000","3.6865","6.05322","0.03569"
"184.8000","3.6945","6.05320","0.03578"
"185.2000","3.7023","6.05359","0.03586"
"185.6000","3.7106","6.05630","0.03595"
"186.0000","3.7187","6.05830","0.03604"
"186.4000","3.7263","6.05517","0.03613"
"186.8000","3.7344","6.05777","0.03621"
"187.2000","3.7424","6.05943","0.03630"
"187.6000","3.7505","6.06068","0.03639"
"188.0000","3.7584","6.06029","0.03647"
"188.4000","3.7666","6.06228","0.03656"
"188.8000","3.7747","6.06473","0.03665"
"189.2000","3.7822","6.06147","0.03673"
"189.6000","3.7905","6.06498","0.03682"
"190.0000","3.7985","6.06632","0.03691"
"190.4000","3.8064","6.06600","0.03699"
"190.8000","3.8144","6.06684","0.03708"
"191.2000","3.8226","6.06934","0.03717"
"191.6000","3.8306","6.07103","0.03726"
"192.0000","3.8384","6.06878","0.03734"
"192.4000","3.8465","6.07143","0.03743"
"192.8000","3.8545","6.07193","0.03751"
"193.2000","3.8624","6.07245","0.03760"
"193.6000","3.8703","6.07314","0.03769"
"194.0000","3.8786","6.07584","0.03778"
"194.4000","3.8866","6.07731","0.03786"
"194.8000","3.8943","6.07461","0.03795"
"195.2000","3.9026","6.07817","0.03804"
"195.6000","3.9104","6.07823","0.03812"
"196.0000","3.9184","6.07863","0.03821"
"196.4000","3.9264","6.07980","0.03830"
"196.8000","3.9346","6.08205","0.03838"
"197.2000","3.9425","6.08284","0.03847"
"197.6000","3.9503","6.08135","0.03855"
"198.0000","3.9586","6.08482","0.03864"
"198.4000","3.9664","6.08413","0.03873"
"198.8000","3.9744","6.08473","0.03882"
"199.2000","3.9823","6.08526","0.03890"
"199.6000","3.9905","6.08746","0.03899"
"200.0000","3.9985","6.08926","0.03908"
"200.4000","4.0064","6.08760","0.03916"
"200.8000","4.0146","6.09070","0.03925"
"201.2000","4.0224","6.08994","0.03934"
"201.6000","4.0304","6.09031","0.03942"
"202.0000","4.0384","6.09150","0.03951"
"202.4000","4.0466","6.09404","0.03960"
"202.8000","4.0545","6.09427","0.03968"
"203.2000","4.0625","6.09390","0.03977"
"203.6000","4.0706","6.09659","0.03986"
"204.0000","4.0783","6.09528","0.03994"
"204.4000","4.0865","6.09707","0.04003"
"204.8000","4.0944","6.09748","0.04012"
"205.2000","4.1026","6.09921","0.04021"
"205.6000","4.1105","6.09971","0.04029"
"206.0000","4.1184","6.09948","0.04038"
"206.4000","4.1266","6.10294","0.04047"
"206.8000","4.1344","6.10128","0.04056"
"207.2000","4.1425","6.10201","0.04064"
"207.6000","4.1504","6.10292","0.04073"
"208.0000","4.1585","6.10456","0.04082"
"208.4000","4.1664","6.10529","0.04090"
"208.8000","4.1745","6.10612","0.04099"
"209.2000","4.1827","6.10830","0.04108"
"209.6000","4.1904","6.10637","0.04116"
"210.0000","4.1985","6.10783","0.04125"
"210.4000","4.2063","6.10823","0.04133"
"210.8000","4.2146","6.11058","0.04142"
"211.2000","4.2224","6.11071","0.04151"
"211.6000","4.2305","6.11087","0.04160"
"212.0000","4.2386","6.11370","0.04168"
"212.4000","4.2463","6.11209","0.04177"
"212.8000","4.2545","6.11355","0.04186"
"213.2000","4.2625","6.11394","0.04194"
"213.6000","4.2705","6.11525","0.04203"
"214.0000","4.2784","6.11533","0.04211"
"214.4000","4.2865","6.11665","0.04220"
"214.8000","4.2946","6.11911","0.04229"
"215.2000","4.3024","6.11738","0.04237"
"215.6000","4.3105","6.11908","0.04246"
"216.0000","4.3184","6.11853","0.04255"
"216.4000","4.3265","6.12054","0.04264"
"216.8000","4.3343","6.12074","0.04272"
"217.2000","4.3425","6.12199","0.04281"
"217.6000","4.3507","6.12426","0.04289"
"218.0000","4.3584","6.12254","0.04298"
"218.4000","4.3665","6.10260","0.04305"
"218.8000","4.3744","6.11699","0.04313"
"219.2000","4.3825","6.12483","0.04321"
"219.6000","4.3904","6.12622","0.04330"
"220.0000","4.3985","6.12767","0.04338"
"220.4000","4.4065","6.12951","0.04347"
"220.8000","4.4144","6.12857","0.04355"
"221.2000","4.4225","6.13049","0.04364"
"221.6000","4.4304","6.12924","0.04373"
"222.0000","4.4386","6.13135","0.04381"
"222.4000","4.4464","6.13044","0.04390"
"222.8000","4.4544","6.13108","0.04398"
"223.2000","4.4626","6.13428","0.04407"
"223.6000","4.4705","6.13313","0.04416"
"224.0000","4.4786","6.13409","0.04425"
"224.4000","4.4864","6.13318","0.04433"
"224.8000","4.4945","6.13507","0.04442"
"225.2000","4.5023","6.13480","0.04450"
"225.6000","4.5105","6.13652","0.04459"
"226.0000","4.5186","6.13799","0.04468"
"226.4000","4.5265","6.13789","0.04476"
"226.8000","4.5345","6.13890","0.04485"
"227.2000","4.5423","6.13725","0.04493"
"227.6000","4.5505","6.14028","0.04502"
"228.0000","4.5584","6.13951","0.04511"
"228.4000","4.5665","6.13995","0.04520"
"228.8000","4.5745","6.14232","0.04528"
"229.2000","4.5824","6.14189","0.04537"
"229.6000","4.5906","6.14371","0.04545"
"230.0000","4.5984","6.14237","0.04554"
"230.4000","4.6065","6.14422","0.04563"
"230.8000","4.6144","6.14384","0.04571"
"231.2000","4.6224","6.14460","0.04580"
"231.6000","4.6305","6.14659","0.04588"
"232.0000","4.6386","6.14751","0.04597"
"232.4000","4.6465","6.14740","0.04606"
"232.8000","4.6544","6.14620","0.04614"
"233.2000","4.6625","6.14913","0.04623"
"233.6000","4.6703","6.14750","0.04631"
"234.0000","4.6785","6.14929","0.04640"
"234.4000","4.6865","6.15087","0.04649"
"234.8000","4.6945","6.15062","0.04657"
"235.2000","4.7026","6.15180","0.04666"
"235.6000","4.7103","6.15053","0.04675"
"236.0000","4.7185","6.15327","0.04684"
"236.4000","4.7264","6.15241","0.04692"
"236.8000","4.7345","6.15285","0.04701"
"237.2000","4.7425","6.15435","0.04709"
"237.6000","4.7504","6.15504","0.04718"
"238.0000","4.7585","6.15568","0.04727"
"238.4000","4.7665","6.15541","0.04735"
"238.8000","4.7746","6.15751","0.04744"
"239.2000","4.7823","6.15504","0.04752"
"239.6000","4.7905","6.15757","0.04761"
"240.0000","4.7984","6.15842","0.04770"
"240.4000","4.8065","6.15872","0.04778"
"240.8000","4.8146","6.16002","0.04787"
"241.2000","4.8224","6.15894","0.04795"
"241.6000","4.8306","6.16125","0.04804"
"242.0000","4.8383","6.15952","0.04813"
"242.4000","4.8465","6.16109","0.04822"
"242.8000","4.8545","6.16271","0.04830"
"243.2000","4.8624","6.16230","0.04839"
"243.6000","4.8705","6.16293","0.04847"
"244.0000","4.8785","6.16341","0.04856"
"244.4000","4.8865","6.16509","0.04865"
"244.8000","4.8943","6.16293","0.04873"
"245.2000","4.9026","6.16542","0.04882"
"245.6000","4.9104","6.16543","0.04890"
"246.0000","4.9184","6.16529","0.04899"
"246.4000","4.9265","6.16776","0.04908"
"246.8000","4.9345","6.16729","0.04916"
"247.2000","4.9426","6.16897","0.04925"
"247.6000","4.9503","6.16657","0.04933"
"248.0000","4.9585","6.16864","0.04942"
"248.4000","4.9664","6.16915","0.04950"
"248.8000","4.9744","6.16954","0.04959"
"249.2000","4.9825","6.17058","0.04968"
"249.6000","4.9905","6.17104","0.04976"
"250.0000","4.9985","6.17174","0.04985"
"250.4000","5.0063","6.16985","0.04993"
"250.8000","5.0146","6.17286","0.05002"
"251.2000","5.0224","6.17266","0.05010"
"251.6000","5.0304","6.17241","0.05019"
"252.0000","5.0385","6.17401","0.05028"
"252.4000","5.0465","6.17446","0.05036"
"252.8000","5.0545","6.17549","0.05045"
"253.2000","5.0624","6.17395","0.05053"
"253.6000","5.0706","6.17602","0.05062"
"254.0000","5.0783","6.17497","0.05070"
"254.4000","5.0864","6.17551","0.05079"
"254.8000","5.0945","6.17739","0.05087"
"255.2000","5.1026","6.17835","0.05096"
"255.6000","5.1105","6.17844","0.05105"
"256.0000","5.1184","6.17660","0.05113"
"256.4000","5.1266","6.17974","0.05122"
"256.8000","5.1343","6.17817","0.05130"
"257.2000","5.1424","6.17860","0.05139"
"257.6000","5.1506","6.18099","0.05147"
"258.0000","5.1586","6.18135","0.05156"
"258.4000","5.1664","6.18058","0.05164"
"258.8000","5.1743","6.18011","0.05173"
"259.2000","5.1826","6.18322","0.05181"
"259.6000","5.1904","6.18147","0.05190"
"260.0000","5.1984","6.18157","0.05199"
"260.4000","5.2065","6.18314","0.05207"
"260.8000","5.2146","6.18447","0.05216"
"261.2000","5.2224","6.18409","0.05224"
"261.6000","5.2304","6.18311","0.05232"
"262.0000","5.2387","6.18647","0.05241"
"262.4000","5.2463","6.18361","0.05249"
"262.8000","5.2543","6.18418","0.05258"
"263.2000","5.2625","6.18673","0.05266"
"263.6000","5.2706","6.18743","0.05275"
"264.0000","5.2784","6.18634","0.05283"
"264.4000","5.2865","6.18639","0.05292"
"264.8000","5.2947","6.18916","0.05300"
"265.2000","5.3022","6.18584","0.05308"
"265.6000","5.3104","6.18782","0.05317"
"266.0000","5.3186","6.18930","0.05326"
"266.4000","5.3266","6.18953","0.05334"
"266.8000","5.3344","6.18889","0.05342"
"267.2000","5.3424","6.18926","0.05351"
"267.6000","5.3507","6.19274","0.05359"
"268.0000","5.3583","6.18883","0.05368"
"268.4000","5.3664","6.18993","0.05376"
"268.8000","5.3746","6.19191","0.05385"
"269.2000","5.3825","6.19146","0.05393"
"269.6000","5.3904","6.19152","0.05401"
"270.0000","5.3986","6.19253","0.05410"
"270.4000","5.4067","6.19459","0.05419"
"270.8000","5.4142","6.19083","0.05426"
"271.2000","5.4224","6.19274","0.05435"
"271.6000","5.4304","6.19408","0.05444"
"272.0000","5.4386","6.19485","0.05452"
"272.4000","5.4464","6.19387","0.05460"
"272.8000","5.4545","6.19450","0.05469"
"273.2000","5.4627","6.19716","0.05477"
"273.6000","5.4702","6.19288","0.05485"
"274.0000","5.4784","6.19530","0.05494"
"274.4000","5.4866","6.19692","0.05502"
"274.8000","5.4945","6.19610","0.05511"
"275.2000","5.5024","6.19563","0.05519"
"275.6000","5.5105","6.19757","0.05527"
"276.0000","5.5186","6.19943","0.05535"
"276.4000","5.5263","6.19574","0.05543"
"276.8000","5.5345","6.19756","0.05552"
"277.2000","5.5425","6.19824","0.05560"
"277.6000","5.5504","6.19814","0.05568"
"278.0000","5.5583","6.19816","0.05576"
"278.4000","5.5666","6.19986","0.05585"
"278.8000","5.5747","6.20137","0.05593"
"279.2000","5.5823","6.19742","0.05601"
"279.6000","5.5905","6.19963","0.05610"
"280.0000","5.5984","6.20055","0.05617"
"280.4000","5.6064","6.20013","0.05626"
"280.8000","5.6144","6.20018","0.05634"
"281.2000","5.6226","6.20218","0.05643"
"281.6000","5.6306","6.20255","0.05651"
"282.0000","5.6383","6.19955","0.05659"
"282.4000","5.6465","6.20269","0.05667"
"282.8000","5.6545","6.20226","0.05675"
"283.2000","5.6625","6.20197","0.05683"
"283.6000","5.6703","6.20145","0.05691"
"284.0000","5.6785","6.20359","0.05700"
"284.4000","5.6866","6.20498","0.05708"
"284.8000","5.6944","6.20158","0.05716"
"285.2000","5.7026","6.20401","0.05724"
"285.6000","5.7104","6.20375","0.05732"
"286.0000","5.7184","6.20299","0.05740"
"286.4000","5.7264","6.20361","0.05748"
"286.8000","5.7346","6.20582","0.05756"
"287.2000","5.7426","6.20554","0.05764"
"287.6000","5.7504","6.20363","0.05772"
"288.0000","5.7586","6.20579","0.05780"
"288.4000","5.7663","6.20452","0.05788"
"288.8000","5.7745","6.20550","0.05796"
"289.2000","5.7824","6.20508","0.05804"
"289.6000","5.7906","6.20666","0.05812"
"290.0000","5.7985","6.20673","0.05820"
"290.4000","5.8063","6.20484","0.05828"
"290.8000","5.8146","6.20822","0.05836"
"291.2000","5.8224","6.20627","0.05844"
"291.6000","5.8304","6.20585","0.05852"
"292.0000","5.8384","6.20672","0.05859"
"292.4000","5.8465","6.20774","0.05867"
"292.8000","5.8544","6.20795","0.05875"
"293.2000","5.8625","6.20687","0.05883"
"293.6000","5.8706","6.20909","0.05891"
"294.0000","5.8784","6.20695","0.05898"
"294.4000","5.8864","6.20744","0.05906"
"294.8000","5.8943","6.20737","0.05914"
"295.2000","5.9025","6.20918","0.05922"
"295.6000","5.9105","6.20903","0.05929"
"296.0000","5.9185","6.20811","0.05937"
"296.4000","5.9266","6.21021","0.05945"
"296.8000","5.9343","6.20820","0.05953"
"297.2000","5.9425","6.20909","0.05960"
"297.6000","5.9505","6.20908","0.05968"
"298.0000","5.9585","6.20973","0.05975"
"298.4000","5.9664","6.20905","0.05983"
"298.8000","5.9745","6.20923","0.05990"
"299.2000","5.9826","6.21136","0.05998"
"299.6000","5.9904","6.20907","0.06005"
"300.0000","5.9985","6.20992","0.06013"
"300.4000","6.0064","6.20922","0.06020"
"300.8000","6.0145","6.21038","0.06028"
"301.2000","6.0224","6.21037","0.06035"
"301.6000","6.0305","6.21029","0.06043"
"302.0000","6.0387","6.21214","0.06050"
"302.4000","6.0464","6.20954","0.06057"
"302.8000","6.0545","6.21008","0.06064"
"303.2000","6.0624","6.21010","0.06071"
"303.6000","6.0705","6.21123","0.06079"
"304.0000","6.0784","6.21026","0.06086"
"304.4000","6.0865","6.21070","0.06093"
"304.8000","6.0946","6.21206","0.06100"
"305.2000","6.1023","6.21001","0.06107"
"305.6000","6.1105","6.21150","0.06114"
"306.0000","6.1184","6.21031","0.06121"
"306.4000","6.1266","6.21138","0.06128"
"306.8000","6.1344","6.21031","0.06135"
"307.2000","6.1425","6.21035","0.06142"
"307.6000","6.1506","6.21299","0.06149"
"308.0000","6.1584","6.21042","0.06156"
"308.4000","6.1665","6.21099","0.06163"
"308.8000","6.1744","6.20992","0.06169"
"309.2000","6.1824","6.21096","0.06176"
"309.6000","6.1903","6.21051","0.06183"
"310.0000","6.1986","6.21118","0.06189"
"310.4000","6.2066","6.21181","0.06196"
"310.8000","6.2145","6.21053","0.06202"
"311.2000","6.2225","6.21097","0.06209"
"311.6000","6.2303","6.20936","0.06215"
"312.0000","6.2385","6.21158","0.06222"
"312.4000","6.2464","6.21020","0.06228"
"312.8000","6.2545","6.20993","0.06235"
"313.2000","6.2626","6.21149","0.06241"
"313.6000","6.2704","6.20994","0.06247"
"314.0000","6.2785","6.21090","0.06253"
"314.4000","6.2864","6.20923","0.06259"
"314.8000","6.2945","6.21007","0.06265"
"315.2000","6.3024","6.20897","0.06271"
"315.6000","6.3105","6.20911","0.06277"
"316.0000","6.3185","6.21077","0.06283"
"316.4000","6.3265","6.20983","0.06289"
"316.8000","6.3346","6.20971","0.06295"
"317.2000","6.3423","6.20736","0.06300"
"317.6000","6.3505","6.20952","0.06306"
"318.0000","6.3583","6.20779","0.06312"
"318.4000","6.3665","6.20817","0.06317"
"318.8000","6.3746","6.20942","0.06323"
"319.2000","6.3825","6.20802","0.06328"
"319.6000","6.3905","6.20775","0.06334"
"320.0000","6.3983","6.20599","0.06339"
"320.4000","6.4065","6.20806","0.06344"
"320.8000","6.4144","6.20606","0.06349"
"321.2000","6.4225","6.20586","0.06354"
"321.6000","6.4305","6.20669","0.06359"
"322.0000","6.4385","6.20633","0.06364"
"322.4000","6.4466","6.20629","0.06369"
"322.8000","6.4544","6.20358","0.06373"
"323.2000","6.4626","6.20583","0.06379"
"323.6000","6.4703","6.20306","0.06383"
"324.0000","6.4784","6.20290","0.06388"
"324.4000","6.4865","6.20450","0.06392"
"324.8000","6.4945","6.20352","0.06396"
"325.2000","6.5026","6.20289","0.06401"
"325.6000","6.5104","6.20079","0.06405"
"326.0000","6.5185","6.20223","0.06409"
"326.4000","6.5263","6.19979","0.06413"
"326.8000","6.5345","6.20020","0.06417"
"327.2000","6.5425","6.20011","0.06421"
"327.6000","6.5505","6.19953","0.06424"
"328.0000","6.5585","6.19891","0.06428"
"328.4000","6.5664","6.19656","0.06432"
"328.8000","6.5746","6.19863","0.06435"
"329.2000","6.5823","6.19485","0.06438"
"329.6000","6.5905","6.19491","0.06442"
"330.0000","6.5984","6.19526","0.06445"
"330.4000","6.6064","6.19386","0.06448"
"330.8000","6.6145","6.19411","0.06451"
"331.2000","6.6225","6.19195","0.06454"
"331.6000","6.6306","6.19225","0.06457"
"332.0000","6.6384","6.18894","0.06459"
"332.4000","6.6465","6.18896","0.06462"
"332.8000","6.6544","6.18872","0.06465"
"333.2000","6.6625","6.18806","0.06467"
"333.6000","6.6705","6.18666","0.06470"
"334.0000","6.6785","6.18462","0.06472"
"334.4000","6.6866","6.18546","0.06475"
"334.8000","6.6943","6.18097","0.06476"
"335.2000","6.7025","6.18151","0.06479"
"335.6000","6.7105","6.18069","0.06480"
"336.0000","6.7185","6.17830","0.06483"
"336.4000","6.7265","6.17772","0.06484"
"336.8000","6.7345","6.17595","0.06486"
"337.2000","6.7425","6.17589","0.06488"
"337.6000","6.7504","6.17153","0.06489"
"338.0000","6.7586","6.17122","0.06491"
"338.4000","6.7664","6.16947","0.06492"
"338.8000","6.7744","6.16734","0.06494"
"339.2000","6.7825","6.16696","0.06495"
"339.6000","6.7906","6.16470","0.06496"
"340.0000","6.7986","6.16368","0.06498"
"340.4000","6.8063","6.15846","0.06499"
"340.8000","6.8146","6.15884","0.06500"
"341.2000","6.8223","6.15636","0.06501"
"341.6000","6.8304","6.15330","0.06502"
"342.0000","6.8386","6.15307","0.06503"
"342.4000","6.8466","6.15043","0.06504"
"342.8000","6.8545","6.14812","0.06504"
"343.2000","6.8623","6.14356","0.06505"
"343.6000","6.8706","6.14331","0.06506"
"344.0000","6.8784","6.13978","0.06507"
"344.4000","6.8864","6.13653","0.06507"
"344.8000","6.8945","6.13445","0.06508"
"345.2000","6.9026","6.13316","0.06508"
"345.6000","6.9104","6.13008","0.06509"
"346.0000","6.9184","6.12416","0.06509"
"346.4000","6.9267","6.12425","0.06510"
"346.8000","6.9343","6.11902","0.06510"
"347.2000","6.9424","6.11545","0.06510"
"347.6000","6.9505","6.11468","0.06511"
"348.0000","6.9586","6.11103","0.06511"
"348.4000","6.9665","6.10725","0.06511"
"348.8000","6.9744","6.10185","0.06512"
"349.2000","6.9826","6.10022","0.06512"
"349.6000","6.9903","6.09544","0.06512"
"350.0000","6.9984","6.09109","0.06512"
"350.4000","7.0065","6.08792","0.06512"
"350.8000","7.0146","6.08541","0.06512"
"351.2000","7.0224","6.08007","0.06513"
"351.6000","7.0304","6.07431","0.06513"
"352.0000","7.0387","6.07390","0.06513"
"352.4000","7.0463","6.06566","0.06513"
"352.8000","7.0545","6.06138","0.06513"
"353.2000","7.0625","6.05873","0.06513"
"353.6000","7.0705","6.05353","0.06513"
"354.0000","7.0785","6.04930","0.06513"
"354.4000","7.0864","6.04259","0.06512"
"354.8000","7.0947","6.03980","0.06512"
"355.2000","7.1023","6.03249","0.06512"
"355.6000","7.1103","6.02675","0.06512"
"356.0000","7.1185","6.02327","0.06512"
"356.4000","7.1266","6.01860","0.06512"
"356.8000","7.1344","6.01122","0.06512"
"357.2000","7.1425","6.00488","0.06511"
"357.6000","7.1507","6.00216","0.06512"
"358.0000","7.1582","5.99195","0.06511"
"358.4000","7.1665","5.98698","0.06511"
"358.8000","7.1745","5.98219","0.06511"
"359.2000","7.1825","5.97507","0.06510"
"359.6000","7.1904","5.96861","0.06510"
"360.0000","7.1984","5.96172","0.06510"
"360.4000","7.2067","5.95751","0.06510"
"360.8000","7.2143","5.94665","0.06509"
"361.2000","7.2224","5.93983","0.06509"
"361.6000","7.2305","5.93459","0.06508"
"362.0000","7.2385","5.92680","0.06508"
"362.4000","7.2464","5.91929","0.06508"
"362.8000","7.2546","5.91138","0.06507"
"363.2000","7.2627","5.90600","0.06507"
"363.6000","7.2702","5.89375","0.06506"
"364.0000","7.2784","5.88700","0.06506"
"364.4000","7.2864","5.88053","0.06505"
"364.8000","7.2945","5.87101","0.06505"
"365.2000","7.3024","5.86227","0.06504"
"365.6000","7.3106","5.85433","0.06504"
"366.0000","7.3187","5.84697","0.06504"
"366.4000","7.3262","5.83416","0.06503"
"366.8000","7.3345","5.82661","0.06502"
"367.2000","7.3425","5.81813","0.06502"
"367.6000","7.3505","5.80782","0.06501"
"368.0000","7.3583","5.79792","0.06500"
"368.4000","7.3665","5.78872","0.06500"
"368.8000","7.3747","5.78114","0.06499"
"369.2000","7.3823","5.76609","0.06498"
"369.6000","7.3905","5.75706","0.06498"
"370.0000","7.3985","5.74807","0.06497"
"370.4000","7.4064","5.73580","0.06496"
"370.8000","7.4144","5.72569","0.06496"
"371.2000","7.4226","5.71520","0.06495"
"371.6000","7.4306","5.70486","0.06495"
"372.0000","7.4383","5.68991","0.06494"
"372.4000","7.4465","5.67998","0.06493"
"372.8000","7.4544","5.66813","0.06492"
"373.2000","7.4625","5.65572","0.06491"
"373.6000","7.4704","5.64306","0.06490"
"374.0000","7.4786","5.63123","0.06490"
"374.4000","7.4866","5.62043","0.06489"
"374.8000","7.4943","5.60380","0.06488"
"375.2000","7.5026","5.59253","0.06487"
"375.6000","7.5105","5.57947","0.06486"
"376.0000","7.5184","5.56440","0.06485"
"376.4000","7.5264","5.55144","0.06484"
"376.8000","7.5345","5.53820","0.06483"
"377.2000","7.5425","5.52531","0.06483"
"377.6000","7.5504","5.50716","0.06481"
"378.0000","7.5586","5.49439","0.06480"
"378.4000","7.5664","5.47879","0.06479"
"378.8000","7.5744","5.46311","0.06478"
"379.2000","7.5823","5.44854","0.06477"
"379.6000","7.5906","5.43283","0.06476"
"380.0000","7.5985","5.41807","0.06475"
"380.4000","7.6064","5.39897","0.06474"
"380.8000","7.6146","5.38421","0.06473"
"381.2000","7.6223","5.36694","0.06472"
"381.6000","7.6305","5.34869","0.06470"
"382.0000","7.6385","5.33222","0.06469"
"382.4000","7.6466","5.31482","0.06468"
"382.8000","7.6545","5.29714","0.06467"
"383.2000","7.6624","5.27691","0.06466"
"383.6000","7.6706","5.25990","0.06464"
"384.0000","7.6784","5.23866","0.06463"
"384.4000","7.6865","5.21848","0.06461"
"384.8000","7.6944","5.19893","0.06460"
"385.2000","7.7025","5.17798","0.06459"
"385.6000","7.7105","5.15894","0.06457"
"386.0000","7.7185","5.13474","0.06456"
"386.4000","7.7266","5.11339","0.06454"
"386.8000","7.7344","5.08969","0.06453"
"387.2000","7.7424","5.06567","0.06451"
"387.6000","7.7504","5.04314","0.06450"
"388.0000","7.7586","5.01855","0.06448"
"388.4000","7.7665","4.99396","0.06446"
"388.8000","7.7745","4.96698","0.06444"
"389.2000","7.7826","4.94188","0.06443"
"389.6000","7.7903","4.91262","0.06441"
"390.0000","7.7985","4.88278","0.06439"
"390.4000","7.8065","4.85232","0.06436"
"390.8000","7.8146","4.81642","0.06434"
"391.2000","7.8225","4.78168","0.06432"
"391.6000","7.8305","4.73845","0.06429"
"392.0000","7.8386","4.69158","0.06426"
"392.4000","7.8464","4.63507","0.06422"
"392.8000","7.8545","4.57115","0.06418"
"393.2000","7.8624","4.49202","0.06413"
"393.4290","7.8671","4.22360","0.06395"
"393.4620","7.8680","3.90516","0.06373"
"393.4730","7.8683","3.72035","0.06359"