File: Coupon Test Data/test__20250509_94834_8.csv
Time,Displacement,Force,Strain 1
(s),(mm),(kN),(mm/mm)
"0.0000","-25.2095","0.06049","-0.00001"
"0.5000","-25.2028","0.14924","0.00003"
"1.0000","-25.1942","0.26786","0.00008"
"1.5000","-25.1858","0.38294","0.00013"
"2.0000","-25.1775","0.49403","0.00018"
"2.5000","-25.1693","0.60018","0.00022"
"3.0000","-25.1608","0.71020","0.00027"
"3.5000","-25.1526","0.81576","0.00032"
"4.0000","-25.1442","0.92212","0.00036"
"4.5000","-25.1358","1.02786","0.00041"
"5.0000","-25.1275","1.12229","0.00045"
"5.5000","-25.1191","1.22214","0.00049"
"6.0000","-25.1109","1.32461","0.00054"
"6.5000","-25.1026","1.42820","0.00058"
"7.0000","-25.0941","1.53195","0.00062"
"7.5000","-25.0859","1.62264","0.00066"
"8.0000","-25.0775","1.72583","0.00070"
"8.5000","-25.0692","1.82610","0.00075"
"9.0000","-25.0608","1.92082","0.00079"
"9.5000","-25.0525","2.01783","0.00083"
"10.0000","-25.0442","2.11840","0.00087"
"10.5000","-25.0357","2.21980","0.00092"
"11.0000","-25.0275","2.30807","0.00096"
"11.5000","-25.0193","2.40565","0.00100"
"12.0000","-25.0110","2.50361","0.00104"
"12.5000","-25.0024","2.59694","0.00108"
"13.0000","-24.9939","2.69431","0.00112"
"13.5000","-24.9860","2.78593","0.00116"
"14.0000","-24.9776","2.87998","0.00120"
"14.5000","-24.9692","2.97333","0.00124"
"15.0000","-24.9607","3.07057","0.00128"
"15.5000","-24.9525","3.16067","0.00132"
"16.0000","-24.9443","3.24896","0.00136"
"16.5000","-24.9358","3.34553","0.00140"
"17.0000","-24.9276","3.43276","0.00143"
"17.5000","-24.9192","3.52553","0.00148"
"18.0000","-24.9108","3.61902","0.00151"
"18.5000","-24.9026","3.70322","0.00155"
"19.0000","-24.8942","3.79667","0.00159"
"19.5000","-24.8860","3.88572","0.00163"
"20.0000","-24.8775","3.97198","0.00166"
"20.5000","-24.8690","4.06482","0.00170"
"21.0000","-24.8609","4.14649","0.00174"
"21.5000","-24.8525","4.23598","0.00178"
"22.0000","-24.8443","4.32329","0.00181"
"22.5000","-24.8358","4.40700","0.00185"
"23.0000","-24.8275","4.49393","0.00189"
"23.5000","-24.8192","4.57270","0.00193"
"24.0000","-24.8108","4.65846","0.00197"
"24.5000","-24.8026","4.73804","0.00201"
"25.0000","-24.7942","4.81385","0.00205"
"25.5000","-24.7859","4.89063","0.00209"
"26.0000","-24.7774","4.96232","0.00213"
"26.5000","-24.7689","5.03538","0.00218"
"27.0000","-24.7611","5.09746","0.00222"
"27.5000","-24.7526","5.15983","0.00227"
"28.0000","-24.7441","5.22059","0.00232"
"28.5000","-24.7357","5.27801","0.00238"
"29.0000","-24.7275","5.32963","0.00244"
"29.5000","-24.7194","5.37639","0.00250"
"30.0000","-24.7108","5.42039","0.00256"
"30.5000","-24.7025","5.46450","0.00262"
"31.0000","-24.6941","5.50398","0.00269"
"31.5000","-24.6858","5.54097","0.00276"
"32.0000","-24.6777","5.57353","0.00283"
"32.5000","-24.6691","5.60882","0.00290"
"33.0000","-24.6609","5.63680","0.00297"
"33.5000","-24.6525","5.66120","0.00304"
"34.0000","-24.6441","5.69278","0.00312"
"34.5000","-24.6359","5.71370","0.00319"
"35.0000","-24.6275","5.73754","0.00327"
"35.5000","-24.6192","5.75944","0.00335"
"36.0000","-24.6108","5.78079","0.00344"
"36.5000","-24.6026","5.80033","0.00352"
"37.0000","-24.5943","5.81737","0.00360"
"37.5000","-24.5857","5.83786","0.00368"
"38.0000","-24.5775","5.85260","0.00377"
"38.5000","-24.5692","5.86823","0.00386"
"39.0000","-24.5609","5.88354","0.00394"
"39.5000","-24.5525","5.89854","0.00403"
"40.0000","-24.5439","5.91592","0.00412"
"40.5000","-24.5360","5.92343","0.00420"
"41.0000","-24.5276","5.93634","0.00429"
"41.5000","-24.5191","5.95186","0.00438"
"42.0000","-24.5107","5.96374","0.00447"
"42.5000","-24.5025","5.97558","0.00456"
"43.0000","-24.4943","5.98299","0.00464"
"43.5000","-24.4858","5.99551","0.00473"
"44.0000","-24.4776","6.00701","0.00482"
"44.5000","-24.4692","6.01708","0.00491"
"45.0000","-24.4608","6.02773","0.00500"
"45.5000","-24.4525","6.03416","0.00509"
"46.0000","-24.4440","6.04720","0.00518"
"46.5000","-24.4360","6.05406","0.00527"
"47.0000","-24.4275","6.05944","0.00535"
"47.5000","-24.4190","6.07927","0.00543"
"48.0000","-24.4109","6.08204","0.00552"
"48.5000","-24.4025","6.08919","0.00561"
"49.0000","-24.3942","6.09686","0.00570"
"49.5000","-24.3858","6.10522","0.00579"
"50.0000","-24.3775","6.11394","0.00589"
"50.5000","-24.3692","6.11939","0.00598"
"51.0000","-24.3607","6.12943","0.00607"
"51.5000","-24.3525","6.13578","0.00616"
"52.0000","-24.3442","6.14317","0.00625"
"52.5000","-24.3360","6.15115","0.00635"
"53.0000","-24.3274","6.15908","0.00644"
"53.5000","-24.3189","6.16932","0.00653"
"54.0000","-24.3111","6.17094","0.00662"
"54.5000","-24.3026","6.17876","0.00672"
"55.0000","-24.2941","6.18918","0.00681"
"55.5000","-24.2857","6.19620","0.00690"
"56.0000","-24.2775","6.20215","0.00699"
"56.5000","-24.2693","6.20641","0.00708"
"57.0000","-24.2608","6.21538","0.00717"
"57.5000","-24.2526","6.22277","0.00726"
"58.0000","-24.2441","6.22969","0.00735"
"58.5000","-24.2358","6.23601","0.00743"
"59.0000","-24.2276","6.24011","0.00752"
"59.5000","-24.2191","6.24975","0.00761"
"60.0000","-24.2110","6.25455","0.00769"
"60.5000","-24.2024","6.26077","0.00778"
"61.0000","-24.1940","6.27009","0.00787"
"61.5000","-24.1859","6.27333","0.00795"
"62.0000","-24.1775","6.28031","0.00804"
"62.5000","-24.1692","6.28656","0.00813"
"63.0000","-24.1608","6.29349","0.00822"
"63.5000","-24.1525","6.29891","0.00831"
"64.0000","-24.1442","6.30290","0.00841"
"64.5000","-24.1357","6.31118","0.00850"
"65.0000","-24.1276","6.31599","0.00859"
"65.5000","-24.1191","6.32229","0.00869"
"66.0000","-24.1109","6.32656","0.00879"
"66.5000","-24.1024","6.33332","0.00890"
"67.0000","-24.0939","6.34210","0.00900"
"67.5000","-24.0861","6.34231","0.00910"
"68.0000","-24.0775","6.35004","0.00920"
"68.5000","-24.0691","6.35866","0.00930"
"69.0000","-24.0607","6.36459","0.00941"
"69.5000","-24.0525","6.37108","0.00951"
"70.0000","-24.0444","6.37338","0.00961"
"70.5000","-24.0358","6.38054","0.00971"
"71.0000","-24.0274","6.38594","0.00981"
"71.5000","-24.0191","6.38869","0.00991"
"72.0000","-24.0108","6.39059","0.01000"
"72.5000","-24.0026","6.38925","0.01008"
"73.0000","-23.9941","6.33979","0.01012"
"73.5000","-23.9860","6.36712","0.01015"
"74.0000","-23.9774","6.41341","0.01021"
"74.4860","-23.9693","6.31385","0.01019"
"74.9860","-23.9612","6.39030","0.01024"
"75.3960","-23.9540","6.27316","0.01021"
"75.8960","-23.9460","6.35814","0.01025"
"76.3920","-23.9375","6.28996","0.01024"
"76.8920","-23.9294","6.37791","0.01029"
"77.3920","-23.9210","6.35418","0.01029"
"77.8920","-23.9126","6.43853","0.01034"
"78.3920","-23.9043","6.48627","0.01040"
"78.8080","-23.8973","6.33779","0.01034"
"79.3080","-23.8891","6.41628","0.01039"
"79.7760","-23.8812","6.34846","0.01036"
"80.2760","-23.8731","6.43250","0.01041"
"80.7040","-23.8657","6.33899","0.01037"
"81.2040","-23.8574","6.43178","0.01042"
"81.6870","-23.8493","6.34445","0.01040"
"82.1870","-23.8410","6.43471","0.01044"
"82.5940","-23.8343","6.32573","0.01040"
"83.0940","-23.8258","6.41427","0.01044"
"83.5720","-23.8181","6.39608","0.01056"
"84.0720","-23.8096","6.41858","0.01064"
"84.5720","-23.8013","6.44193","0.01077"
"84.9980","-23.7943","6.40453","0.01095"
"85.4980","-23.7858","6.49023","0.01102"
"85.9880","-23.7777","6.40758","0.01126"
"86.4880","-23.7693","6.49482","0.01133"
"86.9790","-23.7613","6.40809","0.01157"
"87.4790","-23.7529","6.48970","0.01165"
"87.8750","-23.7463","6.38836","0.01189"
"88.3750","-23.7379","6.47853","0.01196"
"88.8020","-23.7307","6.38361","0.01221"
"89.3020","-23.7224","6.47472","0.01227"
"89.7490","-23.7150","6.38362","0.01252"
"90.2490","-23.7069","6.47341","0.01259"
"90.7190","-23.6987","6.38703","0.01285"
"91.2190","-23.6906","6.47803","0.01292"
"91.6890","-23.6827","6.38486","0.01319"
"92.1890","-23.6743","6.47963","0.01325"
"92.6640","-23.6664","6.39145","0.01351"
"93.1640","-23.6581","6.48506","0.01358"
"93.6230","-23.6506","6.39185","0.01383"
"94.1230","-23.6420","6.48806","0.01390"
"94.6050","-23.6341","6.40220","0.01416"
"95.1050","-23.6259","6.49515","0.01422"
"95.5370","-23.6185","6.40299","0.01448"
"96.0370","-23.6101","6.49859","0.01454"
"96.5240","-23.6020","6.40607","0.01486"
"97.0240","-23.5939","6.49863","0.01492"
"97.4800","-23.5860","6.42750","0.01494"
"97.9800","-23.5779","6.51997","0.01499"
"98.4800","-23.5695","6.55428","0.01502"
"98.9800","-23.5611","6.57666","0.01504"
"99.4800","-23.5529","6.61678","0.01507"
"99.9800","-23.5444","6.61422","0.01508"
"100.4800","-23.5364","6.67366","0.01512"
"100.8840","-23.5293","6.55121","0.01508"
"101.3840","-23.5211","6.64493","0.01512"
"101.8010","-23.5142","6.50868","0.01507"
"102.3010","-23.5058","6.61097","0.01512"
"102.8010","-23.4975","6.70099","0.01517"
"103.2200","-23.4905","6.55061","0.01510"
"103.7200","-23.4823","6.64194","0.01514"
"104.2200","-23.4737","6.71795","0.01518"
"104.5740","-23.4681","6.57258","0.01512"
"105.0740","-23.4597","6.67267","0.01517"
"105.5740","-23.4513","6.75820","0.01521"
"105.8750","-23.4462","6.56498","0.01514"
"106.3750","-23.4380","6.66277","0.01519"
"106.8420","-23.4300","6.65510","0.01519"
"107.2570","-23.4233","6.58866","0.01516"
"107.7570","-23.4149","6.68961","0.01521"
"108.2400","-23.4068","6.67726","0.01521"
"108.5700","-23.4014","6.55466","0.01516"
"109.0700","-23.3929","6.65750","0.01521"
"109.5700","-23.3847","6.73545","0.01525"
"110.0700","-23.3763","6.70526","0.01524"
"110.5700","-23.3682","6.79120","0.01528"
"111.0200","-23.3604","6.73835","0.01530"
"111.3540","-23.3551","6.62128","0.01524"
"111.8540","-23.3467","6.72073","0.01529"
"112.3360","-23.3385","6.70993","0.01529"
"112.7530","-23.3317","6.65483","0.01527"
"113.2530","-23.3234","6.75211","0.01531"
"113.6500","-23.3165","6.65180","0.01527"
"114.1500","-23.3082","6.67037","0.01529"
"114.6500","-23.3001","6.76459","0.01535"
"115.0480","-23.2931","6.60798","0.01563"
"115.5480","-23.2852","6.70132","0.01568"
"116.0480","-23.2767","6.79757","0.01574"
"116.3860","-23.2710","6.60584","0.01605"
"116.8860","-23.2627","6.70534","0.01611"
"117.3860","-23.2545","6.79763","0.01617"
"117.7180","-23.2487","6.61365","0.01647"
"118.2180","-23.2407","6.70851","0.01653"
"118.7180","-23.2322","6.80461","0.01659"
"119.1300","-23.2252","6.62881","0.01691"
"119.6300","-23.2169","6.72969","0.01697"
"120.1300","-23.2087","6.81656","0.01704"
"120.5150","-23.2022","6.64118","0.01736"
"121.0150","-23.1936","6.74470","0.01742"
"121.4790","-23.1864","6.72437","0.01758"
"121.8950","-23.1791","6.66788","0.01780"
"122.3950","-23.1709","6.76497","0.01786"
"122.7310","-23.1653","6.63450","0.01811"
"123.2310","-23.1571","6.68878","0.01822"
"123.7310","-23.1486","6.78697","0.01829"
"124.1040","-23.1424","6.61753","0.01860"
"124.6040","-23.1341","6.71541","0.01866"
"125.1040","-23.1257","6.80836","0.01873"
"125.5830","-23.1178","6.76432","0.01880"
"126.0070","-23.1106","6.63022","0.01909"
"126.5070","-23.1025","6.72039","0.01916"
"127.0070","-23.0940","6.80479","0.01924"
"127.3840","-23.0879","6.67174","0.01950"
"127.8840","-23.0794","6.77161","0.01957"
"128.2480","-23.0736","6.65688","0.01980"
"128.7480","-23.0651","6.71677","0.01992"
"129.2480","-23.0566","6.81217","0.01998"
"129.6130","-23.0506","6.66152","0.02027"
"130.1130","-23.0424","6.75986","0.02034"
"130.6130","-23.0339","6.83298","0.02043"
"130.9560","-23.0283","6.69288","0.02070"
"131.4560","-23.0198","6.79417","0.02076"
"131.9290","-23.0118","6.78246","0.02097"
"132.3470","-23.0050","6.72951","0.02124"
"132.8470","-22.9967","6.82667","0.02129"
"133.3470","-22.9885","6.75563","0.02132"
"133.8470","-22.9800","6.85110","0.02138"
"134.3470","-22.9717","6.87423","0.02140"
"134.7250","-22.9654","6.75881","0.02136"
"135.2250","-22.9570","6.84648","0.02141"
"135.7250","-22.9488","6.92841","0.02145"
"136.2250","-22.9403","6.96302","0.02147"
"136.7250","-22.9321","6.99160","0.02150"
"137.0560","-22.9263","6.79526","0.02142"
"137.5560","-22.9184","6.88569","0.02146"
"138.0560","-22.9100","6.97225","0.02150"
"138.4920","-22.9027","6.87703","0.02147"
"138.9920","-22.8943","6.97015","0.02151"
"139.3390","-22.8883","6.79104","0.02144"
"139.8390","-22.8801","6.88807","0.02148"
"140.3390","-22.8719","6.98330","0.02152"
"140.8390","-22.8637","7.03457","0.02156"
"141.1640","-22.8580","6.87966","0.02150"
"141.5760","-22.8511","6.81021","0.02148"
"142.0760","-22.8427","6.90931","0.02152"
"142.5760","-22.8347","6.96198","0.02155"
"143.0050","-22.8274","6.89009","0.02152"
"143.5050","-22.8192","6.98491","0.02157"
"144.0050","-22.8107","7.06095","0.02161"
"144.3010","-22.8058","6.84837","0.02152"
"144.8010","-22.7975","6.94868","0.02157"
"145.3010","-22.7892","7.04102","0.02161"
"145.6100","-22.7840","6.80261","0.02151"
"146.1100","-22.7757","6.90139","0.02156"
"146.6100","-22.7671","7.00126","0.02161"
"146.9910","-22.7610","6.89243","0.02157"
"147.4140","-22.7538","6.88212","0.02156"
"147.9140","-22.7456","6.97987","0.02161"
"148.4140","-22.7375","7.03924","0.02164"
"148.8500","-22.7298","6.96431","0.02161"
"149.3500","-22.7217","7.05505","0.02166"
"149.8070","-22.7140","6.95497","0.02192"
"150.3070","-22.7058","7.01859","0.02201"
"150.7400","-22.6985","6.89902","0.02226"
"151.2400","-22.6902","6.99206","0.02233"
"151.7400","-22.6819","7.08043","0.02239"
"152.1860","-22.6742","7.03415","0.02258"
"152.5340","-22.6685","6.93071","0.02280"
"153.0340","-22.6602","7.02397","0.02287"
"153.5340","-22.6521","7.09388","0.02295"
"153.9210","-22.6454","6.95558","0.02323"
"154.4210","-22.6373","7.04645","0.02329"
"154.8710","-22.6295","7.03122","0.02345"
"155.2900","-22.6229","6.97406","0.02365"
"155.7900","-22.6145","7.06993","0.02372"
"156.2590","-22.6065","7.05133","0.02389"
"156.6760","-22.5995","6.98772","0.02411"
"157.1760","-22.5913","7.08228","0.02417"
"157.6690","-22.5830","7.06849","0.02436"
"157.9940","-22.5776","6.91945","0.02464"
"158.4940","-22.5694","7.01478","0.02470"
"158.9940","-22.5608","7.04560","0.02483"
"159.3330","-22.5552","6.93432","0.02508"
"159.8330","-22.5469","7.03262","0.02514"
"160.3330","-22.5388","7.05769","0.02528"
"160.6630","-22.5330","6.92094","0.02555"
"161.1630","-22.5250","7.01658","0.02561"
"161.6630","-22.5164","7.10913","0.02569"
"161.9520","-22.5117","6.87661","0.02604"
"162.4520","-22.5033","6.97565","0.02610"
"162.9520","-22.4949","7.07342","0.02617"
"163.3790","-22.4879","7.04368","0.02634"
"163.7080","-22.4825","6.91442","0.02659"
"164.2080","-22.4740","7.01656","0.02666"
"164.7080","-22.4658","7.10852","0.02672"
"164.9770","-22.4610","6.90067","0.02705"
"165.4770","-22.4530","6.95699","0.02715"
"165.9770","-22.4446","7.05576","0.02721"
"166.4770","-22.4362","7.13576","0.02730"
"166.7500","-22.4316","6.89191","0.02771"
"167.2500","-22.4234","6.98966","0.02778"
"167.7500","-22.4149","7.08699","0.02787"
"168.0940","-22.4093","6.96964","0.02808"
"168.5100","-22.4024","6.93144","0.02818"
"169.0100","-22.3939","7.03380","0.02823"
"169.5100","-22.3857","7.11953","0.02827"
"169.7670","-22.3812","6.86789","0.02814"
"170.2670","-22.3730","6.96469","0.02818"
"170.7670","-22.3647","7.06125","0.02823"
"171.1850","-22.3578","7.02846","0.02822"
"171.5190","-22.3521","6.91360","0.02816"
"172.0190","-22.3439","7.01126","0.02820"
"172.5190","-22.3354","7.10230","0.02825"
"172.9480","-22.3284","6.98626","0.02820"
"173.4480","-22.3201","7.08269","0.02825"
"173.9480","-22.3119","7.16916","0.02829"
"174.4480","-22.3032","7.14340","0.02832"
"174.9280","-22.2952","7.11418","0.02832"
"175.3470","-22.2884","7.06677","0.02830"
"175.8470","-22.2799","7.16184","0.02834"
"176.3470","-22.2719","7.23045","0.02839"
"176.5640","-22.2679","6.92071","0.02859"
"177.0640","-22.2597","6.98695","0.02865"
"177.5640","-22.2513","7.08475","0.02870"
"178.0640","-22.2433","7.16453","0.02875"
"178.5030","-22.2357","7.06677","0.02872"
"179.0030","-22.2276","7.15958","0.02877"
"179.5030","-22.2191","7.24340","0.02881"
"180.0030","-22.2107","7.27876","0.02884"
"180.3240","-22.2052","7.05503","0.02877"
"180.8240","-22.1972","7.12879","0.02880"
"181.3240","-22.1889","7.21936","0.02884"
"181.8240","-22.1802","7.27416","0.02887"
"182.1810","-22.1746","7.13026","0.02881"
"182.6810","-22.1661","7.22887","0.02886"
"183.1810","-22.1578","7.31313","0.02890"
"183.5300","-22.1520","7.18041","0.02886"
"183.9630","-22.1449","7.17740","0.02886"
"184.4630","-22.1364","7.27195","0.02891"
"184.9630","-22.1282","7.32428","0.02894"
"185.4630","-22.1198","7.35834","0.02900"
"185.7170","-22.1156","7.12656","0.02941"
"186.2170","-22.1073","7.22348","0.02947"
"186.7170","-22.0989","7.31678","0.02953"
"187.2170","-22.0906","7.38056","0.02960"
"187.3880","-22.0876","7.06879","0.02947"
"187.8880","-22.0792","7.16530","0.02951"
"188.3880","-22.0710","7.25865","0.02956"
"188.8860","-22.0629","7.24061","0.02956"
"189.2160","-22.0571","7.11866","0.02950"
"189.7160","-22.0489","7.21569","0.02955"
"190.2160","-22.0405","7.30655","0.02959"
"190.4830","-22.0359","7.09204","0.02950"
"190.9830","-22.0278","7.16108","0.02954"
"191.4830","-22.0196","7.25750","0.02958"
"191.9830","-22.0110","7.34939","0.02963"
"192.3090","-22.0058","7.20298","0.02984"
"192.6390","-22.0000","7.09527","0.03006"
"193.1390","-21.9919","7.19067","0.03011"
"193.6390","-21.9835","7.28319","0.03018"
"193.9980","-21.9777","7.16084","0.03041"
"194.4120","-21.9705","7.10656","0.03062"
"194.9120","-21.9625","7.20140","0.03067"
"195.4120","-21.9539","7.29608","0.03074"
"195.8120","-21.9474","7.17751","0.03099"
"196.3120","-21.9391","7.23264","0.03110"
"196.8120","-21.9306","7.32750","0.03116"
"197.1740","-21.9245","7.19985","0.03141"
"197.6740","-21.9163","7.22815","0.03156"
"198.1740","-21.9080","7.32023","0.03162"
"198.5220","-21.9021","7.19942","0.03186"
"199.0220","-21.8939","7.21191","0.03203"
"199.5220","-21.8854","7.31009","0.03209"
"199.9840","-21.8778","7.28569","0.03225"
"200.3180","-21.8721","7.16825","0.03251"
"200.8180","-21.8640","7.26292","0.03257"
"201.3180","-21.8555","7.35649","0.03264"
"201.8180","-21.8473","7.36036","0.03272"
"202.0410","-21.8431","7.03172","0.03257"
"202.5410","-21.8353","7.12137","0.03262"
"203.0410","-21.8269","7.21908","0.03266"
"203.5410","-21.8184","7.30649","0.03271"
"203.8770","-21.8129","7.09320","0.03261"
"204.3770","-21.8046","7.18780","0.03266"
"204.8770","-21.7961","7.28431","0.03271"
"205.2750","-21.7894","7.17321","0.03266"
"205.7750","-21.7814","7.22967","0.03269"
"206.2750","-21.7729","7.32814","0.03274"
"206.7750","-21.7646","7.39635","0.03279"
"207.2540","-21.7566","7.26640","0.03273"
"207.7540","-21.7484","7.33628","0.03277"
"208.1810","-21.7409","7.26355","0.03274"
"208.6030","-21.7342","7.20645","0.03275"
"209.1030","-21.7259","7.29893","0.03280"
"209.6030","-21.7173","7.37700","0.03284"
"209.9080","-21.7123","7.17507","0.03286"
"210.4080","-21.7039","7.27151","0.03291"
"210.9080","-21.6959","7.35626","0.03296"
"211.1770","-21.6912","7.14309","0.03326"
"211.6770","-21.6830","7.22599","0.03332"
"212.1770","-21.6744","7.32360","0.03337"
"212.6400","-21.6670","7.29913","0.03355"
"212.9940","-21.6608","7.20256","0.03379"
"213.4940","-21.6526","7.29649","0.03385"
"213.9940","-21.6444","7.37466","0.03392"
"214.3930","-21.6377","7.19531","0.03424"
"214.8930","-21.6291","7.29519","0.03430"
"215.3930","-21.6209","7.37806","0.03437"
"215.7250","-21.6153","7.17553","0.03469"
"216.2250","-21.6071","7.27175","0.03475"
"216.7250","-21.5989","7.36151","0.03481"
"217.1360","-21.5917","7.17520","0.03514"
"217.6360","-21.5837","7.26428","0.03520"
"218.1360","-21.5752","7.35940","0.03525"
"218.6070","-21.5674","7.27309","0.03540"
"219.1070","-21.5591","7.33349","0.03547"
"219.6070","-21.5506","7.37508","0.03553"
"220.1070","-21.5424","7.35558","0.03560"
"220.6070","-21.5340","7.40930","0.03565"
"221.1070","-21.5258","7.41396","0.03567"
"221.6070","-21.5174","7.44126","0.03572"
"222.1070","-21.5091","7.40439","0.03586"
"222.4480","-21.5033","7.20080","0.03618"
"222.9480","-21.4950","7.23287","0.03630"
"223.4480","-21.4867","7.32369","0.03637"
"223.9480","-21.4783","7.34409","0.03650"
"224.2770","-21.4728","7.19142","0.03677"
"224.7770","-21.4645","7.28835","0.03683"
"225.2770","-21.4563","7.37705","0.03689"
"225.5670","-21.4511","7.17283","0.03721"
"226.0670","-21.4432","7.22484","0.03732"
"226.5670","-21.4348","7.32442","0.03738"
"227.0670","-21.4264","7.41336","0.03745"
"227.4180","-21.4204","7.25595","0.03773"
"227.9180","-21.4123","7.34750","0.03780"
"228.4180","-21.4037","7.44368","0.03786"
"228.9180","-21.3955","7.45339","0.03789"
"229.4180","-21.3874","7.46372","0.03791"
"229.9180","-21.3788","7.51628","0.03796"
"230.4180","-21.3705","7.46059","0.03794"
"230.9180","-21.3622","7.49967","0.03797"
"231.4030","-21.3542","7.44808","0.03796"
"231.7370","-21.3485","7.31453","0.03790"
"232.2370","-21.3403","7.40774","0.03795"
"232.7370","-21.3319","7.49869","0.03800"
"233.2370","-21.3234","7.56812","0.03804"
"233.6270","-21.3170","7.36465","0.03796"
"234.1270","-21.3087","7.45720","0.03801"
"234.6270","-21.3005","7.54397","0.03805"
"235.0220","-21.2937","7.43659","0.03803"
"235.4520","-21.2868","7.43188","0.03804"
"235.9520","-21.2783","7.52570","0.03809"
"236.4350","-21.2702","7.49911","0.03812"
"236.5820","-21.2675","7.20642","0.03801"
"237.0820","-21.2596","7.29695","0.03806"
"237.5820","-21.2512","7.39469","0.03811"
"238.0820","-21.2428","7.47954","0.03818"
"238.4970","-21.2357","7.31039","0.03843"
"238.9970","-21.2276","7.40042","0.03849"
"239.4970","-21.2193","7.49220","0.03855"
"239.9970","-21.2108","7.54619","0.03865"
"240.2690","-21.2062","7.34963","0.03900"
"240.7690","-21.1979","7.44370","0.03906"
"241.2690","-21.1898","7.53326","0.03912"
"241.7420","-21.1817","7.50002","0.03914"
"242.1190","-21.1757","7.35931","0.03910"
"242.6190","-21.1671","7.45150","0.03915"
"243.1190","-21.1589","7.50687","0.03918"
"243.3740","-21.1544","7.28084","0.03908"
"243.8740","-21.1463","7.37330","0.03913"
"244.3740","-21.1380","7.46761","0.03917"
"244.8740","-21.1297","7.55230","0.03922"
"245.1360","-21.1251","7.33230","0.03912"
"245.6360","-21.1169","7.40747","0.03916"
"246.1360","-21.1086","7.50066","0.03921"
"246.6040","-21.1007","7.48056","0.03920"
"246.9440","-21.0952","7.36806","0.03915"
"247.4440","-21.0868","7.46471","0.03920"
"247.9440","-21.0784","7.54538","0.03924"
"248.3040","-21.0724","7.34923","0.03915"
"248.8040","-21.0642","7.44330","0.03919"
"249.3040","-21.0556","7.53682","0.03924"
"249.7820","-21.0480","7.43333","0.03931"
"250.2820","-21.0396","7.48271","0.03938"
"250.6930","-21.0325","7.30585","0.03931"
"251.1930","-21.0243","7.39229","0.03936"
"251.6930","-21.0160","7.48385","0.03940"
"252.1930","-21.0077","7.56436","0.03946"
"252.6520","-20.9997","7.46576","0.03972"
"253.1520","-20.9918","7.51396","0.03981"
"253.6290","-20.9837","7.38042","0.04010"
"254.1290","-20.9753","7.46778","0.04017"
"254.6290","-20.9669","7.54460","0.04025"
"254.9850","-20.9612","7.34104","0.04058"
"255.4850","-20.9526","7.43642","0.04064"
"255.9850","-20.9442","7.52850","0.04071"
"256.4000","-20.9376","7.41577","0.04096"
"256.8270","-20.9302","7.40525","0.04112"
"257.3270","-20.9222","7.49630","0.04118"
"257.8270","-20.9138","7.57997","0.04126"
"258.1290","-20.9086","7.35975","0.04160"
"258.6290","-20.9003","7.45377","0.04167"
"259.1290","-20.8921","7.54413","0.04173"
"259.5860","-20.8844","7.51488","0.04190"
"259.9270","-20.8789","7.39811","0.04215"
"260.4270","-20.8705","7.49482","0.04222"
"260.9270","-20.8620","7.58300","0.04229"
"261.2570","-20.8564","7.35452","0.04265"
"261.7570","-20.8484","7.44385","0.04272"
"262.2570","-20.8399","7.53823","0.04279"
"262.6660","-20.8330","7.42344","0.04305"
"263.0960","-20.8259","7.41087","0.04322"
"263.5960","-20.8174","7.50862","0.04328"
"264.0960","-20.8093","7.58843","0.04336"
"264.5960","-20.8009","7.49186","0.04367"
"265.0960","-20.7927","7.54045","0.04378"
"265.4860","-20.7860","7.40009","0.04408"
"265.9860","-20.7778","7.43080","0.04420"
"266.4860","-20.7694","7.52298","0.04426"
"266.9860","-20.7610","7.60519","0.04434"
"267.3190","-20.7554","7.37876","0.04469"
"267.8190","-20.7471","7.47098","0.04476"
"268.3190","-20.7389","7.56110","0.04482"
"268.8190","-20.7304","7.62707","0.04491"
"269.0830","-20.7262","7.38026","0.04526"
"269.5830","-20.7177","7.47826","0.04532"
"270.0830","-20.7096","7.56730","0.04538"
"270.4890","-20.7027","7.45266","0.04564"
"270.9090","-20.6956","7.42006","0.04582"
"271.4090","-20.6874","7.51419","0.04588"
"271.9090","-20.6791","7.59958","0.04595"
"272.2400","-20.6734","7.36272","0.04632"
"272.7400","-20.6652","7.45344","0.04638"
"273.2400","-20.6568","7.54734","0.04644"
"273.7400","-20.6483","7.53944","0.04661"
"274.0730","-20.6429","7.40265","0.04687"
"274.5730","-20.6346","7.49706","0.04693"
"275.0730","-20.6265","7.58210","0.04699"
"275.3870","-20.6209","7.37558","0.04720"
"275.8870","-20.6129","7.44249","0.04725"
"276.3870","-20.6043","7.53749","0.04730"
"276.8870","-20.5961","7.56843","0.04733"
"277.2210","-20.5906","7.41462","0.04735"
"277.7210","-20.5821","7.51045","0.04741"
"278.2210","-20.5737","7.59164","0.04746"
"278.5580","-20.5682","7.38508","0.04750"
"279.0580","-20.5598","7.48027","0.04755"
"279.5580","-20.5515","7.56925","0.04760"
"279.8990","-20.5458","7.41121","0.04752"
"280.3990","-20.5374","7.46819","0.04755"
"280.8990","-20.5293","7.55973","0.04760"
"281.3910","-20.5209","7.55253","0.04778"
"281.8910","-20.5127","7.54213","0.04788"
"282.3910","-20.5043","7.56534","0.04791"
"282.8910","-20.4960","7.59547","0.04800"
"283.3910","-20.4878","7.60866","0.04811"
"283.8910","-20.4792","7.60417","0.04813"
"284.3910","-20.4710","7.64002","0.04816"
"284.8910","-20.4627","7.65873","0.04819"
"285.3910","-20.4544","7.65556","0.04821"
"285.8910","-20.4459","7.64595","0.04822"
"286.3910","-20.4374","7.58692","0.04819"
"286.8910","-20.4295","7.65421","0.04823"
"287.3910","-20.4211","7.70405","0.04827"
"287.8910","-20.4126","7.68090","0.04827"
"288.3910","-20.4042","7.73558","0.04831"
"288.6640","-20.3997","7.47614","0.04819"
"289.1640","-20.3913","7.56316","0.04823"
"289.6640","-20.3830","7.65078","0.04827"
"290.1640","-20.3750","7.71276","0.04831"
"290.4290","-20.3702","7.47438","0.04820"
"290.9290","-20.3620","7.56221","0.04824"
"291.4290","-20.3536","7.65307","0.04829"
"291.9290","-20.3455","7.70419","0.04832"
"292.1920","-20.3410","7.48406","0.04821"
"292.6920","-20.3327","7.57588","0.04826"
"293.1920","-20.3241","7.66792","0.04830"
"293.6110","-20.3175","7.61144","0.04828"
"293.9610","-20.3113","7.50762","0.04823"
"294.4610","-20.3033","7.59683","0.04828"
"294.9610","-20.2949","7.68329","0.04832"
"295.2720","-20.2897","7.47644","0.04823"
"295.7720","-20.2812","7.55010","0.04827"
"296.2720","-20.2731","7.63978","0.04831"
"296.7720","-20.2646","7.71372","0.04834"
"297.1210","-20.2588","7.50097","0.04819"
"297.6210","-20.2506","7.59062","0.04823"
"298.1210","-20.2421","7.67948","0.04829"
"298.6210","-20.2339","7.63922","0.04832"
"299.1210","-20.2254","7.69049","0.04839"
"299.4630","-20.2198","7.48553","0.04858"
"299.9630","-20.2113","7.57865","0.04863"
"300.4630","-20.2033","7.66447","0.04869"
"300.9000","-20.1959","7.63408","0.04886"
"301.2430","-20.1901","7.51946","0.04914"
"301.7430","-20.1818","7.61228","0.04921"
"302.2430","-20.1736","7.69704","0.04927"
"302.5760","-20.1678","7.49675","0.04960"
"303.0760","-20.1597","7.55590","0.04970"
"303.5760","-20.1512","7.64969","0.04976"
"304.0760","-20.1427","7.72534","0.04984"
"304.3780","-20.1378","7.50683","0.05018"
"304.8780","-20.1295","7.59955","0.05024"
"305.3780","-20.1214","7.68647","0.05031"
"305.7920","-20.1142","7.58902","0.05054"
"306.2100","-20.1074","7.53905","0.05075"
"306.7100","-20.0989","7.63508","0.05081"
"307.2100","-20.0908","7.71642","0.05088"
"307.4830","-20.0859","7.50130","0.05121"
"307.9830","-20.0779","7.56595","0.05130"
"308.4830","-20.0695","7.65967","0.05137"
"308.9830","-20.0612","7.73545","0.05144"
"309.2550","-20.0563","7.50436","0.05179"
"309.7550","-20.0484","7.58938","0.05186"
"310.2550","-20.0400","7.68059","0.05193"
"310.7550","-20.0315","7.74869","0.05201"
"311.0640","-20.0264","7.53105","0.05235"
"311.5640","-20.0180","7.62429","0.05242"
"312.0640","-20.0098","7.71137","0.05248"
"312.5620","-20.0013","7.61833","0.05251"
"313.0620","-19.9933","7.68484","0.05256"
"313.4580","-19.9863","7.55331","0.05286"
"313.9580","-19.9783","7.58737","0.05299"
"314.4580","-19.9699","7.67179","0.05306"
"314.8730","-19.9629","7.55166","0.05334"
"315.2980","-19.9558","7.52648","0.05352"
"315.7980","-19.9476","7.61820","0.05358"
"316.2980","-19.9392","7.70308","0.05365"
"316.5820","-19.9344","7.49017","0.05399"
"317.0820","-19.9261","7.55775","0.05408"
"317.5820","-19.9176","7.65239","0.05414"
"318.0820","-19.9096","7.72451","0.05422"
"318.3960","-19.9041","7.49871","0.05458"
"318.8960","-19.8960","7.58990","0.05464"
"319.3960","-19.8875","7.68206","0.05470"
"319.7680","-19.8815","7.55814","0.05496"
"320.1900","-19.8742","7.53276","0.05512"
"320.6900","-19.8662","7.62254","0.05518"
"321.1900","-19.8577","7.70702","0.05525"
"321.4810","-19.8527","7.47359","0.05560"
"321.9810","-19.8445","7.56340","0.05566"
"322.4810","-19.8363","7.65495","0.05572"
"322.9810","-19.8277","7.68920","0.05585"
"323.3240","-19.8222","7.52912","0.05613"
"323.8240","-19.8137","7.62314","0.05619"
"324.2820","-19.8059","7.61641","0.05634"
"324.5160","-19.8022","7.37751","0.05668"
"325.0160","-19.7938","7.47451","0.05673"
"325.5160","-19.7855","7.56782","0.05680"
"326.0160","-19.7772","7.64141","0.05688"
"326.3190","-19.7720","7.43079","0.05721"
"326.8190","-19.7637","7.52477","0.05727"
"327.3190","-19.7557","7.61362","0.05733"
"327.7790","-19.7478","7.59693","0.05750"
"328.1160","-19.7423","7.47829","0.05775"
"328.6160","-19.7338","7.57570","0.05781"
"329.1160","-19.7256","7.66562","0.05787"
"329.6160","-19.7171","7.73062","0.05797"
"329.8880","-19.7128","7.50281","0.05831"
"330.3880","-19.7043","7.59860","0.05838"
"330.8880","-19.6961","7.68743","0.05845"
"331.3170","-19.6890","7.64040","0.05868"
"331.6560","-19.6832","7.52450","0.05895"
"332.1560","-19.6749","7.61648","0.05901"
"332.6560","-19.6666","7.70116","0.05907"
"332.9580","-19.6614","7.45387","0.05912"
"333.4580","-19.6533","7.54316","0.05918"
"333.9580","-19.6448","7.63619","0.05924"
"334.3390","-19.6384","7.52573","0.05920"
"334.7590","-19.6314","7.49143","0.05918"
"335.2590","-19.6232","7.58525","0.05923"
"335.7590","-19.6150","7.67074","0.05928"
"336.0180","-19.6106","7.45397","0.05919"
"336.5180","-19.6021","7.51766","0.05922"
"337.0180","-19.5936","7.61394","0.05927"
"337.5180","-19.5858","7.69212","0.05931"
"337.8300","-19.5801","7.47120","0.05921"
"338.3300","-19.5722","7.55698","0.05925"
"338.8300","-19.5637","7.65178","0.05930"
"339.3300","-19.5554","7.71716","0.05936"
"339.7780","-19.5478","7.62322","0.05957"
"340.2780","-19.5395","7.68375","0.05964"
"340.6830","-19.5328","7.52736","0.05992"
"341.1830","-19.5244","7.55800","0.06006"
"341.6830","-19.5162","7.64521","0.06012"
"342.1830","-19.5078","7.71722","0.06020"
"342.6180","-19.5006","7.54558","0.06052"
"343.1180","-19.4921","7.63295","0.06059"
"343.6180","-19.4840","7.71342","0.06066"
"344.0610","-19.4764","7.55442","0.06064"
"344.5610","-19.4680","7.63710","0.06068"
"345.0610","-19.4600","7.70726","0.06072"
"345.3180","-19.4554","7.47523","0.06063"
"345.8180","-19.4473","7.53347","0.06066"
"346.3180","-19.4388","7.62810","0.06071"
"346.8180","-19.4306","7.70924","0.06075"
"347.1470","-19.4247","7.47860","0.06064"
"347.6470","-19.4169","7.56335","0.06068"
"348.1470","-19.4086","7.65599","0.06073"
"348.6470","-19.4001","7.73010","0.06077"
"348.9240","-19.3954","7.49729","0.06066"
"349.4240","-19.3872","7.58989","0.06071"
"349.9240","-19.3786","7.68404","0.06075"
"350.3930","-19.3709","7.66022","0.06074"
"350.7240","-19.3654","7.52230","0.06068"
"351.2240","-19.3571","7.61744","0.06073"
"351.7240","-19.3488","7.70459","0.06077"
"352.1300","-19.3418","7.54259","0.06069"
"352.6300","-19.3338","7.62553","0.06074"
"353.1300","-19.3253","7.71480","0.06078"
"353.6300","-19.3171","7.63514","0.06075"
"354.1300","-19.3086","7.68266","0.06077"
"354.6300","-19.3002","7.70400","0.06078"
"355.1300","-19.2920","7.69745","0.06079"
"355.6300","-19.2837","7.73143","0.06081"
"355.9830","-19.2778","7.55872","0.06073"
"356.4830","-19.2693","7.57244","0.06074"
"356.9830","-19.2612","7.65869","0.06078"
"357.4830","-19.2528","7.74285","0.06082"
"357.8690","-19.2464","7.61864","0.06080"
"358.2870","-19.2395","7.56713","0.06083"
"358.7870","-19.2310","7.66136","0.06087"
"359.2870","-19.2226","7.74626","0.06092"
"359.6210","-19.2172","7.53928","0.06101"
"360.1210","-19.2087","7.60929","0.06108"
"360.6210","-19.2003","7.70121","0.06113"
"361.1210","-19.1924","7.77196","0.06119"
"361.3880","-19.1875","7.54292","0.06146"
"361.8880","-19.1794","7.62813","0.06152"
"362.3880","-19.1710","7.71923","0.06158"
"362.8880","-19.1628","7.70026","0.06176"
"363.2270","-19.1569","7.57832","0.06201"
"363.7270","-19.1489","7.66673","0.06206"
"364.2270","-19.1404","7.75310","0.06213"
"364.5420","-19.1352","7.54279","0.06247"
"365.0420","-19.1269","7.61291","0.06255"
"365.5420","-19.1184","7.70630","0.06261"
"366.0420","-19.1101","7.77838","0.06269"
"366.3590","-19.1049","7.56562","0.06302"
"366.8590","-19.0964","7.65863","0.06308"
"367.3590","-19.0880","7.74702","0.06315"
"367.7390","-19.0818","7.62549","0.06340"
"368.1640","-19.0746","7.60178","0.06356"
"368.6640","-19.0666","7.69015","0.06361"
"369.1640","-19.0581","7.77080","0.06368"
"369.4600","-19.0531","7.54404","0.06402"
"369.9600","-19.0447","7.63335","0.06408"
"370.4600","-19.0367","7.71872","0.06413"
"370.9460","-19.0284","7.69579","0.06431"
"371.2920","-19.0229","7.57789","0.06453"
"371.7920","-19.0144","7.67050","0.06459"
"372.2920","-19.0059","7.75581","0.06465"
"372.5740","-19.0012","7.53662","0.06497"
"373.0740","-18.9930","7.60794","0.06504"
"373.5740","-18.9845","7.70016","0.06510"
"374.0740","-18.9761","7.77154","0.06518"
"374.3730","-18.9712","7.55104","0.06549"
"374.8730","-18.9628","7.64284","0.06555"
"375.3730","-18.9547","7.72927","0.06561"
"375.8360","-18.9468","7.69926","0.06578"
"376.2530","-18.9401","7.60447","0.06600"
"376.7530","-18.9315","7.69855","0.06606"
"377.2530","-18.9234","7.77647","0.06612"
"377.7530","-18.9149","7.72854","0.06609"
"378.2530","-18.9065","7.69676","0.06623"
"378.7530","-18.8984","7.67433","0.06640"
"379.2530","-18.8899","7.74313","0.06649"
"379.5520","-18.8848","7.51962","0.06684"
"380.0520","-18.8765","7.59611","0.06692"
"380.5520","-18.8685","7.68350","0.06698"
"381.0520","-18.8600","7.76338","0.06705"
"381.4580","-18.8533","7.56804","0.06740"
"381.9580","-18.8449","7.65840","0.06747"
"382.4580","-18.8365","7.74559","0.06754"
"382.8640","-18.8296","7.62933","0.06780"
"383.2960","-18.8227","7.60890","0.06797"
"383.7960","-18.8143","7.69982","0.06803"
"384.2960","-18.8056","7.78304","0.06810"
"384.6930","-18.7994","7.57526","0.06846"
"385.1930","-18.7909","7.66740","0.06853"
"385.6930","-18.7826","7.75489","0.06860"
"386.1170","-18.7756","7.70858","0.06878"
"386.4620","-18.7699","7.59464","0.06903"
"386.9620","-18.7614","7.68727","0.06909"
"387.4620","-18.7532","7.77017","0.06916"
"387.7520","-18.7481","7.56050","0.06950"
"388.2520","-18.7400","7.62795","0.06959"
"388.7520","-18.7317","7.71829","0.06965"
"389.2520","-18.7233","7.78463","0.06975"
"389.5400","-18.7184","7.57417","0.07009"
"390.0400","-18.7102","7.66282","0.07015"
"390.5400","-18.7019","7.75081","0.07022"
"390.9560","-18.6947","7.67799","0.07043"
"391.3730","-18.6881","7.60797","0.07066"
"391.8730","-18.6795","7.70283","0.07073"
"392.3730","-18.6713","7.78453","0.07080"
"392.8730","-18.6629","7.68540","0.07108"
"393.3730","-18.6547","7.73435","0.07119"
"393.8730","-18.6462","7.77936","0.07131"
"394.3730","-18.6377","7.72848","0.07155"
"394.8730","-18.6298","7.75034","0.07169"
"395.3730","-18.6213","7.69113","0.07194"
"395.8730","-18.6129","7.73288","0.07205"
"396.3490","-18.6049","7.58989","0.07238"
"396.8490","-18.5967","7.64316","0.07247"
"397.3490","-18.5885","7.72381","0.07255"
"397.8090","-18.5804","7.69231","0.07274"
"398.1700","-18.5748","7.58139","0.07297"
"398.6700","-18.5663","7.67382","0.07303"
"399.1700","-18.5580","7.75779","0.07310"
"399.5150","-18.5522","7.61743","0.07337"
"400.0150","-18.5439","7.62936","0.07352"
"400.5150","-18.5355","7.71899","0.07358"
"401.0150","-18.5273","7.79019","0.07367"
"401.3510","-18.5216","7.57492","0.07401"
"401.8510","-18.5133","7.66507","0.07407"
"402.3510","-18.5050","7.75099","0.07413"
"402.7810","-18.4977","7.70341","0.07433"
"403.1980","-18.4908","7.61254","0.07455"
"403.6980","-18.4825","7.70351","0.07461"
"404.1980","-18.4744","7.78031","0.07469"
"404.5420","-18.4681","7.58498","0.07502"
"405.0420","-18.4603","7.63342","0.07511"
"405.5420","-18.4519","7.72222","0.07518"
"406.0420","-18.4434","7.79480","0.07526"
"406.3790","-18.4379","7.57573","0.07559"
"406.8790","-18.4296","7.66337","0.07566"
"407.3790","-18.4211","7.75312","0.07573"
"407.7980","-18.4141","7.67082","0.07595"
"408.2240","-18.4071","7.62730","0.07612"
"408.7240","-18.3987","7.71769","0.07618"
"409.2240","-18.3906","7.78729","0.07626"
"409.4800","-18.3860","7.51368","0.07665"
"409.9800","-18.3779","7.59486","0.07672"
"410.4800","-18.3694","7.68680","0.07678"
"410.9800","-18.3613","7.74890","0.07687"
"411.4800","-18.3528","7.65681","0.07714"
"411.9800","-18.3444","7.71833","0.07724"
"412.3630","-18.3380","7.53929","0.07756"
"412.8630","-18.3297","7.61756","0.07764"
"413.3630","-18.3215","7.70436","0.07771"
"413.8630","-18.3131","7.77236","0.07780"
"414.1430","-18.3084","7.54231","0.07815"
"414.6430","-18.2999","7.63318","0.07821"
"415.1430","-18.2920","7.71550","0.07828"
"415.5750","-18.2846","7.65758","0.07849"
"416.0120","-18.2773","7.62262","0.07867"
"416.5120","-18.2690","7.70944","0.07874"
"416.9910","-18.2611","7.68693","0.07892"
"417.4090","-18.2539","7.58565","0.07918"
"417.9090","-18.2456","7.67480","0.07924"
"418.4090","-18.2375","7.74893","0.07933"
"418.7640","-18.2313","7.57357","0.07964"
"419.2640","-18.2233","7.65569","0.07971"
"419.7640","-18.2148","7.74119","0.07978"
"420.1490","-18.2083","7.54348","0.08013"
"420.6490","-18.1999","7.62391","0.08022"
"421.1490","-18.1918","7.70882","0.08028"
"421.5850","-18.1844","7.63228","0.08051"
"422.0850","-18.1760","7.62870","0.08069"
"422.5850","-18.1677","7.70858","0.08077"
"422.9450","-18.1616","7.49912","0.08115"
"423.4450","-18.1534","7.57805","0.08122"
"423.9450","-18.1450","7.66671","0.08129"
"424.3850","-18.1380","7.61729","0.08149"
"424.8130","-18.1304","7.56825","0.08170"
"425.3130","-18.1224","7.65092","0.08177"
"425.8130","-18.1140","7.71531","0.08186"
"426.1700","-18.1079","7.52332","0.08220"
"426.6700","-18.0997","7.60671","0.08227"
"427.1700","-18.0914","7.69079","0.08234"
"427.6670","-18.0830","7.57840","0.08264"
"428.1670","-18.0745","7.63325","0.08275"
"428.6670","-18.0666","7.67971","0.08285"
"429.0370","-18.0602","7.51441","0.08316"
"429.5370","-18.0519","7.60184","0.08323"
"430.0370","-18.0435","7.68946","0.08329"
"430.4770","-18.0362","7.53234","0.08361"
"430.9770","-18.0278","7.59266","0.08372"
"431.4770","-18.0193","7.66496","0.08380"
"431.8980","-18.0127","7.50844","0.08410"
"432.3980","-18.0041","7.59515","0.08417"
"432.8980","-17.9959","7.67215","0.08425"
"433.3150","-17.9889","7.51271","0.08456"
"433.8150","-17.9807","7.59033","0.08464"
"434.3150","-17.9722","7.66395","0.08472"
"434.6970","-17.9659","7.48932","0.08504"
"435.1970","-17.9575","7.57422","0.08511"
"435.6970","-17.9491","7.65679","0.08519"
"436.1180","-17.9422","7.49392","0.08550"
"436.6180","-17.9338","7.57372","0.08558"
"437.1180","-17.9257","7.62482","0.08569"
"437.5070","-17.9189","7.47466","0.08600"
"438.0070","-17.9108","7.55774","0.08607"
"438.5070","-17.9024","7.63115","0.08615"
"438.9630","-17.8947","7.49247","0.08647"
"439.4630","-17.8865","7.56680","0.08655"
"439.9080","-17.8789","7.49437","0.08678"
"440.4080","-17.8708","7.48979","0.08695"
"440.9080","-17.8623","7.57701","0.08702"
"441.3820","-17.8545","7.47251","0.08730"
"441.8820","-17.8462","7.52309","0.08741"
"442.3820","-17.8377","7.55175","0.08754"
"442.8360","-17.8302","7.45053","0.08780"
"443.3360","-17.8218","7.53662","0.08787"
"443.7980","-17.8143","7.47956","0.08808"
"444.2980","-17.8058","7.48507","0.08824"
"444.7980","-17.7977","7.54930","0.08833"
"445.2980","-17.7891","7.43089","0.08864"
"445.7980","-17.7807","7.50649","0.08872"
"446.2980","-17.7726","7.43360","0.08896"
"446.7980","-17.7642","7.47537","0.08909"
"447.2980","-17.7559","7.48360","0.08924"
"447.7980","-17.7474","7.44801","0.08946"
"448.2980","-17.7391","7.49630","0.08957"
"448.7980","-17.7310","7.41847","0.08982"
"449.2980","-17.7225","7.47509","0.08993"
"449.7980","-17.7142","7.42733","0.09015"
"450.2980","-17.7058","7.45242","0.09029"
"450.7980","-17.6976","7.43508","0.09047"
"451.2980","-17.6892","7.41403","0.09066"
"451.7980","-17.6806","7.45346","0.09079"
"452.2980","-17.6727","7.36576","0.09104"
"452.7980","-17.6643","7.43417","0.09113"
"453.2980","-17.6557","7.32564","0.09142"
"453.7980","-17.6475","7.39597","0.09150"
"454.2980","-17.6391","7.39884","0.09167"
"454.7940","-17.6311","7.35026","0.09188"
"455.2940","-17.6226","7.40121","0.09199"
"455.7940","-17.6142","7.34359","0.09222"
"456.2940","-17.6058","7.36191","0.09237"
"456.7940","-17.5975","7.33790","0.09256"
"457.2940","-17.5894","7.33626","0.09273"
"457.7940","-17.5808","7.31826","0.09292"
"458.2940","-17.5727","7.33193","0.09307"
"458.7940","-17.5642","7.27976","0.09329"
"459.2940","-17.5558","7.31650","0.09343"
"459.7940","-17.5477","7.25613","0.09366"
"460.2940","-17.5393","7.28477","0.09379"
"460.7940","-17.5309","7.28201","0.09396"
"461.2940","-17.5225","7.25411","0.09416"
"461.7940","-17.5142","7.27812","0.09429"
"462.2940","-17.5061","7.23331","0.09450"
"462.7940","-17.4975","7.24670","0.09466"
"463.2940","-17.4892","7.21472","0.09486"
"463.7940","-17.4809","7.23412","0.09501"
"464.2940","-17.4727","7.18809","0.09522"
"464.7940","-17.4644","7.24213","0.09533"
"465.2940","-17.4556","7.17015","0.09558"
"465.7940","-17.4477","7.20257","0.09570"
"466.2940","-17.4393","7.16229","0.09592"
"466.7940","-17.4308","7.13659","0.09612"
"467.2940","-17.4226","7.16444","0.09625"
"467.7940","-17.4142","7.13657","0.09645"
"468.2940","-17.4060","7.12674","0.09662"
"468.7940","-17.3976","7.10470","0.09682"
"469.2940","-17.3892","7.11406","0.09698"
"469.7940","-17.3809","7.08315","0.09718"
"470.2940","-17.3725","7.07782","0.09735"
"470.7940","-17.3644","7.06616","0.09753"
"471.2940","-17.3558","7.03855","0.09773"
"471.7940","-17.3477","7.05910","0.09787"
"472.2940","-17.3392","6.99906","0.09810"
"472.7940","-17.3308","7.06043","0.09821"
"473.2940","-17.3227","6.99324","0.09844"
"473.7940","-17.3142","6.96722","0.09864"
"474.2940","-17.3060","6.99809","0.09877"
"474.7940","-17.2976","6.94523","0.09900"
"475.2940","-17.2891","6.94245","0.09917"
"475.7940","-17.2811","6.94701","0.09932"
"476.2940","-17.2725","6.89108","0.09956"
"476.7940","-17.2642","6.92148","0.09969"
"477.2940","-17.2559","6.89850","0.09988"
"477.7940","-17.2477","6.86008","0.10008"
"478.2940","-17.2392","6.86208","0.10025"
"478.7940","-17.2307","6.86832","0.10041"
"479.2940","-17.2228","6.82954","0.10062"
"479.7940","-17.2143","6.78429","0.10083"
"480.2940","-17.2059","6.83406","0.10095"
"480.7940","-17.1975","6.78546","0.10117"
"481.2940","-17.1891","6.74186","0.10139"
"481.7940","-17.1811","6.77817","0.10151"
"482.2940","-17.1726","6.73942","0.10172"
"482.7940","-17.1642","6.70919","0.10192"
"483.2940","-17.1559","6.71047","0.10209"
"483.7940","-17.1475","6.67909","0.10229"
"484.2940","-17.1393","6.63979","0.10250"
"484.7940","-17.1309","6.65785","0.10264"
"485.2940","-17.1227","6.63395","0.10284"
"485.7940","-17.1141","6.59306","0.10305"
"486.2940","-17.1057","6.58718","0.10323"
"486.7940","-17.0977","6.58246","0.10340"
"487.2940","-17.0893","6.52484","0.10363"
"487.7940","-17.0811","6.52575","0.10379"
"488.2940","-17.0725","6.52715","0.10396"
"488.7940","-17.0641","6.48836","0.10417"
"489.2940","-17.0561","6.47451","0.10435"
"489.7940","-17.0476","6.43056","0.10457"
"490.2940","-17.0392","6.41679","0.10475"
"490.7940","-17.0308","6.39019","0.10495"
"491.2940","-17.0226","6.37273","0.10513"
"491.7940","-17.0142","6.31614","0.10537"
"491.9630","-17.0115","5.94189","0.10584"
"491.9780","-17.0110","5.40596","0.10647"
"491.9940","-17.0104","4.94693","0.10701"
"492.0110","-17.0099","4.68161","0.10734"