File: Coupon Test Data/test__20250509_94834_7.csv
Time,Displacement,Force,Strain 1
(s),(mm),(kN),(mm/mm)
"0.0000","-27.3054","0.41904","-0.00050"
"0.5000","-27.2985","0.51013","-0.00047"
"1.0000","-27.2903","0.62573","-0.00042"
"1.5000","-27.2818","0.74198","-0.00037"
"2.0000","-27.2734","0.85703","-0.00032"
"2.5000","-27.2651","0.96777","-0.00027"
"3.0000","-27.2567","1.07824","-0.00023"
"3.5000","-27.2485","1.18081","-0.00019"
"4.0000","-27.2401","1.28381","-0.00014"
"4.5000","-27.2316","1.38134","-0.00010"
"5.0000","-27.2234","1.48541","-0.00006"
"5.5000","-27.2151","1.58974","-0.00001"
"6.0000","-27.2068","1.68662","0.00003"
"6.5000","-27.1983","1.78910","0.00007"
"7.0000","-27.1901","1.89190","0.00011"
"7.5000","-27.1818","1.99386","0.00016"
"8.0000","-27.1733","2.08859","0.00020"
"8.5000","-27.1651","2.18989","0.00024"
"9.0000","-27.1567","2.29181","0.00028"
"9.5000","-27.1485","2.38427","0.00032"
"10.0000","-27.1400","2.48685","0.00036"
"10.5000","-27.1315","2.58881","0.00041"
"11.0000","-27.1236","2.67533","0.00044"
"11.5000","-27.1152","2.77500","0.00049"
"12.0000","-27.1067","2.87662","0.00053"
"12.5000","-27.0983","2.96845","0.00057"
"13.0000","-27.0901","3.06426","0.00061"
"13.5000","-27.0819","3.16002","0.00065"
"14.0000","-27.0733","3.25280","0.00069"
"14.5000","-27.0651","3.34852","0.00073"
"15.0000","-27.0567","3.44081","0.00077"
"15.5000","-27.0484","3.53395","0.00081"
"16.0000","-27.0402","3.62719","0.00085"
"16.5000","-27.0317","3.71847","0.00088"
"17.0000","-27.0235","3.81042","0.00092"
"17.5000","-27.0151","3.90002","0.00096"
"18.0000","-27.0066","3.99421","0.00100"
"18.5000","-26.9985","4.08034","0.00104"
"19.0000","-26.9900","4.17287","0.00108"
"19.5000","-26.9817","4.26110","0.00111"
"20.0000","-26.9733","4.35122","0.00115"
"20.5000","-26.9651","4.43784","0.00119"
"21.0000","-26.9568","4.52547","0.00123"
"21.5000","-26.9483","4.61462","0.00127"
"22.0000","-26.9401","4.69914","0.00130"
"22.5000","-26.9317","4.78360","0.00134"
"23.0000","-26.9235","4.86678","0.00138"
"23.5000","-26.9150","4.95057","0.00142"
"24.0000","-26.9065","5.03496","0.00146"
"24.5000","-26.8986","5.10695","0.00149"
"25.0000","-26.8901","5.18456","0.00154"
"25.5000","-26.8817","5.26028","0.00158"
"26.0000","-26.8733","5.33127","0.00162"
"26.5000","-26.8651","5.39923","0.00167"
"27.0000","-26.8568","5.45955","0.00172"
"27.5000","-26.8483","5.52386","0.00177"
"28.0000","-26.8401","5.58157","0.00183"
"28.5000","-26.8317","5.63270","0.00188"
"29.0000","-26.8233","5.68540","0.00194"
"29.5000","-26.8151","5.73092","0.00201"
"30.0000","-26.8066","5.77839","0.00207"
"30.5000","-26.7985","5.81362","0.00213"
"31.0000","-26.7901","5.85441","0.00220"
"31.5000","-26.7816","5.89397","0.00228"
"32.0000","-26.7734","5.92485","0.00235"
"32.5000","-26.7650","5.95725","0.00243"
"33.0000","-26.7568","5.98683","0.00250"
"33.5000","-26.7484","6.01522","0.00258"
"34.0000","-26.7401","6.03890","0.00265"
"34.5000","-26.7317","6.06394","0.00273"
"35.0000","-26.7232","6.08821","0.00282"
"35.5000","-26.7151","6.10849","0.00290"
"36.0000","-26.7067","6.12907","0.00298"
"36.5000","-26.6985","6.14883","0.00307"
"37.0000","-26.6899","6.16781","0.00316"
"37.5000","-26.6814","6.18868","0.00325"
"38.0000","-26.6736","6.19978","0.00333"
"38.5000","-26.6652","6.21596","0.00342"
"39.0000","-26.6567","6.23464","0.00351"
"39.5000","-26.6482","6.24911","0.00360"
"40.0000","-26.6400","6.26221","0.00368"
"40.5000","-26.6318","6.27271","0.00377"
"41.0000","-26.6233","6.28732","0.00386"
"41.5000","-26.6151","6.30096","0.00395"
"42.0000","-26.6067","6.31279","0.00404"
"42.5000","-26.5983","6.32375","0.00413"
"43.0000","-26.5901","6.32712","0.00421"
"43.5000","-26.5816","6.34902","0.00430"
"44.0000","-26.5735","6.35606","0.00439"
"44.5000","-26.5650","6.36451","0.00448"
"45.0000","-26.5565","6.37711","0.00457"
"45.5000","-26.5484","6.38350","0.00467"
"46.0000","-26.5400","6.39352","0.00476"
"46.5000","-26.5318","6.40262","0.00485"
"47.0000","-26.5233","6.41294","0.00495"
"47.5000","-26.5150","6.42140","0.00504"
"48.0000","-26.5067","6.42834","0.00513"
"48.5000","-26.4983","6.43953","0.00522"
"49.0000","-26.4901","6.44655","0.00531"
"49.5000","-26.4817","6.45529","0.00541"
"50.0000","-26.4734","6.46207","0.00550"
"50.5000","-26.4650","6.47107","0.00559"
"51.0000","-26.4565","6.48265","0.00568"
"51.5000","-26.4487","6.48429","0.00577"
"52.0000","-26.4401","6.49271","0.00586"
"52.5000","-26.4316","6.50323","0.00596"
"53.0000","-26.4233","6.51036","0.00604"
"53.5000","-26.4150","6.51741","0.00613"
"54.0000","-26.4069","6.52178","0.00622"
"54.5000","-26.3983","6.53125","0.00631"
"55.0000","-26.3900","6.53884","0.00641"
"55.5000","-26.3817","6.54547","0.00650"
"56.0000","-26.3734","6.55152","0.00658"
"56.5000","-26.3651","6.55729","0.00668"
"57.0000","-26.3566","6.56835","0.00677"
"57.5000","-26.3485","6.57154","0.00686"
"58.0000","-26.3400","6.57814","0.00696"
"58.5000","-26.3316","6.58768","0.00705"
"59.0000","-26.3235","6.59094","0.00715"
"59.5000","-26.3149","6.59875","0.00725"
"60.0000","-26.3067","6.60416","0.00734"
"60.5000","-26.2983","6.61097","0.00744"
"61.0000","-26.2900","6.61814","0.00754"
"61.5000","-26.2818","6.62224","0.00764"
"62.0000","-26.2733","6.63170","0.00773"
"62.5000","-26.2650","6.63679","0.00783"
"63.0000","-26.2568","6.64166","0.00792"
"63.5000","-26.2485","6.64690","0.00801"
"64.0000","-26.2399","6.65464","0.00809"
"64.5000","-26.2315","6.66284","0.00818"
"65.0000","-26.2236","6.66095","0.00826"
"65.5000","-26.2150","6.66763","0.00833"
"66.0000","-26.2067","6.67570","0.00840"
"66.5000","-26.1983","6.68168","0.00847"
"67.0000","-26.1900","6.68918","0.00854"
"67.5000","-26.1819","6.68673","0.00860"
"68.0000","-26.1733","6.60813","0.00861"
"68.5000","-26.1650","6.67090","0.00865"
"69.0000","-26.1568","6.71562","0.00871"
"69.4890","-26.1485","6.61650","0.00869"
"69.9890","-26.1402","6.69507","0.00874"
"70.4540","-26.1323","6.60577","0.00871"
"70.9540","-26.1243","6.68829","0.00876"
"71.3910","-26.1167","6.59721","0.00874"
"71.8910","-26.1086","6.68371","0.00879"
"72.3270","-26.1013","6.61518","0.00888"
"72.8270","-26.0929","6.68278","0.00895"
"73.2600","-26.0856","6.64819","0.00912"
"73.7600","-26.0773","6.67695","0.00925"
"74.2150","-26.0699","6.65469","0.00941"
"74.7150","-26.0613","6.68631","0.00955"
"75.1660","-26.0540","6.65893","0.00971"
"75.6660","-26.0457","6.68787","0.00984"
"76.1190","-26.0380","6.66887","0.01000"
"76.6190","-26.0296","6.69291","0.01015"
"77.0800","-26.0221","6.67163","0.01031"
"77.5800","-26.0138","6.69373","0.01045"
"78.0160","-26.0062","6.67464","0.01062"
"78.5160","-25.9983","6.69123","0.01076"
"78.9550","-25.9908","6.67125","0.01093"
"79.4550","-25.9825","6.70201","0.01107"
"79.9550","-25.9740","6.63023","0.01132"
"80.4550","-25.9658","6.72053","0.01138"
"80.8840","-25.9585","6.63325","0.01162"
"81.3840","-25.9501","6.72772","0.01169"
"81.8140","-25.9433","6.63031","0.01193"
"82.3140","-25.9348","6.72617","0.01200"
"82.8140","-25.9264","6.64825","0.01226"
"83.3140","-25.9181","6.74211","0.01233"
"83.7550","-25.9109","6.67401","0.01255"
"84.2550","-25.9024","6.77037","0.01261"
"84.6750","-25.8953","6.65154","0.01261"
"85.1750","-25.8873","6.74148","0.01266"
"85.6750","-25.8787","6.81550","0.01270"
"86.0860","-25.8720","6.70233","0.01267"
"86.5860","-25.8637","6.78461","0.01271"
"87.0580","-25.8558","6.72128","0.01268"
"87.5560","-25.8473","6.71595","0.01269"
"88.0560","-25.8390","6.73095","0.01270"
"88.5320","-25.8313","6.71946","0.01271"
"89.0320","-25.8228","6.75959","0.01273"
"89.5320","-25.8146","6.82766","0.01277"
"89.9680","-25.8073","6.74636","0.01278"
"90.4680","-25.7990","6.83017","0.01284"
"90.9680","-25.7904","6.85339","0.01290"
"91.4680","-25.7821","6.86063","0.01301"
"91.9680","-25.7742","6.90089","0.01307"
"92.4680","-25.7656","6.89039","0.01308"
"92.9490","-25.7575","6.80213","0.01305"
"93.4490","-25.7492","6.89817","0.01310"
"93.9490","-25.7410","6.97286","0.01313"
"94.3390","-25.7343","6.84070","0.01309"
"94.8390","-25.7259","6.85825","0.01310"
"95.3390","-25.7179","6.94818","0.01314"
"95.8210","-25.7096","6.89095","0.01312"
"96.3210","-25.7013","6.98163","0.01317"
"96.6940","-25.6951","6.82384","0.01310"
"97.1940","-25.6870","6.92119","0.01315"
"97.6940","-25.6783","7.01720","0.01320"
"98.0530","-25.6725","6.83230","0.01312"
"98.5530","-25.6641","6.93125","0.01317"
"99.0530","-25.6557","7.02684","0.01321"
"99.4600","-25.6490","6.84076","0.01316"
"99.9600","-25.6406","6.94048","0.01321"
"100.4600","-25.6324","7.03213","0.01326"
"100.8750","-25.6253","6.86540","0.01350"
"101.3750","-25.6172","6.96348","0.01356"
"101.8750","-25.6089","7.05316","0.01362"
"102.1530","-25.6043","6.85340","0.01391"
"102.6530","-25.5959","6.95437","0.01398"
"103.1530","-25.5875","7.04678","0.01404"
"103.5690","-25.5804","6.89516","0.01434"
"104.0690","-25.5723","6.99340","0.01439"
"104.5460","-25.5643","6.98315","0.01455"
"104.9610","-25.5572","6.92563","0.01476"
"105.4610","-25.5492","7.01912","0.01482"
"105.8520","-25.5423","6.91605","0.01506"
"106.3520","-25.5343","6.94328","0.01520"
"106.8520","-25.5260","7.04033","0.01526"
"107.2540","-25.5192","6.87619","0.01557"
"107.7540","-25.5107","6.97658","0.01564"
"108.2540","-25.5025","7.06811","0.01570"
"108.6160","-25.4964","6.89037","0.01602"
"109.1160","-25.4880","6.99123","0.01607"
"109.6160","-25.4799","7.06486","0.01615"
"109.9560","-25.4741","6.91958","0.01644"
"110.4560","-25.4658","7.01851","0.01649"
"110.8700","-25.4588","6.91469","0.01674"
"111.3700","-25.4507","6.95907","0.01687"
"111.8700","-25.4422","7.05756","0.01693"
"112.2310","-25.4364","6.88397","0.01723"
"112.7310","-25.4279","6.98483","0.01730"
"113.2310","-25.4194","7.07789","0.01736"
"113.5670","-25.4139","6.90475","0.01766"
"114.0670","-25.4057","7.00435","0.01773"
"114.5670","-25.3972","7.08171","0.01781"
"114.9100","-25.3916","6.92737","0.01809"
"115.4100","-25.3831","7.02820","0.01815"
"115.9010","-25.3748","6.93859","0.01842"
"116.4010","-25.3668","7.03091","0.01848"
"116.9010","-25.3584","7.07958","0.01853"
"117.3500","-25.3510","7.03843","0.01854"
"117.8500","-25.3425","7.10963","0.01858"
"118.3370","-25.3344","7.03341","0.01855"
"118.8370","-25.3261","7.12646","0.01860"
"119.1650","-25.3205","6.91003","0.01852"
"119.6650","-25.3123","7.00782","0.01857"
"120.1650","-25.3039","7.09908","0.01861"
"120.5360","-25.2976","6.95153","0.01855"
"121.0360","-25.2894","7.05049","0.01860"
"121.5360","-25.2813","7.11113","0.01863"
"121.8730","-25.2753","6.97230","0.01857"
"122.3730","-25.2674","7.06623","0.01861"
"122.7590","-25.2606","6.96724","0.01859"
"123.2590","-25.2524","7.03843","0.01862"
"123.7590","-25.2441","7.13412","0.01867"
"124.1900","-25.2369","6.95846","0.01870"
"124.6900","-25.2285","7.05177","0.01876"
"125.1900","-25.2201","7.13959","0.01883"
"125.6330","-25.2129","7.06976","0.01903"
"126.1330","-25.2043","7.16971","0.01908"
"126.6330","-25.1962","7.22257","0.01912"
"127.1330","-25.1879","7.23817","0.01914"
"127.6330","-25.1796","7.21680","0.01914"
"127.9640","-25.1739","7.09058","0.01909"
"128.4640","-25.1657","7.18836","0.01914"
"128.9640","-25.1573","7.27525","0.01918"
"129.3010","-25.1517","7.14420","0.01913"
"129.8010","-25.1433","7.16815","0.01914"
"130.3010","-25.1349","7.26356","0.01919"
"130.6320","-25.1293","7.13468","0.01913"
"131.1320","-25.1211","7.16547","0.01915"
"131.6320","-25.1130","7.25979","0.01919"
"132.0230","-25.1060","7.15447","0.01915"
"132.4470","-25.0995","7.14065","0.01915"
"132.9470","-25.0910","7.24405","0.01919"
"133.4470","-25.0825","7.33117","0.01924"
"133.7480","-25.0774","7.10008","0.01914"
"134.2480","-25.0693","7.19379","0.01918"
"134.7480","-25.0609","7.28974","0.01923"
"135.1830","-25.0537","7.24659","0.01922"
"135.6830","-25.0452","7.27447","0.01924"
"136.1830","-25.0368","7.35056","0.01928"
"136.4550","-25.0324","7.12891","0.01923"
"136.9550","-25.0241","7.22775","0.01927"
"137.4550","-25.0159","7.31812","0.01934"
"137.7200","-25.0114","7.10831","0.01970"
"138.2200","-25.0029","7.19851","0.01976"
"138.7200","-24.9945","7.29750","0.01982"
"139.2030","-24.9869","7.27998","0.01997"
"139.5360","-24.9810","7.16655","0.02022"
"140.0360","-24.9729","7.26255","0.02027"
"140.5360","-24.9645","7.35027","0.02035"
"140.8590","-24.9590","7.14823","0.02067"
"141.3590","-24.9506","7.25007","0.02072"
"141.8590","-24.9425","7.34130","0.02079"
"142.1290","-24.9376","7.14016","0.02110"
"142.6290","-24.9298","7.20443","0.02119"
"143.1290","-24.9213","7.30570","0.02125"
"143.6290","-24.9128","7.36691","0.02134"
"143.8760","-24.9087","7.15525","0.02166"
"144.3760","-24.9006","7.25339","0.02172"
"144.8760","-24.8921","7.34940","0.02178"
"145.1950","-24.8869","7.14174","0.02210"
"145.6950","-24.8784","7.22106","0.02220"
"146.1950","-24.8701","7.32015","0.02226"
"146.6870","-24.8619","7.30398","0.02242"
"147.0170","-24.8563","7.18336","0.02268"
"147.5170","-24.8481","7.28306","0.02274"
"148.0170","-24.8398","7.37145","0.02281"
"148.3460","-24.8341","7.16906","0.02315"
"148.8460","-24.8257","7.26922","0.02321"
"149.3460","-24.8178","7.35744","0.02327"
"149.6320","-24.8127","7.15521","0.02359"
"150.1320","-24.8046","7.22857","0.02368"
"150.6320","-24.7961","7.32842","0.02375"
"151.0910","-24.7886","7.30874","0.02391"
"151.4310","-24.7827","7.20537","0.02415"
"151.9310","-24.7747","7.30027","0.02421"
"152.4310","-24.7662","7.38280","0.02429"
"152.8290","-24.7597","7.21371","0.02461"
"153.3290","-24.7513","7.31147","0.02467"
"153.8260","-24.7428","7.30173","0.02485"
"154.2480","-24.7358","7.25928","0.02504"
"154.7480","-24.7276","7.35106","0.02511"
"155.1460","-24.7209","7.20097","0.02541"
"155.6460","-24.7124","7.29759","0.02547"
"156.1460","-24.7044","7.38174","0.02554"
"156.6080","-24.6966","7.28220","0.02581"
"157.1080","-24.6882","7.37615","0.02588"
"157.6080","-24.6798","7.30948","0.02589"
"158.1080","-24.6716","7.39122","0.02593"
"158.6080","-24.6634","7.37865","0.02605"
"159.1080","-24.6548","7.32072","0.02613"
"159.6080","-24.6467","7.36445","0.02616"
"160.1080","-24.6383","7.32746","0.02616"
"160.6080","-24.6299","7.35329","0.02618"
"161.0900","-24.6219","7.33243","0.02617"
"161.5280","-24.6145","7.31660","0.02617"
"162.0280","-24.6064","7.40152","0.02621"
"162.3670","-24.6003","7.24468","0.02614"
"162.8670","-24.5926","7.33569","0.02618"
"163.3330","-24.5845","7.32569","0.02618"
"163.7530","-24.5775","7.28052","0.02617"
"164.2530","-24.5692","7.37795","0.02621"
"164.6490","-24.5626","7.26568","0.02617"
"165.1490","-24.5542","7.30274","0.02619"
"165.6490","-24.5459","7.39924","0.02624"
"166.1490","-24.5377","7.42072","0.02626"
"166.6490","-24.5291","7.49700","0.02631"
"167.1490","-24.5209","7.52798","0.02636"
"167.6490","-24.5126","7.53042","0.02639"
"168.1490","-24.5043","7.57632","0.02643"
"168.6490","-24.4958","7.53068","0.02641"
"169.1490","-24.4873","7.43918","0.02638"
"169.6490","-24.4794","7.51300","0.02641"
"170.1490","-24.4710","7.57777","0.02646"
"170.4580","-24.4658","7.33782","0.02635"
"170.9580","-24.4574","7.43152","0.02639"
"171.4580","-24.4492","7.52263","0.02644"
"171.9150","-24.4413","7.49709","0.02643"
"172.3350","-24.4345","7.43855","0.02640"
"172.8350","-24.4262","7.53101","0.02645"
"173.2570","-24.4188","7.39063","0.02639"
"173.7570","-24.4108","7.48024","0.02643"
"174.2570","-24.4024","7.56659","0.02647"
"174.5980","-24.3967","7.37338","0.02639"
"175.0980","-24.3884","7.47279","0.02643"
"175.5980","-24.3803","7.56398","0.02647"
"175.9190","-24.3745","7.35994","0.02639"
"176.4190","-24.3665","7.40569","0.02641"
"176.9190","-24.3582","7.50511","0.02645"
"177.4190","-24.3497","7.58689","0.02649"
"177.7080","-24.3449","7.34798","0.02639"
"178.2080","-24.3367","7.44390","0.02643"
"178.7080","-24.3281","7.53798","0.02647"
"179.1420","-24.3209","7.42672","0.02643"
"179.6420","-24.3128","7.51905","0.02648"
"180.1420","-24.3043","7.51974","0.02651"
"180.4900","-24.2986","7.41964","0.02655"
"180.9900","-24.2902","7.52034","0.02661"
"181.4900","-24.2819","7.60808","0.02667"
"181.8170","-24.2762","7.37516","0.02707"
"182.3170","-24.2682","7.46668","0.02713"
"182.8170","-24.2598","7.56496","0.02718"
"183.3170","-24.2514","7.64275","0.02725"
"183.6050","-24.2466","7.40914","0.02760"
"184.1050","-24.2382","7.50774","0.02766"
"184.6050","-24.2298","7.60077","0.02772"
"184.9600","-24.2241","7.40602","0.02804"
"185.4600","-24.2157","7.49912","0.02811"
"185.9600","-24.2072","7.59213","0.02817"
"186.3880","-24.2003","7.46378","0.02845"
"186.8880","-24.1917","7.56209","0.02851"
"187.3880","-24.1836","7.62510","0.02860"
"187.6580","-24.1789","7.43076","0.02891"
"188.1580","-24.1709","7.52601","0.02897"
"188.6580","-24.1624","7.62173","0.02903"
"189.0400","-24.1561","7.49914","0.02927"
"189.4580","-24.1489","7.46358","0.02946"
"189.9580","-24.1408","7.55890","0.02952"
"190.4580","-24.1325","7.64574","0.02959"
"190.7750","-24.1271","7.41821","0.02995"
"191.2750","-24.1187","7.51322","0.03001"
"191.7750","-24.1106","7.60536","0.03007"
"192.1630","-24.1038","7.49614","0.03032"
"192.6630","-24.0956","7.52555","0.03046"
"193.1630","-24.0876","7.61302","0.03053"
"193.5150","-24.0812","7.44756","0.03084"
"194.0150","-24.0732","7.53766","0.03091"
"194.5150","-24.0647","7.62900","0.03098"
"194.8480","-24.0592","7.42919","0.03131"
"195.3480","-24.0509","7.52508","0.03138"
"195.8480","-24.0427","7.61784","0.03144"
"196.2510","-24.0358","7.51141","0.03169"
"196.6720","-24.0289","7.48635","0.03186"
"197.1720","-24.0206","7.58308","0.03192"
"197.6720","-24.0122","7.66801","0.03199"
"197.9470","-24.0076","7.43832","0.03234"
"198.4470","-23.9994","7.53104","0.03240"
"198.9470","-23.9907","7.62904","0.03247"
"199.3630","-23.9840","7.57884","0.03265"
"199.7780","-23.9770","7.50364","0.03288"
"200.2780","-23.9686","7.60044","0.03294"
"200.7780","-23.9606","7.67384","0.03302"
"201.1060","-23.9548","7.48014","0.03335"
"201.6060","-23.9467","7.57382","0.03341"
"202.1060","-23.9382","7.66161","0.03348"
"202.5080","-23.9317","7.47888","0.03382"
"203.0080","-23.9233","7.57552","0.03388"
"203.5080","-23.9150","7.66124","0.03395"
"204.0080","-23.9065","7.58239","0.03422"
"204.5080","-23.8982","7.64751","0.03431"
"204.8630","-23.8921","7.46044","0.03468"
"205.3630","-23.8841","7.54507","0.03475"
"205.8630","-23.8759","7.63617","0.03481"
"206.3630","-23.8672","7.70320","0.03487"
"206.6510","-23.8626","7.48284","0.03492"
"207.1510","-23.8540","7.58156","0.03498"
"207.6510","-23.8459","7.66942","0.03503"
"207.9980","-23.8399","7.46436","0.03495"
"208.4980","-23.8319","7.55622","0.03500"
"208.9980","-23.8234","7.65320","0.03504"
"209.4600","-23.8157","7.62954","0.03504"
"209.7980","-23.8100","7.51505","0.03499"
"210.2980","-23.8017","7.61182","0.03504"
"210.7980","-23.7934","7.69503","0.03508"
"211.0830","-23.7885","7.48316","0.03498"
"211.5830","-23.7802","7.57800","0.03503"
"212.0830","-23.7720","7.66721","0.03507"
"212.5000","-23.7648","7.48524","0.03500"
"213.0000","-23.7565","7.57726","0.03504"
"213.5000","-23.7487","7.66222","0.03508"
"213.9260","-23.7412","7.54269","0.03504"
"214.4260","-23.7329","7.63419","0.03508"
"214.9260","-23.7246","7.71954","0.03513"
"215.3140","-23.7182","7.57271","0.03508"
"215.8140","-23.7098","7.66244","0.03512"
"216.3140","-23.7013","7.73263","0.03516"
"216.8140","-23.6933","7.74771","0.03519"
"217.2940","-23.6850","7.68066","0.03517"
"217.7940","-23.6768","7.75256","0.03521"
"218.2940","-23.6684","7.66572","0.03518"
"218.7940","-23.6603","7.73532","0.03521"
"219.2940","-23.6518","7.78949","0.03524"
"219.7940","-23.6432","7.72116","0.03521"
"220.2940","-23.6354","7.79566","0.03525"
"220.7940","-23.6270","7.84696","0.03528"
"221.0920","-23.6219","7.58722","0.03517"
"221.5920","-23.6136","7.67902","0.03521"
"222.0920","-23.6052","7.77072","0.03526"
"222.5920","-23.5967","7.82558","0.03529"
"222.9320","-23.5912","7.67927","0.03522"
"223.3520","-23.5842","7.65362","0.03521"
"223.8520","-23.5758","7.75056","0.03526"
"224.3520","-23.5675","7.82634","0.03530"
"224.6560","-23.5623","7.61226","0.03520"
"225.1560","-23.5540","7.70978","0.03524"
"225.6560","-23.5458","7.80075","0.03529"
"225.9620","-23.5405","7.59102","0.03519"
"226.4620","-23.5322","7.66736","0.03523"
"226.9620","-23.5242","7.75889","0.03527"
"227.4620","-23.5157","7.84235","0.03531"
"227.7150","-23.5114","7.59718","0.03520"
"228.2150","-23.5031","7.69115","0.03524"
"228.7150","-23.4950","7.78258","0.03529"
"229.1280","-23.4878","7.68005","0.03524"
"229.5540","-23.4809","7.66288","0.03523"
"230.0540","-23.4725","7.76028","0.03528"
"230.5540","-23.4642","7.80601","0.03531"
"230.8830","-23.4588","7.62751","0.03523"
"231.3830","-23.4503","7.72637","0.03527"
"231.8830","-23.4418","7.81687","0.03531"
"232.2270","-23.4362","7.61911","0.03524"
"232.7270","-23.4278","7.71399","0.03528"
"233.2270","-23.4194","7.80724","0.03533"
"233.5650","-23.4139","7.66614","0.03541"
"234.0650","-23.4055","7.70104","0.03548"
"234.5650","-23.3974","7.79245","0.03553"
"235.0650","-23.3890","7.81566","0.03562"
"235.5650","-23.3807","7.74218","0.03587"
"236.0650","-23.3722","7.73496","0.03608"
"236.5650","-23.3638","7.82702","0.03614"
"236.9920","-23.3568","7.79171","0.03631"
"237.3250","-23.3512","7.66961","0.03656"
"237.8250","-23.3429","7.76550","0.03662"
"238.3250","-23.3346","7.85530","0.03669"
"238.6140","-23.3297","7.64881","0.03700"
"239.1140","-23.3215","7.71360","0.03710"
"239.6140","-23.3133","7.80664","0.03716"
"240.0490","-23.3056","7.79280","0.03732"
"240.3810","-23.3004","7.66028","0.03758"
"240.8810","-23.2919","7.76000","0.03764"
"241.3810","-23.2838","7.84926","0.03770"
"241.6980","-23.2783","7.64660","0.03803"
"242.1980","-23.2702","7.71003","0.03813"
"242.6980","-23.2617","7.80701","0.03819"
"243.1980","-23.2535","7.87370","0.03828"
"243.4770","-23.2486","7.67502","0.03860"
"243.9770","-23.2406","7.76778","0.03866"
"244.4770","-23.2321","7.85841","0.03873"
"244.8290","-23.2261","7.66298","0.03907"
"245.3290","-23.2178","7.75507","0.03914"
"245.8290","-23.2097","7.84606","0.03920"
"246.2670","-23.2022","7.78743","0.03939"
"246.6890","-23.1951","7.73477","0.03959"
"247.1890","-23.1871","7.82379","0.03965"
"247.6870","-23.1786","7.80933","0.03983"
"248.0250","-23.1730","7.69388","0.04008"
"248.5250","-23.1647","7.79081","0.04014"
"249.0250","-23.1564","7.87696","0.04021"
"249.3510","-23.1507","7.65114","0.04058"
"249.8510","-23.1426","7.74226","0.04065"
"250.3510","-23.1342","7.83709","0.04071"
"250.8120","-23.1265","7.81805","0.04088"
"251.1440","-23.1211","7.68730","0.04115"
"251.6440","-23.1126","7.78576","0.04121"
"252.1440","-23.1042","7.87696","0.04128"
"252.4510","-23.0992","7.66398","0.04161"
"252.9510","-23.0907","7.74523","0.04170"
"253.4510","-23.0824","7.84015","0.04176"
"253.9510","-23.0745","7.89464","0.04185"
"254.2940","-23.0683","7.71797","0.04218"
"254.7940","-23.0602","7.80956","0.04224"
"255.2940","-23.0518","7.89507","0.04231"
"255.6290","-23.0462","7.68382","0.04266"
"256.1290","-23.0379","7.77808","0.04273"
"256.6290","-23.0297","7.86777","0.04279"
"257.0150","-23.0230","7.75495","0.04305"
"257.4500","-23.0159","7.74534","0.04320"
"257.9500","-23.0076","7.83916","0.04327"
"258.4500","-22.9992","7.89860","0.04338"
"258.9500","-22.9909","7.79506","0.04366"
"259.4500","-22.9824","7.87270","0.04374"
"259.8280","-22.9762","7.70838","0.04405"
"260.3280","-22.9677","7.76948","0.04416"
"260.8280","-22.9597","7.85340","0.04423"
"261.3280","-22.9513","7.84622","0.04439"
"261.6920","-22.9451","7.71524","0.04465"
"262.1920","-22.9368","7.80598","0.04472"
"262.6920","-22.9286","7.88966","0.04479"
"263.0110","-22.9230","7.67970","0.04512"
"263.5110","-22.9149","7.75202","0.04521"
"264.0110","-22.9067","7.84512","0.04527"
"264.5110","-22.8981","7.92942","0.04536"
"264.8020","-22.8932","7.71100","0.04580"
"265.3020","-22.8849","7.80279","0.04586"
"265.8020","-22.8769","7.89167","0.04591"
"266.2550","-22.8691","7.87075","0.04597"
"266.5870","-22.8637","7.73724","0.04598"
"267.0870","-22.8551","7.83746","0.04604"
"267.5870","-22.8470","7.92203","0.04609"
"267.8650","-22.8420","7.70366","0.04600"
"268.3650","-22.8340","7.77755","0.04604"
"268.8650","-22.8257","7.87051","0.04608"
"269.3650","-22.8174","7.89872","0.04610"
"269.6990","-22.8116","7.73379","0.04603"
"270.1990","-22.8034","7.82724","0.04608"
"270.6990","-22.7950","7.91453","0.04612"
"270.9800","-22.7903","7.69478","0.04602"
"271.4800","-22.7821","7.77468","0.04606"
"271.9800","-22.7737","7.86881","0.04610"
"272.4800","-22.7654","7.92429","0.04614"
"272.8400","-22.7594","7.74879","0.04606"
"273.3400","-22.7512","7.84040","0.04611"
"273.8400","-22.7426","7.92464","0.04616"
"274.2870","-22.7355","7.78286","0.04611"
"274.7870","-22.7270","7.87219","0.04616"
"275.2870","-22.7185","7.95110","0.04621"
"275.7870","-22.7102","7.87438","0.04619"
"276.2870","-22.7019","7.94002","0.04623"
"276.7870","-22.6938","7.90149","0.04622"
"277.2870","-22.6852","7.94209","0.04624"
"277.7870","-22.6769","7.96967","0.04627"
"278.2870","-22.6685","7.94133","0.04626"
"278.7870","-22.6602","8.00211","0.04630"
"279.2870","-22.6521","7.98563","0.04630"
"279.7870","-22.6435","7.99094","0.04631"
"280.2710","-22.6356","7.94300","0.04629"
"280.6060","-22.6298","7.80329","0.04623"
"281.1060","-22.6217","7.89220","0.04627"
"281.6060","-22.6134","7.97769","0.04632"
"282.0600","-22.6056","7.94611","0.04631"
"282.3920","-22.6002","7.80953","0.04624"
"282.8920","-22.5919","7.90348","0.04629"
"283.3920","-22.5834","7.99289","0.04633"
"283.7840","-22.5769","7.87553","0.04628"
"284.2030","-22.5700","7.83782","0.04626"
"284.7030","-22.5615","7.93404","0.04631"
"285.2030","-22.5534","8.01534","0.04635"
"285.4680","-22.5488","7.79083","0.04625"
"285.9680","-22.5406","7.86174","0.04629"
"286.4680","-22.5322","7.95660","0.04633"
"286.9680","-22.5241","8.02883","0.04637"
"287.3010","-22.5180","7.81355","0.04627"
"287.8010","-22.5102","7.90169","0.04631"
"288.3010","-22.5018","7.99149","0.04635"
"288.7160","-22.4947","7.87927","0.04630"
"289.2160","-22.4864","7.87930","0.04630"
"289.7160","-22.4782","7.96932","0.04634"
"290.2160","-22.4698","7.93662","0.04633"
"290.7160","-22.4613","7.94601","0.04633"
"291.2160","-22.4532","7.92186","0.04632"
"291.7160","-22.4449","7.96809","0.04634"
"292.2160","-22.4364","7.94773","0.04634"
"292.7160","-22.4281","7.96768","0.04635"
"293.2160","-22.4196","8.00661","0.04637"
"293.5460","-22.4142","7.79478","0.04628"
"294.0460","-22.4057","7.88821","0.04633"
"294.5460","-22.3979","7.97172","0.04637"
"295.0200","-22.3898","7.95077","0.04638"
"295.3550","-22.3841","7.82309","0.04639"
"295.8550","-22.3759","7.91629","0.04645"
"296.3550","-22.3676","8.00304","0.04651"
"296.6480","-22.3625","7.79755","0.04682"
"297.1480","-22.3544","7.85871","0.04690"
"297.6480","-22.3459","7.95460","0.04695"
"298.1480","-22.3375","8.03763","0.04701"
"298.4170","-22.3330","7.80660","0.04737"
"298.9170","-22.3247","7.89812","0.04743"
"299.4170","-22.3164","7.99021","0.04750"
"299.9170","-22.3080","8.01096","0.04763"
"300.2470","-22.3025","7.84922","0.04793"
"300.7470","-22.2940","7.94566","0.04799"
"301.2470","-22.2862","8.02630","0.04805"
"301.5360","-22.2809","7.82028","0.04838"
"302.0360","-22.2729","7.87848","0.04848"
"302.5360","-22.2644","7.97363","0.04854"
"303.0360","-22.2561","8.04788","0.04862"
"303.3450","-22.2508","7.82756","0.04898"
"303.8450","-22.2428","7.91804","0.04904"
"304.3450","-22.2344","8.00921","0.04910"
"304.7580","-22.2275","7.91126","0.04934"
"305.1760","-22.2205","7.86506","0.04954"
"305.6760","-22.2121","7.96060","0.04960"
"306.1760","-22.2037","8.04545","0.04967"
"306.4380","-22.1994","7.80888","0.05002"
"306.9380","-22.1910","7.89402","0.05010"
"307.4380","-22.1826","7.98796","0.05016"
"307.9380","-22.1746","8.05733","0.05024"
"308.2620","-22.1688","7.84054","0.05060"
"308.7620","-22.1608","7.93026","0.05066"
"309.2620","-22.1524","8.02031","0.05073"
"309.6310","-22.1463","7.89984","0.05098"
"310.0530","-22.1391","7.87442","0.05116"
"310.5530","-22.1309","7.96566","0.05122"
"311.0530","-22.1225","8.04805","0.05130"
"311.3760","-22.1172","7.82769","0.05165"
"311.8760","-22.1089","7.91912","0.05172"
"312.3760","-22.1004","8.01099","0.05178"
"312.8760","-22.0919","7.97527","0.05190"
"313.3760","-22.0837","8.02807","0.05198"
"313.7100","-22.0780","7.80810","0.05234"
"314.2100","-22.0697","7.89752","0.05241"
"314.7100","-22.0619","7.98442","0.05247"
"315.2100","-22.0532","8.02682","0.05259"
"315.5450","-22.0477","7.85972","0.05289"
"316.0450","-22.0393","7.95457","0.05295"
"316.5450","-22.0310","8.04049","0.05302"
"316.8350","-22.0260","7.83166","0.05335"
"317.3350","-22.0180","7.89595","0.05345"
"317.8350","-22.0094","7.99101","0.05351"
"318.3350","-22.0011","8.06845","0.05359"
"318.6460","-21.9960","7.84490","0.05395"
"319.1460","-21.9876","7.93920","0.05401"
"319.6460","-21.9792","8.03023","0.05408"
"320.0640","-21.9724","7.97467","0.05427"
"320.4790","-21.9652","7.88708","0.05452"
"320.9790","-21.9568","7.98223","0.05459"
"321.4790","-21.9490","8.05886","0.05466"
"321.8340","-21.9425","7.84500","0.05503"
"322.3340","-21.9347","7.92768","0.05509"
"322.8340","-21.9262","8.01927","0.05516"
"323.2690","-21.9189","7.92740","0.05543"
"323.6940","-21.9118","7.86385","0.05565"
"324.1940","-21.9036","7.95315","0.05572"
"324.6940","-21.8952","8.03457","0.05579"
"325.0400","-21.8894","7.88697","0.05608"
"325.5400","-21.8809","7.89228","0.05625"
"326.0400","-21.8727","7.98411","0.05631"
"326.5400","-21.8645","8.06440","0.05638"
"326.8880","-21.8586","7.93630","0.05664"
"327.3100","-21.8516","7.90551","0.05681"
"327.8100","-21.8430","8.00289","0.05688"
"328.3100","-21.8350","8.08147","0.05695"
"328.5620","-21.8304","7.83681","0.05729"
"329.0620","-21.8225","7.85962","0.05742"
"329.5620","-21.8141","7.95379","0.05748"
"330.0620","-21.8058","8.03862","0.05755"
"330.3250","-21.8011","7.81487","0.05787"
"330.8250","-21.7930","7.87714","0.05797"
"331.3250","-21.7847","7.97121","0.05803"
"331.8250","-21.7763","8.05386","0.05810"
"332.1240","-21.7714","7.83891","0.05843"
"332.6240","-21.7630","7.92999","0.05850"
"333.1240","-21.7544","8.02416","0.05856"
"333.6020","-21.7467","8.00035","0.05873"
"333.9440","-21.7407","7.88626","0.05899"
"334.4440","-21.7326","7.97860","0.05905"
"334.9440","-21.7246","8.06125","0.05912"
"335.2700","-21.7187","7.85815","0.05947"
"335.7700","-21.7106","7.92401","0.05957"
"336.2700","-21.7022","8.01889","0.05963"
"336.7700","-21.6940","8.09722","0.05972"
"337.0440","-21.6891","7.86474","0.06019"
"337.5440","-21.6812","7.95032","0.06025"
"338.0440","-21.6727","8.04379","0.06031"
"338.5280","-21.6645","8.02409","0.06042"
"338.8670","-21.6590","7.89676","0.06051"
"339.3670","-21.6506","7.99083","0.06056"
"339.8670","-21.6422","8.07656","0.06063"
"340.2310","-21.6362","7.86984","0.06057"
"340.7310","-21.6277","7.95882","0.06062"
"341.2310","-21.6193","8.04666","0.06067"
"341.7310","-21.6114","7.97011","0.06071"
"342.2310","-21.6029","8.01412","0.06075"
"342.7310","-21.5945","8.01884","0.06083"
"343.2310","-21.5861","7.97387","0.06096"
"343.7310","-21.5778","8.02004","0.06104"
"344.1680","-21.5705","7.85246","0.06118"
"344.6680","-21.5620","7.91579","0.06125"
"345.1680","-21.5542","7.99941","0.06131"
"345.6680","-21.5457","8.06216","0.06135"
"345.9530","-21.5408","7.84784","0.06129"
"346.4530","-21.5326","7.93960","0.06134"
"346.9530","-21.5243","8.02891","0.06139"
"347.4070","-21.5165","8.00195","0.06139"
"347.7480","-21.5110","7.88124","0.06133"
"348.2480","-21.5025","7.97760","0.06138"
"348.7480","-21.4941","8.06784","0.06143"
"349.1300","-21.4878","7.94536","0.06137"
"349.5530","-21.4808","7.92071","0.06136"
"350.0530","-21.4725","8.01382","0.06141"
"350.5530","-21.4641","8.10209","0.06146"
"350.9420","-21.4577","7.97473","0.06141"
"351.3660","-21.4503","7.95389","0.06139"
"351.8660","-21.4425","8.04017","0.06144"
"352.3660","-21.4341","8.12450","0.06148"
"352.8180","-21.4263","7.98912","0.06145"
"353.3180","-21.4179","8.04070","0.06148"
"353.7870","-21.4103","7.98644","0.06145"
"354.2160","-21.4030","7.92711","0.06142"
"354.7160","-21.3946","8.01756","0.06147"
"355.2160","-21.3867","8.09514","0.06151"
"355.5340","-21.3809","7.88948","0.06141"
"356.0340","-21.3729","7.95514","0.06144"
"356.5340","-21.3645","8.04804","0.06149"
"357.0340","-21.3562","8.12700","0.06153"
"357.3460","-21.3508","7.90851","0.06143"
"357.8460","-21.3427","7.98836","0.06147"
"358.3460","-21.3343","8.07997","0.06151"
"358.8460","-21.3259","8.15216","0.06155"
"359.1310","-21.3212","7.91086","0.06144"
"359.6310","-21.3128","7.99677","0.06148"
"360.1310","-21.3044","8.08734","0.06152"
"360.5770","-21.2971","8.05297","0.06151"
"360.9950","-21.2900","7.96080","0.06147"
"361.4950","-21.2816","8.05270","0.06151"
"361.9950","-21.2738","8.12101","0.06155"
"362.3310","-21.2676","7.91871","0.06146"
"362.8310","-21.2597","8.00411","0.06150"
"363.3310","-21.2512","8.09361","0.06155"
"363.7360","-21.2444","7.97502","0.06150"
"364.2360","-21.2361","7.99045","0.06151"
"364.7360","-21.2278","8.07897","0.06156"
"365.2360","-21.2195","8.12264","0.06160"
"365.7360","-21.2109","7.97097","0.06156"
"366.2360","-21.2028","8.03170","0.06160"
"366.7360","-21.1945","8.09041","0.06164"
"367.1590","-21.1875","7.91054","0.06164"
"367.6590","-21.1790","8.00097","0.06169"
"368.1590","-21.1707","8.08654","0.06174"
"368.5360","-21.1643","7.90224","0.06190"
"369.0360","-21.1559","7.98543","0.06195"
"369.5360","-21.1479","8.06829","0.06201"
"369.9080","-21.1415","7.94388","0.06225"
"370.4080","-21.1334","7.95652","0.06238"
"370.9080","-21.1249","8.04877","0.06244"
"371.4080","-21.1166","8.07111","0.06257"
"371.7480","-21.1108","7.92154","0.06286"
"372.2480","-21.1027","8.01087","0.06292"
"372.7480","-21.0943","8.09494","0.06298"
"373.1150","-21.0880","7.89033","0.06333"
"373.6150","-21.0796","7.97768","0.06340"
"374.1150","-21.0714","8.06595","0.06346"
"374.6060","-21.0634","8.04311","0.06364"
"375.0240","-21.0560","7.95708","0.06388"
"375.5240","-21.0483","8.04172","0.06394"
"376.0240","-21.0397","8.12137","0.06402"
"376.3790","-21.0337","7.91497","0.06436"
"376.8790","-21.0254","8.00204","0.06443"
"377.3790","-21.0172","8.09028","0.06450"
"377.8790","-21.0087","8.13472","0.06461"
"378.2700","-21.0022","7.96881","0.06491"
"378.7700","-20.9940","8.05508","0.06497"
"379.2700","-20.9854","8.13384","0.06505"
"379.5850","-20.9802","7.91221","0.06539"
"380.0850","-20.9719","7.99811","0.06546"
"380.5850","-20.9638","8.08435","0.06552"
"381.0050","-20.9565","8.00259","0.06575"
"381.4380","-20.9495","7.97222","0.06592"
"381.9380","-20.9411","8.06361","0.06599"
"382.4380","-20.9327","8.13021","0.06608"
"382.8240","-20.9264","7.95501","0.06640"
"383.3240","-20.9179","8.04626","0.06646"
"383.8240","-20.9096","8.07448","0.06660"
"384.1940","-20.9035","7.90981","0.06690"
"384.6940","-20.8952","7.99721","0.06697"
"385.1940","-20.8867","8.07848","0.06705"
"385.6160","-20.8800","7.88693","0.06739"
"386.1160","-20.8715","7.97658","0.06746"
"386.6160","-20.8630","8.06340","0.06752"
"387.0390","-20.8559","7.89622","0.06763"
"387.5390","-20.8479","7.97503","0.06769"
"388.0390","-20.8394","8.06229","0.06775"
"388.5120","-20.8312","8.01091","0.06779"
"388.9560","-20.8243","7.95550","0.06778"
"389.4560","-20.8158","8.04289","0.06784"
"389.8790","-20.8088","7.99033","0.06797"
"390.3000","-20.8017","7.92356","0.06811"
"390.8000","-20.7935","8.01378","0.06816"
"391.3000","-20.7849","8.09045","0.06823"
"391.7070","-20.7783","7.92362","0.06857"
"392.2070","-20.7699","8.01305","0.06863"
"392.7070","-20.7615","8.09094","0.06870"
"393.1060","-20.7550","7.92200","0.06902"
"393.6060","-20.7465","8.00874","0.06910"
"394.1060","-20.7384","8.08645","0.06917"
"394.4550","-20.7322","7.88579","0.06953"
"394.9550","-20.7243","7.96164","0.06960"
"395.4550","-20.7158","8.05037","0.06966"
"395.8670","-20.7090","7.93296","0.06982"
"396.3670","-20.7005","7.96217","0.06992"
"396.8670","-20.6922","8.04999","0.06998"
"397.3190","-20.6847","8.00816","0.07014"
"397.6580","-20.6791","7.86521","0.07041"
"398.1580","-20.6708","7.95496","0.07047"
"398.6580","-20.6622","8.03804","0.07054"
"399.1120","-20.6550","7.88213","0.07073"
"399.6120","-20.6466","7.95576","0.07080"
"400.1120","-20.6381","8.03679","0.07087"
"400.4740","-20.6321","7.84918","0.07118"
"400.9740","-20.6240","7.92710","0.07126"
"401.4740","-20.6154","8.01861","0.07132"
"401.9220","-20.6079","7.97098","0.07149"
"402.3470","-20.6009","7.89129","0.07165"
"402.8470","-20.5925","7.98072","0.07171"
"403.3470","-20.5844","8.04204","0.07178"
"403.7700","-20.5771","7.90030","0.07191"
"404.2700","-20.5689","7.98641","0.07198"
"404.7630","-20.5606","7.96918","0.07214"
"405.1840","-20.5537","7.88139","0.07235"
"405.6840","-20.5453","7.97244","0.07241"
"406.1840","-20.5369","8.02493","0.07252"
"406.5420","-20.5309","7.87951","0.07280"
"407.0420","-20.5226","7.96719","0.07286"
"407.5420","-20.5145","8.03608","0.07295"
"407.9300","-20.5078","7.87034","0.07323"
"408.4300","-20.4998","7.94896","0.07329"
"408.8970","-20.4917","7.92822","0.07347"
"409.3220","-20.4847","7.85008","0.07367"
"409.8220","-20.4764","7.93796","0.07372"
"410.3220","-20.4679","7.96057","0.07385"
"410.7530","-20.4607","7.86135","0.07413"
"411.2530","-20.4525","7.94824","0.07419"
"411.6630","-20.4456","7.83806","0.07440"
"412.1630","-20.4371","7.85653","0.07451"
"412.6630","-20.4292","7.94095","0.07457"
"413.1050","-20.4217","7.88330","0.07459"
"413.6050","-20.4133","7.88375","0.07464"
"414.1050","-20.4048","7.96823","0.07471"
"414.5010","-20.3984","7.79661","0.07499"
"415.0010","-20.3899","7.88458","0.07505"
"415.5010","-20.3814","7.96854","0.07512"
"415.9120","-20.3750","7.81824","0.07543"
"416.4120","-20.3664","7.90592","0.07550"
"416.9020","-20.3583","7.88570","0.07566"
"417.3260","-20.3513","7.81116","0.07582"
"417.8260","-20.3430","7.90015","0.07588"
"418.3230","-20.3346","7.87840","0.07604"
"418.7570","-20.3274","7.81072","0.07624"
"419.2570","-20.3191","7.89299","0.07631"
"419.7330","-20.3109","7.79061","0.07658"
"420.2330","-20.3029","7.83150","0.07669"
"420.7330","-20.2946","7.91369","0.07677"
"421.1770","-20.2872","7.76837","0.07706"
"421.6770","-20.2786","7.85040","0.07712"
"422.1770","-20.2703","7.89030","0.07719"
"422.6450","-20.2627","7.77357","0.07746"
"423.1450","-20.2542","7.86064","0.07752"
"423.5920","-20.2470","7.74666","0.07781"
"424.0920","-20.2385","7.79350","0.07792"
"424.5920","-20.2302","7.87502","0.07799"
"425.0020","-20.2232","7.71656","0.07823"
"425.5020","-20.2151","7.79963","0.07829"
"426.0020","-20.2068","7.87345","0.07836"
"426.4420","-20.1992","7.72638","0.07868"
"426.9420","-20.1911","7.80686","0.07875"
"427.4420","-20.1827","7.79646","0.07891"
"427.9120","-20.1749","7.74234","0.07910"
"428.4120","-20.1665","7.82100","0.07918"
"428.9120","-20.1581","7.72493","0.07946"
"429.4120","-20.1500","7.78755","0.07955"
"429.9120","-20.1414","7.69108","0.07980"
"430.4120","-20.1332","7.75938","0.07988"
"430.9120","-20.1249","7.71995","0.08009"
"431.4120","-20.1166","7.73193","0.08024"
"431.9120","-20.1081","7.70875","0.08042"
"432.4120","-20.0996","7.72319","0.08055"
"432.9120","-20.0917","7.71709","0.08072"
"433.4120","-20.0833","7.70833","0.08090"
"433.9120","-20.0748","7.71143","0.08106"
"434.4120","-20.0664","7.68796","0.08123"
"434.9120","-20.0580","7.72065","0.08136"
"435.4120","-20.0500","7.64148","0.08161"
"435.9120","-20.0415","7.70759","0.08171"
"436.4120","-20.0332","7.63938","0.08195"
"436.9120","-20.0248","7.68233","0.08207"
"437.4120","-20.0164","7.63454","0.08229"
"437.9120","-20.0083","7.65517","0.08242"
"438.4120","-19.9998","7.61818","0.08261"
"438.9120","-19.9916","7.64120","0.08273"
"439.4120","-19.9831","7.56919","0.08299"
"439.9120","-19.9747","7.62638","0.08309"
"440.4120","-19.9666","7.58156","0.08330"
"440.9120","-19.9582","7.59815","0.08345"
"441.4120","-19.9500","7.58672","0.08362"
"441.9120","-19.9414","7.57885","0.08381"
"442.4120","-19.9331","7.54248","0.08401"
"442.9120","-19.9250","7.55106","0.08416"
"443.4120","-19.9164","7.52878","0.08435"
"443.9120","-19.9082","7.54669","0.08449"
"444.4120","-19.8998","7.50565","0.08471"
"444.9120","-19.8916","7.53708","0.08484"
"445.4120","-19.8831","7.48772","0.08505"
"445.9120","-19.8747","7.52143","0.08518"
"446.4120","-19.8667","7.47121","0.08540"
"446.9120","-19.8582","7.49265","0.08554"
"447.4120","-19.8497","7.45807","0.08575"
"447.9120","-19.8414","7.46309","0.08591"
"448.4120","-19.8331","7.45471","0.08608"
"448.9120","-19.8251","7.42142","0.08628"
"449.4120","-19.8165","7.41729","0.08646"
"449.9120","-19.8081","7.42365","0.08662"
"450.4120","-19.7998","7.39470","0.08681"
"450.9120","-19.7915","7.38246","0.08700"
"451.4120","-19.7833","7.39029","0.08715"
"451.9120","-19.7748","7.35083","0.08737"
"452.4120","-19.7666","7.37725","0.08750"
"452.9120","-19.7581","7.33271","0.08772"
"453.4120","-19.7497","7.34272","0.08787"
"453.9120","-19.7417","7.31882","0.08807"
"454.4120","-19.7331","7.28702","0.08828"
"454.9120","-19.7249","7.30059","0.08842"
"455.4120","-19.7164","7.28108","0.08862"
"455.9120","-19.7081","7.25280","0.08881"
"456.4120","-19.7000","7.27002","0.08896"
"456.9120","-19.6914","7.20884","0.08920"
"457.4120","-19.6831","7.25953","0.08931"
"457.9120","-19.6748","7.20482","0.08954"
"458.4120","-19.6665","7.18100","0.08972"
"458.9120","-19.6582","7.18053","0.08990"
"459.4120","-19.6497","7.17422","0.09007"
"459.9120","-19.6416","7.14304","0.09027"
"460.4120","-19.6332","7.13220","0.09045"
"460.9120","-19.6248","7.12204","0.09063"
"461.4120","-19.6164","7.11623","0.09081"
"461.9120","-19.6081","7.10356","0.09098"
"462.4120","-19.6000","7.06615","0.09119"
"462.9120","-19.5914","7.01118","0.09142"
"463.4120","-19.5832","7.07345","0.09152"
"463.9120","-19.5749","7.01863","0.09175"
"464.4120","-19.5663","6.97445","0.09196"
"464.9120","-19.5583","7.01575","0.09208"
"465.4120","-19.5498","6.96580","0.09231"
"465.9120","-19.5415","6.95832","0.09249"
"466.4120","-19.5332","6.91633","0.09270"
"466.9120","-19.5247","6.90408","0.09288"
"467.4120","-19.5165","6.91227","0.09303"
"467.9120","-19.5082","6.88699","0.09323"
"468.4120","-19.4999","6.83509","0.09346"
"468.9120","-19.4914","6.84157","0.09362"
"469.4120","-19.4831","6.84088","0.09379"
"469.9120","-19.4750","6.79531","0.09400"
"470.4120","-19.4663","6.73557","0.09425"
"470.9120","-19.4582","6.79044","0.09435"
"471.4120","-19.4499","6.72289","0.09458"
"471.9120","-19.4415","6.69569","0.09478"
"472.4120","-19.4331","6.68391","0.09497"
"472.9120","-19.4246","6.65102","0.09517"
"473.4120","-19.4166","6.63220","0.09536"
"473.8520","-19.4092","6.41360","0.09575"
"473.8680","-19.4089","5.92728","0.09635"
"473.8830","-19.4084","5.45049","0.09692"
"473.9120","-19.4075","5.03561","0.09744"
"474.0170","-19.4058","4.89211","0.09764"