File: Coupon Test Data/test__20250509_94834_5.csv
Time,Displacement,Force,Strain 1
(s),(mm),(kN),(mm/mm)
"0.0000","-19.4468","0.37473","-0.00113"
"0.5000","-19.4399","0.46357","-0.00110"
"1.0000","-19.4317","0.57655","-0.00104"
"1.5000","-19.4232","0.69032","-0.00099"
"2.0000","-19.4148","0.80203","-0.00094"
"2.5000","-19.4065","0.91089","-0.00089"
"3.0000","-19.3981","1.02075","-0.00084"
"3.5000","-19.3898","1.12742","-0.00079"
"4.0000","-19.3814","1.23285","-0.00075"
"4.5000","-19.3732","1.32950","-0.00070"
"5.0000","-19.3648","1.43256","-0.00066"
"5.5000","-19.3564","1.53571","-0.00061"
"6.0000","-19.3482","1.62744","-0.00057"
"6.5000","-19.3398","1.72897","-0.00053"
"7.0000","-19.3315","1.82754","-0.00048"
"7.5000","-19.3231","1.91928","-0.00044"
"8.0000","-19.3147","2.01285","-0.00040"
"8.5000","-19.3065","2.10967","-0.00036"
"9.0000","-19.2980","2.20853","-0.00032"
"9.5000","-19.2897","2.29629","-0.00028"
"10.0000","-19.2816","2.39137","-0.00024"
"10.5000","-19.2732","2.48679","-0.00020"
"11.0000","-19.2647","2.57673","-0.00016"
"11.5000","-19.2562","2.67395","-0.00012"
"12.0000","-19.2483","2.76293","-0.00008"
"12.5000","-19.2399","2.84916","-0.00004"
"13.0000","-19.2314","2.94579","0.00000"
"13.5000","-19.2230","3.03498","0.00004"
"14.0000","-19.2147","3.12422","0.00008"
"14.5000","-19.2065","3.21434","0.00012"
"15.0000","-19.1981","3.30017","0.00015"
"15.5000","-19.1898","3.39068","0.00019"
"16.0000","-19.1814","3.47706","0.00023"
"16.5000","-19.1730","3.56608","0.00027"
"17.0000","-19.1649","3.65034","0.00031"
"17.5000","-19.1564","3.73823","0.00034"
"18.0000","-19.1482","3.82305","0.00038"
"18.5000","-19.1397","3.90894","0.00041"
"19.0000","-19.1313","3.99778","0.00046"
"19.5000","-19.1231","4.07752","0.00049"
"20.0000","-19.1148","4.16238","0.00053"
"20.5000","-19.1065","4.24539","0.00056"
"21.0000","-19.0980","4.33046","0.00060"
"21.5000","-19.0898","4.41294","0.00063"
"22.0000","-19.0815","4.49322","0.00067"
"22.5000","-19.0730","4.57746","0.00070"
"23.0000","-19.0648","4.65683","0.00074"
"23.5000","-19.0564","4.73837","0.00078"
"24.0000","-19.0482","4.81650","0.00081"
"24.5000","-19.0397","4.89638","0.00085"
"25.0000","-19.0312","4.97655","0.00089"
"25.5000","-19.0234","5.04643","0.00092"
"26.0000","-19.0149","5.12228","0.00096"
"26.5000","-19.0064","5.19752","0.00100"
"27.0000","-18.9980","5.26831","0.00104"
"27.5000","-18.9897","5.33586","0.00109"
"28.0000","-18.9816","5.39853","0.00113"
"28.5000","-18.9730","5.46361","0.00117"
"29.0000","-18.9647","5.52353","0.00122"
"29.5000","-18.9564","5.58040","0.00127"
"30.0000","-18.9481","5.63350","0.00132"
"30.5000","-18.9399","5.68177","0.00137"
"31.0000","-18.9313","5.73232","0.00143"
"31.5000","-18.9231","5.77540","0.00148"
"32.0000","-18.9147","5.81747","0.00154"
"32.5000","-18.9063","5.85965","0.00160"
"33.0000","-18.8982","5.89340","0.00166"
"33.5000","-18.8897","5.92918","0.00172"
"34.0000","-18.8814","5.96246","0.00179"
"34.5000","-18.8730","5.99410","0.00186"
"35.0000","-18.8647","6.02324","0.00193"
"35.5000","-18.8566","6.04465","0.00199"
"36.0000","-18.8480","6.07561","0.00206"
"36.5000","-18.8397","6.09907","0.00213"
"37.0000","-18.8314","6.12119","0.00221"
"37.5000","-18.8232","6.14259","0.00228"
"38.0000","-18.8147","6.16349","0.00236"
"38.5000","-18.8061","6.18656","0.00244"
"39.0000","-18.7982","6.20001","0.00252"
"39.5000","-18.7898","6.21722","0.00260"
"40.0000","-18.7814","6.22888","0.00267"
"40.5000","-18.7730","6.25305","0.00274"
"41.0000","-18.7647","6.26896","0.00283"
"41.5000","-18.7565","6.27811","0.00291"
"42.0000","-18.7480","6.29279","0.00299"
"42.5000","-18.7398","6.30798","0.00308"
"43.0000","-18.7314","6.32066","0.00316"
"43.5000","-18.7230","6.33385","0.00325"
"44.0000","-18.7148","6.34283","0.00333"
"44.5000","-18.7063","6.35736","0.00342"
"45.0000","-18.6982","6.36703","0.00350"
"45.5000","-18.6898","6.37747","0.00359"
"46.0000","-18.6813","6.39224","0.00367"
"46.5000","-18.6732","6.39865","0.00376"
"47.0000","-18.6647","6.40884","0.00385"
"47.5000","-18.6565","6.41916","0.00393"
"48.0000","-18.6481","6.42967","0.00402"
"48.5000","-18.6397","6.44003","0.00410"
"49.0000","-18.6315","6.44552","0.00419"
"49.5000","-18.6230","6.45691","0.00428"
"50.0000","-18.6147","6.46478","0.00437"
"50.5000","-18.6065","6.47287","0.00446"
"51.0000","-18.5982","6.47006","0.00453"
"51.5000","-18.5897","6.49203","0.00461"
"52.0000","-18.5811","6.50462","0.00470"
"52.5000","-18.5733","6.50492","0.00478"
"53.0000","-18.5649","6.51135","0.00487"
"53.5000","-18.5564","6.52183","0.00496"
"54.0000","-18.5479","6.52891","0.00505"
"54.5000","-18.5397","6.53608","0.00514"
"55.0000","-18.5316","6.54030","0.00523"
"55.5000","-18.5231","6.54946","0.00532"
"56.0000","-18.5148","6.55823","0.00541"
"56.5000","-18.5063","6.56531","0.00550"
"57.0000","-18.4980","6.57204","0.00559"
"57.5000","-18.4899","6.57654","0.00568"
"58.0000","-18.4814","6.58660","0.00577"
"58.5000","-18.4732","6.59178","0.00586"
"59.0000","-18.4647","6.59863","0.00596"
"59.5000","-18.4562","6.60844","0.00605"
"60.0000","-18.4481","6.61148","0.00615"
"60.5000","-18.4397","6.61879","0.00624"
"61.0000","-18.4315","6.62601","0.00634"
"61.5000","-18.4230","6.63351","0.00643"
"62.0000","-18.4147","6.63955","0.00652"
"62.5000","-18.4065","6.64146","0.00661"
"63.0000","-18.3980","6.65259","0.00669"
"63.5000","-18.3898","6.65949","0.00677"
"64.0000","-18.3814","6.66545","0.00686"
"64.5000","-18.3732","6.66944","0.00693"
"65.0000","-18.3647","6.67463","0.00701"
"65.5000","-18.3562","6.68230","0.00708"
"66.0000","-18.3483","6.67774","0.00714"
"66.4660","-18.3404","6.58015","0.00714"
"66.9660","-18.3319","6.65407","0.00719"
"67.4660","-18.3235","6.70565","0.00724"
"67.9180","-18.3162","6.60573","0.00723"
"68.4180","-18.3079","6.68458","0.00728"
"68.9180","-18.2992","6.72523","0.00733"
"69.3590","-18.2922","6.64821","0.00732"
"69.8590","-18.2838","6.72275","0.00737"
"70.2910","-18.2765","6.62257","0.00734"
"70.7910","-18.2682","6.70703","0.00740"
"71.2410","-18.2608","6.61020","0.00732"
"71.7410","-18.2523","6.69738","0.00737"
"72.1780","-18.2449","6.60874","0.00739"
"72.6780","-18.2370","6.67993","0.00747"
"73.1250","-18.2292","6.66121","0.00767"
"73.6250","-18.2211","6.68577","0.00782"
"74.0660","-18.2137","6.65804","0.00802"
"74.5660","-18.2053","6.69261","0.00816"
"75.0660","-18.1968","6.62349","0.00842"
"75.5660","-18.1886","6.71089","0.00848"
"76.0020","-18.1815","6.62572","0.00872"
"76.5020","-18.1730","6.71743","0.00878"
"76.9930","-18.1648","6.64051","0.00903"
"77.4930","-18.1565","6.73097","0.00908"
"77.9320","-18.1493","6.64946","0.00932"
"78.4320","-18.1408","6.74120","0.00937"
"78.8830","-18.1333","6.65591","0.00961"
"79.3830","-18.1252","6.74311","0.00966"
"79.8230","-18.1174","6.65113","0.00991"
"80.3230","-18.1095","6.73903","0.00996"
"80.7530","-18.1022","6.64795","0.01020"
"81.2530","-18.0940","6.73925","0.01024"
"81.6990","-18.0864","6.65459","0.01048"
"82.1990","-18.0781","6.74622","0.01052"
"82.6250","-18.0709","6.65372","0.01076"
"83.1250","-18.0626","6.74675","0.01080"
"83.6210","-18.0545","6.66990","0.01104"
"84.1210","-18.0460","6.75886","0.01109"
"84.6110","-18.0379","6.68879","0.01132"
"85.1050","-18.0296","6.68260","0.01143"
"85.6050","-18.0214","6.75874","0.01148"
"86.1050","-18.0131","6.74510","0.01150"
"86.5210","-18.0059","6.68558","0.01147"
"87.0210","-17.9979","6.77099","0.01151"
"87.4690","-17.9902","6.68399","0.01148"
"87.9690","-17.9820","6.77547","0.01151"
"88.4060","-17.9746","6.70726","0.01149"
"88.9060","-17.9665","6.80158","0.01153"
"89.4060","-17.9579","6.81431","0.01155"
"89.9060","-17.9495","6.82475","0.01155"
"90.4060","-17.9414","6.87400","0.01157"
"90.9060","-17.9330","6.92596","0.01159"
"91.4060","-17.9248","6.89474","0.01157"
"91.8380","-17.9174","6.86408","0.01156"
"92.3380","-17.9092","6.95112","0.01161"
"92.7970","-17.9014","6.90935","0.01161"
"93.2120","-17.8945","6.84180","0.01159"
"93.7120","-17.8863","6.93541","0.01163"
"94.2120","-17.8779","7.01479","0.01167"
"94.6080","-17.8713","6.87589","0.01162"
"95.0370","-17.8640","6.87664","0.01163"
"95.5370","-17.8559","6.96931","0.01167"
"96.0370","-17.8475","7.04760","0.01172"
"96.3410","-17.8426","6.82807","0.01164"
"96.8410","-17.8341","6.91392","0.01168"
"97.3410","-17.8257","7.00891","0.01173"
"97.7890","-17.8182","6.98547","0.01173"
"98.1270","-17.8127","6.88185","0.01169"
"98.6270","-17.8043","6.98104","0.01173"
"99.1270","-17.7959","7.06422","0.01178"
"99.5130","-17.7895","6.88322","0.01172"
"100.0130","-17.7810","6.98350","0.01177"
"100.5130","-17.7730","7.06556","0.01181"
"100.8450","-17.7672","6.87185","0.01208"
"101.3450","-17.7591","6.96762","0.01212"
"101.8450","-17.7506","7.05675","0.01218"
"102.2370","-17.7442","6.89860","0.01255"
"102.7370","-17.7358","6.99877","0.01260"
"103.1920","-17.7283","6.98077","0.01280"
"103.6080","-17.7214","6.92276","0.01301"
"104.1080","-17.7130","7.02086","0.01307"
"104.4440","-17.7073","6.90051","0.01335"
"104.9440","-17.6991","6.94442","0.01345"
"105.4440","-17.6906","7.04043","0.01350"
"105.7850","-17.6850","6.87482","0.01382"
"106.2850","-17.6767","6.97137","0.01386"
"106.7850","-17.6682","7.06301","0.01392"
"107.1230","-17.6626","6.89773","0.01423"
"107.6230","-17.6543","6.99568","0.01426"
"108.1230","-17.6461","7.06385","0.01434"
"108.4630","-17.6404","6.92156","0.01462"
"108.9630","-17.6322","7.01726","0.01466"
"109.4200","-17.6242","7.00975","0.01483"
"109.8360","-17.6176","6.94003","0.01502"
"110.3360","-17.6092","7.03827","0.01507"
"110.7780","-17.6017","6.95986","0.01505"
"111.2780","-17.5935","7.04447","0.01508"
"111.7530","-17.5857","7.01543","0.01523"
"112.1680","-17.5785","6.94759","0.01543"
"112.6680","-17.5702","7.04154","0.01548"
"113.0590","-17.5637","6.90673","0.01578"
"113.5590","-17.5553","7.00430","0.01581"
"114.0590","-17.5473","7.08446","0.01587"
"114.4340","-17.5407","6.93938","0.01617"
"114.9340","-17.5326","7.03489","0.01621"
"115.3420","-17.5256","6.92930","0.01649"
"115.8420","-17.5175","6.97010","0.01657"
"116.3420","-17.5091","7.06425","0.01662"
"116.7430","-17.5024","6.91567","0.01693"
"117.2430","-17.4940","7.01493","0.01697"
"117.6760","-17.4868","6.99657","0.01714"
"118.0940","-17.4797","6.95218","0.01733"
"118.5940","-17.4716","7.04689","0.01737"
"119.0610","-17.4638","6.97458","0.01738"
"119.5610","-17.4552","7.07147","0.01742"
"120.0610","-17.4471","7.09425","0.01745"
"120.5610","-17.4388","7.14841","0.01750"
"120.8860","-17.4332","6.94204","0.01743"
"121.3860","-17.4251","7.03717","0.01747"
"121.8230","-17.4178","7.01837","0.01747"
"122.2650","-17.4102","7.01678","0.01747"
"122.7650","-17.4020","7.11152","0.01751"
"123.2570","-17.3939","7.04862","0.01749"
"123.7570","-17.3854","7.14251","0.01753"
"124.2570","-17.3772","7.21559","0.01756"
"124.7570","-17.3687","7.15442","0.01755"
"125.2570","-17.3606","7.21467","0.01758"
"125.7570","-17.3521","7.25977","0.01760"
"126.2570","-17.3436","7.24625","0.01759"
"126.7570","-17.3357","7.18626","0.01758"
"127.2570","-17.3272","7.27027","0.01762"
"127.5010","-17.3231","7.05887","0.01752"
"128.0010","-17.3147","7.12194","0.01756"
"128.5010","-17.3065","7.21582","0.01760"
"128.9710","-17.2986","7.19993","0.01760"
"129.3090","-17.2931","7.09470","0.01756"
"129.8090","-17.2846","7.19483","0.01760"
"130.3090","-17.2762","7.28715","0.01765"
"130.7200","-17.2694","7.20989","0.01762"
"131.0540","-17.2638","7.10264","0.01757"
"131.5540","-17.2555","7.20053","0.01762"
"132.0540","-17.2473","7.29085","0.01766"
"132.4730","-17.2400","7.22192","0.01764"
"132.9020","-17.2330","7.19380","0.01763"
"133.4020","-17.2249","7.27887","0.01767"
"133.8690","-17.2168","7.18798","0.01763"
"134.3690","-17.2087","7.27820","0.01767"
"134.7330","-17.2024","7.17397","0.01763"
"135.2330","-17.1942","7.20353","0.01764"
"135.7330","-17.1859","7.29946","0.01768"
"136.2330","-17.1775","7.30687","0.01765"
"136.7330","-17.1693","7.35465","0.01768"
"136.9950","-17.1647","7.12714","0.01756"
"137.4950","-17.1565","7.22153","0.01761"
"137.9950","-17.1481","7.31531","0.01767"
"138.4020","-17.1412","7.20744","0.01798"
"138.8210","-17.1345","7.18395","0.01817"
"139.3210","-17.1262","7.28011","0.01823"
"139.8200","-17.1175","7.27695","0.01843"
"140.1580","-17.1123","7.17068","0.01870"
"140.6580","-17.1037","7.27182","0.01875"
"141.1580","-17.0955","7.35970","0.01882"
"141.4440","-17.0905","7.13735","0.01922"
"141.9440","-17.0825","7.22875","0.01927"
"142.4440","-17.0740","7.32574","0.01933"
"142.8090","-17.0680","7.21186","0.01962"
"143.2310","-17.0608","7.19905","0.01977"
"143.7310","-17.0526","7.29502","0.01982"
"144.2310","-17.0443","7.35807","0.01991"
"144.4970","-17.0398","7.16653","0.02024"
"144.9970","-17.0315","7.26437","0.02029"
"145.4970","-17.0232","7.35445","0.02035"
"145.8250","-17.0175","7.14834","0.02072"
"146.3250","-17.0094","7.24087","0.02076"
"146.8250","-17.0010","7.33588","0.02081"
"147.2210","-16.9943","7.22528","0.02109"
"147.6440","-16.9873","7.21182","0.02123"
"148.1440","-16.9789","7.30947","0.02128"
"148.6440","-16.9709","7.38781","0.02134"
"148.9520","-16.9655","7.14561","0.02173"
"149.4520","-16.9574","7.24194","0.02176"
"149.9520","-16.9487","7.33990","0.02180"
"150.4520","-16.9406","7.32145","0.02198"
"150.7850","-16.9349","7.20121","0.02223"
"151.2850","-16.9266","7.29782","0.02226"
"151.7850","-16.9183","7.38369","0.02232"
"152.0550","-16.9139","7.17164","0.02266"
"152.5550","-16.9054","7.27013","0.02270"
"153.0550","-16.8972","7.36218","0.02274"
"153.4010","-16.8913","7.24101","0.02300"
"153.8270","-16.8844","7.22972","0.02314"
"154.3270","-16.8761","7.32526","0.02318"
"154.8270","-16.8676","7.39862","0.02325"
"155.0920","-16.8632","7.18806","0.02359"
"155.5920","-16.8549","7.28467","0.02363"
"156.0920","-16.8464","7.37695","0.02368"
"156.3520","-16.8422","7.15523","0.02405"
"156.8520","-16.8339","7.24493","0.02408"
"157.3520","-16.8255","7.34151","0.02412"
"157.8400","-16.8174","7.32145","0.02430"
"158.2560","-16.8104","7.25055","0.02453"
"158.7560","-16.8023","7.34295","0.02457"
"159.2230","-16.7943","7.32791","0.02457"
"159.6460","-16.7876","7.28861","0.02455"
"160.1460","-16.7789","7.38640","0.02460"
"160.5860","-16.7717","7.36832","0.02461"
"160.9350","-16.7658","7.26552","0.02456"
"161.4350","-16.7575","7.36083","0.02459"
"161.9350","-16.7492","7.44057","0.02463"
"162.2950","-16.7432","7.25627","0.02456"
"162.7950","-16.7347","7.35032","0.02459"
"163.2950","-16.7264","7.44233","0.02463"
"163.7950","-16.7184","7.49209","0.02466"
"164.2950","-16.7098","7.47579","0.02465"
"164.7950","-16.7015","7.51821","0.02467"
"165.2950","-16.6931","7.55388","0.02469"
"165.6740","-16.6869","7.37403","0.02463"
"166.1740","-16.6784","7.46697","0.02467"
"166.6740","-16.6700","7.43535","0.02465"
"167.1740","-16.6621","7.45700","0.02466"
"167.6740","-16.6535","7.52376","0.02469"
"168.1740","-16.6451","7.54905","0.02470"
"168.6740","-16.6368","7.50960","0.02470"
"169.1740","-16.6286","7.58151","0.02473"
"169.5330","-16.6224","7.43978","0.02468"
"170.0330","-16.6141","7.50514","0.02473"
"170.5330","-16.6060","7.58645","0.02477"
"171.0000","-16.5979","7.54934","0.02489"
"171.4180","-16.5912","7.45908","0.02517"
"171.9180","-16.5828","7.54970","0.02522"
"172.4180","-16.5746","7.61683","0.02529"
"172.7880","-16.5681","7.44004","0.02565"
"173.2880","-16.5600","7.52961","0.02571"
"173.7880","-16.5516","7.61706","0.02576"
"174.1340","-16.5459","7.49670","0.02572"
"174.4560","-16.5405","7.35258","0.02566"
"174.9560","-16.5321","7.44992","0.02571"
"175.4560","-16.5237","7.53953","0.02575"
"175.8660","-16.5169","7.35278","0.02567"
"176.3660","-16.5085","7.44758","0.02572"
"176.8660","-16.5001","7.54319","0.02576"
"177.3660","-16.4923","7.61430","0.02580"
"177.6790","-16.4866","7.40397","0.02571"
"178.1790","-16.4785","7.49610","0.02575"
"178.6790","-16.4701","7.58896","0.02580"
"179.1310","-16.4627","7.56382","0.02579"
"179.4600","-16.4570","7.42975","0.02573"
"179.9600","-16.4490","7.52164","0.02577"
"180.4600","-16.4404","7.61124","0.02582"
"180.7160","-16.4363","7.36693","0.02571"
"181.2160","-16.4279","7.45903","0.02575"
"181.7160","-16.4194","7.55558","0.02580"
"182.2160","-16.4111","7.61559","0.02583"
"182.4570","-16.4072","7.35829","0.02569"
"182.9570","-16.3988","7.45629","0.02574"
"183.4570","-16.3905","7.54920","0.02578"
"183.9110","-16.3828","7.52512","0.02578"
"184.3360","-16.3758","7.48864","0.02579"
"184.8360","-16.3675","7.57640","0.02582"
"185.2550","-16.3604","7.43170","0.02571"
"185.7550","-16.3523","7.52387","0.02577"
"186.2550","-16.3437","7.61557","0.02583"
"186.5660","-16.3387","7.40668","0.02631"
"187.0660","-16.3301","7.47159","0.02641"
"187.5660","-16.3222","7.56194","0.02646"
"188.0660","-16.3137","7.62331","0.02654"
"188.4420","-16.3072","7.40904","0.02694"
"188.9420","-16.2990","7.49813","0.02699"
"189.4420","-16.2908","7.58935","0.02704"
"189.9420","-16.2825","7.65194","0.02714"
"190.2010","-16.2781","7.42623","0.02751"
"190.7010","-16.2697","7.52167","0.02756"
"191.2010","-16.2612","7.61362","0.02762"
"191.5590","-16.2553","7.49665","0.02790"
"192.0590","-16.2470","7.51134","0.02804"
"192.5590","-16.2390","7.59739","0.02809"
"192.9470","-16.2321","7.45832","0.02841"
"193.4470","-16.2241","7.54527","0.02845"
"193.9470","-16.2157","7.63035","0.02852"
"194.3020","-16.2098","7.44847","0.02886"
"194.8020","-16.2015","7.54312","0.02889"
"195.3020","-16.1930","7.63631","0.02895"
"195.6260","-16.1876","7.42938","0.02933"
"196.1260","-16.1794","7.49035","0.02938"
"196.6260","-16.1709","7.58759","0.02942"
"197.1260","-16.1624","7.67409","0.02948"
"197.4810","-16.1568","7.50994","0.02946"
"197.9810","-16.1483","7.57110","0.02947"
"198.4810","-16.1401","7.65754","0.02950"
"198.8620","-16.1336","7.54594","0.02975"
"199.2780","-16.1269","7.49459","0.02992"
"199.7780","-16.1184","7.59017","0.02996"
"200.2780","-16.1103","7.66753","0.03003"
"200.6100","-16.1044","7.45760","0.03041"
"201.1100","-16.0963","7.55136","0.03044"
"201.6100","-16.0879","7.64310","0.03050"
"201.9800","-16.0816","7.52844","0.03077"
"202.3970","-16.0748","7.48764","0.03094"
"202.8970","-16.0666","7.58287","0.03098"
"203.3970","-16.0581","7.67266","0.03104"
"203.6720","-16.0535","7.46082","0.03141"
"204.1720","-16.0452","7.51543","0.03149"
"204.6720","-16.0368","7.60933","0.03154"
"205.1330","-16.0293","7.58908","0.03172"
"205.5500","-16.0222","7.52158","0.03194"
"206.0500","-16.0140","7.61214","0.03199"
"206.4810","-16.0066","7.58591","0.03216"
"206.9010","-15.9999","7.53067","0.03236"
"207.4010","-15.9914","7.62562","0.03242"
"207.8550","-15.9839","7.60051","0.03258"
"208.2710","-15.9770","7.52560","0.03281"
"208.7710","-15.9685","7.62219","0.03286"
"209.2710","-15.9602","7.70622","0.03290"
"209.7710","-15.9518","7.65172","0.03291"
"210.2710","-15.9438","7.71345","0.03297"
"210.7710","-15.9352","7.75703","0.03300"
"211.2710","-15.9269","7.75054","0.03303"
"211.7710","-15.9185","7.75788","0.03311"
"212.2710","-15.9102","7.74835","0.03314"
"212.7710","-15.9021","7.78475","0.03317"
"213.2710","-15.8935","7.82079","0.03321"
"213.4220","-15.8908","7.50805","0.03308"
"213.9220","-15.8825","7.54673","0.03311"
"214.4220","-15.8746","7.63601","0.03316"
"214.9220","-15.8661","7.72221","0.03320"
"215.2650","-15.8604","7.54575","0.03314"
"215.7650","-15.8520","7.63885","0.03318"
"216.2650","-15.8437","7.73052","0.03322"
"216.7650","-15.8353","7.80497","0.03327"
"217.1930","-15.8282","7.63190","0.03321"
"217.6930","-15.8199","7.71669","0.03325"
"218.1930","-15.8114","7.80221","0.03329"
"218.6930","-15.8032","7.70207","0.03325"
"219.1930","-15.7949","7.77028","0.03329"
"219.6930","-15.7867","7.81390","0.03330"
"220.1930","-15.7781","7.76680","0.03329"
"220.6930","-15.7697","7.84152","0.03333"
"221.1930","-15.7617","7.75268","0.03327"
"221.6930","-15.7532","7.81826","0.03330"
"222.1850","-15.7449","7.77165","0.03328"
"222.5470","-15.7390","7.66410","0.03324"
"223.0470","-15.7307","7.75435","0.03328"
"223.5470","-15.7222","7.83950","0.03332"
"223.8500","-15.7172","7.61428","0.03324"
"224.3500","-15.7089","7.69171","0.03327"
"224.8500","-15.7005","7.78298","0.03332"
"225.3500","-15.6923","7.84709","0.03335"
"225.6450","-15.6873","7.64532","0.03326"
"226.1450","-15.6789","7.73795","0.03330"
"226.6450","-15.6706","7.82555","0.03334"
"227.0010","-15.6647","7.70626","0.03329"
"227.4260","-15.6575","7.68916","0.03328"
"227.9260","-15.6496","7.77655","0.03332"
"228.4260","-15.6410","7.85960","0.03336"
"228.7240","-15.6360","7.64076","0.03326"
"229.2240","-15.6276","7.73213","0.03330"
"229.7240","-15.6195","7.82099","0.03334"
"230.1400","-15.6124","7.77176","0.03333"
"230.5540","-15.6057","7.68476","0.03329"
"231.0540","-15.5972","7.78029","0.03333"
"231.5540","-15.5888","7.86219","0.03337"
"231.8180","-15.5843","7.63121","0.03327"
"232.3180","-15.5761","7.72236","0.03331"
"232.8180","-15.5677","7.81373","0.03335"
"233.2590","-15.5605","7.78313","0.03335"
"233.5930","-15.5547","7.66495","0.03330"
"234.0930","-15.5466","7.75726","0.03334"
"234.5930","-15.5383","7.84312","0.03338"
"234.9060","-15.5329","7.63541","0.03334"
"235.4060","-15.5247","7.69652","0.03333"
"235.9060","-15.5162","7.79055","0.03339"
"236.4060","-15.5081","7.86032","0.03351"
"236.7120","-15.5028","7.65050","0.03396"
"237.2120","-15.4947","7.74149","0.03399"
"237.7120","-15.4862","7.83121","0.03403"
"238.0510","-15.4808","7.68719","0.03424"
"238.5510","-15.4722","7.71451","0.03441"
"239.0510","-15.4639","7.80495","0.03447"
"239.5510","-15.4555","7.78054","0.03459"
"239.9680","-15.4487","7.69762","0.03481"
"240.4680","-15.4402","7.79150","0.03487"
"240.9680","-15.4317","7.86855","0.03491"
"241.3720","-15.4253","7.69290","0.03519"
"241.8720","-15.4167","7.78707","0.03526"
"242.3720","-15.4086","7.86766","0.03531"
"242.8670","-15.4004","7.79914","0.03532"
"243.3670","-15.3921","7.86247","0.03538"
"243.7370","-15.3857","7.71938","0.03559"
"244.1690","-15.3786","7.70163","0.03577"
"244.6690","-15.3703","7.79340","0.03584"
"245.1690","-15.3618","7.87420","0.03590"
"245.4570","-15.3571","7.64309","0.03622"
"245.9570","-15.3488","7.73241","0.03630"
"246.4570","-15.3405","7.82076","0.03636"
"246.8420","-15.3340","7.70535","0.03658"
"247.2660","-15.3269","7.68403","0.03676"
"247.7660","-15.3184","7.78057","0.03683"
"248.2660","-15.3106","7.86201","0.03689"
"248.5930","-15.3046","7.66302","0.03718"
"249.0930","-15.2966","7.74707","0.03727"
"249.5930","-15.2883","7.83906","0.03734"
"250.0930","-15.2800","7.91772","0.03741"
"250.3710","-15.2751","7.67382","0.03774"
"250.8710","-15.2670","7.76093","0.03782"
"251.3710","-15.2585","7.85276","0.03789"
"251.7770","-15.2517","7.73756","0.03811"
"252.2070","-15.2446","7.72546","0.03829"
"252.7070","-15.2363","7.81883","0.03836"
"253.2070","-15.2281","7.87163","0.03846"
"253.7070","-15.2195","7.79705","0.03873"
"254.2070","-15.2114","7.86408","0.03883"
"254.5690","-15.2050","7.66412","0.03928"
"255.0690","-15.1971","7.74304","0.03935"
"255.5690","-15.1887","7.83240","0.03942"
"256.0690","-15.1802","7.90981","0.03950"
"256.3310","-15.1758","7.66748","0.03995"
"256.8310","-15.1676","7.75640","0.04001"
"257.3310","-15.1591","7.84877","0.04008"
"257.8310","-15.1508","7.91919","0.04016"
"258.1050","-15.1463","7.68599","0.04059"
"258.6050","-15.1379","7.78062","0.04064"
"259.1050","-15.1297","7.87064","0.04070"
"259.5830","-15.1216","7.85058","0.04090"
"259.9140","-15.1161","7.71574","0.04121"
"260.4140","-15.1078","7.80955","0.04126"
"260.9140","-15.0998","7.89520","0.04132"
"261.2740","-15.0932","7.77927","0.04162"
"261.6930","-15.0867","7.73906","0.04180"
"262.1930","-15.0782","7.83511","0.04185"
"262.6930","-15.0698","7.91905","0.04192"
"262.9600","-15.0652","7.68788","0.04231"
"263.4600","-15.0572","7.77491","0.04237"
"263.9600","-15.0487","7.86883","0.04243"
"264.4350","-15.0408","7.84769","0.04261"
"264.7720","-15.0352","7.72633","0.04289"
"265.2720","-15.0269","7.81973","0.04294"
"265.7720","-15.0186","7.90631","0.04300"
"266.1100","-15.0128","7.70288","0.04338"
"266.6100","-15.0044","7.79389","0.04344"
"267.1100","-14.9962","7.88256","0.04349"
"267.6100","-14.9881","7.87229","0.04356"
"268.1100","-14.9795","7.87242","0.04360"
"268.6100","-14.9714","7.87109","0.04365"
"269.1100","-14.9629","7.87291","0.04374"
"269.6100","-14.9544","7.79368","0.04385"
"270.1100","-14.9464","7.84388","0.04392"
"270.6100","-14.9379","7.92647","0.04398"
"270.9500","-14.9324","7.77408","0.04392"
"271.4500","-14.9238","7.83207","0.04397"
"271.9500","-14.9155","7.92139","0.04402"
"272.4500","-14.9073","7.99449","0.04408"
"272.9110","-14.8995","7.90283","0.04425"
"273.4110","-14.8912","7.97468","0.04432"
"273.9110","-14.8828","8.01878","0.04439"
"274.3590","-14.8755","7.83696","0.04468"
"274.8590","-14.8670","7.91710","0.04476"
"275.3590","-14.8589","7.99548","0.04483"
"275.8590","-14.8505","8.00835","0.04488"
"276.0990","-14.8465","7.75030","0.04478"
"276.5990","-14.8381","7.84125","0.04484"
"277.0990","-14.8298","7.92824","0.04490"
"277.5990","-14.8213","7.99516","0.04494"
"277.9300","-14.8159","7.77119","0.04483"
"278.4300","-14.8076","7.86183","0.04488"
"278.9300","-14.7991","7.95283","0.04493"
"279.3960","-14.7915","7.92740","0.04493"
"279.7330","-14.7858","7.80634","0.04487"
"280.2330","-14.7776","7.89670","0.04492"
"280.7330","-14.7692","7.98513","0.04497"
"281.0600","-14.7638","7.77822","0.04486"
"281.5600","-14.7552","7.85996","0.04491"
"282.0600","-14.7472","7.94837","0.04496"
"282.5600","-14.7388","8.02808","0.04500"
"282.9700","-14.7318","7.84014","0.04491"
"283.4700","-14.7235","7.93037","0.04496"
"283.9700","-14.7153","8.01741","0.04501"
"284.3820","-14.7083","7.90158","0.04495"
"284.8820","-14.6998","7.91963","0.04497"
"285.3820","-14.6919","8.00183","0.04501"
"285.8620","-14.6838","7.92891","0.04497"
"286.3620","-14.6754","8.01754","0.04503"
"286.8620","-14.6669","8.01162","0.04506"
"287.3620","-14.6587","8.04573","0.04508"
"287.6400","-14.6539","7.79317","0.04496"
"288.1400","-14.6457","7.88353","0.04501"
"288.6400","-14.6376","7.97054","0.04505"
"289.1400","-14.6290","8.00842","0.04507"
"289.4700","-14.6236","7.82754","0.04499"
"289.9700","-14.6152","7.92131","0.04503"
"290.4700","-14.6070","8.00615","0.04507"
"290.7830","-14.6016","7.80126","0.04497"
"291.2830","-14.5936","7.85722","0.04500"
"291.7830","-14.5850","7.95213","0.04504"
"292.2830","-14.5767","8.03376","0.04508"
"292.5450","-14.5722","7.79530","0.04497"
"293.0450","-14.5640","7.88394","0.04501"
"293.5450","-14.5557","7.97552","0.04506"
"294.0450","-14.5474","8.04936","0.04509"
"294.3500","-14.5421","7.81965","0.04498"
"294.8500","-14.5340","7.90990","0.04502"
"295.3500","-14.5257","7.99932","0.04506"
"295.8160","-14.5176","7.98032","0.04506"
"296.1470","-14.5123","7.83958","0.04499"
"296.6470","-14.5039","7.93396","0.04504"
"297.1470","-14.4957","8.01925","0.04508"
"297.5160","-14.4894","7.90037","0.04502"
"297.9350","-14.4826","7.85978","0.04500"
"298.4350","-14.4740","7.95448","0.04505"
"298.9350","-14.4660","8.03508","0.04509"
"299.2630","-14.4602","7.80797","0.04498"
"299.7630","-14.4520","7.89491","0.04502"
"300.2630","-14.4437","7.98510","0.04506"
"300.7630","-14.4355","8.04407","0.04510"
"301.0220","-14.4309","7.82491","0.04499"
"301.5220","-14.4228","7.91455","0.04503"
"302.0220","-14.4143","8.00458","0.04508"
"302.4350","-14.4074","7.91610","0.04505"
"302.8510","-14.4006","7.85482","0.04503"
"303.3510","-14.3922","7.94800","0.04507"
"303.8510","-14.3840","8.03061","0.04512"
"304.1600","-14.3787","7.82416","0.04507"
"304.6600","-14.3704","7.87917","0.04510"
"305.1600","-14.3619","7.97250","0.04515"
"305.6600","-14.3539","8.04670","0.04520"
"305.9510","-14.3487","7.81438","0.04528"
"306.4510","-14.3407","7.89794","0.04530"
"306.9510","-14.3322","7.98927","0.04535"
"307.4470","-14.3240","7.96575","0.04568"
"307.7840","-14.3182","7.84435","0.04600"
"308.2840","-14.3101","7.93340","0.04604"
"308.7840","-14.3017","8.01933","0.04609"
"309.1420","-14.2957","7.89928","0.04625"
"309.5610","-14.2888","7.85866","0.04645"
"310.0610","-14.2804","7.95186","0.04651"
"310.5610","-14.2721","8.03458","0.04658"
"310.8770","-14.2668","7.82208","0.04682"
"311.3770","-14.2584","7.89517","0.04692"
"311.8770","-14.2499","7.98671","0.04698"
"312.3770","-14.2420","8.04004","0.04701"
"312.8770","-14.2335","8.00416","0.04702"
"313.2990","-14.2264","7.90616","0.04720"
"313.7250","-14.2194","7.86432","0.04740"
"314.2250","-14.2111","7.95341","0.04746"
"314.7250","-14.2025","8.03921","0.04753"
"315.0880","-14.1966","7.91159","0.04772"
"315.5100","-14.1896","7.87919","0.04792"
"316.0100","-14.1811","7.97102","0.04798"
"316.5100","-14.1731","8.05089","0.04805"
"316.8350","-14.1673","7.84684","0.04833"
"317.3350","-14.1592","7.91228","0.04845"
"317.8350","-14.1507","8.00329","0.04851"
"318.3350","-14.1426","8.07446","0.04859"
"318.6620","-14.1368","7.84747","0.04893"
"319.1620","-14.1289","7.93346","0.04900"
"319.6620","-14.1205","8.02350","0.04907"
"320.1200","-14.1127","8.00027","0.04921"
"320.4560","-14.1071","7.87403","0.04947"
"320.9560","-14.0990","7.96411","0.04954"
"321.4560","-14.0904","8.05258","0.04961"
"321.8680","-14.0836","7.93380","0.04982"
"322.2930","-14.0765","7.90745","0.05003"
"322.7930","-14.0680","7.99978","0.05010"
"323.2930","-14.0600","8.07817","0.05017"
"323.7930","-14.0515","7.98291","0.05048"
"324.2930","-14.0433","7.94020","0.05075"
"324.7930","-14.0347","8.01795","0.05084"
"325.2530","-14.0272","7.98013","0.05107"
"325.5850","-14.0216","7.84218","0.05140"
"326.0850","-14.0133","7.93378","0.05145"
"326.5850","-14.0051","8.02130","0.05152"
"327.0850","-13.9966","8.09366","0.05160"
"327.4250","-13.9909","7.87896","0.05203"
"327.9250","-13.9825","7.97013","0.05209"
"328.4250","-13.9745","8.05349","0.05215"
"328.9250","-13.9660","8.08748","0.05229"
"329.2590","-13.9607","7.90687","0.05265"
"329.7590","-13.9522","7.99960","0.05270"
"330.2590","-13.9437","8.08798","0.05276"
"330.7590","-13.9353","8.09314","0.05287"
"331.0140","-13.9312","7.84758","0.05317"
"331.5140","-13.9228","7.93569","0.05323"
"332.0140","-13.9145","8.02423","0.05329"
"332.5140","-13.9063","8.09203","0.05336"
"332.8500","-13.9004","7.88247","0.05365"
"333.3500","-13.8923","7.96931","0.05371"
"333.8500","-13.8839","8.05866","0.05378"
"334.3500","-13.8758","8.13108","0.05385"
"334.6930","-13.8697","7.91818","0.05416"
"335.1930","-13.8617","7.98134","0.05425"
"335.6930","-13.8532","8.06950","0.05432"
"336.1930","-13.8448","8.12855","0.05443"
"336.4750","-13.8402","7.85997","0.05494"
"336.9750","-13.8318","7.94951","0.05501"
"337.4750","-13.8233","8.03951","0.05508"
"337.9750","-13.8152","8.10966","0.05517"
"338.3130","-13.8093","7.89707","0.05561"
"338.8130","-13.8011","7.98486","0.05567"
"339.3130","-13.7931","8.06725","0.05574"
"339.7440","-13.7856","8.03215","0.05597"
"340.1620","-13.7788","7.94723","0.05622"
"340.6620","-13.7704","8.03772","0.05628"
"341.1620","-13.7622","8.11725","0.05635"
"341.4380","-13.7573","7.90175","0.05674"
"341.9380","-13.7493","7.97232","0.05681"
"342.4380","-13.7408","8.06454","0.05686"
"342.9380","-13.7324","8.14289","0.05694"
"343.2180","-13.7277","7.91800","0.05732"
"343.7180","-13.7194","8.00468","0.05737"
"344.2180","-13.7111","8.09236","0.05743"
"344.6970","-13.7032","8.06643","0.05763"
"345.0470","-13.6971","7.95563","0.05787"
"345.5470","-13.6888","8.04511","0.05792"
"346.0470","-13.6808","8.12395","0.05798"
"346.3170","-13.6760","7.91398","0.05835"
"346.8170","-13.6678","7.97549","0.05841"
"347.3170","-13.6594","8.06627","0.05847"
"347.8170","-13.6512","8.12243","0.05856"
"348.0890","-13.6465","7.91368","0.05891"
"348.5890","-13.6384","8.00081","0.05895"
"349.0890","-13.6298","8.09033","0.05901"
"349.4650","-13.6239","7.96587","0.05928"
"349.8920","-13.6164","7.94739","0.05944"
"350.3920","-13.6082","8.03709","0.05949"
"350.8920","-13.5999","8.11743","0.05955"
"351.2250","-13.5943","7.89889","0.05990"
"351.7250","-13.5860","7.98424","0.05994"
"352.2250","-13.5777","8.07277","0.05999"
"352.7250","-13.5694","8.08677","0.06005"
"353.0580","-13.5637","7.93258","0.06015"
"353.5580","-13.5554","8.02254","0.06020"
"354.0580","-13.5471","8.10668","0.06024"
"354.3900","-13.5415","7.94895","0.06002"
"354.8900","-13.5332","7.96772","0.06004"
"355.3900","-13.5251","8.05390","0.06010"
"355.8900","-13.5165","8.10839","0.06012"
"356.3900","-13.5083","8.09361","0.06029"
"356.7050","-13.5030","7.83736","0.06081"
"357.2050","-13.4946","7.92600","0.06087"
"357.7050","-13.4862","8.01748","0.06093"
"358.2050","-13.4780","8.09492","0.06101"
"358.4860","-13.4731","7.84620","0.06149"
"358.9860","-13.4650","7.93261","0.06155"
"359.4860","-13.4568","8.02281","0.06161"
"359.9860","-13.4482","8.10123","0.06169"
"360.2980","-13.4430","7.86930","0.06215"
"360.7980","-13.4347","7.95970","0.06221"
"361.2980","-13.4266","8.04553","0.06226"
"361.7260","-13.4192","8.01840","0.06246"
"362.0590","-13.4139","7.88678","0.06276"
"362.5590","-13.4052","7.98231","0.06282"
"363.0590","-13.3972","8.06506","0.06288"
"363.3660","-13.3917","7.86015","0.06329"
"363.8660","-13.3837","7.93342","0.06334"
"364.3660","-13.3754","8.02309","0.06340"
"364.8660","-13.3671","8.09796","0.06347"
"365.1870","-13.3615","7.87510","0.06387"
"365.6870","-13.3534","7.96370","0.06392"
"366.1870","-13.3450","8.05227","0.06398"
"366.5810","-13.3383","7.93399","0.06428"
"367.0030","-13.3313","7.90448","0.06445"
"367.5030","-13.3230","7.99638","0.06450"
"368.0030","-13.3148","8.07871","0.06456"
"368.3380","-13.3090","7.87619","0.06494"
"368.8380","-13.3009","7.93293","0.06501"
"369.3380","-13.2924","8.02547","0.06507"
"369.8380","-13.2842","8.10073","0.06513"
"370.2030","-13.2780","7.90144","0.06550"
"370.7030","-13.2696","7.99080","0.06555"
"371.2030","-13.2613","8.07740","0.06561"
"371.7030","-13.2531","8.06269","0.06561"
"372.2030","-13.2449","8.08260","0.06571"
"372.7030","-13.2362","8.06009","0.06586"
"373.2030","-13.2281","8.07384","0.06598"
"373.7030","-13.2197","8.07003","0.06614"
"374.2030","-13.2113","8.08620","0.06627"
"374.7030","-13.2031","8.08407","0.06641"
"375.2030","-13.1946","8.10029","0.06654"
"375.7030","-13.1865","8.08550","0.06670"
"376.2030","-13.1780","8.06765","0.06687"
"376.7030","-13.1696","8.00543","0.06707"
"377.2030","-13.1614","8.05439","0.06718"
"377.7030","-13.1530","8.11437","0.06727"
"378.0400","-13.1473","7.89175","0.06758"
"378.5400","-13.1390","7.97320","0.06766"
"379.0400","-13.1309","8.05716","0.06773"
"379.5400","-13.1225","8.12779","0.06783"
"379.8680","-13.1172","7.90657","0.06815"
"380.3680","-13.1087","7.99598","0.06822"
"380.8680","-13.1002","8.08432","0.06829"
"381.3680","-13.0919","8.14061","0.06841"
"381.6530","-13.0873","7.92781","0.06871"
"382.1530","-13.0788","8.01689","0.06879"
"382.6530","-13.0705","8.10418","0.06886"
"383.1420","-13.0625","8.07661","0.06910"
"383.4700","-13.0567","7.90235","0.06949"
"383.9700","-13.0486","7.98842","0.06956"
"384.4700","-13.0402","8.07606","0.06963"
"384.9700","-13.0321","8.12922","0.06974"
"385.3300","-13.0258","7.93699","0.07016"
"385.8300","-13.0177","8.01933","0.07023"
"386.3300","-13.0092","8.10373","0.07030"
"386.7640","-13.0020","8.06323","0.07052"
"387.1040","-12.9964","7.93181","0.07083"
"387.6040","-12.9880","8.02126","0.07089"
"388.1040","-12.9795","8.10964","0.07096"
"388.5150","-12.9729","7.99199","0.07127"
"388.9370","-12.9656","7.95607","0.07147"
"389.4370","-12.9573","8.04594","0.07153"
"389.9370","-12.9494","8.12336","0.07159"
"390.3050","-12.9428","8.00317","0.07190"
"390.7400","-12.9358","7.97956","0.07207"
"391.2400","-12.9274","8.06915","0.07213"
"391.7400","-12.9192","8.14578","0.07220"
"392.0470","-12.9138","7.92477","0.07260"
"392.5470","-12.9058","7.98843","0.07268"
"393.0470","-12.8973","8.07796","0.07274"
"393.5470","-12.8889","8.14364","0.07282"
"393.9300","-12.8826","7.96690","0.07318"
"394.4300","-12.8743","8.05319","0.07324"
"394.9300","-12.8659","8.13182","0.07331"
"395.2600","-12.8604","7.86702","0.07365"
"395.7600","-12.8520","7.94875","0.07372"
"396.2600","-12.8435","8.03968","0.07379"
"396.7600","-12.8357","8.10452","0.07386"
"397.1820","-12.8283","7.92674","0.07416"
"397.6820","-12.8201","8.00938","0.07422"
"398.1820","-12.8117","8.09028","0.07430"
"398.5790","-12.8050","7.88812","0.07461"
"399.0790","-12.7967","7.96768","0.07468"
"399.5790","-12.7883","8.05580","0.07475"
"400.0790","-12.7804","8.10609","0.07484"
"400.4330","-12.7741","7.92120","0.07513"
"400.9330","-12.7659","8.00662","0.07520"
"401.4330","-12.7576","8.08969","0.07527"
"401.7830","-12.7518","7.91617","0.07553"
"402.2830","-12.7433","7.96851","0.07564"
"402.7830","-12.7352","8.05278","0.07570"
"403.2830","-12.7266","8.05577","0.07585"
"403.6420","-12.7207","7.93611","0.07607"
"404.1420","-12.7124","8.02186","0.07614"
"404.6420","-12.7039","8.10040","0.07622"
"405.0330","-12.6975","7.90960","0.07653"
"405.5330","-12.6891","7.99386","0.07661"
"406.0330","-12.6810","8.07410","0.07668"
"406.4510","-12.6737","7.91140","0.07699"
"406.9510","-12.6656","7.98403","0.07707"
"407.4510","-12.6574","8.06425","0.07714"
"407.8130","-12.6511","7.85673","0.07758"
"408.3130","-12.6427","7.93613","0.07766"
"408.8130","-12.6346","8.01967","0.07773"
"409.2850","-12.6267","7.98841","0.07796"
"409.7120","-12.6194","7.91966","0.07822"
"410.2120","-12.6116","7.99826","0.07829"
"410.7120","-12.6029","8.04022","0.07843"
"411.0660","-12.5971","7.88295","0.07878"
"411.5660","-12.5887","7.96956","0.07884"
"412.0660","-12.5804","8.04881","0.07892"
"412.4470","-12.5739","7.87513","0.07930"
"412.9470","-12.5657","7.95033","0.07938"
"413.4470","-12.5573","8.03249","0.07945"
"413.8020","-12.5512","7.84301","0.07983"
"414.3020","-12.5430","7.92069","0.07990"
"414.8020","-12.5347","8.00700","0.07997"
"415.1990","-12.5281","7.88745","0.08026"
"415.6990","-12.5197","7.92525","0.08039"
"416.1990","-12.5116","8.00611","0.08046"
"416.5700","-12.5050","7.84591","0.08080"
"417.0700","-12.4970","7.90096","0.08089"
"417.5700","-12.4887","7.98463","0.08096"
"417.9930","-12.4814","7.80828","0.08126"
"418.4930","-12.4731","7.88583","0.08134"
"418.9930","-12.4648","7.97062","0.08140"
"419.3950","-12.4581","7.84925","0.08164"
"419.8950","-12.4496","7.88206","0.08176"
"420.3950","-12.4418","7.96071","0.08182"
"420.8160","-12.4344","7.78880","0.08213"
"421.3160","-12.4261","7.86757","0.08220"
"421.8160","-12.4177","7.95379","0.08227"
"422.3140","-12.4095","7.84937","0.08255"
"422.8140","-12.4013","7.90206","0.08264"
"423.3140","-12.3926","7.88216","0.08284"
"423.8140","-12.3846","7.86309","0.08300"
"424.3140","-12.3763","7.93711","0.08308"
"424.7830","-12.3683","7.81703","0.08340"
"425.2830","-12.3600","7.88311","0.08349"
"425.7830","-12.3516","7.85812","0.08370"
"426.2830","-12.3435","7.84369","0.08390"
"426.7830","-12.3350","7.91696","0.08399"
"427.2640","-12.3270","7.78634","0.08432"
"427.7640","-12.3187","7.86550","0.08440"
"428.2640","-12.3103","7.88822","0.08454"
"428.6630","-12.3036","7.76251","0.08479"
"429.1630","-12.2952","7.84754","0.08485"
"429.6630","-12.2872","7.89087","0.08496"
"430.1190","-12.2794","7.78497","0.08525"
"430.6190","-12.2712","7.85905","0.08534"
"431.1190","-12.2627","7.76899","0.08561"
"431.6190","-12.2543","7.82592","0.08572"
"432.1190","-12.2462","7.76024","0.08595"
"432.6190","-12.2377","7.80657","0.08607"
"433.1190","-12.2296","7.78300","0.08626"
"433.6190","-12.2210","7.76944","0.08643"
"434.1190","-12.2126","7.81867","0.08654"
"434.6190","-12.2045","7.73091","0.08679"
"435.1190","-12.1961","7.80144","0.08687"
"435.6190","-12.1879","7.70645","0.08713"
"436.1190","-12.1793","7.77443","0.08722"
"436.6190","-12.1710","7.71465","0.08745"
"437.1190","-12.1629","7.74200","0.08758"
"437.6190","-12.1543","7.69187","0.08782"
"438.1190","-12.1462","7.73023","0.08794"
"438.6190","-12.1377","7.68706","0.08816"
"439.1190","-12.1295","7.72076","0.08829"
"439.6190","-12.1210","7.68406","0.08852"
"440.1190","-12.1126","7.71125","0.08866"
"440.6190","-12.1047","7.64651","0.08891"
"441.1190","-12.0962","7.69913","0.08902"
"441.6010","-12.0879","7.59142","0.08930"
"442.1010","-12.0796","7.65522","0.08939"
"442.6010","-12.0714","7.64891","0.08956"
"443.1010","-12.0633","7.62476","0.08975"
"443.6010","-12.0546","7.61514","0.08993"
"444.1010","-12.0464","7.62550","0.09008"
"444.6010","-12.0381","7.60652","0.09026"
"445.1010","-12.0297","7.59597","0.09044"
"445.6010","-12.0215","7.59418","0.09061"
"446.1010","-12.0130","7.55607","0.09083"
"446.6010","-12.0048","7.57743","0.09097"
"447.1010","-11.9963","7.52608","0.09120"
"447.6010","-11.9880","7.58085","0.09131"
"448.1010","-11.9798","7.53226","0.09153"
"448.6010","-11.9713","7.50151","0.09173"
"449.1010","-11.9631","7.54044","0.09185"
"449.6010","-11.9546","7.48733","0.09207"
"450.1010","-11.9464","7.51262","0.09220"
"450.6010","-11.9382","7.47352","0.09241"
"451.1010","-11.9296","7.46938","0.09259"
"451.6010","-11.9214","7.45913","0.09277"
"452.1010","-11.9131","7.45102","0.09295"
"452.6010","-11.9048","7.45394","0.09311"
"453.1010","-11.8963","7.39886","0.09335"
"453.6010","-11.8878","7.45551","0.09345"
"454.1010","-11.8799","7.39020","0.09368"
"454.6010","-11.8714","7.37445","0.09387"
"455.1010","-11.8630","7.39480","0.09402"
"455.6010","-11.8546","7.35396","0.09423"
"456.1010","-11.8464","7.36886","0.09438"
"456.6010","-11.8382","7.33158","0.09459"
"457.1010","-11.8296","7.29113","0.09481"
"457.6010","-11.8215","7.32961","0.09493"
"458.1010","-11.8131","7.29067","0.09514"
"458.6010","-11.8046","7.25854","0.09535"
"459.1010","-11.7964","7.28342","0.09548"
"459.6010","-11.7880","7.24445","0.09570"
"460.1010","-11.7798","7.23096","0.09588"
"460.6010","-11.7714","7.21818","0.09606"
"461.1010","-11.7630","7.19239","0.09626"
"461.6010","-11.7547","7.18454","0.09644"
"462.1010","-11.7463","7.16879","0.09662"
"462.6010","-11.7382","7.16505","0.09679"
"463.1010","-11.7297","7.13682","0.09699"
"463.6010","-11.7214","7.09804","0.09721"
"464.1010","-11.7131","7.13897","0.09733"
"464.6010","-11.7045","7.08404","0.09756"
"465.1010","-11.6964","7.05855","0.09776"
"465.6010","-11.6882","7.06370","0.09792"
"466.1010","-11.6798","7.02436","0.09813"
"466.6010","-11.6713","7.00740","0.09832"
"467.1010","-11.6628","7.02853","0.09847"
"467.6010","-11.6549","6.97854","0.09868"
"468.1010","-11.6465","6.94865","0.09889"
"468.6010","-11.6380","6.95241","0.09905"
"469.1010","-11.6295","6.92089","0.09926"
"469.6010","-11.6213","6.88596","0.09947"
"470.1010","-11.6132","6.88609","0.09963"
"470.6010","-11.6046","6.86519","0.09983"
"471.1010","-11.5965","6.82527","0.10004"
"471.6010","-11.5880","6.80129","0.10024"
"472.1010","-11.5796","6.79171","0.10042"
"472.6010","-11.5715","6.77386","0.10060"
"473.1010","-11.5630","6.74716","0.10081"
"473.6010","-11.5548","6.69790","0.10103"
"474.1010","-11.5463","6.67447","0.10123"
"474.4660","-11.5402","6.35424","0.10170"
"474.4770","-11.5400","5.87273","0.10230"
"474.4870","-11.5396","5.26875","0.10307"
"474.4940","-11.5392","4.88106","0.10357"