File: Coupon Test Data/test__20250509_94834_4.csv
Time,Displacement,Force,Strain 1
(s),(mm),(kN),(mm/mm)
"0.0000","-13.6618","0.36799","-0.00069"
"0.4000","-13.6571","0.42607","-0.00067"
"0.8000","-13.6501","0.52207","-0.00063"
"1.2000","-13.6434","0.61336","-0.00060"
"1.6000","-13.6368","0.70060","-0.00057"
"2.0000","-13.6300","0.79042","-0.00053"
"2.4000","-13.6236","0.87325","-0.00050"
"2.8000","-13.6166","0.96271","-0.00047"
"3.2000","-13.6101","1.04670","-0.00044"
"3.6000","-13.6033","1.13285","-0.00041"
"4.0000","-13.5968","1.21487","-0.00037"
"4.4000","-13.5901","1.29755","-0.00034"
"4.8000","-13.5834","1.37784","-0.00031"
"5.2000","-13.5767","1.45584","-0.00028"
"5.6000","-13.5700","1.52981","-0.00026"
"6.0000","-13.5633","1.61061","-0.00022"
"6.4000","-13.5567","1.68677","-0.00019"
"6.8000","-13.5500","1.76434","-0.00016"
"7.2000","-13.5434","1.82872","-0.00014"
"7.6000","-13.5368","1.90580","-0.00011"
"8.0000","-13.5300","1.98616","-0.00008"
"8.4000","-13.5234","2.06031","-0.00005"
"8.8000","-13.5167","2.13073","-0.00002"
"9.2000","-13.5101","2.20527","0.00001"
"9.6000","-13.5034","2.28083","0.00004"
"10.0000","-13.4968","2.34918","0.00006"
"10.4000","-13.4900","2.42557","0.00009"
"10.8000","-13.4834","2.49627","0.00012"
"11.2000","-13.4766","2.56878","0.00015"
"11.6000","-13.4701","2.64088","0.00018"
"12.0000","-13.4632","2.71182","0.00020"
"12.4000","-13.4568","2.78089","0.00023"
"12.8000","-13.4499","2.85490","0.00026"
"13.2000","-13.4433","2.92256","0.00029"
"13.6000","-13.4366","2.99317","0.00032"
"14.0000","-13.4299","3.06101","0.00034"
"14.4000","-13.4235","3.12843","0.00037"
"14.8000","-13.4167","3.19773","0.00040"
"15.2000","-13.4102","3.26493","0.00042"
"15.6000","-13.4034","3.33319","0.00045"
"16.0000","-13.3967","3.40172","0.00048"
"16.4000","-13.3901","3.46721","0.00051"
"16.8000","-13.3833","3.53610","0.00053"
"17.2000","-13.3768","3.60123","0.00056"
"17.6000","-13.3701","3.66731","0.00059"
"18.0000","-13.3633","3.73598","0.00061"
"18.4000","-13.3568","3.79885","0.00064"
"18.8000","-13.3498","3.86902","0.00067"
"19.2000","-13.3435","3.92914","0.00069"
"19.6000","-13.3366","3.99796","0.00072"
"20.0000","-13.3300","4.06046","0.00075"
"20.4000","-13.3233","4.12586","0.00077"
"20.8000","-13.3165","4.19036","0.00080"
"21.2000","-13.3101","4.25188","0.00082"
"21.6000","-13.3032","4.31692","0.00085"
"22.0000","-13.2967","4.37820","0.00088"
"22.4000","-13.2901","4.43996","0.00090"
"22.8000","-13.2834","4.50338","0.00093"
"23.2000","-13.2768","4.56363","0.00095"
"23.6000","-13.2699","4.62785","0.00098"
"24.0000","-13.2634","4.68681","0.00100"
"24.4000","-13.2568","4.74760","0.00103"
"24.8000","-13.2500","4.80881","0.00106"
"25.2000","-13.2435","4.86648","0.00108"
"25.6000","-13.2365","4.92976","0.00111"
"26.0000","-13.2302","4.98498","0.00113"
"26.4000","-13.2232","5.04721","0.00116"
"26.8000","-13.2168","5.10303","0.00118"
"27.2000","-13.2100","5.16250","0.00121"
"27.6000","-13.2034","5.21895","0.00123"
"28.0000","-13.1967","5.27656","0.00126"
"28.4000","-13.1899","5.33408","0.00128"
"28.8000","-13.1833","5.39102","0.00131"
"29.2000","-13.1767","5.44553","0.00134"
"29.6000","-13.1700","5.50258","0.00136"
"30.0000","-13.1634","5.55532","0.00138"
"30.4000","-13.1566","5.61188","0.00141"
"30.8000","-13.1500","5.66488","0.00144"
"31.2000","-13.1433","5.71873","0.00146"
"31.6000","-13.1366","5.77207","0.00149"
"32.0000","-13.1301","5.82332","0.00151"
"32.4000","-13.1233","5.87626","0.00154"
"32.8000","-13.1169","5.92340","0.00156"
"33.2000","-13.1100","5.97331","0.00158"
"33.6000","-13.1034","6.02056","0.00161"
"34.0000","-13.0966","6.07059","0.00163"
"34.4000","-13.0901","6.11510","0.00165"
"34.8000","-13.0833","6.16423","0.00167"
"35.2000","-13.0767","6.20777","0.00170"
"35.6000","-13.0698","6.25833","0.00172"
"36.0000","-13.0633","6.30094","0.00174"
"36.4000","-13.0565","6.34967","0.00177"
"36.8000","-13.0500","6.39323","0.00179"
"37.2000","-13.0433","6.43910","0.00181"
"37.6000","-13.0367","6.48383","0.00184"
"38.0000","-13.0301","6.52792","0.00186"
"38.4000","-13.0233","6.57433","0.00189"
"38.8000","-13.0168","6.61726","0.00191"
"39.2000","-13.0100","6.66182","0.00194"
"39.6000","-13.0035","6.70534","0.00196"
"40.0000","-12.9968","6.74862","0.00198"
"40.4000","-12.9901","6.79219","0.00201"
"40.8000","-12.9833","6.83671","0.00204"
"41.2000","-12.9767","6.87694","0.00206"
"41.6000","-12.9699","6.92288","0.00209"
"42.0000","-12.9635","6.95976","0.00212"
"42.4000","-12.9564","7.00656","0.00215"
"42.8000","-12.9502","7.04082","0.00217"
"43.2000","-12.9431","7.08648","0.00220"
"43.6000","-12.9367","7.12264","0.00223"
"44.0000","-12.9299","7.16279","0.00226"
"44.4000","-12.9233","7.20080","0.00229"
"44.8000","-12.9167","7.23690","0.00232"
"45.2000","-12.9100","7.27475","0.00235"
"45.6000","-12.9034","7.31023","0.00238"
"46.0000","-12.8966","7.34597","0.00242"
"46.4000","-12.8900","7.38176","0.00245"
"46.8000","-12.8834","7.41450","0.00248"
"47.2000","-12.8766","7.44980","0.00252"
"47.6000","-12.8701","7.48154","0.00255"
"48.0000","-12.8635","7.51259","0.00259"
"48.4000","-12.8566","7.54796","0.00263"
"48.8000","-12.8502","7.57389","0.00266"
"49.2000","-12.8431","7.60937","0.00270"
"49.6000","-12.8370","7.63247","0.00274"
"50.0000","-12.8298","7.66636","0.00278"
"50.4000","-12.8235","7.68952","0.00282"
"50.8000","-12.8165","7.71876","0.00287"
"51.2000","-12.8099","7.74236","0.00291"
"51.6000","-12.8033","7.76769","0.00295"
"52.0000","-12.7966","7.79256","0.00300"
"52.4000","-12.7900","7.81589","0.00305"
"52.8000","-12.7834","7.83698","0.00309"
"53.2000","-12.7767","7.86093","0.00314"
"53.6000","-12.7701","7.87995","0.00319"
"54.0000","-12.7633","7.90101","0.00324"
"54.4000","-12.7567","7.91872","0.00329"
"54.8000","-12.7501","7.93333","0.00334"
"55.2000","-12.7433","7.95498","0.00339"
"55.6000","-12.7369","7.97284","0.00344"
"56.0000","-12.7298","7.99528","0.00350"
"56.4000","-12.7236","8.00585","0.00356"
"56.8000","-12.7165","8.02569","0.00362"
"57.2000","-12.7101","8.03757","0.00369"
"57.6000","-12.7032","8.05503","0.00375"
"58.0000","-12.6968","8.06697","0.00380"
"58.4000","-12.6899","8.08499","0.00387"
"58.8000","-12.6833","8.09709","0.00393"
"59.2000","-12.6765","8.11225","0.00399"
"59.6000","-12.6700","8.12256","0.00406"
"60.0000","-12.6633","8.13662","0.00413"
"60.4000","-12.6567","8.14703","0.00419"
"60.8000","-12.6500","8.15897","0.00426"
"61.2000","-12.6433","8.16850","0.00433"
"61.6000","-12.6368","8.15871","0.00437"
"62.0000","-12.6299","8.18434","0.00443"
"62.4000","-12.6235","8.20238","0.00448"
"62.8000","-12.6166","8.21499","0.00455"
"63.2000","-12.6103","8.22011","0.00462"
"63.6000","-12.6033","8.22840","0.00470"
"64.0000","-12.5968","8.23492","0.00477"
"64.4000","-12.5899","8.24436","0.00484"
"64.8000","-12.5835","8.25035","0.00491"
"65.2000","-12.5766","8.26328","0.00499"
"65.6000","-12.5702","8.26854","0.00506"
"66.0000","-12.5631","8.28219","0.00513"
"66.4000","-12.5567","8.28524","0.00520"
"66.8000","-12.5498","8.29667","0.00528"
"67.2000","-12.5433","8.30320","0.00535"
"67.6000","-12.5366","8.31028","0.00542"
"68.0000","-12.5299","8.31876","0.00550"
"68.4000","-12.5235","8.32481","0.00557"
"68.8000","-12.5165","8.33346","0.00565"
"69.2000","-12.5101","8.33828","0.00572"
"69.6000","-12.5033","8.34489","0.00579"
"70.0000","-12.4968","8.35167","0.00586"
"70.4000","-12.4901","8.35485","0.00593"
"70.8000","-12.4834","8.36008","0.00600"
"71.2000","-12.4767","8.36995","0.00606"
"71.6000","-12.4701","8.37922","0.00613"
"72.0000","-12.4632","8.39012","0.00620"
"72.4000","-12.4568","8.39204","0.00627"
"72.8000","-12.4498","8.40129","0.00635"
"73.2000","-12.4435","8.40076","0.00642"
"73.6000","-12.4365","8.41050","0.00649"
"74.0000","-12.4300","8.41338","0.00656"
"74.4000","-12.4233","8.42017","0.00663"
"74.8000","-12.4166","8.42681","0.00670"
"75.2000","-12.4101","8.43214","0.00677"
"75.6000","-12.4032","8.43970","0.00685"
"76.0000","-12.3967","8.44452","0.00692"
"76.4000","-12.3900","8.44824","0.00700"
"76.8000","-12.3833","8.45453","0.00707"
"77.2000","-12.3768","8.45699","0.00715"
"77.6000","-12.3699","8.46505","0.00723"
"78.0000","-12.3634","8.46787","0.00730"
"78.4000","-12.3568","8.47374","0.00737"
"78.8000","-12.3500","8.48047","0.00745"
"79.2000","-12.3435","8.48308","0.00753"
"79.6000","-12.3365","8.49131","0.00761"
"80.0000","-12.3302","8.49219","0.00768"
"80.4000","-12.3232","8.50146","0.00776"
"80.8000","-12.3168","8.50443","0.00783"
"81.2000","-12.3099","8.51215","0.00790"
"81.6000","-12.3033","8.51495","0.00798"
"82.0000","-12.2967","8.52088","0.00805"
"82.4000","-12.2899","8.52551","0.00813"
"82.8000","-12.2833","8.53140","0.00820"
"83.2000","-12.2767","8.53478","0.00828"
"83.6000","-12.2700","8.54255","0.00835"
"84.0000","-12.2634","8.54487","0.00843"
"84.4000","-12.2566","8.55127","0.00850"
"84.8000","-12.2500","8.55424","0.00858"
"85.2000","-12.2434","8.55828","0.00865"
"85.6000","-12.2367","8.56312","0.00873"
"86.0000","-12.2302","8.56521","0.00880"
"86.4000","-12.2232","8.56979","0.00887"
"86.8000","-12.2169","8.57219","0.00894"
"87.2000","-12.2099","8.57065","0.00900"
"87.6000","-12.2034","8.54348","0.00902"
"88.0000","-12.1966","8.57984","0.00908"
"88.4000","-12.1902","8.60206","0.00913"
"88.8000","-12.1833","8.61884","0.00920"
"89.2000","-12.1767","8.61933","0.00928"
"89.6000","-12.1698","8.62087","0.00935"
"90.0000","-12.1634","8.61067","0.00943"
"90.4000","-12.1566","8.60737","0.00950"
"90.8000","-12.1500","8.59046","0.00957"
"91.2000","-12.1432","8.50122","0.00956"
"91.6000","-12.1366","8.55718","0.00960"
"92.0000","-12.1300","8.60454","0.00965"
"92.4000","-12.1233","8.63806","0.00970"
"92.6730","-12.1189","8.48338","0.00967"
"93.0730","-12.1119","8.51560","0.00970"
"93.4730","-12.1057","8.57596","0.00974"
"93.8730","-12.0986","8.63706","0.00978"
"94.2730","-12.0922","8.66882","0.00983"
"94.5670","-12.0871","8.47889","0.00978"
"94.9670","-12.0804","8.54574","0.00982"
"95.3670","-12.0740","8.60908","0.00985"
"95.7670","-12.0672","8.66387","0.00990"
"96.0050","-12.0634","8.50989","0.00986"
"96.4050","-12.0563","8.52923","0.00987"
"96.8050","-12.0501","8.59341","0.00991"
"97.2050","-12.0431","8.65749","0.00995"
"97.5080","-12.0381","8.48051","0.00989"
"97.9080","-12.0315","8.55089","0.00993"
"98.3080","-12.0249","8.61902","0.00996"
"98.7080","-12.0183","8.67363","0.01000"
"99.0200","-12.0129","8.50337","0.00995"
"99.4200","-12.0065","8.57266","0.00998"
"99.8200","-11.9995","8.64584","0.01002"
"100.1880","-11.9937","8.60351","0.01002"
"100.5060","-11.9881","8.52938","0.00999"
"100.9060","-11.9816","8.60128","0.01003"
"101.3060","-11.9749","8.66765","0.01006"
"101.5510","-11.9708","8.52902","0.00996"
"101.9510","-11.9643","8.54823","0.00996"
"102.3510","-11.9573","8.62492","0.01000"
"102.7510","-11.9510","8.68260","0.01002"
"103.0230","-11.9462","8.50269","0.00992"
"103.4230","-11.9397","8.57285","0.00998"
"103.8230","-11.9330","8.64577","0.01003"
"104.2230","-11.9264","8.66522","0.01014"
"104.4620","-11.9224","8.52058","0.01042"
"104.8620","-11.9156","8.59672","0.01046"
"105.2620","-11.9091","8.66492","0.01051"
"105.5800","-11.9038","8.60575","0.01071"
"105.9000","-11.8983","8.54758","0.01090"
"106.3000","-11.8918","8.62022","0.01094"
"106.7000","-11.8850","8.68905","0.01099"
"107.0110","-11.8800","8.51620","0.01133"
"107.4110","-11.8730","8.59184","0.01137"
"107.8110","-11.8666","8.66127","0.01141"
"108.1770","-11.8603","8.62482","0.01160"
"108.4950","-11.8550","8.55220","0.01180"
"108.8950","-11.8486","8.62374","0.01184"
"109.2950","-11.8417","8.69365","0.01189"
"109.5750","-11.8372","8.51393","0.01223"
"109.9750","-11.8302","8.59053","0.01228"
"110.3750","-11.8241","8.65726","0.01231"
"110.7410","-11.8175","8.63128","0.01249"
"111.0580","-11.8124","8.54691","0.01271"
"111.4580","-11.8056","8.62369","0.01275"
"111.8580","-11.7989","8.69316","0.01280"
"112.1650","-11.7939","8.51667","0.01315"
"112.5650","-11.7872","8.58977","0.01318"
"112.9650","-11.7808","8.66110","0.01322"
"113.3270","-11.7744","8.63425","0.01339"
"113.6430","-11.7693","8.54785","0.01361"
"114.0430","-11.7625","8.62589","0.01365"
"114.4430","-11.7559","8.69560","0.01370"
"114.7590","-11.7506","8.51910","0.01405"
"115.1590","-11.7440","8.59128","0.01409"
"115.5590","-11.7375","8.66396","0.01413"
"115.9210","-11.7313","8.63416","0.01430"
"116.2380","-11.7262","8.55102","0.01451"
"116.6380","-11.7191","8.63299","0.01455"
"117.0380","-11.7128","8.70029","0.01459"
"117.3860","-11.7067","8.66316","0.01476"
"117.7080","-11.7016","8.60640","0.01494"
"118.1080","-11.6948","8.68374","0.01498"
"118.5080","-11.6883","8.75152","0.01502"
"118.9080","-11.6816","8.70049","0.01503"
"119.3080","-11.6748","8.76161","0.01506"
"119.7080","-11.6683","8.65477","0.01526"
"120.1080","-11.6614","8.71519","0.01532"
"120.4050","-11.6566","8.57896","0.01559"
"120.8050","-11.6498","8.57532","0.01573"
"121.2050","-11.6432","8.64844","0.01576"
"121.6050","-11.6366","8.71545","0.01581"
"121.8760","-11.6320","8.55483","0.01592"
"122.2760","-11.6255","8.62679","0.01595"
"122.6760","-11.6187","8.70310","0.01599"
"123.0760","-11.6123","8.75459","0.01601"
"123.4760","-11.6052","8.76164","0.01608"
"123.8760","-11.5991","8.78105","0.01617"
"124.2760","-11.5919","8.68899","0.01644"
"124.6760","-11.5855","8.75087","0.01649"
"125.0760","-11.5786","8.81802","0.01654"
"125.4760","-11.5721","8.82484","0.01656"
"125.8760","-11.5655","8.86567","0.01659"
"126.2760","-11.5587","8.84799","0.01659"
"126.6760","-11.5520","8.87637","0.01661"
"127.0760","-11.5453","8.91483","0.01663"
"127.4760","-11.5387","8.91763","0.01666"
"127.8760","-11.5321","8.94811","0.01668"
"128.2760","-11.5254","8.97779","0.01672"
"128.5040","-11.5214","8.74979","0.01665"
"128.9040","-11.5151","8.81515","0.01668"
"129.3040","-11.5082","8.88830","0.01672"
"129.7040","-11.5016","8.92476","0.01674"
"130.0390","-11.4960","8.82260","0.01670"
"130.4390","-11.4893","8.89600","0.01674"
"130.8390","-11.4827","8.96604","0.01677"
"131.2390","-11.4761","9.02103","0.01680"
"131.5950","-11.4701","8.96824","0.01678"
"131.9130","-11.4647","8.88038","0.01673"
"132.3130","-11.4582","8.94766","0.01677"
"132.7130","-11.4513","9.00576","0.01683"
"133.0700","-11.4454","8.83982","0.01712"
"133.4700","-11.4387","8.90177","0.01717"
"133.8700","-11.4322","8.96789","0.01721"
"134.2700","-11.4255","9.02852","0.01726"
"134.6470","-11.4192","8.92735","0.01749"
"135.0470","-11.4125","8.96092","0.01757"
"135.4470","-11.4058","9.01973","0.01762"
"135.8470","-11.3994","9.06573","0.01767"
"136.2470","-11.3925","9.07611","0.01774"
"136.6470","-11.3861","9.04907","0.01785"
"137.0470","-11.3791","9.07580","0.01793"
"137.3560","-11.3743","8.92931","0.01790"
"137.5830","-11.3701","8.79900","0.01785"
"137.9830","-11.3637","8.87164","0.01789"
"138.3830","-11.3569","8.94795","0.01792"
"138.7830","-11.3504","9.01650","0.01795"
"139.1830","-11.3437","9.07860","0.01799"
"139.4010","-11.3400","8.89254","0.01792"
"139.7130","-11.3346","8.81668","0.01789"
"140.1130","-11.3282","8.89163","0.01792"
"140.5130","-11.3215","8.96802","0.01795"
"140.9130","-11.3149","9.03950","0.01799"
"141.3130","-11.3083","9.09649","0.01802"
"141.4200","-11.3062","8.78453","0.01790"
"141.8200","-11.2996","8.83777","0.01792"
"142.2200","-11.2929","8.91656","0.01795"
"142.6200","-11.2864","8.98937","0.01799"
"143.0200","-11.2796","9.06021","0.01802"
"143.2800","-11.2755","8.92078","0.01796"
"143.5920","-11.2699","8.83143","0.01793"
"143.9920","-11.2635","8.90611","0.01796"
"144.3920","-11.2567","8.98458","0.01800"
"144.7920","-11.2501","9.05506","0.01803"
"145.1740","-11.2437","9.02161","0.01802"
"145.3110","-11.2413","8.79709","0.01793"
"145.7110","-11.2348","8.86984","0.01796"
"146.1110","-11.2282","8.94587","0.01800"
"146.5110","-11.2214","9.02168","0.01803"
"146.9110","-11.2148","9.08581","0.01806"
"147.0690","-11.2119","8.83886","0.01796"
"147.4690","-11.2057","8.85923","0.01797"
"147.8690","-11.1987","8.94025","0.01801"
"148.2690","-11.1922","9.01265","0.01804"
"148.6690","-11.1855","9.07980","0.01807"
"148.8910","-11.1818","8.89562","0.01793"
"149.2070","-11.1767","8.84101","0.01791"
"149.6070","-11.1698","8.92189","0.01795"
"150.0070","-11.1634","8.99434","0.01798"
"150.4070","-11.1563","9.07094","0.01801"
"150.7510","-11.1509","9.02635","0.01799"
"150.8970","-11.1485","8.81287","0.01813"
"151.2970","-11.1416","8.89131","0.01824"
"151.6970","-11.1353","8.96495","0.01828"
"152.0970","-11.1283","9.04250","0.01833"
"152.4970","-11.1218","9.10386","0.01839"
"152.7160","-11.1180","8.81776","0.01886"
"153.1160","-11.1114","8.89190","0.01890"
"153.5160","-11.1049","8.96737","0.01894"
"153.9160","-11.0981","9.04317","0.01898"
"154.3160","-11.0917","9.10540","0.01903"
"154.4690","-11.0888","8.87959","0.01940"
"154.8690","-11.0822","8.88241","0.01952"
"155.2690","-11.0755","8.96040","0.01956"
"155.6690","-11.0689","9.03503","0.01960"
"156.0690","-11.0623","9.10207","0.01965"
"156.2910","-11.0584","8.88982","0.02002"
"156.6910","-11.0519","8.88903","0.02015"
"157.0910","-11.0450","8.96914","0.02018"
"157.4910","-11.0385","9.04252","0.02022"
"157.8910","-11.0317","9.11113","0.02027"
"158.0550","-11.0289","8.88560","0.02064"
"158.4550","-11.0225","8.88811","0.02076"
"158.8550","-11.0157","8.96778","0.02079"
"159.2550","-11.0092","9.04043","0.02083"
"159.6550","-11.0024","9.10906","0.02089"
"159.8200","-10.9996","8.88657","0.02125"
"160.2200","-10.9931","8.89002","0.02137"
"160.6200","-10.9862","8.97034","0.02141"
"161.0200","-10.9799","9.04071","0.02145"
"161.4200","-10.9729","9.11065","0.02150"
"161.5960","-10.9701","8.88896","0.02186"
"161.9960","-10.9634","8.89298","0.02198"
"162.3960","-10.9567","8.97024","0.02202"
"162.7960","-10.9501","9.04391","0.02206"
"163.1960","-10.9433","9.11017","0.02211"
"163.3410","-10.9408","8.87368","0.02249"
"163.7410","-10.9344","8.89504","0.02258"
"164.1410","-10.9277","8.97225","0.02262"
"164.5410","-10.9211","9.04746","0.02265"
"164.9410","-10.9144","9.11236","0.02270"
"165.1250","-10.9112","8.88626","0.02307"
"165.5250","-10.9045","8.89991","0.02319"
"165.9250","-10.8978","8.97682","0.02322"
"166.3250","-10.8913","9.04882","0.02326"
"166.7250","-10.8845","9.11364","0.02331"
"166.8690","-10.8823","8.87619","0.02368"
"167.2690","-10.8753","8.91077","0.02377"
"167.6690","-10.8690","8.98332","0.02380"
"168.0690","-10.8621","9.06025","0.02384"
"168.4690","-10.8555","9.12142","0.02390"
"168.6560","-10.8524","8.89481","0.02426"
"169.0560","-10.8457","8.94422","0.02432"
"169.4560","-10.8393","9.01728","0.02436"
"169.8560","-10.8323","9.09359","0.02440"
"170.2010","-10.8267","9.04692","0.02456"
"170.4360","-10.8228","8.90251","0.02483"
"170.8360","-10.8161","8.97676","0.02487"
"171.2360","-10.8095","9.04941","0.02491"
"171.6360","-10.8029","9.11847","0.02495"
"172.0360","-10.7962","9.08393","0.02500"
"172.4360","-10.7894","9.12119","0.02503"
"172.8360","-10.7829","9.18036","0.02507"
"173.0890","-10.7785","9.03307","0.02534"
"173.4140","-10.7730","8.99995","0.02549"
"173.8140","-10.7666","9.07240","0.02552"
"174.2140","-10.7598","9.14704","0.02556"
"174.6140","-10.7533","9.21425","0.02560"
"175.0140","-10.7465","9.24734","0.02564"
"175.4140","-10.7398","9.20201","0.02562"
"175.8140","-10.7331","9.22999","0.02564"
"176.2140","-10.7266","9.27425","0.02566"
"176.6140","-10.7197","9.29437","0.02568"
"176.8730","-10.7153","9.12195","0.02562"
"177.2730","-10.7088","9.19324","0.02565"
"177.6730","-10.7021","9.26273","0.02568"
"178.0730","-10.6954","9.32159","0.02571"
"178.3330","-10.6910","9.18064","0.02566"
"178.6460","-10.6860","9.09039","0.02563"
"179.0460","-10.6792","9.16704","0.02566"
"179.4460","-10.6726","9.23752","0.02569"
"179.7930","-10.6668","9.19581","0.02567"
"180.0230","-10.6628","9.05126","0.02561"
"180.4230","-10.6564","9.12408","0.02564"
"180.8230","-10.6494","9.20483","0.02568"
"181.2230","-10.6432","9.27377","0.02571"
"181.6230","-10.6362","9.34453","0.02574"
"182.0000","-10.6300","9.28417","0.02588"
"182.3390","-10.6243","9.18241","0.02610"
"182.7390","-10.6175","9.25124","0.02615"
"183.1390","-10.6112","9.31207","0.02620"
"183.5390","-10.6042","9.35961","0.02627"
"183.7680","-10.6006","9.09639","0.02670"
"184.1680","-10.5936","9.16990","0.02675"
"184.5680","-10.5875","9.23655","0.02678"
"184.9680","-10.5803","9.31250","0.02683"
"185.3680","-10.5739","9.36633","0.02689"
"185.5610","-10.5706","9.13624","0.02727"
"185.9610","-10.5640","9.17338","0.02735"
"186.3610","-10.5575","9.24562","0.02739"
"186.7610","-10.5506","9.31968","0.02743"
"187.1610","-10.5442","9.37869","0.02747"
"187.3820","-10.5402","9.16098","0.02768"
"187.7820","-10.5336","9.17479","0.02775"
"188.1820","-10.5269","9.24917","0.02778"
"188.5820","-10.5204","9.31598","0.02782"
"188.9000","-10.5150","9.18855","0.02783"
"189.3000","-10.5083","9.21240","0.02786"
"189.7000","-10.5019","9.28368","0.02790"
"190.1000","-10.4949","9.35650","0.02794"
"190.5000","-10.4885","9.39294","0.02796"
"190.9000","-10.4814","9.33552","0.02807"
"191.3000","-10.4752","9.36045","0.02814"
"191.7000","-10.4682","9.39252","0.02821"
"192.0590","-10.4624","9.23612","0.02847"
"192.4590","-10.4556","9.29917","0.02852"
"192.8590","-10.4490","9.36251","0.02857"
"193.2590","-10.4424","9.40787","0.02863"
"193.4500","-10.4389","9.14245","0.02896"
"193.8500","-10.4326","9.20807","0.02901"
"194.2500","-10.4257","9.28510","0.02905"
"194.6500","-10.4193","9.35221","0.02910"
"195.0500","-10.4124","9.41493","0.02916"
"195.2270","-10.4095","9.18415","0.02943"
"195.6270","-10.4029","9.21586","0.02952"
"196.0270","-10.3962","9.29104","0.02956"
"196.4270","-10.3897","9.36033","0.02961"
"196.8270","-10.3828","9.42359","0.02967"
"196.9960","-10.3800","9.19615","0.02993"
"197.3960","-10.3736","9.20405","0.03005"
"197.7960","-10.3666","9.28261","0.03010"
"198.1960","-10.3603","9.35178","0.03014"
"198.5960","-10.3533","9.41542","0.03020"
"198.7750","-10.3504","9.18644","0.03047"
"199.1750","-10.3437","9.21495","0.03057"
"199.5750","-10.3371","9.28797","0.03062"
"199.9750","-10.3306","9.35950","0.03066"
"200.3750","-10.3237","9.42115","0.03073"
"200.5250","-10.3211","9.18943","0.03099"
"200.9250","-10.3145","9.22309","0.03109"
"201.3250","-10.3079","9.29688","0.03114"
"201.7250","-10.3012","9.36908","0.03119"
"202.1250","-10.2947","9.42537","0.03125"
"202.3500","-10.2909","9.16852","0.03157"
"202.7500","-10.2841","9.24154","0.03163"
"203.1500","-10.2776","9.31411","0.03168"
"203.5500","-10.2707","9.38718","0.03173"
"203.9500","-10.2642","9.42805","0.03181"
"204.1110","-10.2615","9.17860","0.03211"
"204.5110","-10.2547","9.25188","0.03216"
"204.9110","-10.2485","9.32165","0.03221"
"205.3110","-10.2414","9.39656","0.03226"
"205.7110","-10.2350","9.44380","0.03233"
"205.9010","-10.2314","9.17747","0.03266"
"206.3010","-10.2250","9.24588","0.03272"
"206.7010","-10.2184","9.31976","0.03277"
"207.1010","-10.2117","9.39109","0.03282"
"207.5010","-10.2051","9.44230","0.03290"
"207.7070","-10.2013","9.18485","0.03323"
"208.1070","-10.1948","9.25312","0.03328"
"208.5070","-10.1881","9.32783","0.03333"
"208.9070","-10.1815","9.39646","0.03339"
"209.2530","-10.1757","9.34911","0.03355"
"209.4850","-10.1718","9.19946","0.03379"
"209.8850","-10.1654","9.27021","0.03384"
"210.2850","-10.1586","9.34606","0.03389"
"210.6850","-10.1519","9.41167","0.03395"
"210.9430","-10.1477","9.27482","0.03420"
"211.2570","-10.1422","9.19854","0.03444"
"211.6570","-10.1360","9.26770","0.03450"
"212.0570","-10.1290","9.34568","0.03457"
"212.4570","-10.1226","9.40965","0.03465"
"212.7010","-10.1182","9.27306","0.03515"
"213.0150","-10.1131","9.18628","0.03543"
"213.4150","-10.1065","9.26110","0.03546"
"213.8150","-10.0997","9.33583","0.03549"
"214.2150","-10.0932","9.40207","0.03553"
"214.5170","-10.0878","9.27275","0.03562"
"214.8300","-10.0828","9.18414","0.03558"
"215.2300","-10.0761","9.25924","0.03559"
"215.6300","-10.0695","9.33258","0.03562"
"216.0300","-10.0628","9.40050","0.03565"
"216.2950","-10.0584","9.26238","0.03559"
"216.6130","-10.0531","9.20526","0.03555"
"217.0130","-10.0465","9.27971","0.03558"
"217.4130","-10.0398","9.35258","0.03561"
"217.8130","-10.0331","9.41326","0.03563"
"217.9820","-10.0300","9.17992","0.03549"
"218.3820","-10.0239","9.20805","0.03550"
"218.7820","-10.0168","9.28729","0.03554"
"219.1820","-10.0105","9.35549","0.03557"
"219.5820","-10.0036","9.41928","0.03560"
"219.7760","-10.0004","9.19326","0.03549"
"220.1760","-9.9938","9.20689","0.03550"
"220.5760","-9.9870","9.28362","0.03553"
"220.9760","-9.9805","9.35439","0.03557"
"221.3760","-9.9736","9.41633","0.03559"
"221.5360","-9.9710","9.16889","0.03546"
"221.9360","-9.9644","9.21666","0.03549"
"222.3360","-9.9579","9.28939","0.03552"
"222.7360","-9.9511","9.36268","0.03556"
"223.1360","-9.9444","9.41879","0.03558"
"223.3580","-9.9406","9.16629","0.03546"
"223.7580","-9.9340","9.23592","0.03549"
"224.1580","-9.9273","9.31000","0.03552"
"224.5580","-9.9207","9.37948","0.03556"
"224.9580","-9.9141","9.40950","0.03558"
"225.1050","-9.9118","9.15582","0.03546"
"225.5050","-9.9048","9.23166","0.03549"
"225.9050","-9.8983","9.30317","0.03553"
"226.3050","-9.8915","9.37523","0.03556"
"226.6760","-9.8853","9.33386","0.03553"
"226.9080","-9.8815","9.18621","0.03546"
"227.3080","-9.8749","9.26010","0.03550"
"227.7080","-9.8684","9.33116","0.03553"
"228.1080","-9.8614","9.40019","0.03556"
"228.4400","-9.8561","9.26808","0.03548"
"228.8400","-9.8492","9.29239","0.03550"
"229.2400","-9.8427","9.36012","0.03553"
"229.6400","-9.8360","9.42138","0.03556"
"230.0400","-9.8292","9.36339","0.03553"
"230.4400","-9.8228","9.39646","0.03556"
"230.8400","-9.8159","9.44400","0.03559"
"231.2400","-9.8094","9.46919","0.03561"
"231.6400","-9.8027","9.37991","0.03581"
"232.0400","-9.7961","9.43731","0.03585"
"232.4400","-9.7895","9.48572","0.03590"
"232.8400","-9.7827","9.51688","0.03595"
"233.2400","-9.7760","9.48662","0.03606"
"233.6400","-9.7694","9.48601","0.03616"
"234.0400","-9.7626","9.51996","0.03623"
"234.4400","-9.7562","9.54597","0.03629"
"234.8400","-9.7492","9.52862","0.03633"
"235.2400","-9.7429","9.52978","0.03635"
"235.6400","-9.7359","9.52799","0.03636"
"236.0400","-9.7294","9.52628","0.03637"
"236.4400","-9.7226","9.53503","0.03639"
"236.6410","-9.7192","9.27014","0.03627"
"237.0410","-9.7128","9.33414","0.03630"
"237.4410","-9.7060","9.40839","0.03634"
"237.8410","-9.6996","9.47543","0.03637"
"238.2410","-9.6925","9.54466","0.03641"
"238.6410","-9.6862","9.57402","0.03643"
"239.0410","-9.6792","9.59490","0.03644"
"239.3240","-9.6746","9.44529","0.03638"
"239.5570","-9.6706","9.31977","0.03632"
"239.9570","-9.6641","9.39117","0.03636"
"240.3570","-9.6576","9.46394","0.03639"
"240.7570","-9.6506","9.53754","0.03643"
"241.1570","-9.6442","9.59574","0.03645"
"241.4090","-9.6398","9.45390","0.03639"
"241.7330","-9.6344","9.41147","0.03637"
"242.1330","-9.6279","9.48350","0.03640"
"242.5330","-9.6213","9.55446","0.03644"
"242.9330","-9.6145","9.61989","0.03647"
"243.3140","-9.6081","9.57221","0.03645"
"243.6340","-9.6028","9.48306","0.03641"
"244.0340","-9.5961","9.55572","0.03645"
"244.4340","-9.5895","9.62222","0.03648"
"244.8340","-9.5826","9.66656","0.03651"
"245.2340","-9.5761","9.59077","0.03648"
"245.6340","-9.5693","9.51890","0.03644"
"246.0340","-9.5628","9.57907","0.03647"
"246.4340","-9.5560","9.63734","0.03650"
"246.8250","-9.5495","9.54095","0.03659"
"247.2250","-9.5430","9.58402","0.03664"
"247.6250","-9.5363","9.63025","0.03670"
"247.8810","-9.5321","9.46645","0.03700"
"248.2000","-9.5265","9.40080","0.03721"
"248.6000","-9.5199","9.47165","0.03725"
"249.0000","-9.5132","9.54266","0.03730"
"249.4000","-9.5066","9.60780","0.03734"
"249.8000","-9.5000","9.66056","0.03740"
"250.0860","-9.4953","9.51277","0.03771"
"250.4000","-9.4901","9.41571","0.03794"
"250.8000","-9.4833","9.49137","0.03798"
"251.2000","-9.4767","9.56209","0.03802"
"251.6000","-9.4699","9.63272","0.03806"
"252.0000","-9.4634","9.68392","0.03811"
"252.2390","-9.4594","9.45480","0.03820"
"252.6390","-9.4528","9.47233","0.03825"
"253.0390","-9.4461","9.54111","0.03829"
"253.4390","-9.4393","9.60953","0.03834"
"253.8390","-9.4328","9.66606","0.03838"
"254.1870","-9.4268","9.60374","0.03854"
"254.3310","-9.4243","9.36938","0.03890"
"254.7310","-9.4179","9.43361","0.03895"
"255.1310","-9.4111","9.50864","0.03899"
"255.5310","-9.4048","9.57543","0.03902"
"255.9310","-9.3978","9.64594","0.03907"
"256.3100","-9.3916","9.60475","0.03915"
"256.5340","-9.3876","9.41408","0.03922"
"256.9340","-9.3811","9.48518","0.03925"
"257.3340","-9.3746","9.55684","0.03929"
"257.7340","-9.3678","9.62976","0.03933"
"258.1340","-9.3613","9.69312","0.03937"
"258.4890","-9.3550","9.64887","0.03951"
"258.6200","-9.3528","9.36722","0.03983"
"259.0200","-9.3463","9.43490","0.03987"
"259.4200","-9.3398","9.50747","0.03991"
"259.8200","-9.3330","9.58138","0.03996"
"260.2200","-9.3264","9.64757","0.04000"
"260.6200","-9.3198","9.70140","0.04006"
"260.8080","-9.3166","9.46657","0.04035"
"261.2080","-9.3097","9.46353","0.04048"
"261.6080","-9.3033","9.53498","0.04052"
"262.0080","-9.2965","9.60796","0.04057"
"262.4080","-9.2899","9.67472","0.04061"
"262.7780","-9.2838","9.63116","0.04076"
"263.0020","-9.2800","9.43505","0.04103"
"263.4020","-9.2733","9.50809","0.04108"
"263.8020","-9.2665","9.58222","0.04112"
"264.2020","-9.2600","9.64998","0.04117"
"264.6020","-9.2532","9.70865","0.04123"
"264.7490","-9.2509","9.42606","0.04155"
"265.1490","-9.2439","9.48846","0.04163"
"265.5490","-9.2377","9.55601","0.04167"
"265.9490","-9.2307","9.63223","0.04173"
"266.3490","-9.2242","9.69193","0.04178"
"266.5690","-9.2204","9.46961","0.04208"
"266.9690","-9.2139","9.47007","0.04222"
"267.3690","-9.2073","9.54295","0.04226"
"267.7690","-9.2005","9.61709","0.04232"
"268.1690","-9.1941","9.68028","0.04237"
"268.4800","-9.1885","9.55465","0.04260"
"268.7210","-9.1846","9.43372","0.04282"
"269.1210","-9.1780","9.50595","0.04287"
"269.5210","-9.1714","9.57980","0.04292"
"269.9210","-9.1647","9.65067","0.04297"
"270.3210","-9.1580","9.70856","0.04304"
"270.4880","-9.1551","9.47907","0.04334"
"270.8140","-9.1499","9.44842","0.04348"
"271.2140","-9.1430","9.52511","0.04354"
"271.6140","-9.1366","9.59554","0.04358"
"272.0140","-9.1296","9.66837","0.04364"
"272.4140","-9.1234","9.71598","0.04371"
"272.5630","-9.1205","9.44038","0.04408"
"272.9630","-9.1141","9.47947","0.04416"
"273.3630","-9.1073","9.55457","0.04421"
"273.7630","-9.1007","9.62474","0.04427"
"274.1630","-9.0940","9.69038","0.04432"
"274.5630","-9.0872","9.60361","0.04467"
"274.9630","-9.0808","9.63675","0.04478"
"275.3630","-9.0738","9.64558","0.04494"
"275.7460","-9.0678","9.51563","0.04520"
"276.1460","-9.0608","9.58468","0.04525"
"276.5460","-9.0543","9.64753","0.04531"
"276.9460","-9.0475","9.70378","0.04538"
"277.1710","-9.0437","9.47131","0.04570"
"277.5710","-9.0373","9.47840","0.04582"
"277.9710","-9.0305","9.55167","0.04586"
"278.3710","-9.0241","9.61923","0.04591"
"278.7710","-9.0170","9.68830","0.04597"
"279.1710","-9.0107","9.68718","0.04608"
"279.3140","-9.0079","9.44646","0.04638"
"279.7140","-9.0015","9.51201","0.04644"
"280.1140","-8.9947","9.58673","0.04648"
"280.5140","-8.9882","9.65498","0.04653"
"280.9140","-8.9816","9.71386","0.04659"
"281.0780","-8.9787","9.48351","0.04688"
"281.4780","-8.9719","9.49412","0.04700"
"281.8780","-8.9654","9.56526","0.04705"
"282.2780","-8.9587","9.63733","0.04710"
"282.6780","-8.9521","9.70166","0.04716"
"282.9000","-8.9482","9.51498","0.04744"
"283.2180","-8.9430","9.46306","0.04759"
"283.6180","-8.9363","9.53680","0.04764"
"284.0180","-8.9295","9.61119","0.04769"
"284.4180","-8.9231","9.67710","0.04775"
"284.7660","-8.9171","9.63301","0.04792"
"284.9890","-8.9136","9.42803","0.04824"
"285.3890","-8.9066","9.50521","0.04830"
"285.7890","-8.9004","9.57350","0.04835"
"286.1890","-8.8933","9.64914","0.04842"
"286.5890","-8.8868","9.70777","0.04852"
"286.7660","-8.8839","9.46940","0.04919"
"287.1660","-8.8772","9.46700","0.04937"
"287.5660","-8.8707","9.53856","0.04941"
"287.9660","-8.8638","9.61428","0.04945"
"288.3660","-8.8574","9.67944","0.04949"
"288.7260","-8.8511","9.63975","0.04962"
"288.9500","-8.8474","9.43823","0.04976"
"289.3500","-8.8409","9.50793","0.04977"
"289.7500","-8.8342","9.58220","0.04979"
"290.1500","-8.8276","9.65165","0.04982"
"290.5500","-8.8208","9.70807","0.04985"
"290.7620","-8.8171","9.42945","0.04973"
"291.1620","-8.8107","9.49466","0.04973"
"291.5620","-8.8039","9.57047","0.04976"
"291.9620","-8.7974","9.63875","0.04978"
"292.3620","-8.7906","9.64185","0.04977"
"292.5110","-8.7881","9.41206","0.04966"
"292.9110","-8.7814","9.48309","0.04968"
"293.3110","-8.7749","9.55469","0.04972"
"293.7110","-8.7681","9.62761","0.04975"
"294.1110","-8.7614","9.68919","0.04977"
"294.3250","-8.7580","9.46452","0.04965"
"294.7250","-8.7511","9.48592","0.04966"
"295.1250","-8.7447","9.55563","0.04969"
"295.5250","-8.7377","9.63114","0.04972"
"295.9250","-8.7315","9.69188","0.04976"
"296.3250","-8.7244","9.70730","0.04977"
"296.5380","-8.7210","9.42103","0.04963"
"296.9380","-8.7144","9.48866","0.04967"
"297.3380","-8.7077","9.56141","0.04970"
"297.7380","-8.7012","9.62986","0.04974"
"298.1380","-8.6943","9.69436","0.04977"
"298.3270","-8.6911","9.46786","0.04965"
"298.6470","-8.6860","9.42398","0.04963"
"299.0470","-8.6792","9.50008","0.04967"
"299.4470","-8.6727","9.57060","0.04971"
"299.8470","-8.6659","9.64204","0.04974"
"300.2470","-8.6594","9.69392","0.04976"
"300.4560","-8.6555","9.41641","0.04963"
"300.8560","-8.6491","9.48329","0.04966"
"301.2560","-8.6425","9.55573","0.04970"
"301.6560","-8.6357","9.62864","0.04973"
"302.0560","-8.6292","9.69207","0.04977"
"302.3900","-8.6234","9.62107","0.04973"
"302.6200","-8.6196","9.45569","0.04965"
"303.0200","-8.6129","9.52722","0.04968"
"303.4200","-8.6063","9.59839","0.04972"
"303.8200","-8.5997","9.66662","0.04975"
"304.2200","-8.5929","9.66901","0.04974"
"304.4740","-8.5888","9.45593","0.04964"
"304.8740","-8.5819","9.52731","0.04968"
"305.2740","-8.5756","9.59332","0.04971"
"305.6740","-8.5685","9.66439","0.04975"
"306.0740","-8.5624","9.68990","0.04976"
"306.2540","-8.5591","9.42934","0.04964"
"306.6540","-8.5525","9.49502","0.04967"
"307.0540","-8.5458","9.56889","0.04971"
"307.4540","-8.5391","9.63914","0.04975"
"307.8540","-8.5326","9.70306","0.04978"
"308.2540","-8.5257","9.73322","0.04979"
"308.4070","-8.5231","9.46660","0.04967"
"308.8070","-8.5167","9.53134","0.04970"
"309.2070","-8.5099","9.60600","0.04974"
"309.6070","-8.5033","9.67536","0.04978"
"310.0070","-8.4966","9.74048","0.04981"
"310.4070","-8.4899","9.70350","0.04990"
"310.8070","-8.4832","9.73752","0.04997"
"311.2070","-8.4767","9.76011","0.05002"
"311.6070","-8.4698","9.75254","0.05006"
"312.0070","-8.4634","9.72218","0.05008"
"312.3900","-8.4565","9.61677","0.05004"
"312.7900","-8.4503","9.67575","0.05008"
"313.1900","-8.4434","9.74446","0.05012"
"313.5900","-8.4369","9.79808","0.05015"
"313.8960","-8.4317","9.65052","0.05009"
"314.2110","-8.4265","9.56121","0.05006"
"314.6110","-8.4199","9.63083","0.05010"
"315.0110","-8.4131","9.70387","0.05013"
"315.4110","-8.4067","9.76801","0.05017"
"315.8110","-8.3997","9.82777","0.05020"
"316.2110","-8.3934","9.78626","0.05020"
"316.6110","-8.3863","9.72845","0.05018"
"317.0110","-8.3798","9.77006","0.05020"
"317.4110","-8.3731","9.79462","0.05022"
"317.8110","-8.3663","9.77529","0.05022"
"318.2110","-8.3599","9.77197","0.05023"
"318.6110","-8.3530","9.77942","0.05023"
"319.0110","-8.3465","9.77275","0.05023"
"319.4110","-8.3397","9.69636","0.05020"
"319.8110","-8.3331","9.71907","0.05021"
"320.2110","-8.3266","9.77001","0.05024"
"320.6110","-8.3198","9.81876","0.05026"
"320.8350","-8.3159","9.58910","0.05016"
"321.2350","-8.3095","9.57259","0.05016"
"321.6350","-8.3027","9.64546","0.05019"
"322.0350","-8.2960","9.71675","0.05022"
"322.4350","-8.2893","9.78431","0.05026"
"322.8350","-8.2827","9.82542","0.05028"
"322.9990","-8.2801","9.52790","0.05014"
"323.3990","-8.2733","9.59718","0.05018"
"323.7990","-8.2668","9.66741","0.05021"
"324.1990","-8.2600","9.74037","0.05025"
"324.5990","-8.2533","9.80593","0.05028"
"324.9610","-8.2474","9.76046","0.05026"
"325.1850","-8.2434","9.55755","0.05017"
"325.5850","-8.2372","9.62377","0.05020"
"325.9850","-8.2301","9.70142","0.05024"
"326.3850","-8.2239","9.76531","0.05027"
"326.7850","-8.2167","9.83402","0.05030"
"327.0490","-8.2125","9.68233","0.05024"
"327.3630","-8.2072","9.58861","0.05020"
"327.7630","-8.2007","9.65842","0.05023"
"328.1630","-8.1941","9.73008","0.05026"
"328.5630","-8.1873","9.79935","0.05030"
"328.9630","-8.1808","9.85103","0.05032"
"329.1000","-8.1783","9.58681","0.05020"
"329.5000","-8.1717","9.59800","0.05021"
"329.9000","-8.1650","9.67107","0.05024"
"330.3000","-8.1585","9.74054","0.05028"
"330.7000","-8.1516","9.80941","0.05031"
"331.0890","-8.1453","9.77001","0.05030"
"331.2500","-8.1423","9.56108","0.05020"
"331.6500","-8.1360","9.62594","0.05023"
"332.0500","-8.1290","9.70229","0.05026"
"332.4500","-8.1226","9.77008","0.05030"
"332.8500","-8.1158","9.83424","0.05033"
"333.1350","-8.1114","9.68853","0.05026"
"333.4480","-8.1057","9.59292","0.05021"
"333.8480","-8.0993","9.66209","0.05024"
"334.2480","-8.0925","9.73605","0.05028"
"334.6480","-8.0857","9.80453","0.05031"
"335.0480","-8.0793","9.85477","0.05034"
"335.2940","-8.0750","9.65694","0.05036"
"335.6220","-8.0698","9.60867","0.05040"
"336.0220","-8.0627","9.68385","0.05044"
"336.4220","-8.0565","9.74991","0.05046"
"336.8220","-8.0495","9.82003","0.05049"
"337.2220","-8.0429","9.82646","0.05050"
"337.3880","-8.0401","9.58374","0.05050"
"337.7880","-8.0335","9.64879","0.05054"
"338.1880","-8.0270","9.71738","0.05058"
"338.5880","-8.0201","9.78921","0.05061"
"338.9880","-8.0137","9.84510","0.05064"
"339.3880","-8.0066","9.77111","0.05064"
"339.7880","-8.0003","9.79879","0.05065"
"340.1880","-7.9934","9.84535","0.05068"
"340.4220","-7.9896","9.64908","0.05058"
"340.7500","-7.9842","9.60806","0.05057"
"341.1500","-7.9775","9.68076","0.05060"
"341.5500","-7.9710","9.74961","0.05064"
"341.9500","-7.9641","9.82082","0.05067"
"342.3500","-7.9576","9.84522","0.05075"
"342.5290","-7.9544","9.54575","0.05062"
"342.9290","-7.9478","9.60949","0.05065"
"343.3290","-7.9414","9.67840","0.05069"
"343.7290","-7.9346","9.75056","0.05072"
"344.1290","-7.9280","9.81441","0.05075"
"344.5290","-7.9211","9.81794","0.05076"
"344.7000","-7.9181","9.58620","0.05066"
"345.1000","-7.9117","9.64774","0.05069"
"345.5000","-7.9049","9.72116","0.05072"
"345.9000","-7.8985","9.78756","0.05075"
"346.3000","-7.8917","9.85068","0.05079"
"346.6160","-7.8867","9.73909","0.05075"
"346.8580","-7.8822","9.60944","0.05070"
"347.2580","-7.8757","9.67709","0.05072"
"347.6580","-7.8689","9.75037","0.05076"
"348.0580","-7.8624","9.81827","0.05079"
"348.4580","-7.8558","9.88024","0.05082"
"348.8510","-7.8491","9.76720","0.05098"
"349.2510","-7.8426","9.78681","0.05102"
"349.6400","-7.8359","9.72307","0.05118"
"349.9630","-7.8307","9.60263","0.05139"
"350.3630","-7.8238","9.67565","0.05142"
"350.7630","-7.8173","9.74354","0.05146"
"351.1630","-7.8106","9.81093","0.05149"
"351.5630","-7.8039","9.86197","0.05154"
"351.7200","-7.8014","9.56135","0.05199"
"352.1200","-7.7945","9.62658","0.05204"
"352.5200","-7.7882","9.69437","0.05208"
"352.9200","-7.7811","9.77110","0.05213"
"353.3200","-7.7749","9.83132","0.05217"
"353.6730","-7.7686","9.79095","0.05235"
"353.8970","-7.7651","9.58905","0.05268"
"354.2970","-7.7585","9.65954","0.05272"
"354.6970","-7.7517","9.73316","0.05276"
"355.0970","-7.7452","9.80204","0.05280"
"355.4970","-7.7383","9.86791","0.05286"
"355.7910","-7.7334","9.72533","0.05314"
"356.1050","-7.7283","9.62373","0.05337"
"356.5050","-7.7217","9.69475","0.05340"
"356.9050","-7.7150","9.76593","0.05344"
"357.3050","-7.7083","9.83361","0.05349"
"357.7050","-7.7016","9.88679","0.05356"
"357.9240","-7.6977","9.60566","0.05399"
"358.3240","-7.6912","9.67016","0.05403"
"358.7240","-7.6847","9.74026","0.05406"
"359.1240","-7.6779","9.81159","0.05411"
"359.5240","-7.6713","9.87175","0.05414"
"359.9240","-7.6645","9.80169","0.05433"
"360.3240","-7.6579","9.77570","0.05452"
"360.7240","-7.6513","9.67799","0.05477"
"361.1240","-7.6445","9.73723","0.05483"
"361.5240","-7.6380","9.79824","0.05489"
"361.9240","-7.6314","9.85440","0.05497"
"362.2530","-7.6257","9.77336","0.05525"
"362.4820","-7.6217","9.58730","0.05557"
"362.8820","-7.6153","9.65230","0.05561"
"363.2820","-7.6086","9.72367","0.05565"
"363.6820","-7.6020","9.79277","0.05569"
"364.0820","-7.5954","9.85379","0.05573"
"364.4140","-7.5899","9.78291","0.05588"
"364.6470","-7.5858","9.61940","0.05601"
"365.0470","-7.5791","9.68846","0.05604"
"365.4470","-7.5726","9.75723","0.05607"
"365.8470","-7.5658","9.82751","0.05611"
"366.2470","-7.5593","9.88499","0.05615"
"366.4650","-7.5553","9.66128","0.05617"
"366.8650","-7.5492","9.64357","0.05613"
"367.2650","-7.5421","9.72049","0.05615"
"367.6650","-7.5357","9.78798","0.05618"
"368.0650","-7.5289","9.85587","0.05622"
"368.4650","-7.5222","9.89237","0.05626"
"368.6450","-7.5192","9.60809","0.05613"
"369.0450","-7.5126","9.67243","0.05614"
"369.4450","-7.5062","9.74083","0.05617"
"369.8450","-7.4991","9.81534","0.05620"
"370.2450","-7.4928","9.87385","0.05622"
"370.5870","-7.4867","9.82444","0.05620"
"370.8130","-7.4831","9.61840","0.05610"
"371.2130","-7.4764","9.68758","0.05613"
"371.6130","-7.4699","9.75795","0.05616"
"372.0130","-7.4633","9.82598","0.05619"
"372.4130","-7.4564","9.88965","0.05622"
"372.7280","-7.4513","9.74961","0.05614"
"373.0450","-7.4458","9.65614","0.05609"
"373.4450","-7.4392","9.72480","0.05612"
"373.8450","-7.4326","9.79511","0.05616"
"374.2450","-7.4261","9.85908","0.05619"
"374.6450","-7.4192","9.88111","0.05618"
"374.7680","-7.4170","9.57842","0.05607"
"375.1680","-7.4104","9.59184","0.05612"
"375.5680","-7.4039","9.66007","0.05616"
"375.9680","-7.3971","9.73352","0.05620"
"376.3680","-7.3906","9.79982","0.05624"
"376.7680","-7.3839","9.84954","0.05626"
"376.9680","-7.3807","9.61475","0.05632"
"377.3680","-7.3737","9.62496","0.05643"
"377.7680","-7.3672","9.69282","0.05647"
"378.1680","-7.3605","9.76417","0.05652"
"378.5680","-7.3538","9.82865","0.05657"
"378.9680","-7.3473","9.84922","0.05664"
"379.2680","-7.3421","9.60421","0.05685"
"379.6680","-7.3357","9.65068","0.05693"
"380.0680","-7.3288","9.72075","0.05698"
"380.4680","-7.3223","9.78702","0.05702"
"380.8680","-7.3156","9.84685","0.05707"
"381.0840","-7.3119","9.61147","0.05720"
"381.4840","-7.3052","9.59117","0.05728"
"381.8840","-7.2986","9.66079","0.05732"
"382.2840","-7.2921","9.72988","0.05735"
"382.6840","-7.2852","9.79814","0.05739"
"383.0840","-7.2787","9.83225","0.05742"
"383.3720","-7.2736","9.59572","0.05743"
"383.7720","-7.2674","9.64498","0.05748"
"384.1720","-7.2604","9.71671","0.05752"
"384.5720","-7.2540","9.78052","0.05756"
"384.9720","-7.2470","9.78548","0.05758"
"385.1230","-7.2445","9.52933","0.05763"
"385.5230","-7.2380","9.58888","0.05770"
"385.9230","-7.2312","9.66269","0.05774"
"386.3230","-7.2248","9.72913","0.05778"
"386.7230","-7.2178","9.79203","0.05781"
"387.0230","-7.2130","9.56728","0.05793"
"387.4230","-7.2061","9.62757","0.05799"
"387.8230","-7.1996","9.69492","0.05803"
"388.2230","-7.1929","9.76206","0.05808"
"388.5540","-7.1874","9.69474","0.05817"
"388.7920","-7.1835","9.52594","0.05827"
"389.1920","-7.1767","9.59408","0.05832"
"389.5920","-7.1703","9.66287","0.05837"
"389.9920","-7.1633","9.73349","0.05843"
"390.3920","-7.1568","9.72102","0.05856"
"390.5840","-7.1536","9.48461","0.05861"
"390.9840","-7.1469","9.54374","0.05863"
"391.3840","-7.1404","9.61148","0.05866"
"391.7840","-7.1336","9.67892","0.05871"
"392.1840","-7.1272","9.70349","0.05882"
"392.4670","-7.1222","9.49390","0.05910"
"392.8670","-7.1154","9.55315","0.05912"
"393.2670","-7.1089","9.62018","0.05915"
"393.6670","-7.1022","9.68570","0.05919"
"393.9870","-7.0970","9.57996","0.05919"
"394.3060","-7.0915","9.46755","0.05908"
"394.7060","-7.0851","9.53261","0.05910"
"395.1060","-7.0781","9.60705","0.05913"
"395.5060","-7.0716","9.66898","0.05916"
"395.8090","-7.0665","9.49999","0.05912"
"396.2090","-7.0597","9.51897","0.05917"
"396.6090","-7.0533","9.58228","0.05920"
"397.0090","-7.0466","9.64305","0.05924"
"397.3310","-7.0413","9.48352","0.05921"
"397.7310","-7.0345","9.47725","0.05924"
"398.1310","-7.0279","9.54293","0.05928"
"398.5310","-7.0211","9.61171","0.05933"
"398.8620","-7.0156","9.45294","0.05930"
"399.2620","-7.0090","9.47836","0.05932"
"399.6620","-7.0023","9.54193","0.05937"
"400.0620","-6.9956","9.59697","0.05942"
"400.4280","-6.9894","9.44504","0.05955"
"400.8280","-6.9828","9.49661","0.05960"
"401.2280","-6.9763","9.54650","0.05965"
"401.6280","-6.9694","9.43850","0.05968"
"402.0280","-6.9630","9.47467","0.05972"
"402.4280","-6.9563","9.52595","0.05978"
"402.8280","-6.9495","9.42507","0.05993"
"403.2280","-6.9430","9.45424","0.05999"
"403.6280","-6.9361","9.47341","0.06005"
"404.0280","-6.9297","9.43743","0.06009"
"404.4280","-6.9228","9.45862","0.06013"
"404.8280","-6.9164","9.42131","0.06020"
"405.2280","-6.9094","9.44599","0.06026"
"405.6280","-6.9029","9.40038","0.06029"
"406.0280","-6.8961","9.39968","0.06032"
"406.4280","-6.8895","9.43062","0.06035"
"406.8280","-6.8827","9.36635","0.06034"
"407.2280","-6.8762","9.31396","0.06032"
"407.6280","-6.8694","9.37953","0.06037"
"408.0280","-6.8629","9.43538","0.06042"
"408.4280","-6.8561","9.33674","0.06050"
"408.8280","-6.8495","9.33269","0.06055"
"409.2280","-6.8429","9.36998","0.06060"
"409.6280","-6.8362","9.29007","0.06067"
"410.0280","-6.8297","9.29792","0.06071"
"410.4280","-6.8228","9.30799","0.06074"
"410.8280","-6.8163","9.29393","0.06077"
"411.2280","-6.8095","9.25078","0.06079"
"411.6280","-6.8030","9.24301","0.06080"
"412.0280","-6.7962","9.29709","0.06084"
"412.4280","-6.7897","9.21309","0.06087"
"412.8280","-6.7828","9.24965","0.06090"
"413.2280","-6.7763","9.16691","0.06092"
"413.6280","-6.7693","9.21543","0.06095"
"414.0000","-6.7633","9.15982","0.06095"
"414.4000","-6.7566","9.16674","0.06099"
"414.8000","-6.7500","9.15524","0.06100"
"415.2000","-6.7433","9.11843","0.06103"
"415.6000","-6.7366","9.07818","0.06105"
"416.0000","-6.7301","9.12881","0.06108"
"416.3700","-6.7237","8.98835","0.06105"
"416.7700","-6.7173","9.01724","0.06107"
"417.1700","-6.7105","9.03779","0.06109"
"417.2840","-6.7085","8.68891","0.06108"
"417.2880","-6.7085","8.20050","0.06135"
"417.2920","-6.7083","7.41773","0.06169"
"417.2960","-6.7080","6.47665","0.06208"
"417.2990","-6.7077","5.72604","0.06241"