File: Coupon Test Data/test__20250509_94834_6.csv
Time,Displacement,Force,Strain 1
(s),(mm),(kN),(mm/mm)
"0.0000","-21.6483","0.37579","-0.00126"
"0.5000","-21.6414","0.46593","-0.00122"
"1.0000","-21.6330","0.58140","-0.00117"
"1.5000","-21.6247","0.69379","-0.00112"
"2.0000","-21.6163","0.80821","-0.00108"
"2.5000","-21.6080","0.91825","-0.00103"
"3.0000","-21.5997","1.02848","-0.00098"
"3.5000","-21.5912","1.13916","-0.00093"
"4.0000","-21.5830","1.24205","-0.00089"
"4.5000","-21.5746","1.34447","-0.00085"
"5.0000","-21.5664","1.44767","-0.00080"
"5.5000","-21.5580","1.54690","-0.00076"
"6.0000","-21.5495","1.65214","-0.00072"
"6.5000","-21.5413","1.74847","-0.00068"
"7.0000","-21.5330","1.84018","-0.00064"
"7.5000","-21.5247","1.94223","-0.00060"
"8.0000","-21.5162","2.04480","-0.00055"
"8.5000","-21.5079","2.13919","-0.00051"
"9.0000","-21.4997","2.23353","-0.00047"
"9.5000","-21.4913","2.33514","-0.00043"
"10.0000","-21.4829","2.43443","-0.00039"
"10.5000","-21.4747","2.52316","-0.00035"
"11.0000","-21.4664","2.62059","-0.00031"
"11.5000","-21.4579","2.72026","-0.00027"
"12.0000","-21.4494","2.81239","-0.00023"
"12.5000","-21.4414","2.90453","-0.00019"
"13.0000","-21.4331","3.00017","-0.00015"
"13.5000","-21.4246","3.09098","-0.00011"
"14.0000","-21.4162","3.18593","-0.00008"
"14.5000","-21.4079","3.28086","-0.00004"
"15.0000","-21.3997","3.36479","0.00000"
"15.5000","-21.3913","3.45918","0.00004"
"16.0000","-21.3830","3.55266","0.00008"
"16.5000","-21.3746","3.63935","0.00012"
"17.0000","-21.3662","3.73171","0.00015"
"17.5000","-21.3580","3.81564","0.00019"
"18.0000","-21.3496","3.90659","0.00023"
"18.5000","-21.3414","3.99557","0.00026"
"19.0000","-21.3328","4.08323","0.00030"
"19.5000","-21.3244","4.17383","0.00034"
"20.0000","-21.3163","4.25487","0.00037"
"20.5000","-21.3080","4.34312","0.00041"
"21.0000","-21.2997","4.42636","0.00044"
"21.5000","-21.2911","4.51609","0.00048"
"22.0000","-21.2829","4.59956","0.00052"
"22.5000","-21.2748","4.68060","0.00055"
"23.0000","-21.2663","4.76640","0.00059"
"23.5000","-21.2580","4.84866","0.00062"
"24.0000","-21.2496","4.93086","0.00066"
"24.5000","-21.2413","5.00898","0.00069"
"25.0000","-21.2329","5.08924","0.00073"
"25.5000","-21.2244","5.16716","0.00077"
"26.0000","-21.2165","5.23923","0.00081"
"26.5000","-21.2080","5.31139","0.00085"
"27.0000","-21.1995","5.38386","0.00089"
"27.5000","-21.1912","5.44943","0.00093"
"28.0000","-21.1829","5.51409","0.00098"
"28.5000","-21.1748","5.57118","0.00102"
"29.0000","-21.1662","5.62682","0.00108"
"29.5000","-21.1579","5.68254","0.00113"
"30.0000","-21.1496","5.73222","0.00118"
"30.5000","-21.1412","5.77895","0.00124"
"31.0000","-21.1331","5.81626","0.00130"
"31.5000","-21.1245","5.86093","0.00136"
"32.0000","-21.1163","5.89803","0.00142"
"32.5000","-21.1079","5.93414","0.00149"
"33.0000","-21.0995","5.96898","0.00156"
"33.5000","-21.0914","5.99715","0.00163"
"34.0000","-21.0829","6.02562","0.00170"
"34.5000","-21.0746","6.05233","0.00176"
"35.0000","-21.0661","6.07976","0.00184"
"35.5000","-21.0578","6.10461","0.00191"
"36.0000","-21.0498","6.12256","0.00199"
"36.5000","-21.0412","6.14610","0.00207"
"37.0000","-21.0329","6.16790","0.00215"
"37.5000","-21.0246","6.18595","0.00223"
"38.0000","-21.0163","6.20374","0.00231"
"38.5000","-21.0080","6.22009","0.00239"
"39.0000","-20.9994","6.23956","0.00247"
"39.5000","-20.9913","6.25243","0.00255"
"40.0000","-20.9830","6.26655","0.00264"
"40.5000","-20.9746","6.28242","0.00272"
"41.0000","-20.9662","6.29593","0.00281"
"41.5000","-20.9578","6.30458","0.00289"
"42.0000","-20.9497","6.31967","0.00296"
"42.5000","-20.9412","6.33316","0.00305"
"43.0000","-20.9329","6.34645","0.00314"
"43.5000","-20.9246","6.35592","0.00322"
"44.0000","-20.9162","6.36684","0.00331"
"44.5000","-20.9080","6.37534","0.00340"
"45.0000","-20.8996","6.38739","0.00349"
"45.5000","-20.8913","6.39684","0.00358"
"46.0000","-20.8829","6.40668","0.00367"
"46.5000","-20.8745","6.41938","0.00376"
"47.0000","-20.8663","6.42463","0.00384"
"47.5000","-20.8579","6.43431","0.00394"
"48.0000","-20.8497","6.44362","0.00402"
"48.5000","-20.8412","6.45400","0.00411"
"49.0000","-20.8328","6.46443","0.00420"
"49.5000","-20.8247","6.46716","0.00429"
"50.0000","-20.8162","6.47754","0.00438"
"50.5000","-20.8079","6.48782","0.00447"
"51.0000","-20.7996","6.49439","0.00456"
"51.5000","-20.7913","6.50271","0.00464"
"52.0000","-20.7829","6.50927","0.00474"
"52.5000","-20.7744","6.51966","0.00483"
"53.0000","-20.7664","6.52427","0.00491"
"53.5000","-20.7580","6.53136","0.00500"
"54.0000","-20.7496","6.54103","0.00509"
"54.5000","-20.7412","6.54755","0.00518"
"55.0000","-20.7328","6.55651","0.00527"
"55.5000","-20.7248","6.55929","0.00536"
"56.0000","-20.7163","6.56729","0.00545"
"56.5000","-20.7079","6.57752","0.00554"
"57.0000","-20.6995","6.58281","0.00563"
"57.5000","-20.6912","6.58923","0.00572"
"58.0000","-20.6830","6.59390","0.00582"
"58.5000","-20.6746","6.60242","0.00591"
"59.0000","-20.6664","6.60849","0.00600"
"59.5000","-20.6579","6.61560","0.00608"
"60.0000","-20.6495","6.62385","0.00617"
"60.5000","-20.6414","6.62684","0.00626"
"61.0000","-20.6330","6.63402","0.00635"
"61.5000","-20.6247","6.64040","0.00644"
"62.0000","-20.6161","6.64838","0.00652"
"62.5000","-20.6078","6.65556","0.00661"
"63.0000","-20.5998","6.65638","0.00669"
"63.5000","-20.5912","6.66533","0.00678"
"64.0000","-20.5829","6.67328","0.00686"
"64.5000","-20.5745","6.67798","0.00694"
"65.0000","-20.5663","6.68347","0.00702"
"65.5000","-20.5579","6.68045","0.00710"
"66.0000","-20.5494","6.69511","0.00717"
"66.5000","-20.5415","6.70589","0.00725"
"67.0000","-20.5330","6.71157","0.00734"
"67.5000","-20.5245","6.71594","0.00743"
"68.0000","-20.5162","6.71954","0.00753"
"68.5000","-20.5078","6.72591","0.00762"
"69.0000","-20.4998","6.72626","0.00772"
"69.5000","-20.4912","6.73235","0.00782"
"70.0000","-20.4828","6.73897","0.00792"
"70.5000","-20.4745","6.74216","0.00802"
"71.0000","-20.4662","6.74719","0.00812"
"71.5000","-20.4581","6.75046","0.00821"
"72.0000","-20.4495","6.75767","0.00831"
"72.5000","-20.4413","6.76219","0.00840"
"73.0000","-20.4329","6.76048","0.00849"
"73.4920","-20.4246","6.68863","0.00848"
"73.9920","-20.4166","6.75773","0.00854"
"74.4920","-20.4080","6.80319","0.00861"
"74.9920","-20.3998","6.80873","0.00867"
"75.4920","-20.3912","6.67430","0.00866"
"75.9920","-20.3830","6.74943","0.00870"
"76.4920","-20.3749","6.75635","0.00874"
"76.9270","-20.3673","6.72930","0.00874"
"77.4270","-20.3592","6.80279","0.00879"
"77.8890","-20.3514","6.71345","0.00876"
"78.3890","-20.3432","6.79802","0.00882"
"78.8890","-20.3347","6.84132","0.00886"
"79.3890","-20.3263","6.82043","0.00887"
"79.8890","-20.3182","6.86883","0.00893"
"80.2370","-20.3121","6.71344","0.00888"
"80.7370","-20.3041","6.79556","0.00893"
"81.2340","-20.2957","6.71590","0.00890"
"81.7340","-20.2875","6.80343","0.00895"
"82.2060","-20.2794","6.71058","0.00892"
"82.7060","-20.2711","6.80073","0.00897"
"83.1460","-20.2637","6.70044","0.00894"
"83.6460","-20.2554","6.79223","0.00899"
"84.1130","-20.2478","6.69126","0.00897"
"84.6130","-20.2394","6.78447","0.00902"
"85.0410","-20.2323","6.73199","0.00919"
"85.5410","-20.2239","6.78045","0.00929"
"86.0200","-20.2160","6.76656","0.00945"
"86.5200","-20.2076","6.77748","0.00960"
"87.0010","-20.1994","6.76993","0.00977"
"87.5010","-20.1913","6.77868","0.00992"
"87.9990","-20.1829","6.77029","0.01009"
"88.4990","-20.1747","6.78592","0.01024"
"88.9730","-20.1667","6.77399","0.01041"
"89.4730","-20.1583","6.79185","0.01056"
"89.9660","-20.1502","6.78167","0.01074"
"90.4660","-20.1417","6.80340","0.01089"
"90.9590","-20.1336","6.79020","0.01106"
"91.4590","-20.1254","6.80230","0.01122"
"91.9590","-20.1171","6.82246","0.01137"
"92.3860","-20.1097","6.79518","0.01155"
"92.8860","-20.1014","6.88015","0.01163"
"93.3610","-20.0937","6.78973","0.01189"
"93.8610","-20.0852","6.88031","0.01196"
"94.2870","-20.0783","6.78133","0.01221"
"94.7870","-20.0698","6.87306","0.01229"
"95.1670","-20.0635","6.75819","0.01254"
"95.6670","-20.0550","6.85450","0.01261"
"96.0970","-20.0480","6.75829","0.01286"
"96.5970","-20.0397","6.85387","0.01293"
"97.0620","-20.0317","6.76924","0.01318"
"97.5620","-20.0236","6.86121","0.01325"
"98.0620","-20.0152","6.85415","0.01352"
"98.4970","-20.0081","6.84065","0.01363"
"98.9970","-19.9997","6.93319","0.01368"
"99.4970","-19.9914","6.94708","0.01369"
"99.9970","-19.9829","6.96603","0.01370"
"100.4970","-19.9745","7.00767","0.01372"
"100.9140","-19.9676","6.84040","0.01360"
"101.4140","-19.9593","6.93438","0.01365"
"101.9140","-19.9512","7.00436","0.01368"
"102.4140","-19.9426","6.99593","0.01369"
"102.9140","-19.9344","7.07403","0.01373"
"103.3630","-19.9268","6.94728","0.01368"
"103.8630","-19.9184","7.03081","0.01372"
"104.2890","-19.9114","6.92320","0.01367"
"104.7890","-19.9031","7.01750","0.01372"
"105.2890","-19.8948","7.09976","0.01376"
"105.6370","-19.8888","6.95662","0.01373"
"106.1370","-19.8808","7.04430","0.01377"
"106.6370","-19.8724","7.09245","0.01379"
"107.0610","-19.8653","7.00573","0.01376"
"107.5610","-19.8569","7.10121","0.01380"
"108.0470","-19.8487","7.07761","0.01380"
"108.3830","-19.8431","6.97146","0.01376"
"108.8830","-19.8350","7.06629","0.01380"
"109.3830","-19.8266","7.14467","0.01384"
"109.7290","-19.8207","6.98867","0.01377"
"110.2290","-19.8126","7.08135","0.01382"
"110.6380","-19.8054","6.97615","0.01377"
"111.1380","-19.7974","7.04891","0.01381"
"111.6380","-19.7890","7.14253","0.01385"
"112.1380","-19.7807","7.15677","0.01387"
"112.6060","-19.7727","7.06907","0.01383"
"113.1060","-19.7644","7.15406","0.01387"
"113.5560","-19.7570","7.12590","0.01387"
"113.8850","-19.7515","6.99873","0.01383"
"114.3850","-19.7432","7.09443","0.01387"
"114.8140","-19.7359","6.97684","0.01384"
"115.3140","-19.7277","7.07141","0.01389"
"115.8140","-19.7192","7.16242","0.01393"
"116.2280","-19.7126","6.99045","0.01390"
"116.7280","-19.7041","7.09238","0.01395"
"117.2280","-19.6959","7.16844","0.01403"
"117.5620","-19.6903","6.99576","0.01436"
"118.0620","-19.6818","7.09760","0.01442"
"118.5620","-19.6735","7.18107","0.01448"
"118.8550","-19.6687","6.98761","0.01478"
"119.3550","-19.6603","7.08752","0.01484"
"119.8550","-19.6520","7.17745","0.01490"
"120.2660","-19.6451","7.00468","0.01523"
"120.7660","-19.6367","7.10507","0.01529"
"121.2660","-19.6286","7.17228","0.01536"
"121.6010","-19.6229","7.01142","0.01566"
"122.1010","-19.6147","7.10836","0.01572"
"122.5950","-19.6063","7.10182","0.01588"
"123.0100","-19.5996","7.03232","0.01611"
"123.5100","-19.5911","7.13269","0.01617"
"123.9340","-19.5841","7.10421","0.01632"
"124.3510","-19.5772","7.04390","0.01653"
"124.8510","-19.5687","7.14305","0.01659"
"125.3510","-19.5603","7.14266","0.01666"
"125.7200","-19.5542","7.02146","0.01691"
"126.2200","-19.5459","7.07688","0.01702"
"126.7200","-19.5374","7.17172","0.01708"
"127.0960","-19.5314","7.00374","0.01738"
"127.5960","-19.5229","7.10298","0.01744"
"128.0960","-19.5146","7.19570","0.01751"
"128.5040","-19.5079","7.02060","0.01784"
"129.0040","-19.4997","7.11808","0.01790"
"129.5040","-19.4911","7.20736","0.01797"
"129.8860","-19.4849","7.04116","0.01829"
"130.3860","-19.4764","7.14296","0.01835"
"130.8740","-19.4682","7.13320","0.01853"
"131.2890","-19.4615","7.05663","0.01876"
"131.7890","-19.4530","7.15638","0.01882"
"132.1950","-19.4465","7.04909","0.01907"
"132.6950","-19.4379","7.10816","0.01919"
"133.1950","-19.4297","7.20175","0.01925"
"133.5920","-19.4230","7.04405","0.01957"
"134.0920","-19.4147","7.13947","0.01963"
"134.5920","-19.4064","7.23132","0.01971"
"134.9430","-19.4005","7.08038","0.02009"
"135.4430","-19.3920","7.17862","0.02015"
"135.9430","-19.3839","7.26809","0.02019"
"136.4430","-19.3757","7.28086","0.02020"
"136.9270","-19.3673","7.22020","0.02017"
"137.4270","-19.3593","7.29969","0.02022"
"137.9270","-19.3508","7.31823","0.02023"
"138.4270","-19.3424","7.36812","0.02027"
"138.7220","-19.3375","7.13981","0.02017"
"139.2220","-19.3293","7.22647","0.02021"
"139.7220","-19.3209","7.32239","0.02026"
"140.2220","-19.3123","7.39994","0.02030"
"140.4990","-19.3078","7.12768","0.02017"
"140.9990","-19.2994","7.22627","0.02021"
"141.4990","-19.2914","7.31733","0.02025"
"141.9990","-19.2830","7.39153","0.02029"
"142.4420","-19.2757","7.29968","0.02028"
"142.9420","-19.2671","7.39345","0.02033"
"143.4420","-19.2589","7.39652","0.02034"
"143.8890","-19.2514","7.36446","0.02034"
"144.2140","-19.2460","7.21335","0.02029"
"144.7140","-19.2377","7.30895","0.02033"
"145.2140","-19.2293","7.38734","0.02037"
"145.5340","-19.2238","7.16182","0.02028"
"146.0340","-19.2157","7.25279","0.02032"
"146.5340","-19.2074","7.34835","0.02037"
"147.0340","-19.1989","7.43541","0.02041"
"147.5340","-19.1909","7.45813","0.02043"
"148.0160","-19.1827","7.36900","0.02040"
"148.5160","-19.1743","7.45798","0.02044"
"149.0160","-19.1660","7.45293","0.02045"
"149.5160","-19.1576","7.47486","0.02047"
"149.7770","-19.1532","7.25439","0.02040"
"150.2050","-19.1462","7.25155","0.02041"
"150.7050","-19.1379","7.34704","0.02045"
"151.2050","-19.1294","7.43615","0.02049"
"151.5730","-19.1234","7.31015","0.02053"
"151.9940","-19.1163","7.29239","0.02057"
"152.4940","-19.1082","7.38582","0.02062"
"152.9940","-19.0997","7.46830","0.02071"
"153.3040","-19.0946","7.24958","0.02110"
"153.8040","-19.0861","7.34977","0.02116"
"154.3040","-19.0779","7.44135","0.02121"
"154.6530","-19.0721","7.32814","0.02144"
"155.0700","-19.0652","7.29246","0.02162"
"155.5700","-19.0568","7.39221","0.02168"
"156.0700","-19.0485","7.47809","0.02174"
"156.3430","-19.0436","7.23853","0.02209"
"156.8430","-19.0357","7.33058","0.02216"
"157.3430","-19.0273","7.42744","0.02221"
"157.7860","-19.0198","7.41224","0.02236"
"158.1150","-19.0144","7.27821","0.02263"
"158.6150","-19.0059","7.37876","0.02269"
"159.1150","-18.9976","7.46893","0.02275"
"159.3870","-18.9931","7.25422","0.02307"
"159.8870","-18.9848","7.32886","0.02316"
"160.3870","-18.9764","7.42591","0.02322"
"160.8300","-18.9691","7.40077","0.02339"
"161.1640","-18.9634","7.28562","0.02364"
"161.6640","-18.9552","7.38165","0.02370"
"162.1640","-18.9468","7.46425","0.02378"
"162.5740","-18.9401","7.30752","0.02409"
"163.0740","-18.9316","7.40639","0.02416"
"163.5740","-18.9234","7.48518","0.02423"
"163.9200","-18.9174","7.32384","0.02454"
"164.4200","-18.9094","7.41372","0.02460"
"164.9040","-18.9013","7.39561","0.02477"
"165.3380","-18.8939","7.38106","0.02495"
"165.8380","-18.8855","7.47308","0.02502"
"166.2270","-18.8791","7.29013","0.02535"
"166.7270","-18.8708","7.38457","0.02542"
"167.2270","-18.8623","7.47830","0.02548"
"167.5660","-18.8568","7.28009","0.02580"
"168.0660","-18.8484","7.36609","0.02589"
"168.5660","-18.8402","7.45877","0.02595"
"169.0440","-18.8322","7.44051","0.02612"
"169.3840","-18.8266","7.33120","0.02636"
"169.8840","-18.8182","7.42949","0.02643"
"170.3840","-18.8100","7.51108","0.02650"
"170.7250","-18.8040","7.32635","0.02682"
"171.2250","-18.7958","7.42213","0.02688"
"171.7250","-18.7875","7.51214","0.02695"
"172.0410","-18.7821","7.30060","0.02689"
"172.4570","-18.7754","7.27149","0.02690"
"172.9570","-18.7671","7.36585","0.02695"
"173.4570","-18.7585","7.43563","0.02699"
"173.9280","-18.7506","7.34154","0.02694"
"174.4280","-18.7427","7.42812","0.02698"
"174.9280","-18.7342","7.50103","0.02702"
"175.1860","-18.7298","7.27879","0.02693"
"175.6860","-18.7214","7.37723","0.02697"
"176.1860","-18.7132","7.46575","0.02701"
"176.5920","-18.7062","7.31850","0.02695"
"177.0920","-18.6982","7.40926","0.02699"
"177.5920","-18.6898","7.50429","0.02704"
"178.0920","-18.6812","7.51520","0.02708"
"178.5400","-18.6739","7.46765","0.02709"
"179.0400","-18.6655","7.54219","0.02713"
"179.5400","-18.6574","7.56922","0.02715"
"180.0400","-18.6489","7.49860","0.02711"
"180.5400","-18.6407","7.53562","0.02714"
"181.0400","-18.6322","7.60050","0.02717"
"181.3360","-18.6272","7.33224","0.02766"
"181.8360","-18.6189","7.42859","0.02772"
"182.3360","-18.6106","7.52200","0.02779"
"182.8360","-18.6025","7.59914","0.02788"
"183.3360","-18.5939","7.60906","0.02797"
"183.8360","-18.5857","7.63507","0.02804"
"184.3360","-18.5773","7.64727","0.02809"
"184.8050","-18.5694","7.60238","0.02810"
"185.0460","-18.5655","7.39743","0.02800"
"185.5460","-18.5571","7.49430","0.02805"
"186.0460","-18.5487","7.58745","0.02809"
"186.5460","-18.5405","7.65935","0.02813"
"186.9480","-18.5337","7.53824","0.02808"
"187.4480","-18.5253","7.63097","0.02813"
"187.9480","-18.5174","7.70127","0.02817"
"188.4260","-18.5092","7.63544","0.02814"
"188.9260","-18.5007","7.62924","0.02816"
"189.3690","-18.4934","7.54207","0.02811"
"189.8690","-18.4852","7.62848","0.02815"
"190.3690","-18.4769","7.70088","0.02819"
"190.7220","-18.4708","7.50007","0.02810"
"191.2220","-18.4627","7.59059","0.02814"
"191.7220","-18.4541","7.68346","0.02818"
"192.2220","-18.4459","7.70677","0.02821"
"192.5600","-18.4402","7.55674","0.02813"
"193.0600","-18.4321","7.64787","0.02818"
"193.5600","-18.4235","7.72848","0.02822"
"193.7740","-18.4200","7.41599","0.02808"
"194.2740","-18.4115","7.51185","0.02812"
"194.7740","-18.4035","7.60413","0.02817"
"195.2740","-18.3951","7.67741","0.02820"
"195.6480","-18.3888","7.50980","0.02809"
"196.1480","-18.3803","7.60615","0.02814"
"196.6480","-18.3722","7.68730","0.02821"
"196.9990","-18.3661","7.51828","0.02836"
"197.4990","-18.3579","7.61344","0.02841"
"197.9990","-18.3499","7.70164","0.02846"
"198.4430","-18.3421","7.68831","0.02848"
"198.9430","-18.3339","7.71387","0.02849"
"199.2300","-18.3289","7.50026","0.02839"
"199.7300","-18.3209","7.56979","0.02843"
"200.2300","-18.3124","7.66434","0.02847"
"200.7300","-18.3042","7.74139","0.02851"
"201.0750","-18.2982","7.53245","0.02842"
"201.5750","-18.2900","7.62108","0.02846"
"202.0750","-18.2817","7.70919","0.02850"
"202.3590","-18.2769","7.49661","0.02843"
"202.8590","-18.2686","7.56617","0.02846"
"203.3590","-18.2604","7.65776","0.02851"
"203.7140","-18.2542","7.53765","0.02847"
"204.2140","-18.2460","7.59073","0.02849"
"204.7140","-18.2378","7.68135","0.02854"
"205.0870","-18.2313","7.57228","0.02863"
"205.5070","-18.2245","7.54475","0.02870"
"206.0070","-18.2161","7.64285","0.02876"
"206.5070","-18.2079","7.72907","0.02882"
"207.0070","-18.1994","7.63482","0.02904"
"207.5070","-18.1913","7.68815","0.02914"
"207.8650","-18.1851","7.51828","0.02944"
"208.3650","-18.1769","7.60844","0.02951"
"208.8650","-18.1684","7.69939","0.02958"
"209.2050","-18.1628","7.57376","0.02982"
"209.6350","-18.1556","7.56759","0.02997"
"210.1350","-18.1475","7.66093","0.03002"
"210.6350","-18.1391","7.74601","0.03009"
"210.9610","-18.1334","7.50381","0.03046"
"211.4610","-18.1253","7.59431","0.03052"
"211.9610","-18.1168","7.69189","0.03058"
"212.4610","-18.1086","7.76928","0.03065"
"212.7770","-18.1032","7.52358","0.03103"
"213.2770","-18.0951","7.61601","0.03109"
"213.7770","-18.0866","7.71097","0.03115"
"214.2380","-18.0790","7.68796","0.03131"
"214.5720","-18.0733","7.56642","0.03157"
"215.0720","-18.0651","7.65915","0.03163"
"215.5720","-18.0568","7.73910","0.03171"
"215.9760","-18.0499","7.57898","0.03203"
"216.4760","-18.0415","7.67437","0.03209"
"216.9760","-18.0332","7.73189","0.03219"
"217.3110","-18.0276","7.56075","0.03251"
"217.8110","-18.0192","7.65779","0.03257"
"218.3110","-18.0114","7.73723","0.03263"
"218.6440","-18.0053","7.54468","0.03297"
"219.1440","-17.9973","7.63303","0.03304"
"219.6440","-17.9889","7.72644","0.03310"
"220.0770","-17.9817","7.69333","0.03327"
"220.4150","-17.9759","7.58007","0.03353"
"220.9150","-17.9678","7.67227","0.03359"
"221.4150","-17.9593","7.75569","0.03366"
"221.6870","-17.9549","7.53421","0.03400"
"222.1870","-17.9465","7.62912","0.03407"
"222.6870","-17.9381","7.72365","0.03413"
"223.1510","-17.9303","7.69893","0.03430"
"223.4830","-17.9250","7.56730","0.03457"
"223.9830","-17.9164","7.66602","0.03463"
"224.4830","-17.9081","7.75520","0.03470"
"224.9260","-17.9008","7.64387","0.03486"
"225.4260","-17.8923","7.71559","0.03492"
"225.9260","-17.8843","7.74807","0.03497"
"226.3860","-17.8765","7.63624","0.03493"
"226.8860","-17.8682","7.72551","0.03498"
"227.3860","-17.8597","7.76665","0.03501"
"227.7250","-17.8542","7.62115","0.03495"
"228.2250","-17.8459","7.71728","0.03500"
"228.7250","-17.8374","7.80971","0.03505"
"229.0380","-17.8322","7.53342","0.03546"
"229.5380","-17.8239","7.62293","0.03552"
"230.0380","-17.8157","7.71380","0.03558"
"230.5080","-17.8077","7.68689","0.03574"
"230.9300","-17.8009","7.62307","0.03595"
"231.4300","-17.7923","7.72066","0.03601"
"231.9300","-17.7841","7.79972","0.03608"
"232.2640","-17.7785","7.59590","0.03643"
"232.7640","-17.7702","7.69123","0.03649"
"233.2640","-17.7619","7.78215","0.03655"
"233.6780","-17.7550","7.66988","0.03682"
"234.1020","-17.7478","7.65548","0.03699"
"234.6020","-17.7395","7.74991","0.03705"
"235.1020","-17.7313","7.83434","0.03712"
"235.5200","-17.7240","7.67189","0.03758"
"236.0200","-17.7161","7.75789","0.03765"
"236.5200","-17.7076","7.85085","0.03772"
"237.0200","-17.6993","7.84870","0.03774"
"237.5200","-17.6908","7.87389","0.03779"
"238.0200","-17.6824","7.91053","0.03784"
"238.4590","-17.6754","7.74204","0.03784"
"238.9590","-17.6668","7.82312","0.03790"
"239.4590","-17.6586","7.89261","0.03795"
"239.9590","-17.6503","7.81493","0.03818"
"240.4590","-17.6420","7.86716","0.03828"
"240.9590","-17.6336","7.91880","0.03837"
"241.3200","-17.6275","7.69148","0.03877"
"241.8200","-17.6193","7.77393","0.03884"
"242.3200","-17.6108","7.86466","0.03890"
"242.8200","-17.6027","7.93793","0.03897"
"243.0740","-17.5982","7.70861","0.03932"
"243.5740","-17.5902","7.77484","0.03940"
"244.0740","-17.5816","7.86976","0.03947"
"244.5740","-17.5735","7.94631","0.03953"
"244.8980","-17.5677","7.71668","0.03991"
"245.3980","-17.5598","7.80205","0.03996"
"245.8980","-17.5514","7.89295","0.04002"
"246.3980","-17.5429","7.94396","0.04013"
"246.6580","-17.5386","7.74026","0.04044"
"247.1580","-17.5303","7.83251","0.04049"
"247.6580","-17.5218","7.92342","0.04056"
"248.0700","-17.5151","7.80474","0.04082"
"248.4910","-17.5081","7.77514","0.04098"
"248.9910","-17.4996","7.87004","0.04103"
"249.4910","-17.4915","7.94962","0.04110"
"249.8100","-17.4859","7.72202","0.04145"
"250.3100","-17.4778","7.81019","0.04151"
"250.8100","-17.4694","7.90342","0.04157"
"251.3100","-17.4613","7.92767","0.04169"
"251.6400","-17.4553","7.75900","0.04199"
"252.1400","-17.4474","7.84798","0.04204"
"252.6400","-17.4390","7.93437","0.04211"
"252.9630","-17.4335","7.72602","0.04244"
"253.4630","-17.4253","7.79357","0.04252"
"253.9630","-17.4169","7.88685","0.04257"
"254.4630","-17.4085","7.95578","0.04266"
"254.7440","-17.4038","7.74126","0.04298"
"255.2440","-17.3955","7.83469","0.04304"
"255.7440","-17.3871","7.92343","0.04310"
"256.0800","-17.3815","7.71326","0.04344"
"256.5800","-17.3732","7.78944","0.04351"
"257.0800","-17.3650","7.88088","0.04356"
"257.5800","-17.3565","7.94957","0.04365"
"257.8560","-17.3519","7.73733","0.04397"
"258.3560","-17.3434","7.83323","0.04403"
"258.8560","-17.3356","7.91667","0.04409"
"259.2480","-17.3287","7.75841","0.04403"
"259.6720","-17.3218","7.71861","0.04401"
"260.1720","-17.3134","7.81158","0.04406"
"260.6720","-17.3052","7.89311","0.04410"
"261.0030","-17.2995","7.67120","0.04400"
"261.5030","-17.2912","7.76229","0.04404"
"262.0030","-17.2828","7.85717","0.04408"
"262.5030","-17.2744","7.94131","0.04413"
"262.7660","-17.2701","7.71899","0.04403"
"263.2660","-17.2618","7.79529","0.04406"
"263.7660","-17.2535","7.88797","0.04411"
"264.2660","-17.2451","7.95720","0.04414"
"264.5610","-17.2400","7.75987","0.04405"
"265.0610","-17.2317","7.85323","0.04409"
"265.5610","-17.2239","7.93609","0.04413"
"266.0550","-17.2153","7.81651","0.04408"
"266.5550","-17.2070","7.88591","0.04411"
"266.9180","-17.2009","7.72917","0.04405"
"267.4180","-17.1927","7.75990","0.04407"
"267.9180","-17.1842","7.85292","0.04411"
"268.4180","-17.1758","7.93389","0.04414"
"268.7300","-17.1707","7.69151","0.04403"
"269.2300","-17.1623","7.78158","0.04407"
"269.7300","-17.1541","7.87142","0.04412"
"270.2300","-17.1458","7.92058","0.04414"
"270.4890","-17.1413","7.71560","0.04399"
"270.9890","-17.1331","7.80671","0.04403"
"271.4890","-17.1250","7.89284","0.04408"
"271.8710","-17.1181","7.78306","0.04411"
"272.3710","-17.1102","7.79079","0.04414"
"272.8710","-17.1018","7.88557","0.04419"
"273.3710","-17.0934","7.96919","0.04424"
"273.8710","-17.0851","7.90540","0.04424"
"274.3710","-17.0766","7.95463","0.04428"
"274.8070","-17.0696","7.81328","0.04422"
"275.3070","-17.0610","7.90480","0.04427"
"275.8070","-17.0529","7.98409","0.04431"
"276.3070","-17.0445","7.90680","0.04454"
"276.8070","-17.0361","7.96136","0.04462"
"277.1780","-17.0297","7.77542","0.04498"
"277.6780","-17.0216","7.85985","0.04504"
"278.1780","-17.0134","7.94317","0.04510"
"278.6780","-17.0048","7.86429","0.04531"
"279.1780","-16.9968","7.92202","0.04539"
"279.5960","-16.9897","7.86203","0.04542"
"279.9250","-16.9842","7.72203","0.04540"
"280.4250","-16.9759","7.81546","0.04545"
"280.9250","-16.9676","7.90584","0.04551"
"281.4020","-16.9595","7.88591","0.04552"
"281.7300","-16.9541","7.73991","0.04546"
"282.2300","-16.9457","7.83639","0.04551"
"282.7300","-16.9373","7.92852","0.04555"
"283.2260","-16.9292","7.90891","0.04556"
"283.5530","-16.9237","7.75836","0.04549"
"284.0530","-16.9155","7.85048","0.04554"
"284.5530","-16.9069","7.94308","0.04558"
"284.9710","-16.9002","7.88583","0.04556"
"285.3880","-16.8929","7.82419","0.04554"
"285.8880","-16.8850","7.91016","0.04558"
"286.2810","-16.8783","7.80190","0.04554"
"286.7000","-16.8714","7.76393","0.04552"
"287.2000","-16.8630","7.85846","0.04557"
"287.7000","-16.8546","7.94456","0.04561"
"288.1150","-16.8475","7.76101","0.04553"
"288.6150","-16.8393","7.85382","0.04557"
"289.1150","-16.8312","7.94411","0.04562"
"289.6150","-16.8226","7.89528","0.04583"
"290.1150","-16.8143","7.95566","0.04592"
"290.6150","-16.8059","7.92112","0.04605"
"291.1150","-16.7978","7.95565","0.04618"
"291.6150","-16.7894","7.96554","0.04635"
"292.1150","-16.7807","7.97325","0.04650"
"292.6150","-16.7728","7.91616","0.04672"
"293.1150","-16.7644","7.90058","0.04691"
"293.6150","-16.7560","7.98136","0.04698"
"294.1150","-16.7477","8.04188","0.04707"
"294.4380","-16.7423","7.79924","0.04743"
"294.9380","-16.7338","7.88767","0.04750"
"295.4380","-16.7254","7.97808","0.04756"
"295.9380","-16.7176","8.04865","0.04763"
"296.3390","-16.7104","7.85297","0.04792"
"296.8390","-16.7023","7.93323","0.04799"
"297.3390","-16.6939","8.02002","0.04805"
"297.6990","-16.6879","7.84850","0.04800"
"298.1990","-16.6795","7.93700","0.04805"
"298.6990","-16.6713","8.02034","0.04810"
"299.1990","-16.6630","7.94772","0.04806"
"299.6990","-16.6545","8.00980","0.04810"
"300.1520","-16.6471","7.86465","0.04804"
"300.6520","-16.6388","7.95147","0.04808"
"301.1520","-16.6305","8.03703","0.04813"
"301.5310","-16.6241","7.91524","0.04808"
"301.9560","-16.6171","7.88823","0.04807"
"302.4560","-16.6086","7.98233","0.04812"
"302.9560","-16.6002","8.06857","0.04816"
"303.2890","-16.5947","7.85827","0.04807"
"303.7890","-16.5864","7.91316","0.04810"
"304.2890","-16.5782","8.00283","0.04814"
"304.7890","-16.5697","8.07791","0.04818"
"305.0860","-16.5647","7.85577","0.04808"
"305.5860","-16.5562","7.94997","0.04813"
"306.0860","-16.5484","8.03334","0.04817"
"306.5860","-16.5400","8.09654","0.04820"
"306.8790","-16.5351","7.87547","0.04810"
"307.3790","-16.5266","7.96688","0.04815"
"307.8790","-16.5183","8.05355","0.04819"
"308.2670","-16.5117","7.93518","0.04814"
"308.6920","-16.5048","7.90615","0.04813"
"309.1920","-16.4964","7.99731","0.04818"
"309.6920","-16.4880","8.07689","0.04822"
"310.0240","-16.4825","7.85151","0.04813"
"310.5240","-16.4742","7.94288","0.04817"
"311.0240","-16.4659","8.03043","0.04822"
"311.4330","-16.4590","7.91080","0.04825"
"311.9330","-16.4509","7.91595","0.04828"
"312.4330","-16.4422","8.01167","0.04834"
"312.9330","-16.4341","8.09010","0.04839"
"313.2720","-16.4283","7.87114","0.04866"
"313.7720","-16.4200","7.95787","0.04872"
"314.2720","-16.4117","8.04616","0.04877"
"314.7720","-16.4034","8.10814","0.04883"
"315.2720","-16.3951","8.02964","0.04900"
"315.7720","-16.3865","8.08159","0.04909"
"316.2720","-16.3785","8.03954","0.04924"
"316.7720","-16.3702","8.07172","0.04933"
"317.2720","-16.3617","8.05694","0.04944"
"317.7720","-16.3534","8.06178","0.04958"
"318.2720","-16.3449","8.06422","0.04974"
"318.7720","-16.3369","7.99032","0.04998"
"319.2720","-16.3284","8.01438","0.05012"
"319.7720","-16.3200","8.08809","0.05020"
"320.2410","-16.3122","8.02892","0.05041"
"320.6590","-16.3052","7.93032","0.05067"
"321.1590","-16.2970","8.01760","0.05073"
"321.6590","-16.2886","8.10108","0.05080"
"321.9870","-16.2831","7.89322","0.05115"
"322.4870","-16.2746","7.96120","0.05123"
"322.9870","-16.2666","8.04643","0.05127"
"323.4870","-16.2582","8.11842","0.05133"
"323.8240","-16.2525","7.90620","0.05152"
"324.3240","-16.2443","7.99478","0.05158"
"324.8240","-16.2360","8.08086","0.05163"
"325.1970","-16.2295","7.96136","0.05169"
"325.6970","-16.2213","7.96424","0.05175"
"326.1970","-16.2131","8.05202","0.05180"
"326.6630","-16.2050","8.03275","0.05193"
"326.8090","-16.2027","7.73366","0.05235"
"327.3090","-16.1944","7.82533","0.05241"
"327.8090","-16.1860","7.91944","0.05247"
"328.3090","-16.1778","8.00130","0.05254"
"328.7070","-16.1710","7.87230","0.05283"
"329.2070","-16.1626","7.88407","0.05299"
"329.7070","-16.1548","7.96957","0.05304"
"330.2070","-16.1462","8.05290","0.05311"
"330.4870","-16.1415","7.84168","0.05346"
"330.9870","-16.1331","7.90730","0.05355"
"331.4870","-16.1249","7.99698","0.05361"
"331.9870","-16.1165","8.07913","0.05367"
"332.2690","-16.1119","7.86167","0.05402"
"332.7690","-16.1034","7.92972","0.05410"
"333.2690","-16.0950","8.02108","0.05416"
"333.7690","-16.0868","8.09906","0.05423"
"334.0940","-16.0812","7.86674","0.05460"
"334.5940","-16.0729","7.95403","0.05466"
"335.0940","-16.0647","8.04342","0.05472"
"335.5940","-16.0565","8.10730","0.05480"
"335.9010","-16.0510","7.89120","0.05515"
"336.4010","-16.0431","7.97725","0.05521"
"336.9010","-16.0346","8.06559","0.05527"
"337.3630","-16.0269","8.03101","0.05545"
"337.7880","-16.0198","7.94932","0.05568"
"338.2880","-16.0115","8.03298","0.05575"
"338.7880","-16.0029","7.96442","0.05598"
"339.2880","-15.9946","7.95421","0.05617"
"339.7880","-15.9868","8.02879","0.05623"
"340.2880","-15.9782","8.07898","0.05634"
"340.6340","-15.9724","7.86801","0.05671"
"341.1340","-15.9641","7.95677","0.05677"
"341.6340","-15.9558","8.04426","0.05684"
"342.1340","-15.9473","8.11261","0.05692"
"342.5300","-15.9408","7.90979","0.05728"
"343.0300","-15.9324","7.99676","0.05734"
"343.5300","-15.9240","8.08094","0.05740"
"343.9190","-15.9176","7.95432","0.05764"
"344.3360","-15.9106","7.88249","0.05785"
"344.8360","-15.9025","7.97015","0.05791"
"345.3360","-15.8939","8.05753","0.05798"
"345.7240","-15.8876","7.92539","0.05824"
"346.1470","-15.8802","7.89810","0.05842"
"346.6470","-15.8723","7.98403","0.05848"
"347.1470","-15.8639","8.06392","0.05856"
"347.4470","-15.8588","7.83865","0.05892"
"347.9470","-15.8505","7.92671","0.05900"
"348.4470","-15.8422","8.01755","0.05907"
"348.9470","-15.8337","8.08753","0.05919"
"349.2240","-15.8292","7.86963","0.05960"
"349.7240","-15.8209","7.96156","0.05967"
"350.2240","-15.8124","8.05323","0.05972"
"350.7240","-15.8043","8.10306","0.05980"
"351.0380","-15.7988","7.89742","0.05994"
"351.5380","-15.7907","7.98482","0.05999"
"352.0380","-15.7822","8.06796","0.06004"
"352.3070","-15.7777","7.82262","0.06024"
"352.8070","-15.7692","7.88157","0.06032"
"353.3070","-15.7614","7.96642","0.06037"
"353.8070","-15.7529","8.05055","0.06042"
"354.0760","-15.7483","7.83339","0.06031"
"354.5760","-15.7400","7.89571","0.06036"
"355.0760","-15.7318","7.98556","0.06041"
"355.5760","-15.7233","8.06497","0.06045"
"355.9120","-15.7177","7.85343","0.06047"
"356.4120","-15.7094","7.94529","0.06052"
"356.9120","-15.7010","8.03519","0.06056"
"357.3490","-15.6937","8.00786","0.06056"
"357.6840","-15.6881","7.87951","0.06051"
"358.1840","-15.6797","7.97404","0.06055"
"358.6840","-15.6715","8.06089","0.06060"
"359.0530","-15.6652","7.94807","0.06056"
"359.4720","-15.6583","7.90749","0.06055"
"359.9720","-15.6503","7.99699","0.06059"
"360.4720","-15.6416","8.08358","0.06064"
"360.8020","-15.6361","7.85314","0.06054"
"361.3020","-15.6278","7.94144","0.06058"
"361.8020","-15.6197","8.03028","0.06063"
"362.2860","-15.6115","8.01229","0.06063"
"362.6230","-15.6060","7.88692","0.06057"
"363.1230","-15.5975","7.98147","0.06062"
"363.6230","-15.5892","8.06875","0.06066"
"363.9380","-15.5839","7.85892","0.06058"
"364.4380","-15.5756","7.93014","0.06061"
"364.9380","-15.5672","8.02190","0.06066"
"365.4380","-15.5590","8.09889","0.06070"
"365.7230","-15.5540","7.87401","0.06060"
"366.2230","-15.5458","7.96069","0.06064"
"366.7230","-15.5377","8.04735","0.06069"
"367.2230","-15.5291","8.09286","0.06072"
"367.6330","-15.5225","7.94494","0.06064"
"368.1330","-15.5141","8.03145","0.06069"
"368.6330","-15.5057","8.09223","0.06071"
"369.1330","-15.4972","8.01261","0.06066"
"369.6330","-15.4890","8.05969","0.06068"
"370.1330","-15.4809","8.00457","0.06064"
"370.6330","-15.4724","8.06552","0.06068"
"371.1330","-15.4640","8.06889","0.06068"
"371.5020","-15.4578","7.88741","0.06059"
"372.0020","-15.4497","7.97190","0.06063"
"372.5020","-15.4412","8.05978","0.06068"
"372.9650","-15.4335","8.03283","0.06066"
"373.3010","-15.4279","7.89900","0.06059"
"373.8010","-15.4194","7.99047","0.06064"
"374.3010","-15.4113","8.07477","0.06068"
"374.6920","-15.4046","7.95988","0.06062"
"375.1230","-15.3975","7.93909","0.06061"
"375.6230","-15.3891","8.02995","0.06065"
"376.1230","-15.3810","8.10828","0.06069"
"376.4550","-15.3750","7.88518","0.06058"
"376.9550","-15.3672","7.96256","0.06062"
"377.4550","-15.3588","8.05276","0.06066"
"377.9020","-15.3512","8.02448","0.06064"
"378.2430","-15.3455","7.90352","0.06058"
"378.7430","-15.3373","7.99330","0.06063"
"379.2430","-15.3287","8.08327","0.06067"
"379.6570","-15.3220","7.96647","0.06062"
"380.0810","-15.3149","7.93634","0.06060"
"380.5810","-15.3065","8.03002","0.06065"
"381.0810","-15.2983","8.11187","0.06069"
"381.4310","-15.2923","7.97664","0.06062"
"381.9310","-15.2841","7.99137","0.06063"
"382.4310","-15.2757","8.08333","0.06067"
"382.9310","-15.2676","8.15681","0.06071"
"383.3190","-15.2608","7.96173","0.06064"
"383.8190","-15.2526","7.97109","0.06065"
"384.3190","-15.2443","8.05890","0.06069"
"384.8190","-15.2359","8.12446","0.06073"
"385.1470","-15.2303","7.91911","0.06064"
"385.6470","-15.2222","8.00529","0.06068"
"386.1470","-15.2139","8.09136","0.06072"
"386.5090","-15.2076","7.96933","0.06067"
"387.0090","-15.1997","7.96199","0.06066"
"387.5090","-15.1911","8.05438","0.06071"
"388.0090","-15.1828","8.12584","0.06074"
"388.3890","-15.1764","7.93000","0.06065"
"388.8890","-15.1681","8.01916","0.06070"
"389.3890","-15.1597","8.10345","0.06074"
"389.7520","-15.1537","7.91060","0.06065"
"390.2520","-15.1454","7.99299","0.06069"
"390.7520","-15.1370","8.08175","0.06073"
"391.2230","-15.1292","8.05529","0.06072"
"391.6410","-15.1222","7.96392","0.06068"
"392.1410","-15.1141","8.04967","0.06072"
"392.6410","-15.1055","8.13022","0.06076"
"393.1110","-15.0978","7.98095","0.06069"
"393.6110","-15.0893","8.04480","0.06072"
"394.1110","-15.0809","8.12076","0.06076"
"394.4780","-15.0748","7.90240","0.06066"
"394.9780","-15.0665","7.98203","0.06070"
"395.4780","-15.0585","8.06716","0.06074"
"395.9690","-15.0501","8.04918","0.06074"
"396.3900","-15.0432","7.96676","0.06069"
"396.8900","-15.0348","8.05481","0.06074"
"397.3900","-15.0264","8.11727","0.06077"
"397.6790","-15.0217","7.86764","0.06065"
"398.1790","-15.0133","7.95580","0.06069"
"398.6790","-15.0047","8.04529","0.06073"
"399.1790","-14.9966","8.06067","0.06073"
"399.5500","-14.9902","7.92667","0.06067"
"400.0500","-14.9819","8.01228","0.06071"
"400.5500","-14.9741","8.08299","0.06074"
"400.8990","-14.9677","7.87955","0.06064"
"401.3990","-14.9597","7.95395","0.06067"
"401.8990","-14.9513","8.04234","0.06072"
"402.3990","-14.9430","8.09159","0.06074"
"402.8170","-14.9360","7.92768","0.06066"
"403.3170","-14.9276","8.01239","0.06070"
"403.8170","-14.9194","8.08428","0.06074"
"404.1690","-14.9133","7.89122","0.06063"
"404.6690","-14.9051","7.97509","0.06068"
"405.1690","-14.8968","8.06219","0.06072"
"405.5550","-14.8904","7.94492","0.06066"
"406.0550","-14.8819","7.94878","0.06066"
"406.5550","-14.8738","8.03294","0.06070"
"407.0550","-14.8653","8.07540","0.06072"
"407.5200","-14.8576","7.94769","0.06066"
"408.0200","-14.8493","8.02708","0.06070"
"408.5200","-14.8408","8.07439","0.06073"
"408.9190","-14.8343","7.90585","0.06064"
"409.4190","-14.8258","7.98750","0.06068"
"409.9190","-14.8177","8.04372","0.06071"
"410.4070","-14.8095","7.89419","0.06065"
"410.9070","-14.8011","7.97323","0.06068"
"411.4070","-14.7928","8.05193","0.06073"
"411.9040","-14.7844","7.92623","0.06066"
"412.4040","-14.7763","7.99302","0.06069"
"412.9040","-14.7678","7.94912","0.06068"
"413.3980","-14.7597","7.91702","0.06067"
"413.8980","-14.7513","8.00281","0.06071"
"414.3530","-14.7435","7.96888","0.06069"
"414.8530","-14.7355","7.93543","0.06068"
"415.3530","-14.7270","8.00599","0.06071"
"415.8480","-14.7189","7.87159","0.06064"
"416.3480","-14.7104","7.94840","0.06068"
"416.8480","-14.7020","8.02230","0.06072"
"417.2440","-14.6954","7.84585","0.06063"
"417.7440","-14.6871","7.92674","0.06067"
"418.2440","-14.6790","8.00579","0.06070"
"418.6330","-14.6722","7.81571","0.06061"
"419.1330","-14.6641","7.88971","0.06065"
"419.6330","-14.6556","7.97741","0.06068"
"420.0770","-14.6484","7.88971","0.06064"
"420.5770","-14.6400","7.88345","0.06064"
"421.0770","-14.6315","7.96563","0.06068"
"421.5050","-14.6244","7.81992","0.06062"
"422.0050","-14.6161","7.86762","0.06064"
"422.5050","-14.6080","7.94938","0.06068"
"422.9640","-14.6001","7.84498","0.06063"
"423.4640","-14.5920","7.90405","0.06066"
"423.9640","-14.5834","7.86230","0.06064"
"424.4640","-14.5750","7.84928","0.06063"
"424.9640","-14.5669","7.93026","0.06067"
"425.3840","-14.5597","7.80535","0.06061"
"425.8840","-14.5517","7.83871","0.06062"
"426.3840","-14.5431","7.92471","0.06066"
"426.8480","-14.5355","7.78252","0.06060"
"427.3480","-14.5271","7.84307","0.06062"
"427.8480","-14.5187","7.92004","0.06066"
"428.3390","-14.5107","7.78952","0.06061"
"428.8390","-14.5022","7.86718","0.06064"
"429.3010","-14.4946","7.78311","0.06060"
"429.8010","-14.4862","7.80958","0.06061"
"430.3010","-14.4780","7.88687","0.06065"
"430.7600","-14.4702","7.74320","0.06058"
"431.2600","-14.4618","7.82145","0.06062"
"431.7600","-14.4537","7.86260","0.06064"
"432.2600","-14.4453","7.78147","0.06060"
"432.7600","-14.4370","7.84118","0.06063"
"433.2600","-14.4285","7.76488","0.06059"
"433.7600","-14.4201","7.81865","0.06062"
"434.2600","-14.4121","7.76018","0.06059"
"434.7600","-14.4036","7.79426","0.06061"
"435.2600","-14.3952","7.77979","0.06060"
"435.7600","-14.3869","7.76071","0.06059"
"436.2600","-14.3786","7.79285","0.06061"
"436.7600","-14.3703","7.70520","0.06056"
"437.2600","-14.3617","7.78278","0.06060"
"437.7390","-14.3540","7.67542","0.06055"
"438.2390","-14.3457","7.73076","0.06057"
"438.7390","-14.3372","7.75751","0.06059"
"439.2390","-14.3288","7.69148","0.06056"
"439.7390","-14.3205","7.76552","0.06059"
"440.2190","-14.3128","7.65809","0.06054"
"440.7190","-14.3043","7.72916","0.06057"
"441.2190","-14.2960","7.65200","0.06053"
"441.7190","-14.2876","7.68376","0.06055"
"442.2120","-14.2793","7.62942","0.06052"
"442.7120","-14.2712","7.65550","0.06054"
"443.2120","-14.2627","7.68350","0.06055"
"443.7120","-14.2545","7.62434","0.06053"
"444.2120","-14.2460","7.67618","0.06055"
"444.7120","-14.2376","7.61520","0.06052"
"445.2120","-14.2295","7.64457","0.06053"
"445.7120","-14.2210","7.59469","0.06051"
"446.2120","-14.2129","7.64560","0.06053"
"446.7080","-14.2043","7.57594","0.06050"
"447.2080","-14.1961","7.61014","0.06051"
"447.7080","-14.1879","7.55657","0.06049"
"448.2080","-14.1794","7.55643","0.06049"
"448.7080","-14.1712","7.55101","0.06049"
"449.2080","-14.1628","7.51182","0.06047"
"449.7080","-14.1545","7.54932","0.06049"
"450.2080","-14.1460","7.48698","0.06045"
"450.7080","-14.1376","7.53971","0.06048"
"451.2080","-14.1297","7.48639","0.06046"
"451.7080","-14.1212","7.47226","0.06045"
"452.2080","-14.1127","7.49124","0.06046"
"452.7080","-14.1043","7.44649","0.06044"
"453.2080","-14.0961","7.49316","0.06046"
"453.7080","-14.0880","7.43426","0.06043"
"454.2080","-14.0793","7.41517","0.06042"
"454.7080","-14.0711","7.44246","0.06044"
"455.2080","-14.0628","7.39351","0.06041"
"455.7080","-14.0544","7.40443","0.06042"
"456.2080","-14.0463","7.39448","0.06041"
"456.7080","-14.0377","7.35208","0.06039"
"457.2080","-14.0295","7.38769","0.06041"
"457.7080","-14.0211","7.35509","0.06039"
"458.2080","-14.0127","7.33601","0.06038"
"458.7080","-14.0045","7.31666","0.06037"
"459.2080","-13.9960","7.29986","0.06036"
"459.7080","-13.9878","7.31137","0.06037"
"460.2080","-13.9793","7.26847","0.06035"
"460.7080","-13.9711","7.25849","0.06035"
"461.2080","-13.9629","7.26646","0.06035"
"461.7080","-13.9543","7.20540","0.06032"
"462.2080","-13.9461","7.25527","0.06034"
"462.7080","-13.9378","7.20095","0.06032"
"463.2080","-13.9295","7.16348","0.06030"
"463.7080","-13.9211","7.19574","0.06032"
"464.2080","-13.9125","7.14433","0.06029"
"464.7080","-13.9046","7.17084","0.06030"
"465.2080","-13.8962","7.12726","0.06029"
"465.7080","-13.8877","7.08798","0.06027"
"466.2080","-13.8794","7.12519","0.06028"
"466.7080","-13.8711","7.08258","0.06027"
"467.2080","-13.8629","7.04520","0.06025"
"467.7080","-13.8543","7.00871","0.06023"
"468.2080","-13.8462","7.06152","0.06025"
"468.7080","-13.8378","7.00093","0.06023"
"469.2080","-13.8293","6.96271","0.06021"
"469.7080","-13.8212","6.97657","0.06021"
"470.2080","-13.8127","6.94613","0.06020"
"470.7080","-13.8045","6.92618","0.06019"
"471.2080","-13.7961","6.91009","0.06018"
"471.7080","-13.7877","6.85848","0.06016"
"472.2080","-13.7795","6.89487","0.06018"
"472.7080","-13.7711","6.85050","0.06016"
"473.2080","-13.7628","6.79697","0.06013"
"473.7080","-13.7544","6.78152","0.06013"
"474.1050","-13.7480","6.59537","0.06011"
"474.1160","-13.7477","6.12271","0.05951"
"474.1260","-13.7473","5.65098","0.05885"
"474.1380","-13.7467","5.21689","0.05823"
"474.1560","-13.7460","4.89582","0.05778"