File: Coupon Test Data/test__20250509_94834_3.csv
Time,Displacement,Force,Strain 1
(s),(mm),(kN),(mm/mm)
"0.0000","-20.2597","0.34777","-0.00060"
"0.4000","-20.2545","0.41453","-0.00057"
"0.8000","-20.2480","0.50671","-0.00054"
"1.2000","-20.2411","0.60046","-0.00050"
"1.6000","-20.2344","0.69147","-0.00046"
"2.0000","-20.2278","0.78069","-0.00043"
"2.4000","-20.2210","0.87058","-0.00039"
"2.8000","-20.2144","0.95722","-0.00036"
"3.2000","-20.2078","1.03789","-0.00033"
"3.6000","-20.2011","1.12126","-0.00029"
"4.0000","-20.1944","1.20417","-0.00026"
"4.4000","-20.1877","1.27488","-0.00023"
"4.8000","-20.1811","1.35738","-0.00020"
"5.2000","-20.1745","1.43866","-0.00016"
"5.6000","-20.1677","1.52156","-0.00013"
"6.0000","-20.1612","1.59384","-0.00010"
"6.4000","-20.1544","1.67639","-0.00007"
"6.8000","-20.1478","1.75608","-0.00004"
"7.2000","-20.1411","1.83634","-0.00001"
"7.6000","-20.1344","1.90914","0.00002"
"8.0000","-20.1277","1.98863","0.00005"
"8.4000","-20.1211","2.06656","0.00009"
"8.8000","-20.1143","2.14136","0.00012"
"9.2000","-20.1078","2.21722","0.00015"
"9.6000","-20.1009","2.29733","0.00018"
"10.0000","-20.0944","2.36680","0.00021"
"10.4000","-20.0877","2.44416","0.00024"
"10.8000","-20.0810","2.51989","0.00027"
"11.2000","-20.0744","2.59159","0.00030"
"11.6000","-20.0676","2.66769","0.00033"
"12.0000","-20.0611","2.73928","0.00036"
"12.4000","-20.0543","2.81237","0.00038"
"12.8000","-20.0478","2.88431","0.00041"
"13.2000","-20.0411","2.95554","0.00045"
"13.6000","-20.0345","3.02760","0.00047"
"14.0000","-20.0278","3.09863","0.00051"
"14.4000","-20.0210","3.17172","0.00053"
"14.8000","-20.0144","3.24160","0.00056"
"15.2000","-20.0078","3.31073","0.00059"
"15.6000","-20.0010","3.38324","0.00062"
"16.0000","-19.9945","3.44953","0.00065"
"16.4000","-19.9875","3.52440","0.00068"
"16.8000","-19.9811","3.58885","0.00070"
"17.2000","-19.9742","3.66124","0.00073"
"17.6000","-19.9677","3.72782","0.00076"
"18.0000","-19.9610","3.79619","0.00079"
"18.4000","-19.9543","3.86484","0.00082"
"18.8000","-19.9478","3.93004","0.00084"
"19.2000","-19.9409","3.99972","0.00087"
"19.6000","-19.9344","4.06481","0.00090"
"20.0000","-19.9277","4.13140","0.00093"
"20.4000","-19.9211","4.19794","0.00096"
"20.8000","-19.9145","4.26194","0.00098"
"21.2000","-19.9077","4.33022","0.00101"
"21.6000","-19.9011","4.39423","0.00104"
"22.0000","-19.8944","4.46021","0.00107"
"22.4000","-19.8877","4.52605","0.00109"
"22.8000","-19.8812","4.58800","0.00112"
"23.2000","-19.8742","4.65572","0.00115"
"23.6000","-19.8680","4.71484","0.00117"
"24.0000","-19.8609","4.78347","0.00120"
"24.4000","-19.8544","4.84451","0.00123"
"24.8000","-19.8476","4.90901","0.00125"
"25.2000","-19.8410","4.97120","0.00128"
"25.6000","-19.8345","5.03311","0.00131"
"26.0000","-19.8276","5.09629","0.00133"
"26.4000","-19.8210","5.15798","0.00136"
"26.8000","-19.8143","5.21891","0.00139"
"27.2000","-19.8077","5.28080","0.00141"
"27.6000","-19.8011","5.33953","0.00144"
"28.0000","-19.7943","5.40173","0.00147"
"28.4000","-19.7878","5.45976","0.00149"
"28.8000","-19.7812","5.51941","0.00152"
"29.2000","-19.7744","5.57986","0.00154"
"29.6000","-19.7678","5.63720","0.00157"
"30.0000","-19.7610","5.69749","0.00160"
"30.4000","-19.7546","5.75247","0.00162"
"30.8000","-19.7477","5.81276","0.00165"
"31.2000","-19.7412","5.86797","0.00167"
"31.6000","-19.7343","5.92770","0.00170"
"32.0000","-19.7277","5.98199","0.00173"
"32.4000","-19.7210","6.04011","0.00176"
"32.8000","-19.7144","6.09363","0.00178"
"33.2000","-19.7076","6.15157","0.00181"
"33.6000","-19.7011","6.20289","0.00183"
"34.0000","-19.6943","6.25951","0.00186"
"34.4000","-19.6877","6.31062","0.00189"
"34.8000","-19.6810","6.36458","0.00191"
"35.2000","-19.6744","6.41554","0.00194"
"35.6000","-19.6678","6.46580","0.00197"
"36.0000","-19.6611","6.51636","0.00199"
"36.4000","-19.6545","6.56607","0.00202"
"36.8000","-19.6477","6.61600","0.00205"
"37.2000","-19.6411","6.66475","0.00207"
"37.6000","-19.6344","6.71204","0.00210"
"38.0000","-19.6277","6.75943","0.00213"
"38.4000","-19.6210","6.80621","0.00216"
"38.8000","-19.6145","6.84957","0.00218"
"39.2000","-19.6076","6.89891","0.00221"
"39.6000","-19.6011","6.93884","0.00224"
"40.0000","-19.5942","6.98766","0.00227"
"40.4000","-19.5879","7.02388","0.00230"
"40.8000","-19.5809","7.06843","0.00233"
"41.2000","-19.5744","7.10470","0.00235"
"41.6000","-19.5676","7.14514","0.00238"
"42.0000","-19.5609","7.18237","0.00241"
"42.4000","-19.5544","7.21813","0.00244"
"42.8000","-19.5476","7.25405","0.00247"
"43.2000","-19.5411","7.28936","0.00250"
"43.6000","-19.5344","7.32366","0.00253"
"44.0000","-19.5278","7.36066","0.00256"
"44.4000","-19.5212","7.39270","0.00259"
"44.8000","-19.5143","7.42792","0.00263"
"45.2000","-19.5077","7.45771","0.00266"
"45.6000","-19.5012","7.48753","0.00269"
"46.0000","-19.4943","7.52265","0.00273"
"46.4000","-19.4880","7.54944","0.00276"
"46.8000","-19.4808","7.58643","0.00280"
"47.2000","-19.4746","7.60909","0.00283"
"47.6000","-19.4675","7.64410","0.00288"
"48.0000","-19.4611","7.66777","0.00291"
"48.4000","-19.4542","7.69781","0.00295"
"48.8000","-19.4477","7.72339","0.00299"
"49.2000","-19.4410","7.75080","0.00303"
"49.6000","-19.4342","7.77658","0.00308"
"50.0000","-19.4276","7.80092","0.00312"
"50.4000","-19.4210","7.82317","0.00317"
"50.8000","-19.4144","7.84767","0.00321"
"51.2000","-19.4079","7.86708","0.00326"
"51.6000","-19.4010","7.89033","0.00331"
"52.0000","-19.3944","7.91048","0.00335"
"52.4000","-19.3878","7.93069","0.00340"
"52.8000","-19.3810","7.95249","0.00346"
"53.2000","-19.3746","7.96791","0.00351"
"53.6000","-19.3675","7.98969","0.00357"
"54.0000","-19.3614","8.00229","0.00362"
"54.4000","-19.3542","8.02463","0.00368"
"54.8000","-19.3478","8.03765","0.00373"
"55.2000","-19.3409","8.05630","0.00379"
"55.6000","-19.3344","8.06884","0.00385"
"56.0000","-19.3277","8.08586","0.00391"
"56.4000","-19.3210","8.09880","0.00397"
"56.8000","-19.3142","8.11458","0.00404"
"57.2000","-19.3076","8.10553","0.00408"
"57.6000","-19.3009","8.12948","0.00413"
"58.0000","-19.2944","8.15067","0.00419"
"58.4000","-19.2877","8.16474","0.00425"
"58.8000","-19.2811","8.17233","0.00432"
"59.2000","-19.2745","8.18081","0.00438"
"59.6000","-19.2676","8.19146","0.00446"
"60.0000","-19.2611","8.19930","0.00452"
"60.4000","-19.2543","8.21052","0.00459"
"60.8000","-19.2479","8.21897","0.00466"
"61.2000","-19.2410","8.23101","0.00473"
"61.6000","-19.2345","8.24000","0.00480"
"62.0000","-19.2276","8.25099","0.00487"
"62.4000","-19.2211","8.25724","0.00494"
"62.8000","-19.2143","8.26963","0.00501"
"63.2000","-19.2078","8.27513","0.00508"
"63.6000","-19.2008","8.28716","0.00515"
"64.0000","-19.1944","8.29100","0.00522"
"64.4000","-19.1876","8.30100","0.00529"
"64.8000","-19.1809","8.30533","0.00536"
"65.2000","-19.1743","8.31494","0.00542"
"65.6000","-19.1676","8.32613","0.00548"
"66.0000","-19.1612","8.33249","0.00555"
"66.4000","-19.1543","8.34081","0.00562"
"66.8000","-19.1478","8.34580","0.00569"
"67.2000","-19.1410","8.35115","0.00577"
"67.6000","-19.1344","8.35808","0.00584"
"68.0000","-19.1278","8.36284","0.00591"
"68.4000","-19.1211","8.37134","0.00598"
"68.8000","-19.1144","8.37730","0.00605"
"69.2000","-19.1079","8.38312","0.00612"
"69.6000","-19.1009","8.39298","0.00620"
"70.0000","-19.0945","8.39529","0.00627"
"70.4000","-19.0875","8.40593","0.00635"
"70.8000","-19.0812","8.40657","0.00642"
"71.2000","-19.0742","8.41683","0.00650"
"71.6000","-19.0677","8.42116","0.00657"
"72.0000","-19.0610","8.42800","0.00664"
"72.4000","-19.0542","8.43418","0.00672"
"72.8000","-19.0478","8.43770","0.00679"
"73.2000","-19.0409","8.44480","0.00687"
"73.6000","-19.0344","8.44945","0.00694"
"74.0000","-19.0277","8.45408","0.00701"
"74.4000","-19.0211","8.46201","0.00709"
"74.8000","-19.0144","8.46543","0.00716"
"75.2000","-19.0076","8.47331","0.00723"
"75.6000","-19.0011","8.47644","0.00730"
"76.0000","-18.9945","8.48166","0.00737"
"76.4000","-18.9877","8.48893","0.00745"
"76.8000","-18.9812","8.49143","0.00752"
"77.2000","-18.9742","8.50052","0.00759"
"77.6000","-18.9679","8.49981","0.00766"
"78.0000","-18.9609","8.48467","0.00771"
"78.4000","-18.9544","8.47741","0.00775"
"78.8000","-18.9476","8.51145","0.00780"
"79.2000","-18.9411","8.53142","0.00786"
"79.6000","-18.9344","8.54200","0.00793"
"80.0000","-18.9275","8.54538","0.00799"
"80.4000","-18.9210","8.54656","0.00806"
"80.8000","-18.9143","8.54399","0.00813"
"81.2000","-18.9077","8.54909","0.00820"
"81.6000","-18.9012","8.55203","0.00826"
"82.0000","-18.8943","8.55980","0.00833"
"82.4000","-18.8877","8.56166","0.00840"
"82.8000","-18.8810","8.56507","0.00847"
"83.2000","-18.8743","8.56851","0.00855"
"83.6000","-18.8678","8.57084","0.00862"
"84.0000","-18.8610","8.57698","0.00869"
"84.4000","-18.8546","8.57915","0.00877"
"84.8000","-18.8476","8.58748","0.00885"
"85.2000","-18.8411","8.58942","0.00892"
"85.6000","-18.8343","8.59515","0.00900"
"86.0000","-18.8278","8.59496","0.00909"
"86.4000","-18.8210","8.60030","0.00917"
"86.8000","-18.8144","8.59712","0.00927"
"87.2000","-18.8075","8.58625","0.00938"
"87.6000","-18.8010","8.51171","0.00957"
"88.0000","-18.7942","8.56779","0.00963"
"88.4000","-18.7877","8.61201","0.00969"
"88.8000","-18.7810","8.64003","0.00976"
"89.0530","-18.7768","8.44333","0.01004"
"89.4530","-18.7703","8.50807","0.01009"
"89.8530","-18.7634","8.57833","0.01013"
"90.2530","-18.7570","8.62864","0.01019"
"90.5160","-18.7524","8.48741","0.01041"
"90.9160","-18.7457","8.50651","0.01051"
"91.3160","-18.7391","8.57668","0.01056"
"91.7160","-18.7326","8.63490","0.01061"
"91.9900","-18.7280","8.49752","0.01083"
"92.3900","-18.7211","8.52332","0.01093"
"92.7900","-18.7146","8.59182","0.01098"
"93.1900","-18.7077","8.65364","0.01103"
"93.4540","-18.7032","8.47344","0.01129"
"93.8540","-18.6969","8.54162","0.01134"
"94.2540","-18.6902","8.61237","0.01139"
"94.6540","-18.6835","8.66172","0.01145"
"94.9090","-18.6791","8.49063","0.01171"
"95.3090","-18.6727","8.56210","0.01175"
"95.7090","-18.6658","8.63410","0.01180"
"96.0280","-18.6605","8.56991","0.01196"
"96.3490","-18.6553","8.51542","0.01211"
"96.7490","-18.6486","8.59042","0.01215"
"97.1490","-18.6420","8.65591","0.01220"
"97.4620","-18.6364","8.48793","0.01247"
"97.8620","-18.6302","8.55526","0.01252"
"98.2620","-18.6232","8.63264","0.01256"
"98.6620","-18.6167","8.62023","0.01269"
"98.9790","-18.6113","8.52957","0.01288"
"99.3790","-18.6046","8.60477","0.01293"
"99.7790","-18.5982","8.66868","0.01297"
"100.0540","-18.5933","8.48925","0.01325"
"100.4540","-18.5870","8.55903","0.01329"
"100.8540","-18.5800","8.63661","0.01334"
"101.2050","-18.5745","8.59601","0.01348"
"101.5240","-18.5688","8.52837","0.01366"
"101.9240","-18.5624","8.60134","0.01370"
"102.3240","-18.5556","8.66847","0.01375"
"102.6400","-18.5503","8.50313","0.01390"
"103.0400","-18.5437","8.57857","0.01394"
"103.4400","-18.5370","8.65128","0.01399"
"103.7010","-18.5327","8.52369","0.01400"
"104.1010","-18.5259","8.55408","0.01403"
"104.5010","-18.5194","8.62631","0.01407"
"104.9010","-18.5126","8.68794","0.01410"
"105.1620","-18.5084","8.51566","0.01402"
"105.5620","-18.5016","8.59306","0.01406"
"105.9620","-18.4950","8.66424","0.01409"
"106.2130","-18.4908","8.53335","0.01404"
"106.6130","-18.4842","8.55492","0.01405"
"107.0130","-18.4775","8.63149","0.01409"
"107.4130","-18.4708","8.68917","0.01411"
"107.6670","-18.4665","8.52931","0.01405"
"108.0670","-18.4601","8.60336","0.01408"
"108.4670","-18.4532","8.67879","0.01412"
"108.8670","-18.4467","8.67843","0.01412"
"109.1860","-18.4412","8.58765","0.01409"
"109.5860","-18.4347","8.66147","0.01412"
"109.9860","-18.4280","8.73044","0.01415"
"110.2760","-18.4229","8.55905","0.01408"
"110.6760","-18.4165","8.62961","0.01411"
"111.0760","-18.4098","8.70177","0.01415"
"111.4310","-18.4040","8.65596","0.01413"
"111.7490","-18.3984","8.58237","0.01410"
"112.1490","-18.3920","8.65448","0.01413"
"112.5440","-18.3852","8.62927","0.01412"
"112.8600","-18.3798","8.54790","0.01413"
"113.2600","-18.3735","8.62201","0.01416"
"113.6600","-18.3666","8.69654","0.01420"
"113.9790","-18.3615","8.53586","0.01441"
"114.3790","-18.3546","8.61301","0.01445"
"114.7790","-18.3484","8.68410","0.01449"
"115.1710","-18.3415","8.66034","0.01465"
"115.4920","-18.3362","8.60142","0.01482"
"115.8920","-18.3294","8.68106","0.01486"
"116.2920","-18.3228","8.75253","0.01490"
"116.6690","-18.3166","8.66345","0.01486"
"117.0690","-18.3098","8.70887","0.01488"
"117.4590","-18.3035","8.62052","0.01485"
"117.8590","-18.2967","8.69668","0.01489"
"118.2590","-18.2901","8.76756","0.01492"
"118.6590","-18.2835","8.80181","0.01494"
"119.0590","-18.2767","8.77207","0.01493"
"119.4590","-18.2701","8.79307","0.01494"
"119.8590","-18.2636","8.83109","0.01496"
"120.2590","-18.2566","8.86839","0.01500"
"120.4100","-18.2540","8.62646","0.01532"
"120.8100","-18.2476","8.69914","0.01536"
"121.2100","-18.2409","8.77752","0.01540"
"121.6100","-18.2343","8.84893","0.01544"
"122.0100","-18.2277","8.90484","0.01548"
"122.4100","-18.2209","8.89114","0.01551"
"122.8100","-18.2142","8.94015","0.01555"
"123.1910","-18.2079","8.87829","0.01569"
"123.4250","-18.2039","8.74018","0.01592"
"123.8250","-18.1972","8.81540","0.01596"
"124.2250","-18.1907","8.88196","0.01601"
"124.5490","-18.1852","8.75613","0.01624"
"124.9490","-18.1787","8.82782","0.01628"
"125.3490","-18.1719","8.90588","0.01632"
"125.7490","-18.1653","8.97258","0.01636"
"126.1490","-18.1585","9.02033","0.01640"
"126.3090","-18.1558","8.78094","0.01630"
"126.7090","-18.1493","8.77764","0.01630"
"127.1090","-18.1425","8.85576","0.01634"
"127.5090","-18.1361","8.92596","0.01637"
"127.9090","-18.1291","8.98795","0.01641"
"128.2410","-18.1239","8.88788","0.01637"
"128.6410","-18.1168","8.88783","0.01638"
"129.0410","-18.1105","8.95619","0.01641"
"129.4410","-18.1036","9.02425","0.01644"
"129.8410","-18.0971","9.02775","0.01645"
"130.2410","-18.0903","8.98034","0.01644"
"130.6410","-18.0836","9.02095","0.01646"
"131.0410","-18.0769","9.00173","0.01646"
"131.2920","-18.0728","8.82212","0.01639"
"131.6920","-18.0664","8.89107","0.01642"
"132.0920","-18.0596","8.96489","0.01645"
"132.4920","-18.0530","9.02815","0.01648"
"132.8080","-18.0475","8.96207","0.01646"
"133.0420","-18.0435","8.82505","0.01641"
"133.4420","-18.0371","8.89778","0.01643"
"133.8420","-18.0303","8.97397","0.01647"
"134.2420","-18.0238","9.03566","0.01650"
"134.4730","-18.0195","8.81546","0.01641"
"134.8730","-18.0132","8.87069","0.01644"
"135.2730","-18.0064","8.94990","0.01647"
"135.6730","-17.9998","9.01843","0.01650"
"135.9870","-17.9945","8.89916","0.01651"
"136.3090","-17.9892","8.85812","0.01656"
"136.7090","-17.9827","8.93239","0.01660"
"137.1090","-17.9758","9.00743","0.01665"
"137.4640","-17.9701","8.96369","0.01683"
"137.7790","-17.9647","8.86667","0.01707"
"138.1790","-17.9580","8.94302","0.01711"
"138.5790","-17.9513","9.01506","0.01716"
"138.8940","-17.9462","8.88997","0.01739"
"139.2940","-17.9395","8.88955","0.01752"
"139.6940","-17.9328","8.96502","0.01757"
"140.0940","-17.9263","9.03262","0.01762"
"140.3550","-17.9218","8.89919","0.01785"
"140.6800","-17.9162","8.86894","0.01799"
"141.0800","-17.9098","8.94333","0.01804"
"141.4800","-17.9031","9.01675","0.01809"
"141.8800","-17.8965","9.06090","0.01816"
"142.0360","-17.8935","8.82728","0.01848"
"142.4360","-17.8872","8.89826","0.01853"
"142.8360","-17.8804","8.97615","0.01858"
"143.2360","-17.8737","9.04572","0.01863"
"143.4820","-17.8697","8.89948","0.01886"
"143.8020","-17.8642","8.85768","0.01903"
"144.2020","-17.8577","8.93272","0.01908"
"144.6020","-17.8508","9.00938","0.01913"
"145.0020","-17.8444","9.05808","0.01919"
"145.1910","-17.8413","8.82415","0.01953"
"145.5910","-17.8345","8.90015","0.01958"
"145.9910","-17.8280","8.97458","0.01963"
"146.3910","-17.8211","9.04349","0.01968"
"146.6110","-17.8173","8.82058","0.02002"
"147.0110","-17.8110","8.88386","0.02008"
"147.4110","-17.8042","8.96201","0.02013"
"147.8110","-17.7977","9.03075","0.02018"
"148.0410","-17.7933","8.87171","0.02044"
"148.4410","-17.7872","8.87858","0.02057"
"148.8410","-17.7801","8.96023","0.02062"
"149.2410","-17.7737","9.02679","0.02067"
"149.4750","-17.7696","8.82715","0.02098"
"149.8750","-17.7632","8.87347","0.02107"
"150.2750","-17.7566","8.95026","0.02111"
"150.6750","-17.7498","9.02226","0.02117"
"150.9770","-17.7448","8.82799","0.02149"
"151.3770","-17.7378","8.90521","0.02154"
"151.7770","-17.7315","8.97717","0.02159"
"152.1770","-17.7246","9.04062","0.02166"
"152.5460","-17.7186","8.92754","0.02192"
"152.9460","-17.7119","8.98982","0.02198"
"153.3460","-17.7051","9.05285","0.02203"
"153.7250","-17.6990","8.96223","0.02203"
"154.1250","-17.6922","9.02905","0.02208"
"154.5250","-17.6858","9.08618","0.02212"
"154.9250","-17.6790","9.10882","0.02219"
"155.3250","-17.6725","9.05192","0.02227"
"155.7250","-17.6656","9.06375","0.02229"
"156.1250","-17.6590","8.98121","0.02227"
"156.5250","-17.6523","9.04756","0.02231"
"156.9250","-17.6458","9.10894","0.02234"
"157.2860","-17.6396","9.06610","0.02233"
"157.4250","-17.6372","8.83915","0.02223"
"157.8250","-17.6308","8.91053","0.02226"
"158.2250","-17.6238","8.99229","0.02230"
"158.6250","-17.6175","9.06183","0.02233"
"159.0250","-17.6105","9.12006","0.02237"
"159.1750","-17.6081","8.84552","0.02232"
"159.5750","-17.6014","8.92118","0.02236"
"159.9750","-17.5949","8.99774","0.02239"
"160.3750","-17.5883","9.07085","0.02243"
"160.7660","-17.5815","9.04070","0.02257"
"160.9950","-17.5776","8.89115","0.02277"
"161.3950","-17.5711","8.96671","0.02281"
"161.7950","-17.5645","9.04337","0.02285"
"162.1950","-17.5578","9.11577","0.02289"
"162.5280","-17.5524","9.05393","0.02305"
"162.8440","-17.5471","8.96149","0.02326"
"163.2440","-17.5402","9.04179","0.02331"
"163.6440","-17.5337","9.11520","0.02335"
"164.0440","-17.5269","9.17997","0.02339"
"164.4440","-17.5203","9.16087","0.02340"
"164.8440","-17.5135","9.21246","0.02344"
"165.2440","-17.5070","9.18797","0.02345"
"165.6440","-17.5002","9.17555","0.02345"
"166.0440","-17.4936","9.22463","0.02348"
"166.4440","-17.4869","9.26634","0.02351"
"166.8440","-17.4802","9.23123","0.02363"
"167.1830","-17.4747","9.11463","0.02386"
"167.5830","-17.4680","9.17707","0.02392"
"167.9830","-17.4616","9.23076","0.02398"
"168.2980","-17.4557","9.09715","0.02423"
"168.6980","-17.4496","9.08255","0.02437"
"169.0980","-17.4425","9.16066","0.02442"
"169.4980","-17.4361","9.22599","0.02447"
"169.8980","-17.4293","9.28401","0.02453"
"170.0980","-17.4261","9.05485","0.02484"
"170.4980","-17.4195","9.10420","0.02492"
"170.8980","-17.4127","9.18101","0.02497"
"171.2980","-17.4062","9.24919","0.02501"
"171.6980","-17.3992","9.30904","0.02508"
"172.0050","-17.3942","9.11301","0.02538"
"172.4050","-17.3875","9.17885","0.02544"
"172.8050","-17.3809","9.24845","0.02549"
"173.2050","-17.3743","9.30652","0.02554"
"173.3440","-17.3718","8.99448","0.02542"
"173.7440","-17.3653","9.05655","0.02545"
"174.1440","-17.3586","9.13450","0.02549"
"174.5440","-17.3520","9.20785","0.02553"
"174.9440","-17.3452","9.27542","0.02556"
"175.2030","-17.3410","9.13675","0.02551"
"175.5220","-17.3360","9.08220","0.02549"
"175.9220","-17.3289","9.16351","0.02552"
"176.3220","-17.3225","9.23423","0.02556"
"176.7220","-17.3155","9.29826","0.02559"
"176.9550","-17.3116","9.06926","0.02549"
"177.3550","-17.3052","9.13947","0.02553"
"177.7550","-17.2985","9.21555","0.02556"
"178.1550","-17.2919","9.28514","0.02560"
"178.4320","-17.2869","9.15229","0.02554"
"178.7600","-17.2818","9.11746","0.02553"
"179.1600","-17.2749","9.19597","0.02557"
"179.5600","-17.2683","9.26975","0.02560"
"179.9600","-17.2617","9.33034","0.02563"
"180.1140","-17.2590","9.09317","0.02553"
"180.5140","-17.2526","9.14197","0.02556"
"180.9140","-17.2458","9.22005","0.02559"
"181.3140","-17.2392","9.28647","0.02562"
"181.6530","-17.2334","9.16489","0.02558"
"182.0530","-17.2267","9.23711","0.02561"
"182.4530","-17.2202","9.30989","0.02564"
"182.8530","-17.2136","9.35746","0.02568"
"183.2050","-17.2076","9.26706","0.02564"
"183.4330","-17.2036","9.10728","0.02557"
"183.8330","-17.1972","9.18061","0.02560"
"184.2330","-17.1904","9.25784","0.02564"
"184.6330","-17.1838","9.33125","0.02568"
"185.0330","-17.1771","9.39473","0.02571"
"185.4330","-17.1705","9.34686","0.02581"
"185.8330","-17.1637","9.28289","0.02598"
"186.2330","-17.1572","9.33015","0.02605"
"186.6330","-17.1504","9.38567","0.02613"
"187.0080","-17.1443","9.32774","0.02634"
"187.2460","-17.1403","9.18172","0.02654"
"187.6460","-17.1336","9.25432","0.02658"
"188.0460","-17.1270","9.32726","0.02662"
"188.4460","-17.1202","9.39679","0.02666"
"188.8460","-17.1136","9.40281","0.02668"
"189.0050","-17.1111","9.18217","0.02653"
"189.4050","-17.1041","9.25894","0.02657"
"189.8050","-17.0978","9.32902","0.02660"
"190.2050","-17.0908","9.40037","0.02664"
"190.5660","-17.0850","9.35644","0.02663"
"190.7930","-17.0812","9.18124","0.02655"
"191.1930","-17.0745","9.25743","0.02659"
"191.5930","-17.0680","9.33001","0.02663"
"191.9930","-17.0611","9.39880","0.02666"
"192.2340","-17.0571","9.24878","0.02660"
"192.5530","-17.0518","9.19986","0.02657"
"192.9530","-17.0453","9.27379","0.02661"
"193.3530","-17.0385","9.34990","0.02665"
"193.7530","-17.0318","9.41197","0.02668"
"193.9370","-17.0286","9.19074","0.02659"
"194.3370","-17.0221","9.22893","0.02660"
"194.7370","-17.0153","9.30673","0.02664"
"195.1370","-17.0088","9.37627","0.02667"
"195.5150","-17.0025","9.33395","0.02665"
"195.8320","-16.9973","9.23105","0.02661"
"196.2320","-16.9905","9.30768","0.02664"
"196.6320","-16.9839","9.37752","0.02668"
"196.8750","-16.9797","9.23100","0.02689"
"197.2750","-16.9730","9.25325","0.02699"
"197.6750","-16.9666","9.31145","0.02704"
"198.0750","-16.9597","9.32441","0.02715"
"198.4750","-16.9532","9.34652","0.02725"
"198.8750","-16.9464","9.36870","0.02735"
"199.2000","-16.9410","9.15581","0.02771"
"199.6000","-16.9344","9.22018","0.02776"
"200.0000","-16.9278","9.29153","0.02781"
"200.4000","-16.9210","9.36108","0.02786"
"200.8000","-16.9146","9.33719","0.02801"
"201.0260","-16.9107","9.14784","0.02830"
"201.4260","-16.9038","9.22524","0.02835"
"201.8260","-16.8973","9.29805","0.02839"
"202.2260","-16.8906","9.36914","0.02844"
"202.6260","-16.8840","9.41576","0.02851"
"202.7900","-16.8809","9.14667","0.02888"
"203.1900","-16.8746","9.21544","0.02892"
"203.5900","-16.8678","9.29330","0.02897"
"203.9900","-16.8611","9.36529","0.02902"
"204.3440","-16.8553","9.32230","0.02918"
"204.5760","-16.8513","9.17715","0.02943"
"204.9760","-16.8449","9.24918","0.02947"
"205.3760","-16.8379","9.32812","0.02951"
"205.7760","-16.8316","9.39191","0.02956"
"206.0230","-16.8274","9.25102","0.02981"
"206.3390","-16.8220","9.18804","0.02998"
"206.7390","-16.8155","9.26311","0.03003"
"207.1390","-16.8087","9.34032","0.03007"
"207.5390","-16.8022","9.40490","0.03012"
"207.7650","-16.7984","9.24195","0.03039"
"208.0820","-16.7929","9.18987","0.03055"
"208.4820","-16.7866","9.26242","0.03059"
"208.8820","-16.7796","9.34173","0.03064"
"209.2820","-16.7732","9.40403","0.03069"
"209.5190","-16.7689","9.25588","0.03095"
"209.8360","-16.7638","9.19153","0.03112"
"210.2360","-16.7571","9.26941","0.03117"
"210.6360","-16.7505","9.34200","0.03121"
"211.0360","-16.7439","9.40533","0.03127"
"211.2140","-16.7408","9.17754","0.03159"
"211.6140","-16.7340","9.22602","0.03167"
"212.0140","-16.7275","9.30041","0.03171"
"212.4140","-16.7208","9.37262","0.03176"
"212.8140","-16.7141","9.40603","0.03184"
"212.9790","-16.7111","9.16200","0.03219"
"213.3790","-16.7048","9.23042","0.03224"
"213.7790","-16.6980","9.30795","0.03228"
"214.1790","-16.6913","9.37775","0.03234"
"214.5090","-16.6860","9.32420","0.03251"
"214.7400","-16.6818","9.17156","0.03277"
"215.1400","-16.6755","9.24189","0.03281"
"215.5400","-16.6684","9.32328","0.03285"
"215.9400","-16.6623","9.38670","0.03289"
"216.2420","-16.6569","9.26318","0.03296"
"216.5680","-16.6516","9.21656","0.03303"
"216.9680","-16.6448","9.29289","0.03308"
"217.3680","-16.6383","9.36374","0.03312"
"217.7680","-16.6317","9.42507","0.03317"
"218.1680","-16.6249","9.30962","0.03318"
"218.5680","-16.6184","9.36287","0.03322"
"218.9680","-16.6114","9.41687","0.03327"
"219.3680","-16.6051","9.38521","0.03330"
"219.7680","-16.5981","9.42056","0.03335"
"220.1680","-16.5917","9.44584","0.03340"
"220.5680","-16.5848","9.45063","0.03345"
"220.9680","-16.5783","9.44109","0.03351"
"221.3680","-16.5716","9.46192","0.03357"
"221.7680","-16.5648","9.48413","0.03362"
"222.1680","-16.5581","9.41829","0.03365"
"222.5680","-16.5515","9.46269","0.03370"
"222.9680","-16.5449","9.50799","0.03376"
"223.3680","-16.5383","9.51967","0.03384"
"223.7680","-16.5315","9.39918","0.03410"
"224.1680","-16.5249","9.45181","0.03416"
"224.5680","-16.5183","9.51222","0.03421"
"224.9680","-16.5115","9.56044","0.03426"
"225.3680","-16.5050","9.55059","0.03428"
"225.7680","-16.4982","9.54196","0.03430"
"226.1680","-16.4918","9.56044","0.03432"
"226.5680","-16.4849","9.57364","0.03434"
"226.9280","-16.4790","9.50896","0.03432"
"227.3280","-16.4721","9.56897","0.03436"
"227.7280","-16.4656","9.53503","0.03436"
"228.1280","-16.4589","9.51316","0.03437"
"228.5280","-16.4522","9.48713","0.03436"
"228.9280","-16.4455","9.53564","0.03438"
"229.3280","-16.4389","9.58253","0.03441"
"229.7280","-16.4321","9.61254","0.03445"
"229.9300","-16.4287","9.37063","0.03439"
"230.3300","-16.4223","9.36780","0.03439"
"230.7300","-16.4155","9.44262","0.03443"
"231.1300","-16.4090","9.51174","0.03446"
"231.5300","-16.4022","9.58126","0.03450"
"231.9300","-16.3955","9.63275","0.03453"
"232.1390","-16.3921","9.40872","0.03444"
"232.5390","-16.3853","9.40614","0.03445"
"232.9390","-16.3789","9.47715","0.03448"
"233.3390","-16.3721","9.55105","0.03452"
"233.7390","-16.3656","9.61323","0.03456"
"234.0730","-16.3597","9.49538","0.03451"
"234.4210","-16.3539","9.43523","0.03449"
"234.8210","-16.3474","9.50070","0.03452"
"235.2210","-16.3406","9.56895","0.03455"
"235.6210","-16.3340","9.61798","0.03458"
"235.7660","-16.3312","9.35674","0.03446"
"236.1660","-16.3251","9.38136","0.03448"
"236.5660","-16.3181","9.46139","0.03451"
"236.9660","-16.3116","9.53262","0.03455"
"237.3660","-16.3048","9.60161","0.03458"
"237.7080","-16.2992","9.55215","0.03457"
"237.9310","-16.2956","9.34879","0.03447"
"238.3310","-16.2888","9.42604","0.03451"
"238.7310","-16.2824","9.49854","0.03454"
"239.1310","-16.2753","9.57595","0.03458"
"239.5310","-16.2689","9.62653","0.03461"
"239.7340","-16.2654","9.39199","0.03450"
"240.1340","-16.2588","9.39706","0.03451"
"240.5340","-16.2522","9.47276","0.03454"
"240.9340","-16.2455","9.54684","0.03458"
"241.3340","-16.2390","9.61188","0.03461"
"241.7340","-16.2320","9.53425","0.03458"
"242.1340","-16.2256","9.55236","0.03459"
"242.5340","-16.2185","9.61174","0.03462"
"242.8980","-16.2128","9.53164","0.03459"
"243.2980","-16.2059","9.51971","0.03458"
"243.6980","-16.1994","9.58275","0.03461"
"244.0980","-16.1927","9.64704","0.03464"
"244.4980","-16.1859","9.68763","0.03467"
"244.8980","-16.1794","9.62245","0.03466"
"245.2980","-16.1726","9.64960","0.03468"
"245.6980","-16.1661","9.68433","0.03470"
"245.8560","-16.1632","9.44393","0.03502"
"246.0810","-16.1596","9.30683","0.03526"
"246.4810","-16.1532","9.37955","0.03530"
"246.8810","-16.1464","9.45577","0.03534"
"247.2810","-16.1397","9.52838","0.03539"
"247.6810","-16.1330","9.59389","0.03544"
"248.0290","-16.1274","9.54463","0.03559"
"248.2520","-16.1236","9.34587","0.03591"
"248.6520","-16.1168","9.42154","0.03596"
"249.0520","-16.1103","9.49491","0.03600"
"249.4520","-16.1035","9.56823","0.03605"
"249.8520","-16.0969","9.61125","0.03613"
"249.9210","-16.0955","9.29952","0.03652"
"250.3210","-16.0891","9.36855","0.03658"
"250.7210","-16.0823","9.44648","0.03662"
"251.1210","-16.0758","9.51930","0.03667"
"251.5210","-16.0691","9.58759","0.03672"
"251.7920","-16.0644","9.45687","0.03696"
"252.1090","-16.0590","9.39372","0.03715"
"252.5090","-16.0526","9.46742","0.03719"
"252.9090","-16.0459","9.54280","0.03724"
"253.3090","-16.0392","9.61353","0.03729"
"253.7090","-16.0327","9.66772","0.03736"
"253.9440","-16.0288","9.48437","0.03765"
"254.3440","-16.0218","9.49225","0.03780"
"254.7440","-16.0154","9.56322","0.03785"
"255.1440","-16.0086","9.63580","0.03791"
"255.5440","-16.0020","9.63596","0.03799"
"255.8020","-15.9977","9.49266","0.03795"
"256.2020","-15.9910","9.56527","0.03799"
"256.6020","-15.9845","9.63358","0.03804"
"257.0020","-15.9777","9.61374","0.03821"
"257.4020","-15.9710","9.58772","0.03837"
"257.8020","-15.9643","9.64008","0.03844"
"258.2020","-15.9578","9.68165","0.03851"
"258.5030","-15.9525","9.46692","0.03887"
"258.9030","-15.9460","9.52698","0.03894"
"259.3030","-15.9393","9.59829","0.03899"
"259.7030","-15.9326","9.66608","0.03904"
"260.1030","-15.9259","9.72313","0.03910"
"260.5030","-15.9193","9.70095","0.03927"
"260.7620","-15.9150","9.46569","0.03969"
"261.1620","-15.9083","9.53073","0.03974"
"261.5620","-15.9019","9.59899","0.03979"
"261.9620","-15.8949","9.67012","0.03984"
"262.3620","-15.8885","9.71557","0.03988"
"262.5060","-15.8859","9.40323","0.03973"
"262.9060","-15.8792","9.47352","0.03976"
"263.3060","-15.8728","9.54421","0.03980"
"263.7060","-15.8660","9.62023","0.03985"
"264.1060","-15.8595","9.68702","0.03989"
"264.4510","-15.8534","9.64563","0.03989"
"264.6750","-15.8497","9.44379","0.03980"
"265.0750","-15.8431","9.51628","0.03983"
"265.4750","-15.8364","9.59121","0.03987"
"265.8750","-15.8299","9.66035","0.03991"
"266.2750","-15.8231","9.67345","0.03992"
"266.4190","-15.8206","9.43752","0.03981"
"266.8190","-15.8141","9.50709","0.03985"
"267.2190","-15.8074","9.58113","0.03988"
"267.6190","-15.8007","9.65318","0.03992"
"268.0190","-15.7941","9.69653","0.03995"
"268.1870","-15.7911","9.44724","0.03983"
"268.5870","-15.7847","9.51579","0.03986"
"268.9870","-15.7779","9.59242","0.03990"
"269.3870","-15.7713","9.66347","0.03993"
"269.7870","-15.7645","9.66647","0.03999"
"270.1600","-15.7583","9.60988","0.04011"
"270.5600","-15.7518","9.65921","0.04015"
"270.9360","-15.7454","9.59098","0.04016"
"271.2590","-15.7400","9.48310","0.04011"
"271.6590","-15.7336","9.55150","0.04015"
"272.0590","-15.7266","9.62641","0.04019"
"272.4590","-15.7201","9.69104","0.04023"
"272.8590","-15.7132","9.71374","0.04032"
"272.9200","-15.7120","9.39955","0.04070"
"273.3200","-15.7059","9.44925","0.04076"
"273.7200","-15.6989","9.52642","0.04081"
"274.1200","-15.6925","9.59667","0.04085"
"274.5200","-15.6856","9.66456","0.04090"
"274.9200","-15.6789","9.67130","0.04102"
"275.0610","-15.6767","9.41336","0.04137"
"275.4610","-15.6699","9.48575","0.04142"
"275.8610","-15.6635","9.55572","0.04146"
"276.2610","-15.6564","9.63247","0.04151"
"276.6610","-15.6502","9.68927","0.04157"
"276.8760","-15.6465","9.46450","0.04190"
"277.2760","-15.6398","9.46784","0.04203"
"277.6760","-15.6331","9.54414","0.04207"
"278.0760","-15.6265","9.61695","0.04212"
"278.4760","-15.6199","9.68237","0.04217"
"278.7420","-15.6154","9.54404","0.04242"
"279.0550","-15.6100","9.45106","0.04263"
"279.4550","-15.6036","9.52390","0.04267"
"279.8550","-15.5968","9.59966","0.04272"
"280.2550","-15.5902","9.66900","0.04276"
"280.6020","-15.5843","9.62410","0.04293"
"280.8280","-15.5804","9.43772","0.04322"
"281.2280","-15.5739","9.51019","0.04326"
"281.6280","-15.5672","9.58541","0.04331"
"282.0280","-15.5607","9.65437","0.04335"
"282.4280","-15.5538","9.70085","0.04343"
"282.5870","-15.5512","9.42086","0.04381"
"282.9870","-15.5443","9.49442","0.04386"
"283.3870","-15.5380","9.56474","0.04390"
"283.7870","-15.5311","9.63988","0.04395"
"284.1870","-15.5246","9.69891","0.04400"
"284.3660","-15.5217","9.46405","0.04434"
"284.7660","-15.5148","9.47972","0.04445"
"285.1660","-15.5084","9.55168","0.04450"
"285.5660","-15.5015","9.62744","0.04454"
"285.9660","-15.4950","9.68914","0.04459"
"286.3240","-15.4888","9.57137","0.04484"
"286.7240","-15.4823","9.60347","0.04492"
"287.1240","-15.4755","9.58402","0.04507"
"287.5240","-15.4689","9.59655","0.04520"
"287.9240","-15.4623","9.64721","0.04527"
"288.3240","-15.4555","9.65628","0.04539"
"288.7240","-15.4491","9.58977","0.04564"
"289.1240","-15.4423","9.63655","0.04574"
"289.5240","-15.4358","9.68458","0.04583"
"289.9240","-15.4289","9.71835","0.04595"
"290.1310","-15.4255","9.48114","0.04636"
"290.5310","-15.4186","9.50051","0.04647"
"290.9310","-15.4122","9.56999","0.04652"
"291.3310","-15.4055","9.64203","0.04656"
"291.7310","-15.3988","9.70994","0.04661"
"292.1310","-15.3923","9.76723","0.04665"
"292.4720","-15.3864","9.69118","0.04679"
"292.7050","-15.3826","9.48643","0.04712"
"293.1050","-15.3758","9.55702","0.04718"
"293.5050","-15.3693","9.62567","0.04722"
"293.9050","-15.3626","9.69600","0.04727"
"294.3050","-15.3559","9.75476","0.04733"
"294.5600","-15.3517","9.60034","0.04756"
"294.7990","-15.3476","9.47693","0.04776"
"295.1990","-15.3410","9.54810","0.04780"
"295.5990","-15.3344","9.62160","0.04785"
"295.9990","-15.3276","9.69428","0.04789"
"296.3990","-15.3210","9.75665","0.04792"
"296.6160","-15.3173","9.53432","0.04795"
"297.0160","-15.3111","9.53101","0.04803"
"297.4160","-15.3040","9.61019","0.04807"
"297.8160","-15.2976","9.68106","0.04812"
"298.2160","-15.2907","9.75210","0.04817"
"298.6160","-15.2842","9.76080","0.04823"
"298.7600","-15.2817","9.51855","0.04826"
"299.1600","-15.2750","9.58866","0.04830"
"299.5600","-15.2686","9.66045","0.04834"
"299.9600","-15.2615","9.73795","0.04838"
"300.3600","-15.2553","9.79998","0.04841"
"300.7600","-15.2482","9.83584","0.04847"
"301.0670","-15.2431","9.66533","0.04873"
"301.3900","-15.2378","9.58268","0.04892"
"301.7900","-15.2312","9.65179","0.04897"
"302.1900","-15.2247","9.72014","0.04901"
"302.5900","-15.2178","9.78593","0.04907"
"302.9900","-15.2114","9.81584","0.04914"
"303.1990","-15.2074","9.53507","0.04952"
"303.5990","-15.2011","9.59892","0.04957"
"303.9990","-15.1943","9.67362","0.04962"
"304.3990","-15.1878","9.74304","0.04967"
"304.7990","-15.1810","9.80954","0.04972"
"305.1990","-15.1743","9.79561","0.04978"
"305.5540","-15.1684","9.70008","0.05003"
"305.8950","-15.1627","9.63649","0.05021"
"306.2950","-15.1563","9.70188","0.05027"
"306.6950","-15.1493","9.77352","0.05032"
"307.0950","-15.1430","9.82311","0.05038"
"307.4730","-15.1363","9.70198","0.05068"
"307.8730","-15.1298","9.72748","0.05077"
"308.2730","-15.1231","9.77595","0.05085"
"308.6730","-15.1163","9.80999","0.05094"
"309.0730","-15.1099","9.71892","0.05118"
"309.4580","-15.1033","9.65794","0.05139"
"309.8580","-15.0968","9.71948","0.05144"
"310.2580","-15.0900","9.78666","0.05150"
"310.6580","-15.0834","9.84384","0.05156"
"310.9270","-15.0788","9.69704","0.05182"
"311.2410","-15.0737","9.59593","0.05203"
"311.6410","-15.0669","9.66988","0.05208"
"312.0410","-15.0603","9.74167","0.05213"
"312.4410","-15.0537","9.81051","0.05218"
"312.8410","-15.0469","9.86841","0.05224"
"313.2410","-15.0403","9.81197","0.05233"
"313.6410","-15.0336","9.69460","0.05259"
"314.0410","-15.0270","9.75579","0.05265"
"314.4410","-15.0205","9.81887","0.05270"
"314.8410","-15.0137","9.87127","0.05277"
"314.9940","-15.0111","9.62797","0.05310"
"315.3940","-15.0042","9.61688","0.05324"
"315.7940","-14.9979","9.68634","0.05328"
"316.1940","-14.9910","9.76207","0.05333"
"316.5940","-14.9846","9.82622","0.05338"
"316.9070","-14.9791","9.73430","0.05359"
"317.1370","-14.9755","9.57843","0.05384"
"317.5370","-14.9686","9.65410","0.05388"
"317.9370","-14.9621","9.72631","0.05393"
"318.3370","-14.9553","9.79775","0.05398"
"318.7370","-14.9487","9.85111","0.05404"
"318.9440","-14.9454","9.56252","0.05444"
"319.3440","-14.9385","9.63340","0.05449"
"319.7440","-14.9322","9.70374","0.05453"
"320.1440","-14.9251","9.78049","0.05458"
"320.5440","-14.9188","9.82747","0.05465"
"320.8970","-14.9125","9.66487","0.05496"
"321.2970","-14.9060","9.70557","0.05504"
"321.6970","-14.8994","9.76485","0.05510"
"322.0970","-14.8927","9.80206","0.05519"
"322.4970","-14.8862","9.65632","0.05547"
"322.8970","-14.8793","9.70762","0.05555"
"323.2970","-14.8729","9.76592","0.05560"
"323.6970","-14.8660","9.81914","0.05567"
"323.8870","-14.8629","9.58738","0.05599"
"324.2190","-14.8573","9.55980","0.05614"
"324.6190","-14.8508","9.63027","0.05619"
"325.0190","-14.8441","9.70492","0.05623"
"325.4190","-14.8374","9.77448","0.05629"
"325.8190","-14.8308","9.83123","0.05635"
"325.9650","-14.8282","9.57051","0.05670"
"326.3650","-14.8215","9.60983","0.05679"
"326.7650","-14.8149","9.68287","0.05684"
"327.1650","-14.8083","9.75511","0.05689"
"327.5650","-14.8016","9.82466","0.05694"
"327.9650","-14.7950","9.83169","0.05706"
"328.1090","-14.7924","9.57781","0.05742"
"328.5090","-14.7858","9.64567","0.05748"
"328.9090","-14.7791","9.71997","0.05753"
"329.3090","-14.7727","9.78867","0.05757"
"329.7090","-14.7658","9.85388","0.05763"
"329.9740","-14.7617","9.70680","0.05795"
"330.2890","-14.7559","9.62212","0.05826"
"330.6890","-14.7497","9.68903","0.05831"
"331.0890","-14.7427","9.76688","0.05836"
"331.4890","-14.7363","9.83284","0.05841"
"331.8890","-14.7295","9.87986","0.05849"
"332.1250","-14.7256","9.61895","0.05881"
"332.5250","-14.7191","9.68312","0.05887"
"332.9250","-14.7122","9.75742","0.05891"
"333.3250","-14.7057","9.82433","0.05896"
"333.7250","-14.6988","9.87711","0.05901"
"334.1250","-14.6925","9.78361","0.05915"
"334.5250","-14.6855","9.82425","0.05922"
"334.9250","-14.6791","9.85415","0.05929"
"335.3250","-14.6721","9.78567","0.05944"
"335.7250","-14.6656","9.79574","0.05951"
"336.1250","-14.6589","9.83208","0.05957"
"336.5250","-14.6522","9.77662","0.05963"
"336.9250","-14.6455","9.80528","0.05968"
"337.3250","-14.6390","9.83797","0.05974"
"337.7010","-14.6326","9.75830","0.05985"
"337.9390","-14.6286","9.58646","0.06000"
"338.3390","-14.6222","9.65170","0.06005"
"338.7390","-14.6153","9.72562","0.06009"
"339.1390","-14.6089","9.79242","0.06014"
"339.5390","-14.6020","9.85600","0.06019"
"339.7570","-14.5984","9.63447","0.06018"
"340.0860","-14.5931","9.60169","0.06020"
"340.4860","-14.5862","9.67840","0.06024"
"340.8860","-14.5798","9.74748","0.06027"
"341.2860","-14.5728","9.82007","0.06032"
"341.6860","-14.5664","9.87109","0.06035"
"341.8970","-14.5626","9.58167","0.06021"
"342.2970","-14.5561","9.64804","0.06025"
"342.6970","-14.5496","9.71998","0.06028"
"343.0970","-14.5427","9.79395","0.06032"
"343.4970","-14.5362","9.85500","0.06036"
"343.7220","-14.5321","9.67205","0.06028"
"344.0410","-14.5270","9.61730","0.06025"
"344.4410","-14.5204","9.69045","0.06029"
"344.8410","-14.5139","9.76153","0.06033"
"345.2410","-14.5070","9.83339","0.06036"
"345.6410","-14.5003","9.84227","0.06037"
"345.7970","-14.4975","9.61639","0.06027"
"346.1970","-14.4911","9.68313","0.06030"
"346.5970","-14.4843","9.75847","0.06034"
"346.9970","-14.4778","9.82673","0.06038"
"347.3970","-14.4711","9.86528","0.06042"
"347.7970","-14.4644","9.80630","0.06041"
"348.1970","-14.4578","9.83108","0.06043"
"348.5970","-14.4510","9.87998","0.06046"
"348.9970","-14.4444","9.78658","0.06046"
"349.3970","-14.4379","9.82914","0.06050"
"349.7970","-14.4310","9.87302","0.06053"
"350.1970","-14.4247","9.87123","0.06057"
"350.5970","-14.4175","9.84372","0.06058"
"350.9520","-14.4120","9.67974","0.06049"
"351.3520","-14.4050","9.74655","0.06052"
"351.7520","-14.3986","9.81033","0.06055"
"352.1520","-14.3918","9.87529","0.06059"
"352.5200","-14.3856","9.82535","0.06059"
"352.6660","-14.3833","9.59799","0.06048"
"353.0660","-14.3765","9.66674","0.06051"
"353.4660","-14.3700","9.73697","0.06055"
"353.8660","-14.3630","9.81267","0.06059"
"354.2660","-14.3567","9.87542","0.06062"
"354.6450","-14.3502","9.82948","0.06060"
"354.8710","-14.3466","9.62721","0.06051"
"355.2710","-14.3400","9.69636","0.06054"
"355.6710","-14.3331","9.77146","0.06058"
"356.0710","-14.3266","9.83954","0.06061"
"356.4710","-14.3197","9.90332","0.06065"
"356.6840","-14.3161","9.67279","0.06055"
"357.0840","-14.3097","9.67639","0.06055"
"357.4840","-14.3030","9.74872","0.06058"
"357.8840","-14.2964","9.82059","0.06062"
"358.2840","-14.2897","9.88637","0.06066"
"358.6840","-14.2829","9.89724","0.06073"
"358.9430","-14.2785","9.62997","0.06069"
"359.3430","-14.2720","9.68535","0.06072"
"359.7430","-14.2654","9.75470","0.06075"
"360.1430","-14.2586","9.82423","0.06079"
"360.5430","-14.2519","9.88438","0.06082"
"360.7750","-14.2480","9.65564","0.06087"
"361.1750","-14.2416","9.64930","0.06092"
"361.5750","-14.2347","9.72344","0.06096"
"361.9750","-14.2283","9.79242","0.06100"
"362.3750","-14.2214","9.86078","0.06105"
"362.7750","-14.2150","9.88515","0.06112"
"362.9740","-14.2115","9.61970","0.06141"
"363.3740","-14.2047","9.68348","0.06146"
"363.7740","-14.1982","9.75232","0.06151"
"364.1740","-14.1914","9.82319","0.06155"
"364.5740","-14.1850","9.88003","0.06160"
"364.8750","-14.1796","9.73532","0.06172"
"365.1940","-14.1745","9.63464","0.06178"
"365.5940","-14.1677","9.70459","0.06182"
"365.9940","-14.1610","9.77583","0.06186"
"366.3940","-14.1545","9.84137","0.06190"
"366.7940","-14.1477","9.87177","0.06196"
"367.0340","-14.1439","9.62447","0.06193"
"367.4340","-14.1369","9.68793","0.06197"
"367.8340","-14.1307","9.75225","0.06200"
"368.2340","-14.1237","9.82562","0.06204"
"368.6340","-14.1172","9.86398","0.06207"
"368.8160","-14.1139","9.58510","0.06213"
"369.2160","-14.1074","9.64482","0.06217"
"369.6160","-14.1009","9.71461","0.06221"
"370.0160","-14.0941","9.78854","0.06226"
"370.4160","-14.0877","9.84234","0.06230"
"370.6900","-14.0826","9.63681","0.06254"
"371.0900","-14.0761","9.65967","0.06263"
"371.4900","-14.0694","9.72959","0.06268"
"371.8900","-14.0629","9.79567","0.06273"
"372.2900","-14.0561","9.80374","0.06277"
"372.5750","-14.0514","9.62130","0.06279"
"372.9750","-14.0449","9.67648","0.06283"
"373.3750","-14.0380","9.74137","0.06287"
"373.7750","-14.0316","9.74642","0.06290"
"374.1750","-14.0245","9.60977","0.06283"
"374.5750","-14.0183","9.65949","0.06286"
"374.9750","-14.0113","9.72863","0.06289"
"375.3750","-14.0049","9.76988","0.06292"
"375.7700","-13.9981","9.63444","0.06287"
"376.1700","-13.9914","9.68678","0.06290"
"376.5700","-13.9849","9.73633","0.06293"
"376.9430","-13.9785","9.61999","0.06290"
"377.3430","-13.9720","9.58819","0.06288"
"377.7430","-13.9654","9.65470","0.06291"
"378.1430","-13.9587","9.72302","0.06294"
"378.4890","-13.9529","9.64814","0.06298"
"378.8890","-13.9462","9.61373","0.06299"
"379.2890","-13.9395","9.67271","0.06301"
"379.6890","-13.9330","9.66040","0.06307"
"380.0710","-13.9264","9.55541","0.06313"
"380.4710","-13.9200","9.61609","0.06316"
"380.8710","-13.9130","9.68709","0.06320"
"381.2170","-13.9073","9.60405","0.06328"
"381.5870","-13.9011","9.53831","0.06328"
"381.9870","-13.8946","9.59995","0.06332"
"382.3870","-13.8879","9.66391","0.06335"
"382.7600","-13.8817","9.59019","0.06341"
"383.0910","-13.8763","9.46658","0.06345"
"383.4910","-13.8694","9.53771","0.06350"
"383.8910","-13.8631","9.60457","0.06354"
"384.2910","-13.8559","9.59855","0.06358"
"384.6460","-13.8504","9.51218","0.06361"
"385.0460","-13.8435","9.57384","0.06365"
"385.4460","-13.8370","9.58587","0.06368"
"385.8460","-13.8301","9.48513","0.06367"
"386.2460","-13.8235","9.54142","0.06370"
"386.6460","-13.8170","9.59805","0.06373"
"387.0050","-13.8108","9.43440","0.06376"
"387.4050","-13.8044","9.48565","0.06380"
"387.8050","-13.7976","9.54345","0.06383"
"388.1960","-13.7912","9.40517","0.06388"
"388.5960","-13.7845","9.43548","0.06392"
"388.9960","-13.7779","9.50130","0.06396"
"389.3780","-13.7713","9.46856","0.06398"
"389.7780","-13.7649","9.41871","0.06401"
"390.1780","-13.7580","9.47907","0.06405"
"390.5780","-13.7515","9.43435","0.06406"
"390.9780","-13.7445","9.42431","0.06408"
"391.3780","-13.7381","9.44106","0.06411"
"391.7780","-13.7312","9.39537","0.06415"
"392.1780","-13.7247","9.36973","0.06420"
"392.5780","-13.7180","9.42732","0.06424"
"392.9780","-13.7113","9.37384","0.06424"
"393.3780","-13.7048","9.32997","0.06427"
"393.7780","-13.6980","9.38984","0.06431"
"394.1780","-13.6915","9.34923","0.06433"
"394.5780","-13.6847","9.31938","0.06437"
"394.9780","-13.6782","9.35207","0.06440"
"395.3780","-13.6715","9.27504","0.06438"
"395.7780","-13.6648","9.31313","0.06442"
"396.1780","-13.6580","9.26784","0.06443"
"396.5780","-13.6515","9.25628","0.06447"
"396.9780","-13.6446","9.28669","0.06450"
"397.3780","-13.6382","9.23792","0.06449"
"397.7780","-13.6311","9.26537","0.06452"
"398.1780","-13.6250","9.18501","0.06449"
"398.5780","-13.6179","9.24034","0.06453"
"398.9780","-13.6114","9.17297","0.06453"
"399.3780","-13.6046","9.17179","0.06453"
"399.7780","-13.5980","9.14378","0.06453"
"400.1780","-13.5915","9.09371","0.06453"
"400.5090","-13.5859","8.98603","0.06454"
"400.5130","-13.5858","8.51106","0.06461"
"400.5170","-13.5857","7.71933","0.06436"
"400.5210","-13.5854","6.75450","0.06316"
"400.5250","-13.5850","5.72048","0.06102"