File: Coupon Test Data/test__20250509_94834_1.csv
Time,Displacement,Force,Strain 1
(s),(mm),(kN),(mm/mm)
"0.0000","-23.6040","0.38391","-0.00026"
"0.5000","-23.5971","0.47545","-0.00023"
"1.0000","-23.5887","0.59687","-0.00017"
"1.5000","-23.5807","0.70986","-0.00013"
"2.0000","-23.5722","0.82806","-0.00008"
"2.5000","-23.5637","0.94386","-0.00003"
"3.0000","-23.5554","1.05673","0.00002"
"3.5000","-23.5472","1.16663","0.00006"
"4.0000","-23.5389","1.27663","0.00011"
"4.5000","-23.5303","1.38961","0.00016"
"5.0000","-23.5221","1.49552","0.00020"
"5.5000","-23.5139","1.60139","0.00024"
"6.0000","-23.5054","1.70908","0.00029"
"6.5000","-23.4971","1.81226","0.00033"
"7.0000","-23.4887","1.90885","0.00037"
"7.5000","-23.4805","2.00617","0.00042"
"8.0000","-23.4721","2.10896","0.00046"
"8.5000","-23.4638","2.20984","0.00050"
"9.0000","-23.4554","2.30942","0.00054"
"9.5000","-23.4470","2.40908","0.00058"
"10.0000","-23.4388","2.50595","0.00062"
"10.5000","-23.4304","2.60486","0.00066"
"11.0000","-23.4222","2.69810","0.00070"
"11.5000","-23.4138","2.78572","0.00074"
"12.0000","-23.4053","2.88647","0.00078"
"12.5000","-23.3972","2.98027","0.00082"
"13.0000","-23.3888","3.06770","0.00086"
"13.5000","-23.3805","3.16368","0.00090"
"14.0000","-23.3720","3.26075","0.00094"
"14.5000","-23.3636","3.35064","0.00097"
"15.0000","-23.3556","3.43852","0.00101"
"15.5000","-23.3471","3.53407","0.00105"
"16.0000","-23.3387","3.62379","0.00109"
"16.5000","-23.3304","3.71356","0.00113"
"17.0000","-23.3222","3.80443","0.00116"
"17.5000","-23.3138","3.88943","0.00120"
"18.0000","-23.3053","3.98309","0.00124"
"18.5000","-23.2972","4.07020","0.00128"
"19.0000","-23.2889","4.15337","0.00131"
"19.5000","-23.2804","4.24555","0.00135"
"20.0000","-23.2721","4.33183","0.00138"
"20.5000","-23.2636","4.41824","0.00142"
"21.0000","-23.2555","4.50294","0.00146"
"21.5000","-23.2471","4.58526","0.00149"
"22.0000","-23.2388","4.67326","0.00153"
"22.5000","-23.2304","4.75566","0.00156"
"23.0000","-23.2220","4.83966","0.00160"
"23.5000","-23.2139","4.92194","0.00164"
"24.0000","-23.2054","5.00266","0.00167"
"24.5000","-23.1972","5.08531","0.00170"
"25.0000","-23.1887","5.16472","0.00174"
"25.5000","-23.1802","5.24861","0.00178"
"26.0000","-23.1722","5.32545","0.00181"
"26.5000","-23.1638","5.40262","0.00185"
"27.0000","-23.1555","5.48337","0.00188"
"27.5000","-23.1469","5.56105","0.00192"
"28.0000","-23.1386","5.64108","0.00195"
"28.5000","-23.1306","5.71060","0.00199"
"29.0000","-23.1221","5.79007","0.00202"
"29.5000","-23.1137","5.86831","0.00206"
"30.0000","-23.1053","5.94202","0.00209"
"30.5000","-23.0971","6.01671","0.00213"
"31.0000","-23.0888","6.08632","0.00216"
"31.5000","-23.0803","6.16520","0.00220"
"32.0000","-23.0723","6.23466","0.00223"
"32.5000","-23.0638","6.30569","0.00227"
"33.0000","-23.0553","6.38112","0.00231"
"33.5000","-23.0471","6.44721","0.00234"
"34.0000","-23.0387","6.52036","0.00238"
"34.5000","-23.0306","6.58544","0.00241"
"35.0000","-23.0221","6.65402","0.00245"
"35.5000","-23.0137","6.72373","0.00249"
"36.0000","-23.0054","6.78453","0.00252"
"36.5000","-22.9970","6.85161","0.00256"
"37.0000","-22.9889","6.91317","0.00260"
"37.5000","-22.9804","6.97320","0.00264"
"38.0000","-22.9722","7.03560","0.00268"
"38.5000","-22.9638","7.09566","0.00273"
"39.0000","-22.9552","7.15028","0.00277"
"39.5000","-22.9473","7.20623","0.00281"
"40.0000","-22.9388","7.26344","0.00285"
"40.5000","-22.9304","7.31611","0.00290"
"41.0000","-22.9219","7.36736","0.00294"
"41.5000","-22.9136","7.42084","0.00299"
"42.0000","-22.9057","7.46522","0.00303"
"42.5000","-22.8971","7.51506","0.00309"
"43.0000","-22.8887","7.55760","0.00313"
"43.5000","-22.8803","7.60520","0.00319"
"44.0000","-22.8722","7.64647","0.00324"
"44.5000","-22.8639","7.68554","0.00329"
"45.0000","-22.8552","7.72887","0.00335"
"45.5000","-22.8472","7.75778","0.00340"
"46.0000","-22.8388","7.79671","0.00346"
"46.5000","-22.8303","7.83265","0.00352"
"47.0000","-22.8221","7.86268","0.00359"
"47.5000","-22.8136","7.89654","0.00365"
"48.0000","-22.8055","7.92245","0.00372"
"48.5000","-22.7971","7.95038","0.00379"
"49.0000","-22.7887","7.96809","0.00384"
"49.5000","-22.7804","8.00173","0.00391"
"50.0000","-22.7720","8.02658","0.00398"
"50.5000","-22.7638","8.04420","0.00406"
"51.0000","-22.7553","8.06732","0.00413"
"51.5000","-22.7472","8.08712","0.00421"
"52.0000","-22.7388","8.10598","0.00429"
"52.5000","-22.7302","8.12823","0.00436"
"53.0000","-22.7222","8.14102","0.00444"
"53.5000","-22.7138","8.15771","0.00452"
"54.0000","-22.7055","8.17464","0.00460"
"54.5000","-22.6970","8.19120","0.00468"
"55.0000","-22.6886","8.20779","0.00476"
"55.5000","-22.6806","8.21610","0.00484"
"56.0000","-22.6721","8.23120","0.00492"
"56.5000","-22.6637","8.24589","0.00501"
"57.0000","-22.6554","8.25826","0.00509"
"57.5000","-22.6471","8.25969","0.00516"
"58.0000","-22.6388","8.28173","0.00524"
"58.5000","-22.6302","8.29698","0.00533"
"59.0000","-22.6222","8.30247","0.00542"
"59.5000","-22.6139","8.31050","0.00551"
"60.0000","-22.6053","8.32329","0.00560"
"60.5000","-22.5971","8.33049","0.00569"
"61.0000","-22.5886","8.34268","0.00578"
"61.5000","-22.5805","8.34917","0.00587"
"62.0000","-22.5721","8.35877","0.00596"
"62.5000","-22.5637","8.37121","0.00605"
"63.0000","-22.5553","8.37908","0.00614"
"63.5000","-22.5470","8.38765","0.00623"
"64.0000","-22.5389","8.39275","0.00632"
"64.5000","-22.5304","8.40340","0.00641"
"65.0000","-22.5222","8.41115","0.00650"
"65.5000","-22.5137","8.41859","0.00659"
"66.0000","-22.5052","8.43059","0.00667"
"66.5000","-22.4972","8.43474","0.00676"
"67.0000","-22.4888","8.44291","0.00685"
"67.5000","-22.4805","8.45069","0.00694"
"68.0000","-22.4719","8.45829","0.00703"
"68.5000","-22.4636","8.46645","0.00712"
"69.0000","-22.4556","8.46857","0.00721"
"69.5000","-22.4471","8.47886","0.00730"
"70.0000","-22.4387","8.48755","0.00739"
"70.5000","-22.4302","8.49476","0.00749"
"71.0000","-22.4221","8.49944","0.00758"
"71.5000","-22.4138","8.50337","0.00767"
"72.0000","-22.4052","8.51409","0.00776"
"72.5000","-22.3972","8.51861","0.00786"
"73.0000","-22.3888","8.52454","0.00795"
"73.5000","-22.3803","8.53288","0.00804"
"74.0000","-22.3721","8.53728","0.00814"
"74.5000","-22.3637","8.54600","0.00823"
"75.0000","-22.3556","8.54887","0.00832"
"75.5000","-22.3470","8.55544","0.00842"
"76.0000","-22.3387","8.56230","0.00850"
"76.5000","-22.3304","8.56852","0.00859"
"77.0000","-22.3220","8.57787","0.00868"
"77.5000","-22.3140","8.58228","0.00877"
"78.0000","-22.3053","8.59136","0.00886"
"78.5000","-22.2971","8.59545","0.00896"
"79.0000","-22.2887","8.59970","0.00906"
"79.5000","-22.2802","8.60849","0.00915"
"80.0000","-22.2722","8.61029","0.00924"
"80.5000","-22.2638","8.61637","0.00934"
"81.0000","-22.2554","8.62242","0.00944"
"81.5000","-22.2469","8.62964","0.00953"
"82.0000","-22.2386","8.63599","0.00963"
"82.5000","-22.2307","8.63605","0.00972"
"83.0000","-22.2221","8.64365","0.00981"
"83.5000","-22.2137","8.61897","0.00987"
"84.0000","-22.2053","8.65157","0.00995"
"84.5000","-22.1972","8.66338","0.01002"
"85.0000","-22.1889","8.67003","0.01010"
"85.5000","-22.1802","8.68423","0.01018"
"86.0000","-22.1722","8.68549","0.01027"
"86.5000","-22.1638","8.68371","0.01035"
"87.0000","-22.1553","8.67743","0.01042"
"87.3660","-22.1493","8.52151","0.01038"
"87.8660","-22.1410","8.60106","0.01043"
"88.3660","-22.1327","8.66871","0.01049"
"88.8660","-22.1241","8.71485","0.01055"
"89.2030","-22.1188","8.53765","0.01051"
"89.7030","-22.1103","8.58892","0.01054"
"90.2030","-22.1021","8.66933","0.01060"
"90.7030","-22.0936","8.72761","0.01065"
"91.0710","-22.0876","8.55578","0.01059"
"91.5710","-22.0791","8.64641","0.01064"
"92.0710","-22.0709","8.72173","0.01070"
"92.4810","-22.0640","8.54818","0.01064"
"92.9810","-22.0556","8.63877","0.01069"
"93.4810","-22.0475","8.71685","0.01074"
"93.8950","-22.0403","8.55131","0.01069"
"94.3950","-22.0323","8.63793","0.01073"
"94.8950","-22.0239","8.72391","0.01078"
"95.3020","-22.0171","8.56006","0.01073"
"95.8020","-22.0087","8.65222","0.01078"
"96.3020","-22.0003","8.73772","0.01084"
"96.6420","-21.9946","8.56459","0.01103"
"97.1420","-21.9864","8.65554","0.01108"
"97.6420","-21.9781","8.73894","0.01114"
"97.9880","-21.9723","8.56639","0.01144"
"98.4880","-21.9640","8.65744","0.01150"
"98.9880","-21.9554","8.74764","0.01157"
"99.3390","-21.9499","8.57398","0.01186"
"99.8390","-21.9414","8.67020","0.01192"
"100.3390","-21.9332","8.75502","0.01199"
"100.7320","-21.9265","8.58750","0.01231"
"101.2320","-21.9182","8.68266","0.01236"
"101.7320","-21.9098","8.76540","0.01244"
"102.1490","-21.9030","8.61193","0.01274"
"102.6490","-21.8947","8.70689","0.01281"
"103.1340","-21.8864","8.69295","0.01298"
"103.5510","-21.8796","8.63196","0.01319"
"104.0510","-21.8712","8.72707","0.01326"
"104.4560","-21.8646","8.61711","0.01351"
"104.9560","-21.8561","8.65959","0.01364"
"105.4560","-21.8480","8.74866","0.01370"
"105.8210","-21.8416","8.58076","0.01402"
"106.3210","-21.8334","8.67395","0.01408"
"106.8210","-21.8251","8.76356","0.01415"
"107.1660","-21.8192","8.59112","0.01446"
"107.6660","-21.8109","8.68425","0.01453"
"108.1660","-21.8026","8.77328","0.01459"
"108.5540","-21.7961","8.61006","0.01491"
"109.0540","-21.7876","8.70791","0.01497"
"109.5540","-21.7797","8.78428","0.01504"
"109.9590","-21.7727","8.62714","0.01537"
"110.4590","-21.7645","8.72296","0.01543"
"110.9350","-21.7565","8.70743","0.01560"
"111.3520","-21.7496","8.64736","0.01581"
"111.8520","-21.7410","8.74670","0.01588"
"112.2650","-21.7344","8.63387","0.01613"
"112.7650","-21.7260","8.66965","0.01627"
"113.2650","-21.7175","8.76650","0.01633"
"113.6610","-21.7111","8.60209","0.01668"
"114.1610","-21.7026","8.69849","0.01675"
"114.6610","-21.6945","8.78573","0.01682"
"115.0620","-21.6877","8.62059","0.01700"
"115.5620","-21.6795","8.71646","0.01705"
"116.0620","-21.6710","8.79524","0.01709"
"116.4210","-21.6650","8.63294","0.01700"
"116.9210","-21.6568","8.72911","0.01704"
"117.3690","-21.6493","8.71311","0.01704"
"117.7870","-21.6422","8.66134","0.01701"
"118.2870","-21.6340","8.75592","0.01706"
"118.6800","-21.6273","8.64995","0.01701"
"119.1800","-21.6188","8.68934","0.01703"
"119.6800","-21.6111","8.77497","0.01707"
"120.0980","-21.6037","8.66308","0.01702"
"120.5980","-21.5955","8.75852","0.01706"
"121.0980","-21.5871","8.82801","0.01710"
"121.5980","-21.5788","8.77233","0.01709"
"122.0980","-21.5705","8.85738","0.01713"
"122.5980","-21.5619","8.87866","0.01715"
"123.0980","-21.5540","8.91680","0.01717"
"123.5980","-21.5455","8.93066","0.01718"
"124.0980","-21.5371","8.98595","0.01720"
"124.5980","-21.5287","9.00313","0.01722"
"125.0980","-21.5204","9.00913","0.01724"
"125.5980","-21.5124","9.05215","0.01727"
"126.0230","-21.5049","8.91280","0.01721"
"126.5230","-21.4968","8.99557","0.01726"
"126.9030","-21.4904","8.83152","0.01719"
"127.4030","-21.4820","8.93059","0.01723"
"127.9030","-21.4737","9.02484","0.01728"
"128.4030","-21.4654","9.10261","0.01732"
"128.8210","-21.4583","8.92724","0.01726"
"129.3210","-21.4498","9.02122","0.01730"
"129.8210","-21.4420","9.09222","0.01734"
"130.3080","-21.4337","8.98470","0.01731"
"130.8080","-21.4253","9.06590","0.01735"
"131.2640","-21.4175","9.01741","0.01733"
"131.6840","-21.4108","8.94339","0.01730"
"132.1840","-21.4023","9.03826","0.01735"
"132.6840","-21.3938","9.12140","0.01739"
"132.9980","-21.3887","8.89854","0.01742"
"133.4980","-21.3802","8.99369","0.01746"
"133.9980","-21.3723","9.08164","0.01750"
"134.4220","-21.3650","9.04850","0.01761"
"134.8370","-21.3583","8.96045","0.01780"
"135.3370","-21.3498","9.05777","0.01786"
"135.8370","-21.3416","9.13799","0.01792"
"136.1150","-21.3366","8.91675","0.01827"
"136.6150","-21.3286","9.00679","0.01832"
"137.1150","-21.3203","9.09945","0.01838"
"137.5290","-21.3132","9.03521","0.01858"
"137.9440","-21.3064","8.96785","0.01878"
"138.4440","-21.2982","9.06268","0.01884"
"138.9440","-21.2896","9.14449","0.01891"
"139.2760","-21.2841","8.93779","0.01923"
"139.7760","-21.2759","9.03303","0.01928"
"140.2760","-21.2674","9.12567","0.01934"
"140.6110","-21.2619","8.91274","0.01967"
"141.1110","-21.2535","8.99929","0.01973"
"141.6110","-21.2454","9.09117","0.01979"
"142.0790","-21.2374","9.07880","0.01995"
"142.4120","-21.2320","8.95456","0.02018"
"142.9120","-21.2235","9.05412","0.02023"
"143.4120","-21.2153","9.14043","0.02029"
"143.7370","-21.2097","8.91879","0.02063"
"144.2370","-21.2014","9.01316","0.02068"
"144.7370","-21.1931","9.10789","0.02074"
"145.1640","-21.1861","9.07491","0.02090"
"145.4980","-21.1804","8.95805","0.02113"
"145.9980","-21.1722","9.05367","0.02118"
"146.4980","-21.1637","9.14281","0.02124"
"146.7520","-21.1595","8.91768","0.02156"
"147.2520","-21.1513","8.99705","0.02163"
"147.7520","-21.1428","9.09509","0.02169"
"148.2520","-21.1346","9.10844","0.02182"
"148.5810","-21.1291","8.95908","0.02208"
"149.0810","-21.1207","9.05680","0.02213"
"149.5810","-21.1122","9.14694","0.02220"
"149.9000","-21.1070","8.92548","0.02253"
"150.4000","-21.0986","9.02096","0.02258"
"150.9000","-21.0906","9.11114","0.02264"
"151.2750","-21.0840","9.00308","0.02288"
"151.6960","-21.0772","8.97793","0.02302"
"152.1960","-21.0687","9.07746","0.02308"
"152.6960","-21.0606","9.15308","0.02315"
"153.0100","-21.0550","8.94671","0.02348"
"153.5100","-21.0471","9.03942","0.02353"
"154.0100","-21.0387","9.13096","0.02359"
"154.2860","-21.0340","8.91840","0.02391"
"154.7860","-21.0257","9.00251","0.02397"
"155.2860","-21.0174","9.09736","0.02403"
"155.7250","-21.0099","9.07444","0.02419"
"156.0580","-21.0046","8.95034","0.02443"
"156.5580","-20.9961","9.05036","0.02448"
"157.0580","-20.9877","9.14151","0.02454"
"157.3870","-20.9822","8.91399","0.02489"
"157.8870","-20.9739","9.00820","0.02495"
"158.3870","-20.9657","9.10192","0.02500"
"158.8250","-20.9582","9.07844","0.02517"
"159.1540","-20.9527","8.94327","0.02542"
"159.6540","-20.9443","9.04237","0.02548"
"160.1540","-20.9365","9.12664","0.02553"
"160.4490","-20.9310","8.93101","0.02584"
"160.9490","-20.9231","8.98539","0.02592"
"161.4490","-20.9146","9.08345","0.02596"
"161.9110","-20.9069","9.06207","0.02603"
"162.2510","-20.9011","8.95714","0.02612"
"162.7510","-20.8930","9.05068","0.02617"
"163.2510","-20.8846","9.13337","0.02621"
"163.5920","-20.8791","8.93108","0.02616"
"164.0920","-20.8706","9.03021","0.02621"
"164.5920","-20.8622","9.12311","0.02625"
"164.8760","-20.8574","8.91302","0.02615"
"165.3760","-20.8493","8.98014","0.02618"
"165.8760","-20.8408","9.07852","0.02623"
"166.3380","-20.8330","9.06046","0.02622"
"166.6750","-20.8274","8.94333","0.02618"
"167.1750","-20.8190","9.04242","0.02622"
"167.6750","-20.8109","9.12908","0.02626"
"168.0300","-20.8048","8.97140","0.02620"
"168.5300","-20.7967","9.03872","0.02623"
"169.0300","-20.7882","9.12832","0.02627"
"169.5300","-20.7800","9.15799","0.02629"
"170.0300","-20.7716","9.17706","0.02631"
"170.5300","-20.7632","9.21235","0.02634"
"171.0300","-20.7550","9.21420","0.02635"
"171.5300","-20.7465","9.23697","0.02637"
"172.0300","-20.7383","9.26331","0.02639"
"172.5300","-20.7298","9.25444","0.02639"
"173.0300","-20.7216","9.25327","0.02639"
"173.5300","-20.7133","9.29478","0.02641"
"174.0300","-20.7047","9.32724","0.02643"
"174.5300","-20.6966","9.29283","0.02642"
"175.0300","-20.6883","9.25425","0.02641"
"175.5300","-20.6800","9.32644","0.02644"
"176.0300","-20.6715","9.33392","0.02645"
"176.5100","-20.6634","9.26860","0.02642"
"177.0100","-20.6555","9.32642","0.02645"
"177.5100","-20.6469","9.27625","0.02644"
"178.0100","-20.6385","9.27652","0.02644"
"178.5100","-20.6302","9.35616","0.02648"
"179.0100","-20.6220","9.41637","0.02651"
"179.4570","-20.6144","9.24896","0.02644"
"179.9570","-20.6058","9.33467","0.02648"
"180.4570","-20.5981","9.40816","0.02651"
"180.9570","-20.5896","9.45720","0.02655"
"181.2450","-20.5848","9.18896","0.02642"
"181.7450","-20.5763","9.28235","0.02646"
"182.2450","-20.5680","9.37027","0.02650"
"182.7450","-20.5595","9.44044","0.02654"
"183.0800","-20.5541","9.23340","0.02645"
"183.5800","-20.5458","9.27816","0.02647"
"184.0800","-20.5373","9.37306","0.02652"
"184.5800","-20.5292","9.45466","0.02655"
"184.9870","-20.5221","9.26452","0.02648"
"185.4870","-20.5141","9.34540","0.02651"
"185.9870","-20.5056","9.43656","0.02656"
"186.4870","-20.4974","9.50460","0.02659"
"186.7230","-20.4930","9.25840","0.02654"
"187.1420","-20.4866","9.23599","0.02656"
"187.6420","-20.4781","9.33521","0.02661"
"188.1420","-20.4697","9.42779","0.02665"
"188.6420","-20.4614","9.49844","0.02670"
"188.8710","-20.4576","9.20829","0.02697"
"189.3710","-20.4492","9.30362","0.02702"
"189.8710","-20.4410","9.39762","0.02707"
"190.3710","-20.4325","9.48538","0.02713"
"190.7060","-20.4270","9.35233","0.02739"
"191.0380","-20.4215","9.24308","0.02762"
"191.5380","-20.4131","9.34141","0.02767"
"192.0380","-20.4046","9.43742","0.02773"
"192.5380","-20.3964","9.51253","0.02779"
"192.7770","-20.3922","9.21818","0.02820"
"193.2770","-20.3842","9.30918","0.02825"
"193.7770","-20.3759","9.40378","0.02830"
"194.2770","-20.3673","9.49219","0.02837"
"194.5990","-20.3620","9.22849","0.02875"
"195.0990","-20.3536","9.32045","0.02881"
"195.5990","-20.3456","9.41114","0.02886"
"196.0990","-20.3371","9.49409","0.02893"
"196.3610","-20.3327","9.24198","0.02928"
"196.8610","-20.3242","9.33622","0.02934"
"197.3610","-20.3162","9.42552","0.02939"
"197.8530","-20.3079","9.40708","0.02957"
"198.1900","-20.3022","9.28718","0.02980"
"198.6900","-20.2940","9.38144","0.02985"
"199.1900","-20.2857","9.46852","0.02991"
"199.4480","-20.2811","9.25845","0.03022"
"199.9480","-20.2730","9.30986","0.03032"
"200.4480","-20.2646","9.40657","0.03037"
"200.9480","-20.2562","9.49205","0.03043"
"201.2430","-20.2514","9.22433","0.03081"
"201.7430","-20.2430","9.31950","0.03086"
"202.2430","-20.2347","9.41452","0.03092"
"202.7430","-20.2262","9.49871","0.03098"
"203.0310","-20.2213","9.22228","0.03137"
"203.5310","-20.2130","9.31484","0.03142"
"204.0310","-20.2052","9.40455","0.03147"
"204.5310","-20.1966","9.49376","0.03154"
"204.7740","-20.1925","9.27702","0.03185"
"205.2740","-20.1841","9.29438","0.03198"
"205.7740","-20.1760","9.38741","0.03204"
"206.2740","-20.1675","9.47927","0.03209"
"206.6480","-20.1615","9.36029","0.03234"
"206.9870","-20.1554","9.26452","0.03255"
"207.4870","-20.1474","9.35619","0.03260"
"207.9870","-20.1391","9.44921","0.03266"
"208.4770","-20.1307","9.43323","0.03283"
"208.8010","-20.1254","9.25869","0.03312"
"209.3010","-20.1172","9.35454","0.03317"
"209.8010","-20.1086","9.44990","0.03323"
"210.2730","-20.1006","9.43114","0.03340"
"210.5980","-20.0953","9.26856","0.03367"
"211.0980","-20.0870","9.36453","0.03372"
"211.5980","-20.0790","9.45260","0.03378"
"212.0010","-20.0719","9.34134","0.03404"
"212.4190","-20.0652","9.29916","0.03420"
"212.9190","-20.0566","9.39726","0.03426"
"213.4190","-20.0486","9.47921","0.03432"
"213.7320","-20.0429","9.24176","0.03469"
"214.2320","-20.0351","9.32726","0.03474"
"214.7320","-20.0267","9.42255","0.03480"
"215.2320","-20.0181","9.47451","0.03490"
"215.4820","-20.0140","9.25604","0.03522"
"215.9820","-20.0058","9.35000","0.03527"
"216.4820","-19.9973","9.44430","0.03533"
"216.9420","-19.9897","9.41998","0.03550"
"217.2670","-19.9842","9.25870","0.03578"
"217.7670","-19.9759","9.35549","0.03583"
"218.2670","-19.9676","9.44656","0.03589"
"218.7020","-19.9603","9.41732","0.03606"
"219.0270","-19.9548","9.25915","0.03633"
"219.5270","-19.9467","9.35399","0.03638"
"220.0270","-19.9385","9.44501","0.03644"
"220.4710","-19.9306","9.42425","0.03661"
"220.7960","-19.9255","9.25946","0.03689"
"221.2960","-19.9170","9.35814","0.03694"
"221.7960","-19.9090","9.44763","0.03699"
"222.2960","-19.9005","9.50545","0.03709"
"222.5640","-19.8960","9.23375","0.03747"
"223.0640","-19.8876","9.32992","0.03752"
"223.5640","-19.8795","9.42069","0.03757"
"224.0640","-19.8711","9.49115","0.03760"
"224.3520","-19.8664","9.24066","0.03768"
"224.8520","-19.8580","9.33659","0.03773"
"225.3520","-19.8495","9.43117","0.03779"
"225.8520","-19.8412","9.48704","0.03783"
"226.1160","-19.8369","9.25807","0.03780"
"226.6160","-19.8284","9.35378","0.03784"
"227.1160","-19.8200","9.44674","0.03789"
"227.5690","-19.8127","9.40601","0.03787"
"227.9860","-19.8054","9.31857","0.03783"
"228.4860","-19.7975","9.40691","0.03787"
"228.9860","-19.7891","9.49058","0.03791"
"229.3900","-19.7823","9.30464","0.03784"
"229.8900","-19.7739","9.39035","0.03788"
"230.3900","-19.7657","9.47772","0.03792"
"230.8900","-19.7572","9.53487","0.03796"
"231.2990","-19.7503","9.34793","0.03789"
"231.7990","-19.7422","9.43609","0.03793"
"232.2990","-19.7337","9.52557","0.03798"
"232.7990","-19.7254","9.47239","0.03796"
"233.2990","-19.7170","9.54317","0.03800"
"233.7990","-19.7088","9.60369","0.03803"
"234.0450","-19.7045","9.31597","0.03790"
"234.5450","-19.6964","9.40454","0.03794"
"235.0450","-19.6880","9.49953","0.03799"
"235.5450","-19.6796","9.58995","0.03803"
"236.0450","-19.6715","9.65038","0.03806"
"236.5450","-19.6629","9.54304","0.03802"
"237.0450","-19.6548","9.59940","0.03805"
"237.5450","-19.6463","9.64634","0.03808"
"238.0450","-19.6379","9.69129","0.03810"
"238.4830","-19.6306","9.53589","0.03804"
"238.9830","-19.6223","9.59629","0.03807"
"239.4830","-19.6142","9.55849","0.03805"
"239.9830","-19.6056","9.63677","0.03809"
"240.4690","-19.5977","9.53969","0.03805"
"240.9690","-19.5892","9.61124","0.03809"
"241.4320","-19.5814","9.56152","0.03807"
"241.8660","-19.5744","9.49770","0.03804"
"242.3660","-19.5658","9.58732","0.03808"
"242.8660","-19.5578","9.64805","0.03811"
"243.1800","-19.5522","9.41056","0.03801"
"243.6800","-19.5443","9.49807","0.03805"
"244.1800","-19.5358","9.59325","0.03809"
"244.6800","-19.5275","9.67954","0.03813"
"245.1800","-19.5191","9.73378","0.03817"
"245.6800","-19.5107","9.68656","0.03816"
"246.1800","-19.5025","9.62159","0.03813"
"246.6800","-19.4940","9.67340","0.03816"
"247.1800","-19.4860","9.71953","0.03818"
"247.6230","-19.4782","9.61308","0.03814"
"248.0450","-19.4713","9.52216","0.03810"
"248.5450","-19.4630","9.61042","0.03814"
"249.0450","-19.4545","9.69756","0.03818"
"249.5290","-19.4468","9.67069","0.03817"
"249.7770","-19.4425","9.46815","0.03809"
"250.2770","-19.4340","9.56208","0.03813"
"250.7770","-19.4256","9.65441","0.03817"
"251.2770","-19.4177","9.72341","0.03820"
"251.5170","-19.4133","9.43783","0.03807"
"252.0170","-19.4052","9.52555","0.03812"
"252.5170","-19.3967","9.62097","0.03816"
"253.0170","-19.3886","9.70416","0.03820"
"253.2970","-19.3837","9.48613","0.03810"
"253.7970","-19.3756","9.50105","0.03811"
"254.2970","-19.3671","9.59925","0.03816"
"254.7970","-19.3589","9.68669","0.03820"
"255.1370","-19.3531","9.55849","0.03815"
"255.5520","-19.3463","9.49572","0.03812"
"256.0520","-19.3379","9.59099","0.03817"
"256.5520","-19.3297","9.68106","0.03821"
"257.0000","-19.3220","9.65577","0.03823"
"257.3260","-19.3167","9.48719","0.03814"
"257.8260","-19.3083","9.58348","0.03819"
"258.3260","-19.2998","9.67709","0.03825"
"258.8260","-19.2917","9.69149","0.03829"
"259.3260","-19.2833","9.73602","0.03833"
"259.7330","-19.2767","9.54856","0.03825"
"260.2330","-19.2681","9.64393","0.03830"
"260.7330","-19.2599","9.72895","0.03834"
"261.2330","-19.2515","9.73129","0.03835"
"261.5680","-19.2460","9.57019","0.03828"
"262.0680","-19.2377","9.66256","0.03832"
"262.5680","-19.2292","9.75156","0.03837"
"262.8270","-19.2248","9.48150","0.03825"
"263.3270","-19.2167","9.54141","0.03827"
"263.8270","-19.2083","9.63441","0.03832"
"264.3270","-19.1997","9.71905","0.03836"
"264.5830","-19.1956","9.48174","0.03825"
"265.0830","-19.1872","9.53008","0.03827"
"265.5830","-19.1791","9.62209","0.03832"
"266.0830","-19.1707","9.71406","0.03836"
"266.5790","-19.1626","9.68966","0.03840"
"266.9030","-19.1569","9.51063","0.03837"
"267.4030","-19.1489","9.60134","0.03841"
"267.9030","-19.1404","9.69626","0.03846"
"268.4030","-19.1319","9.77468","0.03850"
"268.6390","-19.1280","9.48034","0.03870"
"269.1390","-19.1197","9.57222","0.03875"
"269.6390","-19.1114","9.66585","0.03880"
"270.1390","-19.1031","9.75049","0.03885"
"270.3920","-19.0988","9.52663","0.03917"
"270.8920","-19.0906","9.56661","0.03927"
"271.3920","-19.0822","9.66176","0.03932"
"271.8920","-19.0738","9.74913","0.03938"
"272.2070","-19.0685","9.53408","0.03970"
"272.7070","-19.0602","9.56181","0.03983"
"273.2070","-19.0521","9.65388","0.03988"
"273.7070","-19.0435","9.74529","0.03994"
"274.0810","-19.0376","9.61526","0.04018"
"274.4950","-19.0303","9.54403","0.04039"
"274.9950","-19.0224","9.63357","0.04044"
"275.4950","-19.0139","9.72513","0.04050"
"275.9460","-19.0062","9.69998","0.04066"
"276.2700","-19.0009","9.51688","0.04096"
"276.7700","-18.9927","9.61065","0.04101"
"277.2700","-18.9842","9.70518","0.04106"
"277.7700","-18.9757","9.78163","0.04113"
"278.0640","-18.9709","9.50801","0.04152"
"278.5640","-18.9625","9.60171","0.04158"
"279.0640","-18.9544","9.69133","0.04163"
"279.5640","-18.9460","9.77065","0.04170"
"279.8240","-18.9415","9.49191","0.04208"
"280.3240","-18.9333","9.58092","0.04214"
"280.8240","-18.9252","9.67102","0.04219"
"281.3240","-18.9166","9.75652","0.04225"
"281.5690","-18.9127","9.51278","0.04259"
"282.0690","-18.9042","9.56325","0.04269"
"282.5690","-18.8960","9.65530","0.04274"
"283.0690","-18.8876","9.74238","0.04280"
"283.3940","-18.8822","9.55028","0.04311"
"283.8230","-18.8750","9.54263","0.04325"
"284.3230","-18.8668","9.63491","0.04330"
"284.8230","-18.8584","9.72498","0.04336"
"285.3230","-18.8499","9.67190","0.04339"
"285.8230","-18.8418","9.70506","0.04346"
"286.3130","-18.8334","9.64671","0.04364"
"286.7540","-18.8263","9.57253","0.04386"
"287.2540","-18.8179","9.66266","0.04392"
"287.7540","-18.8096","9.74460","0.04398"
"288.0740","-18.8040","9.53919","0.04432"
"288.5740","-18.7958","9.54835","0.04446"
"289.0740","-18.7875","9.64110","0.04452"
"289.5740","-18.7791","9.73019","0.04458"
"290.0340","-18.7716","9.69971","0.04475"
"290.3580","-18.7661","9.51747","0.04506"
"290.8580","-18.7578","9.61113","0.04512"
"291.3580","-18.7493","9.70619","0.04517"
"291.8580","-18.7413","9.78149","0.04524"
"292.1220","-18.7364","9.49589","0.04565"
"292.6220","-18.7286","9.57998","0.04571"
"293.1220","-18.7201","9.67611","0.04577"
"293.6220","-18.7118","9.76165","0.04583"
"293.9050","-18.7068","9.55529","0.04615"
"294.4050","-18.6988","9.56883","0.04629"
"294.9050","-18.6904","9.66385","0.04634"
"295.4050","-18.6819","9.75386","0.04641"
"295.7310","-18.6766","9.56967","0.04671"
"296.1630","-18.6693","9.56365","0.04685"
"296.6630","-18.6609","9.65757","0.04691"
"297.1630","-18.6527","9.74498","0.04697"
"297.5460","-18.6462","9.62112","0.04721"
"297.9610","-18.6393","9.55500","0.04742"
"298.4610","-18.6312","9.64596","0.04747"
"298.9610","-18.6226","9.73747","0.04753"
"299.4080","-18.6154","9.69476","0.04770"
"299.7350","-18.6097","9.53009","0.04798"
"300.2350","-18.6017","9.61909","0.04804"
"300.7350","-18.5931","9.71317","0.04810"
"301.2350","-18.5849","9.77925","0.04817"
"301.5570","-18.5793","9.51177","0.04855"
"302.0570","-18.5712","9.60048","0.04861"
"302.5570","-18.5629","9.69176","0.04867"
"303.0570","-18.5544","9.76968","0.04874"
"303.3040","-18.5502","9.49764","0.04912"
"303.8040","-18.5421","9.58433","0.04918"
"304.3040","-18.5336","9.67821","0.04924"
"304.8040","-18.5252","9.76236","0.04930"
"305.0660","-18.5209","9.53296","0.04965"
"305.5660","-18.5125","9.57202","0.04976"
"306.0660","-18.5044","9.66241","0.04981"
"306.5660","-18.4959","9.74966","0.04988"
"306.8930","-18.4905","9.57940","0.05018"
"307.3140","-18.4835","9.55452","0.05034"
"307.8140","-18.4755","9.64401","0.05039"
"308.3140","-18.4668","9.73639","0.05046"
"308.7940","-18.4588","9.70037","0.05065"
"309.1280","-18.4532","9.55362","0.05093"
"309.6280","-18.4449","9.64555","0.05099"
"310.1280","-18.4366","9.73228","0.05106"
"310.6280","-18.4283","9.73003","0.05122"
"311.1200","-18.4201","9.68088","0.05144"
"311.6200","-18.4116","9.75162","0.05152"
"312.0210","-18.4053","9.57161","0.05188"
"312.5210","-18.3968","9.58909","0.05204"
"313.0210","-18.3884","9.67914","0.05211"
"313.5210","-18.3799","9.76626","0.05218"
"314.0210","-18.3717","9.82886","0.05226"
"314.2950","-18.3670","9.57689","0.05261"
"314.7950","-18.3588","9.63038","0.05269"
"315.2950","-18.3506","9.71941","0.05275"
"315.7950","-18.3420","9.80935","0.05281"
"316.2950","-18.3339","9.87218","0.05288"
"316.6930","-18.3270","9.62693","0.05327"
"317.1930","-18.3190","9.69553","0.05335"
"317.6930","-18.3105","9.78101","0.05342"
"318.1930","-18.3022","9.85612","0.05350"
"318.5230","-18.2966","9.68426","0.05379"
"318.9390","-18.2897","9.61932","0.05400"
"319.4390","-18.2814","9.71092","0.05406"
"319.9390","-18.2731","9.79937","0.05412"
"320.4390","-18.2649","9.86980","0.05418"
"320.7620","-18.2593","9.59764","0.05435"
"321.2620","-18.2512","9.68121","0.05441"
"321.7620","-18.2425","9.77661","0.05447"
"322.2620","-18.2345","9.85680","0.05452"
"322.6140","-18.2285","9.72454","0.05461"
"323.0290","-18.2218","9.64778","0.05469"
"323.5290","-18.2133","9.74183","0.05474"
"324.0290","-18.2050","9.83076","0.05479"
"324.5290","-18.1965","9.89503","0.05485"
"324.8220","-18.1918","9.62854","0.05480"
"325.3220","-18.1834","9.72000","0.05484"
"325.8220","-18.1750","9.81219","0.05489"
"326.3220","-18.1668","9.88821","0.05493"
"326.5650","-18.1625","9.65494","0.05482"
"327.0650","-18.1542","9.67723","0.05484"
"327.5650","-18.1460","9.76877","0.05488"
"328.0650","-18.1379","9.85280","0.05493"
"328.5650","-18.1292","9.87048","0.05495"
"329.0650","-18.1210","9.84323","0.05494"
"329.5650","-18.1127","9.90337","0.05497"
"330.0650","-18.1042","9.84464","0.05495"
"330.5650","-18.0962","9.85649","0.05496"
"331.0650","-18.0876","9.88358","0.05498"
"331.3830","-18.0824","9.60341","0.05485"
"331.8830","-18.0739","9.69538","0.05489"
"332.3830","-18.0658","9.78348","0.05494"
"332.8830","-18.0575","9.86802","0.05498"
"333.3830","-18.0490","9.91621","0.05501"
"333.6320","-18.0448","9.61852","0.05487"
"334.1320","-18.0366","9.70337","0.05491"
"334.6320","-18.0281","9.79764","0.05496"
"335.1320","-18.0197","9.88343","0.05500"
"335.5480","-18.0131","9.79382","0.05497"
"335.8880","-18.0072","9.67819","0.05491"
"336.3880","-17.9990","9.76754","0.05496"
"336.8880","-17.9905","9.85806","0.05501"
"337.3880","-17.9824","9.91485","0.05506"
"337.6860","-17.9772","9.65817","0.05533"
"338.1860","-17.9692","9.74338","0.05538"
"338.6860","-17.9606","9.83629","0.05543"
"339.1860","-17.9523","9.90761","0.05548"
"339.5090","-17.9468","9.62296","0.05562"
"340.0090","-17.9386","9.69303","0.05570"
"340.5090","-17.9302","9.78258","0.05575"
"341.0090","-17.9220","9.86512","0.05581"
"341.3660","-17.9158","9.72529","0.05603"
"341.7820","-17.9090","9.64953","0.05625"
"342.2820","-17.9008","9.74120","0.05630"
"342.7820","-17.8922","9.83320","0.05636"
"343.2820","-17.8843","9.89682","0.05642"
"343.6000","-17.8786","9.63277","0.05687"
"344.1000","-17.8705","9.71998","0.05693"
"344.6000","-17.8620","9.81379","0.05699"
"345.1000","-17.8539","9.89410","0.05705"
"345.3540","-17.8492","9.67272","0.05741"
"345.8540","-17.8414","9.68761","0.05755"
"346.3540","-17.8329","9.78225","0.05761"
"346.8540","-17.8245","9.87166","0.05767"
"347.2750","-17.8174","9.82527","0.05786"
"347.6020","-17.8121","9.65428","0.05816"
"348.1020","-17.8037","9.74884","0.05821"
"348.6020","-17.7953","9.84217","0.05827"
"349.1020","-17.7873","9.91611","0.05834"
"349.3410","-17.7829","9.64572","0.05874"
"349.8410","-17.7747","9.69480","0.05884"
"350.3410","-17.7663","9.78849","0.05889"
"350.8410","-17.7583","9.87395","0.05895"
"351.3000","-17.7503","9.85109","0.05914"
"351.6250","-17.7450","9.65971","0.05945"
"352.1250","-17.7365","9.75533","0.05951"
"352.6250","-17.7285","9.84258","0.05957"
"353.1250","-17.7201","9.91953","0.05964"
"353.4360","-17.7148","9.64116","0.06006"
"353.9360","-17.7064","9.72716","0.06013"
"354.4360","-17.6982","9.81720","0.06018"
"354.9360","-17.6898","9.90219","0.06025"
"355.2730","-17.6842","9.76146","0.06052"
"355.6860","-17.6773","9.67249","0.06074"
"356.1860","-17.6688","9.76760","0.06080"
"356.6860","-17.6608","9.85375","0.06086"
"357.1860","-17.6523","9.89011","0.06099"
"357.4250","-17.6481","9.62483","0.06136"
"357.9250","-17.6400","9.71442","0.06142"
"358.4250","-17.6319","9.80385","0.06147"
"358.9250","-17.6233","9.89110","0.06154"
"359.2430","-17.6182","9.67605","0.06189"
"359.7430","-17.6097","9.68723","0.06203"
"360.2430","-17.6013","9.77974","0.06209"
"360.7430","-17.5930","9.86784","0.06215"
"361.2430","-17.5848","9.92026","0.06224"
"361.5420","-17.5795","9.65888","0.06263"
"362.0420","-17.5714","9.74645","0.06269"
"362.5420","-17.5631","9.83555","0.06275"
"363.0420","-17.5546","9.91658","0.06282"
"363.5420","-17.5465","9.84785","0.06302"
"364.0420","-17.5381","9.89374","0.06314"
"364.5000","-17.5304","9.75536","0.06346"
"365.0000","-17.5220","9.73914","0.06365"
"365.5000","-17.5136","9.82544","0.06372"
"366.0000","-17.5057","9.90013","0.06379"
"366.3290","-17.4998","9.70785","0.06414"
"366.7590","-17.4927","9.68573","0.06430"
"367.2590","-17.4843","9.77753","0.06436"
"367.7590","-17.4763","9.86142","0.06442"
"368.2590","-17.4678","9.92891","0.06451"
"368.5760","-17.4627","9.65199","0.06494"
"369.0760","-17.4541","9.74565","0.06500"
"369.5760","-17.4458","9.83521","0.06506"
"370.0760","-17.4375","9.91485","0.06513"
"370.4030","-17.4319","9.74987","0.06543"
"370.8190","-17.4252","9.68990","0.06563"
"371.3190","-17.4168","9.78208","0.06569"
"371.8190","-17.4084","9.87110","0.06575"
"372.3190","-17.3999","9.93439","0.06584"
"372.6020","-17.3953","9.66039","0.06625"
"373.1020","-17.3869","9.74999","0.06631"
"373.6020","-17.3789","9.83703","0.06636"
"374.1020","-17.3704","9.91773","0.06644"
"374.4930","-17.3639","9.68231","0.06684"
"374.9930","-17.3554","9.76337","0.06691"
"375.4930","-17.3473","9.84810","0.06698"
"375.9930","-17.3389","9.91724","0.06706"
"376.4930","-17.3303","9.82606","0.06731"
"376.9930","-17.3223","9.86701","0.06742"
"377.3160","-17.3166","9.64528","0.06778"
"377.8160","-17.3086","9.64828","0.06793"
"378.3160","-17.3002","9.74087","0.06800"
"378.8160","-17.2919","9.82940","0.06806"
"379.3160","-17.2835","9.90673","0.06814"
"379.5800","-17.2791","9.67010","0.06848"
"380.0120","-17.2719","9.65483","0.06864"
"380.5120","-17.2635","9.74653","0.06870"
"381.0120","-17.2552","9.83593","0.06876"
"381.5120","-17.2470","9.90459","0.06885"
"381.7750","-17.2423","9.62916","0.06924"
"382.2750","-17.2342","9.71287","0.06931"
"382.7750","-17.2259","9.80474","0.06938"
"383.2750","-17.2173","9.89059","0.06945"
"383.6030","-17.2120","9.69267","0.06977"
"384.1030","-17.2035","9.69751","0.06994"
"384.6030","-17.1955","9.78518","0.07000"
"385.1030","-17.1870","9.87436","0.07007"
"385.5440","-17.1798","9.83831","0.07024"
"385.8690","-17.1741","9.65557","0.07057"
"386.3690","-17.1661","9.74444","0.07063"
"386.8690","-17.1577","9.83564","0.07069"
"387.3690","-17.1493","9.91398","0.07077"
"387.6190","-17.1450","9.62367","0.07117"
"388.1190","-17.1369","9.70808","0.07124"
"388.6190","-17.1283","9.80398","0.07131"
"389.1190","-17.1200","9.89151","0.07138"
"389.4890","-17.1138","9.76549","0.07163"
"389.9030","-17.1069","9.68106","0.07187"
"390.4030","-17.0988","9.77090","0.07193"
"390.9030","-17.0903","9.86255","0.07200"
"391.4030","-17.0823","9.92986","0.07209"
"391.6360","-17.0781","9.63024","0.07250"
"392.1360","-17.0700","9.71577","0.07257"
"392.6360","-17.0613","9.81147","0.07264"
"393.1360","-17.0532","9.89508","0.07270"
"393.4810","-17.0474","9.75272","0.07298"
"393.8990","-17.0406","9.69701","0.07317"
"394.3990","-17.0321","9.79027","0.07324"
"394.8990","-17.0238","9.87862","0.07331"
"395.3990","-17.0153","9.91263","0.07346"
"395.8990","-17.0069","9.87359","0.07370"
"396.3990","-16.9991","9.89399","0.07384"
"396.6860","-16.9937","9.63839","0.07427"
"397.1860","-16.9857","9.65868","0.07442"
"397.6860","-16.9773","9.75060","0.07448"
"398.1860","-16.9691","9.83707","0.07454"
"398.6860","-16.9607","9.91001","0.07463"
"398.9030","-16.9571","9.60405","0.07506"
"399.4030","-16.9486","9.67154","0.07516"
"399.9030","-16.9404","9.76082","0.07521"
"400.4030","-16.9321","9.84950","0.07528"
"400.9030","-16.9237","9.91248","0.07537"
"401.2100","-16.9185","9.63747","0.07580"
"401.7100","-16.9104","9.72392","0.07586"
"402.2100","-16.9019","9.81596","0.07592"
"402.7100","-16.8933","9.90087","0.07599"
"403.0520","-16.8879","9.73628","0.07629"
"403.4740","-16.8807","9.69742","0.07648"
"403.9740","-16.8728","9.78330","0.07653"
"404.4740","-16.8642","9.87340","0.07660"
"404.9740","-16.8559","9.93189","0.07670"
"405.2710","-16.8507","9.66042","0.07711"
"405.7710","-16.8427","9.74565","0.07717"
"406.2710","-16.8343","9.83700","0.07723"
"406.7710","-16.8258","9.92115","0.07730"
"407.1360","-16.8198","9.77609","0.07759"
"407.5530","-16.8128","9.70496","0.07781"
"408.0530","-16.8044","9.79692","0.07787"
"408.5530","-16.7962","9.88356","0.07793"
"409.0530","-16.7881","9.94593","0.07802"
"409.3340","-16.7830","9.69480","0.07841"
"409.8340","-16.7750","9.73258","0.07852"
"410.3340","-16.7664","9.82559","0.07859"
"410.8340","-16.7582","9.90896","0.07865"
"411.3080","-16.7503","9.85543","0.07885"
"411.5570","-16.7462","9.60559","0.07921"
"412.0570","-16.7377","9.69552","0.07928"
"412.5570","-16.7296","9.78432","0.07934"
"413.0570","-16.7211","9.86816","0.07941"
"413.4400","-16.7148","9.73038","0.07968"
"413.8580","-16.7079","9.65411","0.07990"
"414.3580","-16.6994","9.74640","0.07997"
"414.8580","-16.6911","9.83427","0.08004"
"415.3510","-16.6827","9.80525","0.08023"
"415.6840","-16.6772","9.63977","0.08052"
"416.1840","-16.6688","9.73184","0.08059"
"416.6840","-16.6610","9.81401","0.08065"
"417.1840","-16.6524","9.88526","0.08074"
"417.5830","-16.6455","9.64255","0.08114"
"418.0830","-16.6374","9.70312","0.08124"
"418.5830","-16.6291","9.78896","0.08130"
"419.0830","-16.6208","9.86965","0.08138"
"419.3660","-16.6160","9.63882","0.08173"
"419.8660","-16.6076","9.65467","0.08188"
"420.3660","-16.5992","9.74562","0.08195"
"420.8660","-16.5911","9.82739","0.08202"
"421.2400","-16.5846","9.70526","0.08227"
"421.6580","-16.5779","9.61976","0.08251"
"422.1580","-16.5693","9.71325","0.08258"
"422.6580","-16.5613","9.79808","0.08264"
"423.1160","-16.5535","9.75663","0.08284"
"423.4630","-16.5479","9.60610","0.08312"
"423.9630","-16.5395","9.69414","0.08319"
"424.4630","-16.5310","9.78457","0.08326"
"424.9200","-16.5233","9.74106","0.08346"
"425.3570","-16.5162","9.64090","0.08371"
"425.8570","-16.5078","9.72042","0.08379"
"426.3150","-16.4999","9.65888","0.08404"
"426.7530","-16.4931","9.58200","0.08428"
"427.2530","-16.4845","9.67153","0.08435"
"427.7530","-16.4761","9.75299","0.08443"
"428.2140","-16.4684","9.60143","0.08476"
"428.7140","-16.4603","9.65748","0.08486"
"429.2140","-16.4519","9.72084","0.08496"
"429.6290","-16.4446","9.51419","0.08537"
"430.1290","-16.4368","9.57930","0.08545"
"430.6290","-16.4283","9.67048","0.08551"
"431.1290","-16.4199","9.70850","0.08564"
"431.5870","-16.4123","9.58898","0.08592"
"432.0870","-16.4040","9.66221","0.08600"
"432.5620","-16.3959","9.50879","0.08632"
"433.0620","-16.3874","9.57587","0.08641"
"433.5620","-16.3797","9.65387","0.08647"
"433.9450","-16.3729","9.51131","0.08677"
"434.4450","-16.3648","9.52763","0.08690"
"434.9450","-16.3563","9.61194","0.08698"
"435.4340","-16.3482","9.57371","0.08717"
"435.7990","-16.3420","9.43845","0.08744"
"436.2990","-16.3338","9.52520","0.08750"
"436.7990","-16.3256","9.61104","0.08757"
"437.2510","-16.3177","9.46645","0.08789"
"437.7510","-16.3097","9.53217","0.08798"
"438.2510","-16.3012","9.54640","0.08813"
"438.7510","-16.2930","9.46917","0.08840"
"439.2510","-16.2845","9.54317","0.08848"
"439.7120","-16.2767","9.39248","0.08880"
"440.2120","-16.2687","9.44568","0.08890"
"440.7120","-16.2601","9.52068","0.08899"
"441.2120","-16.2518","9.38428","0.08929"
"441.7120","-16.2436","9.45558","0.08938"
"442.1830","-16.2358","9.42555","0.08956"
"442.6830","-16.2273","9.37671","0.08979"
"443.1830","-16.2188","9.45688","0.08987"
"443.6830","-16.2109","9.34730","0.09014"
"444.1830","-16.2025","9.39237","0.09026"
"444.6670","-16.1942","9.31181","0.09052"
"445.1670","-16.1858","9.33343","0.09066"
"445.6670","-16.1776","9.40328","0.09074"
"446.1670","-16.1694","9.26366","0.09106"
"446.6670","-16.1609","9.34063","0.09114"
"447.1670","-16.1527","9.28335","0.09137"
"447.6670","-16.1443","9.29112","0.09153"
"448.1670","-16.1359","9.27883","0.09170"
"448.6670","-16.1277","9.24959","0.09190"
"449.1670","-16.1192","9.23468","0.09209"
"449.6670","-16.1112","9.23785","0.09224"
"450.1670","-16.1026","9.19247","0.09246"
"450.6670","-16.0941","9.22405","0.09260"
"451.1670","-16.0860","9.15133","0.09284"
"451.6670","-16.0776","9.14763","0.09301"
"452.1670","-16.0694","9.14305","0.09318"
"452.6670","-16.0609","9.08987","0.09342"
"453.1670","-16.0526","9.08584","0.09359"
"453.4410","-16.0479","8.73869","0.09404"
"453.4460","-16.0478","8.11760","0.09423"
"453.4510","-16.0476","7.06939","0.09428"
"453.4560","-16.0472","5.83904","0.09392"