File: Coupon Test Data/test__20250509_94834_2.csv
Time,Displacement,Force,Strain 1
(s),(mm),(kN),(mm/mm)
"0.0000","-22.0952","0.36512","-0.00022"
"0.4000","-22.0901","0.43008","-0.00019"
"0.8000","-22.0833","0.52848","-0.00015"
"1.2000","-22.0766","0.62062","-0.00012"
"1.6000","-22.0698","0.71537","-0.00008"
"2.0000","-22.0633","0.80362","-0.00004"
"2.4000","-22.0565","0.89604","-0.00001"
"2.8000","-22.0498","0.98447","0.00003"
"3.2000","-22.0432","1.07214","0.00006"
"3.6000","-22.0365","1.15779","0.00010"
"4.0000","-22.0300","1.23838","0.00013"
"4.4000","-22.0232","1.32395","0.00016"
"4.8000","-22.0167","1.40603","0.00020"
"5.2000","-22.0099","1.49090","0.00023"
"5.6000","-22.0033","1.57259","0.00026"
"6.0000","-21.9966","1.64530","0.00029"
"6.4000","-21.9899","1.72353","0.00032"
"6.8000","-21.9833","1.80501","0.00036"
"7.2000","-21.9767","1.88618","0.00039"
"7.6000","-21.9698","1.96962","0.00042"
"8.0000","-21.9633","2.03907","0.00045"
"8.4000","-21.9563","2.12460","0.00048"
"8.8000","-21.9500","2.19947","0.00051"
"9.2000","-21.9431","2.28360","0.00055"
"9.6000","-21.9366","2.35380","0.00058"
"10.0000","-21.9298","2.43315","0.00061"
"10.4000","-21.9231","2.51276","0.00064"
"10.8000","-21.9166","2.58882","0.00067"
"11.2000","-21.9098","2.66296","0.00070"
"11.6000","-21.9033","2.73681","0.00073"
"12.0000","-21.8966","2.81432","0.00076"
"12.4000","-21.8899","2.89122","0.00079"
"12.8000","-21.8833","2.96146","0.00082"
"13.2000","-21.8765","3.03904","0.00085"
"13.6000","-21.8700","3.11288","0.00088"
"14.0000","-21.8633","3.18489","0.00091"
"14.4000","-21.8565","3.25969","0.00094"
"14.8000","-21.8501","3.33047","0.00097"
"15.2000","-21.8430","3.40891","0.00100"
"15.6000","-21.8367","3.47462","0.00103"
"16.0000","-21.8297","3.55273","0.00106"
"16.4000","-21.8233","3.62095","0.00109"
"16.8000","-21.8165","3.69356","0.00112"
"17.2000","-21.8099","3.76403","0.00115"
"17.6000","-21.8032","3.83464","0.00117"
"18.0000","-21.7964","3.90684","0.00120"
"18.4000","-21.7898","3.97642","0.00123"
"18.8000","-21.7832","4.04525","0.00126"
"19.2000","-21.7766","4.11512","0.00129"
"19.6000","-21.7700","4.18253","0.00132"
"20.0000","-21.7632","4.25281","0.00134"
"20.4000","-21.7566","4.32142","0.00137"
"20.8000","-21.7499","4.38900","0.00140"
"21.2000","-21.7432","4.45896","0.00143"
"21.6000","-21.7367","4.52383","0.00145"
"22.0000","-21.7298","4.59524","0.00148"
"22.4000","-21.7235","4.65788","0.00151"
"22.8000","-21.7164","4.73015","0.00154"
"23.2000","-21.7100","4.79396","0.00156"
"23.6000","-21.7031","4.86351","0.00159"
"24.0000","-21.6966","4.92732","0.00162"
"24.4000","-21.6898","4.99531","0.00165"
"24.8000","-21.6833","5.05951","0.00167"
"25.2000","-21.6764","5.12750","0.00170"
"25.6000","-21.6699","5.19041","0.00173"
"26.0000","-21.6631","5.25642","0.00176"
"26.4000","-21.6565","5.31949","0.00178"
"26.8000","-21.6499","5.38322","0.00181"
"27.2000","-21.6432","5.44705","0.00184"
"27.6000","-21.6367","5.50844","0.00186"
"28.0000","-21.6298","5.57431","0.00189"
"28.4000","-21.6233","5.63465","0.00192"
"28.8000","-21.6165","5.69888","0.00194"
"29.2000","-21.6101","5.75782","0.00197"
"29.6000","-21.6032","5.82092","0.00200"
"30.0000","-21.5967","5.88075","0.00202"
"30.4000","-21.5898","5.94334","0.00205"
"30.8000","-21.5833","6.00119","0.00208"
"31.2000","-21.5764","6.06409","0.00211"
"31.6000","-21.5700","6.11971","0.00213"
"32.0000","-21.5630","6.18240","0.00216"
"32.4000","-21.5567","6.23563","0.00218"
"32.8000","-21.5497","6.29669","0.00222"
"33.2000","-21.5431","6.35180","0.00224"
"33.6000","-21.5365","6.40621","0.00227"
"34.0000","-21.5298","6.46243","0.00230"
"34.4000","-21.5233","6.51409","0.00232"
"34.8000","-21.5165","6.56953","0.00235"
"35.2000","-21.5100","6.62076","0.00238"
"35.6000","-21.5032","6.67387","0.00241"
"36.0000","-21.4966","6.72579","0.00244"
"36.4000","-21.4899","6.77481","0.00247"
"36.8000","-21.4832","6.82689","0.00250"
"37.2000","-21.4766","6.87501","0.00253"
"37.6000","-21.4701","6.92281","0.00256"
"38.0000","-21.4631","6.97390","0.00259"
"38.4000","-21.4567","7.01689","0.00262"
"38.8000","-21.4496","7.06642","0.00266"
"39.2000","-21.4434","7.10516","0.00269"
"39.6000","-21.4364","7.15245","0.00272"
"40.0000","-21.4299","7.19243","0.00276"
"40.4000","-21.4231","7.23583","0.00279"
"40.8000","-21.4164","7.27680","0.00283"
"41.2000","-21.4099","7.31559","0.00286"
"41.6000","-21.4031","7.35623","0.00290"
"42.0000","-21.3966","7.39366","0.00293"
"42.4000","-21.3899","7.42989","0.00297"
"42.8000","-21.3832","7.46878","0.00301"
"43.2000","-21.3766","7.50254","0.00304"
"43.6000","-21.3698","7.54026","0.00309"
"44.0000","-21.3633","7.57251","0.00313"
"44.4000","-21.3566","7.60668","0.00317"
"44.8000","-21.3499","7.63990","0.00321"
"45.2000","-21.3434","7.66997","0.00325"
"45.6000","-21.3364","7.70381","0.00330"
"46.0000","-21.3300","7.73021","0.00334"
"46.4000","-21.3231","7.76285","0.00339"
"46.8000","-21.3166","7.78849","0.00343"
"47.2000","-21.3098","7.81763","0.00348"
"47.6000","-21.3032","7.84229","0.00353"
"48.0000","-21.2965","7.86951","0.00358"
"48.4000","-21.2898","7.89301","0.00363"
"48.8000","-21.2831","7.91760","0.00369"
"49.2000","-21.2765","7.93784","0.00374"
"49.6000","-21.2699","7.96181","0.00379"
"50.0000","-21.2633","7.98027","0.00385"
"50.4000","-21.2565","8.00244","0.00391"
"50.8000","-21.2498","8.01983","0.00396"
"51.2000","-21.2432","8.03784","0.00402"
"51.6000","-21.2365","8.05595","0.00408"
"52.0000","-21.2300","8.07185","0.00414"
"52.4000","-21.2232","8.08867","0.00420"
"52.8000","-21.2168","8.10269","0.00426"
"53.2000","-21.2098","8.11984","0.00433"
"53.6000","-21.2033","8.13282","0.00439"
"54.0000","-21.1964","8.14814","0.00446"
"54.4000","-21.1900","8.15874","0.00452"
"54.8000","-21.1831","8.17575","0.00459"
"55.2000","-21.1766","8.18480","0.00465"
"55.6000","-21.1697","8.20207","0.00472"
"56.0000","-21.1632","8.20829","0.00479"
"56.4000","-21.1564","8.22335","0.00485"
"56.8000","-21.1498","8.23238","0.00492"
"57.2000","-21.1431","8.24348","0.00499"
"57.6000","-21.1365","8.25291","0.00506"
"58.0000","-21.1299","8.26268","0.00513"
"58.4000","-21.1231","8.27290","0.00520"
"58.8000","-21.1166","8.27620","0.00526"
"59.2000","-21.1099","8.28601","0.00532"
"59.6000","-21.1033","8.29994","0.00539"
"60.0000","-21.0966","8.30913","0.00546"
"60.4000","-21.0899","8.31795","0.00553"
"60.8000","-21.0831","8.32534","0.00560"
"61.2000","-21.0766","8.32958","0.00567"
"61.6000","-21.0697","8.34138","0.00575"
"62.0000","-21.0633","8.34396","0.00582"
"62.4000","-21.0562","8.35786","0.00589"
"62.8000","-21.0501","8.35890","0.00596"
"63.2000","-21.0430","8.37268","0.00603"
"63.6000","-21.0365","8.37687","0.00611"
"64.0000","-21.0298","8.38477","0.00618"
"64.4000","-21.0231","8.39220","0.00625"
"64.8000","-21.0166","8.39762","0.00632"
"65.2000","-21.0098","8.40592","0.00640"
"65.6000","-21.0033","8.41138","0.00647"
"66.0000","-20.9965","8.41734","0.00655"
"66.4000","-20.9899","8.42453","0.00662"
"66.8000","-20.9833","8.42838","0.00670"
"67.2000","-20.9765","8.43671","0.00677"
"67.6000","-20.9699","8.44145","0.00685"
"68.0000","-20.9633","8.44758","0.00692"
"68.4000","-20.9564","8.45645","0.00700"
"68.8000","-20.9500","8.45773","0.00707"
"69.2000","-20.9429","8.46873","0.00714"
"69.6000","-20.9368","8.46854","0.00722"
"70.0000","-20.9297","8.47966","0.00729"
"70.4000","-20.9233","8.48225","0.00736"
"70.8000","-20.9164","8.48990","0.00744"
"71.2000","-20.9098","8.49383","0.00751"
"71.6000","-20.9032","8.49867","0.00758"
"72.0000","-20.8964","8.50632","0.00765"
"72.4000","-20.8899","8.51292","0.00771"
"72.8000","-20.8832","8.51870","0.00778"
"73.2000","-20.8765","8.52667","0.00786"
"73.6000","-20.8699","8.52970","0.00793"
"74.0000","-20.8631","8.53532","0.00800"
"74.4000","-20.8565","8.53854","0.00808"
"74.8000","-20.8500","8.54216","0.00815"
"75.2000","-20.8432","8.54883","0.00823"
"75.6000","-20.8367","8.55107","0.00830"
"76.0000","-20.8297","8.55893","0.00838"
"76.4000","-20.8234","8.55966","0.00845"
"76.8000","-20.8164","8.56732","0.00853"
"77.2000","-20.8100","8.56456","0.00860"
"77.6000","-20.8031","8.56376","0.00866"
"78.0000","-20.7966","8.57315","0.00872"
"78.4000","-20.7898","8.58950","0.00878"
"78.8000","-20.7832","8.59821","0.00885"
"79.2000","-20.7764","8.60676","0.00892"
"79.6000","-20.7698","8.60769","0.00900"
"80.0000","-20.7631","8.61209","0.00908"
"80.4000","-20.7565","8.61351","0.00915"
"80.8000","-20.7498","8.61714","0.00923"
"81.2000","-20.7431","8.62113","0.00931"
"81.6000","-20.7366","8.62249","0.00939"
"82.0000","-20.7298","8.62809","0.00947"
"82.4000","-20.7233","8.63035","0.00954"
"82.8000","-20.7165","8.63557","0.00962"
"83.2000","-20.7101","8.63959","0.00970"
"83.6000","-20.7032","8.64529","0.00978"
"84.0000","-20.6966","8.64956","0.00985"
"84.4000","-20.6898","8.65454","0.00993"
"84.8000","-20.6833","8.65710","0.01001"
"85.2000","-20.6764","8.66549","0.01008"
"85.6000","-20.6700","8.66673","0.01016"
"86.0000","-20.6630","8.67644","0.01024"
"86.4000","-20.6566","8.67604","0.01031"
"86.8000","-20.6497","8.68383","0.01038"
"87.2000","-20.6431","8.68734","0.01046"
"87.6000","-20.6365","8.69133","0.01053"
"88.0000","-20.6298","8.69638","0.01060"
"88.4000","-20.6233","8.69935","0.01067"
"88.8000","-20.6164","8.70549","0.01075"
"89.2000","-20.6099","8.70838","0.01082"
"89.6000","-20.6032","8.71221","0.01089"
"90.0000","-20.5966","8.71667","0.01095"
"90.4000","-20.5900","8.71910","0.01102"
"90.8000","-20.5832","8.72543","0.01108"
"91.2000","-20.5765","8.72758","0.01115"
"91.6000","-20.5699","8.72857","0.01121"
"92.0000","-20.5631","8.72990","0.01127"
"92.2710","-20.5585","8.56496","0.01123"
"92.6710","-20.5520","8.58940","0.01125"
"93.0710","-20.5454","8.65371","0.01129"
"93.4710","-20.5387","8.71051","0.01134"
"93.8710","-20.5320","8.75030","0.01139"
"94.2710","-20.5253","8.76240","0.01143"
"94.6710","-20.5186","8.74169","0.01145"
"95.0620","-20.5122","8.66392","0.01144"
"95.4620","-20.5055","8.65840","0.01145"
"95.8620","-20.4991","8.71789","0.01149"
"96.2620","-20.4920","8.77265","0.01153"
"96.6620","-20.4857","8.79243","0.01157"
"96.9330","-20.4807","8.63220","0.01153"
"97.3330","-20.4743","8.65770","0.01155"
"97.7330","-20.4676","8.72687","0.01159"
"98.1330","-20.4609","8.78445","0.01163"
"98.5080","-20.4548","8.73011","0.01163"
"98.8240","-20.4494","8.63371","0.01160"
"99.2240","-20.4429","8.70469","0.01164"
"99.6240","-20.4361","8.77276","0.01168"
"100.0240","-20.4297","8.75138","0.01170"
"100.2820","-20.4251","8.63472","0.01173"
"100.6820","-20.4185","8.70780","0.01178"
"101.0820","-20.4118","8.77606","0.01183"
"101.4470","-20.4056","8.73225","0.01200"
"101.7630","-20.4005","8.64018","0.01223"
"102.1630","-20.3937","8.71756","0.01228"
"102.5630","-20.3873","8.78221","0.01232"
"102.8660","-20.3818","8.65458","0.01255"
"103.2660","-20.3756","8.65657","0.01267"
"103.6660","-20.3686","8.73667","0.01272"
"104.0660","-20.3621","8.80112","0.01278"
"104.3650","-20.3569","8.61581","0.01306"
"104.7650","-20.3505","8.68677","0.01311"
"105.1650","-20.3439","8.76114","0.01316"
"105.5650","-20.3371","8.81340","0.01323"
"105.8170","-20.3329","8.63503","0.01350"
"106.2170","-20.3261","8.71421","0.01355"
"106.6170","-20.3196","8.78493","0.01360"
"106.9530","-20.3139","8.74235","0.01374"
"107.2690","-20.3088","8.65332","0.01394"
"107.6690","-20.3021","8.73127","0.01399"
"108.0690","-20.2954","8.80175","0.01404"
"108.3090","-20.2913","8.66211","0.01427"
"108.7090","-20.2848","8.67752","0.01438"
"109.1090","-20.2779","8.75673","0.01443"
"109.5090","-20.2714","8.82109","0.01449"
"109.7440","-20.2672","8.62620","0.01478"
"110.1440","-20.2611","8.69493","0.01483"
"110.5440","-20.2541","8.77559","0.01488"
"110.9440","-20.2477","8.82786","0.01495"
"111.2010","-20.2431","8.65004","0.01524"
"111.6010","-20.2364","8.72724","0.01528"
"112.0010","-20.2299","8.79973","0.01534"
"112.3120","-20.2246","8.67437","0.01557"
"112.7120","-20.2181","8.68866","0.01569"
"113.1120","-20.2112","8.76925","0.01574"
"113.5120","-20.2050","8.83174","0.01580"
"113.7690","-20.2002","8.64237","0.01610"
"114.1690","-20.1936","8.71688","0.01615"
"114.5690","-20.1870","8.79235","0.01620"
"114.9690","-20.1803","8.80296","0.01632"
"115.2050","-20.1766","8.65813","0.01656"
"115.6050","-20.1697","8.73928","0.01661"
"116.0050","-20.1633","8.80978","0.01666"
"116.3200","-20.1577","8.74391","0.01685"
"116.6380","-20.1525","8.68093","0.01703"
"117.0380","-20.1459","8.75947","0.01707"
"117.4380","-20.1393","8.82990","0.01713"
"117.6910","-20.1351","8.69968","0.01737"
"118.0910","-20.1283","8.71111","0.01753"
"118.4910","-20.1218","8.78655","0.01759"
"118.8910","-20.1150","8.85482","0.01770"
"119.2070","-20.1095","8.67548","0.01805"
"119.6070","-20.1031","8.75024","0.01810"
"120.0070","-20.0964","8.82617","0.01814"
"120.3800","-20.0903","8.78976","0.01814"
"120.6960","-20.0849","8.70521","0.01810"
"121.0960","-20.0784","8.78078","0.01814"
"121.4960","-20.0715","8.85615","0.01817"
"121.7350","-20.0674","8.71605","0.01811"
"122.1350","-20.0610","8.71692","0.01812"
"122.5350","-20.0542","8.79711","0.01815"
"122.9350","-20.0477","8.86117","0.01818"
"123.1730","-20.0433","8.65720","0.01809"
"123.5730","-20.0372","8.72702","0.01813"
"123.9730","-20.0301","8.80942","0.01817"
"124.3390","-20.0242","8.77571","0.01815"
"124.6560","-20.0188","8.69468","0.01812"
"125.0560","-20.0123","8.77210","0.01815"
"125.4560","-20.0057","8.84434","0.01819"
"125.6890","-20.0016","8.69039","0.01812"
"126.0890","-19.9952","8.71242","0.01813"
"126.4890","-19.9882","8.79431","0.01817"
"126.8670","-19.9821","8.76263","0.01816"
"127.2670","-19.9753","8.75828","0.01816"
"127.6670","-19.9687","8.83448","0.01820"
"128.0670","-19.9621","8.89687","0.01823"
"128.4670","-19.9553","8.87380","0.01823"
"128.8670","-19.9489","8.92258","0.01825"
"129.2670","-19.9420","8.92719","0.01826"
"129.6670","-19.9355","8.93711","0.01827"
"130.0670","-19.9287","8.98649","0.01829"
"130.4670","-19.9222","9.02201","0.01831"
"130.8670","-19.9155","9.03074","0.01832"
"131.2670","-19.9088","9.03083","0.01832"
"131.6670","-19.9021","9.07589","0.01835"
"132.0670","-19.8955","9.09271","0.01837"
"132.3820","-19.8901","8.96392","0.01832"
"132.7820","-19.8834","9.03375","0.01835"
"133.0610","-19.8789","8.90584","0.01830"
"133.3760","-19.8735","8.84416","0.01828"
"133.7760","-19.8672","8.91943","0.01831"
"134.1760","-19.8602","9.00243","0.01835"
"134.5760","-19.8537","9.07239","0.01838"
"134.9760","-19.8468","9.12107","0.01841"
"135.1560","-19.8438","8.89441","0.01831"
"135.5560","-19.8374","8.96596","0.01835"
"135.9560","-19.8306","9.04246","0.01838"
"136.3560","-19.8242","9.02565","0.01838"
"136.6790","-19.8183","8.96719","0.01836"
"137.0790","-19.8121","9.03842","0.01839"
"137.4790","-19.8050","9.11856","0.01843"
"137.8790","-19.7986","9.17675","0.01846"
"138.1520","-19.7938","8.98684","0.01838"
"138.5520","-19.7874","9.05682","0.01841"
"138.9520","-19.7808","9.12666","0.01844"
"139.3130","-19.7746","9.07796","0.01843"
"139.7130","-19.7681","9.06524","0.01843"
"140.1130","-19.7612","9.13135","0.01846"
"140.5130","-19.7549","9.15722","0.01848"
"140.8330","-19.7491","8.97967","0.01840"
"141.2330","-19.7427","9.05075","0.01844"
"141.6330","-19.7359","9.12584","0.01847"
"142.0330","-19.7291","9.18890","0.01851"
"142.2520","-19.7257","8.96688","0.01842"
"142.6520","-19.7189","9.01128","0.01843"
"143.0520","-19.7126","9.08372","0.01847"
"143.4520","-19.7054","9.16231","0.01850"
"143.8520","-19.6993","9.19688","0.01852"
"144.0240","-19.6961","8.98052","0.01843"
"144.4240","-19.6896","9.05297","0.01846"
"144.8240","-19.6828","9.13125","0.01850"
"145.2240","-19.6762","9.19668","0.01852"
"145.4530","-19.6723","9.02628","0.01850"
"145.8530","-19.6657","9.03266","0.01856"
"146.2530","-19.6590","9.11083","0.01860"
"146.6530","-19.6523","9.18266","0.01864"
"146.9670","-19.6470","9.08356","0.01886"
"147.2840","-19.6419","9.01523","0.01904"
"147.6840","-19.6351","9.09531","0.01909"
"148.0840","-19.6286","9.16739","0.01913"
"148.4840","-19.6217","9.18314","0.01925"
"148.7120","-19.6179","8.99379","0.01956"
"149.1120","-19.6115","9.06750","0.01960"
"149.5120","-19.6046","9.14725","0.01965"
"149.9120","-19.5981","9.21032","0.01970"
"150.0950","-19.5947","8.98608","0.02004"
"150.4950","-19.5883","9.03026","0.02012"
"150.8950","-19.5815","9.10998","0.02016"
"151.2950","-19.5750","9.18150","0.02021"
"151.6350","-19.5693","9.13865","0.02037"
"151.8680","-19.5652","8.99696","0.02061"
"152.2680","-19.5588","9.07129","0.02065"
"152.6680","-19.5520","9.15081","0.02070"
"153.0680","-19.5454","9.21256","0.02075"
"153.2300","-19.5427","8.96906","0.02109"
"153.6300","-19.5360","9.03750","0.02114"
"154.0300","-19.5296","9.11183","0.02118"
"154.4300","-19.5227","9.18803","0.02123"
"154.7280","-19.5176","9.05691","0.02148"
"155.0480","-19.5123","9.01198","0.02162"
"155.4480","-19.5057","9.09070","0.02166"
"155.8480","-19.4992","9.16299","0.02171"
"156.2480","-19.4924","9.18753","0.02181"
"156.4760","-19.4887","8.98795","0.02210"
"156.8760","-19.4817","9.07053","0.02214"
"157.2760","-19.4754","9.14297","0.02218"
"157.6760","-19.4684","9.21251","0.02224"
"157.9060","-19.4647","8.97442","0.02257"
"158.3060","-19.4581","9.04944","0.02261"
"158.7060","-19.4515","9.12617","0.02266"
"159.1060","-19.4450","9.19529","0.02270"
"159.3370","-19.4409","9.05022","0.02294"
"159.6590","-19.4354","9.01218","0.02308"
"160.0590","-19.4289","9.08944","0.02312"
"160.4590","-19.4222","9.16394","0.02317"
"160.8590","-19.4156","9.20719","0.02324"
"161.0160","-19.4128","8.98091","0.02354"
"161.4160","-19.4063","9.05450","0.02358"
"161.8160","-19.3996","9.13187","0.02363"
"162.2160","-19.3928","9.20156","0.02368"
"162.4120","-19.3896","8.97187","0.02399"
"162.8120","-19.3829","9.04469","0.02403"
"163.2120","-19.3764","9.11962","0.02407"
"163.6120","-19.3695","9.19405","0.02412"
"163.8430","-19.3657","8.97177","0.02444"
"164.2430","-19.3593","9.03750","0.02449"
"164.6430","-19.3525","9.11629","0.02453"
"165.0430","-19.3458","9.18905","0.02458"
"165.3010","-19.3414","9.05389","0.02481"
"165.6200","-19.3361","9.00622","0.02496"
"166.0200","-19.3296","9.08163","0.02500"
"166.4200","-19.3229","9.15882","0.02504"
"166.8200","-19.3163","9.21175","0.02511"
"166.9890","-19.3130","8.96793","0.02544"
"167.3890","-19.3068","9.03817","0.02548"
"167.7890","-19.2999","9.11879","0.02553"
"168.1890","-19.2933","9.18987","0.02557"
"168.4860","-19.2884","9.06250","0.02581"
"168.8030","-19.2832","9.00198","0.02597"
"169.2030","-19.2767","9.07785","0.02601"
"169.6030","-19.2697","9.15743","0.02606"
"170.0030","-19.2633","9.20928","0.02612"
"170.2060","-19.2597","8.98642","0.02643"
"170.6060","-19.2531","9.06149","0.02647"
"171.0060","-19.2465","9.13683","0.02652"
"171.4060","-19.2399","9.19895","0.02657"
"171.6400","-19.2359","8.97711","0.02690"
"172.0400","-19.2291","9.05351","0.02694"
"172.4400","-19.2225","9.13037","0.02698"
"172.8400","-19.2159","9.19727","0.02703"
"173.0070","-19.2129","8.97198","0.02734"
"173.4070","-19.2066","9.02000","0.02740"
"173.8070","-19.1995","9.10270","0.02743"
"174.2070","-19.1933","9.17086","0.02745"
"174.5210","-19.1877","9.05508","0.02746"
"174.8460","-19.1824","9.01845","0.02749"
"175.2460","-19.1757","9.09755","0.02753"
"175.6460","-19.1691","9.17205","0.02757"
"176.0460","-19.1626","9.22260","0.02760"
"176.3950","-19.1565","9.08806","0.02756"
"176.7950","-19.1502","9.14710","0.02759"
"177.1950","-19.1430","9.21829","0.02763"
"177.5950","-19.1369","9.24857","0.02766"
"177.9950","-19.1297","9.26127","0.02768"
"178.3950","-19.1234","9.29724","0.02770"
"178.7950","-19.1165","9.25473","0.02768"
"179.1950","-19.1100","9.27773","0.02770"
"179.5950","-19.1033","9.31063","0.02772"
"179.9950","-19.0965","9.30122","0.02772"
"180.3950","-19.0899","9.25330","0.02771"
"180.7950","-19.0832","9.29288","0.02774"
"181.1950","-19.0766","9.32273","0.02775"
"181.5950","-19.0701","9.34621","0.02777"
"181.9740","-19.0636","9.24283","0.02773"
"182.3740","-19.0570","9.31212","0.02777"
"182.7740","-19.0504","9.37095","0.02780"
"183.1740","-19.0435","9.36696","0.02780"
"183.5740","-19.0372","9.40339","0.02783"
"183.9740","-19.0301","9.43360","0.02786"
"184.1190","-19.0278","9.16272","0.02772"
"184.5190","-19.0213","9.20824","0.02775"
"184.9190","-19.0146","9.28365","0.02779"
"185.3190","-19.0079","9.35881","0.02784"
"185.7190","-19.0013","9.42273","0.02788"
"186.1190","-18.9947","9.45271","0.02797"
"186.2870","-18.9917","9.21375","0.02835"
"186.6870","-18.9850","9.28642","0.02839"
"187.0870","-18.9785","9.35990","0.02843"
"187.4870","-18.9717","9.43144","0.02848"
"187.8870","-18.9651","9.47921","0.02853"
"188.0780","-18.9616","9.22217","0.02887"
"188.4780","-18.9552","9.29170","0.02892"
"188.8780","-18.9486","9.36747","0.02897"
"189.2780","-18.9418","9.43993","0.02902"
"189.6780","-18.9353","9.48989","0.02908"
"189.8840","-18.9316","9.22953","0.02942"
"190.2840","-18.9253","9.29720","0.02947"
"190.6840","-18.9182","9.37945","0.02952"
"191.0840","-18.9121","9.44394","0.02956"
"191.4840","-18.9050","9.49002","0.02964"
"191.6460","-18.9025","9.24407","0.02995"
"192.0460","-18.8958","9.31682","0.02999"
"192.4460","-18.8891","9.39319","0.03004"
"192.8460","-18.8825","9.46253","0.03009"
"193.1810","-18.8767","9.37454","0.03010"
"193.3340","-18.8741","9.15530","0.03001"
"193.7340","-18.8677","9.22706","0.03005"
"194.1340","-18.8609","9.30668","0.03009"
"194.5340","-18.8546","9.37719","0.03012"
"194.9340","-18.8476","9.44556","0.03015"
"195.2540","-18.8423","9.37521","0.03013"
"195.5690","-18.8370","9.27530","0.03009"
"195.9690","-18.8303","9.35291","0.03013"
"196.3690","-18.8239","9.42575","0.03017"
"196.7690","-18.8171","9.49631","0.03020"
"197.0980","-18.8118","9.41761","0.03019"
"197.2370","-18.8092","9.17053","0.03007"
"197.6370","-18.8025","9.24091","0.03010"
"198.0370","-18.7959","9.31667","0.03014"
"198.4370","-18.7893","9.38871","0.03017"
"198.8370","-18.7826","9.45571","0.03020"
"199.1320","-18.7776","9.31488","0.03014"
"199.5320","-18.7712","9.31505","0.03015"
"199.9320","-18.7643","9.39340","0.03018"
"200.3320","-18.7577","9.46492","0.03022"
"200.7320","-18.7508","9.53344","0.03025"
"201.1320","-18.7443","9.47136","0.03023"
"201.5320","-18.7376","9.49810","0.03024"
"201.7870","-18.7335","9.34592","0.03018"
"202.1210","-18.7280","9.31368","0.03017"
"202.5210","-18.7211","9.39131","0.03020"
"202.9210","-18.7146","9.46006","0.03024"
"203.3140","-18.7078","9.42339","0.03022"
"203.5530","-18.7038","9.29128","0.03017"
"203.9530","-18.6974","9.36450","0.03020"
"204.3530","-18.6907","9.44019","0.03024"
"204.7530","-18.6841","9.50769","0.03027"
"204.9550","-18.6804","9.28495","0.03018"
"205.3550","-18.6739","9.31098","0.03019"
"205.7550","-18.6672","9.39036","0.03023"
"206.1550","-18.6605","9.46655","0.03026"
"206.5550","-18.6541","9.53301","0.03029"
"206.8530","-18.6490","9.40570","0.03024"
"207.0900","-18.6451","9.28094","0.03019"
"207.4900","-18.6381","9.36206","0.03023"
"207.8900","-18.6318","9.43597","0.03026"
"208.2900","-18.6249","9.51170","0.03030"
"208.6900","-18.6183","9.56711","0.03033"
"208.8960","-18.6148","9.28066","0.03020"
"209.2960","-18.6083","9.35278","0.03023"
"209.6960","-18.6018","9.42718","0.03027"
"210.0960","-18.5948","9.50512","0.03030"
"210.4960","-18.5884","9.55980","0.03031"
"210.6470","-18.5857","9.29096","0.03020"
"211.0470","-18.5790","9.35495","0.03024"
"211.4470","-18.5726","9.42814","0.03027"
"211.8470","-18.5658","9.50214","0.03030"
"212.2470","-18.5593","9.54512","0.03034"
"212.4080","-18.5563","9.30480","0.03050"
"212.8080","-18.5497","9.37666","0.03055"
"213.2080","-18.5431","9.45195","0.03059"
"213.6080","-18.5364","9.52205","0.03064"
"213.8940","-18.5318","9.38741","0.03091"
"214.2140","-18.5261","9.33967","0.03108"
"214.6140","-18.5197","9.41402","0.03113"
"215.0140","-18.5129","9.49060","0.03117"
"215.4140","-18.5062","9.55349","0.03123"
"215.6130","-18.5030","9.31808","0.03156"
"216.0130","-18.4962","9.34953","0.03166"
"216.4130","-18.4898","9.42365","0.03170"
"216.8130","-18.4829","9.50094","0.03175"
"217.2130","-18.4765","9.56009","0.03180"
"217.4240","-18.4729","9.33052","0.03213"
"217.8240","-18.4661","9.33672","0.03225"
"218.2240","-18.4596","9.41247","0.03229"
"218.6240","-18.4528","9.48781","0.03234"
"219.0240","-18.4462","9.55510","0.03239"
"219.2450","-18.4423","9.33503","0.03271"
"219.6450","-18.4357","9.33642","0.03283"
"220.0450","-18.4292","9.41197","0.03288"
"220.4450","-18.4223","9.48947","0.03292"
"220.8450","-18.4158","9.55396","0.03297"
"221.0380","-18.4122","9.33530","0.03329"
"221.4380","-18.4061","9.33541","0.03340"
"221.8380","-18.3991","9.41591","0.03345"
"222.2380","-18.3926","9.48858","0.03349"
"222.6380","-18.3858","9.55333","0.03354"
"222.7910","-18.3832","9.31737","0.03386"
"223.1910","-18.3768","9.34931","0.03393"
"223.5910","-18.3699","9.42998","0.03398"
"223.9910","-18.3635","9.49907","0.03402"
"224.3910","-18.3564","9.54383","0.03411"
"224.5390","-18.3541","9.29771","0.03442"
"224.9390","-18.3478","9.36673","0.03446"
"225.3390","-18.3409","9.44609","0.03450"
"225.7390","-18.3343","9.51617","0.03455"
"226.0660","-18.3286","9.46631","0.03471"
"226.2950","-18.3249","9.30889","0.03495"
"226.6950","-18.3184","9.38351","0.03499"
"227.0950","-18.3117","9.46000","0.03503"
"227.4950","-18.3051","9.52844","0.03508"
"227.7680","-18.3001","9.39462","0.03532"
"228.0830","-18.2950","9.31753","0.03549"
"228.4830","-18.2884","9.39475","0.03553"
"228.8830","-18.2818","9.46946","0.03557"
"229.2830","-18.2751","9.53858","0.03562"
"229.5660","-18.2704","9.39754","0.03584"
"229.8830","-18.2653","9.32333","0.03602"
"230.2830","-18.2584","9.40168","0.03607"
"230.6830","-18.2518","9.47499","0.03611"
"231.0830","-18.2450","9.54379","0.03616"
"231.4110","-18.2396","9.38636","0.03637"
"231.8110","-18.2330","9.37263","0.03651"
"232.2110","-18.2265","9.44406","0.03656"
"232.6110","-18.2197","9.51662","0.03661"
"232.9730","-18.2137","9.46702","0.03676"
"233.2050","-18.2097","9.30311","0.03703"
"233.6050","-18.2031","9.37639","0.03707"
"234.0050","-18.1963","9.45304","0.03712"
"234.4050","-18.1898","9.52146","0.03717"
"234.7190","-18.1846","9.42931","0.03737"
"235.0330","-18.1795","9.32439","0.03758"
"235.4330","-18.1726","9.40397","0.03763"
"235.8330","-18.1661","9.47616","0.03767"
"236.2330","-18.1592","9.54602","0.03772"
"236.5620","-18.1537","9.45946","0.03790"
"236.8910","-18.1484","9.40008","0.03808"
"237.2910","-18.1416","9.47331","0.03812"
"237.6910","-18.1352","9.53663","0.03817"
"238.0910","-18.1283","9.50475","0.03832"
"238.4910","-18.1217","9.53178","0.03842"
"238.8910","-18.1151","9.56339","0.03850"
"239.2910","-18.1083","9.54370","0.03864"
"239.6880","-18.1017","9.45283","0.03887"
"240.0880","-18.0953","9.51605","0.03892"
"240.4880","-18.0883","9.58586","0.03898"
"240.8880","-18.0819","9.60454","0.03903"
"241.2880","-18.0748","9.61894","0.03909"
"241.6880","-18.0686","9.62876","0.03918"
"242.0880","-18.0616","9.60113","0.03934"
"242.4880","-18.0551","9.56067","0.03951"
"242.8880","-18.0483","9.62368","0.03957"
"243.2880","-18.0416","9.68148","0.03962"
"243.6880","-18.0351","9.64052","0.03964"
"244.0880","-18.0282","9.65844","0.03966"
"244.4880","-18.0218","9.69275","0.03969"
"244.8880","-18.0151","9.70267","0.03972"
"245.2880","-18.0084","9.71041","0.03974"
"245.4740","-18.0050","9.48861","0.03965"
"245.8740","-17.9987","9.55521","0.03969"
"246.2740","-17.9919","9.62803","0.03973"
"246.6740","-17.9852","9.69000","0.03976"
"247.0740","-17.9787","9.71380","0.03978"
"247.4650","-17.9720","9.64570","0.03977"
"247.7040","-17.9683","9.46466","0.03968"
"248.1040","-17.9613","9.53971","0.03972"
"248.5040","-17.9550","9.60802","0.03975"
"248.9040","-17.9480","9.68048","0.03979"
"249.3000","-17.9416","9.63731","0.03978"
"249.5290","-17.9376","9.46621","0.03970"
"249.9290","-17.9310","9.53881","0.03973"
"250.3290","-17.9245","9.61107","0.03977"
"250.7290","-17.9177","9.68214","0.03981"
"251.0830","-17.9120","9.62695","0.03978"
"251.2460","-17.9090","9.41246","0.03968"
"251.6460","-17.9024","9.48334","0.03972"
"252.0460","-17.8958","9.55807","0.03975"
"252.4460","-17.8893","9.62712","0.03979"
"252.8280","-17.8828","9.59019","0.03978"
"253.0530","-17.8788","9.40741","0.03969"
"253.4530","-17.8723","9.48201","0.03973"
"253.8530","-17.8657","9.55733","0.03976"
"254.2530","-17.8589","9.63222","0.03979"
"254.6530","-17.8523","9.68996","0.03982"
"254.8620","-17.8486","9.41489","0.03969"
"255.2620","-17.8424","9.48139","0.03972"
"255.6620","-17.8354","9.56286","0.03976"
"256.0620","-17.8290","9.63364","0.03980"
"256.4620","-17.8221","9.69878","0.03983"
"256.6830","-17.8184","9.46757","0.03975"
"257.0830","-17.8119","9.49393","0.03979"
"257.4830","-17.8051","9.57109","0.03983"
"257.8830","-17.7987","9.64170","0.03986"
"258.2830","-17.7917","9.67048","0.03989"
"258.6830","-17.7853","9.60035","0.03991"
"259.0830","-17.7785","9.65932","0.03995"
"259.4830","-17.7719","9.69086","0.03997"
"259.8830","-17.7651","9.58761","0.03995"
"260.2830","-17.7587","9.63154","0.03997"
"260.6830","-17.7517","9.69002","0.04000"
"261.0830","-17.7452","9.72486","0.04004"
"261.4830","-17.7382","9.64411","0.04003"
"261.8830","-17.7318","9.58327","0.03999"
"262.2830","-17.7250","9.64778","0.04002"
"262.6830","-17.7185","9.71149","0.04006"
"263.0830","-17.7118","9.76110","0.04010"
"263.2330","-17.7091","9.47864","0.04023"
"263.6330","-17.7027","9.52402","0.04027"
"264.0330","-17.6959","9.60033","0.04031"
"264.4330","-17.6893","9.67163","0.04035"
"264.8330","-17.6825","9.74101","0.04040"
"265.1120","-17.6780","9.60142","0.04071"
"265.4280","-17.6729","9.51857","0.04095"
"265.8280","-17.6660","9.59705","0.04100"
"266.2280","-17.6595","9.66954","0.04105"
"266.6280","-17.6527","9.74113","0.04109"
"267.0010","-17.6466","9.70117","0.04125"
"267.2250","-17.6428","9.50203","0.04155"
"267.6250","-17.6361","9.57657","0.04160"
"268.0250","-17.6296","9.65069","0.04165"
"268.4250","-17.6228","9.72525","0.04170"
"268.8250","-17.6162","9.78688","0.04175"
"269.0180","-17.6127","9.56111","0.04207"
"269.3470","-17.6074","9.53303","0.04220"
"269.7470","-17.6007","9.60894","0.04225"
"270.1470","-17.5941","9.68165","0.04230"
"270.5470","-17.5876","9.74712","0.04235"
"270.7840","-17.5834","9.60466","0.04258"
"271.1000","-17.5780","9.53210","0.04276"
"271.5000","-17.5716","9.60491","0.04281"
"271.9000","-17.5649","9.68008","0.04285"
"272.3000","-17.5582","9.75095","0.04290"
"272.7000","-17.5517","9.79360","0.04297"
"273.1000","-17.5448","9.74817","0.04313"
"273.5000","-17.5382","9.62552","0.04342"
"273.9000","-17.5316","9.68089","0.04349"
"274.3000","-17.5248","9.74493","0.04355"
"274.7000","-17.5184","9.79549","0.04361"
"275.0350","-17.5124","9.72463","0.04380"
"275.2650","-17.5087","9.55189","0.04409"
"275.6650","-17.5022","9.62219","0.04413"
"276.0650","-17.4955","9.69512","0.04418"
"276.4650","-17.4888","9.76731","0.04423"
"276.8650","-17.4821","9.82740","0.04429"
"277.1530","-17.4774","9.68780","0.04454"
"277.4670","-17.4721","9.59348","0.04476"
"277.8670","-17.4654","9.66846","0.04480"
"278.2670","-17.4588","9.74077","0.04485"
"278.6670","-17.4520","9.80840","0.04490"
"279.0670","-17.4453","9.83274","0.04500"
"279.2510","-17.4420","9.55472","0.04539"
"279.6510","-17.4358","9.61602","0.04545"
"280.0510","-17.4289","9.69179","0.04550"
"280.4510","-17.4224","9.75667","0.04555"
"280.7500","-17.4174","9.60846","0.04580"
"281.1000","-17.4115","9.56503","0.04596"
"281.5000","-17.4049","9.63500","0.04601"
"281.9000","-17.3982","9.70756","0.04606"
"282.3000","-17.3917","9.76883","0.04612"
"282.5710","-17.3869","9.63136","0.04636"
"282.8080","-17.3831","9.50245","0.04657"
"283.2080","-17.3764","9.57740","0.04662"
"283.6080","-17.3697","9.65280","0.04667"
"284.0080","-17.3632","9.72398","0.04672"
"284.4080","-17.3563","9.78688","0.04678"
"284.6320","-17.3524","9.50437","0.04716"
"285.0320","-17.3460","9.57281","0.04721"
"285.4320","-17.3393","9.64828","0.04726"
"285.8320","-17.3327","9.72238","0.04731"
"286.2320","-17.3260","9.78281","0.04737"
"286.3950","-17.3233","9.55635","0.04767"
"286.7950","-17.3165","9.55779","0.04780"
"287.1950","-17.3099","9.63218","0.04784"
"287.5950","-17.3033","9.70618","0.04789"
"287.9950","-17.2966","9.77505","0.04795"
"288.2910","-17.2917","9.64051","0.04818"
"288.6040","-17.2863","9.54128","0.04840"
"289.0040","-17.2800","9.61258","0.04845"
"289.4040","-17.2730","9.69141","0.04849"
"289.8040","-17.2665","9.76003","0.04855"
"290.1970","-17.2599","9.72026","0.04871"
"290.4210","-17.2561","9.53023","0.04900"
"290.8210","-17.2497","9.60221","0.04905"
"291.2210","-17.2428","9.68017","0.04910"
"291.6210","-17.2364","9.74912","0.04915"
"292.0210","-17.2294","9.79489","0.04924"
"292.1770","-17.2267","9.52257","0.04959"
"292.5770","-17.2203","9.59122","0.04964"
"292.9770","-17.2137","9.66519","0.04969"
"293.3770","-17.2069","9.74015","0.04974"
"293.7770","-17.2003","9.80016","0.04980"
"293.9420","-17.1974","9.57475","0.05011"
"294.3420","-17.1908","9.57183","0.05025"
"294.7420","-17.1841","9.64842","0.05030"
"295.1420","-17.1775","9.72188","0.05035"
"295.5420","-17.1709","9.78770","0.05041"
"295.8280","-17.1662","9.65165","0.05065"
"296.1410","-17.1607","9.55586","0.05087"
"296.5410","-17.1542","9.62873","0.05091"
"296.9410","-17.1475","9.70511","0.05097"
"297.3410","-17.1408","9.77458","0.05102"
"297.7010","-17.1350","9.72860","0.05118"
"297.9250","-17.1310","9.53619","0.05148"
"298.3250","-17.1247","9.60583","0.05153"
"298.7250","-17.1176","9.68689","0.05158"
"299.1250","-17.1114","9.75247","0.05163"
"299.5250","-17.1043","9.81159","0.05171"
"299.7220","-17.1011","9.52533","0.05210"
"300.1220","-17.0945","9.59618","0.05216"
"300.5220","-17.0879","9.66989","0.05220"
"300.9220","-17.0813","9.74222","0.05225"
"301.3220","-17.0745","9.80451","0.05232"
"301.4920","-17.0715","9.57470","0.05273"
"301.8920","-17.0649","9.57923","0.05289"
"302.2920","-17.0583","9.65420","0.05294"
"302.6920","-17.0517","9.72790","0.05300"
"303.0920","-17.0451","9.79145","0.05305"
"303.4060","-17.0398","9.65206","0.05329"
"303.7330","-17.0342","9.59112","0.05339"
"304.1330","-17.0277","9.66126","0.05343"
"304.5330","-17.0209","9.73415","0.05348"
"304.9330","-17.0143","9.77822","0.05356"
"305.3160","-17.0078","9.72223","0.05375"
"305.7160","-17.0013","9.74419","0.05382"
"306.1160","-16.9945","9.69854","0.05380"
"306.5160","-16.9879","9.73554","0.05382"
"306.9160","-16.9812","9.77621","0.05385"
"307.0850","-16.9782","9.53630","0.05374"
"307.4850","-16.9718","9.55040","0.05374"
"307.8850","-16.9651","9.62536","0.05378"
"308.2850","-16.9585","9.69978","0.05382"
"308.6850","-16.9517","9.77131","0.05386"
"309.0700","-16.9453","9.73217","0.05385"
"309.2960","-16.9417","9.53904","0.05376"
"309.6960","-16.9349","9.61434","0.05380"
"310.0960","-16.9284","9.68678","0.05383"
"310.4960","-16.9215","9.76050","0.05387"
"310.8960","-16.9151","9.80989","0.05390"
"311.0860","-16.9118","9.52714","0.05377"
"311.4860","-16.9050","9.59919","0.05381"
"311.8860","-16.8986","9.67166","0.05384"
"312.2860","-16.8917","9.74608","0.05388"
"312.6860","-16.8854","9.80593","0.05392"
"312.8690","-16.8819","9.58344","0.05382"
"313.1970","-16.8767","9.55416","0.05380"
"313.5970","-16.8699","9.63164","0.05384"
"313.9970","-16.8633","9.70577","0.05388"
"314.3970","-16.8566","9.77598","0.05392"
"314.7240","-16.8510","9.72479","0.05391"
"314.9490","-16.8472","9.53829","0.05383"
"315.3490","-16.8408","9.60962","0.05386"
"315.7490","-16.8341","9.68494","0.05390"
"316.1490","-16.8275","9.75701","0.05394"
"316.5490","-16.8208","9.80899","0.05397"
"316.7460","-16.8173","9.52846","0.05384"
"317.1460","-16.8107","9.59892","0.05388"
"317.5460","-16.8040","9.67542","0.05392"
"317.9460","-16.7975","9.74616","0.05396"
"318.3460","-16.7907","9.81072","0.05399"
"318.5810","-16.7871","9.62564","0.05392"
"318.9810","-16.7800","9.62121","0.05392"
"319.3810","-16.7738","9.68933","0.05396"
"319.7810","-16.7667","9.76588","0.05400"
"320.1810","-16.7603","9.82458","0.05403"
"320.5810","-16.7534","9.76818","0.05407"
"320.9810","-16.7469","9.79262","0.05410"
"321.3810","-16.7402","9.83408","0.05414"
"321.7810","-16.7334","9.75450","0.05432"
"322.1810","-16.7267","9.81254","0.05437"
"322.5810","-16.7201","9.85707","0.05441"
"322.9810","-16.7134","9.84396","0.05443"
"323.2170","-16.7095","9.57133","0.05431"
"323.6170","-16.7031","9.63262","0.05434"
"324.0170","-16.6962","9.70824","0.05438"
"324.4170","-16.6897","9.77707","0.05441"
"324.8170","-16.6828","9.84660","0.05445"
"325.1610","-16.6771","9.79474","0.05443"
"325.3160","-16.6747","9.57748","0.05433"
"325.7160","-16.6677","9.65099","0.05436"
"326.1160","-16.6616","9.71859","0.05439"
"326.5160","-16.6545","9.79681","0.05443"
"326.9160","-16.6481","9.86017","0.05446"
"327.2610","-16.6421","9.80905","0.05444"
"327.4870","-16.6384","9.61417","0.05435"
"327.8870","-16.6318","9.68480","0.05439"
"328.2870","-16.6251","9.76015","0.05442"
"328.6870","-16.6186","9.82851","0.05446"
"329.0870","-16.6116","9.89104","0.05449"
"329.2520","-16.6089","9.64784","0.05437"
"329.6520","-16.6023","9.65925","0.05438"
"330.0520","-16.5957","9.73218","0.05441"
"330.4520","-16.5890","9.80604","0.05445"
"330.8520","-16.5824","9.87147","0.05448"
"331.1650","-16.5773","9.75079","0.05445"
"331.4790","-16.5719","9.64479","0.05446"
"331.8790","-16.5651","9.71962","0.05449"
"332.2790","-16.5585","9.79216","0.05453"
"332.6790","-16.5519","9.86028","0.05456"
"333.0790","-16.5452","9.90103","0.05459"
"333.2480","-16.5421","9.61310","0.05465"
"333.6480","-16.5359","9.67642","0.05468"
"334.0480","-16.5290","9.75407","0.05473"
"334.4480","-16.5224","9.82622","0.05477"
"334.8480","-16.5158","9.89041","0.05481"
"335.1330","-16.5109","9.75368","0.05498"
"335.4480","-16.5059","9.65556","0.05512"
"335.8480","-16.4989","9.73254","0.05517"
"336.2480","-16.4927","9.80097","0.05521"
"336.6480","-16.4856","9.87517","0.05526"
"337.0480","-16.4792","9.87766","0.05530"
"337.4480","-16.4723","9.89153","0.05532"
"337.8480","-16.4658","9.92732","0.05537"
"338.2480","-16.4591","9.86276","0.05537"
"338.6480","-16.4524","9.89636","0.05542"
"338.9140","-16.4481","9.71912","0.05570"
"339.2340","-16.4424","9.65378","0.05588"
"339.6340","-16.4362","9.72110","0.05593"
"340.0340","-16.4292","9.79907","0.05598"
"340.4340","-16.4228","9.86548","0.05602"
"340.8340","-16.4159","9.91473","0.05609"
"341.0190","-16.4128","9.62728","0.05649"
"341.4190","-16.4063","9.69407","0.05654"
"341.8190","-16.3995","9.76976","0.05658"
"342.2190","-16.3930","9.83992","0.05663"
"342.6190","-16.3861","9.90566","0.05668"
"342.8570","-16.3822","9.74907","0.05694"
"343.1730","-16.3770","9.66568","0.05713"
"343.5730","-16.3704","9.73763","0.05717"
"343.9730","-16.3637","9.81280","0.05722"
"344.3730","-16.3570","9.88167","0.05726"
"344.7730","-16.3504","9.92806","0.05733"
"344.9780","-16.3468","9.63941","0.05772"
"345.3780","-16.3401","9.70741","0.05777"
"345.7780","-16.3335","9.78054","0.05781"
"346.1780","-16.3269","9.85155","0.05786"
"346.5780","-16.3202","9.91710","0.05791"
"346.8590","-16.3156","9.77551","0.05813"
"347.1760","-16.3104","9.68594","0.05833"
"347.5760","-16.3035","9.76164","0.05837"
"347.9760","-16.2970","9.83217","0.05842"
"348.3760","-16.2903","9.89961","0.05847"
"348.7500","-16.2840","9.85109","0.05865"
"348.9780","-16.2803","9.66295","0.05893"
"349.3780","-16.2735","9.73764","0.05897"
"349.7780","-16.2671","9.80728","0.05902"
"350.1780","-16.2601","9.88003","0.05907"
"350.5780","-16.2537","9.92866","0.05913"
"350.8220","-16.2494","9.68497","0.05949"
"351.2220","-16.2428","9.72390","0.05957"
"351.6220","-16.2363","9.79334","0.05962"
"352.0220","-16.2294","9.86564","0.05966"
"352.4220","-16.2230","9.92367","0.05971"
"352.6980","-16.2179","9.75956","0.05995"
"353.0530","-16.2125","9.71747","0.06011"
"353.4530","-16.2055","9.79211","0.06016"
"353.8530","-16.1990","9.85814","0.06020"
"354.2530","-16.1922","9.91867","0.06025"
"354.6530","-16.1855","9.85202","0.06028"
"355.0530","-16.1790","9.87910","0.06034"
"355.4530","-16.1722","9.86457","0.06045"
"355.8530","-16.1657","9.85050","0.06055"
"356.2530","-16.1590","9.88569","0.06063"
"356.6530","-16.1524","9.90619","0.06071"
"357.0530","-16.1457","9.81999","0.06091"
"357.4530","-16.1389","9.84073","0.06102"
"357.8530","-16.1323","9.87937","0.06110"
"358.2530","-16.1258","9.89583","0.06120"
"358.5180","-16.1211","9.64706","0.06157"
"358.9180","-16.1146","9.70294","0.06163"
"359.3180","-16.1078","9.77515","0.06168"
"359.7180","-16.1012","9.84353","0.06173"
"360.1180","-16.0944","9.90854","0.06179"
"360.4700","-16.0888","9.84912","0.06196"
"360.6980","-16.0849","9.65144","0.06226"
"361.0980","-16.0781","9.72335","0.06231"
"361.4980","-16.0717","9.79331","0.06236"
"361.8980","-16.0649","9.86516","0.06241"
"362.2980","-16.0582","9.92275","0.06247"
"362.5180","-16.0546","9.69522","0.06280"
"362.9180","-16.0479","9.70023","0.06293"
"363.3180","-16.0414","9.76968","0.06298"
"363.7180","-16.0346","9.84302","0.06303"
"364.1180","-16.0281","9.90650","0.06309"
"364.4410","-16.0224","9.82912","0.06328"
"364.6750","-16.0184","9.66804","0.06355"
"365.0750","-16.0120","9.73562","0.06360"
"365.4750","-16.0052","9.81017","0.06365"
"365.8750","-15.9988","9.87663","0.06370"
"366.2750","-15.9919","9.92057","0.06377"
"366.6750","-15.9856","9.92936","0.06387"
"366.8700","-15.9818","9.65354","0.06427"
"367.2700","-15.9753","9.71446","0.06433"
"367.6700","-15.9686","9.78752","0.06438"
"368.0700","-15.9620","9.85713","0.06443"
"368.4700","-15.9554","9.91807","0.06450"
"368.8700","-15.9487","9.84318","0.06475"
"369.2700","-15.9422","9.83780","0.06489"
"369.6470","-15.9356","9.73560","0.06515"
"370.0470","-15.9292","9.70124","0.06533"
"370.4470","-15.9224","9.76937","0.06538"
"370.8470","-15.9159","9.83371","0.06544"
"371.2470","-15.9090","9.88683","0.06552"
"371.4150","-15.9062","9.63961","0.06588"
"371.8150","-15.8997","9.64919","0.06600"
"372.2150","-15.8929","9.72348","0.06605"
"372.6150","-15.8864","9.79276","0.06610"
"373.0150","-15.8795","9.86157","0.06615"
"373.4150","-15.8732","9.88844","0.06625"
"373.6770","-15.8683","9.62711","0.06665"
"374.0770","-15.8620","9.67606","0.06672"
"374.4770","-15.8552","9.74714","0.06678"
"374.8770","-15.8485","9.81679","0.06683"
"375.2770","-15.8420","9.87575","0.06689"
"375.5250","-15.8377","9.70533","0.06717"
"375.8480","-15.8325","9.62964","0.06736"
"376.2480","-15.8255","9.70228","0.06742"
"376.6480","-15.8192","9.76924","0.06747"
"377.0480","-15.8123","9.83909","0.06752"
"377.3670","-15.8070","9.74023","0.06774"
"377.6090","-15.8031","9.59218","0.06798"
"378.0090","-15.7963","9.66298","0.06803"
"378.4090","-15.7899","9.73283","0.06808"
"378.8090","-15.7830","9.80575","0.06813"
"379.2090","-15.7765","9.84545","0.06821"
"379.5540","-15.7705","9.65046","0.06856"
"379.9540","-15.7639","9.70249","0.06862"
"380.3540","-15.7572","9.76725","0.06868"
"380.7540","-15.7507","9.79766","0.06877"
"380.9760","-15.7470","9.54399","0.06912"
"381.3760","-15.7402","9.60628","0.06918"
"381.7760","-15.7338","9.67493","0.06923"
"382.1760","-15.7269","9.74717","0.06928"
"382.5760","-15.7203","9.77988","0.06937"
"382.9760","-15.7134","9.64144","0.06967"
"383.3760","-15.7069","9.68763","0.06974"
"383.7760","-15.7002","9.74414","0.06981"
"384.1230","-15.6945","9.62255","0.07005"
"384.4890","-15.6883","9.56935","0.07023"
"384.8890","-15.6817","9.63722","0.07029"
"385.2890","-15.6751","9.70579","0.07034"
"385.6890","-15.6683","9.72511","0.07046"
"386.0530","-15.6625","9.60581","0.07071"
"386.4530","-15.6554","9.66672","0.07078"
"386.8530","-15.6493","9.69921","0.07086"
"387.2130","-15.6427","9.52239","0.07121"
"387.6130","-15.6363","9.57537","0.07128"
"388.0130","-15.6296","9.64539","0.07134"
"388.4130","-15.6229","9.70835","0.07140"
"388.7430","-15.6175","9.53166","0.07171"
"389.1430","-15.6108","9.57683","0.07180"
"389.5430","-15.6043","9.63709","0.07186"
"389.9430","-15.5974","9.63628","0.07200"
"390.3140","-15.5914","9.49022","0.07230"
"390.7140","-15.5846","9.55578","0.07236"
"391.1140","-15.5781","9.62190","0.07241"
"391.4660","-15.5720","9.57159","0.07259"
"391.8270","-15.5661","9.50450","0.07279"
"392.2270","-15.5595","9.56502","0.07285"
"392.6270","-15.5526","9.58199","0.07297"
"393.0270","-15.5460","9.48307","0.07320"
"393.4270","-15.5394","9.54112","0.07326"
"393.8270","-15.5327","9.60332","0.07333"
"394.1760","-15.5270","9.43956","0.07363"
"394.5760","-15.5203","9.49428","0.07370"
"394.9760","-15.5136","9.54735","0.07377"
"395.3600","-15.5072","9.40319","0.07408"
"395.7600","-15.5004","9.45042","0.07416"
"396.1600","-15.4940","9.51323","0.07421"
"396.5600","-15.4870","9.42911","0.07445"
"396.9600","-15.4808","9.43095","0.07457"
"397.3600","-15.4737","9.48921","0.07465"
"397.7600","-15.4672","9.43543","0.07484"
"398.1600","-15.4604","9.42571","0.07498"
"398.5600","-15.4538","9.42873","0.07512"
"398.9600","-15.4473","9.42853","0.07524"
"399.3600","-15.4405","9.41777","0.07540"
"399.7600","-15.4339","9.37352","0.07557"
"400.1600","-15.4271","9.41178","0.07566"
"400.5600","-15.4205","9.38717","0.07582"
"400.9600","-15.4139","9.31706","0.07603"
"401.3600","-15.4071","9.37654","0.07610"
"401.7600","-15.4006","9.35636","0.07625"
"402.1600","-15.3939","9.31876","0.07643"
"402.5600","-15.3871","9.33079","0.07655"
"402.9600","-15.3806","9.31787","0.07669"
"403.3600","-15.3737","9.31694","0.07683"
"403.7600","-15.3674","9.25032","0.07704"
"404.1600","-15.3605","9.30518","0.07711"
"404.5600","-15.3540","9.25024","0.07731"
"404.9600","-15.3471","9.25771","0.07744"
"405.3600","-15.3405","9.21256","0.07762"
"405.7600","-15.3338","9.25779","0.07770"
"406.1600","-15.3271","9.17816","0.07793"
"406.5600","-15.3204","9.20434","0.07803"
"406.9600","-15.3139","9.17474","0.07819"
"407.3600","-15.3071","9.18208","0.07832"
"407.7600","-15.3005","9.13456","0.07851"
"408.1600","-15.2938","9.16490","0.07861"
"408.5600","-15.2871","9.09737","0.07882"
"408.9600","-15.2806","9.11322","0.07893"
"409.3600","-15.2738","9.06605","0.07913"
"409.7600","-15.2674","9.08925","0.07922"
"410.1600","-15.2604","9.03819","0.07942"
"410.5600","-15.2540","9.02944","0.07956"
"410.9600","-15.2472","9.04424","0.07968"
"411.3600","-15.2406","8.98955","0.07988"
"411.7600","-15.2338","8.95937","0.08004"
"412.1600","-15.2274","9.00489","0.08012"
"412.5600","-15.2204","8.91678","0.08037"
"412.9600","-15.2139","8.86050","0.08056"
"413.3600","-15.2070","8.91357","0.08063"
"413.5250","-15.2043","8.62286","0.08088"
"413.5290","-15.2042","8.02711","0.08098"
"413.5330","-15.2041","7.18204","0.08092"
"413.5370","-15.2038","6.21011","0.08069"
"413.5380","-15.2037","5.95820","0.08061"